Workbook

Sheet Healthcare SG&A
A1: Sector | B1: Subsector | C1: Core Activity | D1: Effort Split | E1: Key Main Task | F1: % Effort | G1: Category | H1: AI Addressable | I1: Agentification Potential | J1: Actual Agentification Possible | K1: NA | L1: EU | M1: APAC ex India | N1: India
A2: Healthcare | B2: Providers | C2: Finance & Accounting | D2: 0.2 | E2: Transaction processing & reconciliation | F2: 0.3 | G2: Task Processing / Query Handling | H2: 0.9 | I2: =SUMPRODUCT(H2:H5,F2:F5)*D2 -> 0.1655 | J2: 0.62 | K2: 0.62 | L2: 0.58 | M2: 0.52 | N2: 0.45
A3: Healthcare | B3: Providers | C3: Finance & Accounting | D3: 0.2 | E3: Financial planning & analysis | F3: 0.25 | G3: Assessment & Analysis | H3: 0.6 | J3: 0.62 | K3: 0.62 | L3: 0.58 | M3: 0.52 | N3: 0.45
A4: Healthcare | B4: Providers | C4: Finance & Accounting | D4: 0.2 | E4: Budgeting & forecasting | F4: 0.2 | G4: Modelling (incl. Forecasting) | H4: 0.85 | J4: 0.62 | K4: 0.62 | L4: 0.58 | M4: 0.52 | N4: 0.45
A5: Healthcare | B5: Providers | C5: Finance & Accounting | D5: 0.2 | E5: Financial reporting | F5: 0.25 | G5: Document Generation & Management | H5: 0.95 | J5: 0.62 | K5: 0.62 | L5: 0.58 | M5: 0.52 | N5: 0.45
A6: Healthcare | B6: Providers | C6: Human Resources | D6: 0.2 | E6: Recruitment administration | F6: 0.25 | G6: Task Processing / Query Handling | H6: 0.9 | I6: =SUMPRODUCT(H6:H9,F6:F9)*D6 -> 0.124 | J6: 0.5 | K6: 0.5 | L6: 0.47 | M6: 0.42 | N6: 0.36
A7: Healthcare | B7: Providers | C7: Human Resources | D7: 0.2 | E7: Workforce planning | F7: 0.25 | G7: Task Planning & Management | H7: 0.7 | J7: 0.5 | K7: 0.5 | L7: 0.47 | M7: 0.42 | N7: 0.36
A8: Healthcare | B8: Providers | C8: Human Resources | D8: 0.2 | E8: Employee relations & support | F8: 0.3 | G8: Stakeholder / Relationship Management | H8: 0.1 | J8: 0.5 | K8: 0.5 | L8: 0.47 | M8: 0.42 | N8: 0.36
A9: Healthcare | B9: Providers | C9: Human Resources | D9: 0.2 | E9: HR documentation & reporting | F9: 0.2 | G9: Document Generation & Management | H9: 0.95 | J9: 0.5 | K9: 0.5 | L9: 0.47 | M9: 0.42 | N9: 0.36
A10: Healthcare | B10: Providers | C10: Revenue Cycle & Administrative Support | D10: 0.2 | E10: Billing administration | F10: 0.3 | G10: Task Processing / Query Handling | H10: 0.9 | I10: =SUMPRODUCT(H10:H13,F10:F13)*D10 -> 0.17 | J10: 0.68 | K10: 0.68 | L10: 0.63 | M10: 0.56 | N10: 0.48
A11: Healthcare | B11: Providers | C11: Revenue Cycle & Administrative Support | D11: 0.2 | E11: Claims & payment follow-up | F11: 0.3 | G11: Task Processing / Query Handling | H11: 0.9 | J11: 0.68 | K11: 0.68 | L11: 0.63 | M11: 0.56 | N11: 0.48
A12: Healthcare | B12: Providers | C12: Revenue Cycle & Administrative Support | D12: 0.2 | E12: Denial analysis | F12: 0.2 | G12: Assessment & Analysis | H12: 0.6 | J12: 0.68 | K12: 0.68 | L12: 0.63 | M12: 0.56 | N12: 0.48
A13: Healthcare | B13: Providers | C13: Revenue Cycle & Administrative Support | D13: 0.2 | E13: Administrative documentation | F13: 0.2 | G13: Document Generation & Management | H13: 0.95 | J13: 0.68 | K13: 0.68 | L13: 0.63 | M13: 0.56 | N13: 0.48
A14: Healthcare | B14: Providers | C14: Corporate IT & Enterprise Technology | D14: 0.15 | E14: IT service desk & user support | F14: 0.3 | G14: Task Processing / Query Handling | H14: 0.9 | I14: =SUMPRODUCT(H14:H17,F14:F17)*D14 -> 0.1215 | J14: 0.64 | K14: 0.64 | L14: 0.6 | M14: 0.54 | N14: 0.47
A15: Healthcare | B15: Providers | C15: Corporate IT & Enterprise Technology | D15: 0.15 | E15: Application & infrastructure monitoring | F15: 0.25 | G15: Monitoring | H15: 0.7 | J15: 0.64 | K15: 0.64 | L15: 0.6 | M15: 0.54 | N15: 0.47
A16: Healthcare | B16: Providers | C16: Corporate IT & Enterprise Technology | D16: 0.15 | E16: Technology planning & change coordination | F16: 0.25 | G16: Task Planning & Management | H16: 0.7 | J16: 0.64 | K16: 0.64 | L16: 0.6 | M16: 0.54 | N16: 0.47
A17: Healthcare | B17: Providers | C17: Corporate IT & Enterprise Technology | D17: 0.15 | E17: IT documentation | F17: 0.2 | G17: Document Generation & Management | H17: 0.95 | J17: 0.64 | K17: 0.64 | L17: 0.6 | M17: 0.54 | N17: 0.47
A18: Healthcare | B18: Providers | C18: Procurement & Vendor Management | D18: 0.1 | E18: Purchase administration | F18: 0.25 | G18: Task Processing / Query Handling | H18: 0.9 | I18: =SUMPRODUCT(H18:H21,F18:F21)*D18 -> 0.0595 | J18: 0.45 | K18: 0.45 | L18: 0.42 | M18: 0.37 | N18: 0.32
A19: Healthcare | B19: Providers | C19: Procurement & Vendor Management | D19: 0.1 | E19: Supplier evaluation & spend analysis | F19: 0.25 | G19: Assessment & Analysis | H19: 0.6 | J19: 0.45 | K19: 0.45 | L19: 0.42 | M19: 0.37 | N19: 0.32
A20: Healthcare | B20: Providers | C20: Procurement & Vendor Management | D20: 0.1 | E20: Vendor relationship management | F20: 0.3 | G20: Stakeholder / Relationship Management | H20: 0.1 | J20: 0.45 | K20: 0.45 | L20: 0.42 | M20: 0.37 | N20: 0.32
A21: Healthcare | B21: Providers | C21: Procurement & Vendor Management | D21: 0.1 | E21: Contract & procurement documentation | F21: 0.2 | G21: Document Generation & Management | H21: 0.95 | J21: 0.45 | K21: 0.45 | L21: 0.42 | M21: 0.37 | N21: 0.32
A22: Healthcare | B22: Providers | C22: Legal, Risk & Compliance | D22: 0.1 | E22: Compliance monitoring | F22: 0.25 | G22: Monitoring | H22: 0.7 | I22: =SUMPRODUCT(H22:H25,F22:F25)*D22 -> 0.05875 | J22: 0.45 | K22: 0.45 | L22: 0.42 | M22: 0.37 | N22: 0.32
A23: Healthcare | B23: Providers | C23: Legal, Risk & Compliance | D23: 0.1 | E23: Contract & policy review | F23: 0.25 | G23: Assessment & Analysis | H23: 0.6 | J23: 0.45 | K23: 0.45 | L23: 0.42 | M23: 0.37 | N23: 0.32
A24: Healthcare | B24: Providers | C24: Legal & Risk & Compliance | D24: 0.1 | E24: Regulatory stakeholder management | F24: 0.25 | G24: Stakeholder / Relationship Management | H24: 0.1 | J24: 0.45 | K24: 0.45 | L24: 0.42 | M24: 0.37 | N24: 0.32
A25: Healthcare | B25: Providers | C25: Legal, Risk & Compliance | D25: 0.1 | E25: Compliance documentation | F25: 0.25 | G25: Document Generation & Management | H25: 0.95 | J25: 0.45 | K25: 0.45 | L25: 0.42 | M25: 0.37 | N25: 0.32
A26: Healthcare | B26: Providers | C26: Corporate Strategy & General Administration | D26: 0.05 | E26: Strategic planning | F26: 0.3 | G26: Strategy & Design | H26: 0.3 | I26: =SUMPRODUCT(H26:H29,F26:F29)*D26 -> 0.02275 | J26: 0.38 | K26: 0.38 | L26: 0.35 | M26: 0.31 | N26: 0.27
A27: Healthcare | B27: Providers | C27: Corporate Strategy & General Administration | D27: 0.05 | E27: Management analysis | F27: 0.25 | G27: Assessment & Analysis | H27: 0.6 | J27: 0.38 | K27: 0.38 | L27: 0.35 | M27: 0.31 | N27: 0.27
A28: Healthcare | B28: Providers | C28: Corporate Strategy & General Administration | D28: 0.05 | E28: Executive stakeholder coordination | F28: 0.25 | G28: Stakeholder / Relationship Management | H28: 0.1 | J28: 0.38 | K28: 0.38 | L28: 0.35 | M28: 0.31 | N28: 0.27
A29: Healthcare | B29: Providers | C29: Corporate Strategy & General Administration | D29: 0.05 | E29: Corporate reporting | F29: 0.2 | G29: Document Generation & Management | H29: 0.95 | J29: 0.38 | K29: 0.38 | L29: 0.35 | M29: 0.31 | N29: 0.27
I30: =SUM(I2:I29) -> 0.722 | J30: =J2*$D2+J6*$D6+J10*$D10+J14*$D14+J18*$D18+J22*$D22+J26*$D26 -> 0.565 | K30: =K2*$D2+K6*$D6+K10*$D10+K14*$D14+K18*$D18+K22*$D22+K26*$D26 -> 0.565 | L30: =L2*$D2+L6*$D6+L10*$D10+L14*$D14+L18*$D18+L22*$D22+L26*$D26 -> 0.5275 | M30: =M2*$D2+M6*$D6+M10*$D10+M14*$D14+M18*$D18+M22*$D22+M26*$D26 -> 0.4705 | N30: =N2*$D2+N6*$D6+N10*$D10+N14*$D14+N18*$D18+N22*$D22+N26*$D26 -> 0.406
A32: Healthcare | B32: Payers | C32: Customer & Member Operations | D32: 0.2 | E32: Member queries & service requests | F32: 0.35 | G32: Task Processing / Query Handling | H32: 0.9 | I32: =SUMPRODUCT(H32:H35,F32:F35)*D32 -> 0.17 | J32: 0.66 | K32: 0.66 | L32: 0.62 | M32: 0.56 | N32: 0.48
A33: Healthcare | B33: Payers | C33: Customer & Member Operations | D33: 0.2 | E33: Enrollment & account administration | F33: 0.25 | G33: Task Processing / Query Handling | H33: 0.9 | J33: 0.66 | K33: 0.66 | L33: 0.62 | M33: 0.56 | N33: 0.48
A34: Healthcare | B34: Payers | C34: Customer & Member Operations | D34: 0.2 | E34: Member issue assessment | F34: 0.2 | G34: Assessment & Analysis | H34: 0.6 | J34: 0.66 | K34: 0.66 | L34: 0.62 | M34: 0.56 | N34: 0.48
A35: Healthcare | B35: Payers | C35: Customer & Member Operations | D35: 0.2 | E35: Member communications | F35: 0.2 | G35: Document Generation & Management | H35: 0.95 | J35: 0.66 | K35: 0.66 | L35: 0.62 | M35: 0.56 | N35: 0.48
A36: Healthcare | B36: Payers | C36: Sales & Distribution | D36: 0.15 | E36: Sales planning & targeting | F36: 0.25 | G36: Task Planning & Management | H36: 0.7 | I36: =SUMPRODUCT(H36:H39,F36:F39)*D36 -> 0.078 | J36: 0.44 | K36: 0.44 | L36: 0.41 | M36: 0.36 | N36: 0.31
A37: Healthcare | B37: Payers | C37: Sales & Distribution | D37: 0.15 | E37: Broker / employer relationship management | F37: 0.35 | G37: Stakeholder / Relationship Management | H37: 0.1 | J37: 0.44 | K37: 0.44 | L37: 0.41 | M37: 0.36 | N37: 0.31
A38: Healthcare | B38: Payers | C38: Sales & Distribution | D38: 0.15 | E38: Proposal & quote support | F38: 0.2 | G38: Document Generation & Management | H38: 0.95 | J38: 0.44 | K38: 0.44 | L38: 0.41 | M38: 0.36 | N38: 0.31
A39: Healthcare | B39: Payers | C39: Sales & Distribution | D39: 0.15 | E39: Sales performance analysis | F39: 0.2 | G39: Assessment & Analysis | H39: 0.6 | J39: 0.44 | K39: 0.44 | L39: 0.41 | M39: 0.36 | N39: 0.31
A40: Healthcare | B40: Payers | C40: Finance & Accounting | D40: 0.15 | E40: Transaction processing & reconciliation | F40: 0.3 | G40: Task Processing / Query Handling | H40: 0.9 | I40: =SUMPRODUCT(H40:H43,F40:F43)*D40 -> 0.124125 | J40: 0.62 | K40: 0.62 | L40: 0.58 | M40: 0.52 | N40: 0.45
A41: Healthcare | B41: Payers | C41: Finance & Accounting | D41: 0.15 | E41: Financial planning & analysis | F41: 0.25 | G41: Assessment & Analysis | H41: 0.6 | J41: 0.62 | K41: 0.62 | L41: 0.58 | M41: 0.52 | N41: 0.45
...

Sheet Communications
A1: Sector | B1: Subsector | C1: Core Activity | D1: Effort Split | E1: Key Main Task | F1: % Effort | G1: Category | H1: AI Addressable | I1: Agentification Potential | J1: Actual Agentification Possible | K1: NA | L1: EU | M1: APAC ex India | N1: India
A2: Communications | B2: Advertising & Marketing Services | C2: New Business & Sales | D2: 0.3 | E2: Lead & opportunity targeting | F2: 0.25 | G2: Assessment & Analysis | H2: 0.6 | I2: =SUMPRODUCT(H2:H5,F2:F5)*D2 -> 0.135 | J2: 0.43 | K2: 0.43 | L2: 0.4 | M2: 0.36 | N2: 0.31
A3: Communications | B3: Advertising & Marketing Services | C3: New Business & Sales | D3: 0.3 | E3: Prospect relationship management | F3: 0.35 | G3: Stakeholder / Relationship Management | H3: 0.1
A4: Communications | B4: Advertising & Marketing Services | C4: New Business & Sales | D4: 0.3 | E4: Pitch & proposal development | F4: 0.25 | G4: Content Generation | H4: 0.7
A5: Communications | B5: Advertising & Marketing Services | C5: New Business & Sales | D5: 0.3 | E5: Pipeline analytics & reporting | F5: 0.15 | G5: Assessment & Analysis | H5: 0.6
A6: Communications | B6: Advertising & Marketing Services | C6: Finance & Accounting | D6: 0.2 | E6: Transaction processing & reconciliation | F6: 0.3 | G6: Task Processing / Query Handling | H6: 0.9 | I6: =SUMPRODUCT(H6:H9,F6:F9)*D6 -> 0.1655 | J6: 0.68 | K6: 0.68 | L6: 0.63 | M6: 0.58 | N6: 0.52
A7: Communications | B7: Advertising & Marketing Services | C7: Finance & Accounting | D7: 0.2 | E7: Financial planning & analysis | F7: 0.25 | G7: Assessment & Analysis | H7: 0.6
A8: Communications | B8: Advertising & Marketing Services | C8: Finance & Accounting | D8: 0.2 | E8: Budgeting & forecasting | F8: 0.2 | G8: Modelling (incl. Forecasting) | H8: 0.85
A9: Communications | B9: Advertising & Marketing Services | C9: Finance & Accounting | D9: 0.2 | E9: Financial reporting | F9: 0.25 | G9: Document Generation & Management | H9: 0.95
A10: Communications | B10: Advertising & Marketing Services | C10: Human Resources | D10: 0.15 | E10: Recruitment administration | F10: 0.25 | G10: Task Processing / Query Handling | H10: 0.9 | I10: =SUMPRODUCT(H10:H13,F10:F13)*D10 -> 0.093 | J10: 0.48 | K10: 0.48 | L10: 0.45 | M10: 0.41 | N10: 0.37
A11: Communications | B11: Advertising & Marketing Services | C11: Human Resources | D11: 0.15 | E11: Workforce / freelancer planning | F11: 0.25 | G11: Task Planning & Management | H11: 0.7
A12: Communications | B12: Advertising & Marketing Services | C12: Human Resources | D12: 0.15 | E12: Employee & talent relations | F12: 0.3 | G12: Stakeholder / Relationship Management | H12: 0.1
A13: Communications | B13: Advertising & Marketing Services | C13: Human Resources | D13: 0.15 | E13: HR documentation & reporting | F13: 0.2 | G13: Document Generation & Management | H13: 0.95
A14: Communications | B14: Advertising & Marketing Services | C14: Corporate IT & Technology | D14: 0.15 | E14: IT service desk & user support | F14: 0.3 | G14: Task Processing / Query Handling | H14: 0.9 | I14: =SUMPRODUCT(H14:H17,F14:F17)*D14 -> 0.1215 | J14: 0.68 | K14: 0.68 | L14: 0.64 | M14: 0.59 | N14: 0.54
A15: Communications | B15: Advertising & Marketing Services | C15: Corporate IT & Technology | D15: 0.15 | E15: Application & infrastructure monitoring | F15: 0.25 | G15: Monitoring | H15: 0.7
A16: Communications | B16: Advertising & Marketing Services | C16: Corporate IT & Technology | D16: 0.15 | E16: Technology planning & change coordination | F16: 0.25 | G16: Task Planning & Management | H16: 0.7
A17: Communications | B17: Advertising & Marketing Services | C17: Corporate IT & Technology | D17: 0.15 | E17: IT documentation | F17: 0.2 | G17: Document Generation & Management | H17: 0.95
A18: Communications | B18: Advertising & Marketing Services | C18: Legal & Corporate Administration | D18: 0.2 | E18: Contract & policy review | F18: 0.3 | G18: Assessment & Analysis | H18: 0.6 | I18: =SUMPRODUCT(H18:H21,F18:F21)*D18 -> 0.094 | J18: 0.35 | K18: 0.35 | L18: 0.33 | M18: 0.3 | N18: 0.26
A19: Communications | B19: Advertising & Marketing Services | C19: Legal & Corporate Administration | D19: 0.2 | E19: Legal / client stakeholder coordination | F19: 0.25 | G19: Stakeholder / Relationship Management | H19: 0.1
A20: Communications | B20: Advertising & Marketing Services | C20: Legal & Corporate Administration | D20: 0.2 | E20: Corporate & strategic planning | F20: 0.25 | G20: Strategy & Design | H20: 0.3
A21: Communications | B21: Advertising & Marketing Services | C21: Legal & Corporate Administration | D21: 0.2 | E21: Legal & corporate documentation | F21: 0.2 | G21: Document Generation & Management | H21: 0.95
I22: =SUM(I2:I21) -> 0.609 | J22: =+J2*$D2+J6*$D6+J10*$D10+J14*$D14+J18*$D18 -> 0.509 | K22: =+K2*$D2+K6*$D6+K10*$D10+K14*$D14+K18*$D18 -> 0.509 | L22: =+L2*$D2+L6*$D6+L10*$D10+L14*$D14+L18*$D18 -> 0.4755 | M22: =+M2*$D2+M6*$D6+M10*$D10+M14*$D14+M18*$D18 -> 0.434 | N22: =+N2*$D2+N6*$D6+N10*$D10+N14*$D14+N18*$D18 -> 0.3855
A24: Communications | B24: Pay TV & Distribution | C24: Sales & Channel Management | D24: 0.25 | E24: Sales & channel planning | F24: 0.25 | G24: Task Planning & Management | H24: 0.7 | I24: =SUMPRODUCT(H24:H27,F24:F27)*D24 -> 0.13 | J24: 0.4 | K24: 0.4 | L24: 0.37 | M24: 0.33 | N24: 0.29
A25: Communications | B25: Pay TV & Distribution | C25: Sales & Channel Management | D25: 0.25 | E25: Affiliate / channel relationship management | F25: 0.35 | G25: Stakeholder / Relationship Management | H25: 0.1 | J25: 0.4 | K25: 0.4 | L25: 0.37 | M25: 0.33 | N25: 0.29
A26: Communications | B26: Pay TV & Distribution | C26: Sales & Channel Management | D26: 0.25 | E26: Pricing & account analytics | F26: 0.2 | G26: Assessment & Analysis | H26: 0.6 | J26: 0.4 | K26: 0.4 | L26: 0.37 | M26: 0.33 | N26: 0.29
A27: Communications | B27: Pay TV & Distribution | C27: Sales & Channel Management | D27: 0.25 | E27: Sales administration & reporting | F27: 0.2 | G27: Document Generation & Management | H27: 0.95 | J27: 0.4 | K27: 0.4 | L27: 0.37 | M27: 0.33 | N27: 0.29
A28: Communications | B28: Pay TV & Distribution | C28: Marketing & Subscriber Growth | D28: 0.2 | E28: Campaign & content development | F28: 0.3 | G28: Content Generation | H28: 0.7 | I28: =SUMPRODUCT(H28:H31,F28:F31)*D28 -> 0.091 | J28: 0.36 | K28: 0.36 | L28: 0.33 | M28: 0.3 | N28: 0.27
A29: Communications | B29: Pay TV & Distribution | C29: Marketing & Subscriber Growth | D29: 0.2 | E29: Subscriber segmentation & churn analytics | F29: 0.25 | G29: Assessment & Analysis | H29: 0.6 | J29: 0.36 | K29: 0.36 | L29: 0.33 | M29: 0.3 | N29: 0.27
A30: Communications | B30: Pay TV & Distribution | C30: Marketing & Subscriber Growth | D30: 0.2 | E30: Campaign / proposition planning | F30: 0.25 | G30: Strategy & Design | H30: 0.3 | J30: 0.36 | K30: 0.36 | L30: 0.33 | M30: 0.3 | N30: 0.27
A31: Communications | B31: Pay TV & Distribution | C31: Marketing & Subscriber Growth | D31: 0.2 | E31: Agency / channel coordination | F31: 0.2 | G31: Stakeholder / Relationship Management | H31: 0.1 | J31: 0.36 | K31: 0.36 | L31: 0.33 | M31: 0.3 | N31: 0.27
A32: Communications | B32: Pay TV & Distribution | C32: Finance & Accounting | D32: 0.2 | E32: Transaction processing & reconciliation | F32: 0.3 | G32: Task Processing / Query Handling | H32: 0.9 | I32: =SUMPRODUCT(H32:H35,F32:F35)*D32 -> 0.1655 | J32: 0.68 | K32: 0.68 | L32: 0.63 | M32: 0.58 | N32: 0.52
A33: Communications | B33: Pay TV & Distribution | C33: Finance & Accounting | D33: 0.2 | E33: Financial planning & analysis | F33: 0.25 | G33: Assessment & Analysis | H33: 0.6 | J33: 0.68 | K33: 0.68 | L33: 0.63 | M33: 0.58 | N33: 0.52
A34: Communications | B34: Pay TV & Distribution | C34: Finance & Accounting | D34: 0.2 | E34: Budgeting & forecasting | F34: 0.2 | G34: Modelling (incl. Forecasting) | H34: 0.85 | J34: 0.68 | K34: 0.68 | L34: 0.63 | M34: 0.58 | N34: 0.52
A35: Communications | B35: Pay TV & Distribution | C35: Finance & Accounting | D35: 0.2 | E35: Financial reporting | F35: 0.25 | G35: Document Generation & Management | H35: 0.95 | J35: 0.68 | K35: 0.68 | L35: 0.63 | M35: 0.58 | N35: 0.52
A36: Communications | B36: Pay TV & Distribution | C36: Human Resources | D36: 0.1 | E36: Recruitment administration | F36: 0.25 | G36: Task Processing / Query Handling | H36: 0.9 | I36: =SUMPRODUCT(H36:H39,F36:F39)*D36 -> 0.062 | J36: 0.48 | K36: 0.48 | L36: 0.45 | M36: 0.41 | N36: 0.37
A37: Communications | B37: Pay TV & Distribution | C37: Human Resources | D37: 0.1 | E37: Workforce planning | F37: 0.25 | G37: Task Planning & Management | H37: 0.7 | J37: 0.48 | K37: 0.48 | L37: 0.45 | M37: 0.41 | N37: 0.37
A38: Communications | B38: Pay TV & Distribution | C38: Human Resources | D38: 0.1 | E38: Employee relations & support | F38: 0.3 | G38: Stakeholder / Relationship Management | H38: 0.1 | J38: 0.48 | K38: 0.48 | L38: 0.45 | M38: 0.41 | N38: 0.37
A39: Communications | B39: Pay TV & Distribution | C39: Human Resources | D39: 0.1 | E39: HR documentation & reporting | F39: 0.2 | G39: Document Generation & Management | H39: 0.95 | J39: 0.48 | K39: 0.48 | L39: 0.45 | M39: 0.41 | N39: 0.37
A40: Communications | B40: Pay TV & Distribution | C40: Corporate IT & Technology | D40: 0.1 | E40: IT support & user services | F40: 0.3 | G40: Task Processing / Query Handling | H40: 0.9 | I40: =SUMPRODUCT(H40:H43,F40:F43)*D40 -> 0.081 | J40: 0.68 | K40: 0.68 | L40: 0.64 | M40: 0.59 | N40: 0.54
A41: Communications | B41: Pay TV & Distribution | C41: Corporate IT & Technology | D41: 0.1 | E41: Enterprise system monitoring | F41: 0.25 | G41: Monitoring | H41: 0.7 | J41: 0.68 | K41: 0.68 | L41: 0.64 | M41: 0.59 | N41: 0.54
...

Sheet Consumer Staples
A1: Sector | B1: Subsector | C1: Core Activity | D1: Effort Split | E1: Key Main Task | F1: % Effort | G1: Category | H1: AI Addressable | I1: Agentification Potential | J1: Actual Agentification Possible | K1: NA | L1: EU | M1: APAC ex India | N1: India
A2: Consumer Staples | B2: Beverages | C2: Sales & Channel Management | D2: 0.3 | E2: Sales planning & account targeting | F2: 0.25 | G2: Task Planning & Management | H2: 0.7 | I2: =SUMPRODUCT(H2:H5,F2:F5)*D2 -> 0.156 | J2: 0.4 | K2: 0.4 | L2: 0.37 | M2: 0.32 | N2: 0.24
A3: Consumer Staples | B3: Beverages | C3: Sales & Channel Management | D3: 0.3 | E3: Distributor / retailer relationship management | F3: 0.35 | G3: Stakeholder / Relationship Management | H3: 0.1 | J3: 0.4 | K3: 0.4 | L3: 0.37 | M3: 0.32 | N3: 0.24
A4: Consumer Staples | B4: Beverages | C4: Sales & Channel Management | D4: 0.3 | E4: Pricing & account analytics | F4: 0.2 | G4: Assessment & Analysis | H4: 0.6 | J4: 0.4 | K4: 0.4 | L4: 0.37 | M4: 0.32 | N4: 0.24
A5: Consumer Staples | B5: Beverages | C5: Sales & Channel Management | D5: 0.3 | E5: Sales administration & reporting | F5: 0.2 | G5: Document Generation & Management | H5: 0.95 | J5: 0.4 | K5: 0.4 | L5: 0.37 | M5: 0.32 | N5: 0.24
A6: Consumer Staples | B6: Beverages | C6: Marketing & Brand Management | D6: 0.2 | E6: Campaign & content development | F6: 0.3 | G6: Content Generation | H6: 0.7 | I6: =SUMPRODUCT(H6:H9,F6:F9)*D6 -> 0.091 | J6: 0.34 | K6: 0.34 | L6: 0.31 | M6: 0.27 | N6: 0.18
A7: Consumer Staples | B7: Beverages | C7: Marketing & Brand Management | D7: 0.2 | E7: Consumer & market analytics | F7: 0.25 | G7: Assessment & Analysis | H7: 0.6 | J7: 0.34 | K7: 0.34 | L7: 0.31 | M7: 0.27 | N7: 0.18
A8: Consumer Staples | B8: Beverages | C8: Marketing & Brand Management | D8: 0.2 | E8: Brand / campaign planning | F8: 0.25 | G8: Strategy & Design | H8: 0.3 | J8: 0.34 | K8: 0.34 | L8: 0.31 | M8: 0.27 | N8: 0.18
A9: Consumer Staples | B9: Beverages | C9: Marketing & Brand Management | D9: 0.2 | E9: Agency / sponsorship coordination | F9: 0.2 | G9: Stakeholder / Relationship Management | H9: 0.1 | J9: 0.34 | K9: 0.34 | L9: 0.31 | M9: 0.27 | N9: 0.18
A10: Consumer Staples | B10: Beverages | C10: Finance & Accounting | D10: 0.2 | E10: Transaction processing & reconciliation | F10: 0.3 | G10: Task Processing / Query Handling | H10: 0.9 | I10: =SUMPRODUCT(H10:H13,F10:F13)*D10 -> 0.1655 | J10: 0.64 | K10: 0.64 | L10: 0.59 | M10: 0.52 | N10: 0.4
A11: Consumer Staples | B11: Beverages | C11: Finance & Accounting | D11: 0.2 | E11: Financial planning & analysis | F11: 0.25 | G11: Assessment & Analysis | H11: 0.6 | J11: 0.64 | K11: 0.64 | L11: 0.59 | M11: 0.52 | N11: 0.4
A12: Consumer Staples | B12: Beverages | C12: Finance & Accounting | D12: 0.2 | E12: Budgeting & forecasting | F12: 0.2 | G12: Modelling (incl. Forecasting) | H12: 0.85 | J12: 0.64 | K12: 0.64 | L12: 0.59 | M12: 0.52 | N12: 0.4
A13: Consumer Staples | B13: Beverages | C13: Finance & Accounting | D13: 0.2 | E13: Financial reporting | F13: 0.25 | G13: Document Generation & Management | H13: 0.95 | J13: 0.64 | K13: 0.64 | L13: 0.59 | M13: 0.52 | N13: 0.4
A14: Consumer Staples | B14: Beverages | C14: Human Resources | D14: 0.1 | E14: Recruitment administration | F14: 0.25 | G14: Task Processing / Query Handling | H14: 0.9 | I14: =SUMPRODUCT(H14:H17,F14:F17)*D14 -> 0.062 | J14: 0.43 | K14: 0.43 | L14: 0.4 | M14: 0.35 | N14: 0.25
A15: Consumer Staples | B15: Beverages | C15: Human Resources | D15: 0.1 | E15: Workforce planning | F15: 0.25 | G15: Task Planning & Management | H15: 0.7 | J15: 0.43 | K15: 0.43 | L15: 0.4 | M15: 0.35 | N15: 0.25
A16: Consumer Staples | B16: Beverages | C16: Human Resources | D16: 0.1 | E16: Employee relations & support | F16: 0.3 | G16: Stakeholder / Relationship Management | H16: 0.1 | J16: 0.43 | K16: 0.43 | L16: 0.4 | M16: 0.35 | N16: 0.25
A17: Consumer Staples | B17: Beverages | C17: Human Resources | D17: 0.1 | E17: HR documentation & reporting | F17: 0.2 | G17: Document Generation & Management | H17: 0.95 | J17: 0.43 | K17: 0.43 | L17: 0.4 | M17: 0.35 | N17: 0.25
A18: Consumer Staples | B18: Beverages | C18: Corporate IT & Enterprise Technology | D18: 0.1 | E18: IT service desk & user support | F18: 0.3 | G18: Task Processing / Query Handling | H18: 0.9 | I18: =SUMPRODUCT(H18:H21,F18:F21)*D18 -> 0.081 | J18: 0.63 | K18: 0.63 | L18: 0.59 | M18: 0.53 | N18: 0.41
A19: Consumer Staples | B19: Beverages | C19: Corporate IT & Enterprise Technology | D19: 0.1 | E19: Application & infrastructure monitoring | F19: 0.25 | G19: Monitoring | H19: 0.7 | J19: 0.63 | K19: 0.63 | L19: 0.59 | M19: 0.53 | N19: 0.41
A20: Consumer Staples | B20: Beverages | C20: Corporate IT & Enterprise Technology | D20: 0.1 | E20: Technology planning & change coordination | F20: 0.25 | G20: Task Planning & Management | H20: 0.7 | J20: 0.63 | K20: 0.63 | L20: 0.59 | M20: 0.53 | N20: 0.41
A21: Consumer Staples | B21: Beverages | C21: Corporate IT & Enterprise Technology | D21: 0.1 | E21: IT documentation | F21: 0.2 | G21: Document Generation & Management | H21: 0.95 | J21: 0.63 | K21: 0.63 | L21: 0.59 | M21: 0.53 | N21: 0.41
A22: Consumer Staples | B22: Beverages | C22: Legal, Regulatory & Corporate Administration | D22: 0.1 | E22: Regulatory / policy monitoring | F22: 0.25 | G22: Monitoring | H22: 0.7 | I22: =SUMPRODUCT(H22:H25,F22:F25)*D22 -> 0.05875 | J22: 0.41 | K22: 0.41 | L22: 0.38 | M22: 0.33 | N22: 0.24
A23: Consumer Staples | B23: Beverages | C23: Legal, Regulatory & Corporate Administration | D23: 0.1 | E23: Contract / policy review | F23: 0.25 | G23: Assessment & Analysis | H23: 0.6 | J23: 0.41 | K23: 0.41 | L23: 0.38 | M23: 0.33 | N23: 0.24
A24: Consumer Staples | B24: Beverages | C24: Legal, Regulatory & Corporate Administration | D24: 0.1 | E24: Regulator / legal stakeholder management | F24: 0.25 | G24: Stakeholder / Relationship Management | H24: 0.1 | J24: 0.41 | K24: 0.41 | L24: 0.38 | M24: 0.33 | N24: 0.24
A25: Consumer Staples | B25: Beverages | C25: Legal, Regulatory & Corporate Administration | D25: 0.1 | E25: Compliance documentation | F25: 0.25 | G25: Document Generation & Management | H25: 0.95 | J25: 0.41 | K25: 0.41 | L25: 0.38 | M25: 0.33 | N25: 0.24
I26: =SUM(I2:I25) -> 0.61425 | J26: =+J6*$D6+J10*$D10+J14*$D14+J18*$D18+J22*$D22+$D2*J2 -> 0.463 | K26: =+K6*$D6+K10*$D10+K14*$D14+K18*$D18+K22*$D22+$D2*K2 -> 0.463 | L26: =+L6*$D6+L10*$D10+L14*$D14+L18*$D18+L22*$D22+$D2*L2 -> 0.428 | M26: =+M6*$D6+M10*$D10+M14*$D14+M18*$D18+M22*$D22+$D2*M2 -> 0.375 | N26: =+N6*$D6+N10*$D10+N14*$D14+N18*$D18+N22*$D22+$D2*N2 -> 0.278
A28: Consumer Staples | B28: Food & Agriculture | C28: Sales & Channel Management | D28: 0.25 | E28: Sales / channel planning | F28: 0.25 | G28: Task Planning & Management | H28: 0.7 | I28: =SUMPRODUCT(H28:H31,F28:F31)*D28 -> 0.13 | J28: 0.38 | K28: 0.38 | L28: 0.35 | M28: 0.3 | N28: 0.21
A29: Consumer Staples | B29: Food & Agriculture | C29: Sales & Channel Management | D29: 0.25 | E29: Retailer / distributor relationship management | F29: 0.35 | G29: Stakeholder / Relationship Management | H29: 0.1 | J29: 0.38 | K29: 0.38 | L29: 0.35 | M29: 0.3 | N29: 0.21
A30: Consumer Staples | B30: Food & Agriculture | C30: Sales & Channel Management | D30: 0.25 | E30: Pricing & account analytics | F30: 0.2 | G30: Assessment & Analysis | H30: 0.6 | J30: 0.38 | K30: 0.38 | L30: 0.35 | M30: 0.3 | N30: 0.21
A31: Consumer Staples | B31: Food & Agriculture | C31: Sales & Channel Management | D31: 0.25 | E31: Sales administration & reporting | F31: 0.2 | G31: Document Generation & Management | H31: 0.95 | J31: 0.38 | K31: 0.38 | L31: 0.35 | M31: 0.3 | N31: 0.21
A32: Consumer Staples | B32: Food & Agriculture | C32: Marketing & Brand Management | D32: 0.15 | E32: Campaign / content development | F32: 0.3 | G32: Content Generation | H32: 0.7 | I32: =SUMPRODUCT(H32:H35,F32:F35)*D32 -> 0.06825 | J32: 0.32 | K32: 0.32 | L32: 0.29 | M32: 0.25 | N32: 0.16
A33: Consumer Staples | B33: Food & Agriculture | C33: Marketing & Brand Management | D33: 0.15 | E33: Consumer / category analytics | F33: 0.25 | G33: Assessment & Analysis | H33: 0.6 | J33: 0.32 | K33: 0.32 | L33: 0.29 | M33: 0.25 | N33: 0.16
A34: Consumer Staples | B34: Food & Agriculture | C34: Marketing & Brand Management | D34: 0.15 | E34: Brand & campaign planning | F34: 0.25 | G34: Strategy & Design | H34: 0.3 | J34: 0.32 | K34: 0.32 | L34: 0.29 | M34: 0.25 | N34: 0.16
A35: Consumer Staples | B35: Food & Agriculture | C35: Marketing & Brand Management | D35: 0.15 | E35: Agency / channel coordination | F35: 0.2 | G35: Stakeholder / Relationship Management | H35: 0.1 | J35: 0.32 | K35: 0.32 | L35: 0.29 | M35: 0.25 | N35: 0.16
A36: Consumer Staples | B36: Food & Agriculture | C36: Finance & Accounting | D36: 0.2 | E36: Transaction processing & reconciliation | F36: 0.3 | G36: Task Processing / Query Handling | H36: 0.9 | I36: =SUMPRODUCT(H36:H39,F36:F39)*D36 -> 0.1655 | J36: 0.61 | K36: 0.61 | L36: 0.56 | M36: 0.49 | N36: 0.36
A37: Consumer Staples | B37: Food & Agriculture | C37: Finance & Accounting | D37: 0.2 | E37: Financial planning & analysis | F37: 0.25 | G37: Assessment & Analysis | H37: 0.6 | J37: 0.61 | K37: 0.61 | L37: 0.56 | M37: 0.49 | N37: 0.36
A38: Consumer Staples | B38: Food & Agriculture | C38: Finance & Accounting | D38: 0.2 | E38: Budgeting & forecasting | F38: 0.2 | G38: Modelling (incl. Forecasting) | H38: 0.85 | J38: 0.61 | K38: 0.61 | L38: 0.56 | M38: 0.49 | N38: 0.36
A39: Consumer Staples | B39: Food & Agriculture | C39: Finance & Accounting | D39: 0.2 | E39: Financial reporting | F39: 0.25 | G39: Document Generation & Management | H39: 0.95 | J39: 0.61 | K39: 0.61 | L39: 0.56 | M39: 0.49 | N39: 0.36
A40: Consumer Staples | B40: Food & Agriculture | C40: Human Resources | D40: 0.15 | E40: Recruitment administration | F40: 0.25 | G40: Task Processing / Query Handling | H40: 0.9 | I40: =SUMPRODUCT(H40:H43,F40:F43)*D40 -> 0.093 | J40: 0.4 | K40: 0.4 | L40: 0.37 | M40: 0.32 | N40: 0.22
A41: Consumer Staples | B41: Food & Agriculture | C41: Human Resources | D41: 0.15 | E41: Workforce planning | F41: 0.25 | G41: Task Planning & Management | H41: 0.7 | J41: 0.4 | K41: 0.4 | L41: 0.37 | M41: 0.32 | N41: 0.22
...

Sheet Financials
A1: Sector | B1: Subsector | C1: Core Activity | D1: Effort Split | E1: Key Main Task | F1: % Effort | G1: Category | H1: AI Addressable | I1: Agentification Potential | J1: Actual Agentification Possible | K1: NA | L1: EU | M1: APAC ex India | N1: India
A2: Financials | B2: Retail Banking | C2: Marketing & Corporate Communications | D2: 0.15 | E2: Campaign & content development | F2: 0.3 | G2: Content Generation | H2: 0.7 | I2: =SUMPRODUCT(H2:H5,F2:F5)*D2 -> 0.06825 | J2: 0.36 | K2: 0.36 | L2: 0.32 | M2: 0.29 | N2: 0.31
A3: Financials | B3: Retail Banking | C3: Marketing & Corporate Communications | D3: 0.15 | E3: Customer / market analytics | F3: 0.25 | G3: Assessment & Analysis | H3: 0.6 | J3: 0.36 | K3: 0.36 | L3: 0.32 | M3: 0.29 | N3: 0.31
A4: Financials | B4: Retail Banking | C4: Marketing & Corporate Communications | D4: 0.15 | E4: Campaign / proposition planning | F4: 0.25 | G4: Strategy & Design | H4: 0.3 | J4: 0.36 | K4: 0.36 | L4: 0.32 | M4: 0.29 | N4: 0.31
A5: Financials | B5: Retail Banking | C5: Marketing & Corporate Communications | D5: 0.15 | E5: Agency / external stakeholder coordination | F5: 0.2 | G5: Stakeholder / Relationship Management | H5: 0.1 | J5: 0.36 | K5: 0.36 | L5: 0.32 | M5: 0.29 | N5: 0.31
A6: Financials | B6: Retail Banking | C6: Finance & Accounting | D6: 0.2 | E6: Transaction processing & reconciliation | F6: 0.3 | G6: Task Processing / Query Handling | H6: 0.9 | I6: =SUMPRODUCT(H6:H9,F6:F9)*D6 -> 0.1655 | J6: 0.68 | K6: 0.68 | L6: 0.64 | M6: 0.61 | N6: 0.63
A7: Financials | B7: Retail Banking | C7: Finance & Accounting | D7: 0.2 | E7: Financial planning & analysis | F7: 0.25 | G7: Assessment & Analysis | H7: 0.6 | J7: 0.68 | K7: 0.68 | L7: 0.64 | M7: 0.61 | N7: 0.63
A8: Financials | B8: Retail Banking | C8: Finance & Accounting | D8: 0.2 | E8: Budgeting & forecasting | F8: 0.2 | G8: Modelling (incl. Forecasting) | H8: 0.85 | J8: 0.68 | K8: 0.68 | L8: 0.64 | M8: 0.61 | N8: 0.63
A9: Financials | B9: Retail Banking | C9: Finance & Accounting | D9: 0.2 | E9: Financial reporting | F9: 0.25 | G9: Document Generation & Management | H9: 0.95 | J9: 0.68 | K9: 0.68 | L9: 0.64 | M9: 0.61 | N9: 0.63
A10: Financials | B10: Retail Banking | C10: Human Resources | D10: 0.15 | E10: Recruitment administration | F10: 0.25 | G10: Task Processing / Query Handling | H10: 0.9 | I10: =SUMPRODUCT(H10:H13,F10:F13)*D10 -> 0.093 | J10: 0.48 | K10: 0.48 | L10: 0.44 | M10: 0.41 | N10: 0.43
A11: Financials | B11: Retail Banking | C11: Human Resources | D11: 0.15 | E11: Workforce planning | F11: 0.25 | G11: Task Planning & Management | H11: 0.7 | J11: 0.48 | K11: 0.48 | L11: 0.44 | M11: 0.41 | N11: 0.43
A12: Financials | B12: Retail Banking | C12: Human Resources | D12: 0.15 | E12: Employee relations & support | F12: 0.3 | G12: Stakeholder / Relationship Management | H12: 0.1 | J12: 0.48 | K12: 0.48 | L12: 0.44 | M12: 0.41 | N12: 0.43
A13: Financials | B13: Retail Banking | C13: Human Resources | D13: 0.15 | E13: HR documentation & reporting | F13: 0.2 | G13: Document Generation & Management | H13: 0.95 | J13: 0.48 | K13: 0.48 | L13: 0.44 | M13: 0.41 | N13: 0.43
A14: Financials | B14: Retail Banking | C14: Corporate IT & Enterprise Technology | D14: 0.2 | E14: IT service desk & user support | F14: 0.3 | G14: Task Processing / Query Handling | H14: 0.9 | I14: =SUMPRODUCT(H14:H17,F14:F17)*D14 -> 0.162 | J14: 0.68 | K14: 0.68 | L14: 0.64 | M14: 0.61 | N14: 0.63
A15: Financials | B15: Retail Banking | C15: Corporate IT & Enterprise Technology | D15: 0.2 | E15: Application, infrastructure & security monitoring | F15: 0.25 | G15: Monitoring | H15: 0.7 | J15: 0.68 | K15: 0.68 | L15: 0.64 | M15: 0.61 | N15: 0.63
A16: Financials | B16: Retail Banking | C16: Corporate IT & Enterprise Technology | D16: 0.2 | E16: Technology planning & change coordination | F16: 0.25 | G16: Task Planning & Management | H16: 0.7 | J16: 0.68 | K16: 0.68 | L16: 0.64 | M16: 0.61 | N16: 0.63
A17: Financials | B17: Retail Banking | C17: Corporate IT & Enterprise Technology | D17: 0.2 | E17: IT documentation | F17: 0.2 | G17: Document Generation & Management | H17: 0.95 | J17: 0.68 | K17: 0.68 | L17: 0.64 | M17: 0.61 | N17: 0.63
A18: Financials | B18: Retail Banking | C18: Legal, Regulatory & Corporate Administration | D18: 0.2 | E18: Regulatory / policy monitoring | F18: 0.25 | G18: Monitoring | H18: 0.7 | I18: =SUMPRODUCT(H18:H21,F18:F21)*D18 -> 0.1175 | J18: 0.45 | K18: 0.45 | L18: 0.41 | M18: 0.38 | N18: 0.4
A19: Financials | B19: Retail Banking | C19: Legal, Regulatory & Corporate Administration | D19: 0.2 | E19: Contract & policy review | F19: 0.25 | G19: Assessment & Analysis | H19: 0.6 | J19: 0.45 | K19: 0.45 | L19: 0.41 | M19: 0.38 | N19: 0.4
A20: Financials | B20: Retail Banking | C20: Legal, Regulatory & Corporate Administration | D20: 0.2 | E20: Regulator / legal stakeholder management | F20: 0.25 | G20: Stakeholder / Relationship Management | H20: 0.1 | J20: 0.45 | K20: 0.45 | L20: 0.41 | M20: 0.38 | N20: 0.4
A21: Financials | B21: Retail Banking | C21: Legal, Regulatory & Corporate Administration | D21: 0.2 | E21: Compliance & corporate documentation | F21: 0.25 | G21: Document Generation & Management | H21: 0.95 | J21: 0.45 | K21: 0.45 | L21: 0.41 | M21: 0.38 | N21: 0.4
A22: Financials | B22: Retail Banking | C22: Corporate Strategy & Management | D22: 0.1 | E22: Strategic planning | F22: 0.3 | G22: Strategy & Design | H22: 0.3 | I22: =SUMPRODUCT(H22:H25,F22:F25)*D22 -> 0.0455 | J22: 0.35 | K22: 0.35 | L22: 0.31 | M22: 0.28 | N22: 0.3
A23: Financials | B23: Retail Banking | C23: Corporate Strategy & Management | D23: 0.1 | E23: Management / market analysis | F23: 0.25 | G23: Assessment & Analysis | H23: 0.6 | J23: 0.35 | K23: 0.35 | L23: 0.31 | M23: 0.28 | N23: 0.3
A24: Financials | B24: Retail Banking | C24: Corporate Strategy & Management | D24: 0.1 | E24: Executive stakeholder coordination | F24: 0.25 | G24: Stakeholder / Relationship Management | H24: 0.1 | J24: 0.35 | K24: 0.35 | L24: 0.31 | M24: 0.28 | N24: 0.3
A25: Financials | B25: Retail Banking | C25: Corporate Strategy & Management | D25: 0.1 | E25: Corporate reporting | F25: 0.2 | G25: Document Generation & Management | H25: 0.95 | J25: 0.35 | K25: 0.35 | L25: 0.31 | M25: 0.28 | N25: 0.3
I26: =SUM(I2:I25) -> 0.65175 | J26: =+J6*$D6+J10*$D10+J14*$D14+J18*$D18+J22*$D22+$D2*J2 -> 0.523 | K26: =+K6*$D6+K10*$D10+K14*$D14+K18*$D18+K22*$D22+$D2*K2 -> 0.523 | L26: =+L6*$D6+L10*$D10+L14*$D14+L18*$D18+L22*$D22+$D2*L2 -> 0.483 | M26: =+M6*$D6+M10*$D10+M14*$D14+M18*$D18+M22*$D22+$D2*M2 -> 0.453 | N26: =+N6*$D6+N10*$D10+N14*$D14+N18*$D18+N22*$D22+$D2*N2 -> 0.473
A28: Financials | B28: Private Equity | C28: Finance & Accounting | D28: 0.2 | E28: Transaction processing & reconciliation | F28: 0.3 | G28: Task Processing / Query Handling | H28: 0.9 | I28: =SUMPRODUCT(H28:H31,F28:F31)*D28 -> 0.1655 | J28: 0.68 | K28: 0.68 | L28: 0.65 | M28: 0.61 | N28: 0.58
A29: Financials | B29: Private Equity | C29: Finance & Accounting | D29: 0.2 | E29: Financial planning & analysis | F29: 0.25 | G29: Assessment & Analysis | H29: 0.6 | J29: 0.68 | K29: 0.68 | L29: 0.65 | M29: 0.61 | N29: 0.58
A30: Financials | B30: Private Equity | C30: Finance & Accounting | D30: 0.2 | E30: Budgeting & forecasting | F30: 0.2 | G30: Modelling (incl. Forecasting) | H30: 0.85 | J30: 0.68 | K30: 0.68 | L30: 0.65 | M30: 0.61 | N30: 0.58
A31: Financials | B31: Private Equity | C31: Finance & Accounting | D31: 0.2 | E31: Financial reporting | F31: 0.25 | G31: Document Generation & Management | H31: 0.95 | J31: 0.68 | K31: 0.68 | L31: 0.65 | M31: 0.61 | N31: 0.58
A32: Financials | B32: Private Equity | C32: Human Resources | D32: 0.15 | E32: Recruitment administration | F32: 0.25 | G32: Task Processing / Query Handling | H32: 0.9 | I32: =SUMPRODUCT(H32:H35,F32:F35)*D32 -> 0.093 | J32: 0.48 | K32: 0.48 | L32: 0.45 | M32: 0.41 | N32: 0.38
A33: Financials | B33: Private Equity | C33: Human Resources | D33: 0.15 | E33: Workforce planning | F33: 0.25 | G33: Task Planning & Management | H33: 0.7 | J33: 0.48 | K33: 0.48 | L33: 0.45 | M33: 0.41 | N33: 0.38
A34: Financials | B34: Private Equity | C34: Human Resources | D34: 0.15 | E34: Employee relations & support | F34: 0.3 | G34: Stakeholder / Relationship Management | H34: 0.1 | J34: 0.48 | K34: 0.48 | L34: 0.45 | M34: 0.41 | N34: 0.38
A35: Financials | B35: Private Equity | C35: Human Resources | D35: 0.15 | E35: HR documentation & reporting | F35: 0.2 | G35: Document Generation & Management | H35: 0.95 | J35: 0.48 | K35: 0.48 | L35: 0.45 | M35: 0.41 | N35: 0.38
A36: Financials | B36: Private Equity | C36: Corporate IT & Enterprise Technology | D36: 0.15 | E36: IT service desk & user support | F36: 0.3 | G36: Task Processing / Query Handling | H36: 0.9 | I36: =SUMPRODUCT(H36:H39,F36:F39)*D36 -> 0.1215 | J36: 0.68 | K36: 0.68 | L36: 0.65 | M36: 0.61 | N36: 0.58
A37: Financials | B37: Private Equity | C37: Corporate IT & Enterprise Technology | D37: 0.15 | E37: Application, infrastructure & security monitoring | F37: 0.25 | G37: Monitoring | H37: 0.7 | J37: 0.68 | K37: 0.68 | L37: 0.65 | M37: 0.61 | N37: 0.58
A38: Financials | B38: Private Equity | C38: Corporate IT & Enterprise Technology | D38: 0.15 | E38: Technology planning & change coordination | F38: 0.25 | G38: Task Planning & Management | H38: 0.7 | J38: 0.68 | K38: 0.68 | L38: 0.65 | M38: 0.61 | N38: 0.58
A39: Financials | B39: Private Equity | C39: Corporate IT & Enterprise Technology | D39: 0.15 | E39: IT documentation | F39: 0.2 | G39: Document Generation & Management | H39: 0.95 | J39: 0.68 | K39: 0.68 | L39: 0.65 | M39: 0.61 | N39: 0.58
A40: Financials | B40: Private Equity | C40: Legal, Regulatory & Corporate Administration | D40: 0.25 | E40: Regulatory / policy monitoring | F40: 0.25 | G40: Monitoring | H40: 0.7 | I40: =SUMPRODUCT(H40:H43,F40:F43)*D40 -> 0.146875 | J40: 0.45 | K40: 0.45 | L40: 0.42 | M40: 0.38 | N40: 0.35
A41: Financials | B41: Private Equity | C41: Legal, Regulatory & Corporate Administration | D41: 0.25 | E41: Contract & policy review | F41: 0.25 | G41: Assessment & Analysis | H41: 0.6 | J41: 0.45 | K41: 0.45 | L41: 0.42 | M41: 0.38 | N41: 0.35
...

Sheet CD
A1: Sector | B1: Subsector | C1: Core Activity | D1: Effort Split | E1: Key Main Task | F1: % Effort | G1: Category | H1: AI Addressable | I1: Agentification Potential | J1: Actual Agentification Possible | K1: NA | L1: EU | M1: APAC ex India | N1: India
A2: Consumer Discretionary | B2: Consumer Products Manufacturing | C2: Sales & Channel Management | D2: 0.25 | E2: Sales planning & account targeting | F2: 0.25 | G2: Task Planning & Management | H2: 0.7 | I2: =SUMPRODUCT(H2:H5,F2:F5)*D2 -> 0.13 | J2: 0.4 | K2: 0.4 | L2: 0.37 | M2: 0.33 | N2: 0.28
A3: Consumer Discretionary | B3: Consumer Products Manufacturing | C3: Sales & Channel Management | D3: 0.25 | E3: Retailer / distributor relationship management | F3: 0.35 | G3: Stakeholder / Relationship Management | H3: 0.1 | J3: 0.4 | K3: 0.4 | L3: 0.37 | M3: 0.33 | N3: 0.28
A4: Consumer Discretionary | B4: Consumer Products Manufacturing | C4: Sales & Channel Management | D4: 0.25 | E4: Pricing & account analytics | F4: 0.2 | G4: Assessment & Analysis | H4: 0.6 | J4: 0.4 | K4: 0.4 | L4: 0.37 | M4: 0.33 | N4: 0.28
A5: Consumer Discretionary | B5: Consumer Products Manufacturing | C5: Sales & Channel Management | D5: 0.25 | E5: Sales administration & reporting | F5: 0.2 | G5: Document Generation & Management | H5: 0.95 | J5: 0.4 | K5: 0.4 | L5: 0.37 | M5: 0.33 | N5: 0.28
A6: Consumer Discretionary | B6: Consumer Products Manufacturing | C6: Marketing & Brand Management | D6: 0.2 | E6: Campaign & content development | F6: 0.3 | G6: Content Generation | H6: 0.7 | I6: =SUMPRODUCT(H6:H9,F6:F9)*D6 -> 0.091 | J6: 0.35 | K6: 0.35 | L6: 0.32 | M6: 0.28 | N6: 0.2
A7: Consumer Discretionary | B7: Consumer Products Manufacturing | C7: Marketing & Brand Management | D7: 0.2 | E7: Consumer & market analytics | F7: 0.25 | G7: Assessment & Analysis | H7: 0.6 | J7: 0.35 | K7: 0.35 | L7: 0.32 | M7: 0.28 | N7: 0.2
A8: Consumer Discretionary | B8: Consumer Products Manufacturing | C8: Marketing & Brand Management | D8: 0.2 | E8: Brand & campaign planning | F8: 0.25 | G8: Strategy & Design | H8: 0.3 | J8: 0.35 | K8: 0.35 | L8: 0.32 | M8: 0.28 | N8: 0.2
A9: Consumer Discretionary | B9: Consumer Products Manufacturing | C9: Marketing & Brand Management | D9: 0.2 | E9: Agency / stakeholder coordination | F9: 0.2 | G9: Stakeholder / Relationship Management | H9: 0.1 | J9: 0.35 | K9: 0.35 | L9: 0.32 | M9: 0.28 | N9: 0.2
A10: Consumer Discretionary | B10: Consumer Products Manufacturing | C10: Finance & Accounting | D10: 0.2 | E10: Transaction processing & reconciliation | F10: 0.3 | G10: Task Processing / Query Handling | H10: 0.9 | I10: =SUMPRODUCT(H10:H13,F10:F13)*D10 -> 0.1655 | J10: 0.65 | K10: 0.65 | L10: 0.6 | M10: 0.54 | N10: 0.42
A11: Consumer Discretionary | B11: Consumer Products Manufacturing | C11: Finance & Accounting | D11: 0.2 | E11: Financial planning & analysis | F11: 0.25 | G11: Assessment & Analysis | H11: 0.6 | J11: 0.65 | K11: 0.65 | L11: 0.6 | M11: 0.54 | N11: 0.42
A12: Consumer Discretionary | B12: Consumer Products Manufacturing | C12: Finance & Accounting | D12: 0.2 | E12: Budgeting & forecasting | F12: 0.2 | G12: Modelling (incl. Forecasting) | H12: 0.85 | J12: 0.65 | K12: 0.65 | L12: 0.6 | M12: 0.54 | N12: 0.42
A13: Consumer Discretionary | B13: Consumer Products Manufacturing | C13: Finance & Accounting | D13: 0.2 | E13: Financial reporting | F13: 0.25 | G13: Document Generation & Management | H13: 0.95 | J13: 0.65 | K13: 0.65 | L13: 0.6 | M13: 0.54 | N13: 0.42
A14: Consumer Discretionary | B14: Consumer Products Manufacturing | C14: Human Resources | D14: 0.1 | E14: Recruitment administration | F14: 0.25 | G14: Task Processing / Query Handling | H14: 0.9 | I14: =SUMPRODUCT(H14:H17,F14:F17)*D14 -> 0.062 | J14: 0.45 | K14: 0.45 | L14: 0.42 | M14: 0.37 | N14: 0.28
A15: Consumer Discretionary | B15: Consumer Products Manufacturing | C15: Human Resources | D15: 0.1 | E15: Workforce planning | F15: 0.25 | G15: Task Planning & Management | H15: 0.7 | J15: 0.45 | K15: 0.45 | L15: 0.42 | M15: 0.37 | N15: 0.28
A16: Consumer Discretionary | B16: Consumer Products Manufacturing | C16: Human Resources | D16: 0.1 | E16: Employee relations & support | F16: 0.3 | G16: Stakeholder / Relationship Management | H16: 0.1 | J16: 0.45 | K16: 0.45 | L16: 0.42 | M16: 0.37 | N16: 0.28
A17: Consumer Discretionary | B17: Consumer Products Manufacturing | C17: Human Resources | D17: 0.1 | E17: HR documentation & reporting | F17: 0.2 | G17: Document Generation & Management | H17: 0.95 | J17: 0.45 | K17: 0.45 | L17: 0.42 | M17: 0.37 | N17: 0.28
A18: Consumer Discretionary | B18: Consumer Products Manufacturing | C18: Corporate IT & Enterprise Technology | D18: 0.1 | E18: IT service desk & user support | F18: 0.3 | G18: Task Processing / Query Handling | H18: 0.9 | I18: =SUMPRODUCT(H18:H21,F18:F21)*D18 -> 0.081 | J18: 0.65 | K18: 0.65 | L18: 0.61 | M18: 0.55 | N18: 0.43
A19: Consumer Discretionary | B19: Consumer Products Manufacturing | C19: Corporate IT & Enterprise Technology | D19: 0.1 | E19: Application & infrastructure monitoring | F19: 0.25 | G19: Monitoring | H19: 0.7 | J19: 0.65 | K19: 0.65 | L19: 0.61 | M19: 0.55 | N19: 0.43
A20: Consumer Discretionary | B20: Consumer Products Manufacturing | C20: Corporate IT & Enterprise Technology | D20: 0.1 | E20: Technology planning & change coordination | F20: 0.25 | G20: Task Planning & Management | H20: 0.7 | J20: 0.65 | K20: 0.65 | L20: 0.61 | M20: 0.55 | N20: 0.43
A21: Consumer Discretionary | B21: Consumer Products Manufacturing | C21: Corporate IT & Enterprise Technology | D21: 0.1 | E21: IT documentation | F21: 0.2 | G21: Document Generation & Management | H21: 0.95 | J21: 0.65 | K21: 0.65 | L21: 0.61 | M21: 0.55 | N21: 0.43
A22: Consumer Discretionary | B22: Consumer Products Manufacturing | C22: Legal & Corporate Administration | D22: 0.15 | E22: Compliance / policy monitoring | F22: 0.25 | G22: Monitoring | H22: 0.7 | I22: =SUMPRODUCT(H22:H25,F22:F25)*D22 -> 0.088125 | J22: 0.42 | K22: 0.42 | L22: 0.39 | M22: 0.34 | N22: 0.25
A23: Consumer Discretionary | B23: Consumer Products Manufacturing | C23: Legal & Corporate Administration | D23: 0.15 | E23: Contract & policy review | F23: 0.25 | G23: Assessment & Analysis | H23: 0.6 | J23: 0.42 | K23: 0.42 | L23: 0.39 | M23: 0.34 | N23: 0.25
A24: Consumer Discretionary | B24: Consumer Products Manufacturing | C24: Legal & Corporate Administration | D24: 0.15 | E24: Legal / external stakeholder management | F24: 0.25 | G24: Stakeholder / Relationship Management | H24: 0.1 | J24: 0.42 | K24: 0.42 | L24: 0.39 | M24: 0.34 | N24: 0.25
A25: Consumer Discretionary | B25: Consumer Products Manufacturing | C25: Legal & Corporate Administration | D25: 0.15 | E25: Legal & compliance documentation | F25: 0.25 | G25: Document Generation & Management | H25: 0.95 | J25: 0.42 | K25: 0.42 | L25: 0.39 | M25: 0.34 | N25: 0.25
I26: =SUM(I2:I25) -> 0.617625 | J26: =+J6*$D6+J10*$D10+J14*$D14+J18*$D18+J22*$D22+$D2*J2 -> 0.473 | K26: =+K6*$D6+K10*$D10+K14*$D14+K18*$D18+K22*$D22+$D2*K2 -> 0.473 | L26: =+L6*$D6+L10*$D10+L14*$D14+L18*$D18+L22*$D22+$D2*L2 -> 0.438 | M26: =+M6*$D6+M10*$D10+M14*$D14+M18*$D18+M22*$D22+$D2*M2 -> 0.3895 | N26: =+N6*$D6+N10*$D10+N14*$D14+N18*$D18+N22*$D22+$D2*N2 -> 0.3025
A28: Consumer Discretionary | B28: Automotive | C28: Sales & Dealer Management | D28: 0.25 | E28: Sales & demand planning | F28: 0.25 | G28: Task Planning & Management | H28: 0.7 | I28: =SUMPRODUCT(H28:H31,F28:F31)*D28 -> 0.13 | J28: 0.4 | K28: 0.4 | L28: 0.37 | M28: 0.33 | N28: 0.27
A29: Consumer Discretionary | B29: Automotive | C29: Sales & Dealer Management | D29: 0.25 | E29: Dealer / fleet relationship management | F29: 0.35 | G29: Stakeholder / Relationship Management | H29: 0.1 | J29: 0.4 | K29: 0.4 | L29: 0.37 | M29: 0.33 | N29: 0.27
A30: Consumer Discretionary | B30: Automotive | C30: Sales & Dealer Management | D30: 0.25 | E30: Pricing & dealer performance analytics | F30: 0.2 | G30: Assessment & Analysis | H30: 0.6 | J30: 0.4 | K30: 0.4 | L30: 0.37 | M30: 0.33 | N30: 0.27
A31: Consumer Discretionary | B31: Automotive | C31: Sales & Dealer Management | D31: 0.25 | E31: Sales administration & reporting | F31: 0.2 | G31: Document Generation & Management | H31: 0.95 | J31: 0.4 | K31: 0.4 | L31: 0.37 | M31: 0.33 | N31: 0.27
A32: Consumer Discretionary | B32: Automotive | C32: Marketing & Customer Growth | D32: 0.15 | E32: Campaign & content development | F32: 0.3 | G32: Content Generation | H32: 0.7 | I32: =SUMPRODUCT(H32:H35,F32:F35)*D32 -> 0.06825 | J32: 0.35 | K32: 0.35 | L32: 0.32 | M32: 0.28 | N32: 0.2
A33: Consumer Discretionary | B33: Automotive | C33: Marketing & Customer Growth | D33: 0.15 | E33: Customer / market analytics | F33: 0.25 | G33: Assessment & Analysis | H33: 0.6 | J33: 0.35 | K33: 0.35 | L33: 0.32 | M33: 0.28 | N33: 0.2
A34: Consumer Discretionary | B34: Automotive | C34: Marketing & Customer Growth | D34: 0.15 | E34: Brand & campaign planning | F34: 0.25 | G34: Strategy & Design | H34: 0.3 | J34: 0.35 | K34: 0.35 | L34: 0.32 | M34: 0.28 | N34: 0.2
A35: Consumer Discretionary | B35: Automotive | C35: Marketing & Customer Growth | D35: 0.15 | E35: Agency / dealer coordination | F35: 0.2 | G35: Stakeholder / Relationship Management | H35: 0.1 | J35: 0.35 | K35: 0.35 | L35: 0.32 | M35: 0.28 | N35: 0.2
A36: Consumer Discretionary | B36: Automotive | C36: Finance & Accounting | D36: 0.2 | E36: Transaction processing & reconciliation | F36: 0.3 | G36: Task Processing / Query Handling | H36: 0.9 | I36: =SUMPRODUCT(H36:H39,F36:F39)*D36 -> 0.1655 | J36: 0.65 | K36: 0.65 | L36: 0.6 | M36: 0.54 | N36: 0.43
A37: Consumer Discretionary | B37: Automotive | C37: Finance & Accounting | D37: 0.2 | E37: Financial planning & analysis | F37: 0.25 | G37: Assessment & Analysis | H37: 0.6 | J37: 0.65 | K37: 0.65 | L37: 0.6 | M37: 0.54 | N37: 0.43
A38: Consumer Discretionary | B38: Automotive | C38: Finance & Accounting | D38: 0.2 | E38: Budgeting & forecasting | F38: 0.2 | G38: Modelling (incl. Forecasting) | H38: 0.85 | J38: 0.65 | K38: 0.65 | L38: 0.6 | M38: 0.54 | N38: 0.43
A39: Consumer Discretionary | B39: Automotive | C39: Finance & Accounting | D39: 0.2 | E39: Financial reporting | F39: 0.25 | G39: Document Generation & Management | H39: 0.95 | J39: 0.65 | K39: 0.65 | L39: 0.6 | M39: 0.54 | N39: 0.43
A40: Consumer Discretionary | B40: Automotive | C40: Human Resources | D40: 0.15 | E40: Recruitment administration | F40: 0.25 | G40: Task Processing / Query Handling | H40: 0.9 | I40: =SUMPRODUCT(H40:H43,F40:F43)*D40 -> 0.093 | J40: 0.45 | K40: 0.45 | L40: 0.42 | M40: 0.37 | N40: 0.29
A41: Consumer Discretionary | B41: Automotive | C41: Human Resources | D41: 0.15 | E41: Workforce planning | F41: 0.25 | G41: Task Planning & Management | H41: 0.7 | J41: 0.45 | K41: 0.45 | L41: 0.42 | M41: 0.37 | N41: 0.29
...

Sheet Energy
A1: Sector | B1: Subsector | C1: Core Activity | D1: Effort Split | E1: Key Main Task | F1: % Effort | G1: Category | H1: AI Addressable | I1: Agentification Potential | J1: Actual Agentification Possible | K1: NA | L1: EU | M1: APAC ex India | N1: India
A2: Energy | B2: Upstream Oil & Gas | C2: Finance & Accounting | D2: 0.2 | E2: Transaction processing & reconciliation | F2: 0.3 | G2: Task Processing / Query Handling | H2: 0.9 | I2: =SUMPRODUCT(H2:H5,F2:F5)*D2 -> 0.1655 | J2: 0.66 | K2: 0.66 | L2: 0.63 | M2: 0.58 | N2: 0.55
A3: Energy | B3: Upstream Oil & Gas | C3: Finance & Accounting | D3: 0.2 | E3: Financial planning & analysis | F3: 0.25 | G3: Assessment & Analysis | H3: 0.6 | J3: 0.66 | K3: 0.66 | L3: 0.63 | M3: 0.58 | N3: 0.55
A4: Energy | B4: Upstream Oil & Gas | C4: Finance & Accounting | D4: 0.2 | E4: Budgeting & forecasting | F4: 0.2 | G4: Modelling (incl. Forecasting) | H4: 0.85 | J4: 0.66 | K4: 0.66 | L4: 0.63 | M4: 0.58 | N4: 0.55
A5: Energy | B5: Upstream Oil & Gas | C5: Finance & Accounting | D5: 0.2 | E5: Financial reporting | F5: 0.25 | G5: Document Generation & Management | H5: 0.95 | J5: 0.66 | K5: 0.66 | L5: 0.63 | M5: 0.58 | N5: 0.55
A6: Energy | B6: Upstream Oil & Gas | C6: Human Resources | D6: 0.15 | E6: Recruitment administration | F6: 0.25 | G6: Task Processing / Query Handling | H6: 0.9 | I6: =SUMPRODUCT(H6:H9,F6:F9)*D6 -> 0.093 | J6: 0.46 | K6: 0.46 | L6: 0.43 | M6: 0.38 | N6: 0.36
A7: Energy | B7: Upstream Oil & Gas | C7: Human Resources | D7: 0.15 | E7: Workforce planning | F7: 0.25 | G7: Task Planning & Management | H7: 0.7 | J7: 0.46 | K7: 0.46 | L7: 0.43 | M7: 0.38 | N7: 0.36
A8: Energy | B8: Upstream Oil & Gas | C8: Human Resources | D8: 0.15 | E8: Employee relations & support | F8: 0.3 | G8: Stakeholder / Relationship Management | H8: 0.1 | J8: 0.46 | K8: 0.46 | L8: 0.43 | M8: 0.38 | N8: 0.36
A9: Energy | B9: Upstream Oil & Gas | C9: Human Resources | D9: 0.15 | E9: HR documentation & reporting | F9: 0.2 | G9: Document Generation & Management | H9: 0.95 | J9: 0.46 | K9: 0.46 | L9: 0.43 | M9: 0.38 | N9: 0.36
A10: Energy | B10: Upstream Oil & Gas | C10: Corporate IT & Enterprise Technology | D10: 0.15 | E10: IT service desk & user support | F10: 0.3 | G10: Task Processing / Query Handling | H10: 0.9 | I10: =SUMPRODUCT(H10:H13,F10:F13)*D10 -> 0.1215 | J10: 0.65 | K10: 0.65 | L10: 0.62 | M10: 0.57 | N10: 0.54
A11: Energy | B11: Upstream Oil & Gas | C11: Corporate IT & Enterprise Technology | D11: 0.15 | E11: Application, infrastructure & security monitoring | F11: 0.25 | G11: Monitoring | H11: 0.7 | J11: 0.65 | K11: 0.65 | L11: 0.62 | M11: 0.57 | N11: 0.54
A12: Energy | B12: Upstream Oil & Gas | C12: Corporate IT & Enterprise Technology | D12: 0.15 | E12: Technology planning & change coordination | F12: 0.25 | G12: Task Planning & Management | H12: 0.7 | J12: 0.65 | K12: 0.65 | L12: 0.62 | M12: 0.57 | N12: 0.54
A13: Energy | B13: Upstream Oil & Gas | C13: Corporate IT & Enterprise Technology | D13: 0.15 | E13: IT documentation | F13: 0.2 | G13: Document Generation & Management | H13: 0.95 | J13: 0.65 | K13: 0.65 | L13: 0.62 | M13: 0.57 | N13: 0.54
A14: Energy | B14: Upstream Oil & Gas | C14: Legal, Regulatory & Corporate Administration | D14: 0.25 | E14: Regulatory / policy monitoring | F14: 0.25 | G14: Monitoring | H14: 0.7 | I14: =SUMPRODUCT(H14:H17,F14:F17)*D14 -> 0.146875 | J14: 0.43 | K14: 0.43 | L14: 0.4 | M14: 0.35 | N14: 0.32
A15: Energy | B15: Upstream Oil & Gas | C15: Legal, Regulatory & Corporate Administration | D15: 0.25 | E15: Contract & policy review | F15: 0.25 | G15: Assessment & Analysis | H15: 0.6 | J15: 0.43 | K15: 0.43 | L15: 0.4 | M15: 0.35 | N15: 0.32
A16: Energy | B16: Upstream Oil & Gas | C16: Legal, Regulatory & Corporate Administration | D16: 0.25 | E16: Regulator / legal stakeholder management | F16: 0.25 | G16: Stakeholder / Relationship Management | H16: 0.1 | J16: 0.43 | K16: 0.43 | L16: 0.4 | M16: 0.35 | N16: 0.32
A17: Energy | B17: Upstream Oil & Gas | C17: Legal, Regulatory & Corporate Administration | D17: 0.25 | E17: Compliance & corporate documentation | F17: 0.25 | G17: Document Generation & Management | H17: 0.95 | J17: 0.43 | K17: 0.43 | L17: 0.4 | M17: 0.35 | N17: 0.32
A18: Energy | B18: Upstream Oil & Gas | C18: Procurement & Vendor Management | D18: 0.15 | E18: Purchase & vendor administration | F18: 0.25 | G18: Task Processing / Query Handling | H18: 0.9 | I18: =SUMPRODUCT(H18:H21,F18:F21)*D18 -> 0.08925 | J18: 0.46 | K18: 0.46 | L18: 0.43 | M18: 0.38 | N18: 0.35
A19: Energy | B19: Upstream Oil & Gas | C19: Procurement & Vendor Management | D19: 0.15 | E19: Vendor / spend analysis | F19: 0.25 | G19: Assessment & Analysis | H19: 0.6 | J19: 0.46 | K19: 0.46 | L19: 0.43 | M19: 0.38 | N19: 0.35
A20: Energy | B20: Upstream Oil & Gas | C20: Procurement & Vendor Management | D20: 0.15 | E20: Vendor relationship management | F20: 0.3 | G20: Stakeholder / Relationship Management | H20: 0.1 | J20: 0.46 | K20: 0.46 | L20: 0.43 | M20: 0.38 | N20: 0.35
A21: Energy | B21: Upstream Oil & Gas | C21: Procurement & Vendor Management | D21: 0.15 | E21: Contract & procurement documentation | F21: 0.2 | G21: Document Generation & Management | H21: 0.95 | J21: 0.46 | K21: 0.46 | L21: 0.43 | M21: 0.38 | N21: 0.35
A22: Energy | B22: Upstream Oil & Gas | C22: Corporate Strategy & Management | D22: 0.1 | E22: Strategic planning | F22: 0.3 | G22: Strategy & Design | H22: 0.3 | I22: =SUMPRODUCT(H22:H25,F22:F25)*D22 -> 0.0455 | J22: 0.34 | K22: 0.34 | L22: 0.31 | M22: 0.27 | N22: 0.24
A23: Energy | B23: Upstream Oil & Gas | C23: Corporate Strategy & Management | D23: 0.1 | E23: Management / market analysis | F23: 0.25 | G23: Assessment & Analysis | H23: 0.6 | J23: 0.34 | K23: 0.34 | L23: 0.31 | M23: 0.27 | N23: 0.24
A24: Energy | B24: Upstream Oil & Gas | C24: Corporate Strategy & Management | D24: 0.1 | E24: Executive stakeholder coordination | F24: 0.25 | G24: Stakeholder / Relationship Management | H24: 0.1 | J24: 0.34 | K24: 0.34 | L24: 0.31 | M24: 0.27 | N24: 0.24
A25: Energy | B25: Upstream Oil & Gas | C25: Corporate Strategy & Management | D25: 0.1 | E25: Corporate reporting | F25: 0.2 | G25: Document Generation & Management | H25: 0.95 | J25: 0.34 | K25: 0.34 | L25: 0.31 | M25: 0.27 | N25: 0.24
I26: =SUM(I2:I25) -> 0.661625 | J26: =+J6*$D6+J10*$D10+J14*$D14+J18*$D18+J22*$D22+$D2*J2 -> 0.509 | K26: =+K6*$D6+K10*$D10+K14*$D14+K18*$D18+K22*$D22+$D2*K2 -> 0.509 | L26: =+L6*$D6+L10*$D10+L14*$D14+L18*$D18+L22*$D22+$D2*L2 -> 0.479 | M26: =+M6*$D6+M10*$D10+M14*$D14+M18*$D18+M22*$D22+$D2*M2 -> 0.43 | N26: =+N6*$D6+N10*$D10+N14*$D14+N18*$D18+N22*$D22+$D2*N2 -> 0.4015
A28: Energy | B28: Integrated Oil & Gas | C28: Finance & Accounting | D28: 0.2 | E28: Transaction processing & reconciliation | F28: 0.3 | G28: Task Processing / Query Handling | H28: 0.9 | I28: =SUMPRODUCT(H28:H31,F28:F31)*D28 -> 0.1655 | J28: 0.67 | K28: 0.67 | L28: 0.64 | M28: 0.59 | N28: 0.56
A29: Energy | B29: Integrated Oil & Gas | C29: Finance & Accounting | D29: 0.2 | E29: Financial planning & analysis | F29: 0.25 | G29: Assessment & Analysis | H29: 0.6 | J29: 0.67 | K29: 0.67 | L29: 0.64 | M29: 0.59 | N29: 0.56
A30: Energy | B30: Integrated Oil & Gas | C30: Finance & Accounting | D30: 0.2 | E30: Budgeting & forecasting | F30: 0.2 | G30: Modelling (incl. Forecasting) | H30: 0.85 | J30: 0.67 | K30: 0.67 | L30: 0.64 | M30: 0.59 | N30: 0.56
A31: Energy | B31: Integrated Oil & Gas | C31: Finance & Accounting | D31: 0.2 | E31: Financial reporting | F31: 0.25 | G31: Document Generation & Management | H31: 0.95 | J31: 0.67 | K31: 0.67 | L31: 0.64 | M31: 0.59 | N31: 0.56
A32: Energy | B32: Integrated Oil & Gas | C32: Human Resources | D32: 0.15 | E32: Recruitment administration | F32: 0.25 | G32: Task Processing / Query Handling | H32: 0.9 | I32: =SUMPRODUCT(H32:H35,F32:F35)*D32 -> 0.093 | J32: 0.47 | K32: 0.47 | L32: 0.44 | M32: 0.39 | N32: 0.37
A33: Energy | B33: Integrated Oil & Gas | C33: Human Resources | D33: 0.15 | E33: Workforce planning | F33: 0.25 | G33: Task Planning & Management | H33: 0.7 | J33: 0.47 | K33: 0.47 | L33: 0.44 | M33: 0.39 | N33: 0.37
A34: Energy | B34: Integrated Oil & Gas | C34: Human Resources | D34: 0.15 | E34: Employee relations & support | F34: 0.3 | G34: Stakeholder / Relationship Management | H34: 0.1 | J34: 0.47 | K34: 0.47 | L34: 0.44 | M34: 0.39 | N34: 0.37
A35: Energy | B35: Integrated Oil & Gas | C35: Human Resources | D35: 0.15 | E35: HR documentation & reporting | F35: 0.2 | G35: Document Generation & Management | H35: 0.95 | J35: 0.47 | K35: 0.47 | L35: 0.44 | M35: 0.39 | N35: 0.37
A36: Energy | B36: Integrated Oil & Gas | C36: Corporate IT & Enterprise Technology | D36: 0.2 | E36: IT service desk & user support | F36: 0.3 | G36: Task Processing / Query Handling | H36: 0.9 | I36: =SUMPRODUCT(H36:H39,F36:F39)*D36 -> 0.162 | J36: 0.66 | K36: 0.66 | L36: 0.63 | M36: 0.58 | N36: 0.55
