Workbook

Sheet Read Me & Sources
B2: AI Productivity Compression Engine — Methodology & Sourcing
B3: 2030 lens | feeds the 'melting ice' (gross deflation); meltwater / capture-rate handled separately
B5: THE BRIDGE (per service line)
B6: 1. Realised gross productivity % | C6: = Gross agentification % (your workbook) × Max adoption % | D6: Delivery-cost efficiency: how much less effort the same scope takes. NOT revenue loss yet.
B7: 2. Net delivery efficiency % | C7: = Realised gross productivity % − Agent cost ratio % | D7: Agents raise the competitive price floor, shrinking the saving that can be passed on.
B8: 3. Revenue compression % | C8: = Net delivery efficiency % × Effort-linked rev share % × Passback % | D8: Only effort-priced revenue deflates; only the passed-back share becomes lost revenue.
B9: 4. Compression $ | C9: = Size 2030 pre-AI × Revenue compression % | D9: The melting ice per line, in $mn.
B10: 5. GCC leakage (separate pipe) | C10: = Size 2030 pre-AI × GCC exposure % | D10: Work leaving the vendor entirely (insourcing). Distinct from passback — no double-count.
B12: WHY THE FLAT 45% / 10% MUST GO
B13: Your summary tab applies a flat 45% passback and 10% agent cost to every line. That collapses to a near-constant multiplier (~0.74 on new-services TAM; compression ~0.47 x realised gross), which quietly erases the line-level differentiation your task build works hard to create. Result: ADMS and Consulting look far more alike than they are. This engine replaces the two flat levers with differentiated, sourced values and adds the missing effort-linked-share term — widening the ADMS-vs-Consulting compression spread from ~12pp to ~24pp.
B17: EVIDENCE BEHIND EACH LEVER (base case — confirm against house view)
B18: Lever | C18: What the evidence says | D18: Source
B19: Realised uplift (agentification are ceilings) | C19: Lab coding task 55.8% faster; real enterprise codebase ~21%; deployed CX support +14% avg (+34% novices, ~0 experts); consulting +12-28% inside frontier but -19pp outside. Field << lab. | D19: Peng et al. 2023 (MS Research/GitHub); Paradis et al. (Google RCT); Brynjolfsson-Li-Raymond, QJE 2025; Dell'Acqua et al. HBS/BCG 2023
B20: Passback % | C20: Gain-share contracts pricing in 5-10%/yr AI productivity are now the default on IT outsourcing renewals >$50m/yr (since 2024). Flat 45% is too low for ADMS/BPM; jagged frontier protects Consulting. | D20: TechVendorIndex (TCS review 2026); Infosys/TCS pricing-model disclosures
B21: Effort-linked rev share | C21: Infosys FP share ~39-45% of revenue (rest T&M); clients shifting to managed services for predictability; Consulting value-priced & cyclical. Annuity insulates timing, not level. | D21: Infosys 6-K FY15 & 20-F risk factors (SEC EDGAR); Infosys/TCS business-model profiles
B22: Agent cost ratio | C22: Inference cost ~10x/yr decline, tapering to 3-5x thru 2027 then 1.5-2x; BUT token consumption up ~100x for agentic/reasoning loops, so cost-per-task falls slower. Low for text/code, high for voice/multi-agent. | D22: a16z 'LLMflation' 2024; Epoch AI inference price trends 2025; industry token-cost guides 2026
B23: GCC exposure | C23: India GCCs $64.6bn FY24 -> $99-105bn by 2030, 2,100-2,500 centres, 40%+ lead AI strategy; moving up-stack into engineering/D&A. AI cuts insourcing cost -> exposure scales with addressability. | D23: NASSCOM-Zinnov India GCC Landscape 2024/25; PIB Dec 2025
B25: LEGEND
B26: Blue text | C26: Published hardcodes / your inputs (Size, agentification, adoption)
B27: Yellow fill | C27: Assumption levers to confirm (agent cost, effort share, passback, GCC)
B28: Black text | C28: Formulas — do not overtype
B29: Green text | C29: Links to another tab
B31: NOTE: the 8 rows in the engine are your visible summary lines as a worked template. Your full universe sums to $1,558,196mn, so paste the remaining Business-opportunity x Service-line rows below row 13 and the formulas will extend.

Sheet Assumption Logic
A1: Assumption Logic — why each yellow cell holds its value
A2: Base-case values with line-specific reasoning, the evidence anchor, and a keep/refine verdict. Values live (and get edited) in the Compression Engine.
A4: ARCHETYPE MAPPING — the 13 lines inherit 6 service-line archetypes
A5: Levers are set at the service-line archetype level, held constant across business-opportunity buckets. Rationale: pricing/effort economics are a property of the WORK, not the bucket — and bucket differences are already captured upstream in your agentification x adoption inputs (e.g. Trad-ITS Consulting adoption 39.5% vs Digital-Cloud Consulting 56.5%).
A6: Service line as it appears | C6: Maps to | D6: Agent / Effort / Pass / GCC
A7: Application Maintenance & Development | C7: ADMS archetype (same work: app dev + maintenance) | D7: 9 / 88 / 75 / 5
A8: ADMS | C8: ADMS archetype | D8: 9 / 88 / 75 / 5
A9: Business Process Services | C9: BPM archetype (same work: business process ops) | D9: 18 / 85 / 72 / 3
A10: BPM | C10: BPM archetype | D10: 18 / 85 / 72 / 3
A11: Application Implementation & Managed Services (x2 buckets) | C11: App-Impl archetype | D11: 10 / 78 / 68 / 5
A12: Infrastructure Implementation & Managed Services (x2 buckets) | C12: Infra archetype | D12: 14 / 58 / 60 / 4
A13: Consulting (x4 buckets) | C13: Consulting archetype | D13: 7 / 48 / 42 / 2
A14: Data & Analytics | C14: D&A archetype | D14: 12 / 68 / 58 / 4
A15: Optional refinement: if you want a traditional-vs-digital pricing tilt, nudge passback & effort-linkage DOWN for the three Digital buckets (more differentiation / value-pricing) and UP for Trad ITS. Left flat here for defensibility — flag it as a scenario.
A17: PASSBACK % — role: x net efficiency x effort share -> compression
A18: Overall verdict: KEEP base (well-anchored). The AI-era acceleration on top of the historical deflation rate is judgment — sensitivity-test +/-15pp.
A19: Service line | B19: Base | C19: Line-specific logic | D19: Evidence anchor | E19: Keep / Refine
A20: ADMS | B20: 0.75 | C20: Most commoditised, T&M/effort-priced, existing productivity clauses; AI gain-share is now the renewal default. Client captures the most. | D20: TCS renewals: 5-10%/yr AI gain-share default >$50m (TechVendorIndex) | E20: KEEP
A21: BPM | B21: 0.72 | C21: Per-seat / per-transaction; pricing shifting to per-resolution, so automation savings pass through fast. Clients re-benchmark aggressively. | D21: Outcome pricing $0.50-2/resolution (vendor pricing 2026) | E21: KEEP
A22: Application Impl & MS | B22: 0.68 | C22: Project + managed mix; competitive RFPs re-benchmark to AI-native cost; large-deal gain-share. Slightly less than pure T&M lines. | D22: ISG award-pricing deflation; gain-share norms | E22: KEEP
A23: Infrastructure Impl & MS | B23: 0.6 | C23: Structurally high (already cedes 10-30% cumulative over 5yr), but annuity/SLA locks mid-term timing, so not fully passed by 2030. | D23: ISG: infra outsourcing 10-30% cumulative unit-price cut / 5yr; benchmarking clauses | E23: KEEP
A24: Data & Analytics | B24: 0.58 | C24: Delivery/engineering portion re-prices, but advanced analytics/AI is differentiated and often expanding, so blended passback sits mid. | D24: ISG deflation (delivery) offset by scarce-skill premium | E24: KEEP / watch
A25: Consulting | B25: 0.42 | C25: Jagged frontier protects differentiated judgment (AI worsens out-of-frontier work); value-priced, little benchmarking, high switching cost -> vendor retains most. | D25: Dell'Acqua/HBS-BCG 2023 (-19pp outside frontier) | E25: KEEP
A27: AGENT COST RATIO % — role: subtracted from realised gross -> net efficiency
A28: Overall verdict: KEEP base, but the MOST uncertain 2030 input. Refine BPM/Infra with bottoms-up run-cost (multi-agent orchestration).
A29: Service line | B29: Base | C29: Line-specific logic | D29: Evidence anchor | E29: Keep / Refine
A30: Consulting | B30: 0.07 | C30: Mostly text/analysis; light integration; cheap inference and high reuse of outputs. | D30: Copilot ~$19-30/user/mo (~1% of labour) | E30: KEEP
A31: ADMS | B31: 0.09 | C31: Maintenance is text/code-heavy; cheap per-token; high pattern reuse across tickets. | D31: Coding copilot seat cost; token deflation | E31: KEEP
A32: Application Impl & MS | B32: 0.1 | C32: Code-gen seats cheap, but agentic build/test loops burn tokens (consumption up ~100x); moderate integration. | D32: a16z LLMflation; token consumption paradox | E32: KEEP
A33: Data & Analytics | B33: 0.12 | C33: Data pipelines + model inference at scale is compute-heavy; recurring run cost, not one-off. | D33: Inference cost at scale; Forrester TEI | E33: KEEP
A34: Infrastructure Impl & MS | B34: 0.14 | C34: AIOps orchestration + continuous monitoring at scale; integration-heavy; multi-agent workflows. | D34: Forrester TEI: integration/inference dominate TCO | E34: REFINE
A35: BPM | B35: 0.18 | C35: Voice + document AI, heaviest orchestration; failed-session overhead (3-4 billable sessions per genuine resolution) inflates effective cost. | D35: Freddy AI 23-30% resolution -> 3-4 sessions/resolution (vendor data) | E35: REFINE
A37: EFFORT-LINKED REV SHARE % — role: x net efficiency x passback -> compression
A38: Overall verdict: REFINE — firm-level anchor is solid (Infosys FP mix), but per-line splits are judgment. Pull per-service-line pricing mix from vendor disclosures / ISG.
A39: Service line | B39: Base | C39: Line-specific logic | D39: Evidence anchor | E39: Keep / Refine
A40: ADMS | B40: 0.88 | C40: T&M / effort-priced maintenance; billing tracks hours almost 1:1 -> highest linkage. | D40: Infosys: FP ~39-45%, rest T&M (SEC) | E40: REFINE
A41: BPM | B41: 0.85 | C41: Per-FTE / per-transaction headcount pricing; revenue moves with seats/volume. | D41: BPM per-seat/per-transaction norms | E41: REFINE
A42: Application Impl & MS | B42: 0.78 | C42: Project effort + managed component; mostly effort-priced with some fixed/outcome. | D42: Infosys/TCS pricing-model mix | E42: REFINE
A43: Data & Analytics | B43: 0.68 | C43: Engineering/pipeline delivery effort-linked; advanced analytics value-priced -> mid-high. | D43: Mixed delivery vs advisory pricing | E43: REFINE
A44: Infrastructure Impl & MS | B44: 0.58 | C44: Heavy annuity/asset/outcome + already automated; a big slice is not effort-priced. | D44: Managed-services annuity shift (Infosys profile) | E44: REFINE
...

Sheet Compression Engine
A1: AI Productivity Compression Engine — Base Case (2030)
A2: Blue = your hardcodes | Yellow = assumption levers (confirm) | Black = formulas | $mn unless noted
A4: Business opportunity | B4: Service line | C4: Size 2030 pre-AI ($mn) | D4: Gross agentif. % | E4: Max adoption % | F4: Realised gross productivity % | G4: Agent cost ratio % | H4: Net delivery efficiency % | I4: Effort-linked rev share % | J4: Passback % | K4: Compression rate % | L4: GCC exposure % | M4: Vendor-retained base ($mn) | N4: Compression $ (on retained) | O4: GCC leakage $ | P4: Total erosion $ | Q4: Erosion % of size
A5: Digital Business | B5: Application Maintenance & Development | C5: 181044 | D5: 0.742 | E5: 0.597 | F5: =D5*E5 -> 0.442974 | G5: 0.09 | H5: =MAX(F5-G5,0) -> 0.352974 | I5: 0.88 | J5: 0.75 | K5: =H5*I5*J5 -> 0.23296284 | L5: 0.05 | M5: =C5*(1-L5) -> 171991.8 | N5: =M5*K5 -> 40067.698 | O5: =C5*L5 -> 9052.2 | P5: =N5+O5 -> 49119.898 | Q5: =P5/C5 -> 0.2713147
A6: Digital Business | B6: Business Process Services | C6: 134527 | D6: 0.751 | E6: 0.606 | F6: =D6*E6 -> 0.455106 | G6: 0.18 | H6: =MAX(F6-G6,0) -> 0.275106 | I6: 0.85 | J6: 0.72 | K6: =H6*I6*J6 -> 0.16836487 | L6: 0.03 | M6: =C6*(1-L6) -> 130491.19 | N6: =M6*K6 -> 21970.133 | O6: =C6*L6 -> 4035.81 | P6: =N6+O6 -> 26005.943 | Q6: =P6/C6 -> 0.19331393
A7: Digital Business | B7: Consulting | C7: 72691 | D7: 0.617 | E7: 0.371 | F7: =D7*E7 -> 0.228907 | G7: 0.07 | H7: =MAX(F7-G7,0) -> 0.158907 | I7: 0.48 | J7: 0.42 | K7: =H7*I7*J7 -> 0.032035651 | L7: 0.02 | M7: =C7*(1-L7) -> 71237.18 | N7: =M7*K7 -> 2282.1295 | O7: =C7*L7 -> 1453.82 | P7: =N7+O7 -> 3735.9495 | Q7: =P7/C7 -> 0.051394938
A8: Digital Technology & Cloud | B8: Application Implementation & Managed Services | C8: 63624 | D8: 0.79 | E8: 0.608 | F8: =D8*E8 -> 0.48032 | G8: 0.1 | H8: =MAX(F8-G8,0) -> 0.38032 | I8: 0.78 | J8: 0.68 | K8: =H8*I8*J8 -> 0.20172173 | L8: 0.05 | M8: =C8*(1-L8) -> 60442.8 | N8: =M8*K8 -> 12192.626 | O8: =C8*L8 -> 3181.2 | P8: =N8+O8 -> 15373.826 | Q8: =P8/C8 -> 0.24163564
A9: Digital Technology & Cloud | B9: Consulting | C9: 41419 | D9: 0.614 | E9: 0.565 | F9: =D9*E9 -> 0.34691 | G9: 0.07 | H9: =MAX(F9-G9,0) -> 0.27691 | I9: 0.48 | J9: 0.42 | K9: =H9*I9*J9 -> 0.055825056 | L9: 0.02 | M9: =C9*(1-L9) -> 40590.62 | N9: =M9*K9 -> 2265.9736 | O9: =C9*L9 -> 828.38 | P9: =N9+O9 -> 3094.3536 | Q9: =P9/C9 -> 0.074708555
A10: Digital Technology & Cloud | B10: Infrastructure Implementation & Managed Services | C10: 229952 | D10: 0.824 | E10: 0.537 | F10: =D10*E10 -> 0.442488 | G10: 0.14 | H10: =MAX(F10-G10,0) -> 0.302488 | I10: 0.58 | J10: 0.6 | K10: =H10*I10*J10 -> 0.10526582 | L10: 0.04 | M10: =C10*(1-L10) -> 220753.92 | N10: =M10*K10 -> 23237.843 | O10: =C10*L10 -> 9198.08 | P10: =N10+O10 -> 32435.923 | Q10: =P10/C10 -> 0.14105519
A11: Digital Product Engineering | B11: Application Implementation & Managed Services | C11: 199215 | D11: 0.829 | E11: 0.643 | F11: =D11*E11 -> 0.533047 | G11: 0.1 | H11: =MAX(F11-G11,0) -> 0.433047 | I11: 0.78 | J11: 0.68 | K11: =H11*I11*J11 -> 0.22968813 | L11: 0.05 | M11: =C11*(1-L11) -> 189254.25 | N11: =M11*K11 -> 43469.455 | O11: =C11*L11 -> 9960.75 | P11: =N11+O11 -> 53430.205 | Q11: =P11/C11 -> 0.26820372
A12: Digital Product Engineering | B12: Consulting | C12: 13776 | D12: 0.624 | E12: 0.371 | F12: =D12*E12 -> 0.231504 | G12: 0.07 | H12: =MAX(F12-G12,0) -> 0.161504 | I12: 0.48 | J12: 0.42 | K12: =H12*I12*J12 -> 0.032559206 | L12: 0.02 | M12: =C12*(1-L12) -> 13500.48 | N12: =M12*K12 -> 439.56491 | O12: =C12*L12 -> 275.52 | P12: =N12+O12 -> 715.08491 | Q12: =P12/C12 -> 0.051908022
A13: Trad ITS | B13: ADMS | C13: 15408 | D13: 0.806 | E13: 0.626 | F13: =D13*E13 -> 0.504556 | G13: 0.09 | H13: =MAX(F13-G13,0) -> 0.414556 | I13: 0.88 | J13: 0.75 | K13: =H13*I13*J13 -> 0.27360696 | L13: 0.05 | M13: =C13*(1-L13) -> 14637.6 | N13: =M13*K13 -> 4004.9492 | O13: =C13*L13 -> 770.4 | P13: =N13+O13 -> 4775.3492 | Q13: =P13/C13 -> 0.30992661
A14: Trad ITS | B14: BPM | C14: 94317 | D14: 0.751 | E14: 0.606 | F14: =D14*E14 -> 0.455106 | G14: 0.18 | H14: =MAX(F14-G14,0) -> 0.275106 | I14: 0.85 | J14: 0.72 | K14: =H14*I14*J14 -> 0.16836487 | L14: 0.03 | M14: =C14*(1-L14) -> 91487.49 | N14: =M14*K14 -> 15403.28 | O14: =C14*L14 -> 2829.51 | P14: =N14+O14 -> 18232.79 | Q14: =P14/C14 -> 0.19331393
A15: Trad ITS | B15: Infrastructure Implementation & Managed Services | C15: 36242 | D15: 0.824 | E15: 0.537 | F15: =D15*E15 -> 0.442488 | G15: 0.14 | H15: =MAX(F15-G15,0) -> 0.302488 | I15: 0.58 | J15: 0.6 | K15: =H15*I15*J15 -> 0.10526582 | L15: 0.04 | M15: =C15*(1-L15) -> 34792.32 | N15: =M15*K15 -> 3662.4422 | O15: =C15*L15 -> 1449.68 | P15: =N15+O15 -> 5112.1222 | Q15: =P15/C15 -> 0.14105519
A16: Trad ITS | B16: Consulting | C16: 141598 | D16: 0.614 | E16: 0.395 | F16: =D16*E16 -> 0.24253 | G16: 0.07 | H16: =MAX(F16-G16,0) -> 0.17253 | I16: 0.48 | J16: 0.42 | K16: =H16*I16*J16 -> 0.034782048 | L16: 0.02 | M16: =C16*(1-L16) -> 138766.04 | N16: =M16*K16 -> 4826.5671 | O16: =C16*L16 -> 2831.96 | P16: =N16+O16 -> 7658.5271 | Q16: =P16/C16 -> 0.054086407
A17: Digital Technology & Cloud | B17: Data & Analytics | C17: 334383 | D17: 0.778 | E17: 0.559 | F17: =D17*E17 -> 0.434902 | G17: 0.12 | H17: =MAX(F17-G17,0) -> 0.314902 | I17: 0.68 | J17: 0.58 | K17: =H17*I17*J17 -> 0.12419735 | L17: 0.04 | M17: =C17*(1-L17) -> 321007.68 | N17: =M17*K17 -> 39868.303 | O17: =C17*L17 -> 13375.32 | P17: =N17+O17 -> 53243.623 | Q17: =P17/C17 -> 0.15922945
A18: TOTAL / weighted avg | C18: =SUM(C5:C17) -> 1558196 | K18: =N18/M18 -> 0.14256011 | M18: =SUM(M5:M17) -> 1498953.4 | N18: =SUM(N5:N17) -> 213690.96 | O18: =SUM(O5:O17) -> 59242.63 | P18: =SUM(P5:P17) -> 272933.59 | Q18: =P18/C18 -> 0.17515999
A20: GCC-FIRST logic: GCC leakage is stripped from Size (col M = retained base), then compression (col K) hits only the retained base (col N). Total erosion (P) = compression + GCC, i.e. Size x [1-(1-compression)(1-GCC)] — no double-count. Paste remaining rows inside 5:17 so totals capture them; formulas in F,H,K,M,N,O,P,Q copy straight down.

Sheet Passback Sensitivity
A1: Passback Sensitivity — the single biggest swing lever (+/-15pp)
A2: Holds net efficiency, effort share & GCC from the engine; flexes passback only. Compression is on the GCC-retained base. High passback = more compression = more bearish for vendors.
A4: Service line | B4: Size 2030 ($mn) | C4: Net eff. x effort share | D4: Low passback (base -15pp) | E4: Base passback | F4: High passback (base +15pp) | G4: Compression $ - Low | H4: Compression $ - Base | I4: Compression $ - High
A5: ='Compression Engine'!B5 -> Application Maintenance & Development | B5: ='Compression Engine'!C5 -> 181044 | C5: ='Compression Engine'!H5*'Compression Engine'!I5 -> 0.31061712 | D5: =MAX('Compression Engine'!J5-0.15,0) -> 0.6 | E5: ='Compression Engine'!J5 -> 0.75 | F5: =MIN('Compression Engine'!J5+0.15,0.95) -> 0.9 | G5: =$B5*(1-'Compression Engine'!L5)*$C5*D5 -> 32054.159 | H5: =$B5*(1-'Compression Engine'!L5)*$C5*E5 -> 40067.698 | I5: =$B5*(1-'Compression Engine'!L5)*$C5*F5 -> 48081.238
A6: ='Compression Engine'!B6 -> Business Process Services | B6: ='Compression Engine'!C6 -> 134527 | C6: ='Compression Engine'!H6*'Compression Engine'!I6 -> 0.2338401 | D6: =MAX('Compression Engine'!J6-0.15,0) -> 0.57 | E6: ='Compression Engine'!J6 -> 0.72 | F6: =MIN('Compression Engine'!J6+0.15,0.95) -> 0.87 | G6: =$B6*(1-'Compression Engine'!L6)*$C6*D6 -> 17393.022 | H6: =$B6*(1-'Compression Engine'!L6)*$C6*E6 -> 21970.133 | I6: =$B6*(1-'Compression Engine'!L6)*$C6*F6 -> 26547.243
A7: ='Compression Engine'!B7 -> Consulting | B7: ='Compression Engine'!C7 -> 72691 | C7: ='Compression Engine'!H7*'Compression Engine'!I7 -> 0.07627536 | D7: =MAX('Compression Engine'!J7-0.15,0) -> 0.27 | E7: ='Compression Engine'!J7 -> 0.42 | F7: =MIN('Compression Engine'!J7+0.15,0.95) -> 0.57 | G7: =$B7*(1-'Compression Engine'!L7)*$C7*D7 -> 1467.0832 | H7: =$B7*(1-'Compression Engine'!L7)*$C7*E7 -> 2282.1295 | I7: =$B7*(1-'Compression Engine'!L7)*$C7*F7 -> 3097.1757
A8: ='Compression Engine'!B8 -> Application Implementation & Managed Services | B8: ='Compression Engine'!C8 -> 63624 | C8: ='Compression Engine'!H8*'Compression Engine'!I8 -> 0.2966496 | D8: =MAX('Compression Engine'!J8-0.15,0) -> 0.53 | E8: ='Compression Engine'!J8 -> 0.68 | F8: =MIN('Compression Engine'!J8+0.15,0.95) -> 0.83 | G8: =$B8*(1-'Compression Engine'!L8)*$C8*D8 -> 9503.0762 | H8: =$B8*(1-'Compression Engine'!L8)*$C8*E8 -> 12192.626 | I8: =$B8*(1-'Compression Engine'!L8)*$C8*F8 -> 14882.176
A9: ='Compression Engine'!B9 -> Consulting | B9: ='Compression Engine'!C9 -> 41419 | C9: ='Compression Engine'!H9*'Compression Engine'!I9 -> 0.1329168 | D9: =MAX('Compression Engine'!J9-0.15,0) -> 0.27 | E9: ='Compression Engine'!J9 -> 0.42 | F9: =MIN('Compression Engine'!J9+0.15,0.95) -> 0.57 | G9: =$B9*(1-'Compression Engine'!L9)*$C9*D9 -> 1456.6973 | H9: =$B9*(1-'Compression Engine'!L9)*$C9*E9 -> 2265.9736 | I9: =$B9*(1-'Compression Engine'!L9)*$C9*F9 -> 3075.2499
A10: ='Compression Engine'!B10 -> Infrastructure Implementation & Managed Services | B10: ='Compression Engine'!C10 -> 229952 | C10: ='Compression Engine'!H10*'Compression Engine'!I10 -> 0.17544304 | D10: =MAX('Compression Engine'!J10-0.15,0) -> 0.45 | E10: ='Compression Engine'!J10 -> 0.6 | F10: =MIN('Compression Engine'!J10+0.15,0.95) -> 0.75 | G10: =$B10*(1-'Compression Engine'!L10)*$C10*D10 -> 17428.382 | H10: =$B10*(1-'Compression Engine'!L10)*$C10*E10 -> 23237.843 | I10: =$B10*(1-'Compression Engine'!L10)*$C10*F10 -> 29047.304
A11: ='Compression Engine'!B11 -> Application Implementation & Managed Services | B11: ='Compression Engine'!C11 -> 199215 | C11: ='Compression Engine'!H11*'Compression Engine'!I11 -> 0.33777666 | D11: =MAX('Compression Engine'!J11-0.15,0) -> 0.53 | E11: ='Compression Engine'!J11 -> 0.68 | F11: =MIN('Compression Engine'!J11+0.15,0.95) -> 0.83 | G11: =$B11*(1-'Compression Engine'!L11)*$C11*D11 -> 33880.604 | H11: =$B11*(1-'Compression Engine'!L11)*$C11*E11 -> 43469.455 | I11: =$B11*(1-'Compression Engine'!L11)*$C11*F11 -> 53058.305
A12: ='Compression Engine'!B12 -> Consulting | B12: ='Compression Engine'!C12 -> 13776 | C12: ='Compression Engine'!H12*'Compression Engine'!I12 -> 0.07752192 | D12: =MAX('Compression Engine'!J12-0.15,0) -> 0.27 | E12: ='Compression Engine'!J12 -> 0.42 | F12: =MIN('Compression Engine'!J12+0.15,0.95) -> 0.57 | G12: =$B12*(1-'Compression Engine'!L12)*$C12*D12 -> 282.57745 | H12: =$B12*(1-'Compression Engine'!L12)*$C12*E12 -> 439.56491 | I12: =$B12*(1-'Compression Engine'!L12)*$C12*F12 -> 596.55238
A13: ='Compression Engine'!B13 -> ADMS | B13: ='Compression Engine'!C13 -> 15408 | C13: ='Compression Engine'!H13*'Compression Engine'!I13 -> 0.36480928 | D13: =MAX('Compression Engine'!J13-0.15,0) -> 0.6 | E13: ='Compression Engine'!J13 -> 0.75 | F13: =MIN('Compression Engine'!J13+0.15,0.95) -> 0.9 | G13: =$B13*(1-'Compression Engine'!L13)*$C13*D13 -> 3203.9594 | H13: =$B13*(1-'Compression Engine'!L13)*$C13*E13 -> 4004.9492 | I13: =$B13*(1-'Compression Engine'!L13)*$C13*F13 -> 4805.9391
A14: ='Compression Engine'!B14 -> BPM | B14: ='Compression Engine'!C14 -> 94317 | C14: ='Compression Engine'!H14*'Compression Engine'!I14 -> 0.2338401 | D14: =MAX('Compression Engine'!J14-0.15,0) -> 0.57 | E14: ='Compression Engine'!J14 -> 0.72 | F14: =MIN('Compression Engine'!J14+0.15,0.95) -> 0.87 | G14: =$B14*(1-'Compression Engine'!L14)*$C14*D14 -> 12194.263 | H14: =$B14*(1-'Compression Engine'!L14)*$C14*E14 -> 15403.28 | I14: =$B14*(1-'Compression Engine'!L14)*$C14*F14 -> 18612.296
A15: ='Compression Engine'!B15 -> Infrastructure Implementation & Managed Services | B15: ='Compression Engine'!C15 -> 36242 | C15: ='Compression Engine'!H15*'Compression Engine'!I15 -> 0.17544304 | D15: =MAX('Compression Engine'!J15-0.15,0) -> 0.45 | E15: ='Compression Engine'!J15 -> 0.6 | F15: =MIN('Compression Engine'!J15+0.15,0.95) -> 0.75 | G15: =$B15*(1-'Compression Engine'!L15)*$C15*D15 -> 2746.8317 | H15: =$B15*(1-'Compression Engine'!L15)*$C15*E15 -> 3662.4422 | I15: =$B15*(1-'Compression Engine'!L15)*$C15*F15 -> 4578.0528
A16: ='Compression Engine'!B16 -> Consulting | B16: ='Compression Engine'!C16 -> 141598 | C16: ='Compression Engine'!H16*'Compression Engine'!I16 -> 0.0828144 | D16: =MAX('Compression Engine'!J16-0.15,0) -> 0.27 | E16: ='Compression Engine'!J16 -> 0.42 | F16: =MIN('Compression Engine'!J16+0.15,0.95) -> 0.57 | G16: =$B16*(1-'Compression Engine'!L16)*$C16*D16 -> 3102.7931 | H16: =$B16*(1-'Compression Engine'!L16)*$C16*E16 -> 4826.5671 | I16: =$B16*(1-'Compression Engine'!L16)*$C16*F16 -> 6550.341
A17: ='Compression Engine'!B17 -> Data & Analytics | B17: ='Compression Engine'!C17 -> 334383 | C17: ='Compression Engine'!H17*'Compression Engine'!I17 -> 0.21413336 | D17: =MAX('Compression Engine'!J17-0.15,0) -> 0.43 | E17: ='Compression Engine'!J17 -> 0.58 | F17: =MIN('Compression Engine'!J17+0.15,0.95) -> 0.73 | G17: =$B17*(1-'Compression Engine'!L17)*$C17*D17 -> 29557.535 | H17: =$B17*(1-'Compression Engine'!L17)*$C17*E17 -> 39868.303 | I17: =$B17*(1-'Compression Engine'!L17)*$C17*F17 -> 50179.071
A18: TOTAL compression $ | G18: =SUM(G5:G17) -> 164270.98 | H18: =SUM(H5:H17) -> 213690.96 | I18: =SUM(I5:I17) -> 263110.94
A20: The Low->High span here is your defensible compression range. Present it as the band, not a point.

Sheet Segment Split
A1: Segment Split — adoption differs by firm archetype
A2: Specialists adopt fastest (highest ceiling), mid-tiers slowest. Weighted adoption = SUMPRODUCT(multiplier x mix), capped at 100%.
A4: Archetype adoption multipliers (vs base adoption)
A5: Archetype | B5: Adoption multiplier
A6: Digital specialists | B6: 1.25
A7: Large firms | B7: 1
A8: Mid-tiers | B8: 0.8
A10: Per-line revenue mix across archetypes (edit yellow; must sum to 100%)
A11: Service line | B11: Base adoption % | C11: % Specialist | D11: % Large | E11: % Mid-tier | F11: Weighted adoption % | G11: Delta vs base (pp)
A12: ='Compression Engine'!B5 -> Application Maintenance & Development | B12: ='Compression Engine'!E5 -> 0.597 | C12: 0.2 | D12: 0.55 | E12: 0.25 | F12: =MIN(B12*(C12*$B$6+D12*$B$7+E12*$B$8),1) -> 0.597 | G12: =(F12-B12)*100 -> 0
A13: ='Compression Engine'!B6 -> Business Process Services | B13: ='Compression Engine'!E6 -> 0.606 | C13: 0.15 | D13: 0.55 | E13: 0.3 | F13: =MIN(B13*(C13*$B$6+D13*$B$7+E13*$B$8),1) -> 0.592365 | G13: =(F13-B13)*100 -> -1.3635
A14: ='Compression Engine'!B7 -> Consulting | B14: ='Compression Engine'!E7 -> 0.371 | C14: 0.15 | D14: 0.55 | E14: 0.3 | F14: =MIN(B14*(C14*$B$6+D14*$B$7+E14*$B$8),1) -> 0.3626525 | G14: =(F14-B14)*100 -> -0.83475
A15: ='Compression Engine'!B8 -> Application Implementation & Managed Services | B15: ='Compression Engine'!E8 -> 0.608 | C15: 0.3 | D15: 0.5 | E15: 0.2 | F15: =MIN(B15*(C15*$B$6+D15*$B$7+E15*$B$8),1) -> 0.62928 | G15: =(F15-B15)*100 -> 2.128
A16: ='Compression Engine'!B9 -> Consulting | B16: ='Compression Engine'!E9 -> 0.565 | C16: 0.15 | D16: 0.55 | E16: 0.3 | F16: =MIN(B16*(C16*$B$6+D16*$B$7+E16*$B$8),1) -> 0.5522875 | G16: =(F16-B16)*100 -> -1.27125
A17: ='Compression Engine'!B10 -> Infrastructure Implementation & Managed Services | B17: ='Compression Engine'!E10 -> 0.537 | C17: 0.2 | D17: 0.55 | E17: 0.25 | F17: =MIN(B17*(C17*$B$6+D17*$B$7+E17*$B$8),1) -> 0.537 | G17: =(F17-B17)*100 -> 0
A18: ='Compression Engine'!B11 -> Application Implementation & Managed Services | B18: ='Compression Engine'!E11 -> 0.643 | C18: 0.3 | D18: 0.5 | E18: 0.2 | F18: =MIN(B18*(C18*$B$6+D18*$B$7+E18*$B$8),1) -> 0.665505 | G18: =(F18-B18)*100 -> 2.2505
A19: ='Compression Engine'!B12 -> Consulting | B19: ='Compression Engine'!E12 -> 0.371 | C19: 0.15 | D19: 0.55 | E19: 0.3 | F19: =MIN(B19*(C19*$B$6+D19*$B$7+E19*$B$8),1) -> 0.3626525 | G19: =(F19-B19)*100 -> -0.83475
A20: ='Compression Engine'!B13 -> ADMS | B20: ='Compression Engine'!E13 -> 0.626 | C20: 0.2 | D20: 0.55 | E20: 0.25 | F20: =MIN(B20*(C20*$B$6+D20*$B$7+E20*$B$8),1) -> 0.626 | G20: =(F20-B20)*100 -> 0
A21: ='Compression Engine'!B14 -> BPM | B21: ='Compression Engine'!E14 -> 0.606 | C21: 0.15 | D21: 0.55 | E21: 0.3 | F21: =MIN(B21*(C21*$B$6+D21*$B$7+E21*$B$8),1) -> 0.592365 | G21: =(F21-B21)*100 -> -1.3635
A22: ='Compression Engine'!B15 -> Infrastructure Implementation & Managed Services | B22: ='Compression Engine'!E15 -> 0.537 | C22: 0.15 | D22: 0.55 | E22: 0.3 | F22: =MIN(B22*(C22*$B$6+D22*$B$7+E22*$B$8),1) -> 0.5249175 | G22: =(F22-B22)*100 -> -1.20825
A23: ='Compression Engine'!B16 -> Consulting | B23: ='Compression Engine'!E16 -> 0.395 | C23: 0.15 | D23: 0.55 | E23: 0.3 | F23: =MIN(B23*(C23*$B$6+D23*$B$7+E23*$B$8),1) -> 0.3861125 | G23: =(F23-B23)*100 -> -0.88875
A24: ='Compression Engine'!B17 -> Data & Analytics | B24: ='Compression Engine'!E17 -> 0.559 | C24: 0.3 | D24: 0.5 | E24: 0.2 | F24: =MIN(B24*(C24*$B$6+D24*$B$7+E24*$B$8),1) -> 0.578565 | G24: =(F24-B24)*100 -> 1.9565
A26: To flow this into compression: in the engine, replace Max adoption (col E) with the Weighted adoption (col F) for the segment view. Kept separate here so the base case stays clean.
