Workbook

Sheet Cover
A1: Coforge Integrated Financial Model
A2: Official-source build | Quarterly P&L FY16–Q1FY27 | Annual three statements FY16–FY30E | INR million unless stated
A4: OUTPERFORM framework: order-book conversion, Encora, client mining, people productivity, AI uplift and acquisition deleveraging
A6: Model scope | B6: Quarterly P&L only; annual P&L, detailed balance sheet and cash flow
A7: Historical period | B7: FY16–FY26 plus Q1 FY27 actual
A8: Forecast period | B8: FY27E–FY30E
A9: Source policy | B9: Official Coforge annual reports, quarterly factsheets and investor presentations
A10: Revenue architecture | B10: Retained base + executable-order-book conversion + fresh-order realization + client farming + AI uplift − T&M deflation + Encora − portfolio exits
A11: AI policy | B11: Service category “AI-led Engineering” is not treated as pure AI revenue; only incremental scenario uplift is modeled as AI revenue
A12: Acquisition policy | B12: Encora revenue, PPA, share consideration, acquisition debt, interest and principal are separated
A13: Cash policy | B13: Historical closing cash is anchored to the reported balance sheet; forecast cash is CFO + CFI + CFF
A14: Circularity policy | B14: One-way flow: assumptions / drivers → P&L → non-cash BS schedules → cash flow → cash → balance sheet
A15: Formatting | B15: Aptos Narrow 10; hardcoded actuals medium blue; formulas black; forecast columns pale green
A16: House view | B16: OUTPERFORM
A17: Model status | B17: =Checks!B6 -> OK

Sheet Summary
A1: Coforge Financial Summary
A2: OUTPERFORM: operating momentum, Encora integration, cash generation, deleveraging and valuation
A5: Metric | B5: FY16A | C5: FY17A | D5: FY18A | E5: FY19A | F5: FY20A | G5: FY21A | H5: FY22A | I5: FY23A | J5: FY24A | K5: FY25A | L5: FY26A | M5: FY27E | N5: FY28E | O5: FY29E | P5: FY30E
A7: Revenue | B7: ='Annual P&L'!C7 -> 26824.049 | C7: ='Annual P&L'!D7 -> 28021 | D7: ='Annual P&L'!E7 -> 29914 | E7: ='Annual P&L'!F7 -> 36762 | F7: ='Annual P&L'!G7 -> 41839 | G7: ='Annual P&L'!H7 -> 46628 | H7: ='Annual P&L'!I7 -> 64320 | I7: ='Annual P&L'!J7 -> 80146 | ... P7: ='Annual P&L'!Q7 -> 457101.52
A8: Revenue growth | B8: ='Annual P&L'!C8 -> 0 | C8: ='Annual P&L'!D8 -> 0.044622317 | D8: ='Annual P&L'!E8 -> 0.067556476 | E8: ='Annual P&L'!F8 -> 0.22892291 | F8: ='Annual P&L'!G8 -> 0.13810456 | G8: ='Annual P&L'!H8 -> 0.11446258 | H8: ='Annual P&L'!I8 -> 0.37942867 | I8: ='Annual P&L'!J8 -> 0.246051 | ... P8: ='Annual P&L'!Q8 -> 0.2366927
A9: Revenue | B9: ='Order Book & Revenue'!C33 -> 0 | C9: ='Order Book & Revenue'!D33 -> 0 | D9: ='Order Book & Revenue'!E33 -> 0 | E9: ='Order Book & Revenue'!F33 -> 0 | F9: ='Order Book & Revenue'!G33 -> 0 | G9: ='Order Book & Revenue'!H33 -> 0 | H9: ='Order Book & Revenue'!I33 -> 866.5 | I9: ='Order Book & Revenue'!J33 -> 1001.7 | ... P9: ='Order Book & Revenue'!Q33 -> 4712.3868
A10: Executable order book | B10: ='Order Book & Revenue'!C10 -> 301 | C10: ='Order Book & Revenue'!D10 -> 320 | D10: ='Order Book & Revenue'!E10 -> 339 | E10: ='Order Book & Revenue'!F10 -> 390 | F10: ='Order Book & Revenue'!G10 -> 468 | G10: ='Order Book & Revenue'!H10 -> 520 | H10: ='Order Book & Revenue'!I10 -> 720 | I10: ='Order Book & Revenue'!J10 -> 869 | ... P10: ='Order Book & Revenue'!Q10 -> 2903.2106
A11: Fresh order intake | B11: ='Order Book & Revenue'!C15 -> 420 | C11: ='Order Book & Revenue'!D15 -> 457 | D11: ='Order Book & Revenue'!E15 -> 507 | E11: ='Order Book & Revenue'!F15 -> 646 | F11: ='Order Book & Revenue'!G15 -> 748 | G11: ='Order Book & Revenue'!H15 -> 781 | H11: ='Order Book & Revenue'!I15 -> 1151 | I11: ='Order Book & Revenue'!J15 -> 1265 | ... P11: ='Order Book & Revenue'!Q15 -> 3222.0199
A12: Gross margin | B12: ='Annual P&L'!C11 -> 0.41489825 | C12: ='Annual P&L'!D11 -> 0.40566004 | D12: ='Annual P&L'!E11 -> 0.40101625 | E12: ='Annual P&L'!F11 -> 0.40637071 | F12: ='Annual P&L'!G11 -> 0.37517627 | G12: ='Annual P&L'!H11 -> 0.35461525 | H12: ='Annual P&L'!I11 -> 0.37702114 | I12: ='Annual P&L'!J11 -> 0.39072443 | ... P12: ='Annual P&L'!Q11 -> 0.353
A13: Adjusted EBITDA margin | B13: ='Annual P&L'!C14 -> 0.18049929 | C13: ='Annual P&L'!D14 -> 0.17108597 | D13: ='Annual P&L'!E14 -> 0.1675804 | E13: ='Annual P&L'!F14 -> 0.17640498 | F13: ='Annual P&L'!G14 -> 0.17287698 | G13: ='Annual P&L'!H14 -> 0.16717423 | H13: ='Annual P&L'!I14 -> 0.1713153 | I13: ='Annual P&L'!J14 -> 0.15979587 | ... P13: ='Annual P&L'!Q14 -> 0.223
A14: EBITDA | B14: ='Annual P&L'!C16 -> 4841.7219 | C14: ='Annual P&L'!D16 -> 4794 | D14: ='Annual P&L'!E16 -> 5013 | E14: ='Annual P&L'!F16 -> 6485 | F14: ='Annual P&L'!G16 -> 7233 | G14: ='Annual P&L'!H16 -> 7795 | H14: ='Annual P&L'!I16 -> 11019 | I14: ='Annual P&L'!J16 -> 12807 | ... P14: ='Annual P&L'!Q16 -> 99191.03
A15: EBIT margin | B15: ='Annual P&L'!C20 -> 0.13944309 | C15: ='Annual P&L'!D20 -> 0.12551301 | D15: ='Annual P&L'!E20 -> 0.12499164 | E15: ='Annual P&L'!F20 -> 0.14245688 | F15: ='Annual P&L'!G20 -> 0.131528 | G15: ='Annual P&L'!H20 -> 0.12779875 | H15: ='Annual P&L'!I20 -> 0.13599192 | I15: ='Annual P&L'!J20 -> 0.12754224 | ... P15: ='Annual P&L'!Q20 -> 0.177
A16: Net income | B16: ='Annual P&L'!C30 -> 2799.6308 | C16: ='Annual P&L'!D30 -> 2501 | D16: ='Annual P&L'!E30 -> 2802 | E16: ='Annual P&L'!F30 -> 4033 | F16: ='Annual P&L'!G30 -> 4440 | G16: ='Annual P&L'!H30 -> 4556 | H16: ='Annual P&L'!I30 -> 6617 | I16: ='Annual P&L'!J30 -> 6938 | ... P16: ='Annual P&L'!Q30 -> 61734.403
A17: Diluted EPS | B17: ='Annual P&L'!C35 -> 9.11 | C17: ='Annual P&L'!D35 -> 8.142 | D17: ='Annual P&L'!E35 -> 9.068 | E17: ='Annual P&L'!F35 -> 12.946 | F17: ='Annual P&L'!G35 -> 14.194 | G17: ='Annual P&L'!H35 -> 14.658 | H17: ='Annual P&L'!I35 -> 21.304 | I17: ='Annual P&L'!J35 -> 22.306 | ... P17: ='Annual P&L'!Q35 -> 145.25742
A18: CFO | B18: ='Annual Cash Flow'!C19 -> 3602.9216 | C18: ='Annual Cash Flow'!D19 -> 4723 | D18: ='Annual Cash Flow'!E19 -> 3824 | E18: ='Annual Cash Flow'!F19 -> 4527 | F18: ='Annual Cash Flow'!G19 -> 2969 | G18: ='Annual Cash Flow'!H19 -> 7623 | H18: ='Annual Cash Flow'!I19 -> 7656 | I18: ='Annual Cash Flow'!J19 -> 9505 | ... P18: ='Annual Cash Flow'!Q19 -> 67071.397
A19: Free cash flow | B19: ='Annual Cash Flow'!C44 -> 1993.805 | C19: ='Annual Cash Flow'!D44 -> 4723 | D19: ='Annual Cash Flow'!E44 -> 3824 | E19: ='Annual Cash Flow'!F44 -> 4527 | F19: ='Annual Cash Flow'!G44 -> 2969 | G19: ='Annual Cash Flow'!H44 -> 7623 | H19: ='Annual Cash Flow'!I44 -> 6115 | I19: ='Annual Cash Flow'!J44 -> 7923 | ... P19: ='Annual Cash Flow'!Q44 -> 53358.352
A20: Closing cash | B20: ='Annual Cash Flow'!C41 -> 2878.6273 | C20: ='Annual Cash Flow'!D41 -> 3502 | D20: ='Annual Cash Flow'!E41 -> 4102 | E20: ='Annual Cash Flow'!F41 -> 5194 | F20: ='Annual Cash Flow'!G41 -> 8195 | G20: ='Annual Cash Flow'!H41 -> 7999 | H20: ='Annual Cash Flow'!I41 -> 4468 | I20: ='Annual Cash Flow'!J41 -> 5699 | ... P20: ='Annual Cash Flow'!Q41 -> 29969.931
A21: Acquisition debt | M21: ='Acquisition & Debt'!C17 -> 490 | N21: ='Acquisition & Debt'!D17 -> 270 | O21: ='Acquisition & Debt'!E17 -> 0 | P21: ='Acquisition & Debt'!F17 -> 0
A22: Headcount | B22: ='People & AI'!C7 -> 9476 | C22: ='People & AI'!D7 -> 8853 | D22: ='People & AI'!E7 -> 9423 | E22: ='People & AI'!F7 -> 10263 | F22: ='People & AI'!G7 -> 11156 | G22: ='People & AI'!H7 -> 12391 | H22: ='People & AI'!I7 -> 22500 | I22: ='People & AI'!J7 -> 23224 | ... P22: ='People & AI'!Q7 -> 58687.431
A23: Billable headcount | B23: ='People & AI'!C10 -> 8743 | C23: ='People & AI'!D10 -> 8066 | D23: ='People & AI'!E10 -> 8588 | E23: ='People & AI'!F10 -> 9363 | F23: ='People & AI'!G10 -> 10274 | G23: ='People & AI'!H10 -> 11469 | H23: ='People & AI'!I10 -> 21294 | I23: ='People & AI'!J10 -> 21815 | ... P23: ='People & AI'!Q10 -> 55186.887
A24: Revenue / IT billable | B24: ='People & AI'!C14 -> 0 | C24: ='People & AI'!D14 -> 0 | D24: ='People & AI'!E14 -> 0 | E24: ='People & AI'!F14 -> 0 | F24: ='People & AI'!G14 -> 0 | G24: ='People & AI'!H14 -> 0 | H24: ='People & AI'!I14 -> 0 | I24: ='People & AI'!J14 -> 0 | ... P24: ='People & AI'!Q14 -> 113852.82
A25: Incremental AI revenue | B25: ='People & AI'!C21 -> 0 | C25: ='People & AI'!D21 -> 0 | D25: ='People & AI'!E21 -> 0 | E25: ='People & AI'!F21 -> 0 | F25: ='People & AI'!G21 -> 0 | G25: ='People & AI'!H21 -> 0 | H25: ='People & AI'!I21 -> 0 | I25: ='People & AI'!J21 -> 0 | ... P25: ='People & AI'!Q21 -> 148.15445
A26: T&M AI deflation drag | B26: ='People & AI'!C20 -> 0 | C26: ='People & AI'!D20 -> 0 | D26: ='People & AI'!E20 -> 0 | E26: ='People & AI'!F20 -> 0 | F26: ='People & AI'!G20 -> 0 | G26: ='People & AI'!H20 -> 0 | H26: ='People & AI'!I20 -> 0 | I26: ='People & AI'!J20 -> 0 | ... P26: ='People & AI'!Q20 -> -10.000425
A27: Reference market price | B27: =Valuation!C7 -> 99.339996 | C27: =Valuation!D7 -> 87.120003 | D27: =Valuation!E7 -> 173 | E27: =Valuation!F7 -> 266.79001 | F27: =Valuation!G7 -> 229.55 | G27: =Valuation!H7 -> 585.39001 | H27: =Valuation!I7 -> 891.5 | I27: =Valuation!J7 -> 762.82001 | ... P27: =Valuation!Q7 -> 1981.5
A28: P/E | B28: =Valuation!C14 -> 10.9045 | C28: =Valuation!D14 -> 10.700074 | D28: =Valuation!E14 -> 19.078077 | E28: =Valuation!F14 -> 20.60791 | F28: =Valuation!G14 -> 16.172327 | G28: =Valuation!H14 -> 39.936554 | H28: =Valuation!I14 -> 41.846602 | I28: =Valuation!J14 -> 34.197974 | ... P28: =Valuation!Q14 -> 13.6413
A29: EV / EBITDA | B29: =Valuation!C16 -> 5.6241178 | C29: =Valuation!D16 -> 4.7475772 | D29: =Valuation!E16 -> 9.8649055 | E29: =Valuation!F16 -> 11.971581 | F29: =Valuation!G16 -> 8.6850726 | G29: =Valuation!H16 -> 22.300698 | H29: =Valuation!I16 -> 25.039383 | I29: =Valuation!J16 -> 18.339466 | ... P29: =Valuation!Q16 -> 8.250774
A30: Blended target price | B30: =Valuation!C32 -> 0 | C30: =Valuation!D32 -> 0 | D30: =Valuation!E32 -> 0 | E30: =Valuation!F32 -> 0 | F30: =Valuation!G32 -> 0 | G30: =Valuation!H32 -> 0 | H30: =Valuation!I32 -> 0 | I30: =Valuation!J32 -> 0 | ... P30: =Valuation!Q32 -> 3981.1948
A31: Upside / (downside) | B31: =Valuation!C33 -> 0 | C31: =Valuation!D33 -> 0 | D31: =Valuation!E33 -> 0 | E31: =Valuation!F33 -> 0 | F31: =Valuation!G33 -> 0 | G31: =Valuation!H33 -> 0 | H31: =Valuation!I33 -> 0 | I31: =Valuation!J33 -> 0 | ... P31: =Valuation!Q33 -> 1.0091823
A32: Rating | B32: =Valuation!C34 -> 0 | C32: =Valuation!D34 -> 0 | D32: =Valuation!E34 -> 0 | E32: =Valuation!F34 -> 0 | F32: =Valuation!G34 -> 0 | G32: =Valuation!H34 -> 0 | H32: =Valuation!I34 -> 0 | I32: =Valuation!J34 -> 0 | ... P32: =Valuation!Q34 -> OUTPERFORM

Sheet Sources
A1: Sources & Data Conventions
A2: Primary-source register; non-disclosed metrics remain blank and forecast assumptions are visibly editable
A5: ID | B5: Data / period | C5: Units | D5: Primary source | E5: Model use | F5: Status | G5: Notes
A6: S1 | B6: Annual reports FY16–FY26 | C6: ₹m | D6: https://investors.coforge.com/annual-report | E6: Audited P&L, balance sheet and cash flow | F6: Loaded | G6: Latest comparative presentation used where applicable
A7: S2 | B7: Quarterly factsheets FY16–FY25 | C7: ₹m / $m / % / # | D7: https://investors.coforge.com/quarter-reports | E7: Quarterly P&L and operating KPI history | F7: Loaded | G7: Reported figures retained; annual restatement bridge shown separately
A8: S3 | B8: Q4 FY26 presentation | C8: $m / ₹m / % / # | D8: https://investors.coforge.com/hubfs/Investor-Presentation-and-Factsheet-Q4FY26.pdf | E8: FY26 operations, order intake, order book, clients, people and mix | F8: Loaded | G8: FY26 revenue ₹164,027m / $1,870m
A9: S4 | B9: Q1 FY27 presentation | C9: $m / ₹m / % / # | D9: https://investors.coforge.com/hubfs/Investor-Presentation-Q1-FY27.pdf | E9: Q1 actuals, Encora, PPA, debt, operating metrics | F9: Loaded | G9: Encora consolidated from 1 May 2026
A10: S5 | B10: Q1 FY27 results | C10: ₹m | D10: https://investors.coforge.com/quarter-reports | E10: Q1 reported P&L | F10: Loaded | G10: Revenue ₹55,277m; attributable PAT ₹5,186m
A11: S6 | B11: Continuous NIIT Technologies / Coforge prices from listing | C11: ₹ / share | D11: https://finance.yahoo.com/quote/COFORGE.NS/history/ | E11: Daily price history, FY05–FY26 year-end prices and valuation reference price | F11: Loaded | G11: Continuous backfilled listed-company series. NSE states NIITTECH traded from Aug-2004 to Aug-2020 and COFORGE since Aug-2020: https://nsearchives.nseindia.com/corporate/COFORGE_16112021040103_SEIntimation.pdf
A12: S7 | B12: Historical AI revenue | C12: n/a | D12: n/a | E12: Forecast policy | F12: Not disclosed | G12: AI-led Engineering mix is not equated to pure AI revenue
A13: S8 | B13: Historical cash-flow residuals | C13: ₹m | D13: Audited CFS totals | E13: Line-by-line reconciliation | F13: Calculated | G13: Reported residual/reclassification is formula-derived; forecast residual is zero
A14: S9 | B14: Assets / liabilities held for sale | C14: ₹m | D14: Audited balance-sheet totals | E14: Historical classification bridge | F14: Calculated | G14: Derived from reported subtotals when PDF extraction obscures the row

Sheet Assumptions
A1: Forecast Assumptions
A2: Blue text on yellow = editable; all forecast financials and valuations are calculated
A5: Driver | B5: Units | C5: FY27E | D5: FY28E | E5: FY29E | F5: FY30E | G5: Logic / interpretation
A6: Repeat / retained base | B6: % | C6: 0.955 | D6: 0.957 | E6: 0.96 | F6: 0.962 | G6: Prior-year revenue retained before incremental drivers
A7: Executable order book growth | B7: % | C7: 0.12 | D7: 0.1 | E7: 0.09 | F7: 0.08 | G7: Next-12-month executable order book
A8: Incremental order-book realization | B8: % | C8: 0.04 | D8: 0.042 | E8: 0.044 | F8: 0.045 | G8: Current-year revenue from EOB expansion
A9: Fresh order intake growth | B9: % | C9: 0.1 | D9: 0.1 | E9: 0.09 | F9: 0.08 | G9: Annual order-intake scenario
A10: Fresh order first-year realization | B10: % | C10: 0.06 | D10: 0.062 | E10: 0.065 | F10: 0.067 | G10: Current-year revenue from incremental order intake
A11: Client farming / pricing uplift | B11: % | C11: 0.01 | D11: 0.015 | E11: 0.015 | F11: 0.015 | G11: Mining, pricing and cross-sell uplift on retained base
A12: T&M mix | B12: % | C12: 0.57 | D12: 0.56 | E12: 0.55 | F12: 0.54 | G12: Q1 FY27 actual is 57%
A13: AI deflation on T&M revenue | B13: % | C13: 0.01 | D13: 0.01 | E13: 0.008 | F13: 0.005 | G13: Productivity / rate drag on the T&M pool
A14: Outcome-pricing offset | B14: % | C14: 0.008 | D14: 0.01 | E14: 0.012 | F14: 0.013 | G14: Value capture from fixed/outcome pricing
A15: Incremental AI uplift | B15: % | C15: 0.02 | D15: 0.03 | E15: 0.035 | F15: 0.04 | G15: Incremental AI-led revenue; not a historical disclosure
A16: Portfolio exits | B16: $m | C16: 19 | D16: 0 | E16: 0 | F16: 0 | G16: $15m India Government portfolio + $4m data-center impact
A17: Encora monthly run-rate | B17: $m | C17: 50.35 | G17: Q1 FY27 disclosed $100.7m for two months
A18: Encora growth | B18: % | C18: 0.05 | D18: 0.1 | E18: 0.1 | F18: 0.09 | G18: Separate acquired-revenue growth
A19: Average INR / USD | B19: ₹ / $ | C19: 94 | D19: 95 | E19: 96 | F19: 97 | G19: Forecast translation rate
A20: Gross margin | B20: % | C20: 0.343 | D20: 0.347 | E20: 0.35 | F20: 0.353 | G20: Scale, offshore and portfolio mix
A21: SG&A / revenue | B21: % | C21: 0.138 | D21: 0.135 | E21: 0.132 | F21: 0.13 | G21: Selling / general administration
A22: SBC / revenue | B22: % | C22: 0.006 | D22: 0.006 | E22: 0.006 | F22: 0.006 | G22: Share-based compensation
A23: D&A / revenue | B23: % | C23: 0.049 | D23: 0.046 | E23: 0.043 | F23: 0.04 | G23: Includes Encora intangible amortization
A24: Other income / revenue | B24: % | C24: 0.005 | D24: 0.005 | E24: 0.005 | F24: 0.005 | G24: Non-operating income excluding financing cost
A25: Effective tax rate | B25: % | C25: 0.25 | D25: 0.25 | E25: 0.25 | F25: 0.25 | G25: P&L tax rate
A26: NCI share of post-tax profit | B26: % | C26: 0.02 | D26: 0.015 | E26: 0.01 | F26: 0.01 | G26: Minority share
A27: Billed receivable days | B27: days | C27: 65 | D27: 64 | E27: 63 | F27: 62 | G27: Closing billed receivables
A28: Unbilled + contract asset days | B28: days | C28: 39 | D28: 37 | E28: 35 | F28: 33 | G28: Q1 FY27: 24 unbilled + 15 contract asset days
A29: Contract cost / revenue | B29: % | C29: 0.03 | D29: 0.028 | E29: 0.026 | F29: 0.024 | G29: Capitalized contract acquisition / fulfilment costs
... A54: DCF valuation weight | B54: % | C54: 0.3 | D54: 0.3 | E54: 0.3 | F54: 0.3 | G54: Blended target weight
A55: Reference market price | B55: ₹ / share | C55: ='COFORGE Prices'!D5445 -> 1981.5 | D55: ='COFORGE Prices'!D5445 -> 1981.5 | E55: ='COFORGE Prices'!D5445 -> 1981.5 | F55: ='COFORGE Prices'!D5445 -> 1981.5 | G55: User input; FY27–FY30 carried unless explicitly changed
A56: FY27 Q1 actual net cash change | B56: ₹m | C56: 2947 | G56: Reported balance-sheet cash movement: ₹13,883m − ₹10,936m
A57: FY27 Q1 actual CFO | B57: ₹m | C57: 5374 | G57: $57.6m translated at Q1 average rate
A58: FY27 Q1 acquisition cash flow | B58: ₹m | C58: -46939 | G58: $503.1m translated at Q1 average rate
A59: FY27 Q1 debt / credit-line inflow | B59: ₹m | C59: 46547 | G59: $498.9m translated at Q1 average rate
A60: FY27 Q1 lease principal | B60: ₹m | C60: -317 | G60: $3.4m translated
A61: FY27 Q1 interest paid | B61: ₹m | C61: -728 | G61: $7.8m translated
A62: FY27 Q1 capex | B62: ₹m | C62: -438 | G62: $4.7m translated
A63: OCI / other reserve movement | B63: ₹m | C63: 0 | D63: 0 | E63: 0 | F63: 0 | G63: Editable reserve movement

Sheet Raw Financials
A1: Raw Reported Financials — Source Layer
A2: Hardcoded official reported inputs only; calculations live downstream
A4: Annual reported P&L
A5: Metric | B5: Units | C5: FY16A | D5: FY17A | E5: FY18A | F5: FY19A | G5: FY20A | H5: FY21A | I5: FY22A | J5: FY23A | K5: FY24A | L5: FY25A | M5: FY26A
A6: Revenue | B6: ₹m | C6: 26824.049 | D6: 28021 | E6: 29914 | F6: 36762 | G6: 41839 | H6: 46628 | I6: 64320 | J6: 80146 | K6: 91790 | L6: 120733 | M6: 164027
A7: Other income | B7: ₹m | C7: 205.4828 | D7: 269 | E7: 391 | F7: 535 | G7: 677 | H7: 326 | I7: 518 | J7: 619 | K7: 614 | L7: 1647 | M7: 732
A8: Total income | B8: ₹m | C8: 27029.532 | D8: 28290 | E8: 30305 | F8: 37297 | G8: 42516 | H8: 46954 | I8: 64838 | J8: 80765 | K8: 92404 | L8: 122380 | M8: 164759
A9: Purchases / stock | B9: ₹m | C9: 308.69553 | D9: 141 | E9: 317 | F9: 291 | G9: 844 | H9: 1935 | I9: 1724 | J9: 551 | K9: 94 | L9: 101 | M9: 65
A10: Employee benefits | B10: ₹m | C10: 15386.102 | D10: 16513 | E10: 17601 | F10: 21532 | G10: 25298 | H10: 28158 | I10: 38346 | J10: 48280 | K10: 55069 | L10: 72241 | M10: 92161
A11: Professional charges | B11: ₹m | L11: 13902 | M11: 21918
A12: Other production expenses | B12: ₹m | L12: 9149 | M12: 12045
A13: Other expenses | B13: ₹m | C13: 6287.5291 | D13: 6573 | E13: 6983 | F13: 8454 | G13: 8464 | H13: 8740 | I13: 13231 | J13: 18508 | K13: 22350 | L13: 8122 | M13: 7374
A14: Finance costs | B14: ₹m | C14: 48.795223 | D14: 60 | E14: 94 | F14: 92 | G14: 155 | H14: 143 | I14: 650 | J14: 806 | K14: 1256 | L14: 1347 | M14: 1686
A15: D&A | B15: ₹m | C15: 1101.2935 | D15: 1277 | E15: 1274 | F15: 1248 | G15: 1730 | H15: 1836 | I15: 2272 | J15: 2585 | K15: 3186 | L15: 4276 | M15: 6819
A16: PBT pre-exceptional | B16: ₹m | C16: 3814.5324 | D16: 3727 | E16: 4036 | F16: 5680 | G16: 6025 | H16: 6142 | I16: 8615 | J16: 10035 | K16: 10449 | L16: 12961 | M16: 21588
A17: Exceptional items | B17: ₹m | C17: 13.156528 | D17: 221 | E17: 0 | F17: 56 | G17: 71 | H17: 180 | I17: 0 | J17: 523 | K17: 0 | L17: 0 | M17: 2260
A18: PBT | B18: ₹m | C18: 3801.3759 | D18: 3506 | E18: 4036 | F18: 5624 | G18: 5954 | H18: 5962 | I18: 8615 | J18: 9512 | K18: 10449 | L18: 12961 | M18: 19328
A19: Current tax | B19: ₹m | C19: 872.66633 | D19: 922 | E19: 1084 | F19: 1387 | G19: 1551 | H19: 1608 | I19: 1774 | J19: 2492 | K19: 2493 | L19: 4033 | M19: 5024
A20: Deferred tax | B20: ₹m | C20: -40.98601 | D20: -137 | E20: -135 | F20: 16 | G20: -273 | H20: -306 | I20: -306 | J20: -431 | K20: -400 | L20: -707 | M20: -2441
A21: Tax | B21: ₹m | C21: 831.68032 | D21: 785 | E21: 949 | F21: 1403 | G21: 1278 | H21: 1302 | I21: 1468 | J21: 2061 | K21: 2093 | L21: 3326 | M21: 2583
A22: Profit incl. NCI | B22: ₹m | C22: 2969.6955 | D22: 2721 | E22: 3087 | F22: 4221 | G22: 4676 | H22: 4660 | I22: 7147 | J22: 7451 | K22: 8356 | L22: 9361 | M22: 17447
A23: NCI | B23: ₹m | C23: 170.06476 | D23: 220 | E23: 285 | F23: 188 | G23: 236 | H23: 104 | I23: 530 | J23: 513 | K23: 276 | L23: 1240 | M23: 1890
A24: Net income attributable | B24: ₹m | C24: 2799.6308 | D24: 2501 | E24: 2802 | F24: 4033 | G24: 4440 | H24: 4556 | I24: 6617 | J24: 6938 | K24: 8080 | L24: 8121 | M24: 15557
... A26: Diluted EPS | B26: ₹ / share | C26: 9.11 | D26: 8.142 | E26: 9.068 | F26: 12.946 | G26: 14.194 | H26: 14.658 | I26: 21.304 | J26: 22.306 | K26: 25.918 | L26: 24.41 | M26: 45.9
A30: Quarterly reported P&L
A31: Metric | B31: Units | C31: Q1 FY16A | D31: Q2 FY16A | E31: Q3 FY16A | F31: Q4 FY16A | G31: Q1 FY17A | H31: Q2 FY17A | I31: Q3 FY17A | J31: Q4 FY17A | K31: Q1 FY18A | L31: Q2 FY18A | M31: Q3 FY18A | N31: Q4 FY18A | O31: Q1 FY19A | P31: Q2 FY19A | Q31: Q3 FY19A | R31: Q4 FY19A | S31: Q1 FY20A | T31: Q2 FY20A | U31: Q3 FY20A | V31: Q4 FY20A | W31: Q1 FY21A | X31: Q2 FY21A | Y31: Q3 FY21A | Z31: Q4 FY21A | AA31: Q1 FY22A | AB31: Q2 FY22A | AC31: Q3 FY22A | AD31: Q4 FY22A | AE31: Q1 FY23A | AF31: Q2 FY23A | AG31: Q3 FY23A | AH31: Q4 FY23A | AI31: Q1 FY24A | AJ31: Q2 FY24A | AK31: Q3 FY24A | AL31: Q4 FY24A | AM31: Q1 FY25A | AN31: Q2 FY25A | AO31: Q3 FY25A | AP31: Q4 FY25A | AQ31: Q1 FY26A | AR31: Q2 FY26A | AS31: Q3 FY26A | AT31: Q4 FY26A | AU31: Q1 FY27A
A32: Revenue | B32: ₹m | C32: 6411 | D32: 6779 | E32: 6787 | F32: 6847 | G32: 6707 | H32: 6929 | I32: 6938 | J32: 7447 | K32: 7089 | L32: 7372 | M32: 7565 | N32: 7888 | O32: 8249 | P32: 9074 | Q32: 9717 | R32: 9722 | S32: 9597 | T32: 10385 | U32: 10734 | V32: 11093 | W32: 10570 | X32: 11537 | Y32: 11906 | Z32: 12615 | AA32: 14616 | AB32: 15694 | AC32: 16581 | AD32: 17429 | AE32: 18294 | AF32: 19594 | AG32: 20558 | AH32: 21700 | AI32: 22210 | AJ32: 22762 | AK32: 23233 | AL32: 23585 | AM32: 24008 | AN32: 30623 | AO32: 33182 | AP32: 34222 | AQ32: 36886 | AR32: 39857 | AS32: 41881 | AT32: 44504 | AU32: 55277
A33: Cost of revenue | B33: ₹m | C33: 4081 | D33: 4256 | E33: 4255 | F33: 4304 | G33: 4356 | H33: 4481 | I33: 4441 | J33: 4625 | K33: 4577 | L33: 4790 | M33: 4812 | N33: 5000 | O33: 5438 | P33: 5897 | Q33: 6280 | R33: 6294 | S33: 6348 | T33: 6796 | U33: 7068 | V33: 7289 | W33: 7241 | X33: 7776 | Y33: 8096 | Z33: 8580 | AA33: 10250 | AB33: 10656 | AC33: 11210 | AD33: 11620 | AE33: 12739 | AF33: 13317 | AG33: 13698 | AH33: 14306 | AI33: 15391.53 | AJ33: 15374 | AK33: 15542.877 | AL33: 15545 | AM33: 16097 | AN33: 20701.148 | AO33: 22165.576 | AP33: 22483 | AQ33: 24326 | AR33: 26299 | AS33: 28112 | AT33: 29204 | AU33: 36343
A34: Gross profit | B34: ₹m | C34: 2330 | D34: 2523 | E34: 2532 | F34: 2543 | G34: 2351 | H34: 2448 | I34: 2497 | J34: 2822 | K34: 2512 | L34: 2582 | M34: 2753 | N34: 2888 | O34: 2811 | P34: 3177 | Q34: 3437 | R34: 3428 | S34: 3249 | T34: 3589 | U34: 3666 | V34: 3804 | W34: 3329 | X34: 3761 | Y34: 3810 | Z34: 4035 | AA34: 4366 | AB34: 5038 | AC34: 5371 | AD34: 5809 | AE34: 5555 | AF34: 6277 | AG34: 6860 | AH34: 7394 | AI34: 6818.47 | AJ34: 7388 | AK34: 7690.123 | AL34: 8040 | AM34: 7911 | AN34: 9921.852 | AO34: 11016.424 | AP34: 11739 | AQ34: 12560 | AR34: 13558 | AS34: 13769 | AT34: 15300 | AU34: 18934
A35: Gross margin | B35: % | C35: 0.364 | D35: 0.372 | E35: 0.373 | F35: 0.371 | G35: 0.351 | H35: 0.353 | I35: 0.36 | J35: 0.379 | K35: 0.354 | L35: 0.35 | M35: 0.364 | N35: 0.366 | O35: 0.341 | P35: 0.35 | Q35: 0.354 | R35: 0.353 | S35: 0.339 | T35: 0.346 | U35: 0.341 | V35: 0.343 | W35: 0.315 | X35: 0.326 | Y35: 0.32 | Z35: 0.32 | AA35: 0.299 | AB35: 0.321 | AC35: 0.324 | AD35: 0.333 | AE35: 0.304 | AF35: 0.32 | AG35: 0.334 | AH35: 0.341 | AI35: 0.307 | AJ35: 0.325 | AK35: 0.331 | AL35: 0.341 | AM35: 0.32951516 | AN35: 0.324 | AO35: 0.332 | AP35: 0.343 | AQ35: 0.341 | AR35: 0.34 | AS35: 0.329 | AT35: 0.344 | AU35: 0.343
A36: SG&A | B36: ₹m | C36: 1288 | D36: 1329 | E36: 1296 | F36: 1282 | G36: 1336 | H36: 1303 | I36: 1335 | J36: 1298 | K36: 1404 | L36: 1391 | M36: 1458 | N36: 1470 | O36: 1505 | P36: 1543 | Q36: 1632 | R36: 1722 | S36: 1843 | T36: 1691 | U36: 1725 | V36: 1816 | W36: 1523 | X36: 1589 | Y36: 1665 | Z36: 1767 | AA36: 2007 | AB36: 2115 | AC36: 2145 | AD36: 2260 | AE36: 2543 | AF36: 2682 | AG36: 3063 | AH36: 3150 | AI36: 3264 | AJ36: 3392 | AK36: 3508 | AL36: 3561 | AM36: 3625 | AN36: 4858.852 | AO36: 5126.424 | AP36: 5868 | AQ36: 6118 | AR36: 6276 | AS36: 6468 | AT36: 6132 | AU36: 7701
A37: Adjusted EBITDA | B37: ₹m | C37: 1042 | D37: 1194 | E37: 1236 | F37: 1261 | G37: 1015 | H37: 1145 | I37: 1162 | J37: 1523 | K37: 1108 | L37: 1191 | M37: 1295 | N37: 1417 | O37: 1306 | P37: 1634 | Q37: 1805 | R37: 1706 | S37: 1406 | T37: 1898 | U37: 1941 | V37: 1988 | W37: 1806 | X37: 2172 | Y37: 2145 | Z37: 2268 | AA37: 2359 | AB37: 2923 | AC37: 3226 | AD37: 3549 | AE37: 3012 | AF37: 3596 | AG37: 3797 | AH37: 4244 | AI37: 3545 | AJ37: 3997 | AK37: 4170 | AL37: 4473 | AM37: 4286 | AN37: 5063 | AO37: 5890 | AP37: 5871 | AQ37: 6442 | AR37: 7282 | AS37: 7301 | AT37: 9168 | AU37: 11233
A38: ESOP | B38: ₹m | C38: 0 | D38: 0 | E38: 0 | F38: 0 | G38: 0 | H38: 0 | I38: 0 | J38: 0 | K38: 0 | L38: 0 | M38: 0 | N38: 0 | O38: 0 | P38: 0 | Q38: 0 | R38: 0 | S38: 0 | T38: 0 | U38: 0 | V38: 17 | W38: 120 | X38: 124 | Y38: 136 | Z38: 100 | AA38: 159 | AB38: 135 | AC38: 158 | AD38: 210 | AE38: 90 | AF38: 147 | AG38: 182 | AH38: 168 | AI38: 216 | AJ38: 519 | AK38: 0 | AL38: 222 | AM38: 199 | AN38: 222 | AO38: 700 | AP38: 616 | AQ38: 593 | AR38: 561 | AS38: 444 | AT38: 381 | AU38: 457
A39: EBITDA | B39: ₹m | C39: 1042 | D39: 1194 | E39: 1236 | F39: 1261 | G39: 1015 | H39: 1145 | I39: 1162 | J39: 1523 | K39: 1108 | L39: 1191 | M39: 1295 | N39: 1417 | O39: 1306 | P39: 1634 | Q39: 1805 | R39: 1706 | S39: 1406 | T39: 1898 | U39: 1940 | V39: 1988 | W39: 1806 | X39: 2172 | Y39: 2145 | Z39: 2268 | AA39: 2359 | AB39: 2923 | AC39: 3020 | AD39: 3293 | AE39: 2918 | AF39: 3444 | AG39: 3615 | AH39: 4076 | AI39: 3316 | AJ39: 3474 | AK39: 4012 | AL39: 4251 | AM39: 4087 | AN39: 4841 | AO39: 5190 | AP39: 5871 | AQ39: 6442 | AR39: 7282 | AS39: 7302 | AT39: 9168 | AU39: 11233
A40: D&A | B40: ₹m | C40: 276 | D40: 265 | E40: 273 | F40: 287 | G40: 326 | H40: 317 | I40: 321 | J40: 312 | K40: 316 | L40: 341 | M40: 311 | N40: 305 | O40: 312 | P40: 319 | Q40: 314 | R40: 303 | S40: 401 | T40: 447 | U40: 449 | V40: 433 | W40: 465 | X40: 460 | Y40: 462 | Z40: 449 | AA40: 524 | AB40: 598 | AC40: 566 | AD40: 584 | AE40: 630 | AF40: 614 | AG40: 624 | AH40: 717 | AI40: 757 | AJ40: 772 | AK40: 811 | AL40: 846 | AM40: 815 | AN40: 0 | AO40: 0 | AP40: 1254 | AQ40: 1592 | AR40: 1719 | AS40: 1708 | AT40: 1800 | AU40: 2411
A41: EBIT | B41: ₹m | C41: 766 | D41: 929 | E41: 963 | F41: 974 | G41: 689 | H41: 828 | I41: 841 | J41: 1211 | K41: 792 | L41: 850 | M41: 984 | N41: 1112 | O41: 994 | P41: 1315 | Q41: 1491 | R41: 1403 | S41: 1005 | T41: 1451 | U41: 1491 | V41: 1555 | W41: 1341 | X41: 1712 | Y41: 1683 | Z41: 1819 | AA41: 1835 | AB41: 2325 | AC41: 2454 | AD41: 2709 | AE41: 2288 | AF41: 2830 | AG41: 2991 | AH41: 3359 | AI41: 2559 | AJ41: 2702 | AK41: 3201 | AL41: 3405 | AM41: 3272 | AN41: 3598 | AO41: 3922 | AP41: 4195 | AQ41: 4858 | AR41: 5563 | AS41: 5594 | AT41: 7368 | AU41: 8822
A42: Other income, net | B42: ₹m | C42: 79 | D42: 13 | E42: 52 | F42: 39 | G42: 83 | H42: 29 | I42: 59 | J42: -12 | K42: 58 | L42: 87 | M42: 5 | N42: 148 | O42: 209 | P42: 215 | Q42: 5 | R42: 47 | S42: 171 | T42: 76 | U42: 130 | V42: 180 | W42: 48 | X42: -63 | Y42: 19 | Z42: 109 | AA42: 52 | AB42: -77 | AC42: -122 | AD42: -119 | AE42: -76 | AF42: -150 | AG42: 83 | AH42: -487 | AI42: -152 | AJ42: -295 | AK42: -257 | AL42: -452 | AM42: -272 | AO42: -327 | AP42: -92 | AR42: -292 | AS42: -208 | AT42: -179 | AU42: -598
A43: FX gain / loss | B43: ₹m | AP43: -170 | AQ43: -44 | AR43: 310 | AS43: -68 | AT43: -403 | AU43: -653
A44: PBT pre-exceptional | B44: ₹m | C44: 845 | D44: 942 | E44: 1015 | F44: 1013 | G44: 772 | H44: 857 | I44: 900 | J44: 1199 | K44: 849 | L44: 937 | M44: 989 | N44: 1261 | O44: 1203 | P44: 1530 | Q44: 1496 | R44: 1451 | S44: 1176 | T44: 1527 | U44: 1621 | V44: 1718 | W44: 1269 | X44: 1525 | Y44: 1566 | Z44: 1782 | AA44: 1632 | AB44: 2248 | AC44: 2332 | AD44: 2590 | AE44: 2212 | AF44: 2680 | AG44: 3074 | AH44: 2872 | AI44: 2407 | AJ44: 2407 | AK44: 2944 | AL44: 2953 | AM44: 3000 | AN44: 3598 | AO44: 3595 | AP44: 3933 | AQ44: 4402 | AR44: 5582 | AS44: 5318 | AT44: 6786 | AU44: 7571
A45: Exceptional items | B45: ₹m | C45: 800 | D45: 0 | E45: 13 | F45: 13 | G45: 361 | H45: 361 | I45: 13 | J45: -140 | K45: -140 | L45: 0 | M45: 0 | N45: -140 | O45: 0 | P45: 0 | Q45: 0 | R45: 56 | S45: -57 | T45: -57 | U45: 0 | V45: 128 | W45: 180 | X45: 0 | Y45: 0 | Z45: 0 | AA45: 0 | AB45: 0 | AC45: 0 | AD45: 0 | AE45: 0 | AF45: 0 | AG45: 0 | AH45: 0 | AI45: 0 | AJ45: 0 | AK45: 0 | AL45: 97 | AM45: 953 | AN45: 201 | AO45: 0 | AP45: 0 | AQ45: 248 | AR45: 0 | AS45: 1476 | AT45: 536 | AU45: 550
...

Sheet Raw Operating
A1: Raw Reported Operating KPIs
A2: Official disclosures; blanks mean the KPI was not disclosed in that period
A5: Metric | B5: Units | C5: FY16A | D5: FY17A | E5: FY18A | F5: FY19A | G5: FY20A | H5: FY21A | I5: FY22A | J5: FY23A | K5: FY24A | L5: FY25A | M5: FY26A | N5: FY27E | O5: FY28E | P5: FY29E | Q5: FY30E
A7: Revenue | B7: $m | I7: 866.5 | J7: 1001.7 | K7: 1118.7 | L7: 1448 | M7: 1870
A8: Revenue | B8: ₹m | I8: 64320 | J8: 80146 | K8: 91790 | L8: 120733 | M8: 164027
A9: Fresh order intake | B9: $m | C9: 420 | D9: 457 | E9: 507 | F9: 646 | G9: 748 | H9: 781 | I9: 1151 | J9: 1265 | K9: 1973 | L9: 3456 | M9: 2262
A10: Executable order book (next 12m) | B10: $m | C10: 301 | D10: 320 | E10: 339 | F10: 390 | G10: 468 | H10: 520 | I10: 720 | J10: 869 | K10: 1019 | L10: 1505 | M10: 1752
A11: BFS mix | B11: % | C11: 0.17 | D11: 0.19 | E11: 0.17 | F11: 0.16 | G11: 0.16 | H11: 0.17 | I11: 0.255 | J11: 0.307 | K11: 0.322 | L11: 0.305 | M11: 0.265
A12: Insurance mix | B12: % | C12: 0.21 | D12: 0.23 | E12: 0.26 | F12: 0.29 | G12: 0.3 | H12: 0.32 | I12: 0.283 | J12: 0.226 | K12: 0.222 | L12: 0.185 | M12: 0.15
A13: TTH mix | B13: % | C13: 0.35 | D13: 0.32 | E13: 0.27 | F13: 0.27 | G13: 0.28 | H13: 0.19 | I13: 0.19 | J13: 0.191 | K13: 0.18 | L13: 0.183 | M13: 0.23
A14: Government mix | B14: % | C14: 0.04 | D14: 0.03 | E14: 0.01 | L14: 0.077 | M14: 0.07
A15: Healthcare & HiTech mix | B15: % | L15: 0.07 | M15: 0.108
A16: Manufacturing mix | B16: % | C16: 0.08
A17: Others mix | B17: % | C17: 0.15 | F17: 0.28 | G17: 0.26 | H17: 0.31 | J17: 0.275 | K17: 0.276 | L17: 0.179 | M17: 0.177
A18: Americas mix | B18: % | C18: 0.46 | D18: 0.48 | E18: 0.49 | F18: 0.49 | G18: 0.48 | H18: 0.48 | I18: 0.518 | J18: 0.499 | K18: 0.483 | L18: 0.548 | M18: 0.569
A19: EMEA mix | B19: % | C19: 0.34 | D19: 0.33 | E19: 0.31 | F19: 0.33 | G19: 0.37 | H19: 0.37 | I19: 0.354 | J19: 0.389 | K19: 0.394 | L19: 0.337 | M19: 0.289
A20: ROW mix | B20: % | C20: 0.2 | D20: 0.19 | E20: 0.2 | F20: 0.18 | G20: 0.15 | H20: 0.15 | I20: 0.128 | J20: 0.112 | K20: 0.123 | L20: 0.115 | M20: 0.142
A21: Onsite mix | B21: % | C21: 0.59 | D21: 0.6 | E21: 0.61 | F21: 0.65 | G21: 0.64 | H21: 0.62 | I21: 0.56 | J21: 0.501 | K21: 0.483 | L21: 0.468 | M21: 0.476
A22: Offshore mix | B22: % | C22: 0.41 | D22: 0.4 | E22: 0.39 | F22: 0.35 | G22: 0.36 | H22: 0.38 | I22: 0.44 | J22: 0.499 | K22: 0.517 | L22: 0.532 | M22: 0.524
A23: Fixed-price mix | B23: % | C23: 0.45 | D23: 0.48 | E23: 0.46 | F23: 0.47 | G23: 0.48 | H23: 0.54 | I23: 0.54 | J23: 0.52 | K23: 0.504 | L23: 0.462 | M23: 0.469
A24: T&M mix | B24: % | C24: 0.55 | D24: 0.52 | E24: 0.54 | F24: 0.53 | G24: 0.52 | H24: 0.46 | I24: 0.46 | J24: 0.48 | K24: 0.496 | L24: 0.538 | M24: 0.531
A25: Repeat business | B25: % | C25: 0.91 | D25: 0.91 | E25: 0.89 | F25: 0.9 | G25: 0.89 | H25: 0.89 | I25: 0.93 | J25: 0.92 | K25: 0.92 | L25: 0.94 | M25: 0.955
A26: Top 5 clients | B26: % | C26: 0.32 | D26: 0.33 | E26: 0.3 | F26: 0.28 | G26: 0.28 | H26: 0.24 | I26: 0.229 | J26: 0.232 | K26: 0.235 | L26: 0.186 | M26: 0.21
A27: Top 10 clients | B27: % | C27: 0.44 | D27: 0.45 | E27: 0.42 | F27: 0.39 | G27: 0.38 | H27: 0.34 | I27: 0.34 | J27: 0.355 | K27: 0.345 | L27: 0.284 | M27: 0.308
A28: New clients | B28: # | C28: 28 | D28: 15 | E28: 31 | F28: 40 | G28: 41 | H28: 45 | I28: 47 | J28: 44 | K28: 29 | L28: 47 | M28: 31
A29: Average INR / USD | B29: ₹ / $ | C29: 65.32 | D29: 67.08 | E29: 64.54 | F29: 69.55 | G29: 70.54 | H29: 74.32 | I29: 74.18 | J29: 80.05 | K29: 82.78 | L29: 86.6 | M29: 87.8
A30: AI-led Engineering / Engineering mix | B30: % | J30: 0.363 | K30: 0.352 | L30: 0.413 | M30: 0.441
A31: Intelligent Automation mix | B31: % | H31: 0.15 | I31: 0.138 | J31: 0.12 | K31: 0.115 | L31: 0.092 | M31: 0.082
A32: Data mix | B32: % | I32: 0.208 | J32: 0.235 | K32: 0.249 | L32: 0.235 | M32: 0.215
A33: Cloud mix | B33: % | I33: 0.179 | J33: 0.183 | K33: 0.191 | L33: 0.179 | M33: 0.184
A34: BPM mix | B34: % | C34: 0.05 | D34: 0.05 | E34: 0.04 | F34: 0.04 | G34: 0.03 | H34: 0.03 | I34: 0.107 | J34: 0.099 | K34: 0.094 | L34: 0.081 | M34: 0.079
A35: ADM mix | B35: % | C35: 0.65 | D35: 0.67 | E35: 0.66 | F35: 0.69 | G35: 0.73 | H35: 0.7
A36: IP Assets mix | B36: % | C36: 0.08 | D36: 0.07 | E36: 0.07 | F36: 0.06 | G36: 0.06 | H36: 0.07
A37: Managed Services mix | B37: % | C37: 0.17 | D37: 0.18 | E37: 0.19 | F37: 0.18 | G37: 0.17 | H37: 0.17
A38: SI & PI mix | B38: % | C38: 0.05 | D38: 0.04 | E38: 0.04 | F38: 0.04 | G38: 0.01 | H38: 0.04
A39: Product Engineering mix | B39: % | H39: 0.16 | I39: 0.12 | J39: 0.101 | K39: 0.085
A40: Software Engineering mix | B40: % | J40: 0.262 | K40: 0.267
A41: Gross margin | B41: % | C41: 0.357 | D41: 44 | E41: 0.379 | F41: -36 | G41: 0.344 | H41: -218 | I41: 0.32 | J41: 71 | K41: 0.326 | L41: 0.337 | M41: 0.338
A42: Adjusted EBITDA margin | B42: % | C42: 0.163 | D42: 106 | E42: 0.205 | F42: -112 | I42: 0.187 | J42: 109 | K42: 0.176 | L42: 0.143 | M42: 0.186
A43: Headcount | B43: # | C43: 9476 | D43: 8853 | E43: 9423 | F43: 10263 | G43: 11156 | H43: 12391 | I43: 22500 | J43: 23224 | K43: 24726 | L43: 33497 | M43: 35777
...

Sheet Quarterly P&L
A1: Quarterly Profit & Loss
A2: Reported quarters only; annual restatement / classification differences are shown as a bridge, not forced into Q4
A5: Metric | B5: Units | C5: Q1 FY16A | D5: Q2 FY16A | E5: Q3 FY16A | F5: Q4 FY16A | G5: Q1 FY17A | H5: Q2 FY17A | I5: Q3 FY17A | J5: Q4 FY17A | K5: Q1 FY18A | L5: Q2 FY18A | M5: Q3 FY18A | N5: Q4 FY18A | O5: Q1 FY19A | P5: Q2 FY19A | Q5: Q3 FY19A | R5: Q4 FY19A | S5: Q1 FY20A | T5: Q2 FY20A | U5: Q3 FY20A | V5: Q4 FY20A | W5: Q1 FY21A | X5: Q2 FY21A | Y5: Q3 FY21A | Z5: Q4 FY21A | AA5: Q1 FY22A | AB5: Q2 FY22A | AC5: Q3 FY22A | AD5: Q4 FY22A | AE5: Q1 FY23A | AF5: Q2 FY23A | AG5: Q3 FY23A | AH5: Q4 FY23A | AI5: Q1 FY24A | AJ5: Q2 FY24A | AK5: Q3 FY24A | AL5: Q4 FY24A | AM5: Q1 FY25A | AN5: Q2 FY25A | AO5: Q3 FY25A | AP5: Q4 FY25A | AQ5: Q1 FY26A | AR5: Q2 FY26A | AS5: Q3 FY26A | AT5: Q4 FY26A | AU5: Q1 FY27A
A6: Revenue | B6: ₹m | C6: ='Raw Financials'!C32 -> 6411 | D6: ='Raw Financials'!D32 -> 6779 | E6: ='Raw Financials'!E32 -> 6787 | F6: ='Raw Financials'!F32 -> 6847 | G6: ='Raw Financials'!G32 -> 6707 | H6: ='Raw Financials'!H32 -> 6929 | I6: ='Raw Financials'!I32 -> 6938 | J6: ='Raw Financials'!J32 -> 7447 | ... AU6: ='Raw Financials'!AU32 -> 55277
A7: Revenue growth QoQ | B7: % | D7: =IFERROR(D6/C6-1,"") -> 0.057401341 | E7: =IFERROR(E6/D6-1,"") -> 0.0011801151 | F7: =IFERROR(F6/E6-1,"") -> 0.0088404302 | G7: =IFERROR(G6/F6-1,"") -> -0.020446911 | H7: =IFERROR(H6/G6-1,"") -> 0.033099747 | I7: =IFERROR(I6/H6-1,"") -> 0.0012988887 | J7: =IFERROR(J6/I6-1,"") -> 0.073364082 | K7: =IFERROR(K6/J6-1,"") -> -0.04807305 | ... AU7: =IFERROR(AU6/AT6-1,"") -> 0.24206813
A8: Cost of revenue | B8: ₹m | C8: ='Raw Financials'!C33 -> 4081 | D8: ='Raw Financials'!D33 -> 4256 | E8: ='Raw Financials'!E33 -> 4255 | F8: ='Raw Financials'!F33 -> 4304 | G8: ='Raw Financials'!G33 -> 4356 | H8: ='Raw Financials'!H33 -> 4481 | I8: ='Raw Financials'!I33 -> 4441 | J8: ='Raw Financials'!J33 -> 4625 | ... AU8: ='Raw Financials'!AU33 -> 36343
A9: Gross profit | B9: ₹m | C9: ='Raw Financials'!C34 -> 2330 | D9: ='Raw Financials'!D34 -> 2523 | E9: ='Raw Financials'!E34 -> 2532 | F9: ='Raw Financials'!F34 -> 2543 | G9: ='Raw Financials'!G34 -> 2351 | H9: ='Raw Financials'!H34 -> 2448 | I9: ='Raw Financials'!I34 -> 2497 | J9: ='Raw Financials'!J34 -> 2822 | ... AU9: ='Raw Financials'!AU34 -> 18934
A10: Gross margin | B10: % | C10: ='Raw Financials'!C35 -> 0.364 | D10: ='Raw Financials'!D35 -> 0.372 | E10: ='Raw Financials'!E35 -> 0.373 | F10: ='Raw Financials'!F35 -> 0.371 | G10: ='Raw Financials'!G35 -> 0.351 | H10: ='Raw Financials'!H35 -> 0.353 | I10: ='Raw Financials'!I35 -> 0.36 | J10: ='Raw Financials'!J35 -> 0.379 | ... AU10: ='Raw Financials'!AU35 -> 0.343
A11: SG&A | B11: ₹m | C11: ='Raw Financials'!C36 -> 1288 | D11: ='Raw Financials'!D36 -> 1329 | E11: ='Raw Financials'!E36 -> 1296 | F11: ='Raw Financials'!F36 -> 1282 | G11: ='Raw Financials'!G36 -> 1336 | H11: ='Raw Financials'!H36 -> 1303 | I11: ='Raw Financials'!I36 -> 1335 | J11: ='Raw Financials'!J36 -> 1298 | ... AU11: ='Raw Financials'!AU36 -> 7701
A12: Adjusted EBITDA | B12: ₹m | C12: ='Raw Financials'!C37 -> 1042 | D12: ='Raw Financials'!D37 -> 1194 | E12: ='Raw Financials'!E37 -> 1236 | F12: ='Raw Financials'!F37 -> 1261 | G12: ='Raw Financials'!G37 -> 1015 | H12: ='Raw Financials'!H37 -> 1145 | I12: ='Raw Financials'!I37 -> 1162 | J12: ='Raw Financials'!J37 -> 1523 | ... AU12: ='Raw Financials'!AU37 -> 11233
A13: Adjusted EBITDA margin | B13: % | C13: =IFERROR(C12/C6,"") -> 0.16253315 | D13: =IFERROR(D12/D6,"") -> 0.17613217 | E13: =IFERROR(E12/E6,"") -> 0.18211286 | F13: =IFERROR(F12/F6,"") -> 0.18416825 | G13: =IFERROR(G12/G6,"") -> 0.15133443 | H13: =IFERROR(H12/H6,"") -> 0.16524751 | I13: =IFERROR(I12/I6,"") -> 0.16748342 | J13: =IFERROR(J12/J6,"") -> 0.20451188 | ... AU13: =IFERROR(AU12/AU6,"") -> 0.20321291
A14: ESOP | B14: ₹m | C14: ='Raw Financials'!C38 -> 0 | D14: ='Raw Financials'!D38 -> 0 | E14: ='Raw Financials'!E38 -> 0 | F14: ='Raw Financials'!F38 -> 0 | G14: ='Raw Financials'!G38 -> 0 | H14: ='Raw Financials'!H38 -> 0 | I14: ='Raw Financials'!I38 -> 0 | J14: ='Raw Financials'!J38 -> 0 | ... AU14: ='Raw Financials'!AU38 -> 457
A15: EBITDA | B15: ₹m | C15: ='Raw Financials'!C39 -> 1042 | D15: ='Raw Financials'!D39 -> 1194 | E15: ='Raw Financials'!E39 -> 1236 | F15: ='Raw Financials'!F39 -> 1261 | G15: ='Raw Financials'!G39 -> 1015 | H15: ='Raw Financials'!H39 -> 1145 | I15: ='Raw Financials'!I39 -> 1162 | J15: ='Raw Financials'!J39 -> 1523 | ... AU15: ='Raw Financials'!AU39 -> 11233
A16: EBITDA margin | B16: % | C16: =IFERROR(C15/C6,"") -> 0.16253315 | D16: =IFERROR(D15/D6,"") -> 0.17613217 | E16: =IFERROR(E15/E6,"") -> 0.18211286 | F16: =IFERROR(F15/F6,"") -> 0.18416825 | G16: =IFERROR(G15/G6,"") -> 0.15133443 | H16: =IFERROR(H15/H6,"") -> 0.16524751 | I16: =IFERROR(I15/I6,"") -> 0.16748342 | J16: =IFERROR(J15/J6,"") -> 0.20451188 | ... AU16: =IFERROR(AU15/AU6,"") -> 0.20321291
A17: D&A | B17: ₹m | C17: ='Raw Financials'!C40 -> 276 | D17: ='Raw Financials'!D40 -> 265 | E17: ='Raw Financials'!E40 -> 273 | F17: ='Raw Financials'!F40 -> 287 | G17: ='Raw Financials'!G40 -> 326 | H17: ='Raw Financials'!H40 -> 317 | I17: ='Raw Financials'!I40 -> 321 | J17: ='Raw Financials'!J40 -> 312 | ... AU17: ='Raw Financials'!AU40 -> 2411
A18: EBIT | B18: ₹m | C18: ='Raw Financials'!C41 -> 766 | D18: ='Raw Financials'!D41 -> 929 | E18: ='Raw Financials'!E41 -> 963 | F18: ='Raw Financials'!F41 -> 974 | G18: ='Raw Financials'!G41 -> 689 | H18: ='Raw Financials'!H41 -> 828 | I18: ='Raw Financials'!I41 -> 841 | J18: ='Raw Financials'!J41 -> 1211 | ... AU18: ='Raw Financials'!AU41 -> 8822
A19: EBIT margin | B19: % | C19: =IFERROR(C18/C6,"") -> 0.11948214 | D19: =IFERROR(D18/D6,"") -> 0.13704086 | E19: =IFERROR(E18/E6,"") -> 0.14188891 | F19: =IFERROR(F18/F6,"") -> 0.14225208 | G19: =IFERROR(G18/G6,"") -> 0.10272849 | H19: =IFERROR(H18/H6,"") -> 0.11949776 | I19: =IFERROR(I18/I6,"") -> 0.12121649 | J19: =IFERROR(J18/J6,"") -> 0.16261582 | ... AU19: =IFERROR(AU18/AU6,"") -> 0.15959622
A20: Other income, net | B20: ₹m | C20: ='Raw Financials'!C42 -> 79 | D20: ='Raw Financials'!D42 -> 13 | E20: ='Raw Financials'!E42 -> 52 | F20: ='Raw Financials'!F42 -> 39 | G20: ='Raw Financials'!G42 -> 83 | H20: ='Raw Financials'!H42 -> 29 | I20: ='Raw Financials'!I42 -> 59 | J20: ='Raw Financials'!J42 -> -12 | ... AU20: ='Raw Financials'!AU42 -> -598
A21: FX gain / loss | B21: ₹m | C21: ='Raw Financials'!C43 -> 0 | D21: ='Raw Financials'!D43 -> 0 | E21: ='Raw Financials'!E43 -> 0 | F21: ='Raw Financials'!F43 -> 0 | G21: ='Raw Financials'!G43 -> 0 | H21: ='Raw Financials'!H43 -> 0 | I21: ='Raw Financials'!I43 -> 0 | J21: ='Raw Financials'!J43 -> 0 | ... AU21: ='Raw Financials'!AU43 -> -653
A22: PBT pre-exceptional | B22: ₹m | C22: ='Raw Financials'!C44 -> 845 | D22: ='Raw Financials'!D44 -> 942 | E22: ='Raw Financials'!E44 -> 1015 | F22: ='Raw Financials'!F44 -> 1013 | G22: ='Raw Financials'!G44 -> 772 | H22: ='Raw Financials'!H44 -> 857 | I22: ='Raw Financials'!I44 -> 900 | J22: ='Raw Financials'!J44 -> 1199 | ... AU22: ='Raw Financials'!AU44 -> 7571
A23: Exceptional items | B23: ₹m | C23: ='Raw Financials'!C45 -> 800 | D23: ='Raw Financials'!D45 -> 0 | E23: ='Raw Financials'!E45 -> 13 | F23: ='Raw Financials'!F45 -> 13 | G23: ='Raw Financials'!G45 -> 361 | H23: ='Raw Financials'!H45 -> 361 | I23: ='Raw Financials'!I45 -> 13 | J23: ='Raw Financials'!J45 -> -140 | ... AU23: ='Raw Financials'!AU45 -> 550
A24: PBT | B24: ₹m | C24: ='Raw Financials'!C46 -> 844 | D24: ='Raw Financials'!D46 -> 942 | E24: ='Raw Financials'!E46 -> 1002 | F24: ='Raw Financials'!F46 -> 1013 | G24: ='Raw Financials'!G46 -> 411 | H24: ='Raw Financials'!H46 -> 856 | I24: ='Raw Financials'!I46 -> 900 | J24: ='Raw Financials'!J46 -> 1339 | ... AU24: ='Raw Financials'!AU46 -> 7021
A25: Tax | B25: ₹m | C25: ='Raw Financials'!C47 -> 219 | D25: ='Raw Financials'!D47 -> 216 | E25: ='Raw Financials'!E47 -> 212 | F25: ='Raw Financials'!F47 -> 184 | G25: ='Raw Financials'!G47 -> 80 | H25: ='Raw Financials'!H47 -> 213 | I25: ='Raw Financials'!I47 -> 228 | J25: ='Raw Financials'!J47 -> 265 | ... AU25: ='Raw Financials'!AU47 -> 1704
A26: Profit incl. NCI | B26: ₹m | C26: ='Raw Financials'!C48 -> 625 | D26: ='Raw Financials'!D48 -> 726 | E26: ='Raw Financials'!E48 -> 790 | F26: ='Raw Financials'!F48 -> 829 | G26: ='Raw Financials'!G48 -> 331 | H26: ='Raw Financials'!H48 -> 643 | I26: ='Raw Financials'!I48 -> 672 | J26: ='Raw Financials'!J48 -> 1075 | ... AU26: ='Raw Financials'!AU48 -> 5317
A27: NCI | B27: ₹m | C27: ='Raw Financials'!C49 -> 40 | D27: ='Raw Financials'!D49 -> 43 | E27: ='Raw Financials'!E49 -> 48 | F27: ='Raw Financials'!F49 -> 39 | G27: ='Raw Financials'!G49 -> 46 | H27: ='Raw Financials'!H49 -> 54 | I27: ='Raw Financials'!I49 -> 48 | J27: ='Raw Financials'!J49 -> 72 | ... AU27: ='Raw Financials'!AU49 -> 131
A28: Net income attributable | B28: ₹m | C28: ='Raw Financials'!C50 -> 585 | D28: ='Raw Financials'!D50 -> 683 | E28: ='Raw Financials'!E50 -> 742 | F28: ='Raw Financials'!F50 -> 790 | G28: ='Raw Financials'!G50 -> 285 | H28: ='Raw Financials'!H50 -> 589 | I28: ='Raw Financials'!I50 -> 624 | J28: ='Raw Financials'!J50 -> 1003 | ... AU28: ='Raw Financials'!AU50 -> 5186
A29: Net margin | B29: % | C29: =IFERROR(C28/C6,"") -> 0.091249415 | D29: =IFERROR(D28/D6,"") -> 0.10075232 | E29: =IFERROR(E28/E6,"") -> 0.10932665 | F29: =IFERROR(F28/F6,"") -> 0.115379 | G29: =IFERROR(G28/G6,"") -> 0.042492918 | H29: =IFERROR(H28/H6,"") -> 0.085005051 | I29: =IFERROR(I28/I6,"") -> 0.089939464 | J29: =IFERROR(J28/J6,"") -> 0.13468511 | ... AU29: =IFERROR(AU28/AU6,"") -> 0.093818405
A30: Basic EPS | B30: ₹ / share | C30: ='Raw Financials'!C51 -> 9.6 | D30: ='Raw Financials'!D51 -> 11.2 | E30: ='Raw Financials'!E51 -> 12.1 | F30: ='Raw Financials'!F51 -> 12.9 | G30: ='Raw Financials'!G51 -> 4.7 | H30: ='Raw Financials'!H51 -> 9.6 | I30: ='Raw Financials'!I51 -> 10.1 | J30: ='Raw Financials'!J51 -> 16.3 | ... AU30: ='Raw Financials'!AU51 -> 12.3

Sheet Annual P&L
A1: Annual Profit & Loss
A2: Audited history and formula-driven FY27E–FY30E forecast
A5: Metric | B5: Units | C5: FY16A | D5: FY17A | E5: FY18A | F5: FY19A | G5: FY20A | H5: FY21A | I5: FY22A | J5: FY23A | K5: FY24A | L5: FY25A | M5: FY26A | N5: FY27E | O5: FY28E | P5: FY29E | Q5: FY30E
A7: Revenue | B7: ₹m | C7: ='Raw Financials'!C6 -> 26824.049 | D7: ='Raw Financials'!D6 -> 28021 | E7: ='Raw Financials'!E6 -> 29914 | F7: ='Raw Financials'!F6 -> 36762 | G7: ='Raw Financials'!G6 -> 41839 | H7: ='Raw Financials'!H6 -> 46628 | I7: ='Raw Financials'!I6 -> 64320 | J7: ='Raw Financials'!J6 -> 80146 | ... M7: ='Raw Financials'!M6 -> 164027 | N7: ='Order Book & Revenue'!N31 -> 228523.77 | O7: ='Order Book & Revenue'!O31 -> 293835.96 | P7: ='Order Book & Revenue'!P31 -> 369616.09 | Q7: ='Order Book & Revenue'!Q31 -> 457101.52
A8: Revenue growth | B8: % | D8: =IFERROR(D7/C7-1,"") -> 0.044622317 | E8: =IFERROR(E7/D7-1,"") -> 0.067556476 | F8: =IFERROR(F7/E7-1,"") -> 0.22892291 | G8: =IFERROR(G7/F7-1,"") -> 0.13810456 | H8: =IFERROR(H7/G7-1,"") -> 0.11446258 | I8: =IFERROR(I7/H7-1,"") -> 0.37942867 | J8: =IFERROR(J7/I7-1,"") -> 0.246051 | K8: =IFERROR(K7/J7-1,"") -> 0.14528486 | ... Q8: =IFERROR(Q7/P7-1,"") -> 0.2366927
A9: Cost of revenue | B9: ₹m | C9: =SUM('Raw Financials'!C9,'Raw Financials'!C10,'Raw Financials'!C11,'Raw Financials'!C12) -> 15694.798 | D9: =SUM('Raw Financials'!D9,'Raw Financials'!D10,'Raw Financials'!D11,'Raw Financials'!D12) -> 16654 | E9: =SUM('Raw Financials'!E9,'Raw Financials'!E10,'Raw Financials'!E11,'Raw Financials'!E12) -> 17918 | F9: =SUM('Raw Financials'!F9,'Raw Financials'!F10,'Raw Financials'!F11,'Raw Financials'!F12) -> 21823 | G9: =SUM('Raw Financials'!G9,'Raw Financials'!G10,'Raw Financials'!G11,'Raw Financials'!G12) -> 26142 | H9: =SUM('Raw Financials'!H9,'Raw Financials'!H10,'Raw Financials'!H11,'Raw Financials'!H12) -> 30093 | I9: =SUM('Raw Financials'!I9,'Raw Financials'!I10,'Raw Financials'!I11,'Raw Financials'!I12) -> 40070 | J9: =SUM('Raw Financials'!J9,'Raw Financials'!J10,'Raw Financials'!J11,'Raw Financials'!J12) -> 48831 | K9: =K7-K10 -> 61866.46 | L9: =L7-L10 -> 80045.979 | M9: =M7-M10 -> 108585.87 | N9: =N7-N10 -> 150140.12 | O9: =O7-O10 -> 191874.88 | P9: =P7-P10 -> 240250.46 | Q9: =Q7-Q10 -> 295744.68
A10: Gross profit | B10: ₹m | C10: =C7-C9 -> 11129.251 | D10: =D7-D9 -> 11367 | E10: =E7-E9 -> 11996 | F10: =F7-F9 -> 14939 | G10: =G7-G9 -> 15697 | H10: =H7-H9 -> 16535 | I10: =I7-I9 -> 24250 | J10: =J7-J9 -> 31315 | K10: =K7*'Raw Operating'!K41 -> 29923.54 | L10: =L7*'Raw Operating'!L41 -> 40687.021 | M10: =M7*'Raw Operating'!M41 -> 55441.126 | N10: =N7*Assumptions!C20 -> 78383.654 | O10: =O7*Assumptions!D20 -> 101961.08 | P10: =P7*Assumptions!E20 -> 129365.63 | Q10: =Q7*Assumptions!F20 -> 161356.84
A11: Gross margin | B11: % | C11: =IFERROR(C10/C7,"") -> 0.41489825 | D11: =IFERROR(D10/D7,"") -> 0.40566004 | E11: =IFERROR(E10/E7,"") -> 0.40101625 | F11: =IFERROR(F10/F7,"") -> 0.40637071 | G11: =IFERROR(G10/G7,"") -> 0.37517627 | H11: =IFERROR(H10/H7,"") -> 0.35461525 | I11: =IFERROR(I10/I7,"") -> 0.37702114 | J11: =IFERROR(J10/J7,"") -> 0.39072443 | K11: =K10/K7 -> 0.326 | L11: =L10/L7 -> 0.337 | M11: =M10/M7 -> 0.338 | N11: =N10/N7 -> 0.343 | O11: =O10/O7 -> 0.347 | P11: =P10/P7 -> 0.35 | Q11: =Q10/Q7 -> 0.353
A12: SG&A | B12: ₹m | C12: ='Raw Financials'!C13 -> 6287.5291 | D12: ='Raw Financials'!D13 -> 6573 | E12: ='Raw Financials'!E13 -> 6983 | F12: ='Raw Financials'!F13 -> 8454 | G12: ='Raw Financials'!G13 -> 8464 | H12: ='Raw Financials'!H13 -> 8740 | I12: ='Raw Financials'!I13 -> 13231 | J12: ='Raw Financials'!J13 -> 18508 | K12: =K10-K13 -> 13768.5 | L12: =L10-L13 -> 23422.202 | M12: =M10-M13 -> 24932.104 | N12: =N7*Assumptions!C21 -> 31536.281 | O12: =O7*Assumptions!D21 -> 39667.855 | P12: =P7*Assumptions!E21 -> 48789.324 | Q12: =Q7*Assumptions!F21 -> 59423.198
A13: Adjusted EBITDA | B13: ₹m | C13: =C10-C12 -> 4841.7219 | D13: =D10-D12 -> 4794 | E13: =E10-E12 -> 5013 | F13: =F10-F12 -> 6485 | G13: =G10-G12 -> 7233 | H13: =H10-H12 -> 7795 | I13: =I10-I12 -> 11019 | J13: =J10-J12 -> 12807 | K13: =K7*'Raw Operating'!K42 -> 16155.04 | L13: =L7*'Raw Operating'!L42 -> 17264.819 | M13: =M7*'Raw Operating'!M42 -> 30509.022 | N13: =N10-N12 -> 46847.374 | O13: =O10-O12 -> 62293.224 | P13: =P10-P12 -> 80576.308 | Q13: =Q10-Q12 -> 101933.64
A14: Adjusted EBITDA margin | B14: % | C14: =IFERROR(C13/C7,"") -> 0.18049929 | D14: =IFERROR(D13/D7,"") -> 0.17108597 | E14: =IFERROR(E13/E7,"") -> 0.1675804 | F14: =IFERROR(F13/F7,"") -> 0.17640498 | G14: =IFERROR(G13/G7,"") -> 0.17287698 | H14: =IFERROR(H13/H7,"") -> 0.16717423 | I14: =IFERROR(I13/I7,"") -> 0.1713153 | J14: =IFERROR(J13/J7,"") -> 0.15979587 | K14: =K13/K7 -> 0.176 | L14: =L13/L7 -> 0.143 | M14: =M13/M7 -> 0.186 | N14: =N13/N7 -> 0.205 | O14: =O13/O7 -> 0.212 | P14: =P13/P7 -> 0.218 | Q14: =Q13/Q7 -> 0.223
A15: Share-based compensation | B15: ₹m | C15: =0 -> 0 | D15: =0 -> 0 | E15: =0 -> 0 | F15: =0 -> 0 | G15: =0 -> 0 | H15: =0 -> 0 | I15: =0 -> 0 | J15: =0 -> 0 | ... M15: =0 -> 0 | N15: =N7*Assumptions!C22 -> 1371.1426 | O15: =O7*Assumptions!D22 -> 1763.0158 | P15: =P7*Assumptions!E22 -> 2217.6966 | Q15: =Q7*Assumptions!F22 -> 2742.6091
A16: EBITDA | B16: ₹m | C16: =C13-C15 -> 4841.7219 | D16: =D13-D15 -> 4794 | E16: =E13-E15 -> 5013 | F16: =F13-F15 -> 6485 | G16: =G13-G15 -> 7233 | H16: =H13-H15 -> 7795 | I16: =I13-I15 -> 11019 | J16: =J13-J15 -> 12807 | ... Q16: =Q13-Q15 -> 99191.03
A17: EBITDA margin | B17: % | C17: =IFERROR(C16/C7,"") -> 0.18049929 | D17: =IFERROR(D16/D7,"") -> 0.17108597 | E17: =IFERROR(E16/E7,"") -> 0.1675804 | F17: =IFERROR(F16/F7,"") -> 0.17640498 | G17: =IFERROR(G16/G7,"") -> 0.17287698 | H17: =IFERROR(H16/H7,"") -> 0.16717423 | I17: =IFERROR(I16/I7,"") -> 0.1713153 | J17: =IFERROR(J16/J7,"") -> 0.15979587 | K17: =K16/K7 -> 0.176 | L17: =L16/L7 -> 0.143 | M17: =M16/M7 -> 0.186 | N17: =N16/N7 -> 0.199 | O17: =O16/O7 -> 0.206 | P17: =P16/P7 -> 0.212 | Q17: =Q16/Q7 -> 0.217
A18: D&A | B18: ₹m | C18: ='Raw Financials'!C15 -> 1101.2935 | D18: ='Raw Financials'!D15 -> 1277 | E18: ='Raw Financials'!E15 -> 1274 | F18: ='Raw Financials'!F15 -> 1248 | G18: ='Raw Financials'!G15 -> 1730 | H18: ='Raw Financials'!H15 -> 1836 | I18: ='Raw Financials'!I15 -> 2272 | J18: ='Raw Financials'!J15 -> 2585 | ... M18: ='Raw Financials'!M15 -> 6819 | N18: =N7*Assumptions!C23 -> 11197.665 | O18: =O7*Assumptions!D23 -> 13516.454 | P18: =P7*Assumptions!E23 -> 15893.492 | Q18: =Q7*Assumptions!F23 -> 18284.061
A19: EBIT | B19: ₹m | C19: =C16-C18 -> 3740.4283 | D19: =D16-D18 -> 3517 | E19: =E16-E18 -> 3739 | F19: =F16-F18 -> 5237 | G19: =G16-G18 -> 5503 | H19: =H16-H18 -> 5959 | I19: =I16-I18 -> 8747 | J19: =J16-J18 -> 10222 | ... Q19: =Q16-Q18 -> 80906.969
A20: EBIT margin | B20: % | C20: =IFERROR(C19/C7,"") -> 0.13944309 | D20: =IFERROR(D19/D7,"") -> 0.12551301 | E20: =IFERROR(E19/E7,"") -> 0.12499164 | F20: =IFERROR(F19/F7,"") -> 0.14245688 | G20: =IFERROR(G19/G7,"") -> 0.131528 | H20: =IFERROR(H19/H7,"") -> 0.12779875 | I20: =IFERROR(I19/I7,"") -> 0.13599192 | J20: =IFERROR(J19/J7,"") -> 0.12754224 | K20: =K19/K7 -> 0.14129034 | L20: =L19/L7 -> 0.10758301 | M20: =M19/M7 -> 0.14442758 | N20: =N19/N7 -> 0.15 | O20: =O19/O7 -> 0.16 | P20: =P19/P7 -> 0.169 | Q20: =Q19/Q7 -> 0.177
A21: Other income | B21: ₹m | C21: ='Raw Financials'!C7 -> 205.4828 | D21: ='Raw Financials'!D7 -> 269 | E21: ='Raw Financials'!E7 -> 391 | F21: ='Raw Financials'!F7 -> 535 | G21: ='Raw Financials'!G7 -> 677 | H21: ='Raw Financials'!H7 -> 326 | I21: ='Raw Financials'!I7 -> 518 | J21: ='Raw Financials'!J7 -> 619 | ... M21: ='Raw Financials'!M7 -> 732 | N21: =N7*Assumptions!C24 -> 1142.6189 | O21: =O7*Assumptions!D24 -> 1469.1798 | P21: =P7*Assumptions!E24 -> 1848.0805 | Q21: =Q7*Assumptions!F24 -> 2285.5076
A22: Finance costs | B22: ₹m | C22: ='Raw Financials'!C14 -> 48.795223 | D22: ='Raw Financials'!D14 -> 60 | E22: ='Raw Financials'!E14 -> 94 | F22: ='Raw Financials'!F14 -> 92 | G22: ='Raw Financials'!G14 -> 155 | H22: ='Raw Financials'!H14 -> 143 | I22: ='Raw Financials'!I14 -> 650 | J22: ='Raw Financials'!J14 -> 806 | ... M22: ='Raw Financials'!M14 -> 1686 | N22: ='Acquisition & Debt'!C22 -> 2218.4 | O22: ='Acquisition & Debt'!D22 -> 1814.5 | P22: ='Acquisition & Debt'!E22 -> 739.2 | Q22: ='Acquisition & Debt'!F22 -> 48.5
A23: PBT pre-exceptional | B23: ₹m | C23: ='Raw Financials'!C16 -> 3814.5324 | D23: ='Raw Financials'!D16 -> 3727 | E23: ='Raw Financials'!E16 -> 4036 | F23: ='Raw Financials'!F16 -> 5680 | G23: ='Raw Financials'!G16 -> 6025 | H23: ='Raw Financials'!H16 -> 6142 | I23: ='Raw Financials'!I16 -> 8615 | J23: ='Raw Financials'!J16 -> 10035 | ... M23: ='Raw Financials'!M16 -> 21588 | N23: =N19+N21-N22 -> 33202.785 | O23: =O19+O21-O22 -> 46668.433 | P23: =P19+P21-P22 -> 63574 | Q23: =Q19+Q21-Q22 -> 83143.977
A24: Exceptional items | B24: ₹m | C24: ='Raw Financials'!C17 -> 13.156528 | D24: ='Raw Financials'!D17 -> 221 | E24: ='Raw Financials'!E17 -> 0 | F24: ='Raw Financials'!F17 -> 56 | G24: ='Raw Financials'!G17 -> 71 | H24: ='Raw Financials'!H17 -> 180 | I24: ='Raw Financials'!I17 -> 0 | J24: ='Raw Financials'!J17 -> 523 | ... M24: ='Raw Financials'!M17 -> 2260 | N24: =0 -> 0 | O24: =0 -> 0 | P24: =0 -> 0 | Q24: =0 -> 0
A25: PBT | B25: ₹m | C25: ='Raw Financials'!C18 -> 3801.3759 | D25: ='Raw Financials'!D18 -> 3506 | E25: ='Raw Financials'!E18 -> 4036 | F25: ='Raw Financials'!F18 -> 5624 | G25: ='Raw Financials'!G18 -> 5954 | H25: ='Raw Financials'!H18 -> 5962 | I25: ='Raw Financials'!I18 -> 8615 | J25: ='Raw Financials'!J18 -> 9512 | ... M25: ='Raw Financials'!M18 -> 19328 | N25: =N23-N24 -> 33202.785 | O25: =O23-O24 -> 46668.433 | P25: =P23-P24 -> 63574 | Q25: =Q23-Q24 -> 83143.977
A26: Tax | B26: ₹m | C26: ='Raw Financials'!C21 -> 831.68032 | D26: ='Raw Financials'!D21 -> 785 | E26: ='Raw Financials'!E21 -> 949 | F26: ='Raw Financials'!F21 -> 1403 | G26: ='Raw Financials'!G21 -> 1278 | H26: ='Raw Financials'!H21 -> 1302 | I26: ='Raw Financials'!I21 -> 1468 | J26: ='Raw Financials'!J21 -> 2061 | ... M26: ='Raw Financials'!M21 -> 2583 | N26: =N25*Assumptions!C25 -> 8300.6962 | O26: =O25*Assumptions!D25 -> 11667.108 | P26: =P25*Assumptions!E25 -> 15893.5 | Q26: =Q25*Assumptions!F25 -> 20785.994
A27: Effective tax rate | B27: % | C27: =IFERROR(C26/C25,"") -> 0.21878403 | D27: =IFERROR(D26/D25,"") -> 0.22390188 | E27: =IFERROR(E26/E25,"") -> 0.2351338 | F27: =IFERROR(F26/F25,"") -> 0.24946657 | G27: =IFERROR(G26/G25,"") -> 0.21464562 | H27: =IFERROR(H26/H25,"") -> 0.21838309 | I27: =IFERROR(I26/I25,"") -> 0.17040046 | J27: =IFERROR(J26/J25,"") -> 0.21667368 | ... M27: =IFERROR(M26/M25,"") -> 0.13364031 | N27: =N26/N25 -> 0.25 | O27: =O26/O25 -> 0.25 | P27: =P26/P25 -> 0.25 | Q27: =Q26/Q25 -> 0.25
A28: Profit incl. NCI | B28: ₹m | C28: ='Raw Financials'!C22 -> 2969.6955 | D28: ='Raw Financials'!D22 -> 2721 | E28: ='Raw Financials'!E22 -> 3087 | F28: ='Raw Financials'!F22 -> 4221 | G28: ='Raw Financials'!G22 -> 4676 | H28: ='Raw Financials'!H22 -> 4660 | I28: ='Raw Financials'!I22 -> 7147 | J28: ='Raw Financials'!J22 -> 7451 | ... M28: ='Raw Financials'!M22 -> 17447 | N28: =N25-N26 -> 24902.089 | O28: =O25-O26 -> 35001.325 | P28: =P25-P26 -> 47680.5 | Q28: =Q25-Q26 -> 62357.983
A29: NCI | B29: ₹m | C29: ='Raw Financials'!C23 -> 170.06476 | D29: ='Raw Financials'!D23 -> 220 | E29: ='Raw Financials'!E23 -> 285 | F29: ='Raw Financials'!F23 -> 188 | G29: ='Raw Financials'!G23 -> 236 | H29: ='Raw Financials'!H23 -> 104 | I29: ='Raw Financials'!I23 -> 530 | J29: ='Raw Financials'!J23 -> 513 | ... M29: ='Raw Financials'!M23 -> 1890 | N29: =N28*Assumptions!C26 -> 498.04177 | O29: =O28*Assumptions!D26 -> 525.01988 | P29: =P28*Assumptions!E26 -> 476.805 | Q29: =Q28*Assumptions!F26 -> 623.57983
A30: Net income attributable | B30: ₹m | C30: ='Raw Financials'!C24 -> 2799.6308 | D30: ='Raw Financials'!D24 -> 2501 | E30: ='Raw Financials'!E24 -> 2802 | F30: ='Raw Financials'!F24 -> 4033 | G30: ='Raw Financials'!G24 -> 4440 | H30: ='Raw Financials'!H24 -> 4556 | I30: ='Raw Financials'!I24 -> 6617 | J30: ='Raw Financials'!J24 -> 6938 | ... M30: ='Raw Financials'!M24 -> 15557 | N30: =N28-N29 -> 24404.047 | O30: =O28-O29 -> 34476.305 | P30: =P28-P29 -> 47203.695 | Q30: =Q28-Q29 -> 61734.403
A31: Net margin | B31: % | C31: =IFERROR(C30/C7,"") -> 0.10437018 | D31: =IFERROR(D30/D7,"") -> 0.089254488 | E31: =IFERROR(E30/E7,"") -> 0.093668516 | F31: =IFERROR(F30/F7,"") -> 0.10970567 | G31: =IFERROR(G30/G7,"") -> 0.10612108 | H31: =IFERROR(H30/H7,"") -> 0.097709531 | I31: =IFERROR(I30/I7,"") -> 0.10287624 | J31: =IFERROR(J30/J7,"") -> 0.086567015 | ... M31: =IFERROR(M30/M7,"") -> 0.094844142 | N31: =N30/N7 -> 0.10678997 | O31: =O30/O7 -> 0.11733181 | P31: =P30/P7 -> 0.12771006 | Q31: =Q30/Q7 -> 0.13505622
A32: Basic weighted shares | B32: m | C32: =IFERROR(C30/C34,"") -> 305.50314 | D32: =IFERROR(D30/D34,"") -> 306.4951 | E32: =IFERROR(E30/E34,"") -> 307.03485 | F32: =IFERROR(F30/F34,"") -> 307.9096 | G32: =IFERROR(G30/G34,"") -> 310.96792 | H32: =IFERROR(H30/H34,"") -> 305.03482 | I32: =IFERROR(I30/I34,"") -> 303.47643 | J32: =IFERROR(J30/J34,"") -> 304.91342 | ... M32: =IFERROR(M30/M34,"") -> 334.99139 | N32: =N33*0.995 -> 422.875 | O32: =O33*0.995 -> 422.875 | P32: =P33*0.995 -> 422.875 | Q32: =Q33*0.995 -> 422.875
A33: Diluted weighted shares | B33: m | C33: =IFERROR(C30/C35,"") -> 307.31403 | D33: =IFERROR(D30/D35,"") -> 307.17268 | E33: =IFERROR(E30/E35,"") -> 308.99868 | F33: =IFERROR(F30/F35,"") -> 311.5248 | G33: =IFERROR(G30/G35,"") -> 312.80823 | H33: =IFERROR(H30/H35,"") -> 310.82003 | I33: =IFERROR(I30/I35,"") -> 310.59895 | J33: =IFERROR(J30/J35,"") -> 311.03739 | ... M33: =IFERROR(M30/M35,"") -> 338.93246 | N33: =Assumptions!C47 -> 425 | O33: =Assumptions!D47 -> 425 | P33: =Assumptions!E47 -> 425 | Q33: =Assumptions!F47 -> 425
A34: Basic EPS | B34: ₹ / share | C34: ='Raw Financials'!C25 -> 9.164 | D34: ='Raw Financials'!D25 -> 8.16 | E34: ='Raw Financials'!E25 -> 9.126 | F34: ='Raw Financials'!F25 -> 13.098 | G34: ='Raw Financials'!G25 -> 14.278 | H34: ='Raw Financials'!H25 -> 14.936 | I34: ='Raw Financials'!I25 -> 21.804 | J34: ='Raw Financials'!J25 -> 22.754 | ... M34: ='Raw Financials'!M25 -> 46.44 | N34: =N30/N32 -> 57.709836 | O34: =O30/O32 -> 81.52836 | P34: =P30/P32 -> 111.62565 | Q34: =Q30/Q32 -> 145.98736
A35: Diluted EPS | B35: ₹ / share | C35: ='Raw Financials'!C26 -> 9.11 | D35: ='Raw Financials'!D26 -> 8.142 | E35: ='Raw Financials'!E26 -> 9.068 | F35: ='Raw Financials'!F26 -> 12.946 | G35: ='Raw Financials'!G26 -> 14.194 | H35: ='Raw Financials'!H26 -> 14.658 | I35: ='Raw Financials'!I26 -> 21.304 | J35: ='Raw Financials'!J26 -> 22.306 | ... M35: ='Raw Financials'!M26 -> 45.9 | N35: =N30/N33 -> 57.421287 | O35: =O30/O33 -> 81.120718 | P35: =P30/P33 -> 111.06752 | Q35: =Q30/Q33 -> 145.25742
A36: Dividend paid | B36: ₹m | C36: =-'Raw Financials'!C133 -> 731.36613 | D36: =-'Raw Financials'!D133 -> 0 | E36: =-'Raw Financials'!E133 -> 613 | F36: =-'Raw Financials'!F133 -> 0 | G36: =-'Raw Financials'!G133 -> 0 | H36: =-'Raw Financials'!H133 -> 686 | I36: =-'Raw Financials'!I133 -> 3152 | J36: =-'Raw Financials'!J133 -> 3534 | ... M36: =-'Raw Financials'!M133 -> 5277 | N36: =N30*Assumptions!C44 -> 8541.4164 | O36: =O30*Assumptions!D44 -> 12756.233 | P36: =P30*Assumptions!E44 -> 18409.441 | Q36: =Q30*Assumptions!F44 -> 24693.761
