Workbook

Sheet USD revenue
A2: Global services revenue | USD millions
A4: Reported annual revenue; FY labels follow each company’s own year end. FY26 full-year results pending for all five.
A6: Company | B6: FY end | C6: FY16 | D6: FY17 | E6: FY18 | F6: FY19 | G6: FY20 | H6: FY21 | I6: FY22 | J6: FY23 | K6: FY24 | L6: FY25 | M6: FY26
A7: Accenture | B7: 31 Aug | C7: ='Reported revenue'!D7 -> 34798 | D7: ='Reported revenue'!D8 -> 36765 | E7: ='Reported revenue'!D9 -> 41603 | F7: ='Reported revenue'!D10 -> 43215 | G7: ='Reported revenue'!D11 -> 44327 | H7: ='Reported revenue'!D12 -> 50533 | I7: ='Reported revenue'!D13 -> 61594 | J7: ='Reported revenue'!D14 -> 64112 | K7: ='Reported revenue'!D15 -> 64896 | L7: ='Reported revenue'!D16 -> 69673 | M7: Pending
A8: Capgemini | B8: 31 Dec | C8: ='Reported revenue'!D18*'FX rates'!B7 -> 13883.181 | D8: ='Reported revenue'!D19*'FX rates'!B8 -> 14456.239 | E8: ='Reported revenue'!D20*'FX rates'!B9 -> 15594.895 | F8: ='Reported revenue'!D21*'FX rates'!B10 -> 15811.525 | G8: ='Reported revenue'!D22*'FX rates'!B11 -> 18082.568 | H8: ='Reported revenue'!D23*'FX rates'!B12 -> 21483.28 | I8: ='Reported revenue'!D24*'FX rates'!B13 -> 23169.533 | J8: ='Reported revenue'!D25*'FX rates'!B14 -> 24362.047 | K8: ='Reported revenue'!D26*'FX rates'!B15 -> 23907.872 | L8: ='Reported revenue'!D27*'FX rates'!B16 -> 25398.929 | M8: Pending
A9: Cognizant | B9: 31 Dec | C9: ='Reported revenue'!D29 -> 13487 | D9: ='Reported revenue'!D30 -> 14810 | E9: ='Reported revenue'!D31 -> 16125 | F9: ='Reported revenue'!D32 -> 16783 | G9: ='Reported revenue'!D33 -> 16652 | H9: ='Reported revenue'!D34 -> 18507 | I9: ='Reported revenue'!D35 -> 19428 | J9: ='Reported revenue'!D36 -> 19353 | K9: ='Reported revenue'!D37 -> 19736 | L9: ='Reported revenue'!D38 -> 21108 | M9: Pending
A10: Atos | B10: 31 Dec | C10: ='Reported revenue'!D40*'FX rates'!B7 -> 12973.062 | D10: ='Reported revenue'!D41*'FX rates'!B8 -> 14342.099 | E10: ='Reported revenue'!D42*'FX rates'!B9 -> 14485.279 | F10: ='Reported revenue'!D43*'FX rates'!B10 -> 12971.607 | G10: ='Reported revenue'!D44*'FX rates'!B11 -> 12757.521 | H10: ='Reported revenue'!D45*'FX rates'!B12 -> 12822.537 | I10: ='Reported revenue'!D46*'FX rates'!B13 -> 11946.609 | J10: ='Reported revenue'!D47*'FX rates'!B14 -> 11566.618 | K10: ='Reported revenue'!D48*'FX rates'!B15 -> 10362.314 | L10: ='Reported revenue'!D49*'FX rates'!B16 -> 9045.9306 | M10: Pending
A11: CGI | B11: 30 Sep | C11: ='Reported revenue'!D51/'FX rates'!G7 -> 8059.8265 | D11: ='Reported revenue'!D52/'FX rates'!G8 -> 8253.5008 | E11: ='Reported revenue'!D53/'FX rates'!G9 -> 8963.0784 | F11: ='Reported revenue'!D54/'FX rates'!G10 -> 9126.7521 | G11: ='Reported revenue'!D55/'FX rates'!G11 -> 9039.2361 | H11: ='Reported revenue'!D56/'FX rates'!G12 -> 9591.7108 | I11: ='Reported revenue'!D57/'FX rates'!G13 -> 10070.596 | J11: ='Reported revenue'!D58/'FX rates'!G14 -> 10601.706 | K11: ='Reported revenue'!D59/'FX rates'!G15 -> 10784.187 | L11: ='Reported revenue'!D60/'FX rates'!G16 -> 11379.219 | M11: Pending
A13: Notes
A14: Euro reporters use calendar-year average USD per EUR; CGI uses fiscal-year average CAD per USD. USD reporters use published USD revenue.
A15: FY26 cells marked “Pending” await a full-year published result; no forecast or annualized interim revenue is included.
A16: Accenture FY16–18 reflects originally reported revenue; the FY19 10-K changed revenue presentation and restated prior years.
A17: Atos revenue reflects the group perimeter reported for each year; disposals, IFRS changes and later restatements affect year-on-year comparison.
A18: USD conversion is for size comparison only; company fiscal periods differ.

Sheet Reported revenue
A2: Reported group revenue | original currency millions
A4: Inputs and source links. A blank value means the full fiscal year has not been reported as of 17 Sep 2026.
A6: Company | B6: FY | C6: Currency | D6: Revenue (m) | E6: Source / report | F6: Source URL
A7: Accenture | B7: 2016 | C7: USD | D7: 34798 | E7: Accenture FY2018 10-K, selected financial data | F7: https://www.sec.gov/Archives/edgar/data/1467373/000146737318000318/acn831201810k.htm
A8: Accenture | B8: 2017 | C8: USD | D8: 36765 | E8: Accenture FY2018 10-K, selected financial data | F8: https://www.sec.gov/Archives/edgar/data/1467373/000146737318000318/acn831201810k.htm
A9: Accenture | B9: 2018 | C9: USD | D9: 41603 | E9: Accenture FY2018 10-K, selected financial data | F9: https://www.sec.gov/Archives/edgar/data/1467373/000146737318000318/acn831201810k.htm
A10: Accenture | B10: 2019 | C10: USD | D10: 43215 | E10: Accenture FY2019 10-K | F10: https://www.sec.gov/Archives/edgar/data/1467373/000146737319000339/acn831201910k.htm
A11: Accenture | B11: 2020 | C11: USD | D11: 44327 | E11: Accenture FY2022 10-K, consolidated income statements | F11: https://www.sec.gov/Archives/edgar/data/1467373/000146737322000295/acn-20220831.htm
A12: Accenture | B12: 2021 | C12: USD | D12: 50533 | E12: Accenture FY2022 10-K, consolidated income statements | F12: https://www.sec.gov/Archives/edgar/data/1467373/000146737322000295/acn-20220831.htm
A13: Accenture | B13: 2022 | C13: USD | D13: 61594 | E13: Accenture FY2022 10-K, consolidated income statements | F13: https://www.sec.gov/Archives/edgar/data/1467373/000146737322000295/acn-20220831.htm
A14: Accenture | B14: 2023 | C14: USD | D14: 64112 | E14: Accenture FY2025 10-K, consolidated income statements | F14: https://www.sec.gov/Archives/edgar/data/1467373/000146737325000217/acn-20250831.htm
A15: Accenture | B15: 2024 | C15: USD | D15: 64896 | E15: Accenture FY2025 10-K, consolidated income statements | F15: https://www.sec.gov/Archives/edgar/data/1467373/000146737325000217/acn-20250831.htm
A16: Accenture | B16: 2025 | C16: USD | D16: 69673 | E16: Accenture FY2025 10-K, consolidated income statements | F16: https://www.sec.gov/Archives/edgar/data/1467373/000146737325000217/acn-20250831.htm
A17: Accenture | B17: 2026 | C17: USD | E17: Full-year result pending
A18: Capgemini | B18: 2016 | C18: EUR | D18: 12539 | E18: Capgemini group presentation, Oct 2025, p. 68 | F18: https://www.capgemini.com/wp-content/uploads/2025/10/Capgemini_an-introduction-to-our-Group_Oct2025.pdf
A19: Capgemini | B19: 2017 | C19: EUR | D19: 12792 | E19: Capgemini group presentation, Oct 2025, p. 68 | F19: https://www.capgemini.com/wp-content/uploads/2025/10/Capgemini_an-introduction-to-our-Group_Oct2025.pdf
A20: Capgemini | B20: 2018 | C20: EUR | D20: 13197 | E20: Capgemini group presentation, Oct 2025, p. 68 | F20: https://www.capgemini.com/wp-content/uploads/2025/10/Capgemini_an-introduction-to-our-Group_Oct2025.pdf
A21: Capgemini | B21: 2019 | C21: EUR | D21: 14125 | E21: Capgemini group presentation, Oct 2025, p. 68 | F21: https://www.capgemini.com/wp-content/uploads/2025/10/Capgemini_an-introduction-to-our-Group_Oct2025.pdf
A22: Capgemini | B22: 2020 | C22: EUR | D22: 15848 | E22: Capgemini group presentation, Oct 2025, p. 68 | F22: https://www.capgemini.com/wp-content/uploads/2025/10/Capgemini_an-introduction-to-our-Group_Oct2025.pdf
A23: Capgemini | B23: 2021 | C23: EUR | D23: 18160 | E23: Capgemini group presentation, Oct 2025, p. 68 | F23: https://www.capgemini.com/wp-content/uploads/2025/10/Capgemini_an-introduction-to-our-Group_Oct2025.pdf
A24: Capgemini | B24: 2022 | C24: EUR | D24: 21995 | E24: Capgemini group presentation, Oct 2025, p. 68 | F24: https://www.capgemini.com/wp-content/uploads/2025/10/Capgemini_an-introduction-to-our-Group_Oct2025.pdf
A25: Capgemini | B25: 2023 | C25: EUR | D25: 22522 | E25: Capgemini group presentation, Oct 2025, p. 68 | F25: https://www.capgemini.com/wp-content/uploads/2025/10/Capgemini_an-introduction-to-our-Group_Oct2025.pdf
A26: Capgemini | B26: 2024 | C26: EUR | D26: 22096 | E26: Capgemini group presentation, Oct 2025, p. 68 | F26: https://www.capgemini.com/wp-content/uploads/2025/10/Capgemini_an-introduction-to-our-Group_Oct2025.pdf
A27: Capgemini | B27: 2025 | C27: EUR | D27: 22465 | E27: Capgemini FY2025 results | F27: https://www.capgemini.com/news/press-releases/full-year-2025-results/
A28: Capgemini | B28: 2026 | C28: EUR | E28: Full-year result pending
A29: Cognizant | B29: 2016 | C29: USD | D29: 13487 | E29: Cognizant FY2018 10-K | F29: https://www.sec.gov/Archives/edgar/data/1058290/000105829019000009/ctsh20181231-10k.htm
A30: Cognizant | B30: 2017 | C30: USD | D30: 14810 | E30: Cognizant FY2018 10-K | F30: https://www.sec.gov/Archives/edgar/data/1058290/000105829019000009/ctsh20181231-10k.htm
A31: Cognizant | B31: 2018 | C31: USD | D31: 16125 | E31: Cognizant FY2018 10-K | F31: https://www.sec.gov/Archives/edgar/data/1058290/000105829019000009/ctsh20181231-10k.htm
A32: Cognizant | B32: 2019 | C32: USD | D32: 16783 | E32: Cognizant FY2021 10-K | F32: https://www.sec.gov/Archives/edgar/data/1058290/000105829022000023/ctsh-20211231.htm
A33: Cognizant | B33: 2020 | C33: USD | D33: 16652 | E33: Cognizant FY2021 10-K | F33: https://www.sec.gov/Archives/edgar/data/1058290/000105829022000023/ctsh-20211231.htm
A34: Cognizant | B34: 2021 | C34: USD | D34: 18507 | E34: Cognizant FY2021 10-K | F34: https://www.sec.gov/Archives/edgar/data/1058290/000105829022000023/ctsh-20211231.htm
A35: Cognizant | B35: 2022 | C35: USD | D35: 19428 | E35: Cognizant FY2022 10-K | F35: https://www.sec.gov/Archives/edgar/data/1058290/000105829023000027/ctsh-20221231.htm
A36: Cognizant | B36: 2023 | C36: USD | D36: 19353 | E36: Cognizant FY2025 10-K | F36: https://www.sec.gov/Archives/edgar/data/1058290/000105829026000008/ctsh-20251231.htm
A37: Cognizant | B37: 2024 | C37: USD | D37: 19736 | E37: Cognizant FY2025 10-K | F37: https://www.sec.gov/Archives/edgar/data/1058290/000105829026000008/ctsh-20251231.htm
A38: Cognizant | B38: 2025 | C38: USD | D38: 21108 | E38: Cognizant FY2025 10-K | F38: https://www.sec.gov/Archives/edgar/data/1058290/000105829026000008/ctsh-20251231.htm
A39: Cognizant | B39: 2026 | C39: USD | E39: Full-year result pending
A40: Atos | B40: 2016 | C40: EUR | D40: 11717 | E40: Atos FY2016 results | F40: https://atos.net/en/2017/press-release/general-press-releases_2017_02_22/2016-record-results
A41: Atos | B41: 2017 | C41: EUR | D41: 12691 | E41: Atos FY2017 results | F41: https://www.atosgroup.com/en/press/2017-annual-results
A42: Atos | B42: 2018 | C42: EUR | D42: 12258 | E42: Atos FY2018 results | F42: https://www.atosgroup.com/en/press/2018-annual-results
A43: Atos | B43: 2019 | C43: EUR | D43: 11588 | E43: Atos FY2019 results | F43: https://www.atosgroup.com/en/press/2019-annual-results
...

Sheet FX rates
A2: Annual average exchange rates
A4: USD per 1 EUR, annual average. Applied to Capgemini and Atos calendar-year revenue. | F4: CGI fiscal-year average rate, CAD per USD (year ended 30 Sep). Conversion = reported CAD m ÷ rate.
A6: Calendar year | B6: USD per EUR | C6: Definition | D6: Source URL | F6: CGI FY | G6: CAD per USD | H6: Source URL
A7: 2016 | B7: 1.1072 | C7: Annual average of daily observations | D7: https://fred.stlouisfed.org/series/AEXUSEU | F7: 2016 | G7: 1.3255 | H7: https://www.cgi.com/sites/default/files/2018-07/cgi-2017-annual-report.pdf
A8: 2017 | B8: 1.1301 | C8: Annual average of daily observations | D8: https://fred.stlouisfed.org/series/AEXUSEU | F8: 2017 | G8: 1.314 | H8: https://www.cgi.com/sites/default/files/2018-07/cgi-2017-annual-report.pdf
A9: 2018 | B9: 1.1817 | C9: Annual average of daily observations | D9: https://fred.stlouisfed.org/series/AEXUSEU | F9: 2018 | G9: 1.2838 | H9: https://www.cgi.com/sites/default/files/2019-12/cgi-2019-annual-report.pdf
A10: 2019 | B10: 1.1194 | C10: Annual average of daily observations | D10: https://fred.stlouisfed.org/series/AEXUSEU | F10: 2019 | G10: 1.327 | H10: https://www.cgi.com/sites/default/files/2019-12/cgi-2019-annual-report.pdf
A11: 2020 | B11: 1.141 | C11: Annual average of daily observations | D11: https://fred.stlouisfed.org/series/AEXUSEU | F11: 2020 | G11: 1.3457 | H11: https://www.cgi.com/sites/default/files/2021-12/cgi-2021-annual-report.pdf
A12: 2021 | B12: 1.183 | C12: Annual average of daily observations | D12: https://fred.stlouisfed.org/series/AEXUSEU | F12: 2021 | G12: 1.2643 | H12: https://www.cgi.com/sites/default/files/2021-12/cgi-2021-annual-report.pdf
A13: 2022 | B13: 1.0534 | C13: Annual average of daily observations | D13: https://fred.stlouisfed.org/series/AEXUSEU | F13: 2022 | G13: 1.2777 | H13: https://www.cgi.com/sites/default/files/2022-12/cgi-2022-annual-report.pdf
A14: 2023 | B14: 1.0817 | C14: Annual average of daily observations | D14: https://fred.stlouisfed.org/series/AEXUSEU | F14: 2023 | G14: 1.3485 | H14: https://www.cgi.com/sites/default/files/2023-12/cgi-2023-annual-report.pdf
A15: 2024 | B15: 1.082 | C15: Annual average of daily observations | D15: https://fred.stlouisfed.org/series/AEXUSEU | F15: 2024 | G15: 1.3609 | H15: https://www.cgi.com/sites/default/files/2025-12/cgi-2025-annual-report.pdf
A16: 2025 | B16: 1.1306 | C16: Annual average of daily observations | D16: https://fred.stlouisfed.org/series/AEXUSEU | F16: 2025 | G16: 1.3984 | H16: https://www.cgi.com/sites/default/files/2025-12/cgi-2025-annual-report.pdf
A18: Source: Federal Reserve G.5A annual series, accessed via FRED. Conversion = reported EUR m × USD/EUR.
