Workbook

Sheet Cover
A1: HCLTech Fresh Integrated Financial Model
A2: Fresh-source build | Quarterly P&L FY16–FY26 | Annual three statements FY16–FY30E | INR crore unless stated
A4: Operating model, cash-anchored three statements, client mining, AI revenue and valuation
A6: Model scope | B6: Quarterly P&L only; annual P&L, balance sheet and cash flow
A7: Historical period | B7: FY16–FY26
A8: Forecast period | B8: FY27E–FY30E
A9: Source policy | B9: Official HCLTech results / annual reports; market prices from HCLTECH.NS history
A10: FY16 convention | B10: 12-month comparable P&L; statutory FY16 BS/CFS reflects the 9-month transition year
A11: Cash policy | B11: Historical closing cash is linked to the reported annual balance sheet; differences versus audited CFS cash sit in an explicit basis / FX reconciliation line
A12: Forecast revenue | B12: Core services capacity and pricing, T&M mix / AI deflation, Advanced AI recognized revenue, and HCLSoftware
A13: Billable FTE policy | B13: Historical implied billable FTE only where utilization was reported; later years remain blank rather than invented
A14: Client metric | B14: Revenue per $1m+ client is a proxy; total active client count is not assumed
A15: Formatting | B15: Aptos Narrow 10; reported actuals medium blue; formulas black; forecast columns pale green
A16: Model status | B16: =Checks!B6 -> OK

Sheet Summary
A1: HCLTech Financial Summary
A2: Integrated view of financials, operating drivers, cash generation and valuation
A5: Metric | B5: Units | C5: FY16A | D5: FY17A | E5: FY18A | F5: FY19A | G5: FY20A | H5: FY21A | I5: FY22A | J5: FY23A | K5: FY24A | L5: FY25A | M5: FY26A | N5: FY27E | O5: FY28E | P5: FY29E | Q5: FY30E
A7: Revenue | B7: ₹ cr | C7: ='Annual P&L'!C7 -> 40913 | D7: ='Annual P&L'!D7 -> 46723 | E7: ='Annual P&L'!E7 -> 50570 | F7: ='Annual P&L'!F7 -> 60427 | G7: ='Annual P&L'!G7 -> 70678 | H7: ='Annual P&L'!H7 -> 75379 | I7: ='Annual P&L'!I7 -> 85651 | J7: ='Annual P&L'!J7 -> 101456 | ... Q7: ='Annual P&L'!Q7 -> 175279.02
A8: Revenue growth | B8: % | C8: ='Annual P&L'!C8 -> 0 | D8: ='Annual P&L'!D8 -> 0.14200865 | E8: ='Annual P&L'!E8 -> 0.082336323 | F8: ='Annual P&L'!F8 -> 0.19491794 | G8: ='Annual P&L'!G8 -> 0.16964271 | H8: ='Annual P&L'!H8 -> 0.066512918 | I8: ='Annual P&L'!I8 -> 0.13627138 | J8: ='Annual P&L'!J8 -> 0.18452791 | ... Q8: ='Annual P&L'!Q8 -> 0.081531488
A9: EBITDA | B9: ₹ cr | C9: ='Annual P&L'!C17 -> 8732 | D9: ='Annual P&L'!D17 -> 10309 | E9: ='Annual P&L'!E17 -> 11440 | F9: ='Annual P&L'!F17 -> 13967 | G9: ='Annual P&L'!G17 -> 16694 | H9: ='Annual P&L'!H17 -> 19955 | I9: ='Annual P&L'!I17 -> 20530 | J9: ='Annual P&L'!J17 -> 22628 | ... Q9: ='Annual P&L'!Q17 -> 37684.989
A10: EBITDA margin | B10: % | C10: ='Annual P&L'!C18 -> 0.21342849 | D10: ='Annual P&L'!D18 -> 0.2206408 | E10: ='Annual P&L'!E18 -> 0.22622108 | F10: ='Annual P&L'!F18 -> 0.2311384 | G10: ='Annual P&L'!G18 -> 0.23619797 | H10: ='Annual P&L'!H18 -> 0.2647289 | I10: ='Annual P&L'!I18 -> 0.23969364 | J10: ='Annual P&L'!J18 -> 0.22303264 | ... Q10: ='Annual P&L'!Q18 -> 0.215
A11: EBIT | B11: ₹ cr | C11: ='Annual P&L'!C20 -> 8226 | D11: ='Annual P&L'!D20 -> 9474 | E11: ='Annual P&L'!E20 -> 9987 | F11: ='Annual P&L'!F20 -> 11820 | G11: ='Annual P&L'!G20 -> 13853 | H11: ='Annual P&L'!H20 -> 15344 | I11: ='Annual P&L'!I20 -> 16204 | J11: ='Annual P&L'!J20 -> 18483 | ... Q11: ='Annual P&L'!Q20 -> 32426.619
A12: EBIT margin | B12: % | C12: ='Annual P&L'!C21 -> 0.20106079 | D12: ='Annual P&L'!D21 -> 0.20276951 | E12: ='Annual P&L'!E21 -> 0.19748863 | F12: ='Annual P&L'!F21 -> 0.19560792 | G12: ='Annual P&L'!G21 -> 0.19600158 | H12: ='Annual P&L'!H21 -> 0.20355802 | I12: ='Annual P&L'!I21 -> 0.18918635 | J12: ='Annual P&L'!J21 -> 0.1821775 | ... Q12: ='Annual P&L'!Q21 -> 0.185
A13: Net income | B13: ₹ cr | C13: ='Annual P&L'!C29 -> 7354 | D13: ='Annual P&L'!D29 -> 8457 | E13: ='Annual P&L'!E29 -> 8780 | F13: ='Annual P&L'!F29 -> 10123 | G13: ='Annual P&L'!G29 -> 11062 | H13: ='Annual P&L'!H29 -> 11145 | I13: ='Annual P&L'!I29 -> 13499 | J13: ='Annual P&L'!J29 -> 14851 | ... Q13: ='Annual P&L'!Q29 -> 25300.616
A14: Net margin | B14: % | C14: ='Annual P&L'!C30 -> 0.17974727 | D14: ='Annual P&L'!D30 -> 0.18100293 | E14: ='Annual P&L'!E30 -> 0.17362072 | F14: ='Annual P&L'!F30 -> 0.16752445 | G14: ='Annual P&L'!G30 -> 0.15651263 | H14: ='Annual P&L'!H30 -> 0.14785285 | I14: ='Annual P&L'!I30 -> 0.1576047 | J14: ='Annual P&L'!J30 -> 0.14637873 | ... Q14: ='Annual P&L'!Q30 -> 0.14434481
A15: Diluted EPS | B15: ₹ / share | C15: ='Annual P&L'!C34 -> 27.084561 | D15: ='Annual P&L'!D34 -> 31.146877 | E15: ='Annual P&L'!E34 -> 32.336476 | F15: ='Annual P&L'!F34 -> 37.282705 | G15: ='Annual P&L'!G34 -> 40.741014 | H15: ='Annual P&L'!H34 -> 41.0467 | I15: ='Annual P&L'!I34 -> 49.716411 | J15: ='Annual P&L'!J34 -> 54.695787 | ... Q15: ='Annual P&L'!Q34 -> 93.18141
A16: CFO | B16: ₹ cr | C16: ='Annual Cash Flow'!C15 -> 3823 | D16: ='Annual Cash Flow'!D15 -> 8995 | E16: ='Annual Cash Flow'!E15 -> 8328 | F16: ='Annual Cash Flow'!F15 -> 8971 | G16: ='Annual Cash Flow'!G15 -> 13359 | H16: ='Annual Cash Flow'!H15 -> 19618 | I16: ='Annual Cash Flow'!I15 -> 16900 | J16: ='Annual Cash Flow'!J15 -> 18009 | ... Q16: ='Annual Cash Flow'!Q15 -> 29887.889
A17: FCF | B17: ₹ cr | C17: ='Annual Cash Flow'!C38 -> 2881 | D17: ='Annual Cash Flow'!D38 -> 5073 | E17: ='Annual Cash Flow'!E38 -> 3007 | F17: ='Annual Cash Flow'!F38 -> 5537 | G17: ='Annual Cash Flow'!G38 -> 11493 | H17: ='Annual Cash Flow'!H38 -> 17714 | I17: ='Annual Cash Flow'!I38 -> 15255 | J17: ='Annual Cash Flow'!J38 -> 16348 | ... Q17: ='Annual Cash Flow'!Q38 -> 27433.982
A18: Closing cash | B18: ₹ cr | C18: ='Annual Balance Sheet'!C7 -> 729.3 | D18: ='Annual Balance Sheet'!D7 -> 1316.5 | E18: ='Annual Balance Sheet'!E7 -> 1693.9 | F18: ='Annual Balance Sheet'!F7 -> 5929 | G18: ='Annual Balance Sheet'!G7 -> 4843 | H18: ='Annual Balance Sheet'!H7 -> 6515 | I18: ='Annual Balance Sheet'!I7 -> 10510 | J18: ='Annual Balance Sheet'!J7 -> 9065 | ... Q18: ='Annual Balance Sheet'!Q7 -> 16169.033
A19: Net cash / (debt) | B19: ₹ cr | C19: ='Annual Balance Sheet'!C34 -> -243.9 | D19: ='Annual Balance Sheet'!D34 -> 774.8 | E19: ='Annual Balance Sheet'!E34 -> 1256.8 | F19: ='Annual Balance Sheet'!F34 -> 1943 | G19: ='Annual Balance Sheet'!G34 -> -249 | H19: ='Annual Balance Sheet'!H34 -> 2608 | I19: ='Annual Balance Sheet'!I34 -> 6525 | J19: ='Annual Balance Sheet'!J34 -> 6814 | ... Q19: ='Annual Balance Sheet'!Q34 -> 16169.033
A20: Total headcount | B20: # | C20: ='Revenue Drivers'!C6 -> 104896 | D20: ='Revenue Drivers'!D6 -> 115973 | E20: ='Revenue Drivers'!E6 -> 120081 | F20: ='Revenue Drivers'!F6 -> 137965 | G20: ='Revenue Drivers'!G6 -> 150423 | H20: ='Revenue Drivers'!H6 -> 168977 | I20: ='Revenue Drivers'!I6 -> 208877 | J20: ='Revenue Drivers'!J6 -> 225944 | ... Q20: ='Revenue Drivers'!Q6 -> 261948.71
A21: Billable FTE | B21: # | C21: ='Revenue Drivers'!C11 -> 81875.544 | D21: ='Revenue Drivers'!D11 -> 90453.779 | E21: ='Revenue Drivers'!E11 -> 94116.335 | F21: ='Revenue Drivers'!F11 -> 108216.32 | G21: ='Revenue Drivers'!G11 -> 0 | H21: ='Revenue Drivers'!H11 -> 0 | I21: ='Revenue Drivers'!I11 -> 0 | J21: ='Revenue Drivers'!J11 -> 0 | ... Q21: ='Revenue Drivers'!Q11 -> 209297.02
A22: Advanced AI recognized revenue / FY26 run-rate proxy | B22: $m | C22: ='Revenue Drivers'!C21 -> 0 | D22: ='Revenue Drivers'!D21 -> 0 | E22: ='Revenue Drivers'!E21 -> 0 | F22: ='Revenue Drivers'!F21 -> 0 | G22: ='Revenue Drivers'!G21 -> 0 | H22: ='Revenue Drivers'!H21 -> 0 | I22: ='Revenue Drivers'!I21 -> 0 | J22: ='Revenue Drivers'!J21 -> 0 | ... Q22: ='Revenue Drivers'!Q21 -> 1049.8488
A23: TCV | B23: $m | C23: ='Client Data'!C21 -> 0 | D23: ='Client Data'!D21 -> 0 | E23: ='Client Data'!E21 -> 0 | F23: ='Client Data'!F21 -> 0 | G23: ='Client Data'!G21 -> 0 | H23: ='Client Data'!H21 -> 7300 | I23: ='Client Data'!I21 -> 8308 | J23: ='Client Data'!J21 -> 8850 | ... Q23: ='Client Data'!Q21 -> 12556.294
A24: Revenue / $1m+ client proxy | B24: $m | C24: ='Client Data'!C19 -> 12.936515 | D24: ='Client Data'!D19 -> 13.903162 | E24: ='Client Data'!E19 -> 13.97148 | F24: ='Client Data'!F19 -> 13.855538 | G24: ='Client Data'!G19 -> 12.561315 | H24: ='Client Data'!H19 -> 12.577256 | I24: ='Client Data'!I19 -> 13.017007 | J24: ='Client Data'!J19 -> 13.453674 | ... Q24: ='Client Data'!Q19 -> 13.611579
A25: Share price / implied target | B25: ₹ / share | C25: =Valuation!C7 -> 407.04999 | D25: =Valuation!D7 -> 437.375 | E25: =Valuation!E7 -> 484.29999 | F25: =Valuation!F7 -> 541.45001 | G25: =Valuation!G7 -> 436.39999 | H25: =Valuation!H7 -> 982.65002 | I25: =Valuation!I7 -> 1163.75 | J25: =Valuation!J7 -> 1085.25 | ... Q25: =Valuation!Q7 -> 1956.8096
A26: P/E | B26: x | C26: =Valuation!C13 -> 15.028857 | D26: =Valuation!D13 -> 14.042339 | E26: =Valuation!E13 -> 14.976894 | F26: =Valuation!F13 -> 14.52282 | G26: =Valuation!G13 -> 10.711564 | H26: =Valuation!H13 -> 23.939806 | I26: =Valuation!I13 -> 23.407764 | J26: =Valuation!J13 -> 19.841565 | ... Q26: =Valuation!Q13 -> 21
A27: EV / EBITDA | B27: x | C27: =Valuation!C14 -> 11.404198 | D27: =Valuation!D14 -> 10.335663 | E27: =Valuation!E14 -> 10.671669 | F27: =Valuation!F14 -> 9.9898539 | G27: =Valuation!G14 -> 6.4780679 | H27: =Valuation!H14 -> 12.532134 | I27: =Valuation!I14 -> 14.510903 | J27: =Valuation!J14 -> 12.110805 | ... Q27: =Valuation!Q14 -> 12.847995
A28: Dividend yield | B28: % | C28: =Valuation!C17 -> 0.024415823 | D28: =Valuation!D17 -> 0.034274029 | E28: =Valuation!E17 -> 0.015453741 | F28: =Valuation!F17 -> 0.0089904745 | G28: =Valuation!G17 -> 0.013721664 | H28: =Valuation!H17 -> 0.012210226 | I28: =Valuation!I17 -> 0.036063184 | J28: =Valuation!J17 -> 0.044124994 | ... Q28: =Valuation!Q17 -> 0.042880832

Sheet Sources
A1: Sources & Data Conventions
A2: Primary-source register and transparent treatment of unavailable disclosures
A5: ID | B5: Data / Period | C5: Units | D5: Primary source | E5: Use in model | F5: Status | G5: Notes
A6: S1 | B6: Quarterly / annual investor releases FY16–FY26 | C6: ₹ cr / $m | D6: https://www.hcltech.com/en-us/investor-relations/financial-results | E6: Quarterly P&L, management P&L, segments, clients, AI, headcount | F6: Loaded | G6: Official company archive
A7: S2 | B7: Annual reports FY16–FY26 | C7: ₹ cr | D7: https://www.hcltech.com/en-us/investor-relations/annual-report | E7: Audited CFS controls and accounting cross-checks | F7: Loaded | G7: FY16 was a 9-month statutory transition period
A8: S3 | B8: FY26 Q4 investor release | C8: ₹ cr / $m | D8: https://www.hcltech.com/sites/default/files/document/open/quarter-results/2026-04/hcltech-q4-fy26-investor-release.pdf | E8: FY26 P&L, BS, CFS, AI, segments and clients | F8: Loaded | G8: Advanced AI Q4 recognized revenue $155m; exit annualized revenue $620m
A9: S4 | B9: FY26 annual report | C9: ₹ cr | D9: https://www.hcltech.com/sites/default/files/document/open/annual-report/2026-07/AGM-Notice-Annual-Report-FY-2025-26.pdf | E9: Audited FY26 cash flow and balances | F9: Loaded | G9: CFS ending cash differs from investor-release BS cash; explicit reconciliation retained
A10: S5 | B10: HCLTECH.NS price history | C10: ₹ / share | D10: https://query1.finance.yahoo.com/v8/finance/chart/HCLTECH.NS | E10: Daily prices and FY-end share prices | F10: Loaded | G10: Market-price source only; no valuation opinions fetched
A11: S6 | B11: Advanced AI Q1 FY27 update | C11: $m | D11: https://www.hcltech.com/en-us/investor-relations/financial-results | E11: Q1 FY27 recognized AI revenue | F11: Loaded | G11: $171m reported
A12: S7 | B12: FY17–FY23 quarterly investor releases | C12: % / # | D12: https://www.hcltech.com/en-us/investor-relations/financial-results | E12: Historical vertical, geography, contract mix, client bands and FY23 quarterly P&L | F12: Loaded | G12: Annual operating mix loaded only where disclosed; recast quarter lines may differ modestly from annual controls
A13: S8 | B13: FY17–FY26 annual reports | C13: ₹ cr / % | D13: https://www.hcltech.com/en-us/investor-relations/annual-report | E13: Audited cash flows, segment restatements and financial controls | F13: Loaded | G13: Gross cash capex and acquisition lines retained separately from total CFI
A14: S9 | B14: FY23 large-deal announcement | C14: $m | D14: https://www.hcltech.com/en-us/press-releases/hcltech-delivers-another-year-stellar-growth-robust-deal-pipeline | E14: FY23 new-deal TCV | F14: Loaded | G14: $8.85bn
A15: S10 | B15: Unavailable disclosures | C15: n/a | D15: n/a | E15: Blanks retained | F15: Policy | G15: No total active clients and no utilization / billable FTE reported after FY19; FY20 annual operational mix not disclosed

Sheet Assumptions
A1: Forecast Assumptions
A2: Blue text on yellow = editable forecast input; all forecast outputs are formula-linked
A5: Driver | B5: Units | C5: FY27E | D5: FY28E | E5: FY29E | F5: FY30E
A6: Total headcount growth | B6: % | C6: 0.03 | D6: 0.035 | E6: 0.04 | F6: 0.04
A7: Service employee share | B7: % | C7: 0.94 | D7: 0.94 | E7: 0.94 | F7: 0.94
A8: Blended utilization / billable rate | B8: % | C8: 0.84 | D8: 0.845 | E8: 0.85 | F8: 0.85
A9: Revenue per billable FTE pricing / productivity | B9: % | C9: 0.03 | D9: 0.035 | E9: 0.04 | F9: 0.04
A10: T&M mix | B10: % | C10: 0.34 | D10: 0.33 | E10: 0.32 | F10: 0.31
A11: AI deflation on T&M revenue | B11: % | C11: 0.01 | D11: 0.013 | E11: 0.015 | F11: 0.015
A12: Advanced AI recognized revenue growth | B12: % | D12: 0.15 | E12: 0.12 | F12: 0.1
A13: HCLSoftware revenue growth | B13: % | C13: 0.04 | D13: 0.05 | E13: 0.06 | F13: 0.06
A14: USD / INR average | B14: ₹ / $ | C14: 95 | D14: 96 | E14: 97 | F14: 98
A15: Gross margin | B15: % | C15: 0.342 | D15: 0.344 | E15: 0.346 | F15: 0.347
A16: R&D / revenue | B16: % | C16: 0.015 | D16: 0.015 | E16: 0.015 | F16: 0.015
A17: D&A / revenue | B17: % | C17: 0.033 | D17: 0.032 | E17: 0.031 | F17: 0.03
A18: EBIT margin | B18: % | C18: 0.18 | D18: 0.182 | E18: 0.184 | F18: 0.185
A19: Effective tax rate | B19: % | C19: 0.25 | D19: 0.25 | E19: 0.25 | F19: 0.25
A20: Other income yield on cash + investments | B20: % | C20: 0.03 | D20: 0.03 | E20: 0.03 | F20: 0.03
A21: Receivable days | B21: days | C21: 64 | D21: 63 | E21: 62 | F21: 61
A22: Unbilled days | B22: days | C22: 22 | D22: 22 | E22: 21 | F22: 21
A23: Other current assets / revenue | B23: % | C23: 0.058 | D23: 0.057 | E23: 0.056 | F23: 0.055
A24: Current operating liabilities / revenue | B24: % | C24: 0.225 | D24: 0.223 | E24: 0.221 | F24: 0.22
... A39: LTM attrition | B39: % | C39: 0.125 | D39: 0.123 | E39: 0.12 | F39: 0.12
A40: Advanced AI recognized revenue | B40: $m | C40: 741

Sheet Raw Financials
A1: Raw Reported Financials — Source Layer
A2: Hardcoded reported inputs only; actual values in medium blue; calculations live in downstream tabs
A4: Annual reported financials (INR crore unless stated)
A5: Metric | B5: Units | C5: FY16A | D5: FY17A | E5: FY18A | F5: FY19A | G5: FY20A | H5: FY21A | I5: FY22A | J5: FY23A | K5: FY24A | L5: FY25A | M5: FY26A
A6: Revenue | B6: ₹ cr | C6: 40913 | D6: 46723 | E6: 50570 | F6: 60427 | G6: 70678 | H6: 75379 | I6: 85651 | J6: 101456 | K6: 109913 | L6: 117055 | M6: 130144
A7: Direct costs | B7: ₹ cr | C7: 26901 | D7: 30890 | E7: 33237 | F7: 39268 | G7: 44018 | H7: 44591 | I7: 52760 | J7: 64523 | K7: 70474 | L7: 76157 | M7: 85811
A8: Reported gross profit | B8: ₹ cr | C8: 14012 | D8: 15833 | E8: 17333 | F8: 21159 | G8: 26659 | H8: 30788 | I8: 32891 | J8: 36933 | K8: 39439 | L8: 40898 | M8: 44333
A9: R&D | B9: ₹ cr | G9: 1276 | H9: 1383 | I9: 1526 | J9: 1632 | K9: 1651 | L9: 1658 | M9: 2000
A10: SG&A | B10: ₹ cr | C10: 5217 | D10: 5524 | E10: 5894 | F10: 7191 | G10: 8690 | H10: 9348 | I10: 10835 | J10: 12673 | K10: 13588 | L10: 13736 | M10: 15581
A11: Reported EBITDA | B11: ₹ cr | C11: 8795 | D11: 10309 | E11: 11440 | F11: 13967 | G11: 16694 | H11: 20057 | I11: 20530 | J11: 22628 | K11: 24200 | L11: 25504 | M11: 26752
A12: D&A | B12: ₹ cr | C12: 506 | D12: 835 | E12: 1453 | F12: 2147 | G12: 2841 | H12: 4611 | I12: 4326 | J12: 4145 | K12: 4173 | L12: 4084 | M12: 4355
A13: EBIT | B13: ₹ cr | C13: 8226 | D13: 9474 | E13: 9987 | F13: 11820 | G13: 13853 | H13: 15344 | I13: 16204 | J13: 18483 | K13: 20027 | L13: 21420 | M13: 22397
A14: FX gain / (loss) | B14: ₹ cr | C14: 72 | D14: 188 | E14: 541 | F14: 182 | G14: -15 | H14: 46 | I14: 328 | J14: 91 | K14: -2 | L14: 86 | M14: -241
A15: Other income, net | B15: ₹ cr | C15: 937 | D15: 746 | E15: 570 | F15: 623 | G15: 193 | H15: 463 | I15: 419 | J15: 914 | K15: 942 | L15: 1755 | M15: 902
A16: Tax | B16: ₹ cr | C16: 1883 | D16: 1952 | E16: 2316 | F16: 2481 | G16: 2938 | H16: 4684 | I16: 3428 | J16: 4643 | K16: 5257 | L16: 5862 | M16: 5687
A17: NCI / other attribution | B17: ₹ cr | G17: 31 | H17: 24 | I17: 24 | J17: -6 | K17: 8 | L17: 9
A18: Net income attributable | B18: ₹ cr | C18: 7354 | D18: 8457 | E18: 8780 | F18: 10123 | G18: 11062 | H18: 11145 | I18: 13499 | J18: 14851 | K18: 15702 | L18: 17390 | M18: 17361
A19: USD revenue | B19: $m | C19: 6235.4 | D19: 7035 | E19: 7838 | F19: 8632 | G19: 9936 | H19: 10175 | I19: 11481 | J19: 12633 | K19: 13269 | L19: 13840 | M19: 14664
A20: Headcount | B20: # | C20: 104896 | D20: 115973 | E20: 120081 | F20: 137965 | G20: 150423 | H20: 168977 | I20: 208877 | J20: 225944 | K20: 227481 | L20: 223420 | M20: 227181
A21: Reported utilization | B21: % | C21: 0.856 | D21: 0.857 | E21: 0.859 | F21: 0.854
A22: TCV | B22: $m | H22: 7300 | I22: 8308 | J22: 8850 | K22: 9759 | L22: 9268 | M22: 9323
A23: Cash flow from operations | B23: ₹ cr | C23: 3823 | D23: 8995 | E23: 8328 | F23: 8971 | G23: 13359 | H23: 19618 | I23: 16900 | J23: 18009 | K23: 22448 | L23: 22261 | M23: 19975
A24: Cash flow from investing | B24: ₹ cr | C24: -2189 | D24: -3817 | E24: -2283 | F24: -3073 | G24: -12374 | H24: -5730 | I24: 1477 | J24: -3931 | K24: -6723 | L24: -4914 | M24: -1473
A25: Cash flow from financing | B25: ₹ cr | C25: -2237 | D25: -4533 | E25: -5714 | F25: -1462 | G25: -3168 | H25: -11192 | I25: -14508 | J25: -15881 | K25: -15464 | L25: -18561 | M25: -19369
A26: Cash dividends paid | B26: ₹ cr | C26: -2697 | D26: -4068 | E26: -2031 | F26: -1321 | G26: -1625 | H26: -3256 | I26: -11389 | J26: -12995 | K26: -14073 | L26: -16250 | M26: -14618
A27: Capex | B27: ₹ cr | C27: -942 | D27: -3922 | E27: -5321 | F27: -3434 | G27: -1866 | H27: -1904 | I27: -1645 | J27: -1661 | K27: -1048 | L27: -1108 | M27: -1422
A28: Acquisitions / cash acquired | B28: ₹ cr | C28: -1183 | D28: -488 | E28: -107 | F28: -2828 | G28: -6091 | H28: -1211 | I28: 40 | J28: -738 | K28: -2048 | L28: -2032 | M28: -160
A29: Cash & equivalents | B29: ₹ cr | C29: 729.3 | D29: 1316.5 | E29: 1693.9 | F29: 5929 | G29: 4843 | H29: 6515 | I29: 10510 | J29: 9065 | K29: 9456 | L29: 8245 | M29: 8265
A30: Receivables | B30: ₹ cr | C30: 7721.3 | D30: 8301.4 | E30: 9639.4 | F30: 11706 | G30: 14134 | H30: 13663 | I30: 15476 | J30: 19572 | K30: 19483 | L30: 19523 | M30: 23585
A31: Unbilled receivables | B31: ₹ cr | C31: 3001.5 | D31: 2501.2 | E31: 2618.1 | G31: 3638 | H31: 3862 | I31: 5195 | J31: 5934 | K31: 6038 | L31: 6319 | M31: 7956
A32: Treasury / current investments | B32: ₹ cr | C32: 11123.6 | D32: 11365.3 | E32: 8083.8 | F32: 5462 | G32: 10530 | H32: 13975 | I32: 11373 | J32: 13647 | K32: 18532 | L32: 21493 | M32: 23136
A33: Other current assets | B33: ₹ cr | C33: 2410.3 | D33: 2983.2 | E33: 2519.8 | F33: 3716 | G33: 5188 | H33: 4943 | I33: 5326 | J33: 5359 | K33: 5822 | L33: 6529 | M33: 7600
A34: Total current assets | B34: ₹ cr | C34: 24985.9 | D34: 26467.6 | E34: 24555 | F34: 29717 | G34: 38425 | H34: 43052 | I34: 48041 | J34: 53577 | K34: 59331 | L34: 62109 | M34: 70542
A35: PPE | B35: ₹ cr | C35: 4323.1 | D35: 4680.6 | E35: 5184.7 | F35: 5801 | G35: 6244 | H35: 6245 | I35: 5741 | J35: 5411 | K35: 4999 | L35: 4560 | M35: 4717
A36: ROU assets | B36: ₹ cr | I36: 2305 | J36: 2337 | K36: 2910 | L36: 3016 | M36: 3592
A37: Goodwill & intangibles | B37: ₹ cr | C37: 6419.4 | D37: 7358.3 | E37: 14405.7 | F37: 17695 | G37: 29421 | H37: 29150 | I37: 27160 | J37: 26911 | K37: 27262 | L37: 28655 | M37: 29130
A38: Other non-current assets reported | B38: ₹ cr | C38: 3878.9 | D38: 3711.8 | E38: 3767.5 | F38: 5293 | G38: 4149 | H38: 4389 | I38: 4298 | J38: 3435 | K38: 3863 | L38: 4843 | M38: 4955
A39: Total assets | B39: ₹ cr | C39: 39767.3 | D39: 46432.3 | E39: 48435.1 | F39: 58897 | G39: 83216 | H39: 87702 | I39: 89033 | J39: 93411 | K39: 99777 | L39: 105544 | M39: 116258
A40: Current operating liabilities | B40: ₹ cr | C40: 9508.5 | D40: 11147.7 | E40: 9914.3 | F40: 11148 | G40: 20889 | H40: 16755 | I40: 18014 | J40: 20420 | K40: 21532 | L40: 24471 | M40: 29828
A41: Short-term borrowings | B41: ₹ cr
...

Sheet Quarterly P&L
A1: Quarterly Profit & Loss
A2: Reported quarterly P&L only | FY16 is 12-month comparable, with Q1 derived as annual less Q2–Q4
A5: Metric | B5: Units | C5: Q1 FY16A | D5: Q2 FY16A | E5: Q3 FY16A | F5: Q4 FY16A | G5: Q1 FY17A | H5: Q2 FY17A | I5: Q3 FY17A | J5: Q4 FY17A | K5: Q1 FY18A | L5: Q2 FY18A | M5: Q3 FY18A | N5: Q4 FY18A | O5: Q1 FY19A | P5: Q2 FY19A | Q5: Q3 FY19A | R5: Q4 FY19A | S5: Q1 FY20A | T5: Q2 FY20A | U5: Q3 FY20A | V5: Q4 FY20A | W5: Q1 FY21A | X5: Q2 FY21A | Y5: Q3 FY21A | Z5: Q4 FY21A | AA5: Q1 FY22A | AB5: Q2 FY22A | AC5: Q3 FY22A | AD5: Q4 FY22A | AE5: Q1 FY23A | AF5: Q2 FY23A | AG5: Q3 FY23A | AH5: Q4 FY23A | AI5: Q1 FY24A | AJ5: Q2 FY24A | AK5: Q3 FY24A | AL5: Q4 FY24A | AM5: Q1 FY25A | AN5: Q2 FY25A | AO5: Q3 FY25A | AP5: Q4 FY25A | AQ5: Q1 FY26A | AR5: Q2 FY26A | AS5: Q3 FY26A | AT5: Q4 FY26A
A6: Revenue | B6: ₹ cr | C6: ='Raw Financials'!C56 -> 9777 | D6: ='Raw Financials'!D56 -> 10097 | E6: ='Raw Financials'!E56 -> 10341 | F6: ='Raw Financials'!F56 -> 10698 | G6: ='Raw Financials'!G56 -> 11336 | H6: ='Raw Financials'!H56 -> 11519 | I6: ='Raw Financials'!I56 -> 11814 | J6: ='Raw Financials'!J56 -> 12053 | ... AT6: ='Raw Financials'!AT56 -> 33981
A7: QoQ growth | B7: % | D7: =IFERROR(D6/C6-1,"") -> 0.032729876 | E7: =IFERROR(E6/D6-1,"") -> 0.024165594 | F7: =IFERROR(F6/E6-1,"") -> 0.034522773 | G7: =IFERROR(G6/F6-1,"") -> 0.059637315 | H7: =IFERROR(H6/G6-1,"") -> 0.01614326 | I7: =IFERROR(I6/H6-1,"") -> 0.025609862 | J7: =IFERROR(J6/I6-1,"") -> 0.020230235 | K7: =IFERROR(K6/J6-1,"") -> 0.007964822 | ... AT7: =IFERROR(AT6/AS6-1,"") -> 0.0032179972
A8: YoY growth | B8: % | G8: =IFERROR(G6/C6-1,"") -> 0.15945587 | H8: =IFERROR(H6/D6-1,"") -> 0.14083391 | I8: =IFERROR(I6/E6-1,"") -> 0.1424427 | J8: =IFERROR(J6/F6-1,"") -> 0.12665919 | K8: =IFERROR(K6/G6-1,"") -> 0.071718419 | L8: =IFERROR(L6/H6-1,"") -> 0.079433979 | M8: =IFERROR(M6/I6-1,"") -> 0.084137464 | N8: =IFERROR(N6/J6-1,"") -> 0.093420725 | ... AT8: =IFERROR(AT6/AP6-1,"") -> 0.1234874
A9: Direct costs | B9: ₹ cr | C9: ='Raw Financials'!C57 -> 6430 | D9: ='Raw Financials'!D57 -> 6742 | E9: ='Raw Financials'!E57 -> 6768 | F9: ='Raw Financials'!F57 -> 6961 | G9: ='Raw Financials'!G57 -> 7440 | H9: ='Raw Financials'!H57 -> 7653 | I9: ='Raw Financials'!I57 -> 7809 | J9: ='Raw Financials'!J57 -> 7987 | ... AT9: ='Raw Financials'!AT57 -> 22537
A10: Gross profit | B10: ₹ cr | C10: =IF(OR(C6="",C9=""),"",C6-C9) -> 3347 | D10: =IF(OR(D6="",D9=""),"",D6-D9) -> 3355 | E10: =IF(OR(E6="",E9=""),"",E6-E9) -> 3573 | F10: =IF(OR(F6="",F9=""),"",F6-F9) -> 3737 | G10: =IF(OR(G6="",G9=""),"",G6-G9) -> 3896 | H10: =IF(OR(H6="",H9=""),"",H6-H9) -> 3866 | I10: =IF(OR(I6="",I9=""),"",I6-I9) -> 4005 | J10: =IF(OR(J6="",J9=""),"",J6-J9) -> 4066 | ... AT10: =IF(OR(AT6="",AT9=""),"",AT6-AT9) -> 11444
A11: Gross margin | B11: % | C11: =IFERROR(C10/C6,"") -> 0.34233405 | D11: =IFERROR(D10/D6,"") -> 0.33227691 | E11: =IFERROR(E10/E6,"") -> 0.34551784 | F11: =IFERROR(F10/F6,"") -> 0.34931763 | G11: =IFERROR(G10/G6,"") -> 0.34368384 | H11: =IFERROR(H10/H6,"") -> 0.33561941 | I11: =IFERROR(I10/I6,"") -> 0.33900457 | J11: =IFERROR(J10/J6,"") -> 0.3373434 | ... AT11: =IFERROR(AT10/AT6,"") -> 0.33677643
A12: R&D | B12: ₹ cr | C12: ='Raw Financials'!C59 -> 0 | D12: ='Raw Financials'!D59 -> 0 | E12: ='Raw Financials'!E59 -> 0 | F12: ='Raw Financials'!F59 -> 0 | G12: ='Raw Financials'!G59 -> 0 | H12: ='Raw Financials'!H59 -> 0 | I12: ='Raw Financials'!I59 -> 0 | J12: ='Raw Financials'!J59 -> 0 | ... AT12: ='Raw Financials'!AT59 -> 530
A13: SG&A | B13: ₹ cr | C13: ='Raw Financials'!C60 -> 1248 | D13: ='Raw Financials'!D60 -> 1263 | E13: ='Raw Financials'!E60 -> 1348 | F13: ='Raw Financials'!F60 -> 1358 | G13: ='Raw Financials'!G60 -> 1375 | H13: ='Raw Financials'!H60 -> 1355 | I13: ='Raw Financials'!I60 -> 1377 | J13: ='Raw Financials'!J60 -> 1417 | ... AT13: ='Raw Financials'!AT60 -> 4202
A14: Other operating / reclassification | B14: ₹ cr | C14: =IF(OR(C10="",C12="",C13="",C16=""),"",C10-C12-C13-C16) -> 13 | D14: =IF(OR(D10="",D12="",D13="",D16=""),"",D10-D12-D13-D16) -> 13 | E14: =IF(OR(E10="",E12="",E13="",E16=""),"",E10-E12-E13-E16) -> 19 | F14: =IF(OR(F10="",F12="",F13="",F16=""),"",F10-F12-F13-F16) -> 18 | G14: =IF(OR(G10="",G12="",G13="",G16=""),"",G10-G12-G13-G16) -> 19 | H14: =IF(OR(H10="",H12="",H13="",H16=""),"",H10-H12-H13-H16) -> 21 | I14: =IF(OR(I10="",I12="",I13="",I16=""),"",I10-I12-I13-I16) -> 0 | J14: =IF(OR(J10="",J12="",J13="",J16=""),"",J10-J12-J13-J16) -> 0 | ... AT14: =IF(OR(AT10="",AT12="",AT13="",AT16=""),"",AT10-AT12-AT13-AT16) -> 0
A15: EBITDA | B15: ₹ cr | C15: =IFERROR(C16/C6,"") -> 0.21335788 | D15: =IFERROR(D16/D6,"") -> 0.20590274 | E15: =IFERROR(E16/E6,"") -> 0.2133256 | F15: =IFERROR(F16/F6,"") -> 0.22069546 | G15: =IFERROR(G16/G6,"") -> 0.22071277 | H15: =IFERROR(H16/H6,"") -> 0.2161646 | I15: =IFERROR(I16/I6,"") -> 0.22244794 | J15: =IFERROR(J16/J6,"") -> 0.21977931 | ... AT15: =IFERROR(AT16/AT6,"") -> 0.19752214
A16: EBITDA margin | B16: % | C16: =IF(OR(C18="",C17=""),"",C18+C17) -> 2086 | D16: =IF(OR(D18="",D17=""),"",D18+D17) -> 2079 | E16: =IF(OR(E18="",E17=""),"",E18+E17) -> 2206 | F16: =IF(OR(F18="",F17=""),"",F18+F17) -> 2361 | G16: =IF(OR(G18="",G17=""),"",G18+G17) -> 2502 | H16: =IF(OR(H18="",H17=""),"",H18+H17) -> 2490 | I16: =IF(OR(I18="",I17=""),"",I18+I17) -> 2628 | J16: =IF(OR(J18="",J17=""),"",J18+J17) -> 2649 | ... AT16: =IF(OR(AT18="",AT17=""),"",AT18+AT17) -> 6712
A17: D&A | B17: ₹ cr | C17: ='Raw Financials'!C62 -> 111 | D17: ='Raw Financials'!D62 -> 122 | E17: ='Raw Financials'!E62 -> 134 | F17: ='Raw Financials'!F62 -> 139 | G17: ='Raw Financials'!G62 -> 169 | H17: ='Raw Financials'!H62 -> 172 | I17: ='Raw Financials'!I62 -> 220 | J17: ='Raw Financials'!J62 -> 233 | ... AT17: ='Raw Financials'!AT62 -> 1092
A18: EBIT | B18: ₹ cr | C18: ='Raw Financials'!C63 -> 1975 | D18: ='Raw Financials'!D63 -> 1957 | E18: ='Raw Financials'!E63 -> 2072 | F18: ='Raw Financials'!F63 -> 2222 | G18: ='Raw Financials'!G63 -> 2333 | H18: ='Raw Financials'!H63 -> 2318 | I18: ='Raw Financials'!I63 -> 2408 | J18: ='Raw Financials'!J63 -> 2416 | ... AT18: ='Raw Financials'!AT63 -> 5620
A19: EBIT margin | B19: % | C19: =IFERROR(C18/C6,"") -> 0.2020047 | D19: =IFERROR(D18/D6,"") -> 0.19381995 | E19: =IFERROR(E18/E6,"") -> 0.20036747 | F19: =IFERROR(F18/F6,"") -> 0.20770237 | G19: =IFERROR(G18/G6,"") -> 0.20580452 | H19: =IFERROR(H18/H6,"") -> 0.20123275 | I19: =IFERROR(I18/I6,"") -> 0.20382597 | J19: =IFERROR(J18/J6,"") -> 0.20044802 | ... AT19: =IFERROR(AT18/AT6,"") -> 0.16538654
A20: FX gain / (loss) | B20: ₹ cr | C20: ='Raw Financials'!C64 -> 36 | D20: ='Raw Financials'!D64 -> 22 | E20: ='Raw Financials'!E64 -> 11 | F20: ='Raw Financials'!F64 -> 3 | G20: ='Raw Financials'!G64 -> 66 | H20: ='Raw Financials'!H64 -> 31 | I20: ='Raw Financials'!I64 -> 43 | J20: ='Raw Financials'!J64 -> 48 | ... AT20: ='Raw Financials'!AT64 -> -128
A21: Other income, net | B21: ₹ cr | C21: ='Raw Financials'!C65 -> 177 | D21: ='Raw Financials'!D65 -> 219 | E21: ='Raw Financials'!E65 -> 344 | F21: ='Raw Financials'!F65 -> 197 | G21: ='Raw Financials'!G65 -> 187 | H21: ='Raw Financials'!H65 -> 204 | I21: ='Raw Financials'!I65 -> 188 | J21: ='Raw Financials'!J65 -> 167 | ... AT21: ='Raw Financials'!AT65 -> 210
A22: PBT | B22: ₹ cr | C22: =IF(OR(C18="",C20="",C21=""),"",SUM(C18,C20,C21)) -> 2188 | D22: =IF(OR(D18="",D20="",D21=""),"",SUM(D18,D20,D21)) -> 2198 | E22: =IF(OR(E18="",E20="",E21=""),"",SUM(E18,E20,E21)) -> 2427 | F22: =IF(OR(F18="",F20="",F21=""),"",SUM(F18,F20,F21)) -> 2422 | G22: =IF(OR(G18="",G20="",G21=""),"",SUM(G18,G20,G21)) -> 2586 | H22: =IF(OR(H18="",H20="",H21=""),"",SUM(H18,H20,H21)) -> 2553 | I22: =IF(OR(I18="",I20="",I21=""),"",SUM(I18,I20,I21)) -> 2639 | J22: =IF(OR(J18="",J20="",J21=""),"",SUM(J18,J20,J21)) -> 2631 | ... AT22: =IF(OR(AT18="",AT20="",AT21=""),"",SUM(AT18,AT20,AT21)) -> 5702
A23: Tax | B23: ₹ cr | C23: ='Raw Financials'!C66 -> 406 | D23: ='Raw Financials'!D66 -> 472 | E23: ='Raw Financials'!E66 -> 508 | F23: ='Raw Financials'!F66 -> 497 | G23: ='Raw Financials'!G66 -> 543 | H23: ='Raw Financials'!H66 -> 538 | I23: ='Raw Financials'!I66 -> 568 | J23: ='Raw Financials'!J66 -> 303 | ... AT23: ='Raw Financials'!AT66 -> 1212
A24: NCI / other attribution | B24: ₹ cr | C24: ='Raw Financials'!C67 -> 0 | D24: ='Raw Financials'!D67 -> 0 | E24: ='Raw Financials'!E67 -> 0 | F24: ='Raw Financials'!F67 -> 0 | G24: ='Raw Financials'!G67 -> 0 | H24: ='Raw Financials'!H67 -> 0 | I24: ='Raw Financials'!I67 -> 0 | J24: ='Raw Financials'!J67 -> 0 | ... AT24: ='Raw Financials'!AT67 -> 2
A25: Net income attributable | B25: ₹ cr | C25: ='Raw Financials'!C68 -> 1782 | D25: ='Raw Financials'!D68 -> 1726 | E25: ='Raw Financials'!E68 -> 1920 | F25: ='Raw Financials'!F68 -> 1926 | G25: ='Raw Financials'!G68 -> 2047 | H25: ='Raw Financials'!H68 -> 2014 | I25: ='Raw Financials'!I68 -> 2070 | J25: ='Raw Financials'!J68 -> 2325 | ... AT25: ='Raw Financials'!AT68 -> 4488
A26: Net margin | B26: % | C26: =IFERROR(C25/C6,"") -> 0.1822645 | D26: =IFERROR(D25/D6,"") -> 0.17094186 | E26: =IFERROR(E25/E6,"") -> 0.1856687 | F26: =IFERROR(F25/F6,"") -> 0.18003365 | G26: =IFERROR(G25/G6,"") -> 0.18057516 | H26: =IFERROR(H25/H6,"") -> 0.17484157 | I26: =IFERROR(I25/I6,"") -> 0.17521585 | J26: =IFERROR(J25/J6,"") -> 0.19289803 | ... AT26: =IFERROR(AT25/AT6,"") -> 0.13207381

Sheet Annual P&L
A1: Annual Profit & Loss
A2: Actuals link to raw reported data; FY27E–FY30E are formula-driven from operating assumptions
A5: Metric | B5: Units | C5: FY16A | D5: FY17A | E5: FY18A | F5: FY19A | G5: FY20A | H5: FY21A | I5: FY22A | J5: FY23A | K5: FY24A | L5: FY25A | M5: FY26A | N5: FY27E | O5: FY28E | P5: FY29E | Q5: FY30E
A7: Revenue | B7: ₹ cr | C7: ='Raw Financials'!C6 -> 40913 | D7: ='Raw Financials'!D6 -> 46723 | E7: ='Raw Financials'!E6 -> 50570 | F7: ='Raw Financials'!F6 -> 60427 | G7: ='Raw Financials'!G6 -> 70678 | H7: ='Raw Financials'!H6 -> 75379 | I7: ='Raw Financials'!I6 -> 85651 | J7: ='Raw Financials'!J6 -> 101456 | ... M7: ='Raw Financials'!M6 -> 130144 | N7: ='Revenue Drivers'!N26 -> 138192.4 | O7: ='Revenue Drivers'!O26 -> 149041.66 | P7: ='Revenue Drivers'!P26 -> 162065.57 | Q7: ='Revenue Drivers'!Q26 -> 175279.02
A8: YoY growth | B8: % | D8: =IFERROR(D7/C7-1,"") -> 0.14200865 | E8: =IFERROR(E7/D7-1,"") -> 0.082336323 | F8: =IFERROR(F7/E7-1,"") -> 0.19491794 | G8: =IFERROR(G7/F7-1,"") -> 0.16964271 | H8: =IFERROR(H7/G7-1,"") -> 0.066512918 | I8: =IFERROR(I7/H7-1,"") -> 0.13627138 | J8: =IFERROR(J7/I7-1,"") -> 0.18452791 | K8: =IFERROR(K7/J7-1,"") -> 0.083356332 | ... Q8: =IFERROR(Q7/P7-1,"") -> 0.081531488
A9: Direct costs | B9: ₹ cr | C9: ='Raw Financials'!C7 -> 26901 | D9: ='Raw Financials'!D7 -> 30890 | E9: ='Raw Financials'!E7 -> 33237 | F9: ='Raw Financials'!F7 -> 39268 | G9: ='Raw Financials'!G7 -> 44018 | H9: ='Raw Financials'!H7 -> 44591 | I9: ='Raw Financials'!I7 -> 52760 | J9: ='Raw Financials'!J7 -> 64523 | ... M9: ='Raw Financials'!M7 -> 85811 | N9: =N7*(1-Assumptions!C15) -> 90930.602 | O9: =O7*(1-Assumptions!D15) -> 97771.332 | P9: =P7*(1-Assumptions!E15) -> 105990.88 | Q9: =Q7*(1-Assumptions!F15) -> 114457.2
A10: Gross profit | B10: ₹ cr | C10: =C7-C9 -> 14012 | D10: =D7-D9 -> 15833 | E10: =E7-E9 -> 17333 | F10: =F7-F9 -> 21159 | G10: =G7-G9 -> 26660 | H10: =H7-H9 -> 30788 | I10: =I7-I9 -> 32891 | J10: =J7-J9 -> 36933 | ... Q10: =Q7-Q9 -> 60821.82
A11: Gross margin | B11: % | C11: =IFERROR(C10/C7,"") -> 0.34248283 | D11: =IFERROR(D10/D7,"") -> 0.33886951 | E11: =IFERROR(E10/E7,"") -> 0.34275262 | F11: =IFERROR(F10/F7,"") -> 0.35015804 | G11: =IFERROR(G10/G7,"") -> 0.37720366 | H11: =IFERROR(H10/H7,"") -> 0.40844267 | I11: =IFERROR(I10/I7,"") -> 0.38401186 | J11: =IFERROR(J10/J7,"") -> 0.36402973 | ... Q11: =IFERROR(Q10/Q7,"") -> 0.347
A12: Reported gross profit control | B12: ₹ cr | C12: ='Raw Financials'!C8 -> 14012 | D12: ='Raw Financials'!D8 -> 15833 | E12: ='Raw Financials'!E8 -> 17333 | F12: ='Raw Financials'!F8 -> 21159 | G12: ='Raw Financials'!G8 -> 26659 | H12: ='Raw Financials'!H8 -> 30788 | I12: ='Raw Financials'!I8 -> 32891 | J12: ='Raw Financials'!J8 -> 36933 | ... M12: ='Raw Financials'!M8 -> 44333 | N12: =N10 -> 47261.802 | O12: =O10 -> 51270.333 | P12: =P10 -> 56074.688 | Q12: =Q10 -> 60821.82
A13: Gross profit check | B13: ₹ cr | C13: =C10-C12 -> 0 | D13: =D10-D12 -> 0 | E13: =E10-E12 -> 0 | F13: =F10-F12 -> 0 | G13: =G10-G12 -> 1 | H13: =H10-H12 -> 0 | I13: =I10-I12 -> 0 | J13: =J10-J12 -> 0 | ... Q13: =Q10-Q12 -> 0
A14: R&D | B14: ₹ cr | C14: ='Raw Financials'!C9 -> 0 | D14: ='Raw Financials'!D9 -> 0 | E14: ='Raw Financials'!E9 -> 0 | F14: ='Raw Financials'!F9 -> 0 | G14: ='Raw Financials'!G9 -> 1276 | H14: ='Raw Financials'!H9 -> 1383 | I14: ='Raw Financials'!I9 -> 1526 | J14: ='Raw Financials'!J9 -> 1632 | ... M14: ='Raw Financials'!M9 -> 2000 | N14: =N7*Assumptions!C16 -> 2072.8861 | O14: =O7*Assumptions!D16 -> 2235.625 | P14: =P7*Assumptions!E16 -> 2430.9836 | Q14: =Q7*Assumptions!F16 -> 2629.1853
A15: SG&A + other operating costs | B15: ₹ cr | C15: =IF(OR(C10="",C14="",C17=""),"",C10-C14-C17) -> 5280 | D15: =IF(OR(D10="",D14="",D17=""),"",D10-D14-D17) -> 5524 | E15: =IF(OR(E10="",E14="",E17=""),"",E10-E14-E17) -> 5893 | F15: =IF(OR(F10="",F14="",F17=""),"",F10-F14-F17) -> 7192 | G15: =IF(OR(G10="",G14="",G17=""),"",G10-G14-G17) -> 8690 | H15: =IF(OR(H10="",H14="",H17=""),"",H10-H14-H17) -> 9450 | I15: =IF(OR(I10="",I14="",I17=""),"",I10-I14-I17) -> 10835 | J15: =IF(OR(J10="",J14="",J17=""),"",J10-J14-J17) -> 12673 | ... M15: =IF(OR(M10="",M14="",M17=""),"",M10-M14-M17) -> 15581 | N15: =N10-N14-N17 -> 15753.934 | O15: =O10-O14-O17 -> 17139.791 | P15: =P10-P14-P17 -> 18799.606 | Q15: =Q10-Q14-Q17 -> 20507.645
A16: Reported EBITDA control | B16: ₹ cr | C16: ='Raw Financials'!C11 -> 8795 | D16: ='Raw Financials'!D11 -> 10309 | E16: ='Raw Financials'!E11 -> 11440 | F16: ='Raw Financials'!F11 -> 13967 | G16: ='Raw Financials'!G11 -> 16694 | H16: ='Raw Financials'!H11 -> 20057 | I16: ='Raw Financials'!I11 -> 20530 | J16: ='Raw Financials'!J11 -> 22628 | ... M16: ='Raw Financials'!M11 -> 26752 | N16: =N17 -> 29434.982 | O16: =O17 -> 31894.916 | P16: =P17 -> 34844.098 | Q16: =Q17 -> 37684.989
A17: EBITDA | B17: ₹ cr | C17: =C20+C19 -> 8732 | D17: =D20+D19 -> 10309 | E17: =E20+E19 -> 11440 | F17: =F20+F19 -> 13967 | G17: =G20+G19 -> 16694 | H17: =H20+H19 -> 19955 | I17: =I20+I19 -> 20530 | J17: =J20+J19 -> 22628 | ... Q17: =Q20+Q19 -> 37684.989
A18: EBITDA margin | B18: % | C18: =IFERROR(C17/C7,"") -> 0.21342849 | D18: =IFERROR(D17/D7,"") -> 0.2206408 | E18: =IFERROR(E17/E7,"") -> 0.22622108 | F18: =IFERROR(F17/F7,"") -> 0.2311384 | G18: =IFERROR(G17/G7,"") -> 0.23619797 | H18: =IFERROR(H17/H7,"") -> 0.2647289 | I18: =IFERROR(I17/I7,"") -> 0.23969364 | J18: =IFERROR(J17/J7,"") -> 0.22303264 | ... Q18: =IFERROR(Q17/Q7,"") -> 0.215
A19: D&A | B19: ₹ cr | C19: ='Raw Financials'!C12 -> 506 | D19: ='Raw Financials'!D12 -> 835 | E19: ='Raw Financials'!E12 -> 1453 | F19: ='Raw Financials'!F12 -> 2147 | G19: ='Raw Financials'!G12 -> 2841 | H19: ='Raw Financials'!H12 -> 4611 | I19: ='Raw Financials'!I12 -> 4326 | J19: ='Raw Financials'!J12 -> 4145 | ... M19: ='Raw Financials'!M12 -> 4355 | N19: =N7*Assumptions!C17 -> 4560.3493 | O19: =O7*Assumptions!D17 -> 4769.3333 | P19: =P7*Assumptions!E17 -> 5024.0327 | Q19: =Q7*Assumptions!F17 -> 5258.3706
A20: EBIT | B20: ₹ cr | C20: ='Raw Financials'!C13 -> 8226 | D20: ='Raw Financials'!D13 -> 9474 | E20: ='Raw Financials'!E13 -> 9987 | F20: ='Raw Financials'!F13 -> 11820 | G20: ='Raw Financials'!G13 -> 13853 | H20: ='Raw Financials'!H13 -> 15344 | I20: ='Raw Financials'!I13 -> 16204 | J20: ='Raw Financials'!J13 -> 18483 | ... M20: ='Raw Financials'!M13 -> 22397 | N20: =N7*Assumptions!C18 -> 24874.633 | O20: =O7*Assumptions!D18 -> 27125.583 | P20: =P7*Assumptions!E18 -> 29820.065 | Q20: =Q7*Assumptions!F18 -> 32426.619
A21: EBIT margin | B21: % | C21: =IFERROR(C20/C7,"") -> 0.20106079 | D21: =IFERROR(D20/D7,"") -> 0.20276951 | E21: =IFERROR(E20/E7,"") -> 0.19748863 | F21: =IFERROR(F20/F7,"") -> 0.19560792 | G21: =IFERROR(G20/G7,"") -> 0.19600158 | H21: =IFERROR(H20/H7,"") -> 0.20355802 | I21: =IFERROR(I20/I7,"") -> 0.18918635 | J21: =IFERROR(J20/J7,"") -> 0.1821775 | ... Q21: =IFERROR(Q20/Q7,"") -> 0.185
A22: FX gain / (loss) | B22: ₹ cr | C22: ='Raw Financials'!C14 -> 72 | D22: ='Raw Financials'!D14 -> 188 | E22: ='Raw Financials'!E14 -> 541 | F22: ='Raw Financials'!F14 -> 182 | G22: ='Raw Financials'!G14 -> -15 | H22: ='Raw Financials'!H14 -> 46 | I22: ='Raw Financials'!I14 -> 328 | J22: ='Raw Financials'!J14 -> 91 | ... M22: ='Raw Financials'!M14 -> -241 | N22: =0 -> 0 | O22: =0 -> 0 | P22: =0 -> 0 | Q22: =0 -> 0
A23: Other income, net | B23: ₹ cr | C23: ='Raw Financials'!C15 -> 937 | D23: ='Raw Financials'!D15 -> 746 | E23: ='Raw Financials'!E15 -> 570 | F23: ='Raw Financials'!F15 -> 623 | G23: ='Raw Financials'!G15 -> 193 | H23: ='Raw Financials'!H15 -> 463 | I23: ='Raw Financials'!I15 -> 419 | J23: ='Raw Financials'!J15 -> 914 | ... M23: ='Raw Financials'!M15 -> 902 | N23: =SUM('Annual Balance Sheet'!M7,'Annual Balance Sheet'!M10)*Assumptions!C20 -> 942.03 | O23: =SUM('Annual Balance Sheet'!N7,'Annual Balance Sheet'!N10)*Assumptions!D20 -> 1122.9522 | P23: =SUM('Annual Balance Sheet'!O7,'Annual Balance Sheet'!O10)*Assumptions!E20 -> 1207.903 | Q23: =SUM('Annual Balance Sheet'!P7,'Annual Balance Sheet'!P10)*Assumptions!F20 -> 1307.5365
A24: PBT | B24: ₹ cr | C24: =SUM(C20,C22,C23) -> 9235 | D24: =SUM(D20,D22,D23) -> 10408 | E24: =SUM(E20,E22,E23) -> 11098 | F24: =SUM(F20,F22,F23) -> 12625 | G24: =SUM(G20,G22,G23) -> 14031 | H24: =SUM(H20,H22,H23) -> 15853 | I24: =SUM(I20,I22,I23) -> 16951 | J24: =SUM(J20,J22,J23) -> 19488 | ... Q24: =SUM(Q20,Q22,Q23) -> 33734.155
A25: PBT margin | B25: % | C25: =IFERROR(C24/C7,"") -> 0.22572288 | D25: =IFERROR(D24/D7,"") -> 0.22275967 | E25: =IFERROR(E24/E7,"") -> 0.21945818 | F25: =IFERROR(F24/F7,"") -> 0.20892978 | G25: =IFERROR(G24/G7,"") -> 0.19852005 | H25: =IFERROR(H24/H7,"") -> 0.21031056 | I25: =IFERROR(I24/I7,"") -> 0.19790779 | J25: =IFERROR(J24/J7,"") -> 0.19208327 | ... Q25: =IFERROR(Q24/Q7,"") -> 0.19245974
A26: Tax | B26: ₹ cr | C26: ='Raw Financials'!C16 -> 1883 | D26: ='Raw Financials'!D16 -> 1952 | E26: ='Raw Financials'!E16 -> 2316 | F26: ='Raw Financials'!F16 -> 2481 | G26: ='Raw Financials'!G16 -> 2938 | H26: ='Raw Financials'!H16 -> 4684 | I26: ='Raw Financials'!I16 -> 3428 | J26: ='Raw Financials'!J16 -> 4643 | ... M26: ='Raw Financials'!M16 -> 5687 | N26: =N24*Assumptions!C19 -> 6454.1657 | O26: =O24*Assumptions!D19 -> 7062.1338 | P26: =P24*Assumptions!E19 -> 7756.9921 | Q26: =Q24*Assumptions!F19 -> 8433.5388
A27: Effective tax rate | B27: % | C27: =IFERROR(C26/C24,"") -> 0.20389821 | D27: =IFERROR(D26/D24,"") -> 0.18754804 | E27: =IFERROR(E26/E24,"") -> 0.20868625 | F27: =IFERROR(F26/F24,"") -> 0.19651485 | G27: =IFERROR(G26/G24,"") -> 0.20939349 | H27: =IFERROR(H26/H24,"") -> 0.29546458 | I27: =IFERROR(I26/I24,"") -> 0.20222996 | J27: =IFERROR(J26/J24,"") -> 0.23824918 | ... Q27: =IFERROR(Q26/Q24,"") -> 0.25
A28: NCI / other attribution | B28: ₹ cr | C28: ='Raw Financials'!C17 -> 0 | D28: ='Raw Financials'!D17 -> 0 | E28: ='Raw Financials'!E17 -> 0 | F28: ='Raw Financials'!F17 -> 0 | G28: ='Raw Financials'!G17 -> 31 | H28: ='Raw Financials'!H17 -> 24 | I28: ='Raw Financials'!I17 -> 24 | J28: ='Raw Financials'!J17 -> -6 | ... M28: ='Raw Financials'!M17 -> 0 | N28: =0 -> 0 | O28: =0 -> 0 | P28: =0 -> 0 | Q28: =0 -> 0
A29: Net income attributable | B29: ₹ cr | C29: ='Raw Financials'!C18 -> 7354 | D29: ='Raw Financials'!D18 -> 8457 | E29: ='Raw Financials'!E18 -> 8780 | F29: ='Raw Financials'!F18 -> 10123 | G29: ='Raw Financials'!G18 -> 11062 | H29: ='Raw Financials'!H18 -> 11145 | I29: ='Raw Financials'!I18 -> 13499 | J29: ='Raw Financials'!J18 -> 14851 | ... M29: ='Raw Financials'!M18 -> 17361 | N29: =N24-N26-N28 -> 19362.497 | O29: =O24-O26-O28 -> 21186.401 | P29: =P24-P26-P28 -> 23270.976 | Q29: =Q24-Q26-Q28 -> 25300.616
A30: Net margin | B30: % | C30: =IFERROR(C29/C7,"") -> 0.17974727 | D30: =IFERROR(D29/D7,"") -> 0.18100293 | E30: =IFERROR(E29/E7,"") -> 0.17362072 | F30: =IFERROR(F29/F7,"") -> 0.16752445 | G30: =IFERROR(G29/G7,"") -> 0.15651263 | H30: =IFERROR(H29/H7,"") -> 0.14785285 | I30: =IFERROR(I29/I7,"") -> 0.1576047 | J30: =IFERROR(J29/J7,"") -> 0.14637873 | ... Q30: =IFERROR(Q29/Q7,"") -> 0.14434481
A31: Basic shares outstanding | B31: m | C31: =2713.7 -> 2713.7 | D31: =2713.7 -> 2713.7 | E31: =2713.7 -> 2713.7 | F31: =2713.7 -> 2713.7 | G31: =2713.7 -> 2713.7 | H31: =2713.7 -> 2713.7 | I31: =2713.7 -> 2713.7 | J31: =2713.7 -> 2713.7 | ... M31: =2713.7 -> 2713.7 | N31: =M31*(1+Assumptions!C37) -> 2713.7 | O31: =N31*(1+Assumptions!D37) -> 2713.7 | P31: =O31*(1+Assumptions!E37) -> 2713.7 | Q31: =P31*(1+Assumptions!F37) -> 2713.7
A32: Diluted shares outstanding | B32: m | C32: =C31+1.5 -> 2715.2 | D32: =D31+1.5 -> 2715.2 | E32: =E31+1.5 -> 2715.2 | F32: =F31+1.5 -> 2715.2 | G32: =G31+1.5 -> 2715.2 | H32: =H31+1.5 -> 2715.2 | I32: =I31+1.5 -> 2715.2 | J32: =J31+1.5 -> 2715.2 | ... M32: =M31+1.5 -> 2715.2 | N32: =M32*(1+Assumptions!C37) -> 2715.2 | O32: =N32*(1+Assumptions!D37) -> 2715.2 | P32: =O32*(1+Assumptions!E37) -> 2715.2 | Q32: =P32*(1+Assumptions!F37) -> 2715.2
A33: Basic EPS | B33: ₹ / share | C33: =IFERROR(C29*10/C31,"") -> 27.099532 | D33: =IFERROR(D29*10/D31,"") -> 31.164093 | E33: =IFERROR(E29*10/E31,"") -> 32.35435 | F33: =IFERROR(F29*10/F31,"") -> 37.303313 | G33: =IFERROR(G29*10/G31,"") -> 40.763533 | H33: =IFERROR(H29*10/H31,"") -> 41.069389 | I33: =IFERROR(I29*10/I31,"") -> 49.743892 | J33: =IFERROR(J29*10/J31,"") -> 54.72602 | ... Q33: =IFERROR(Q29*10/Q31,"") -> 93.232916
A34: Diluted EPS | B34: ₹ / share | C34: =IFERROR(C29*10/C32,"") -> 27.084561 | D34: =IFERROR(D29*10/D32,"") -> 31.146877 | E34: =IFERROR(E29*10/E32,"") -> 32.336476 | F34: =IFERROR(F29*10/F32,"") -> 37.282705 | G34: =IFERROR(G29*10/G32,"") -> 40.741014 | H34: =IFERROR(H29*10/H32,"") -> 41.0467 | I34: =IFERROR(I29*10/I32,"") -> 49.716411 | J34: =IFERROR(J29*10/J32,"") -> 54.695787 | ... Q34: =IFERROR(Q29*10/Q32,"") -> 93.18141
A35: Dividend per share | B35: ₹ / share | C35: =IFERROR(-'Annual Cash Flow'!C28*10/C31,"") -> 9.9384604 | D35: =IFERROR(-'Annual Cash Flow'!D28*10/D31,"") -> 14.990603 | E35: =IFERROR(-'Annual Cash Flow'!E28*10/E31,"") -> 7.4842466 | F35: =IFERROR(-'Annual Cash Flow'!F28*10/F31,"") -> 4.8678925 | G35: =IFERROR(-'Annual Cash Flow'!G28*10/G31,"") -> 5.9881343 | H35: =IFERROR(-'Annual Cash Flow'!H28*10/H31,"") -> 11.998379 | I35: =IFERROR(-'Annual Cash Flow'!I28*10/I31,"") -> 41.96853 | J35: =IFERROR(-'Annual Cash Flow'!J28*10/J31,"") -> 47.886649 | ... M35: =IFERROR(-'Annual Cash Flow'!M28*10/M31,"") -> 53.867413 | N35: =N33*Assumptions!C35 -> 64.215821 | O35: =O33*Assumptions!D35 -> 70.264809 | P35: =P33*Assumptions!E35 -> 77.178312 | Q35: =Q33*Assumptions!F35 -> 83.909624
A36: Dividend payout | B36: % | C36: =IFERROR(C35/C33,"") -> 0.36673919 | D36: =IFERROR(D35/D33,"") -> 0.48102164 | E36: =IFERROR(E35/E33,"") -> 0.23132118 | F36: =IFERROR(F35/F33,"") -> 0.13049491 | G36: =IFERROR(G35/G33,"") -> 0.14689929 | H36: =IFERROR(H35/H33,"") -> 0.29214895 | I36: =IFERROR(I35/I33,"") -> 0.84369213 | J36: =IFERROR(J35/J33,"") -> 0.87502525 | ... Q36: =IFERROR(Q35/Q33,"") -> 0.9

Sheet Annual Balance Sheet
A1: Annual Balance Sheet
A2: Historical balances from reported annual releases; borrowings remain unallocated where no maturity split was reported
A5: Metric | B5: Units | C5: FY16A | D5: FY17A | E5: FY18A | F5: FY19A | G5: FY20A | H5: FY21A | I5: FY22A | J5: FY23A | K5: FY24A | L5: FY25A | M5: FY26A | N5: FY27E | O5: FY28E | P5: FY29E | Q5: FY30E
A7: Cash & equivalents | B7: ₹ cr | C7: ='Raw Financials'!C29 -> 729.3 | D7: ='Raw Financials'!D29 -> 1316.5 | E7: ='Raw Financials'!E29 -> 1693.9 | F7: ='Raw Financials'!F29 -> 5929 | G7: ='Raw Financials'!G29 -> 4843 | H7: ='Raw Financials'!H29 -> 6515 | I7: ='Raw Financials'!I29 -> 10510 | J7: ='Raw Financials'!J29 -> 9065 | ... M7: ='Raw Financials'!M29 -> 8265 | N7: ='Annual Cash Flow'!N35 -> 11175.182 | O7: ='Annual Cash Flow'!O35 -> 12690.724 | P7: ='Annual Cash Flow'!P35 -> 14412.746 | Q7: ='Annual Cash Flow'!Q35 -> 16169.033
A8: Trade receivables | B8: ₹ cr | C8: ='Raw Financials'!C30 -> 7721.3 | D8: ='Raw Financials'!D30 -> 8301.4 | E8: ='Raw Financials'!E30 -> 9639.4 | F8: ='Raw Financials'!F30 -> 11706 | G8: ='Raw Financials'!G30 -> 14134 | H8: ='Raw Financials'!H30 -> 13663 | I8: ='Raw Financials'!I30 -> 15476 | J8: ='Raw Financials'!J30 -> 19572 | ... M8: ='Raw Financials'!M30 -> 23585 | N8: ='Annual P&L'!N7/365*Assumptions!C21 -> 24230.997 | O8: ='Annual P&L'!O7/365*Assumptions!D21 -> 25725 | P8: ='Annual P&L'!P7/365*Assumptions!E21 -> 27528.947 | Q8: ='Annual P&L'!Q7/365*Assumptions!F21 -> 29293.206
A9: Unbilled receivables | B9: ₹ cr | C9: ='Raw Financials'!C31 -> 3001.5 | D9: ='Raw Financials'!D31 -> 2501.2 | E9: ='Raw Financials'!E31 -> 2618.1 | F9: ='Raw Financials'!F31 -> 0 | G9: ='Raw Financials'!G31 -> 3638 | H9: ='Raw Financials'!H31 -> 3862 | I9: ='Raw Financials'!I31 -> 5195 | J9: ='Raw Financials'!J31 -> 5934 | ... M9: ='Raw Financials'!M31 -> 7956 | N9: ='Annual P&L'!N7/365*Assumptions!C22 -> 8329.4052 | O9: ='Annual P&L'!O7/365*Assumptions!D22 -> 8983.3332 | P9: ='Annual P&L'!P7/365*Assumptions!E22 -> 9324.3206 | Q9: ='Annual P&L'!Q7/365*Assumptions!F22 -> 10084.546
A10: Treasury investments | B10: ₹ cr | C10: ='Raw Financials'!C32 -> 11123.6 | D10: ='Raw Financials'!D32 -> 11365.3 | E10: ='Raw Financials'!E32 -> 8083.8 | F10: ='Raw Financials'!F32 -> 5462 | G10: ='Raw Financials'!G32 -> 10530 | H10: ='Raw Financials'!H32 -> 13975 | I10: ='Raw Financials'!I32 -> 11373 | J10: ='Raw Financials'!J32 -> 13647 | ... M10: ='Raw Financials'!M32 -> 23136 | N10: ='Annual P&L'!N7*Assumptions!C26 -> 26256.557 | O10: ='Annual P&L'!O7*Assumptions!D26 -> 27572.708 | P10: ='Annual P&L'!P7*Assumptions!E26 -> 29171.803 | Q10: ='Annual P&L'!Q7*Assumptions!F26 -> 30673.828
A11: Other current assets | B11: ₹ cr | C11: =C12-SUM(C7:C10) -> 2410.2 | D11: =D12-SUM(D7:D10) -> 2983.2 | E11: =E12-SUM(E7:E10) -> 2519.8 | F11: =F12-SUM(F7:F10) -> 6620 | G11: =G12-SUM(G7:G10) -> 5280 | H11: =H12-SUM(H7:H10) -> 5037 | I11: =I12-SUM(I7:I10) -> 5487 | J11: =J12-SUM(J7:J10) -> 5359 | ... M11: =M12-SUM(M7:M10) -> 7600 | N11: ='Annual P&L'!N7*Assumptions!C23 -> 8015.1594 | O11: ='Annual P&L'!O7*Assumptions!D23 -> 8495.3749 | P11: ='Annual P&L'!P7*Assumptions!E23 -> 9075.6721 | Q11: ='Annual P&L'!Q7*Assumptions!F23 -> 9640.3461
A12: Total current assets | B12: ₹ cr | C12: ='Raw Financials'!C34 -> 24985.9 | D12: ='Raw Financials'!D34 -> 26467.6 | E12: ='Raw Financials'!E34 -> 24555 | F12: ='Raw Financials'!F34 -> 29717 | G12: ='Raw Financials'!G34 -> 38425 | H12: ='Raw Financials'!H34 -> 43052 | I12: ='Raw Financials'!I34 -> 48041 | J12: ='Raw Financials'!J34 -> 53577 | ... M12: ='Raw Financials'!M34 -> 70542 | N12: =SUM(N7:N11) -> 78007.3 | O12: =SUM(O7:O11) -> 83467.14 | P12: =SUM(P7:P11) -> 89513.488 | Q12: =SUM(Q7:Q11) -> 95860.96
A13: PPE | B13: ₹ cr | C13: ='Raw Financials'!C35 -> 4323.1 | D13: ='Raw Financials'!D35 -> 4680.6 | E13: ='Raw Financials'!E35 -> 5184.7 | F13: ='Raw Financials'!F35 -> 5801 | G13: ='Raw Financials'!G35 -> 6244 | H13: ='Raw Financials'!H35 -> 6245 | I13: ='Raw Financials'!I35 -> 5741 | J13: ='Raw Financials'!J35 -> 5411 | ... M13: ='Raw Financials'!M35 -> 4717 | N13: =M13-'Annual Cash Flow'!N17-'Annual P&L'!N19*Assumptions!C28 -> 3915.4841 | O13: =N13-'Annual Cash Flow'!O17-'Annual P&L'!O19*Assumptions!D28 -> 3140.4674 | P13: =O13-'Annual Cash Flow'!P17-'Annual P&L'!P19*Assumptions!E28 -> 2394.9658 | Q13: =P13-'Annual Cash Flow'!Q17-'Annual P&L'!Q19*Assumptions!F28 -> 1693.8497
A14: ROU assets | B14: ₹ cr | C14: ='Raw Financials'!C36 -> 0 | D14: ='Raw Financials'!D36 -> 0 | E14: ='Raw Financials'!E36 -> 0 | F14: ='Raw Financials'!F36 -> 0 | G14: ='Raw Financials'!G36 -> 0 | H14: ='Raw Financials'!H36 -> 0 | I14: ='Raw Financials'!I36 -> 2305 | J14: ='Raw Financials'!J36 -> 2337 | ... M14: ='Raw Financials'!M36 -> 3592 | N14: =M14+'Annual Cash Flow'!N25-'Annual P&L'!N19*Assumptions!C30 -> 4338.239 | O14: =N14+'Annual Cash Flow'!O25-'Annual P&L'!O19*Assumptions!D30 -> 5172.8723 | P14: =O14+'Annual Cash Flow'!P25-'Annual P&L'!P19*Assumptions!E30 -> 6112.8526 | Q14: =P14+'Annual Cash Flow'!Q25-'Annual P&L'!Q19*Assumptions!F30 -> 7164.5267
A15: Goodwill & intangibles | B15: ₹ cr | C15: ='Raw Financials'!C37 -> 6419.4 | D15: ='Raw Financials'!D37 -> 7358.3 | E15: ='Raw Financials'!E37 -> 14405.7 | F15: ='Raw Financials'!F37 -> 17695 | G15: ='Raw Financials'!G37 -> 29421 | H15: ='Raw Financials'!H37 -> 29150 | I15: ='Raw Financials'!I37 -> 27160 | J15: ='Raw Financials'!J37 -> 26911 | ... M15: ='Raw Financials'!M37 -> 29130 | N15: =M15-'Annual Cash Flow'!N19-'Annual P&L'!N19*(1-Assumptions!C28-Assumptions!C30) -> 28217.93 | O15: =N15-'Annual Cash Flow'!O19-'Annual P&L'!O19*(1-Assumptions!D28-Assumptions!D30) -> 27264.063 | P15: =O15-'Annual Cash Flow'!P19-'Annual P&L'!P19*(1-Assumptions!E28-Assumptions!E30) -> 26259.257 | Q15: =P15-'Annual Cash Flow'!Q19-'Annual P&L'!Q19*(1-Assumptions!F28-Assumptions!F30) -> 25207.583
A16: Other non-current assets | B16: ₹ cr | C16: =IF(OR('Raw Financials'!C39="",C12=""),"",'Raw Financials'!C39-SUM(C12:C15)) -> 4038.9 | D16: =IF(OR('Raw Financials'!D39="",D12=""),"",'Raw Financials'!D39-SUM(D12:D15)) -> 7925.8 | E16: =IF(OR('Raw Financials'!E39="",E12=""),"",'Raw Financials'!E39-SUM(E12:E15)) -> 4289.7 | F16: =IF(OR('Raw Financials'!F39="",F12=""),"",'Raw Financials'!F39-SUM(F12:F15)) -> 5684 | G16: =IF(OR('Raw Financials'!G39="",G12=""),"",'Raw Financials'!G39-SUM(G12:G15)) -> 9126 | H16: =IF(OR('Raw Financials'!H39="",H12=""),"",'Raw Financials'!H39-SUM(H12:H15)) -> 9255 | I16: =IF(OR('Raw Financials'!I39="",I12=""),"",'Raw Financials'!I39-SUM(I12:I15)) -> 5786 | J16: =IF(OR('Raw Financials'!J39="",J12=""),"",'Raw Financials'!J39-SUM(J12:J15)) -> 5175 | ... M16: =IF(OR('Raw Financials'!M39="",M12=""),"",'Raw Financials'!M39-SUM(M12:M15)) -> 8277 | N16: ='Annual P&L'!N7*Assumptions!C25 -> 5527.6962 | O16: ='Annual P&L'!O7*Assumptions!D25 -> 5812.6249 | P16: ='Annual P&L'!P7*Assumptions!E25 -> 6158.4917 | Q16: ='Annual P&L'!Q7*Assumptions!F25 -> 6485.3237
A17: Total assets | B17: ₹ cr | C17: ='Raw Financials'!C39 -> 39767.3 | D17: ='Raw Financials'!D39 -> 46432.3 | E17: ='Raw Financials'!E39 -> 48435.1 | F17: ='Raw Financials'!F39 -> 58897 | G17: ='Raw Financials'!G39 -> 83216 | H17: ='Raw Financials'!H39 -> 87702 | I17: ='Raw Financials'!I39 -> 89033 | J17: ='Raw Financials'!J39 -> 93411 | ... M17: ='Raw Financials'!M39 -> 116258 | N17: =SUM(N12:N16) -> 120006.65 | O17: =SUM(O12:O16) -> 124857.17 | P17: =SUM(P12:P16) -> 130439.06 | Q17: =SUM(Q12:Q16) -> 136412.24
A18: Current operating liabilities | B18: ₹ cr | C18: ='Raw Financials'!C40 -> 9508.5 | D18: ='Raw Financials'!D40 -> 11147.7 | E18: ='Raw Financials'!E40 -> 9914.3 | F18: ='Raw Financials'!F40 -> 11148 | G18: ='Raw Financials'!G40 -> 20889 | H18: ='Raw Financials'!H40 -> 16755 | I18: ='Raw Financials'!I40 -> 18014 | J18: ='Raw Financials'!J40 -> 20420 | ... M18: ='Raw Financials'!M40 -> 29828 | N18: ='Annual P&L'!N7*Assumptions!C24 -> 31093.291 | O18: ='Annual P&L'!O7*Assumptions!D24 -> 33236.291 | P18: ='Annual P&L'!P7*Assumptions!E24 -> 35816.491 | Q18: ='Annual P&L'!Q7*Assumptions!F24 -> 38561.384
A19: Short-term borrowings | B19: ₹ cr | C19: ='Raw Financials'!C41 -> 0 | D19: ='Raw Financials'!D41 -> 0 | E19: ='Raw Financials'!E41 -> 0 | F19: ='Raw Financials'!F41 -> 0 | G19: ='Raw Financials'!G41 -> 0 | H19: ='Raw Financials'!H41 -> 0 | I19: ='Raw Financials'!I41 -> 0 | J19: ='Raw Financials'!J41 -> 0 | ... M19: ='Raw Financials'!M41 -> 0 | N19: =N22*Assumptions!C34 -> 11.8 | O19: =O22*Assumptions!D34 -> 0 | P19: =P22*Assumptions!E34 -> 0 | Q19: =Q22*Assumptions!F34 -> 0
A20: Long-term borrowings | B20: ₹ cr | C20: ='Raw Financials'!C42 -> 0 | D20: ='Raw Financials'!D42 -> 0 | E20: ='Raw Financials'!E42 -> 0 | F20: ='Raw Financials'!F42 -> 0 | G20: ='Raw Financials'!G42 -> 0 | H20: ='Raw Financials'!H42 -> 0 | I20: ='Raw Financials'!I42 -> 0 | J20: ='Raw Financials'!J42 -> 0 | ... M20: ='Raw Financials'!M42 -> 0 | N20: =N22-N19 -> 47.2 | O20: =O22-O19 -> 0 | P20: =P22-P19 -> 0 | Q20: =Q22-Q19 -> 0
A21: Borrowings — maturity split not reported | B21: ₹ cr | C21: ='Raw Financials'!C43 -> 973.2 | D21: ='Raw Financials'!D43 -> 541.7 | E21: ='Raw Financials'!E43 -> 437.1 | F21: ='Raw Financials'!F43 -> 3986 | G21: ='Raw Financials'!G43 -> 5092 | H21: ='Raw Financials'!H43 -> 3907 | I21: ='Raw Financials'!I43 -> 3985 | J21: ='Raw Financials'!J43 -> 2251 | ... M21: ='Raw Financials'!M43 -> 159 | N21: =0 -> 0 | O21: =0 -> 0 | P21: =0 -> 0 | Q21: =0 -> 0
A22: Total borrowings | B22: ₹ cr | C22: =SUM(C19:C21) -> 973.2 | D22: =SUM(D19:D21) -> 541.7 | E22: =SUM(E19:E21) -> 437.1 | F22: =SUM(F19:F21) -> 3986 | G22: =SUM(G19:G21) -> 5092 | H22: =SUM(H19:H21) -> 3907 | I22: =SUM(I19:I21) -> 3985 | J22: =SUM(J19:J21) -> 2251 | ... M22: =SUM(M19:M21) -> 159 | N22: =MAX(0,M22+Assumptions!C33) -> 59 | O22: =MAX(0,N22+Assumptions!D33) -> 0 | P22: =MAX(0,O22+Assumptions!E33) -> 0 | Q22: =MAX(0,P22+Assumptions!F33) -> 0
A23: Lease liabilities | B23: ₹ cr | C23: ='Raw Financials'!C44 -> 0 | D23: ='Raw Financials'!D44 -> 0 | E23: ='Raw Financials'!E44 -> 0 | F23: ='Raw Financials'!F44 -> 0 | G23: ='Raw Financials'!G44 -> 0 | H23: ='Raw Financials'!H44 -> 0 | I23: ='Raw Financials'!I44 -> 2358 | J23: ='Raw Financials'!J44 -> 2535 | ... M23: ='Raw Financials'!M44 -> 5056 | N23: =M23+'Annual Cash Flow'!N25+'Annual Cash Flow'!N26 -> 5703.1089 | O23: =N23+'Annual Cash Flow'!O25+'Annual Cash Flow'!O26 -> 6350.9871 | P23: =O23+'Annual Cash Flow'!P25+'Annual Cash Flow'!P26 -> 7025.5765 | Q23: =P23+'Annual Cash Flow'!Q25+'Annual Cash Flow'!Q26 -> 7723.8094
A24: Other non-current liabilities | B24: ₹ cr | C24: ='Raw Financials'!C45 -> 1263.5 | D24: ='Raw Financials'!D45 -> 1252.5 | E24: ='Raw Financials'!E45 -> 1266.9 | F24: ='Raw Financials'!F45 -> 1538 | G24: ='Raw Financials'!G45 -> 2548 | H24: ='Raw Financials'!H45 -> 2683 | I24: ='Raw Financials'!I45 -> 2670 | J24: ='Raw Financials'!J45 -> 2807 | ... M24: ='Raw Financials'!M45 -> 6018 | N24: =M24 -> 6018 | O24: =N24 -> 6018 | P24: =O24 -> 6018 | Q24: =P24 -> 6018
A25: Total liabilities | B25: ₹ cr | C25: =IF('Raw Financials'!C46="",C17-'Raw Financials'!C48,'Raw Financials'!C46) -> 11745.2 | D25: =IF('Raw Financials'!D46="",D17-'Raw Financials'!D48,'Raw Financials'!D46) -> 12941.9 | E25: =IF('Raw Financials'!E46="",E17-'Raw Financials'!E48,'Raw Financials'!E46) -> 11618.3 | F25: =IF('Raw Financials'!F46="",F17-'Raw Financials'!F48,'Raw Financials'!F46) -> 16672 | G25: =IF('Raw Financials'!G46="",G17-'Raw Financials'!G48,'Raw Financials'!G46) -> 31002 | H25: =IF('Raw Financials'!H46="",H17-'Raw Financials'!H48,'Raw Financials'!H46) -> 25612 | I25: =IF('Raw Financials'!I46="",I17-'Raw Financials'!I48,'Raw Financials'!I46) -> 27027 | J25: =IF('Raw Financials'!J46="",J17-'Raw Financials'!J48,'Raw Financials'!J46) -> 28013 | ... M25: =IF('Raw Financials'!M46="",M17-'Raw Financials'!M48,'Raw Financials'!M46) -> 41061 | N25: =SUM(N18,N22:N24) -> 42873.4 | O25: =SUM(O18,O22:O24) -> 45605.278 | P25: =SUM(P18,P22:P24) -> 48860.068 | Q25: =SUM(Q18,Q22:Q24) -> 52303.194
A26: Share capital | B26: ₹ cr | C26: ='Raw Financials'!C47 -> 0 | D26: ='Raw Financials'!D47 -> 0 | E26: ='Raw Financials'!E47 -> 0 | F26: ='Raw Financials'!F47 -> 0 | G26: ='Raw Financials'!G47 -> 0 | H26: ='Raw Financials'!H47 -> 0 | I26: ='Raw Financials'!I47 -> 0 | J26: ='Raw Financials'!J47 -> 0 | ... M26: ='Raw Financials'!M47 -> 0 | N26: =M26 -> 0 | O26: =N26 -> 0 | P26: =O26 -> 0 | Q26: =P26 -> 0
A27: Retained earnings / cumulative profit proxy | B27: ₹ cr | C27: =SUM('Annual P&L'!$C$29:C29)+SUM('Annual Cash Flow'!$C$28:C28) -> 4657 | D27: =SUM('Annual P&L'!$C$29:D29)+SUM('Annual Cash Flow'!$C$28:D28) -> 9046 | E27: =SUM('Annual P&L'!$C$29:E29)+SUM('Annual Cash Flow'!$C$28:E28) -> 15795 | F27: =SUM('Annual P&L'!$C$29:F29)+SUM('Annual Cash Flow'!$C$28:F28) -> 24597 | G27: =SUM('Annual P&L'!$C$29:G29)+SUM('Annual Cash Flow'!$C$28:G28) -> 34034 | H27: =SUM('Annual P&L'!$C$29:H29)+SUM('Annual Cash Flow'!$C$28:H28) -> 41923 | I27: =SUM('Annual P&L'!$C$29:I29)+SUM('Annual Cash Flow'!$C$28:I28) -> 44033 | J27: =SUM('Annual P&L'!$C$29:J29)+SUM('Annual Cash Flow'!$C$28:J28) -> 45889 | ... M27: =SUM('Annual P&L'!$C$29:M29)+SUM('Annual Cash Flow'!$C$28:M28) -> 51401 | N27: =M27+'Annual P&L'!N29+'Annual Cash Flow'!N28 -> 53337.25 | O27: =N27+'Annual P&L'!O29+'Annual Cash Flow'!O28 -> 55455.89 | P27: =O27+'Annual P&L'!P29+'Annual Cash Flow'!P28 -> 57782.987 | Q27: =P27+'Annual P&L'!Q29+'Annual Cash Flow'!Q28 -> 60313.049
A28: Other reserves / equity | B28: ₹ cr | C28: =C29-C26-C27 -> 23365.1 | D28: =D29-D26-D27 -> 24444.4 | E28: =E29-E26-E27 -> 21021.8 | F28: =F29-F26-F27 -> 17173 | G28: =G29-G26-G27 -> 17652 | H28: =H29-H26-H27 -> 19583 | I28: =I29-I26-I27 -> 17881 | J28: =J29-J26-J27 -> 19516 | ... M28: =M29-M26-M27 -> 23764 | N28: =M28+Assumptions!C36 -> 23764 | O28: =N28+Assumptions!D36 -> 23764 | P28: =O28+Assumptions!E36 -> 23764 | Q28: =P28+Assumptions!F36 -> 23764
A29: Stockholders equity | B29: ₹ cr | C29: ='Raw Financials'!C48 -> 28022.1 | D29: ='Raw Financials'!D48 -> 33490.4 | E29: ='Raw Financials'!E48 -> 36816.8 | F29: ='Raw Financials'!F48 -> 41770 | G29: ='Raw Financials'!G48 -> 51686 | H29: ='Raw Financials'!H48 -> 61506 | I29: ='Raw Financials'!I48 -> 61914 | J29: ='Raw Financials'!J48 -> 65405 | ... M29: ='Raw Financials'!M48 -> 75165 | N29: =SUM(N26:N28) -> 77101.25 | O29: =SUM(O26:O28) -> 79219.89 | P29: =SUM(P26:P28) -> 81546.987 | Q29: =SUM(Q26:Q28) -> 84077.049
A30: Non-controlling interests | B30: ₹ cr | C30: =C17-C25-C29 -> 0 | D30: =D17-D25-D29 -> 0 | E30: =E17-E25-E29 -> 0 | F30: =F17-F25-F29 -> 455 | G30: =G17-G25-G29 -> 528 | H30: =H17-H25-H29 -> 584 | I30: =I17-I25-I29 -> 92 | J30: =J17-J25-J29 -> -7 | ... M30: =M17-M25-M29 -> 32 | N30: =M30 -> 32 | O30: =N30 -> 32 | P30: =O30 -> 32 | Q30: =P30 -> 32
A31: Total equity | B31: ₹ cr | C31: =SUM(C29:C30) -> 28022.1 | D31: =SUM(D29:D30) -> 33490.4 | E31: =SUM(E29:E30) -> 36816.8 | F31: =SUM(F29:F30) -> 42225 | G31: =SUM(G29:G30) -> 52214 | H31: =SUM(H29:H30) -> 62090 | I31: =SUM(I29:I30) -> 62006 | J31: =SUM(J29:J30) -> 65398 | ... Q31: =SUM(Q29:Q30) -> 84109.049
A32: Total liabilities & equity | B32: ₹ cr | C32: =C25+C31 -> 39767.3 | D32: =D25+D31 -> 46432.3 | E32: =E25+E31 -> 48435.1 | F32: =F25+F31 -> 58897 | G32: =G25+G31 -> 83216 | H32: =H25+H31 -> 87702 | I32: =I25+I31 -> 89033 | J32: =J25+J31 -> 93411 | ... M32: =M25+M31 -> 116258 | N32: =SUM(N25,N31) -> 120006.65 | O32: =SUM(O25,O31) -> 124857.17 | P32: =SUM(P25,P31) -> 130439.06 | Q32: =SUM(Q25,Q31) -> 136412.24
