Workbook

Sheet Cover
A1: HCLTech Annual Operating & Financial Model
A2: FY16–FY26 actual | FY27–FY30 forecast | INR crore unless noted
A4: Quarterly only for P&L; annual-only balance sheet, cash flow, segment, client and workforce model
A6: Model status | B6: ='Checks & Sources'!G17 -> REVIEW
A7: Historical period | B7: FY16–FY26
A8: Forecast period | B8: FY27–FY30
A9: FY16 convention | B9: Nine-month transition year
A10: Core currency | B10: INR crore
A11: Quarterly scope | B11: P&L only
A12: Revenue method | B12: Billable employees × prior revenue/billable employee × productivity factor
A13: AI adjustment | B13: T&M mix × AI deflation; fixed-price share receives productivity uplift
A14: Forecast cells | B14: Formula-driven; editable assumptions in blue/yellow
A15: Historical sources | B15: HCLTech filings and compiled market-statement extracts
A16: Version | B16: 2026-08-22
A17: Important | B17: Some historical BS components, mix and client metrics are explicit model estimates where a consistent FY16–FY26 disclosure series was unavailable.

Sheet Fin Summary
A1: HCLTech — Financial Summary
A2: INR crore unless stated otherwise | FY16–FY26 actuals; FY27–FY30 estimates | all figures linked to model schedules
A4: Profit & Loss Statement | B4: FY16A | C4: FY17A | D4: FY18A | E4: FY19A | F4: FY20A | G4: FY21A | H4: FY22A | I4: FY23A | J4: FY24A | K4: FY25A | L4: FY26A | M4: FY27E | N4: FY28E | O4: FY29E | P4: FY30E | R4: Key Ratios | S4: FY16A | T4: FY17A | U4: FY18A | V4: FY19A | W4: FY20A | X4: FY21A | Y4: FY22A | Z4: FY23A | AA4: FY24A | AB4: FY25A | AC4: FY26A | AD4: FY27E | AE4: FY28E | AF4: FY29E | AG4: FY30E
A5: Revenue | B5: ='Annual P&L'!B5 -> 31136 | C5: ='Annual P&L'!C5 -> 46722 | D5: ='Annual P&L'!D5 -> 50570 | E5: ='Annual P&L'!E5 -> 60428 | F5: ='Annual P&L'!F5 -> 70678 | G5: ='Annual P&L'!G5 -> 75379 | H5: ='Annual P&L'!H5 -> 85651 | I5: ='Annual P&L'!I5 -> 101456 | ... P5: ='Annual P&L'!P5 -> 156486.23 | R5: Growth (%)
A6: Growth | B6: ='Annual P&L'!B6 -> 0 | C6: ='Annual P&L'!C6 -> 0.50057811 | D6: ='Annual P&L'!D6 -> 0.082359488 | E6: ='Annual P&L'!E6 -> 0.19493771 | F6: ='Annual P&L'!F6 -> 0.16962335 | G6: ='Annual P&L'!G6 -> 0.066512918 | H6: ='Annual P&L'!H6 -> 0.13627138 | I6: ='Annual P&L'!I6 -> 0.18452791 | ... P6: ='Annual P&L'!P6 -> 0.052983298 | R6: Revenue | S6: =0 -> 0 | T6: =IFERROR('Annual P&L'!C5/'Annual P&L'!B5-1,0) -> 0.50057811 | U6: =IFERROR('Annual P&L'!D5/'Annual P&L'!C5-1,0) -> 0.082359488 | V6: =IFERROR('Annual P&L'!E5/'Annual P&L'!D5-1,0) -> 0.19493771 | W6: =IFERROR('Annual P&L'!F5/'Annual P&L'!E5-1,0) -> 0.16962335 | X6: =IFERROR('Annual P&L'!G5/'Annual P&L'!F5-1,0) -> 0.066512918 | Y6: =IFERROR('Annual P&L'!H5/'Annual P&L'!G5-1,0) -> 0.13627138 | Z6: =IFERROR('Annual P&L'!I5/'Annual P&L'!H5-1,0) -> 0.18452791 | AA6: =IFERROR('Annual P&L'!J5/'Annual P&L'!I5-1,0) -> 0.083356332 | ... AG6: =IFERROR('Annual P&L'!P5/'Annual P&L'!O5-1,0) -> 0.052983298
A7: Gross profit | B7: ='Annual P&L'!B8 -> 10663.281 | C7: ='Annual P&L'!C8 -> 15833 | D7: ='Annual P&L'!D8 -> 17333 | E7: ='Annual P&L'!E8 -> 21160 | F7: ='Annual P&L'!F8 -> 25383 | G7: ='Annual P&L'!G8 -> 29404 | H7: ='Annual P&L'!H8 -> 31235 | I7: ='Annual P&L'!I8 -> 35301 | ... P7: ='Annual P&L'!P8 -> 53205.317 | R7: EBITDA | S7: =0 -> 0 | T7: =IFERROR('Annual P&L'!C14/'Annual P&L'!B14-1,0) -> 0.53994314 | U7: =IFERROR('Annual P&L'!D14/'Annual P&L'!C14-1,0) -> 0.10970996 | V7: =IFERROR('Annual P&L'!E14/'Annual P&L'!D14-1,0) -> 0.22106643 | W7: =IFERROR('Annual P&L'!F14/'Annual P&L'!E14-1,0) -> 0.19500322 | X7: =IFERROR('Annual P&L'!G14/'Annual P&L'!F14-1,0) -> 0.16701611 | Y7: =IFERROR('Annual P&L'!H14/'Annual P&L'!G14-1,0) -> 0.046096196 | Z7: =IFERROR('Annual P&L'!I14/'Annual P&L'!H14-1,0) -> 0.11040777 | AA7: =IFERROR('Annual P&L'!J14/'Annual P&L'!I14-1,0) -> 0.06942419 | ... AG7: =IFERROR('Annual P&L'!P14/'Annual P&L'!O14-1,0) -> 0.052983298
A8: Gross margin | B8: ='Annual P&L'!B9 -> 0.34247433 | C8: ='Annual P&L'!C9 -> 0.33887676 | D8: ='Annual P&L'!D9 -> 0.34275262 | E8: ='Annual P&L'!E9 -> 0.3501688 | F8: ='Annual P&L'!F9 -> 0.3591358 | G8: ='Annual P&L'!G9 -> 0.39008212 | H8: ='Annual P&L'!H9 -> 0.36467759 | I8: ='Annual P&L'!I9 -> 0.34794394 | ... P8: ='Annual P&L'!P9 -> 0.34 | R8: EBIT | S8: =0 -> 0 | T8: =IFERROR('Annual P&L'!C17/'Annual P&L'!B17-1,0) -> 0.5162357 | U8: =IFERROR('Annual P&L'!D17/'Annual P&L'!C17-1,0) -> 0.05414248 | V8: =IFERROR('Annual P&L'!E17/'Annual P&L'!D17-1,0) -> 0.18352022 | W8: =IFERROR('Annual P&L'!F17/'Annual P&L'!E17-1,0) -> 0.17189747 | X8: =IFERROR('Annual P&L'!G17/'Annual P&L'!F17-1,0) -> 0.11860247 | Y8: =IFERROR('Annual P&L'!H17/'Annual P&L'!G17-1,0) -> 0.045302013 | Z8: =IFERROR('Annual P&L'!I17/'Annual P&L'!H17-1,0) -> 0.14119027 | AA8: =IFERROR('Annual P&L'!J17/'Annual P&L'!I17-1,0) -> 0.083418988 | ... AG8: =IFERROR('Annual P&L'!P17/'Annual P&L'!O17-1,0) -> 0.052983298
A9: EBITDA | B9: ='Annual P&L'!B14 -> 6694.403 | C9: ='Annual P&L'!C14 -> 10309 | D9: ='Annual P&L'!D14 -> 11440 | E9: ='Annual P&L'!E14 -> 13969 | F9: ='Annual P&L'!F14 -> 16693 | G9: ='Annual P&L'!G14 -> 19481 | H9: ='Annual P&L'!H14 -> 20379 | I9: ='Annual P&L'!I14 -> 22629 | ... P9: ='Annual P&L'!P14 -> 30514.814 | R9: Net profit | S9: =0 -> 0 | T9: =IFERROR('Annual P&L'!C25/'Annual P&L'!B25-1,0) -> 0.51855832 | U9: =IFERROR('Annual P&L'!D25/'Annual P&L'!C25-1,0) -> 0.038429703 | V9: =IFERROR('Annual P&L'!E25/'Annual P&L'!D25-1,0) -> 0.1526987 | W9: =IFERROR('Annual P&L'!F25/'Annual P&L'!E25-1,0) -> 0.092759064 | X9: =IFERROR('Annual P&L'!G25/'Annual P&L'!F25-1,0) -> 0.12393781 | Y9: =IFERROR('Annual P&L'!H25/'Annual P&L'!G25-1,0) -> 0.085819995 | Z9: =IFERROR('Annual P&L'!I25/'Annual P&L'!H25-1,0) -> 0.10007407 | AA9: =IFERROR('Annual P&L'!J25/'Annual P&L'!I25-1,0) -> 0.057302539 | ... AG9: =IFERROR('Annual P&L'!P25/'Annual P&L'!O25-1,0) -> -0.057960799
A10: EBITDA margin | B10: ='Annual P&L'!B15 -> 0.21500524 | C10: ='Annual P&L'!C15 -> 0.22064552 | D10: ='Annual P&L'!D15 -> 0.22622108 | E10: ='Annual P&L'!E15 -> 0.23116767 | F10: ='Annual P&L'!F15 -> 0.23618382 | G10: ='Annual P&L'!G15 -> 0.25844068 | H10: ='Annual P&L'!H15 -> 0.23793067 | I10: ='Annual P&L'!I15 -> 0.2230425 | ... P10: ='Annual P&L'!P15 -> 0.195 | R10: EPS | S10: =0 -> 0 | T10: =IFERROR('Annual P&L'!C29/'Annual P&L'!B29-1,0) -> 0.51804008 | U10: =IFERROR('Annual P&L'!D29/'Annual P&L'!C29-1,0) -> 0.045278421 | V10: =IFERROR('Annual P&L'!E29/'Annual P&L'!D29-1,0) -> 0.17581479 | W10: =IFERROR('Annual P&L'!F29/'Annual P&L'!E29-1,0) -> 0.10824117 | X10: =IFERROR('Annual P&L'!G29/'Annual P&L'!F29-1,0) -> 0.12390848 | Y10: =IFERROR('Annual P&L'!H29/'Annual P&L'!G29-1,0) -> 0.08636129 | Z10: =IFERROR('Annual P&L'!I29/'Annual P&L'!H29-1,0) -> 0.10114778 | AA10: =IFERROR('Annual P&L'!J29/'Annual P&L'!I29-1,0) -> 0.056060865 | ... AG10: =IFERROR('Annual P&L'!P29/'Annual P&L'!O29-1,0) -> -0.057960799
A11: EBIT | B11: ='Annual P&L'!B17 -> 6249.0284 | C11: ='Annual P&L'!C17 -> 9475 | D11: ='Annual P&L'!D17 -> 9988 | E11: ='Annual P&L'!E17 -> 11821 | F11: ='Annual P&L'!F17 -> 13853 | G11: ='Annual P&L'!G17 -> 15496 | H11: ='Annual P&L'!H17 -> 16198 | I11: ='Annual P&L'!I17 -> 18485 | ... P11: ='Annual P&L'!P17 -> 25037.796
A12: EBIT margin | B12: ='Annual P&L'!B18 -> 0.20070107 | C12: ='Annual P&L'!C18 -> 0.20279526 | D12: ='Annual P&L'!D18 -> 0.1975084 | E12: ='Annual P&L'!E18 -> 0.19562124 | F12: ='Annual P&L'!F18 -> 0.19600158 | G12: ='Annual P&L'!G18 -> 0.2055745 | H12: ='Annual P&L'!H18 -> 0.1891163 | I12: ='Annual P&L'!I18 -> 0.18219721 | ... P12: ='Annual P&L'!P18 -> 0.16 | R12: Margins (%)
A13: PBT | B13: ='Annual P&L'!B21 -> 7046.6605 | C13: ='Annual P&L'!C21 -> 10409 | D13: ='Annual P&L'!D21 -> 11099 | E13: ='Annual P&L'!E21 -> 12626 | F13: ='Annual P&L'!F21 -> 14032 | G13: ='Annual P&L'!G21 -> 16153 | H13: ='Annual P&L'!H21 -> 16975 | I13: ='Annual P&L'!I21 -> 19488 | ... P13: ='Annual P&L'!P21 -> 21070.931 | R13: Gross margin | S13: ='Annual P&L'!B9 -> 0.34247433 | T13: ='Annual P&L'!C9 -> 0.33887676 | U13: ='Annual P&L'!D9 -> 0.34275262 | V13: ='Annual P&L'!E9 -> 0.3501688 | W13: ='Annual P&L'!F9 -> 0.3591358 | X13: ='Annual P&L'!G9 -> 0.39008212 | Y13: ='Annual P&L'!H9 -> 0.36467759 | Z13: ='Annual P&L'!I9 -> 0.34794394 | ... AG13: ='Annual P&L'!P9 -> 0.34
A14: PBT margin | B14: ='Annual P&L'!B22 -> 0.22631875 | C14: ='Annual P&L'!C22 -> 0.22278584 | D14: ='Annual P&L'!D22 -> 0.21947795 | E14: ='Annual P&L'!E22 -> 0.20894287 | F14: ='Annual P&L'!F22 -> 0.1985342 | G14: ='Annual P&L'!G22 -> 0.21429045 | H14: ='Annual P&L'!H22 -> 0.198188 | I14: ='Annual P&L'!I22 -> 0.19208327 | ... P14: ='Annual P&L'!P22 -> 0.13465038 | R14: EBITDA margin | S14: ='Annual P&L'!B15 -> 0.21500524 | T14: ='Annual P&L'!C15 -> 0.22064552 | U14: ='Annual P&L'!D15 -> 0.22622108 | V14: ='Annual P&L'!E15 -> 0.23116767 | W14: ='Annual P&L'!F15 -> 0.23618382 | X14: ='Annual P&L'!G15 -> 0.25844068 | Y14: ='Annual P&L'!H15 -> 0.23793067 | Z14: ='Annual P&L'!I15 -> 0.2230425 | ... AG14: ='Annual P&L'!P15 -> 0.195
A15: Income tax | B15: ='Annual P&L'!B23 -> 1477.5626 | C15: ='Annual P&L'!C23 -> 1952 | D15: ='Annual P&L'!D23 -> 2317 | E15: ='Annual P&L'!E23 -> 2481 | F15: ='Annual P&L'!F23 -> 2938 | G15: ='Annual P&L'!G23 -> 3663 | H15: ='Annual P&L'!H23 -> 3443 | I15: ='Annual P&L'!I23 -> 4642 | ... P15: ='Annual P&L'!P23 -> 5267.7327 | R15: EBIT margin | S15: ='Annual P&L'!B18 -> 0.20070107 | T15: ='Annual P&L'!C18 -> 0.20279526 | U15: ='Annual P&L'!D18 -> 0.1975084 | V15: ='Annual P&L'!E18 -> 0.19562124 | W15: ='Annual P&L'!F18 -> 0.19600158 | X15: ='Annual P&L'!G18 -> 0.2055745 | Y15: ='Annual P&L'!H18 -> 0.1891163 | Z15: ='Annual P&L'!I18 -> 0.18219721 | ... AG15: ='Annual P&L'!P18 -> 0.16
A16: Net profit | B16: ='Annual P&L'!B25 -> 5569.0979 | C16: ='Annual P&L'!C25 -> 8457 | D16: ='Annual P&L'!D25 -> 8782 | E16: ='Annual P&L'!E25 -> 10123 | F16: ='Annual P&L'!F25 -> 11062 | G16: ='Annual P&L'!G25 -> 12433 | H16: ='Annual P&L'!H25 -> 13500 | I16: ='Annual P&L'!I25 -> 14851 | ... P16: ='Annual P&L'!P25 -> 15803.198 | R16: PBT margin | S16: ='Annual P&L'!B22 -> 0.22631875 | T16: ='Annual P&L'!C22 -> 0.22278584 | U16: ='Annual P&L'!D22 -> 0.21947795 | V16: ='Annual P&L'!E22 -> 0.20894287 | W16: ='Annual P&L'!F22 -> 0.1985342 | X16: ='Annual P&L'!G22 -> 0.21429045 | Y16: ='Annual P&L'!H22 -> 0.198188 | Z16: ='Annual P&L'!I22 -> 0.19208327 | ... AG16: ='Annual P&L'!P22 -> 0.13465038
A17: Net margin | B17: ='Annual P&L'!B26 -> 0.17886363 | C17: ='Annual P&L'!C26 -> 0.18100681 | D17: ='Annual P&L'!D26 -> 0.17366027 | E17: ='Annual P&L'!E26 -> 0.16752168 | F17: ='Annual P&L'!F26 -> 0.15651263 | G17: ='Annual P&L'!G26 -> 0.16493984 | H17: ='Annual P&L'!H26 -> 0.15761637 | I17: ='Annual P&L'!I26 -> 0.14637873 | ... P17: ='Annual P&L'!P26 -> 0.10098779 | R17: Net margin | S17: ='Annual P&L'!B26 -> 0.17886363 | T17: ='Annual P&L'!C26 -> 0.18100681 | U17: ='Annual P&L'!D26 -> 0.17366027 | V17: ='Annual P&L'!E26 -> 0.16752168 | W17: ='Annual P&L'!F26 -> 0.15651263 | X17: ='Annual P&L'!G26 -> 0.16493984 | Y17: ='Annual P&L'!H26 -> 0.15761637 | Z17: ='Annual P&L'!I26 -> 0.14637873 | ... AG17: ='Annual P&L'!P26 -> 0.10098779
A18: Basic EPS | B18: ='Annual P&L'!B29 -> 19.71516 | C18: ='Annual P&L'!C29 -> 29.928404 | D18: ='Annual P&L'!D29 -> 31.283515 | E18: ='Annual P&L'!E29 -> 36.783619 | F18: ='Annual P&L'!F29 -> 40.765121 | G18: ='Annual P&L'!G29 -> 45.816265 | H18: ='Annual P&L'!H29 -> 49.773017 | I18: ='Annual P&L'!I29 -> 54.807447 | ... P18: ='Annual P&L'!P29 -> 58.27437
A19: Diluted EPS | B19: ='Annual P&L'!B30 -> 19.71516 | C19: ='Annual P&L'!C30 -> 29.928404 | D19: ='Annual P&L'!D30 -> 31.283515 | E19: ='Annual P&L'!E30 -> 36.783619 | F19: ='Annual P&L'!F30 -> 40.765121 | G19: ='Annual P&L'!G30 -> 45.816265 | H19: ='Annual P&L'!H30 -> 49.773017 | I19: ='Annual P&L'!I30 -> 54.807447 | ... P19: ='Annual P&L'!P30 -> 58.158054 | R19: Returns (%)
A20: Weighted-average basic shares | B20: ='Annual P&L'!B27 -> 282.47794 | C20: ='Annual P&L'!C27 -> 282.57438 | D20: ='Annual P&L'!D27 -> 280.72293 | E20: ='Annual P&L'!E27 -> 275.20402 | F20: ='Annual P&L'!F27 -> 271.35943 | G20: ='Annual P&L'!G27 -> 271.36651 | H20: ='Annual P&L'!H27 -> 271.2313 | I20: ='Annual P&L'!I27 -> 270.96683 | ... P20: ='Annual P&L'!P27 -> 271.18608 | R20: ROE | S20: ='Annual Balance Sheet'!B24 -> 0.19873949 | T20: ='Annual Balance Sheet'!C24 -> 0.2749685 | U20: ='Annual Balance Sheet'!D24 -> 0.24981794 | V20: ='Annual Balance Sheet'!E24 -> 0.25614619 | W20: ='Annual Balance Sheet'!F24 -> 0.23426762 | X20: ='Annual Balance Sheet'!G24 -> 0.21753889 | Y20: ='Annual Balance Sheet'!H24 -> 0.21757174 | Z20: ='Annual Balance Sheet'!I24 -> 0.2331324 | ... AG20: ='Annual Balance Sheet'!P24 -> 0.2531182
A21: Weighted-average diluted shares | B21: ='Annual P&L'!B28 -> 282.47794 | C21: ='Annual P&L'!C28 -> 282.57438 | D21: ='Annual P&L'!D28 -> 280.72293 | E21: ='Annual P&L'!E28 -> 275.20402 | F21: ='Annual P&L'!F28 -> 271.35943 | G21: ='Annual P&L'!G28 -> 271.36651 | H21: ='Annual P&L'!H28 -> 271.2313 | I21: ='Annual P&L'!I28 -> 270.96683 | ... P21: ='Annual P&L'!P28 -> 271.72845 | R21: ROA | S21: =IFERROR('Annual P&L'!B25/'Annual Balance Sheet'!B12,0) -> 0.14004214 | T21: =IFERROR('Annual P&L'!C25/'Annual Balance Sheet'!C12,0) -> 0.18213653 | U21: =IFERROR('Annual P&L'!D25/'Annual Balance Sheet'!D12,0) -> 0.18131479 | V21: =IFERROR('Annual P&L'!E25/'Annual Balance Sheet'!E12,0) -> 0.17187924 | W21: =IFERROR('Annual P&L'!F25/'Annual Balance Sheet'!F12,0) -> 0.13293117 | X21: =IFERROR('Annual P&L'!G25/'Annual Balance Sheet'!G12,0) -> 0.14176254 | Y21: =IFERROR('Annual P&L'!H25/'Annual Balance Sheet'!H12,0) -> 0.15162917 | Z21: =IFERROR('Annual P&L'!I25/'Annual Balance Sheet'!I12,0) -> 0.15898556 | ... AG21: =IFERROR('Annual P&L'!P25/'Annual Balance Sheet'!P12,0) -> -0.29194047
R22: FCF margin | S22: ='Annual Cash Flow'!B22 -> 504.6 | T22: ='Annual Cash Flow'!C22 -> -431.5 | U22: ='Annual Cash Flow'!D22 -> -104.6 | V22: ='Annual Cash Flow'!E22 -> 3548.9 | W22: ='Annual Cash Flow'!F22 -> 3578 | X22: ='Annual Cash Flow'!G22 -> -1390 | Y22: ='Annual Cash Flow'!H22 -> 169 | Z22: ='Annual Cash Flow'!I22 -> -1557 | ... AG22: ='Annual Cash Flow'!P22 -> 0
A24: Cash Flow Statement | B24: FY16A | C24: FY17A | D24: FY18A | E24: FY19A | F24: FY20A | G24: FY21A | H24: FY22A | I24: FY23A | J24: FY24A | K24: FY25A | L24: FY26A | M24: FY27E | N24: FY28E | O24: FY29E | P24: FY30E | R24: Gearing
A25: Net profit | B25: ='Annual Cash Flow'!B5 -> 5569.0979 | C25: ='Annual Cash Flow'!C5 -> 8457 | D25: ='Annual Cash Flow'!D5 -> 8782 | E25: ='Annual Cash Flow'!E5 -> 10123 | F25: ='Annual Cash Flow'!F5 -> 11062 | G25: ='Annual Cash Flow'!G5 -> 12433 | H25: ='Annual Cash Flow'!H5 -> 13500 | I25: ='Annual Cash Flow'!I5 -> 14851 | ... P25: ='Annual Cash Flow'!P5 -> 15803.198 | R25: Net debt / EBITDA | S25: =IFERROR(-'Annual Balance Sheet'!B22/'Annual P&L'!B14,0) -> -1.6251636 | T25: =IFERROR(-'Annual Balance Sheet'!C22/'Annual P&L'!C14,0) -> -1.1776215 | U25: =IFERROR(-'Annual Balance Sheet'!D22/'Annual P&L'!D14,0) -> -0.85979021 | V25: =IFERROR(-'Annual Balance Sheet'!E22/'Annual P&L'!E14,0) -> -0.55551578 | W25: =IFERROR(-'Annual Balance Sheet'!F22/'Annual P&L'!F14,0) -> -0.46780087 | X25: =IFERROR(-'Annual Balance Sheet'!G22/'Annual P&L'!G14,0) -> -0.73486987 | Y25: =IFERROR(-'Annual Balance Sheet'!H22/'Annual P&L'!H14,0) -> -0.76254968 | Z25: =IFERROR(-'Annual Balance Sheet'!I22/'Annual P&L'!I14,0) -> -0.79216934 | ... AG25: =IFERROR(-'Annual Balance Sheet'!P22/'Annual P&L'!P14,0) -> 5.367081
A26: D&A | B26: ='Annual Cash Flow'!B6 -> 445.37462 | C26: ='Annual Cash Flow'!C6 -> 834 | D26: ='Annual Cash Flow'!D6 -> 1452 | E26: ='Annual Cash Flow'!E6 -> 2148 | F26: ='Annual Cash Flow'!F6 -> 2840 | G26: ='Annual Cash Flow'!G6 -> 3985 | H26: ='Annual Cash Flow'!H6 -> 4181 | I26: ='Annual Cash Flow'!I6 -> 4144 | ... P26: ='Annual Cash Flow'!P6 -> 5477.0179 | R26: Debt / equity | S26: =IFERROR('Annual Balance Sheet'!B14/'Annual Balance Sheet'!B19,0) -> 0.034729731 | T26: =IFERROR('Annual Balance Sheet'!C14/'Annual Balance Sheet'!C19,0) -> 0.016174784 | U26: =IFERROR('Annual Balance Sheet'!D14/'Annual Balance Sheet'!D19,0) -> 0.011872297 | V26: =IFERROR('Annual Balance Sheet'!E14/'Annual Balance Sheet'!E19,0) -> 0.094401288 | W26: =IFERROR('Annual Balance Sheet'!F14/'Annual Balance Sheet'!F19,0) -> 0.14486259 | X26: =IFERROR('Annual Balance Sheet'!G14/'Annual Balance Sheet'!G19,0) -> 0.099434701 | Y26: =IFERROR('Annual Balance Sheet'!H14/'Annual Balance Sheet'!H19,0) -> 0.10229655 | Z26: =IFERROR('Annual Balance Sheet'!I14/'Annual Balance Sheet'!I19,0) -> 0.073182666 | ... AG26: =IFERROR('Annual Balance Sheet'!P14/'Annual Balance Sheet'!P19,0) -> 0.078092309
A27: Other non-cash / working capital | B27: ='Annual Cash Flow'!B7 -> -823.5002 | C27: ='Annual Cash Flow'!C7 -> -934 | D27: ='Annual Cash Flow'!D7 -> -1111 | E27: ='Annual Cash Flow'!E7 -> -805 | F27: ='Annual Cash Flow'!F7 -> -179 | G27: ='Annual Cash Flow'!G7 -> -657 | H27: ='Annual Cash Flow'!H7 -> -777 | I27: ='Annual Cash Flow'!I7 -> -1003 | ... P27: ='Annual Cash Flow'!P7 -> 0 | R27: Net debt / equity | S27: =IFERROR(-'Annual Balance Sheet'!B22/'Annual Balance Sheet'!B19,0) -> -0.38824713 | T27: =IFERROR(-'Annual Balance Sheet'!C22/'Annual Balance Sheet'!C19,0) -> -0.36249492 | U27: =IFERROR(-'Annual Balance Sheet'!D22/'Annual Balance Sheet'!D19,0) -> -0.26716064 | V27: =IFERROR(-'Annual Balance Sheet'!E22/'Annual Balance Sheet'!E19,0) -> -0.18378174 | W27: =IFERROR(-'Annual Balance Sheet'!F22/'Annual Balance Sheet'!F19,0) -> -0.14955473 | X27: =IFERROR(-'Annual Balance Sheet'!G22/'Annual Balance Sheet'!G19,0) -> -0.23056482 | Y27: =IFERROR(-'Annual Balance Sheet'!H22/'Annual Balance Sheet'!H19,0) -> -0.25062091 | Z27: =IFERROR(-'Annual Balance Sheet'!I22/'Annual Balance Sheet'!I19,0) -> -0.27410624 | ... AG27: =IFERROR(-'Annual Balance Sheet'!P22/'Annual Balance Sheet'!P19,0) -> 2.452465
A28: Cash flow from operations | B28: ='Annual Cash Flow'!B12 -> 4157.9723 | C28: ='Annual Cash Flow'!C12 -> 9343.5 | D28: ='Annual Cash Flow'!D12 -> 6898.1 | E28: ='Annual Cash Flow'!E12 -> 9151 | F28: ='Annual Cash Flow'!F12 -> 18739 | G28: ='Annual Cash Flow'!G12 -> 12116 | H28: ='Annual Cash Flow'!H12 -> 14567 | I28: ='Annual Cash Flow'!I12 -> 15691 | ... P28: ='Annual Cash Flow'!P12 -> 19697.42
A29: CFO / net profit | B29: ='Annual Cash Flow'!B13 -> 0.74661505 | C29: ='Annual Cash Flow'!C13 -> 1.1048244 | D29: ='Annual Cash Flow'!D13 -> 0.78548167 | E29: ='Annual Cash Flow'!E13 -> 0.90398103 | F29: ='Annual Cash Flow'!F13 -> 1.6939975 | G29: ='Annual Cash Flow'!G13 -> 0.97450334 | H29: ='Annual Cash Flow'!H13 -> 1.079037 | I29: ='Annual Cash Flow'!I13 -> 1.0565618 | ... P29: ='Annual Cash Flow'!P13 -> 1.2464199 | R29: Operating KPIs
A30: Capex | B30: ='Annual Cash Flow'!B18 -> -2164.2746 | C30: ='Annual Cash Flow'!C18 -> -6197.7 | D30: ='Annual Cash Flow'!D18 -> -4936.2 | E30: ='Annual Cash Flow'!E18 -> -6053.6 | F30: ='Annual Cash Flow'!F18 -> -17633 | G30: ='Annual Cash Flow'!G18 -> -3483 | H30: ='Annual Cash Flow'!H18 -> -1600 | I30: ='Annual Cash Flow'!I18 -> -3597 | ... P30: ='Annual Cash Flow'!P18 -> -5477.0179 | R30: Closing headcount | S30: ='Revenue Drivers'!B7 -> 106107 | T30: ='Revenue Drivers'!C7 -> 117781 | U30: ='Revenue Drivers'!D7 -> 120081 | V30: ='Revenue Drivers'!E7 -> 137965 | W30: ='Revenue Drivers'!F7 -> 150423 | X30: ='Revenue Drivers'!G7 -> 168977 | Y30: ='Revenue Drivers'!H7 -> 208877 | Z30: ='Revenue Drivers'!I7 -> 225944 | ... AG30: ='Revenue Drivers'!P7 -> 260074.61
A31: Acquisitions / investments | B31: ='Annual Cash Flow'!B19 -> -960.3 | C31: ='Annual Cash Flow'!C19 -> -3124.5746 | D31: ='Annual Cash Flow'!D19 -> -9322.2746 | E31: ='Annual Cash Flow'!E19 -> -14258.475 | F31: ='Annual Cash Flow'!F19 -> -20312.075 | G31: ='Annual Cash Flow'!G19 -> -37945.075 | H31: ='Annual Cash Flow'!H19 -> -41428.075 | I31: ='Annual Cash Flow'!I19 -> -43028.075 | ... P31: ='Annual Cash Flow'!P19 -> -76927.801 | R31: Billable employees | S31: ='Revenue Drivers'!B9 -> 82763.46 | T31: ='Revenue Drivers'!C9 -> 91869.18 | U31: ='Revenue Drivers'!D9 -> 94863.99 | V31: ='Revenue Drivers'!E9 -> 108992.35 | W31: ='Revenue Drivers'!F9 -> 120338.4 | X31: ='Revenue Drivers'!G9 -> 135181.6 | Y31: ='Revenue Drivers'!H9 -> 169190.37 | Z31: ='Revenue Drivers'!I9 -> 183014.64 | ... AG31: ='Revenue Drivers'!P9 -> 213261.18
A32: Cash flow from investing | B32: ='Annual Cash Flow'!B20 -> -3124.5746 | C32: ='Annual Cash Flow'!C20 -> -9322.2746 | D32: ='Annual Cash Flow'!D20 -> -14258.475 | E32: ='Annual Cash Flow'!E20 -> -20312.075 | F32: ='Annual Cash Flow'!F20 -> -37945.075 | G32: ='Annual Cash Flow'!G20 -> -41428.075 | H32: ='Annual Cash Flow'!H20 -> -43028.075 | I32: ='Annual Cash Flow'!I20 -> -46625.075 | ... P32: ='Annual Cash Flow'!P20 -> -82404.819 | R32: Attrition | S32: ='Revenue Drivers'!B11 -> 0.37620467 | T32: ='Revenue Drivers'!C11 -> 0.51777974 | U32: ='Revenue Drivers'!D11 -> 0.53306845 | V32: ='Revenue Drivers'!E11 -> 0.55441506 | W32: ='Revenue Drivers'!F11 -> 0.58731045 | X32: ='Revenue Drivers'!G11 -> 0.55761287 | Y32: ='Revenue Drivers'!H11 -> 0.5062404 | Z32: ='Revenue Drivers'!I11 -> 0.55436002 | ... AG32: ='Revenue Drivers'!P11 -> 0.73377735
A33: Debt issuance / (repayment) | B33: ='Annual Cash Flow'!B22 -> 504.6 | C33: ='Annual Cash Flow'!C22 -> -431.5 | D33: ='Annual Cash Flow'!D22 -> -104.6 | E33: ='Annual Cash Flow'!E22 -> 3548.9 | F33: ='Annual Cash Flow'!F22 -> 3578 | G33: ='Annual Cash Flow'!G22 -> -1390 | H33: ='Annual Cash Flow'!H22 -> 169 | I33: ='Annual Cash Flow'!I22 -> -1557 | ... P33: ='Annual Cash Flow'!P22 -> 0 | R33: Advanced AI revenue mix | S33: ='Revenue Drivers'!B28 -> 0 | T33: ='Revenue Drivers'!C28 -> 0 | U33: ='Revenue Drivers'!D28 -> 0 | V33: ='Revenue Drivers'!E28 -> 0 | W33: ='Revenue Drivers'!F28 -> 0 | X33: ='Revenue Drivers'!G28 -> 0 | Y33: ='Revenue Drivers'!H28 -> 0 | Z33: ='Revenue Drivers'!I28 -> 0 | ... AG33: ='Revenue Drivers'!P28 -> 0.078461044
A34: Equity issuance / (buybacks) & other | B34: ='Annual Cash Flow'!B23 -> 585.79861 | C34: ='Annual Cash Flow'!C23 -> 1092.3822 | D34: ='Annual Cash Flow'!D23 -> -4105.2942 | E34: ='Annual Cash Flow'!E23 -> -3390.9151 | F34: ='Annual Cash Flow'!F23 -> 890.11498 | G34: ='Annual Cash Flow'!G23 -> 4498.5292 | H34: ='Annual Cash Flow'!H23 -> -1652.5528 | I34: ='Annual Cash Flow'!I23 -> 1534.0816 | ... P34: ='Annual Cash Flow'!P23 -> 0 | R34: Software ARR growth | S34: =0 -> 0 | T34: ='Operating Cuts'!C22 -> 0 | U34: ='Operating Cuts'!D22 -> 0 | V34: ='Operating Cuts'!E22 -> 0 | W34: ='Operating Cuts'!F22 -> 0 | X34: ='Operating Cuts'!G22 -> 0 | Y34: ='Operating Cuts'!H22 -> 0 | Z34: ='Operating Cuts'!I22 -> 0.052 | AA34: ='Operating Cuts'!J22 -> 0.007 | ... AG34: ='Operating Cuts'!P22 -> 0.08
A35: Dividends | B35: ='Annual Cash Flow'!B24 -> -2883.3965 | C35: ='Annual Cash Flow'!C24 -> -4081.0822 | D35: ='Annual Cash Flow'!D24 -> -1350.3058 | E35: ='Annual Cash Flow'!E24 -> -1324.8849 | F35: ='Annual Cash Flow'!F24 -> -1961.115 | G35: ='Annual Cash Flow'!G24 -> -7055.5292 | H35: ='Annual Cash Flow'!H24 -> -11932.447 | I35: ='Annual Cash Flow'!I24 -> -12993.082 | ... P35: ='Annual Cash Flow'!P24 -> -7111.4391
A36: Cash flow from financing | B36: ='Annual Cash Flow'!B26 -> -969.49772 | C36: ='Annual Cash Flow'!C26 -> -2486.2 | D36: ='Annual Cash Flow'!D26 -> -4449.2 | E36: ='Annual Cash Flow'!E26 -> -361.9 | F36: ='Annual Cash Flow'!F26 -> 2686 | G36: ='Annual Cash Flow'!G26 -> -3290 | H36: ='Annual Cash Flow'!H26 -> -12639 | I36: ='Annual Cash Flow'!I26 -> -12013 | ... P36: ='Annual Cash Flow'!P26 -> -7111.4391 | R36: Valuations
A37: FX / other | B37: ='Annual Cash Flow'!B27 -> 0 | C37: ='Annual Cash Flow'!C27 -> 0 | D37: ='Annual Cash Flow'!D27 -> 0 | E37: ='Annual Cash Flow'!E27 -> 0 | F37: ='Annual Cash Flow'!F27 -> 0 | G37: ='Annual Cash Flow'!G27 -> 0 | H37: ='Annual Cash Flow'!H27 -> 0 | I37: ='Annual Cash Flow'!I27 -> 0 | ... P37: ='Annual Cash Flow'!P27 -> 0 | R37: Share price (INR) | S37: ='Market Data'!C5 -> 407.04999 | T37: ='Market Data'!C6 -> 437.375 | U37: ='Market Data'!C7 -> 484.29999 | V37: ='Market Data'!C8 -> 541.45001 | W37: ='Market Data'!C9 -> 436.39999 | X37: ='Market Data'!C10 -> 982.65002 | Y37: ='Market Data'!C11 -> 1163.75 | Z37: ='Market Data'!C12 -> 1085.25 | AA37: ='Market Data'!C13 -> 1543.55 | AB37: ='Market Data'!C14 -> 1592.5 | AC37: ='Market Data'!C15 -> 1341.6 | AD37: ='Market Data'!C16 -> 1475.76 | AE37: ='Market Data'!C17 -> 1471.8198 | AF37: ='Market Data'!C18 -> 1346.3551 | AG37: ='Market Data'!C19 -> 1221.2182 | AH37: =AD37/AC37-1 -> 0.1
A38: Net change in cash | B38: ='Annual Cash Flow'!B28 -> 63.9 | C38: ='Annual Cash Flow'!C28 -> -2464.9746 | D38: ='Annual Cash Flow'!D28 -> -11809.575 | E38: ='Annual Cash Flow'!E28 -> -11522.975 | F38: ='Annual Cash Flow'!F28 -> -16520.075 | G38: ='Annual Cash Flow'!G28 -> -32602.075 | H38: ='Annual Cash Flow'!H28 -> -41100.075 | I38: ='Annual Cash Flow'!I28 -> -42947.075 | ... P38: ='Annual Cash Flow'!P28 -> -69818.839 | R38: Market capitalization | S38: =S37*'Annual P&L'!B27 -> 114982.64 | T38: =T37*'Annual P&L'!C27 -> 123590.97 | U38: =U37*'Annual P&L'!D27 -> 135954.11 | V38: =V37*'Annual P&L'!E27 -> 149009.22 | W38: =W37*'Annual P&L'!F27 -> 118421.25 | X38: =X37*'Annual P&L'!G27 -> 266658.31 | Y38: =Y37*'Annual P&L'!H27 -> 315645.42 | Z38: =Z37*'Annual P&L'!I27 -> 294066.75 | ... AG38: =AG37*'Annual P&L'!P27 -> 331177.39
A39: Opening cash | B39: ='Annual Cash Flow'!B29 -> 11788.8 | C39: ='Annual Cash Flow'!C29 -> 11852.7 | D39: ='Annual Cash Flow'!D29 -> 12681.8 | E39: ='Annual Cash Flow'!E29 -> 10273.1 | F39: ='Annual Cash Flow'!F29 -> 11746 | G39: ='Annual Cash Flow'!G29 -> 15373 | H39: ='Annual Cash Flow'!H29 -> 20490 | I39: ='Annual Cash Flow'!I29 -> 21883 | ... P39: ='Annual Cash Flow'!P29 -> -88741.64 | R39: Enterprise value | S39: =S38+'Annual Balance Sheet'!B14-'Annual Balance Sheet'!B5 -> 104103.14 | T39: =T38+'Annual Balance Sheet'!C14-'Annual Balance Sheet'!C5 -> 111450.87 | U39: =U38+'Annual Balance Sheet'!D14-'Annual Balance Sheet'!D5 -> 126118.11 | V39: =V38+'Annual Balance Sheet'!E14-'Annual Balance Sheet'!E5 -> 141249.22 | W39: =W38+'Annual Balance Sheet'!F14-'Annual Balance Sheet'!F5 -> 110612.25 | X39: =X38+'Annual Balance Sheet'!G14-'Annual Balance Sheet'!G5 -> 252342.31 | Y39: =Y38+'Annual Balance Sheet'!H14-'Annual Balance Sheet'!H5 -> 300105.42 | Z39: =Z38+'Annual Balance Sheet'!I14-'Annual Balance Sheet'!I5 -> 276140.75 | ... AG39: =AG38+'Annual Balance Sheet'!P14-'Annual Balance Sheet'!P5 -> 494952.87
A40: Closing cash | B40: ='Annual Cash Flow'!B30 -> 11852.7 | C40: ='Annual Cash Flow'!C30 -> 12681.8 | D40: ='Annual Cash Flow'!D30 -> 10273.1 | E40: ='Annual Cash Flow'!E30 -> 11746 | F40: ='Annual Cash Flow'!F30 -> 15373 | G40: ='Annual Cash Flow'!G30 -> 20490 | H40: ='Annual Cash Flow'!H30 -> 21883 | I40: ='Annual Cash Flow'!I30 -> 22712 | ... P40: ='Annual Cash Flow'!P30 -> -158560.48 | R40: P/E | S40: =IFERROR(S37/'Annual P&L'!B29,0) -> 20.646547 | T40: =IFERROR(T37/'Annual P&L'!C29,0) -> 14.614044 | U40: =IFERROR(U37/'Annual P&L'!D29,0) -> 15.480997 | V40: =IFERROR(V37/'Annual P&L'!E29,0) -> 14.719868 | W40: =IFERROR(W37/'Annual P&L'!F29,0) -> 10.70523 | X40: =IFERROR(X37/'Annual P&L'!G29,0) -> 21.447624 | Y40: =IFERROR(Y37/'Annual P&L'!H29,0) -> 23.381142 | Z40: =IFERROR(Z37/'Annual P&L'!I29,0) -> 19.801141 | ... AG40: =IFERROR(AG37/'Annual P&L'!P29,0) -> 20.956353
A41: Free cash flow | B41: ='Annual Cash Flow'!B32 -> 1993.6977 | C41: ='Annual Cash Flow'!C32 -> 3145.8 | D41: ='Annual Cash Flow'!D32 -> 1961.9 | E41: ='Annual Cash Flow'!E32 -> 3097.4 | F41: ='Annual Cash Flow'!F32 -> 1106 | G41: ='Annual Cash Flow'!G32 -> 8633 | H41: ='Annual Cash Flow'!H32 -> 12967 | I41: ='Annual Cash Flow'!I32 -> 12094 | ... P41: ='Annual Cash Flow'!P32 -> 14220.402 | R41: EV / EBITDA | S41: =IFERROR(S39/'Annual P&L'!B14,0) -> 15.550773 | T41: =IFERROR(T39/'Annual P&L'!C14,0) -> 10.811026 | U41: =IFERROR(U39/'Annual P&L'!D14,0) -> 11.024311 | V41: =IFERROR(V39/'Annual P&L'!E14,0) -> 10.11162 | W41: =IFERROR(W39/'Annual P&L'!F14,0) -> 6.6262657 | X41: =IFERROR(X39/'Annual P&L'!G14,0) -> 12.953252 | Y41: =IFERROR(Y39/'Annual P&L'!H14,0) -> 14.726209 | Z41: =IFERROR(Z39/'Annual P&L'!I14,0) -> 12.202959 | ... AG41: =IFERROR(AG39/'Annual P&L'!P14,0) -> 16.220085
A42: FCF margin | B42: ='Annual Cash Flow'!B33 -> 0.064031916 | C42: ='Annual Cash Flow'!C33 -> 0.067330166 | D42: ='Annual Cash Flow'!D33 -> 0.038795729 | E42: ='Annual Cash Flow'!E33 -> 0.051257695 | F42: ='Annual Cash Flow'!F33 -> 0.015648434 | G42: ='Annual Cash Flow'!G33 -> 0.11452792 | H42: ='Annual Cash Flow'!H33 -> 0.15139345 | I42: ='Annual Cash Flow'!I33 -> 0.11920438 | ... P42: ='Annual Cash Flow'!P33 -> 0.090873185 | R42: P / book value | S42: =IFERROR(S38/'Annual Balance Sheet'!B19,0) -> 4.1032843 | T42: =IFERROR(T38/'Annual Balance Sheet'!C19,0) -> 3.6903401 | U42: =IFERROR(U38/'Annual Balance Sheet'!D19,0) -> 3.6927195 | V42: =IFERROR(V38/'Annual Balance Sheet'!E19,0) -> 3.5290172 | W42: =IFERROR(W38/'Annual Balance Sheet'!F19,0) -> 2.2679547 | X42: =IFERROR(X38/'Annual Balance Sheet'!G19,0) -> 4.294637 | Y42: =IFERROR(Y38/'Annual Balance Sheet'!H19,0) -> 5.0905626 | Z42: =IFERROR(Z38/'Annual Balance Sheet'!I19,0) -> 4.496571 | ... AG42: =IFERROR(AG38/'Annual Balance Sheet'!P19,0) -> 4.9592343
...

Sheet Assumptions
A1: Forecast Assumptions
A2: Editable FY27–FY30 inputs; blue font on yellow fill
A4: Driver | B4: FY16A | C4: FY17A | D4: FY18A | E4: FY19A | F4: FY20A | G4: FY21A | H4: FY22A | I4: FY23A | J4: FY24A | K4: FY25A | L4: FY26A | M4: FY27E | N4: FY28E | O4: FY29E | P4: FY30E
A5: Gross hiring / opening headcount | M5: 0.16 | N5: 0.16 | O5: 0.16 | P5: 0.16
A6: Attrition | M6: 0.125 | N6: 0.125 | O6: 0.125 | P6: 0.125
A7: Billable % | M7: 0.825 | N7: =M7-0.5% -> 0.82 | O7: =N7 -> 0.82 | P7: =O7 -> 0.82
A8: Nominal pricing / productivity | M8: 0.025 | N8: 0.025 | O8: 0.025 | P8: 0.025
A9: T&M mix | M9: 0.6145 | N9: =M9-1.25% -> 0.602 | O9: =N9 -> 0.602 | P9: =O9 -> 0.602
A10: AI deflation on T&M | M10: 0.03 | N10: =M10+0.5% -> 0.035 | O10: =N10 -> 0.035 | P10: =O10 -> 0.035
A11: Fixed-price productivity uplift | M11: 0.045 | N11: =M11+0.75% -> 0.0525 | O11: =N11 -> 0.0525 | P11: =O11 -> 0.0525
A12: Gross margin | M12: 0.34 | N12: 0.34 | O12: 0.34 | P12: 0.34
A13: S&M / revenue | M13: 0.06 | N13: 0.06 | O13: 0.06 | P13: 0.06
A14: G&A / revenue | M14: 0.085 | N14: 0.085 | O14: 0.085 | P14: 0.085
A15: D&A / revenue | M15: 0.035 | N15: 0.035 | O15: 0.035 | P15: 0.035
A16: Net other income / revenue | M16: 0.012 | N16: 0.012 | O16: 0.012 | P16: 0.012
A17: Tax rate | M17: 0.25 | N17: 0.25 | O17: 0.25 | P17: 0.25
A18: Receivable days | M18: 82 | N18: 82 | O18: 82 | P18: 82
A19: Other current assets / revenue | M19: 0.14 | N19: 0.14 | O19: 0.14 | P19: 0.14
A20: Current liabilities / revenue | M20: 0.18 | N20: 0.18 | O20: 0.18 | P20: 0.18
A21: Capex / revenue | M21: 0.022 | N21: 0.022 | O21: 0.022 | P21: 0.022
A22: Dividend payout | M22: 0.45 | N22: 0.45 | O22: 0.45 | P22: 0.45
A23: Basic shares growth | M23: 0 | N23: 0 | O23: 0 | P23: 0
A24: Dilution | M24: 0.002 | N24: 0.002 | O24: 0.002 | P24: 0.002
A25: Application services / ITBS mix change | B25: ppt | M25: 0 | N25: 0 | O25: 0 | P25: 0
A26: Infrastructure services / ITBS mix change | B26: ppt | M26: 0 | N26: 0 | O26: 0 | P26: 0
A27: Business services / ITBS mix change | B27: ppt | M27: 0 | N27: 0 | O27: 0 | P27: 0
A28: ER&D mix change | B28: ppt | M28: 0 | N28: 0 | O28: 0 | P28: 0
A29: Products & Platforms mix change | B29: ppt | M29: 0 | N29: 0 | O29: 0 | P29: 0
A30: Perpetual license growth | B30: % | M30: 0.05 | N30: 0.05 | O30: 0.05 | P30: 0.05
A31: Subscription & support growth | B31: % | M31: 0.03 | N31: 0.03 | O31: 0.03 | P31: 0.03
A32: Professional services growth | B32: % | M32: 0.06 | N32: 0.06 | O32: 0.06 | P32: 0.06
A33: Software ARR growth | B33: % | M33: 0.08 | N33: 0.08 | O33: 0.08 | P33: 0.08
A34: ITBS EBIT margin | B34: % | M34: 0.163 | N34: 0.163 | O34: 0.163 | P34: 0.163
A35: ER&D EBIT margin | B35: % | M35: 0.155 | N35: 0.155 | O35: 0.155 | P35: 0.155
A36: Products EBIT margin | B36: % | M36: 0.202 | N36: 0.202 | O36: 0.202 | P36: 0.202
A37: Advanced AI revenue growth | B37: % | M37: 0.25 | N37: =M37+0.005 -> 0.255 | O37: =N37+0.95% -> 0.2645 | P37: =O37+1% -> 0.2745
A38: Yield on opening cash | M38: 0.04 | N38: 0.04 | O38: 0.04 | P38: 0.04
A39: Finance cost / average debt | M39: 0.08 | N39: 0.08 | O39: 0.08 | P39: 0.08
A40: Maintenance capex / revenue | M40: 0.018 | N40: 0.018 | O40: 0.018 | P40: 0.018
A41: Data centre & AI infrastructure capex / revenue | M41: 0.01 | N41: 0.01 | O41: 0.01 | P41: 0.01
...

Sheet Annual Balance Sheet
A1: Annual Balance Sheet
A2: Historical totals sourced from reported/compiled statements; non-cash current assets and equity are aggregated where detailed disclosure is unavailable
A4: Metric | B4: FY16A | C4: FY17A | D4: FY18A | E4: FY19A | F4: FY20A | G4: FY21A | H4: FY22A | I4: FY23A | J4: FY24A | K4: FY25A | L4: FY26A | M4: FY27E | N4: FY28E | O4: FY29E | P4: FY30E
A5: Cash & equivalents | B5: 11852.7 | C5: 12681.8 | D5: 10273.1 | E5: 11746 | F5: 15373 | G5: 20490 | H5: 21883 | I5: 22712 | J5: 27988 | K5: 29738 | L5: 31401 | M5: ='Annual Cash Flow'!M30 -> 33379.455 | N5: ='Annual Cash Flow'!N30 -> -24835.017 | O5: ='Annual Cash Flow'!O30 -> -88741.64 | P5: ='Annual Cash Flow'!P30 -> -158560.48
A6: Trade receivables & other current assets (actuals) / receivables (forecast) | B6: 13133.1 | C6: 13785.8 | D6: 14777.3 | E6: 18326 | F6: 23051 | G6: 22562 | H6: 26158 | I6: 30865 | J6: 31343 | K6: 32371 | L6: 39141 | M6: ='Annual P&L'!M5*Assumptions!M18/365 -> 30507.284 | N6: ='Annual P&L'!N5*Assumptions!N18/365 -> 31814.627 | O6: ='Annual P&L'!O5*Assumptions!O18/365 -> 33386.864 | P6: ='Annual P&L'!P5*Assumptions!P18/365 -> 35155.81
A7: Other current assets (forecast only) | B7: =SUM(B5:B6) -> 24985.8 | C7: =SUM(C5:C6) -> 26467.6 | D7: =SUM(D5:D6) -> 25050.4 | E7: =SUM(E5:E6) -> 30072 | F7: =SUM(F5:F6) -> 38424 | G7: =SUM(G5:G6) -> 43052 | H7: =SUM(H5:H6) -> 48041 | I7: =SUM(I5:I6) -> 53577 | ... L7: =SUM(L5:L6) -> 70542 | M7: ='Annual P&L'!M5*Assumptions!M19 -> 19011.246 | N7: ='Annual P&L'!N5*Assumptions!N19 -> 19825.944 | O7: ='Annual P&L'!O5*Assumptions!O19 -> 20805.716 | P7: ='Annual P&L'!P5*Assumptions!P19 -> 21908.072
A8: Total current assets | B8: 24985.8 | C8: 26467.6 | D8: 25050.4 | E8: 30072 | F8: 38424 | G8: 43052 | H8: 48041 | I8: 53577 | J8: 59331 | K8: 62109 | L8: 70542 | M8: =SUM(M5:M7) -> 82897.985 | N8: =SUM(N5:N7) -> 26805.554 | O8: =SUM(O5:O7) -> -34549.06 | P8: =SUM(P5:P7) -> -101496.6
A9: Net PPE & intangibles | B9: 4323.1 | C9: 4680.6 | D9: 5184.7 | E9: 5801 | F9: 8868 | G9: 8637 | H9: 8046 | I9: 7748 | J9: 7909 | K9: 7576 | L9: 8309 | M9: =L9-'Annual Cash Flow'!M18-'Annual P&L'!M16 -> 8309 | N9: =M9-'Annual Cash Flow'!N18-'Annual P&L'!N16 -> 8309 | O9: =N9-'Annual Cash Flow'!O18-'Annual P&L'!O16 -> 8309 | P9: =O9-'Annual Cash Flow'!P18-'Annual P&L'!P16 -> 8309
A10: Goodwill, intangibles & investments | B10: 6579.5 | C10: 11572.2 | D10: 14432.5 | E10: 17730 | F10: 29459 | G10: 29197 | H10: 27272 | I10: 27021 | J10: 27356 | K10: 28746 | L10: 29260 | M10: =L10 -> 29260 | N10: =M10 -> 29260 | O10: =N10 -> 29260 | P10: =O10 -> 29260
A11: Other long-term assets | B11: 3878.9 | C11: 3711.8 | D11: 3767.5 | E11: 5293 | F11: 6465 | G11: 6817 | H11: 5674 | I11: 5065 | J11: 5181 | K11: 7113 | L11: 8147 | M11: =L11*(1+'Annual P&L'!M6) -> 8500.7279 | N11: =M11*(1+'Annual P&L'!N6) -> 8865.0138 | O11: =N11*(1+'Annual P&L'!O6) -> 9303.111 | P11: =O11*(1+'Annual P&L'!P6) -> 9796.0205
A12: Total assets | B12: 39767.3 | C12: 46432.2 | D12: 48435.1 | E12: 58896 | F12: 83216 | G12: 87703 | H12: 89033 | I12: 93411 | J12: 99777 | K12: 105544 | L12: 116258 | M12: =SUM(M8:M11) -> 128967.71 | N12: =SUM(N8:N11) -> 73239.568 | O12: =SUM(O8:O11) -> 12323.051 | P12: =SUM(P8:P11) -> -54131.576
A13: Current liabilities | B13: 9508.5 | C13: 11147.7 | D13: 9914.3 | E13: 11148 | F13: 20889 | G13: 16755 | H13: 18014 | I13: 20420 | J13: 21532 | K13: 24471 | L13: 29828 | M13: ='Annual P&L'!M5*Assumptions!M20 -> 24443.031 | N13: ='Annual P&L'!N5*Assumptions!N20 -> 25490.5 | O13: ='Annual P&L'!O5*Assumptions!O20 -> 26750.207 | P13: ='Annual P&L'!P5*Assumptions!P20 -> 28167.521
A14: Debt & lease liabilities | B14: 973.2 | C14: 541.7 | D14: 437.1 | E14: 3986 | F14: 7564 | G14: 6174 | H14: 6343 | I14: 4786 | J14: 5756 | K14: 6276 | L14: 5215 | M14: 5215 | N14: 5215 | O14: 5215 | P14: 5215
A15: Other long-term liabilities | B15: 1263.5 | C15: 1252.5 | D15: 1266.9 | E15: 1538 | F15: 2548 | G15: 2683 | H15: 2670 | I15: 2807 | J15: 4218 | K15: 5124 | L15: 6018 | M15: 6279.2906 | N15: 6548.3801 | O15: 6871.9924 | P15: 7236.0932
A16: Total liabilities | B16: 11745.2 | C16: 12941.9 | D16: 11618.3 | E16: 16672 | F16: 31001 | G16: 25612 | H16: 27027 | I16: 28013 | J16: 31506 | K16: 35871 | L16: 41061 | M16: =SUM(M13:M15) -> 35937.321 | N16: =SUM(N13:N15) -> 37253.88 | O16: =SUM(O13:O15) -> 38837.199 | P16: =SUM(P13:P15) -> 40618.614
A17: Share capital & other contributed equity | B17: 0 | C17: 0 | D17: 0 | E17: 0 | F17: 0 | G17: 0 | H17: 0 | I17: 0 | J17: 0 | K17: 0 | L17: 0 | M17: =L17 -> 0 | N17: =M17 -> 0 | O17: =N17 -> 0 | P17: =O17 -> 0
A18: Retained earnings & reserves (incl. other equity in actuals) | B18: =B13 -> 9508.5 | C18: =C13 -> 11147.7 | D18: =D13 -> 9914.3 | E18: =E13 -> 11148 | F18: =F13 -> 20889 | G18: =G13 -> 16755 | H18: =H13 -> 18014 | I18: =I13 -> 20420 | ... L18: =L13 -> 29828 | M18: =L18+'Annual P&L'!M25+'Annual Cash Flow'!M23+'Annual Cash Flow'!M24 -> 39136.466 | N18: =M18+'Annual P&L'!N25+'Annual Cash Flow'!N23+'Annual Cash Flow'!N24 -> 48861.649 | O18: =N18+'Annual P&L'!O25+'Annual Cash Flow'!O23+'Annual Cash Flow'!O24 -> 58088.185 | P18: =O18+'Annual P&L'!P25+'Annual Cash Flow'!P23+'Annual Cash Flow'!P24 -> 66779.944
A19: Total equity | B19: 28022.1 | C19: 33490.4 | D19: 36816.8 | E19: 42224 | F19: 52215 | G19: 62091 | H19: 62006 | I19: 65398 | J19: 68271 | K19: 69673 | L19: 75197 | M19: =SUM(M17:M18) -> 39136.466 | N19: =SUM(N17:N18) -> 48861.649 | O19: =SUM(O17:O18) -> 58088.185 | P19: =SUM(P17:P18) -> 66779.944
A20: Total liabilities & equity | B20: =SUM(B16,B19) -> 39767.3 | C20: =SUM(C16,C19) -> 46432.3 | D20: =SUM(D16,D19) -> 48435.1 | E20: =SUM(E16,E19) -> 58896 | F20: =SUM(F16,F19) -> 83216 | G20: =SUM(G16,G19) -> 87703 | H20: =SUM(H16,H19) -> 89033 | I20: =SUM(I16,I19) -> 93411 | ... P20: =SUM(P16,P19) -> 107398.56
A21: Balance check | B21: =B12-B20 -> 0 | C21: =C12-C20 -> -0.1 | D21: =D12-D20 -> 0 | E21: =E12-E20 -> 0 | F21: =F12-F20 -> 0 | G21: =G12-G20 -> 0 | H21: =H12-H20 -> 0 | I21: =I12-I20 -> 0 | ... P21: =P12-P20 -> -161530.13
A22: Net cash / (debt) | B22: =B5-B14 -> 10879.5 | C22: =C5-C14 -> 12140.1 | D22: =D5-D14 -> 9836 | E22: =E5-E14 -> 7760 | F22: =F5-F14 -> 7809 | G22: =G5-G14 -> 14316 | H22: =H5-H14 -> 15540 | I22: =I5-I14 -> 17926 | ... P22: =P5-P14 -> -163775.48
A23: ROA | B23: 0.14004214 | C23: 0.19621924 | D23: 0.18514283 | E23: 0.18863125 | F23: 0.15568003 | G23: 0.14548412 | H23: 0.15277023 | I23: 0.16280064 | J23: 0.16255668 | K23: 0.16940303 | L23: 0.15654503 | M23: =IFERROR('Annual P&L'!M25/AVERAGE(L12,M12),0) -> 0.13803189 | N23: =IFERROR('Annual P&L'!N25/AVERAGE(M12,N12),0) -> 0.17489133 | O23: =IFERROR('Annual P&L'!O25/AVERAGE(N12,O12),0) -> 0.39212265 | P23: =IFERROR('Annual P&L'!P25/AVERAGE(O12,P12),0) -> -0.75597969
A24: ROE | B24: =IFERROR('Annual P&L'!B25/B19,0) -> 0.19873949 | C24: =IFERROR('Annual P&L'!C25/AVERAGE(B19,C19),0) -> 0.2749685 | D24: =IFERROR('Annual P&L'!D25/AVERAGE(C19,D19),0) -> 0.24981794 | E24: =IFERROR('Annual P&L'!E25/AVERAGE(D19,E19),0) -> 0.25614619 | F24: =IFERROR('Annual P&L'!F25/AVERAGE(E19,F19),0) -> 0.23426762 | G24: =IFERROR('Annual P&L'!G25/AVERAGE(F19,G19),0) -> 0.21753889 | H24: =IFERROR('Annual P&L'!H25/AVERAGE(G19,H19),0) -> 0.21757174 | I24: =IFERROR('Annual P&L'!I25/AVERAGE(H19,I19),0) -> 0.2331324 | J24: =IFERROR('Annual P&L'!J25/AVERAGE(I19,J19),0) -> 0.23493854 | ... P24: =IFERROR('Annual P&L'!P25/AVERAGE(O19,P19),0) -> 0.2531182

Sheet Quarterly P&L
A1: Quarterly Profit & Loss Statement — Detailed
A2: Only statement maintained quarterly | reported series retained; S&M/G&A and D&A detail allocated using annual model ratios where quarterly disclosure is unavailable
A4: Metric | B4: Q1 FY2016 | C4: Q2 FY2016 | D4: Q3 FY2016 | E4: Q1 FY2017 | F4: Q2 FY2017 | G4: Q3 FY2017 | H4: Q4 FY2017 | I4: Q1 FY2018 | J4: Q2 FY2018 | K4: Q3 FY2018 | L4: Q4 FY2018 | M4: Q1 FY2019 | N4: Q2 FY2019 | O4: Q3 FY2019 | P4: Q4 FY2019 | Q4: Q1 FY2020 | R4: Q2 FY2020 | S4: Q3 FY2020 | T4: Q4 FY2020 | U4: Q1 FY2021 | V4: Q2 FY2021 | W4: Q3 FY2021 | X4: Q4 FY2021 | Y4: Q1 FY2022 | Z4: Q2 FY2022 | AA4: Q3 FY2022 | AB4: Q4 FY2022 | AC4: Q1 FY2023 | AD4: Q2 FY2023 | AE4: Q3 FY2023 | AF4: Q4 FY2023 | AG4: Q1 FY2024 | AH4: Q2 FY2024 | AI4: Q3 FY2024 | AJ4: Q4 FY2024 | AK4: Q1 FY2025 | AL4: Q2 FY2025 | AM4: Q3 FY2025 | AN4: Q4 FY2025 | AO4: Q1 FY2026 | AP4: Q2 FY2026 | AQ4: Q3 FY2026 | AR4: Q4 FY2026 | AS4: Q1 FY2027 | AT4: Q2 FY2027 | AU4: Q3 FY2027 | AV4: Q4 FY2027 | AW4: Q1 FY2028 | AX4: Q2 FY2028 | AY4: Q3 FY2028 | AZ4: Q4 FY2028 | BA4: Q1 FY2029 | BB4: Q2 FY2029 | BC4: Q3 FY2029 | BD4: Q4 FY2029 | BE4: Q1 FY2030 | BF4: Q2 FY2030 | BG4: Q3 FY2030 | BH4: Q4 FY2030
A5: Revenue | B5: 1544.519 | C5: 1566.1 | D5: 1587.2 | E5: 1690.7 | F5: 1722.4 | G5: 1745.3 | H5: 1816.8 | I5: 1884.2 | J5: 1928 | K5: 1988 | L5: 2038 | M5: 2054.5 | N5: 2098.6 | O5: 2201.5 | P5: 2277.8 | Q5: 2363.6 | R5: 2485.6 | S5: 2543.4 | T5: 2543.4 | U5: 2355.5 | V5: 2507 | W5: 2616.6 | X5: 2695.9 | Y5: 2719.6 | Z5: 2790.7 | AA5: 2977.5 | AB5: 2993.1 | AC5: 3024.9 | AD5: 3082.1 | AE5: 3244 | AF5: 3234.6 | AG5: 3200 | AH5: 3224.7 | AI5: 3415 | AJ5: 3429.9 | AK5: 3363.8 | AL5: 3445.2 | AM5: 3533 | AN5: 3498.2 | AO5: 3545 | AP5: 3644 | AQ5: 3793 | AR5: 3682 | AS5: 3650 | AT5: =('Revenue Drivers'!M25-AS5)/3 -> 3883.5614 | AU5: =('Revenue Drivers'!M25-AS5)/3 -> 3883.5614 | AV5: =('Revenue Drivers'!M25-AS5)/3 -> 3883.5614 | AW5: ='Revenue Drivers'!N25/4 -> 3989.093 | AX5: ='Revenue Drivers'!N25/4 -> 3989.093 | AY5: ='Revenue Drivers'!N25/4 -> 3989.093 | AZ5: ='Revenue Drivers'!N25/4 -> 3989.093 | BA5: ='Revenue Drivers'!O25/4 -> 4186.2286 | BB5: ='Revenue Drivers'!O25/4 -> 4186.2286 | BC5: ='Revenue Drivers'!O25/4 -> 4186.2286 | BD5: ='Revenue Drivers'!O25/4 -> 4186.2286 | BE5: ='Revenue Drivers'!P25/4 -> 4408.0288 | BF5: ='Revenue Drivers'!P25/4 -> 4408.0288 | BG5: ='Revenue Drivers'!P25/4 -> 4408.0288 | BH5: ='Revenue Drivers'!P25/4 -> 4408.0288
A6: QoQ growth | B6: =0 -> 0 | C6: =IFERROR(C5/B5-1,0) -> 0.013972635 | D6: =IFERROR(D5/C5-1,0) -> 0.013472958 | E6: =IFERROR(E5/D5-1,0) -> 0.065209173 | F6: =IFERROR(F5/E5-1,0) -> 0.01874963 | G6: =IFERROR(G5/F5-1,0) -> 0.013295402 | H6: =IFERROR(H5/G5-1,0) -> 0.040967169 | I6: =IFERROR(I5/H5-1,0) -> 0.037098195 | J6: =IFERROR(J5/I5-1,0) -> 0.02324594 | ... BH6: =IFERROR(BH5/BG5-1,0) -> 0
A7: YoY growth | B7: =0 -> 0 | C7: =0 -> 0 | D7: =0 -> 0 | E7: =E5/B5-1 -> 0.094645 | F7: =F5/C5-1 -> 0.099802056 | G7: =G5/D5-1 -> 0.099609375 | H7: =0 -> 0 | I7: =I5/E5-1 -> 0.11444964 | J7: 0.11936832 | K7: 0.13905919 | L7: 0.12175253 | M7: 0.090383186 | N7: 0.088485477 | O7: 0.10739437 | P7: 0.11766438 | Q7: 0.15045023 | R7: 0.18440865 | S7: 0.1553032 | T7: 0.11660374 | U7: -0.0034269758 | V7: 0.0086095912 | W7: 0.028780373 | X7: 0.05995911 | Y7: 0.1545744 | Z7: 0.11316314 | AA7: 0.13792708 | AB7: 0.11024148 | AC7: 0.11225916 | AD7: 0.10441825 | AE7: 0.089504618 | AF7: 0.080685577 | AG7: 0.057886211 | AH7: 0.046267156 | AI7: 0.0527127 | AJ7: 0.060378408 | AK7: 0.0511875 | AL7: 0.068378454 | AM7: 0.034553441 | AN7: 0.019913117 | AO7: =AO5/AK5-1 -> 0.05386765 | AP7: 0.057703471 | AQ7: 0.073591848 | AR7: 0.052541307 | AS7: 0.029619182 | AT7: 0.095819826 | AU7: 0.052772857 | AV7: 0.084510441 | AW7: 0.12810397 | AX7: 0.031156231 | AY7: 0.031156231 | AZ7: 0.031156231 | BA7: 0.060222289 | BB7: 0.060222289 | BC7: 0.060222289 | BD7: 0.060222289 | BE7: 0.060222289 | BF7: 0.060222289 | BG7: 0.060222289 | BH7: 0.060222289
A8: Cost of services | B8: 1031.574 | C8: 1024.9845 | D8: 1032.7631 | E8: 1109.6337 | F8: 1144.3291 | G8: 1153.6353 | H8: 1203.9145 | I8: 1249.5678 | J8: 1272.7219 | K8: 1305.6727 | L8: 1323.718 | M8: 1348.0528 | N8: 1354.1131 | O8: 1423.6339 | P8: 1484.4874 | Q8: 1571.4163 | R8: 1614.619 | S8: 1614.2561 | T8: 1570.505 | U8: 1461.5428 | V8: 1520.73 | W8: 1565.8661 | X8: 1657.3156 | Y8: 1687.8921 | Z8: 1753.7297 | AA8: 1907.888 | AB8: 1943.3891 | AC8: 1992.6645 | AD8: 2027.0994 | AE8: 2081.8704 | AF8: 2106.5141 | AG8: 2108.9139 | AH8: 2105.7513 | AI8: 2210.8782 | AJ8: 2282.1069 | AK8: 2250.4861 | AL8: 2289.9562 | AM8: 2323.9315 | AN8: 2336.1814 | AO8: 2404.255 | AP8: 2457.0932 | AQ8: 2533.3325 | AR8: 2499.4171 | AS8: 2488.0462 | AT8: =AT5*(1-'Annual P&L'!M9) -> 2563.1505 | AU8: =AU5*(1-'Annual P&L'!M9) -> 2563.1505 | AV8: =AV5*(1-'Annual P&L'!M9) -> 2563.1505 | AW8: =AW5*(1-'Annual P&L'!N9) -> 2632.8014 | AX8: =AX5*(1-'Annual P&L'!N9) -> 2632.8014 | AY8: =AY5*(1-'Annual P&L'!N9) -> 2632.8014 | AZ8: =AZ5*(1-'Annual P&L'!N9) -> 2632.8014 | BA8: =BA5*(1-'Annual P&L'!O9) -> 2762.9109 | BB8: =BB5*(1-'Annual P&L'!O9) -> 2762.9109 | BC8: =BC5*(1-'Annual P&L'!O9) -> 2762.9109 | BD8: =BD5*(1-'Annual P&L'!O9) -> 2762.9109 | BE8: =BE5*(1-'Annual P&L'!P9) -> 2909.299 | BF8: =BF5*(1-'Annual P&L'!P9) -> 2909.299 | BG8: =BG5*(1-'Annual P&L'!P9) -> 2909.299 | BH8: =BH5*(1-'Annual P&L'!P9) -> 2909.299
A9: Gross profit | B9: =IFERROR(B8/B5,0) -> 0.66789337 | C9: =IFERROR(C8/C5,0) -> 0.65448216 | D9: =IFERROR(D8/D5,0) -> 0.65068237 | E9: =IFERROR(E8/E5,0) -> 0.65631616 | F9: =IFERROR(F8/F5,0) -> 0.66438059 | G9: =IFERROR(G8/G5,0) -> 0.66099543 | H9: =IFERROR(H8/H5,0) -> 0.6626566 | I9: =IFERROR(I8/I5,0) -> 0.66318215 | ... BH9: =IFERROR(BH8/BH5,0) -> 0.66
A10: Gross margin | B10: =IFERROR(B8/B5,0) -> 0.66789337 | C10: 0.34551784 | D10: 0.34931763 | E10: 0.34368384 | F10: 0.33561941 | G10: 0.33900457 | H10: 0.3373434 | I10: 0.33681785 | J10: 0.33987454 | K10: 0.34322299 | L10: 0.35048183 | M10: 0.34385358 | N10: 0.35475405 | O10: 0.35333461 | P10: 0.34828018 | Q10: 0.33515982 | R10: 0.35041077 | S10: 0.36531569 | T10: 0.38251748 | U10: 0.37951909 | V10: 0.39340648 | W10: 0.4015646 | X10: 0.3852459 | Y10: 0.37936018 | Z10: 0.37158073 | AA10: 0.35923156 | AB10: 0.35071027 | AC10: 0.34124616 | AD10: 0.34229928 | AE10: 0.3582397 | AF10: 0.34875592 | AG10: 0.34096441 | AH10: =IFERROR(AH8/AH5,0) -> 0.6530069 | AI10: 0.3525979 | AJ10: 0.33464332 | AK10: 0.3309691 | AL10: 0.3353198 | AM10: 0.34222148 | AN10: 0.33217616 | AO10: 0.32178984 | AP10: 0.32571536 | AQ10: 0.33210321 | AR10: 0.32117948 | AS10: 0.3183435 | AT10: =AT8-AT11 -> 0.34 | AU10: =AU8-AU11 -> 1844.3804 | AV10: =AV8-AV11 -> 1844.3804 | AW10: =AW8-AW11 -> 1891.6371 | AX10: =AX8-AX11 -> 1891.6371 | AY10: =AY8-AY11 -> 1891.6371 | AZ10: =AZ8-AZ11 -> 1891.6371 | BA10: =BA8-BA11 -> 1977.112 | ... BH10: =BH8-BH11 -> 2076.1775
A11: Operating expenses | B11: 213.55147 | C11: 225.6541 | D11: 224.32664 | E11: 223.26905 | F11: 226.83226 | G11: 229.57476 | H11: 241.47628 | I11: 238.84007 | J11: 252.90076 | K11: 272.86883 | L11: 289.94992 | M11: 281.12808 | N11: 315.89854 | O11: 352.68313 | P11: 357.12599 | Q11: 385.80284 | R11: 376.49863 | S11: 412.61002 | T11: 446.8394 | U11: 410.73709 | V11: 445.20351 | W11: 451.96065 | X11: 564.79119 | Y11: 493.01898 | Z11: 493.42224 | AA11: 493.07219 | AB11: 492.86742 | AC11: 507.02914 | AD11: 496.41212 | AE11: 526.45139 | AF11: 545.01661 | AG11: 551.01917 | AH11: 524.23137 | AI11: 526.5482 | AJ11: 543.14673 | AK11: 528.60228 | AL11: 514.8343 | AM11: 520.19849 | AN11: 533.18462 | AO11: 562.8968 | AP11: 559.79926 | AQ11: 563.14942 | AR11: 587.49901 | AS11: 550.47138 | AT11: =AT8-AT11 -> 2563.1505 | AU11: 718.77014 | AV11: 718.77014 | AW11: 741.16431 | AX11: 741.16431 | AY11: 741.16431 | AZ11: 741.16431 | BA11: 785.79892 | BB11: 785.79892 | BC11: 785.79892 | BD11: 785.79892 | BE11: 833.12153 | BF11: 833.12153 | BG11: 833.12153 | BH11: 833.12153
A12: Selling & marketing (modelled allocation) | B12: 205.21534 | C12: 216.84553 | D12: 215.56989 | E12: 214.55358 | F12: 217.9777 | G12: 220.61314 | H12: 232.05008 | I12: 229.51678 | J12: 243.02859 | K12: 262.2172 | L12: 278.63152 | M12: 270.15404 | N12: 303.56721 | O12: 338.91589 | P12: 343.18532 | Q12: 370.74275 | R12: 361.80174 | S12: 396.5035 | T12: 429.3967 | U12: 394.70368 | V12: 427.82467 | W12: 434.31804 | X12: 542.74416 | Y12: 473.77363 | Z12: 474.16115 | AA12: 473.82476 | AB12: 473.62799 | AC12: 487.23689 | AD12: 477.03432 | AE12: 505.90098 | AF12: 523.74149 | AG12: 529.50974 | AH12: 503.76763 | AI12: 505.99401 | AJ12: 521.94461 | AK12: 507.96791 | AL12: 494.73737 | AM12: 499.89217 | AN12: 512.37137 | AO12: 540.92372 | AP12: 537.94709 | AQ12: 541.16647 | AR12: 564.56557 | AS12: 528.98334 | AT12: 2463.0961 | AU12: 690.71243 | AV12: 690.71243 | AW12: 712.23243 | AX12: 712.23243 | AY12: 712.23243 | AZ12: 712.23243 | BA12: 755.12469 | BB12: 755.12469 | BC12: 755.12469 | BD12: 755.12469 | BE12: 800.60003 | BF12: 800.60003 | BG12: 800.60003 | BH12: 800.60003
A13: G&A (modelled allocation) | B13: =B11-B12 -> 8.336135 | C13: =C11-C12 -> 8.8085697 | D13: =D11-D12 -> 8.7567515 | E13: =E11-E12 -> 8.7154676 | F13: =F11-F12 -> 8.8545602 | G13: =G11-G12 -> 8.9616156 | H13: =H11-H12 -> 9.4262 | I13: =I11-I12 -> 9.3232936 | ... BH13: =BH11-BH12 -> 32.521497
A14: D&A | B14: =IFERROR('Annual P&L'!F16*B5/'Annual P&L'!F5,0) -> 62.062225 | C14: =IFERROR('Annual P&L'!F16*C5/'Annual P&L'!F5,0) -> 62.929398 | D14: =IFERROR('Annual P&L'!F16*D5/'Annual P&L'!F5,0) -> 63.777243 | E14: =IFERROR('Annual P&L'!F16*E5/'Annual P&L'!F5,0) -> 67.936105 | F14: =IFERROR('Annual P&L'!F16*F5/'Annual P&L'!F5,0) -> 69.209881 | G14: =IFERROR('Annual P&L'!F16*G5/'Annual P&L'!F5,0) -> 70.130055 | H14: =IFERROR('Annual P&L'!F16*H5/'Annual P&L'!F5,0) -> 73.003084 | I14: =IFERROR('Annual P&L'!F16*I5/'Annual P&L'!F5,0) -> 75.711367 | J14: =IFERROR('Annual P&L'!F16*J5/'Annual P&L'!F5,0) -> 77.471349 | K14: =IFERROR('Annual P&L'!F16*K5/'Annual P&L'!F5,0) -> 79.882283 | L14: =IFERROR('Annual P&L'!F16*L5/'Annual P&L'!F5,0) -> 81.891395 | M14: =IFERROR('Annual P&L'!F16*M5/'Annual P&L'!F5,0) -> 82.554402 | N14: =IFERROR('Annual P&L'!F16*N5/'Annual P&L'!F5,0) -> 84.326438 | O14: =IFERROR('Annual P&L'!F16*O5/'Annual P&L'!F5,0) -> 88.46119 | P14: =IFERROR('Annual P&L'!F16*P5/'Annual P&L'!F5,0) -> 91.527095 | Q14: =IFERROR('Annual P&L'!F16*Q5/'Annual P&L'!F5,0) -> 94.97473 | R14: =IFERROR('Annual P&L'!F16*R5/'Annual P&L'!F5,0) -> 99.876963 | S14: =IFERROR('Annual P&L'!F16*S5/'Annual P&L'!F5,0) -> 102.1995 | T14: =IFERROR('Annual P&L'!F16*T5/'Annual P&L'!F5,0) -> 102.1995 | U14: =IFERROR('Annual P&L'!F16*U5/'Annual P&L'!F5,0) -> 94.649254 | V14: =IFERROR('Annual P&L'!F16*V5/'Annual P&L'!F5,0) -> 100.73686 | W14: =IFERROR('Annual P&L'!F16*W5/'Annual P&L'!F5,0) -> 105.14084 | X14: =IFERROR('Annual P&L'!F16*X5/'Annual P&L'!F5,0) -> 108.32729 | Y14: =IFERROR('Annual P&L'!F16*Y5/'Annual P&L'!F5,0) -> 109.27961 | Z14: =IFERROR('Annual P&L'!F16*Z5/'Annual P&L'!F5,0) -> 112.13656 | AA14: =IFERROR('Annual P&L'!F16*AA5/'Annual P&L'!F5,0) -> 119.6426 | AB14: =IFERROR('Annual P&L'!F16*AB5/'Annual P&L'!F5,0) -> 120.26945 | AC14: =IFERROR('Annual P&L'!F16*AC5/'Annual P&L'!F5,0) -> 121.54724 | AD14: =IFERROR('Annual P&L'!F16*AD5/'Annual P&L'!F5,0) -> 123.84567 | AE14: =IFERROR('Annual P&L'!F16*AE5/'Annual P&L'!F5,0) -> 130.35117 | AF14: =IFERROR('Annual P&L'!F16*AF5/'Annual P&L'!F5,0) -> 129.97346 | AG14: =IFERROR('Annual P&L'!F16*AG5/'Annual P&L'!F5,0) -> 128.58315 | AH14: =IFERROR('Annual P&L'!F16*AH5/'Annual P&L'!F5,0) -> 129.57565 | AI14: =IFERROR('Annual P&L'!F16*AI5/'Annual P&L'!F5,0) -> 137.22233 | AJ14: =IFERROR('Annual P&L'!F16*AJ5/'Annual P&L'!F5,0) -> 137.82105 | AK14: =IFERROR('Annual P&L'!F16*AK5/'Annual P&L'!F5,0) -> 135.165 | AL14: =IFERROR('Annual P&L'!F16*AL5/'Annual P&L'!F5,0) -> 138.43584 | AM14: =IFERROR('Annual P&L'!F16*AM5/'Annual P&L'!F5,0) -> 141.96384 | AN14: =IFERROR('Annual P&L'!F16*AN5/'Annual P&L'!F5,0) -> 140.56549 | AO14: =IFERROR('Annual P&L'!F16*AO5/'Annual P&L'!F5,0) -> 142.44602 | AP14: =IFERROR('Annual P&L'!F16*AP5/'Annual P&L'!F5,0) -> 146.42406 | AQ14: =IFERROR('Annual P&L'!F16*AQ5/'Annual P&L'!F5,0) -> 152.41122 | AR14: =IFERROR('Annual P&L'!F16*AR5/'Annual P&L'!F5,0) -> 147.95099 | AS14: =IFERROR('Annual P&L'!F16*AS5/'Annual P&L'!F5,0) -> 146.66516 | AT14: =IFERROR('Annual P&L'!F16*AT5/'Annual P&L'!F5,0) -> 156.05018 | AU14: =IFERROR('Annual P&L'!F16*AU5/'Annual P&L'!F5,0) -> 156.05018 | AV14: =IFERROR('Annual P&L'!F16*AV5/'Annual P&L'!F5,0) -> 156.05018 | AW14: =IFERROR('Annual P&L'!F16*AW5/'Annual P&L'!F5,0) -> 160.29067 | AX14: =IFERROR('Annual P&L'!F16*AX5/'Annual P&L'!F5,0) -> 160.29067 | AY14: =IFERROR('Annual P&L'!F16*AY5/'Annual P&L'!F5,0) -> 160.29067 | AZ14: =IFERROR('Annual P&L'!F16*AZ5/'Annual P&L'!F5,0) -> 160.29067 | BA14: =IFERROR('Annual P&L'!F16*BA5/'Annual P&L'!F5,0) -> 168.21202 | BB14: =IFERROR('Annual P&L'!F16*BB5/'Annual P&L'!F5,0) -> 168.21202 | BC14: =IFERROR('Annual P&L'!F16*BC5/'Annual P&L'!F5,0) -> 168.21202 | BD14: =IFERROR('Annual P&L'!F16*BD5/'Annual P&L'!F5,0) -> 168.21202 | BE14: =IFERROR('Annual P&L'!F16*BE5/'Annual P&L'!F5,0) -> 177.12445 | BF14: =IFERROR('Annual P&L'!F16*BF5/'Annual P&L'!F5,0) -> 177.12445 | BG14: =IFERROR('Annual P&L'!F16*BG5/'Annual P&L'!F5,0) -> 177.12445 | BH14: =IFERROR('Annual P&L'!F16*BH5/'Annual P&L'!F5,0) -> 177.12445
A15: EBITDA | B15: =B17+B14 -> 361.45576 | C15: =C17+C14 -> 378.39079 | D15: =D17+D14 -> 393.88754 | E15: =E17+E14 -> 425.73333 | F15: =F17+F14 -> 420.4485 | G15: =G17+G14 -> 432.21997 | H15: =H17+H14 -> 444.41229 | I15: =I17+I14 -> 471.50348 | ... BH15: =BH17+BH14 -> 882.40907
A16: EBITDA margin | B16: =IFERROR(B15/B5,0) -> 0.2340248 | C16: =IFERROR(C15/C5,0) -> 0.24161343 | D16: =IFERROR(D15/D5,0) -> 0.24816504 | E16: =IFERROR(E15/E5,0) -> 0.25180891 | F16: =IFERROR(F15/F5,0) -> 0.24410619 | G16: =IFERROR(G15/G5,0) -> 0.24764795 | H16: =IFERROR(H15/H5,0) -> 0.24461267 | I16: =IFERROR(I15/I5,0) -> 0.25024068 | ... BH16: =IFERROR(BH15/BH5,0) -> 0.20018223
A17: EBIT | B17: =IFERROR(B16/B14,0) -> 299.39353 | C17: =IFERROR(C16/C14,0) -> 315.4614 | D17: =IFERROR(D16/D14,0) -> 330.1103 | E17: =IFERROR(E16/E14,0) -> 357.79722 | F17: =IFERROR(F16/F14,0) -> 351.23861 | G17: =IFERROR(G16/G14,0) -> 362.08992 | H17: =IFERROR(H16/H14,0) -> 371.40921 | I17: =IFERROR(I16/I14,0) -> 395.79211 | ... BH17: =IFERROR(BH16/BH14,0) -> 705.28462
A18: EBIT margin | B18: =IFERROR(B11/B5,0) -> 0.13826406 | C18: 0.2014312 | D18: 0.2079828 | E18: 0.21162668 | F18: 0.20392395 | G18: 0.20746572 | H18: 0.20443043 | I18: 0.21005844 | J18: 0.20870195 | K18: 0.20596502 | L18: 0.20821003 | M18: 0.2070183 | N18: 0.20422583 | O18: 0.19313332 | P18: 0.19149468 | Q18: 0.17193303 | R18: 0.19893884 | S18: 0.20308795 | T18: 0.20683163 | U18: 0.20514545 | V18: 0.21582231 | W18: 0.22883639 | X18: 0.17574585 | Y18: 0.19807654 | Z18: 0.19477124 | AA18: 0.19363217 | AB18: 0.1860424 | AC18: 0.17362768 | AD18: 0.18123633 | AE18: 0.19595506 | AF18: 0.18026009 | AG18: 0.16877092 | AH18: =IFERROR(AH11/AH5,0) -> 0.16256749 | AI18: 0.19841102 | AJ18: 0.17628689 | AK18: 0.17382471 | AL18: 0.18588455 | AM18: 0.1949816 | AN18: 0.17975931 | AO18: 0.16300372 | AP18: 0.17209317 | AQ18: 0.1836325 | AR18: 0.16161973 | AS18: 0.16752943 | AT18: =AT14-AT16 -> 0.16 | AU18: =AU14-AU16 -> 0.16 | AV18: =AV14-AV16 -> 0.16 | AW18: =AW14-AW16 -> 0.16 | AX18: =AX14-AX16 -> 0.16 | AY18: =AY14-AY16 -> 0.16 | AZ18: =AZ14-AZ16 -> 0.16 | BA18: =BA14-BA16 -> 0.16 | ... BH18: =BH14-BH16 -> 0.16
A19: Foreign exchange gain / (loss) | B19: =0 -> 0 | C19: =0 -> 0 | D19: =0 -> 0 | E19: =0 -> 0 | F19: =0 -> 0 | G19: =0 -> 0 | H19: =0 -> 0 | I19: =0 -> 0 | ... BH19: =0 -> 0
A20: Other income | B20: =44.5394701594533+B21 -> 44.53947 | C20: =52.0973213422299+C21 -> 52.097321 | D20: =29.3761076836791+D21 -> 29.376108 | E20: =27.8899876499647+E21 -> 27.889988 | F20: =30.5034812049657+F21 -> 30.503481 | G20: =27.773522938886+G21 -> 27.773523 | H20: =25.1726209242512+H21 -> 25.172621 | I20: =25.1247345460531+I21 -> 25.124735 | J20: =23.879041338266+J21 -> 23.879041 | K20: =20.9540911930043+K21 -> 20.954091 | L20: =18.4021549434706+L21 -> 18.402155 | M20: =22.6501297016861+M21 -> 22.65013 | N20: =25.8423928403203+N21 -> 25.842393 | O20: =22.296866042423+O21 -> 22.296866 | P20: =18.3762476547842+P21 -> 18.376248 | Q20: =15.6853820395738+Q21 -> 15.685382 | R20: =0.992651757188498+R21 -> 0.99265176 | S20: =7.57339950372208+S21 -> 7.5733995 | T20: =3.14675632060247+T21 -> 3.1467563 | U20: =27.0656073090073+U21 -> 27.065607 | V20: =18.7411530601269+V21 -> 18.741153 | W20: =16.809574137395+W21 -> 16.809574 | X20: =19.6270084512778+X21 -> 19.627008 | Y20: =16.939904325294+Y21 -> 16.939904 | Z20: =10.4034809973372+Z21 -> 10.403481 | AA20: =17.3335273834579+AA21 -> 17.333527 | AB20: =15.4973093773509+AB21 -> 15.497309 | AC20: =33.9050758608932+AC21 -> 33.905076 | AD20: =13.8585878635663+AD21 -> 13.858588 | AE20: =17.1312359550561+AE21 -> 17.131236 | AF20: =48.2649101706382+AF21 -> 48.26491 | AG20: =31.3964101003955+AG21 -> 31.39641 | AH20: =25.2685325434912+AH21 -> 25.268533 | AI20: =27.6119665330802+AI21 -> 27.611967 | AJ20: =29.4861398645566+AJ21 -> 29.48614 | AK20: =99.6299604376804+AK21 -> 99.62996 | AL20: =38.4365047467257+AL21 -> 38.436505 | AM20: =35.9328203412512+AM21 -> 35.93282 | AN20: =34.4661641208754+AN21 -> 34.466164 | AO20: =28.2674882203697+AO21 -> 28.267488 | AP20: =23.3867635088598+AP21 -> 23.386764 | AQ20: =27.4351972130373+AQ21 -> 27.435197 | AR20: =22.7544804449545+AR21 -> 22.75448 | AS20: =33.249949391249+AS21 -> 33.249949 | AT20: =AT14-AT11+AT21 -> -2407.1004 | AU20: =47.9180093415809+AU21 -> 47.918009 | AV20: =47.9180093415809+AV21 -> 47.918009 | AW20: =49.4109539000793+AW21 -> 49.410954 | AX20: =49.4109539000793+AX21 -> 49.410954 | AY20: =49.4109539000793+AY21 -> 49.410954 | AZ20: =49.4109539000793+AZ21 -> 49.410954 | BA20: =52.386594622914+BA21 -> 52.386595 | BB20: =52.386594622914+BB21 -> 52.386595 | BC20: =52.386594622914+BC21 -> 52.386595 | BD20: =52.386594622914+BD21 -> 52.386595 | BE20: =55.5414352399521+BE21 -> 55.541435 | BF20: =55.5414352399521+BF21 -> 55.541435 | BG20: =55.5414352399521+BG21 -> 55.541435 | BH20: =55.5414352399521+BH21 -> 55.541435
