Workbook

Sheet DCF
C2: Persistent Systems DCF including Nagarro
C4: FY26–FY30 DCF. INR million except per-share values. Terminal value at 31 March 2030.
C6: INR WACC (derived) | D6: =Assumptions!D79 -> 0.11330614 | H6: DCF fair value / share | K6: =D49 -> 5952.893
C7: Terminal growth (Gordon method) | D7: 0.0825 | H7: Standalone / share | K7: =D24 -> 5416.991
C8: Reference price (27 Oct 2026) | D8: 4877.2 | H8: Nagarro impact / share | K8: =D44 -> 535.90206
H9: Upside / (downside) | K9: =D50 -> 0.22055545
C11: Persistent standalone
C12: PV of FY27E–FY30E FCFF | D12: =SUM(Forecast!D25:H25) -> 65655.715
C13: Terminal revenue (FY31) | D13: =Forecast!H12*(1+$D$7) -> 319325.05
C14: Terminal NOPAT | D14: =D13*Assumptions!H23*(1-Assumptions!H24) -> 41911.412
C15: Terminal D&A less capex | D15: =D13*(Assumptions!H25-Assumptions!H26) -> -957.97514
C16: Terminal incremental NWC | D16: =(D13-Forecast!H12)*Assumptions!H27 -> 4867.3102
C17: Terminal FCFF (FY31) | D17: =D14+D15-D16 -> 36086.127
C18: Terminal enterprise value at FY30 | D18: =IF(D6>D7,D17/(D6-D7),NA()) -> 1171394
C19: PV of terminal enterprise value | D19: =D18*Forecast!H24 -> 762508.27
C20: Persistent enterprise value | D20: =D12+D19 -> 828163.99
C21: Cash + investments + QIP gross proceeds | D21: =Sources!D8+SUM(Sources!D9:D10)*Assumptions!D14+Assumptions!D60 -> 72495.675
C22: Reported borrowings | D22: =Sources!D11 -> 0
C23: Persistent standalone equity value | D23: =D20+D21-D22 -> 900659.66
C24: Persistent value / share at group WACC | D24: =D23/Assumptions!D11 -> 5416.991
C27: Nagarro transaction
C28: PV of post-closing FCFF (100%) | D28: =SUM(Forecast!D46:H46) -> 14961.366
C29: Terminal revenue (100%) | D29: =Forecast!H31*(1+$D$7)*Assumptions!D8 -> 139776.03
C30: Terminal NOPAT (100%) | D30: =D29*(Assumptions!H31+Assumptions!H38)*(1-Assumptions!H32) -> 11573.456
C31: Terminal D&A less capex (100%) | D31: =D29*(Assumptions!H33-Assumptions!H34) -> -419.3281
C32: Terminal incremental NWC (100%) | D32: =(D29-Forecast!H31*Assumptions!D8)*Assumptions!H35 -> 2130.5354
C33: Terminal FCFF (100%) | D33: =D30+D31-D32 -> 9023.5921
C34: PV of terminal enterprise value (100%) | D34: =IF(D6>D7,D33/(D6-D7)*Forecast!H24,NA()) -> 190670.6
C35: Nagarro enterprise value (100%) | D35: =D28+D34 -> 205631.97
C36: Closing net debt proxy (EUR m) | D36: =SUM(Sources!D16:D18)-Sources!D15 -> 190.879 | F36: June 2026 balances held constant to assumed closing. Lease debt excluded.
C37: PV of closing net debt (INR m) | D37: =D36*Assumptions!D10*Assumptions!D8/(1+$D$6)^((Assumptions!D7-Assumptions!D6)/365) -> 17659.596
C38: Nagarro equity value (100%) | D38: =D35-D37 -> 187972.37
C39: Minority equity value excluded | D39: =D38*(1-Assumptions!D9) -> 11203.153 | F39: 94.04% acquired; remaining minority retained. No squeeze-out cost assumed.
C40: Acquired equity value | D40: =D38-D39 -> 176769.22
C41: Cash consideration at closing | D41: =Sources!D19*Sources!D20*Assumptions!D9*Assumptions!D10*Assumptions!D8 -> 97100.323
C42: PV of consideration and additional fees | D42: =(D41+Assumptions!D13*Assumptions!D8)/(1+$D$6)^((Assumptions!D7-Assumptions!D6)/365) -> 87667.102 | F42: Full purchase price deducted once, independent of cash/debt funding mix.
C43: Net acquisition value to Persistent | D43: =D40-D42 -> 89102.119
C44: Acquisition impact per Persistent share | D44: =D43/Assumptions!D11 -> 535.90206
C47: Persistent including Nagarro
C48: Equity value including transaction | D48: =D23+D43 -> 989761.78
...

Sheet Assumptions
C2: Assumptions
C4: Blue / yellow cells are editable analyst assumptions. Forecasts are not company guidance.
C6: Discounting anchor | D6: =DATE(2026-D17,3,31) -> 46112 | F6: Derived from FY26 discount period. Uses updated inputs, not a historical valuation
C7: Expected Nagarro closing | D7: 46477 | F7: Assumed last day of announced Q1 CY27 closing window
C8: Nagarro included (1 / 0) | D8: 1 | F8: 1 includes transaction, cash flows and consideration together
C9: Ownership acquired | D9: =Sources!D21 -> 0.9404 | F9: Secured 94.04%; no squeeze-out assumed
C10: EUR / INR | D10: 103 | F10: Analyst FX assumption, held flat. Not a live FX quote
C11: Diluted shares (million) | D11: =Sources!D12+Sources!D43-Sources!D44 -> 166.26568 | F11: Q2 diluted proxy plus issued shares since September, including QIP
C12: Acquisition debt funding share | D12: =IF(DCF!D41=0,0,D64/DCF!D41) -> 0.78079328 | F12: Derived planned new debt / consideration; links to financing inputs in the WACC build.
C13: Additional transaction fees (INR m) | D13: 500 | F13: Future incremental cost assumption; reported prior costs are sunk
C14: Investment value / book | D14: 1 | F14: Book value proxy for current and non-current investments
C15: Persistent normalized opening NWC | D15: 0.2 | F15: 20% of FY25 revenue. Analyst proxy, not audited NWC
C16: Nagarro normalized opening NWC | D16: 0.2 | F16: 20% of closing annualized revenue. Acquired NWC is in purchase price
C17: FY26 discount period (0 / 1) | D17: 0 | F17: 0 = FY26 base year; FY27–FY30 discounted at periods 1–4. 1 includes FY26 as period 1
C19: Forecast assumptions
D20: FY26A / norm | E20: FY27E | F20: FY28E | G20: FY29E | H20: FY30E
C22: Revenue growth / FY27 Q2 uplift | D22: =Sources!D23/Sources!D24-1 -> 0.23534623 | E22: 0.04 | F22: 0.17 | G22: 0.15 | H22: 0.13
C23: Persistent EBIT margin after rent | D23: =(Sources!D25+Sources!D27-Sources!D28-Sources!D29)/Sources!D23 -> 0.15438776 | E23: 0.15 | F23: 0.16 | G23: 0.17 | H23: 0.175
C24: Persistent cash tax rate | D24: 0.25 | E24: 0.25 | F24: 0.25 | G24: 0.25 | H24: 0.25
C25: Persistent non-lease D&A / sales | D25: =(Sources!D26-Sources!D27)/Sources!D23 -> 0.01692856 | E25: 0.016 | F25: 0.016 | G25: 0.016 | H25: 0.016
C26: Persistent cash capex / sales | D26: =Sources!D30/Sources!D23 -> 0.014142572 | E26: 0.019 | F26: 0.019 | G26: 0.019 | H26: 0.019
C27: Persistent NWC / annual sales | D27: 0.2 | E27: 0.2 | F27: 0.2 | G27: 0.2 | H27: 0.2
C30: Nagarro EUR revenue growth | D30: 0 | E30: 0.03 | F30: 0.06 | G30: 0.07 | H30: 0.08
C31: Nagarro EBIT margin after rent | D31: 0 | E31: 0.09 | F31: 0.1 | G31: 0.11 | H31: 0.115
C32: Nagarro cash tax rate | D32: 0.28 | E32: 0.28 | F32: 0.28 | G32: 0.28 | H32: 0.28
C33: Nagarro non-lease D&A / sales | D33: 0.015 | E33: 0.015 | F33: 0.015 | G33: 0.015 | H33: 0.015
C34: Nagarro cash capex / sales | D34: 0.018 | E34: 0.018 | F34: 0.018 | G34: 0.018 | H34: 0.018
C35: Nagarro NWC / annual sales | D35: 0.2 | E35: 0.2 | F35: 0.2 | G35: 0.2 | H35: 0.2
C38: Synergy EBIT / Nagarro sales | D38: 0 | E38: 0 | F38: 0 | G38: 0 | H38: 0
C39: Integration cash costs (INR m) | D39: 0 | E39: 0 | F39: 1000 | G39: 500 | H39: 0
C42: FY26 uses reported revenue, EBIT after cash rent, non-lease D&A and capex; tax and NWC are normalized.
C43: Nagarro FY27 run-rate grows H1 CY26 annualized revenue for 9 months to March 2027.
C44: Margins are analyst estimates after cash rent. Non-lease D&A is added back; leases stay outside net debt.
C45: Synergies default to zero. Integration costs receive no tax shield. Calendar-year Nagarro is mapped to March fiscal years.
C46: Nagarro cash, debt and outstanding shares at June 2026 are held constant as closing proxies.
C47: FY27 revenue = annualized Q2 FY27 revenue x (1 + 4% uplift). FY28–FY30 use annual revenue growth.
C50: INR WACC derivation (October 2026 inputs)
C51: India 10Y government yield | D51: =Sources!D31 -> 0.0749
C52: Less: sovereign default spread | D52: =Sources!D32 -> 0.0187
C53: Default-free INR risk-free rate | D53: =D51 -> 0.0749 | F53: Government yield less default spread avoids embedding sovereign default risk twice.
...

Sheet Forecast
C2: Forecast
C4: FY26–FY30 only. INR million. FY26 reported operating inputs with normalized tax and NWC.
C6: Fiscal year end | D6: 46112 | E6: 46477 | F6: 46843 | G6: 47208 | H6: 47573
C7: Fiscal year start | D7: =DATE(2025,3,31) -> 45747 | E7: =D6 -> 46112 | F7: =E6 -> 46477 | G7: =F6 -> 46843 | H7: =G6 -> 47208
C8: Persistent operating years | D8: =MAX(0,D6-D7)/(D6-DATE(YEAR(D6)-1,3,31)) -> 1 | E8: =MAX(0,E6-E7)/(E6-DATE(YEAR(E6)-1,3,31)) -> 1 | F8: =MAX(0,F6-F7)/(F6-DATE(YEAR(F6)-1,3,31)) -> 1 | G8: =MAX(0,G6-G7)/(G6-DATE(YEAR(G6)-1,3,31)) -> 1 | H8: =MAX(0,H6-H7)/(H6-DATE(YEAR(H6)-1,3,31)) -> 1
C9: Discount period | D9: =0+Assumptions!$D$17 -> 0 | E9: =1+Assumptions!$D$17 -> 1 | F9: =2+Assumptions!$D$17 -> 2 | G9: =3+Assumptions!$D$17 -> 3 | H9: =4+Assumptions!$D$17 -> 4
C11: Persistent standalone
C12: Annual revenue | D12: =Sources!D23 -> 147484.49 | E12: =Sources!D6*4*(1+Assumptions!E22) -> 194018.41 | F12: =E12*(1+Assumptions!F22) -> 227001.54 | G12: =F12*(1+Assumptions!G22) -> 261051.77 | H12: =G12*(1+Assumptions!H22) -> 294988.5
C13: Revenue used for cash flows | D13: =D12*D8 -> 147484.49 | E13: =E12*E8 -> 194018.41 | F13: =F12*F8 -> 227001.54 | G13: =G12*G8 -> 261051.77 | H13: =H12*H8 -> 294988.5
C14: EBIT margin after cash rent | D14: =Assumptions!D23 -> 0.15438776 | E14: =Assumptions!E23 -> 0.15 | F14: =Assumptions!F23 -> 0.16 | G14: =Assumptions!G23 -> 0.17 | H14: =Assumptions!H23 -> 0.175
C15: Operating EBIT | D15: =D13*D14 -> 22769.8 | E15: =E13*E14 -> 29102.761 | F15: =F13*F14 -> 36320.246 | G15: =G13*G14 -> 44378.8 | H15: =H13*H14 -> 51622.987
C16: Unlevered normalized cash tax | D16: =D15*Assumptions!D24 -> 5692.45 | E16: =E15*Assumptions!E24 -> 7275.6902 | F16: =F15*Assumptions!F24 -> 9080.0614 | G16: =G15*Assumptions!G24 -> 11094.7 | H16: =H15*Assumptions!H24 -> 12905.747
C17: NOPAT | D17: =D15-D16 -> 17077.35 | E17: =E15-E16 -> 21827.071 | F17: =F15-F16 -> 27240.184 | G17: =G15-G16 -> 33284.1 | H17: =H15-H16 -> 38717.24
C18: Non-lease D&A | D18: =D13*Assumptions!D25 -> 2496.7 | E18: =E13*Assumptions!E25 -> 3104.2945 | F18: =F13*Assumptions!F25 -> 3632.0246 | G18: =G13*Assumptions!G25 -> 4176.8283 | H18: =H13*Assumptions!H25 -> 4719.8159
C19: Cash capex | D19: =D13*Assumptions!D26 -> 2085.81 | E19: =E13*Assumptions!E26 -> 3686.3497 | F19: =F13*Assumptions!F26 -> 4313.0292 | G19: =G13*Assumptions!G26 -> 4959.9836 | H19: =H13*Assumptions!H26 -> 5604.7814
C20: Opening normalized NWC | D20: =Sources!D24*Assumptions!D15 -> 23877.434 | E20: =D21 -> 29496.898 | F20: =E21 -> 38803.681 | G20: =F21 -> 45400.307 | H20: =G21 -> 52210.353
C21: Closing normalized NWC | D21: =D12*Assumptions!D27 -> 29496.898 | E21: =E12*Assumptions!E27 -> 38803.681 | F21: =F12*Assumptions!F27 -> 45400.307 | G21: =G12*Assumptions!G27 -> 52210.353 | H21: =H12*Assumptions!H27 -> 58997.699
C22: Increase / (release) in NWC | D22: =D21-D20 -> 5619.464 | E22: =E21-E20 -> 9306.7833 | F22: =F21-F20 -> 6596.6258 | G22: =G21-G20 -> 6810.0461 | H22: =H21-H20 -> 6787.3459
C23: Persistent FCFF | D23: =D17+D18-D19-D22 -> 11868.776 | E23: =E17+E18-E19-E22 -> 11938.232 | F23: =F17+F18-F19-F22 -> 19962.554 | G23: =G17+G18-G19-G22 -> 25690.899 | H23: =H17+H18-H19-H22 -> 31044.929
C24: Discount factor | D24: =1/(1+DCF!$D$6)^D9 -> 1 | E24: =1/(1+DCF!$D$6)^E9 -> 0.89822553 | F24: =1/(1+DCF!$D$6)^F9 -> 0.80680911 | G24: =1/(1+DCF!$D$6)^G9 -> 0.72469654 | H24: =1/(1+DCF!$D$6)^H9 -> 0.65094093
C25: Present value of FCFF | D25: =IF(D9=0,0,D23*D24) -> 0 | E25: =IF(E9=0,0,E23*E24) -> 10723.225 | F25: =IF(F9=0,0,F23*F24) -> 16105.97 | G25: =IF(G9=0,0,G23*G24) -> 18618.105 | H25: =IF(H9=0,0,H23*H24) -> 20208.415
C28: Nagarro including integration
C29: Annual revenue run-rate (EUR m) | D29: =0 -> 0 | E29: =Sources!D14*2*(1+Assumptions!E30)^0.75 -> 1023.4207 | F29: =E29*(1+Assumptions!F30) -> 1084.8259 | G29: =F29*(1+Assumptions!G30) -> 1160.7637 | H29: =G29*(1+Assumptions!H30) -> 1253.6248
C30: INR per EUR | D30: =Assumptions!$D$10 -> 103 | E30: =Assumptions!$D$10 -> 103 | F30: =Assumptions!$D$10 -> 103 | G30: =Assumptions!$D$10 -> 103 | H30: =Assumptions!$D$10 -> 103
C31: Annual revenue run-rate (INR m) | D31: =D29*D30 -> 0 | E31: =E29*E30 -> 105412.33 | F31: =F29*F30 -> 111737.07 | G31: =G29*G30 -> 119558.66 | H31: =H29*H30 -> 129123.36
C32: Post-closing operating years | D32: =Assumptions!$D$8*MAX(0,D6-MAX(D7,Assumptions!$D$7))/(D6-DATE(YEAR(D6)-1,3,31)) -> 0 | E32: =Assumptions!$D$8*MAX(0,E6-MAX(E7,Assumptions!$D$7))/(E6-DATE(YEAR(E6)-1,3,31)) -> 0 | F32: =Assumptions!$D$8*MAX(0,F6-MAX(F7,Assumptions!$D$7))/(F6-DATE(YEAR(F6)-1,3,31)) -> 1 | G32: =Assumptions!$D$8*MAX(0,G6-MAX(G7,Assumptions!$D$7))/(G6-DATE(YEAR(G6)-1,3,31)) -> 1 | H32: =Assumptions!$D$8*MAX(0,H6-MAX(H7,Assumptions!$D$7))/(H6-DATE(YEAR(H6)-1,3,31)) -> 1
C33: Post-closing revenue | D33: =D31*D32 -> 0 | E33: =E31*E32 -> 0 | F33: =F31*F32 -> 111737.07 | G33: =G31*G32 -> 119558.66 | H33: =H31*H32 -> 129123.36
C34: EBIT margin after cash rent | D34: =Assumptions!D31 -> 0 | E34: =Assumptions!E31 -> 0.09 | F34: =Assumptions!F31 -> 0.1 | G34: =Assumptions!G31 -> 0.11 | H34: =Assumptions!H31 -> 0.115
C35: Operating EBIT | D35: =D33*D34 -> 0 | E35: =E33*E34 -> 0 | F35: =F33*F34 -> 11173.707 | G35: =G33*G34 -> 13151.453 | H35: =H33*H34 -> 14849.186
C36: Synergy EBIT | D36: =D33*Assumptions!D38 -> 0 | E36: =E33*Assumptions!E38 -> 0 | F36: =F33*Assumptions!F38 -> 0 | G36: =G33*Assumptions!G38 -> 0 | H36: =H33*Assumptions!H38 -> 0
C37: NOPAT including synergies | D37: =(D35+D36)*(1-Assumptions!D32) -> 0 | E37: =(E35+E36)*(1-Assumptions!E32) -> 0 | F37: =(F35+F36)*(1-Assumptions!F32) -> 8045.069 | G37: =(G35+G36)*(1-Assumptions!G32) -> 9469.0462 | H37: =(H35+H36)*(1-Assumptions!H32) -> 10691.414
C38: Non-lease D&A | D38: =D33*Assumptions!D33 -> 0 | E38: =E33*Assumptions!E33 -> 0 | F38: =F33*Assumptions!F33 -> 1676.056 | G38: =G33*Assumptions!G33 -> 1793.38 | H38: =H33*Assumptions!H33 -> 1936.8504
C39: Cash capex | D39: =D33*Assumptions!D34 -> 0 | E39: =E33*Assumptions!E34 -> 0 | F39: =F33*Assumptions!F34 -> 2011.2672 | G39: =G33*Assumptions!G34 -> 2152.056 | H39: =H33*Assumptions!H34 -> 2324.2204
C40: Prior NWC / sales assumption | D40: =Assumptions!D16 -> 0.2 | E40: =Assumptions!D35 -> 0.2 | F40: =Assumptions!E35 -> 0.2 | G40: =Assumptions!F35 -> 0.2 | H40: =Assumptions!G35 -> 0.2
C41: Prior annualized NWC proxy | D41: =D31/(1+Assumptions!D30)*D40 -> 0 | E41: =E31/(1+Assumptions!E30)*E40 -> 20468.414 | F41: =F31/(1+Assumptions!F30)*F40 -> 21082.466 | G41: =G31/(1+Assumptions!G30)*G40 -> 22347.414 | H41: =H31/(1+Assumptions!H30)*H40 -> 23911.733
C42: Current annualized NWC proxy | D42: =D31*Assumptions!D35 -> 0 | E42: =E31*Assumptions!E35 -> 21082.466 | F42: =F31*Assumptions!F35 -> 22347.414 | G42: =G31*Assumptions!G35 -> 23911.733 | H42: =H31*Assumptions!H35 -> 25824.671
C43: Incremental NWC investment | D43: =(D42-D41)*D32 -> 0 | E43: =(E42-E41)*E32 -> 0 | F43: =(F42-F41)*F32 -> 1264.948 | G43: =(G42-G41)*G32 -> 1564.319 | H43: =(H42-H41)*H32 -> 1912.9386
C44: Integration cash cost | D44: =Assumptions!D39*IF(D32>0,1,0) -> 0 | E44: =Assumptions!E39*IF(E32>0,1,0) -> 0 | F44: =Assumptions!F39*IF(F32>0,1,0) -> 1000 | G44: =Assumptions!G39*IF(G32>0,1,0) -> 500 | H44: =Assumptions!H39*IF(H32>0,1,0) -> 0
C45: Nagarro FCFF (100%) | D45: =D37+D38-D39-D43-D44 -> 0 | E45: =E37+E38-E39-E43-E44 -> 0 | F45: =F37+F38-F39-F43-F44 -> 5444.9098 | G45: =G37+G38-G39-G43-G44 -> 7046.0512 | H45: =H37+H38-H39-H43-H44 -> 8391.1053
C46: Present value of FCFF | D46: =D45*D24 -> 0 | E46: =E45*E24 -> 0 | F46: =F45*F24 -> 4393.0028 | G46: =G45*G24 -> 5106.2489 | H46: =H45*H24 -> 5462.1139
...

Sheet Sources
C2: Sources
C5: Reported input | D5: Value | E5: Units | F5: Period | G5: Location / basis | H5: Source URL
C6: Persistent Q2 revenue | D6: 46639.04 | E6: INR m | F6: 30-Sep-26 | G6: Consolidated FS, p6 | H6: https://www.persistent.com/wp-content/uploads/2026/10/Consolidated-Financial-Statements-Q2FY27.pdf
C7: Persistent H1 revenue | D7: 89671.31 | E7: INR m | F7: 30-Sep-26 | G7: Consolidated FS, p6 | H7: https://www.persistent.com/wp-content/uploads/2026/10/Consolidated-Financial-Statements-Q2FY27.pdf
C8: Persistent cash | D8: 16311.85 | E8: INR m | F8: 30-Sep-26 | G8: Consolidated FS, p5 | H8: https://www.persistent.com/wp-content/uploads/2026/10/Consolidated-Financial-Statements-Q2FY27.pdf
C9: Persistent current investments | D9: 6226.39 | E9: INR m | F9: 30-Sep-26 | G9: Consolidated FS, p5 | H9: https://www.persistent.com/wp-content/uploads/2026/10/Consolidated-Financial-Statements-Q2FY27.pdf
C10: Persistent non-current investments | D10: 7311.34 | E10: INR m | F10: 30-Sep-26 | G10: Consolidated FS, p5. Book value proxy | H10: https://www.persistent.com/wp-content/uploads/2026/10/Consolidated-Financial-Statements-Q2FY27.pdf
C11: Persistent borrowings | D11: 0 | E11: INR m | F11: 30-Sep-26 | G11: No borrowings line on reported balance sheet | H11: https://www.persistent.com/wp-content/uploads/2026/10/Consolidated-Financial-Statements-Q2FY27.pdf
C12: Persistent diluted shares | D12: 158.18169 | E12: million | F12: Q2 FY27 | G12: Consolidated FS, p51. Weighted diluted proxy | H12: https://www.persistent.com/wp-content/uploads/2026/10/Consolidated-Financial-Statements-Q2FY27.pdf
C13: Persistent operating EBIT | D13: 6977.2 | E13: INR m | F13: Q2 FY27 | G13: Presentation, p38. Before acquisition exceptional expense | H13: https://www.persistent.com/wp-content/uploads/2026/10/analyst-presentation-and-factsheet-q2fy27.pdf
C14: Nagarro H1 revenue | D14: 500.491 | E14: EUR m | F14: 30-Jun-26 | G14: H1 report, p3. Converted from EUR thousands | H14: https://www.nagarro.com/hubfs/Investors/InvestorDocuments/H1-Q2-2026/Nagarro%20SE_H1%202026_EN.pdf?hsLang=en
C15: Nagarro cash | D15: 131.264 | E15: EUR m | F15: 30-Jun-26 | G15: H1 report, p57 | H15: https://www.nagarro.com/hubfs/Investors/InvestorDocuments/H1-Q2-2026/Nagarro%20SE_H1%202026_EN.pdf?hsLang=en
C16: Nagarro borrowings | D16: 310.5 | E16: EUR m | F16: 30-Jun-26 | G16: H1 report, p57 | H16: https://www.nagarro.com/hubfs/Investors/InvestorDocuments/H1-Q2-2026/Nagarro%20SE_H1%202026_EN.pdf?hsLang=en
C17: Nagarro acquisition liabilities | D17: 8.952 | E17: EUR m | F17: 30-Jun-26 | G17: H1 report, p21. Current 2.988 + non-current 5.964 | H17: https://www.nagarro.com/hubfs/Investors/InvestorDocuments/H1-Q2-2026/Nagarro%20SE_H1%202026_EN.pdf?hsLang=en
... C44: September issued common shares | D44: 157.75 | E44: million | F44: 30-Sep-26 | G44: Q2 FY27 FS. Share capital INR788.75m / face value INR5 | H44: https://www.persistent.com/wp-content/uploads/2026/10/Consolidated-Financial-Statements-Q2FY27.pdf
