Workbook

Sheet Summary
A1: Persistent — Financial Summary
A4: Profit & Loss Statement | B4: FY16A | C4: FY17A | D4: FY18A | E4: FY19A | F4: FY20A | G4: FY21A | H4: FY22A | I4: FY23A | J4: FY24A | K4: FY25A | L4: FY26A | M4: FY27E | N4: FY28E | O4: FY29E | P4: FY30E | R4: Key Ratios | S4: FY16A | T4: FY17A | U4: FY18A | V4: FY19A | W4: FY20A | X4: FY21A | Y4: FY22A | Z4: FY23A | AA4: FY24A | AB4: FY25A | AC4: FY26A | AD4: FY27E | AE4: FY28E | AF4: FY29E | AG4: FY30E
A5: Revenue | B5: ='Annual P&L'!B5 -> 23123.31 | C5: ='Annual P&L'!C5 -> 28784.39 | D5: ='Annual P&L'!D5 -> 30337.03 | E5: ='Annual P&L'!E5 -> 33659.41 | F5: ='Annual P&L'!F5 -> 35658.08 | G5: ='Annual P&L'!G5 -> 41878.88 | H5: ='Annual P&L'!H5 -> 57107.46 | I5: ='Annual P&L'!I5 -> 83505.92 | ... P5: ='Annual P&L'!P5 -> 281990.34 | R5: Growth (%) | AJ5: =AC37*1.4 -> 6828.0803 | AK5: =AJ5*(1.15) -> 7852.2923 | AL5: =AK5*1.15 -> 9030.1362 | AM5: =AL5*1.1 -> 9933.1498
A6: Growth | B6: =[1]Annual_Statements!B6 -> 0 | C6: =[1]Annual_Statements!C6 -> 0.096795375 | D6: =[1]Annual_Statements!D6 -> 0.02974374 | E6: =[1]Annual_Statements!E6 -> 0.17234338 | F6: =[1]Annual_Statements!F6 -> 0.098154241 | G6: =[1]Annual_Statements!G6 -> 0.10664053 | H6: =[1]Annual_Statements!H6 -> 0.21068347 | I6: =[1]Annual_Statements!I6 -> 0.20655864 | ... P6: =[1]Annual_Statements!P6 -> 0.058461231 | R6: Revenue | S6: =0 -> 0 | T6: =IFERROR(C5/B5-1,0) -> 0.24482135 | U6: =IFERROR(D5/C5-1,0) -> 0.053940348 | V6: =IFERROR(E5/D5-1,0) -> 0.10951566 | W6: =IFERROR(F5/E5-1,0) -> 0.059379235 | X6: =IFERROR(G5/F5-1,0) -> 0.17445695 | Y6: =IFERROR(H5/G5-1,0) -> 0.36363389 | Z6: =IFERROR(I5/H5-1,0) -> 0.4622594 | AA6: =IFERROR(J5/I5-1,0) -> 0.17615458 | ... AG6: =IFERROR(P5/O5-1,0) -> 0.14041043 | AJ6: =AJ5/AC37-1 -> 0.4 | AK6: =AK5/AD37-1 -> 0.15 | AL6: =AL5/AE37-1 -> 0.15 | AM6: =AM5/AF37-1 -> 0.1
A7: Gross profit | B7: ='Annual P&L'!B10 -> 8818.51 | C7: ='Annual P&L'!C10 -> 10266.37 | D7: ='Annual P&L'!D10 -> 10632.91 | E7: ='Annual P&L'!E10 -> 12281.26 | F7: ='Annual P&L'!F10 -> 12163.75 | G7: ='Annual P&L'!G10 -> 14228.64 | H7: ='Annual P&L'!H10 -> 19212.523 | I7: ='Annual P&L'!I10 -> 28190.6 | ... P7: ='Annual P&L'!P10 -> 102080.5 | R7: EBITDA | S7: =0 -> 0 | T7: =IFERROR(C9/B9-1,0) -> 0.0882965 | U7: =IFERROR(D9/C9-1,0) -> 0.032570743 | V7: =IFERROR(E9/D9-1,0) -> 0.23855607 | W7: =IFERROR(F9/E9-1,0) -> -0.15086403 | X7: =IFERROR(G9/F9-1,0) -> 0.38555524 | Y7: =IFERROR(H9/G9-1,0) -> 0.40285513 | Z7: =IFERROR(I9/H9-1,0) -> 0.58544231 | AA7: =IFERROR(J9/I9-1,0) -> 0.13506262 | ... AG7: =IFERROR(P9/O9-1,0) -> 0.16877885
A8: Gross margin | B8: =B7/B5 -> 0.38136884 | C8: =C7/C5 -> 0.3566645 | D8: =D7/D5 -> 0.35049278 | E8: =E7/E5 -> 0.36486855 | F8: =F7/F5 -> 0.34112184 | G8: =G7/G5 -> 0.33975694 | H8: =H7/H5 -> 0.33642755 | I8: =I7/I5 -> 0.33758804 | ... P8: =P7/P5 -> 0.362 | R8: EBIT | S8: =0 -> 0 | T8: =IFERROR(C11/B11-1,0) -> -0.048884869 | U8: =IFERROR(D11/C11-1,0) -> 0.017430916 | V8: =IFERROR(E11/D11-1,0) -> 0.36440998 | W8: =IFERROR(F11/E11-1,0) -> -0.22748975 | X8: =IFERROR(G11/F11-1,0) -> 0.5519187 | Y8: =IFERROR(H11/G11-1,0) -> 0.56101229 | Z8: =IFERROR(I11/H11-1,0) -> 0.57446907 | AA8: =IFERROR(J11/I11-1,0) -> 0.13445716 | ... AG8: =IFERROR(P11/O11-1,0) -> 0.17928806
A9: EBITDA | B9: ='Annual P&L'!B13 -> 4171.06 | C9: ='Annual P&L'!C13 -> 4539.35 | D9: ='Annual P&L'!D13 -> 4687.2 | E9: ='Annual P&L'!E13 -> 5805.36 | F9: ='Annual P&L'!F13 -> 4929.54 | G9: ='Annual P&L'!G13 -> 6830.15 | H9: ='Annual P&L'!H13 -> 9581.711 | I9: ='Annual P&L'!I13 -> 15191.25 | ... P9: ='Annual P&L'!P13 -> 58090.011 | R9: Net profit | S9: =0 -> 0 | T9: =IFERROR(C16/B16-1,0) -> 0.013801406 | U9: =IFERROR(D16/C16-1,0) -> 0.071726403 | V9: =IFERROR(E16/D16-1,0) -> 0.088492918 | W9: =IFERROR(F16/E16-1,0) -> -0.03238749 | X9: =IFERROR(G16/F16-1,0) -> 0.32439485 | Y9: =IFERROR(H16/G16-1,0) -> 0.53188647 | Z9: =IFERROR(I16/H16-1,0) -> 0.33417103 | AA9: =IFERROR(J16/I16-1,0) -> 0.18716677 | ... AG9: =IFERROR(P16/O16-1,0) -> 0.17906841
A10: EBITDA margin | B10: =B9/B5 -> 0.18038334 | C10: =C9/C5 -> 0.1577018 | D10: =D9/D5 -> 0.15450425 | E10: =E9/E5 -> 0.17247361 | F10: =F9/F5 -> 0.13824468 | G10: =G9/G5 -> 0.16309295 | H10: =H9/H5 -> 0.16778388 | I10: =I9/I5 -> 0.18191824 | ... P10: =P9/P5 -> 0.206 | R10: EPS | S10: =0 -> 0 | T10: =IFERROR(C18/B18-1,0) -> 0.011272142 | U10: =IFERROR(D18/C18-1,0) -> 0.071921444 | V10: =IFERROR(E18/D18-1,0) -> 0.089130973 | W10: =IFERROR(F18/E18-1,0) -> 0.0088656513 | X10: =IFERROR(G18/F18-1,0) -> 0.32875169 | Y10: =IFERROR(H18/G18-1,0) -> 0.53196541 | Z10: =IFERROR(I18/H18-1,0) -> 0.36960372 | AA10: =IFERROR(J18/I18-1,0) -> -0.41453164 | ... AG10: =IFERROR(P18/O18-1,0) -> 0.17906841
A11: EBIT | B11: ='Annual P&L'!B16 -> 3205.9 | C11: ='Annual P&L'!C16 -> 3049.18 | D11: ='Annual P&L'!D16 -> 3102.33 | E11: ='Annual P&L'!E16 -> 4232.85 | F11: ='Annual P&L'!F16 -> 3269.92 | G11: ='Annual P&L'!G16 -> 5074.65 | H11: ='Annual P&L'!H16 -> 7921.591 | I11: ='Annual P&L'!I16 -> 12472.3 | ... P11: ='Annual P&L'!P16 -> 51322.242
A12: EBIT margin | B12: =B11/B5 -> 0.13864365 | C12: =C11/C5 -> 0.10593172 | D12: =D11/D5 -> 0.10226215 | E12: =E11/E5 -> 0.12575532 | F12: =F11/F5 -> 0.091702077 | G12: =G11/G5 -> 0.12117444 | H12: =H11/H5 -> 0.13871377 | I12: =I11/I5 -> 0.14935827 | ... P12: =P11/P5 -> 0.182 | R12: Margins (%)
A13: PBT | B13: ='Annual P&L'!B21 -> 3956.27 | C13: ='Annual P&L'!C21 -> 4006.73 | D13: ='Annual P&L'!D21 -> 4292.61 | E13: ='Annual P&L'!E21 -> 4863.39 | F13: ='Annual P&L'!F21 -> 4523.42 | G13: ='Annual P&L'!G21 -> 6094.43 | H13: ='Annual P&L'!H21 -> 9242.79 | I13: ='Annual P&L'!I21 -> 12408.52 | ... P13: ='Annual P&L'!P21 -> 51604.233 | R13: Gross margin | S13: =B8 -> 0.38136884 | T13: =C8 -> 0.3566645 | U13: =D8 -> 0.35049278 | V13: =E8 -> 0.36486855 | W13: =F8 -> 0.34112184 | X13: =G8 -> 0.33975694 | Y13: =H8 -> 0.33642755 | Z13: =I8 -> 0.33758804 | ... AG13: =P8 -> 0.362
A14: PBT margin | B14: =B13/B5 -> 0.17109445 | C14: =C13/C5 -> 0.13919802 | D14: =D13/D5 -> 0.14149737 | E14: =E13/E5 -> 0.14448827 | F14: =F13/F5 -> 0.1268554 | G14: =G13/G5 -> 0.14552514 | H14: =H13/H5 -> 0.16184908 | I14: =I13/I5 -> 0.14859449 | ... P14: =P13/P5 -> 0.183 | R14: EBITDA margin | S14: =B10 -> 0.18038334 | T14: =C10 -> 0.1577018 | U14: =D10 -> 0.15450425 | V14: =E10 -> 0.17247361 | W14: =F10 -> 0.13824468 | X14: =G10 -> 0.16309295 | Y14: =H10 -> 0.16778388 | Z14: =I10 -> 0.18191824 | ... AG14: =P10 -> 0.206
A15: Income tax | B15: ='Annual P&L'!B23 -> 982.66 | C15: ='Annual P&L'!C23 -> 992.08 | D15: ='Annual P&L'!D23 -> 1061.73 | E15: ='Annual P&L'!E23 -> 1346.6 | F15: ='Annual P&L'!F23 -> 1120.53 | G15: ='Annual P&L'!G23 -> 1587.66 | H15: ='Annual P&L'!H23 -> 2338.93 | I15: ='Annual P&L'!I23 -> 3197.59 | ... P15: ='Annual P&L'!P23 -> 11868.974 | R15: EBIT margin | S15: =B12 -> 0.13864365 | T15: =C12 -> 0.10593172 | U15: =D12 -> 0.10226215 | V15: =E12 -> 0.12575532 | W15: =F12 -> 0.091702077 | X15: =G12 -> 0.12117444 | Y15: =H12 -> 0.13871377 | Z15: =I12 -> 0.14935827 | ... AG15: =P12 -> 0.182
A16: Net profit | B16: ='Annual P&L'!B25 -> 2973.61 | C16: ='Annual P&L'!C25 -> 3014.65 | D16: ='Annual P&L'!D25 -> 3230.88 | E16: ='Annual P&L'!E25 -> 3516.79 | F16: ='Annual P&L'!F25 -> 3402.89 | G16: ='Annual P&L'!G25 -> 4506.77 | H16: ='Annual P&L'!H25 -> 6903.86 | I16: ='Annual P&L'!I25 -> 9210.93 | ... P16: ='Annual P&L'!P25 -> 39735.259 | R16: PBT margin | S16: =B14 -> 0.17109445 | T16: =C14 -> 0.13919802 | U16: =D14 -> 0.14149737 | V16: =E14 -> 0.14448827 | W16: =F14 -> 0.1268554 | X16: =G14 -> 0.14552514 | Y16: =H14 -> 0.16184908 | Z16: =I14 -> 0.14859449 | ... AG16: =P14 -> 0.183
A17: Net margin | B17: =B16/B5 -> 0.12859794 | C17: =C16/C5 -> 0.10473211 | D17: =D16/D5 -> 0.10649955 | E17: =E16/E5 -> 0.10448163 | F17: =F16/F5 -> 0.095431106 | G17: =G16/G5 -> 0.10761439 | H17: =H16/H5 -> 0.12089244 | I17: =I16/I5 -> 0.11030272 | ... P17: =P16/P5 -> 0.14091 | R17: Net margin | S17: =B17 -> 0.12859794 | T17: =C17 -> 0.10473211 | U17: =D17 -> 0.10649955 | V17: =E17 -> 0.10448163 | W17: =F17 -> 0.095431106 | X17: =G17 -> 0.10761439 | Y17: =H17 -> 0.12089244 | Z17: =I17 -> 0.11030272 | ... AG17: =P17 -> 0.14091
A18: Basic EPS | B18: ='Annual P&L'!B29 -> 37.26 | C18: ='Annual P&L'!C29 -> 37.68 | D18: ='Annual P&L'!D29 -> 40.39 | E18: ='Annual P&L'!E29 -> 43.99 | F18: ='Annual P&L'!F29 -> 44.38 | G18: ='Annual P&L'!G29 -> 58.97 | H18: ='Annual P&L'!H29 -> 90.34 | I18: ='Annual P&L'!I29 -> 123.73 | ... P18: ='Annual P&L'!P29 -> 255.09886
A19: Diluted EPS | B19: ='Annual P&L'!B30 -> 37.17 | C19: ='Annual P&L'!C30 -> 37.68 | D19: ='Annual P&L'!D30 -> 40.39 | E19: ='Annual P&L'!E30 -> 43.99 | F19: ='Annual P&L'!F30 -> 44.38 | G19: ='Annual P&L'!G30 -> 58.97 | H19: ='Annual P&L'!H30 -> 90.34 | I19: ='Annual P&L'!I30 -> 120.52 | ... P19: ='Annual P&L'!P30 -> 253.24538 | R19: Returns (%)
A20: Weighted-average basic shares | B20: ='Annual P&L'!B27 -> 79.807032 | C20: ='Annual P&L'!C27 -> 80.006635 | D20: ='Annual P&L'!D27 -> 79.992077 | E20: ='Annual P&L'!E27 -> 79.945215 | F20: ='Annual P&L'!F27 -> 76.676205 | G20: ='Annual P&L'!G27 -> 76.424792 | H20: ='Annual P&L'!H27 -> 76.420855 | I20: ='Annual P&L'!I27 -> 74.443789 | ... P20: ='Annual P&L'!P27 -> 155.76416 | R20: ROE | S20: =B63 -> 0.18139555 | T20: =C63 -> 0.15872736 | U20: =D63 -> 0.15188424 | V20: =E63 -> 0.14999019 | W20: =F63 -> 0.14263367 | X20: =G63 -> 0.16120559 | Y20: =H63 -> 0.20497058 | Z20: =I63 -> 0.23230136 | ... AG20: =P63 -> 0.24164377
A21: Weighted-average diluted shares | B21: ='Annual P&L'!B28 -> 80.000269 | C21: ='Annual P&L'!C28 -> 80.006635 | D21: ='Annual P&L'!D28 -> 79.992077 | E21: ='Annual P&L'!E28 -> 79.945215 | F21: ='Annual P&L'!F28 -> 76.676205 | G21: ='Annual P&L'!G28 -> 76.424792 | H21: ='Annual P&L'!H28 -> 76.420855 | I21: ='Annual P&L'!I28 -> 76.426568 | ... P21: ='Annual P&L'!P28 -> 156.90418 | R21: ROA | S21: =IFERROR(B16/B53,0) -> 0.14116066 | T21: =IFERROR(C16/AVERAGE(B53,C53),0) -> 0.13540116 | U21: =IFERROR(D16/AVERAGE(C53,D53),0) -> 0.12910003 | V21: =IFERROR(E16/AVERAGE(D53,E53),0) -> 0.12754791 | W21: =IFERROR(F16/AVERAGE(E53,F53),0) -> 0.11442578 | X21: =IFERROR(G16/AVERAGE(F53,G53),0) -> 0.13338191 | Y21: =IFERROR(H16/AVERAGE(G53,H53),0) -> 0.15198998 | Z21: =IFERROR(I16/AVERAGE(H53,I53),0) -> 0.15234522 | AA21: =IFERROR(J16/AVERAGE(I53,J53),0) -> 0.15520732 | ... AG21: =IFERROR(P16/AVERAGE(O53,P53),0) -> 0.18905066
R22: FCF margin | S22: =B42 -> 0.038110893 | T22: =C42 -> 0.023914351 | U22: =D42 -> 0.11726164 | V22: =E42 -> 0.11717615 | W22: =F42 -> 0.069263124 | X22: =G42 -> 0.14513784 | Y22: =H42 -> 0.080477927 | Z22: =I42 -> 0.062565983 | ... AG22: =P42 -> 0.15061894
A24: Cash Flow Statement | B24: FY16A | C24: FY17A | D24: FY18A | E24: FY19A | F24: FY20A | G24: FY21A | H24: FY22A | I24: FY23A | J24: FY24A | K24: FY25A | L24: FY26A | M24: FY27E | N24: FY28E | O24: FY29E | P24: FY30E | R24: Gearing
A25: Net profit | B25: =B16 -> 2973.61 | C25: =C16 -> 3014.65 | D25: =D16 -> 3230.88 | E25: =E16 -> 3516.79 | F25: =F16 -> 3402.89 | G25: =G16 -> 4506.77 | H25: =H16 -> 6903.86 | I25: =I16 -> 9210.93 | ... P25: =P16 -> 39735.259 | R25: Net debt / EBITDA | S25: =IFERROR((B55-B46)/B9,0) -> -0.32982024 | T25: =IFERROR((C55-C46)/C9,0) -> -0.31715334 | U25: =IFERROR((D55-D46)/D9,0) -> -0.28314772 | V25: =IFERROR((E55-E46)/E9,0) -> -0.29756639 | W25: =IFERROR((F55-F46)/F9,0) -> -0.3043712 | X25: =IFERROR((G55-G46)/G9,0) -> -0.24258618 | Y25: =IFERROR((H55-H46)/H9,0) -> 0.25691132 | Z25: =IFERROR((I55-I46)/I9,0) -> 0.08090381 | ... AG25: =IFERROR((P55-P46)/P9,0) -> -0.99435193
A26: D&A | B26: ='Annual P&L'!B95 -> 965.16 | C26: ='Annual P&L'!C95 -> 1490.17 | D26: ='Annual P&L'!D95 -> 1584.87 | E26: ='Annual P&L'!E95 -> 1572.51 | F26: ='Annual P&L'!F95 -> 1659.62 | G26: ='Annual P&L'!G95 -> 1755.5 | H26: ='Annual P&L'!H95 -> 1660.12 | I26: ='Annual P&L'!I95 -> 2718.95 | ... P26: ='Annual P&L'!P95 -> 6767.7682 | R26: Debt / equity | S26: =IFERROR(B55/B60,0) -> 0.0015677462 | T26: =IFERROR(C55/C60,0) -> 0.001143075 | U26: =IFERROR(D55/D60,0) -> 0.00077801842 | V26: =IFERROR(E55/E60,0) -> 0.00051051743 | W26: =IFERROR(F55/F60,0) -> 0.016748576 | X26: =IFERROR(G55/G60,0) -> 0.027270783 | Y26: =IFERROR(H55/H60,0) -> 0.16149895 | Z26: =IFERROR(I55/I60,0) -> 0.14877765 | ... AG26: =IFERROR(P55/P60,0) -> 0.029181252
A27: Other non-cash / working capital | B27: =B28-B25-B26 -> -1398.17 | C27: =C28-C25-C26 -> -1640.72 | D27: =D28-D25-D26 -> -603.82 | E27: =E28-E25-E26 -> -766.16 | F27: =F28-F25-F26 -> -1834.33 | G27: =G28-G25-G26 -> 1096.98 | H27: =H28-H25-H26 -> -114.12 | I27: =I28-I25-I26 -> -2372.26 | ... P27: =P28-P25-P26 -> -82.076421 | R27: Net debt / equity | S27: =IFERROR((B55-B46)/B60,0) -> -0.083920171 | T27: =IFERROR((C55-C46)/C60,0) -> -0.075801508 | U27: =IFERROR((D55-D46)/D60,0) -> -0.062390496 | V27: =IFERROR((E55-E46)/E60,0) -> -0.073676578 | W27: =IFERROR((F55-F46)/F60,0) -> -0.062890364 | X27: =IFERROR((G55-G46)/G60,0) -> -0.059266736 | Y27: =IFERROR((H55-H46)/H60,0) -> 0.073084597 | Z27: =IFERROR((I55-I46)/I60,0) -> 0.030996364 | ... AG27: =IFERROR((P55-P46)/P60,0) -> -0.35127005
A28: Cash flow from operations | B28: ='Annual P&L'!B108 -> 2540.6 | C28: ='Annual P&L'!C108 -> 2864.1 | D28: ='Annual P&L'!D108 -> 4211.93 | E28: ='Annual P&L'!E108 -> 4323.14 | F28: ='Annual P&L'!F108 -> 3228.18 | G28: ='Annual P&L'!G108 -> 7359.25 | H28: ='Annual P&L'!H108 -> 8449.86 | I28: ='Annual P&L'!I108 -> 9557.62 | ... P28: ='Annual P&L'!P108 -> 46420.951 | AD28: =AJ5 -> 6828.0803
A29: CFO margin | B29: =B28/B25 -> 0.85438238 | C29: =C28/C25 -> 0.95006054 | D29: =D28/D25 -> 1.3036479 | E29: =E28/E25 -> 1.2292858 | F29: =F28/F25 -> 0.94865835 | G29: =G28/G25 -> 1.6329322 | H29: =H28/H25 -> 1.2239327 | I29: =I28/I25 -> 1.037639 | ... P29: =P28/P25 -> 1.1682559 | R29: Operating KPIs
A30: Capex | B30: ='Annual P&L'!B111 -> -1659.35 | C30: ='Annual P&L'!C111 -> -2175.74 | D30: ='Annual P&L'!D111 -> -654.56 | E30: ='Annual P&L'!E111 -> -379.06 | F30: ='Annual P&L'!F111 -> -758.39 | G30: ='Annual P&L'!G111 -> -1281.04 | H30: ='Annual P&L'!H111 -> -3853.97 | I30: ='Annual P&L'!I111 -> -4332.99 | ... P30: ='Annual P&L'!P111 -> -3947.8648 | R30: Closing headcount | S30: ='People & AI'!B5 -> 9264 | T30: ='People & AI'!C5 -> 9460 | U30: ='People & AI'!D5 -> 8976 | V30: ='People & AI'!E5 -> 9962 | W30: ='People & AI'!F5 -> 10632 | X30: ='People & AI'!G5 -> 13680 | Y30: ='People & AI'!H5 -> 18599 | Z30: ='People & AI'!I5 -> 22889 | ... AG30: ='People & AI'!P5 -> 35100.1
A31: Acquisitions / investments | B31: =B32-B30 -> 1289.42 | C31: =C32-C30 -> -43.61 | D31: =D32-D30 -> -2819.34 | E31: =E32-E30 -> -1879.93 | F31: =F32-F30 -> 609.95 | G31: =G32-G30 -> -4135.69 | H31: =H32-H30 -> -5919.46 | I31: =I32-I30 -> 119.89 | ... P31: =P32-P30 -> -3948.7042 | R31: Billable employees | S31: ='People & AI'!B6 -> 0 | T31: ='People & AI'!C6 -> 0 | U31: ='People & AI'!D6 -> 0 | V31: ='People & AI'!E6 -> 0 | W31: ='People & AI'!F6 -> 0 | X31: ='People & AI'!G6 -> 0 | Y31: ='People & AI'!H6 -> 0 | Z31: ='People & AI'!I6 -> 0 | ... AG31: ='People & AI'!P6 -> 33204.694
A32: Cash flow from investing | B32: ='Annual P&L'!B116 -> -369.93 | C32: ='Annual P&L'!C116 -> -2219.35 | D32: ='Annual P&L'!D116 -> -3473.9 | E32: ='Annual P&L'!E116 -> -2258.99 | F32: ='Annual P&L'!F116 -> -148.44 | G32: ='Annual P&L'!G116 -> -5416.73 | H32: ='Annual P&L'!H116 -> -9773.43 | I32: ='Annual P&L'!I116 -> -4213.1 | ... P32: ='Annual P&L'!P116 -> -7896.569 | R32: Attrition | S32: ='People & AI'!B9 -> 0.164 | T32: ='People & AI'!C9 -> 0.157 | U32: ='People & AI'!D9 -> 0.147 | V32: ='People & AI'!E9 -> 0.167 | W32: ='People & AI'!F9 -> 0.143 | X32: ='People & AI'!G9 -> 0.117 | Y32: ='People & AI'!H9 -> 0.266 | Z32: ='People & AI'!I9 -> 0.198 | ... AG32: ='People & AI'!P9 -> 0.118
A33: Dividends | B33: ='Annual P&L'!B122 -> -1039.51 | C33: ='Annual P&L'!C122 -> -480.01 | D33: ='Annual P&L'!D122 -> -799.79 | E33: ='Annual P&L'!E122 -> -879.14 | F33: ='Annual P&L'!F122 -> -1146.38 | G33: ='Annual P&L'!G122 -> -1069.95 | H33: ='Annual P&L'!H122 -> -1987.05 | I33: ='Annual P&L'!I122 -> -2980.58 | ... P33: ='Annual P&L'!P122 -> -15496.751 | R33: AI revenue mix | S33: ='Bookings & Revenue'!B22/'Bookings & Revenue'!B27 -> 0 | T33: ='Bookings & Revenue'!C22/'Bookings & Revenue'!C27 -> 0 | U33: ='Bookings & Revenue'!D22/'Bookings & Revenue'!D27 -> 0 | V33: ='Bookings & Revenue'!E22/'Bookings & Revenue'!E27 -> 0 | W33: ='Bookings & Revenue'!F22/'Bookings & Revenue'!F27 -> 0 | X33: ='Bookings & Revenue'!G22/'Bookings & Revenue'!G27 -> 0 | Y33: ='Bookings & Revenue'!H22/'Bookings & Revenue'!H27 -> 0 | Z33: ='Bookings & Revenue'!I22/'Bookings & Revenue'!I27 -> 0 | ... AG33: ='Bookings & Revenue'!P22/'Bookings & Revenue'!P27 -> 0.02034478
A34: Buybacks / other financing | B34: ='Annual P&L'!B124 -> -226.78 | C34: ='Annual P&L'!C124 -> -104.07 | D34: ='Annual P&L'!D124 -> -156.35 | E34: ='Annual P&L'!E124 -> -717.06 | F34: ='Annual P&L'!F124 -> -1856.94 | G34: ='Annual P&L'!G124 -> -372.66 | H34: ='Annual P&L'!H124 -> 3809.94 | I34: ='Annual P&L'!I124 -> -1058.87 | ... P34: ='Annual P&L'!P124 -> 0 | R34: Revenue / billable employee | S34: =IFERROR('Annual P&L'!B5/Summary!S31,"") | T34: =IFERROR('Annual P&L'!C5/Summary!T31,"") | U34: =IFERROR('Annual P&L'!D5/Summary!U31,"") | V34: =IFERROR('Annual P&L'!E5/Summary!V31,"") | W34: =IFERROR('Annual P&L'!F5/Summary!W31,"") | X34: =IFERROR('Annual P&L'!G5/Summary!X31,"") | Y34: =IFERROR('Annual P&L'!H5/Summary!Y31,"") | Z34: =IFERROR('Annual P&L'!I5/Summary!Z31,"") | ... AG34: =IFERROR('Annual P&L'!P5/Summary!AG31,"") -> 8.4924843
A35: Debt issuance / repayment | B35: =B36-B33-B34 -> 0 | C35: =C36-C33-C34 -> 0 | D35: =D36-D33-D34 -> 0 | E35: =E36-E33-E34 -> 0 | F35: =F36-F33-F34 -> 0 | G35: =G36-G33-G34 -> 0 | H35: =H36-H33-H34 -> 0 | I35: =I36-I33-I34 -> 0 | ... P35: =P36-P33-P34 -> -3365.2596 | R35: FY26 / current market price (INPUT) | S35: =AC37 -> 4877.2002
A36: Cash flow from financing | B36: ='Annual P&L'!B125 -> -1266.29 | C36: ='Annual P&L'!C125 -> -584.08 | D36: ='Annual P&L'!D125 -> -956.14 | E36: ='Annual P&L'!E125 -> -1596.2 | F36: ='Annual P&L'!F125 -> -3003.32 | G36: ='Annual P&L'!G125 -> -1442.61 | H36: ='Annual P&L'!H125 -> 1822.89 | I36: ='Annual P&L'!I125 -> -4039.45 | ... P36: ='Annual P&L'!P125 -> -18862.011 | R36: Valuations
A37: FX / other | B37: ='Annual P&L'!B128 -> -491.11 | C37: ='Annual P&L'!C128 -> -0.69 | D37: ='Annual P&L'!D128 -> 100.45 | E37: ='Annual P&L'!E128 -> -72.22 | F37: ='Annual P&L'!F128 -> 84.12 | G37: ='Annual P&L'!G128 -> 19.4 | H37: ='Annual P&L'!H128 -> 59.37 | I37: ='Annual P&L'!I128 -> 387.06 | ... P37: ='Annual P&L'!P128 -> 0 | R37: Share price (INR) | S37: 381.07501 | T37: 297.85001 | U37: 347.02499 | V37: 318.39999 | W37: 275.47501 | X37: 961.02502 | Y37: 2382.6499 | Z37: 2304.75 | AA37: 3984.55 | AB37: 5513.75 | AC37: 4877.2002 | AD37: =AJ5 -> 6828.0803 | AE37: =AK5 -> 7852.2923 | AF37: =AL5 -> 9030.1362 | AG37: =AM5 -> 9933.1498
A38: Net change in cash | B38: ='Annual P&L'!B127+'Annual P&L'!B128 -> 413.27 | C38: ='Annual P&L'!C127+'Annual P&L'!C128 -> 59.98 | D38: ='Annual P&L'!D127+'Annual P&L'!D128 -> -117.66 | E38: ='Annual P&L'!E127+'Annual P&L'!E128 -> 395.73 | F38: ='Annual P&L'!F127+'Annual P&L'!F128 -> 160.54 | G38: ='Annual P&L'!G127+'Annual P&L'!G128 -> 519.31 | H38: ='Annual P&L'!H127+'Annual P&L'!H128 -> 558.69 | I38: ='Annual P&L'!I127+'Annual P&L'!I128 -> 1692.13 | ... P38: ='Annual P&L'!P127+'Annual P&L'!P128 -> 19662.371 | R38: Market capitalization | S38: =IF(S37>0,S37*B21,0) -> 30486.103 | T38: =IF(T37>0,T37*C21,0) -> 23829.977 | U38: =IF(U37>0,U37*D21,0) -> 27759.25 | V38: =IF(V37>0,V37*E21,0) -> 25454.556 | W38: =IF(W37>0,W37*F21,0) -> 21122.378 | X38: =IF(X37>0,X37*G21,0) -> 73446.138 | Y38: =IF(Y37>0,Y37*H21,0) -> 182084.14 | Z38: =IF(Z37>0,Z37*I21,0) -> 176144.13 | ... AG38: =IF(AG37>0,AG37*P21,0) -> 1558552.7
A39: Opening cash | B39: ='Annual P&L'!B129 -> 988.13 | C39: ='Annual P&L'!C129 -> 1401.4 | D39: ='Annual P&L'!D129 -> 1461.38 | E39: ='Annual P&L'!E129 -> 1343.72 | F39: ='Annual P&L'!F129 -> 1739.45 | G39: ='Annual P&L'!G129 -> 1899.99 | H39: ='Annual P&L'!H129 -> 2419.3 | I39: ='Annual P&L'!I129 -> 2977.99 | ... P39: ='Annual P&L'!P129 -> 42898.03 | R39: Enterprise value | S39: =IF(S37>0,S38+B55-B46,0) -> 29110.403 | T39: =IF(T37>0,T38+C55-C46,0) -> 22390.307 | U39: =IF(U37>0,U38+D55-D46,0) -> 26432.08 | V39: =IF(V37>0,V38+E55-E46,0) -> 23727.076 | W39: =IF(W37>0,W38+F55-F46,0) -> 19621.968 | X39: =IF(X37>0,X38+G55-G46,0) -> 71789.238 | Y39: =IF(Y37>0,Y38+H55-H46,0) -> 184545.79 | Z39: =IF(Z37>0,Z38+I55-I46,0) -> 177373.16 | ... AG39: =IF(AG37>0,AG38+P55-P46,0) -> 1500790.8
A40: Closing cash | B40: =[1]Annual_Statements!B97 -> 326970 | C40: =[1]Annual_Statements!C97 -> 226250 | D40: =[1]Annual_Statements!D97 -> 198180 | E40: =[1]Annual_Statements!E97 -> 195680 | F40: =[1]Annual_Statements!F97 -> 186490 | G40: =[1]Annual_Statements!G97 -> 247140 | H40: =[1]Annual_Statements!H97 -> 174720 | I40: =[1]Annual_Statements!I97 -> 121730 | ... P40: =[1]Annual_Statements!P97 -> 441280.72 | R40: P / E | S40: =IF(S37>0,IFERROR(S37/B19,0),0) -> 10.25222 | T40: =IF(T37>0,IFERROR(T37/C19,0),0) -> 7.9047242 | U40: =IF(U37>0,IFERROR(U37/D19,0),0) -> 8.5918543 | V40: =IF(V37>0,IFERROR(V37/E19,0),0) -> 7.2380085 | W40: =IF(W37>0,IFERROR(W37/F19,0),0) -> 6.2071881 | X40: =IF(X37>0,IFERROR(X37/G19,0),0) -> 16.296846 | Y40: =IF(Y37>0,IFERROR(Y37/H19,0),0) -> 26.374252 | Z40: =IF(Z37>0,IFERROR(Z37/I19,0),0) -> 19.123382 | ... AG40: =IF(AG37>0,IFERROR(AG37/P19,0),0) -> 39.223419
A41: Free cash flow | B41: =B28+B30 -> 881.25 | C41: =C28+C30 -> 688.36 | D41: =D28+D30 -> 3557.37 | E41: =E28+E30 -> 3944.08 | F41: =F28+F30 -> 2469.79 | G41: =G28+G30 -> 6078.21 | H41: =H28+H30 -> 4595.89 | I41: =I28+I30 -> 5224.63 | ... P41: =P28+P30 -> 42473.086 | R41: EV / EBITDA | S41: =IF(S37>0,IFERROR(S39/B9,0),0) -> 6.979138 | T41: =IF(T37>0,IFERROR(T39/C9,0),0) -> 4.9324918 | U41: =IF(U37>0,IFERROR(U39/D9,0),0) -> 5.6392047 | V41: =IF(V37>0,IFERROR(V39/E9,0),0) -> 4.0870981 | W41: =IF(W37>0,IFERROR(W39/F9,0),0) -> 3.9804867 | X41: =IF(X37>0,IFERROR(X39/G9,0),0) -> 10.510639 | Y41: =IF(Y37>0,IFERROR(Y39/H9,0),0) -> 19.260213 | Z41: =IF(Z37>0,IFERROR(Z39/I9,0),0) -> 11.676008 | ... AG41: =IF(AG37>0,IFERROR(AG39/P9,0),0) -> 25.835609
A42: FCF margin | B42: =IFERROR(B41/B5,0) -> 0.038110893 | C42: =IFERROR(C41/C5,0) -> 0.023914351 | D42: =IFERROR(D41/D5,0) -> 0.11726164 | E42: =IFERROR(E41/E5,0) -> 0.11717615 | F42: =IFERROR(F41/F5,0) -> 0.069263124 | G42: =IFERROR(G41/G5,0) -> 0.14513784 | H42: =IFERROR(H41/H5,0) -> 0.080477927 | I42: =IFERROR(I41/I5,0) -> 0.062565983 | ... P42: =IFERROR(P41/P5,0) -> 0.15061894 | R42: P / book value | S42: =IF(S37>0,IFERROR(S38/B60,0),0) -> 1.8597071 | T42: =IF(T37>0,IFERROR(T38/C60,0),0) -> 1.254696 | U42: =IF(U37>0,IFERROR(U38/D60,0),0) -> 1.3049672 | V42: =IF(V37>0,IFERROR(V38/E60,0),0) -> 1.0856303 | W42: =IF(W37>0,IFERROR(W38/F60,0),0) -> 0.88535404 | X42: =IF(X37>0,IFERROR(X38/G60,0),0) -> 2.6271428 | Y42: =IF(Y37>0,IFERROR(Y38/H60,0),0) -> 5.4059456 | Z42: =IF(Z37>0,IFERROR(Z38/I60,0),0) -> 4.4423876 | ... AG42: =IF(AG37>0,IFERROR(AG38/P60,0),0) -> 9.4780948
R43: Dividend per share | S43: ='[1]Market data'!E5 -> 12.13 | T43: ='[1]Market data'!E6 -> 12.88 | U43: ='[1]Market data'!E7 -> 21.75 | V43: ='[1]Market data'!E8 -> 21.5 | W43: ='[1]Market data'!E9 -> 17.5 | X43: ='[1]Market data'!E10 -> 27 | Y43: ='[1]Market data'!E11 -> 31 | Z43: ='[1]Market data'!E12 -> 34 | AA43: ='[1]Market data'!E13 -> 46 | AB43: ='[1]Market data'!E14 -> 43 | AC43: ='[1]Market data'!E15 -> 48 | AD43: ='[1]Market data'!E16 -> 49.097915 | AE43: ='[1]Market data'!E17 -> 53.821716 | AF43: ='[1]Market data'!E18 -> 57.394577 | AG43: ='[1]Market data'!E19 -> 60.674359
...

Sheet PERSISTENT Prices
A1: Persistent Systems Market Prices
A2: Month-end price history from listing plus exact FY-end closes; latest available close drives the forecast reference price
A5: Date | B5: Close | C5: Adjusted close | D5: Volume | E5: Fiscal year | F5: Source | H5: Fiscal year | I5: FY-end date | J5: FY-end close
A6: 40298.156 | B6: 99.662498 | C6: 81.489655 | D6: 951820 | E6: FY11 | F6: https://finance.yahoo.com/quote/PERSISTENT.NS/history/ | H6: FY11A | I6: 40633.156 | J6: 91.8125
A7: 40329.156 | B7: 96.699997 | C7: 79.365997 | D7: 151008 | E7: FY11 | F7: https://finance.yahoo.com/quote/PERSISTENT.NS/history/ | H7: FY12A | I7: 40998.156 | J7: 79.262497
A8: 40359.156 | B8: 103 | C8: 84.536659 | D8: 198452 | E8: FY11 | F8: https://finance.yahoo.com/quote/PERSISTENT.NS/history/ | H8: FY13A | I8: 41361.156 | J8: 136
A9: 40389.156 | B9: 113.625 | C9: 93.451057 | D9: 228908 | E9: FY11 | F9: https://finance.yahoo.com/quote/PERSISTENT.NS/history/ | H9: FY14A | I9: 41729.156 | J9: 262.36249
A10: 40421.156 | B10: 113.5625 | C10: 93.399658 | D10: 206200 | E10: FY11 | F10: https://finance.yahoo.com/quote/PERSISTENT.NS/history/ | H10: FY15A | I10: 42094.156 | J10: 357.14999
A11: 40451.156 | B11: 111.5875 | C11: 91.775314 | D11: 555560 | E11: FY11 | F11: https://finance.yahoo.com/quote/PERSISTENT.NS/history/ | H11: FY16A | I11: 42460.156 | J11: 381.07501
A12: 40480.156 | B12: 100.8125 | C12: 82.913406 | D12: 183828 | E12: FY11 | F12: https://finance.yahoo.com/quote/PERSISTENT.NS/history/ | H12: FY17A | I12: 42825.156 | J12: 297.85001
A13: 40512.156 | B13: 95.612503 | C13: 78.636658 | D13: 40792 | E13: FY11 | F13: https://finance.yahoo.com/quote/PERSISTENT.NS/history/ | H13: FY18A | I13: 43187.156 | J13: 347.02499
A14: 40543.156 | B14: 107.425 | C14: 88.351852 | D14: 53560 | E14: FY11 | F14: https://finance.yahoo.com/quote/PERSISTENT.NS/history/ | H14: FY19A | I14: 43552.156 | J14: 318.39999
A15: 40574.156 | B15: 96.375 | C15: 80.081886 | D15: 35908 | E15: FY11 | F15: https://finance.yahoo.com/quote/PERSISTENT.NS/history/ | H15: FY20A | I15: 43921.156 | J15: 275.47501
A16: 40602.156 | B16: 94.362503 | C16: 78.409607 | D16: 63840 | E16: FY11 | F16: https://finance.yahoo.com/quote/PERSISTENT.NS/history/ | H16: FY21A | I16: 44286.156 | J16: 961.02502
A17: 40633.156 | B17: 91.8125 | C17: 76.290703 | D17: 187968 | E17: FY11 | F17: https://finance.yahoo.com/quote/PERSISTENT.NS/history/ | H17: FY22A | I17: 44651.156 | J17: 2382.6499
... A21: 40753.156 | B21: 88.837502 | C21: 74.117683 | D21: 16260 | E21: FY12 | F21: https://finance.yahoo.com/quote/PERSISTENT.NS/history/ | H21: FY26A | I21: 46111.156 | J21: 4877.2002
A22: 40785.156 | B22: 80.275002 | C22: 66.973923 | D22: 397204 | E22: FY12 | F22: https://finance.yahoo.com/quote/PERSISTENT.NS/history/
A23: 40816.156 | B23: 76.25 | C23: 63.615837 | D23: 50380 | E23: FY12 | F23: https://finance.yahoo.com/quote/PERSISTENT.NS/history/
A24: 40847.156 | B24: 79.800003 | C24: 66.577644 | D24: 42184 | E24: FY12 | F24: https://finance.yahoo.com/quote/PERSISTENT.NS/history/
A25: 40877.156 | B25: 79.775002 | C25: 66.556801 | D25: 38856 | E25: FY12 | F25: https://finance.yahoo.com/quote/PERSISTENT.NS/history/
A26: 40907.156 | B26: 82.112503 | C26: 68.506973 | D26: 19224 | E26: FY12 | F26: https://finance.yahoo.com/quote/PERSISTENT.NS/history/
A27: 40939.156 | B27: 80.8125 | C27: 68.141914 | D27: 22936 | E27: FY12 | F27: https://finance.yahoo.com/quote/PERSISTENT.NS/history/
A28: 40968.156 | B28: 77.237503 | C28: 65.127457 | D28: 14740 | E28: FY12 | F28: https://finance.yahoo.com/quote/PERSISTENT.NS/history/
A29: 40998.156 | B29: 79.262497 | C29: 66.834946 | D29: 23220 | E29: FY12 | F29: https://finance.yahoo.com/quote/PERSISTENT.NS/history/
A30: 41029.156 | B30: 89.949997 | C30: 75.846764 | D30: 71384 | E30: FY13 | F30: https://finance.yahoo.com/quote/PERSISTENT.NS/history/
A31: 41060.156 | B31: 85.849998 | C31: 72.389595 | D31: 17388 | E31: FY13 | F31: https://finance.yahoo.com/quote/PERSISTENT.NS/history/
A32: 41089.156 | B32: 99.112503 | C32: 83.572678 | D32: 43016 | E32: FY13 | F32: https://finance.yahoo.com/quote/PERSISTENT.NS/history/
A33: 41121.156 | B33: 96.212502 | C33: 81.650696 | D33: 35660 | E33: FY13 | F33: https://finance.yahoo.com/quote/PERSISTENT.NS/history/
... A202: 46265.156 | B202: 5594.5 | C202: 5594.5 | D202: 1111436 | E202: FY27 | F202: https://finance.yahoo.com/quote/PERSISTENT.NS/history/

Sheet Sources
A1: Sources & Data Conventions
A2: Primary-source register; non-disclosed metrics remain blank, derived classifications are explicit and forecast assumptions are editable
A5: ID | B5: Data / period | C5: Units | D5: Primary source | E5: Model use | F5: Status | G5: Notes
A6: S1 | B6: Annual reports FY16–FY25 | C6: ₹m | D6: https://www.persistent.com/investors/financial-results-and-reports/annual-reports/ | E6: Audited P&L, balance sheet and cash flow | F6: Loaded | G6: Annual comparatives used; explicit classification residuals preserve reported totals
A7: S2 | B7: FY26 audited consolidated statements | C7: ₹m | D7: https://www.persistent.com/wp-content/uploads/2026/04/Consolidated-Financial-Statements-FY2025-26.pdf | E7: FY26 annual three statements and segment note | F7: Loaded | G7: FY26 revenue ₹147,484.5m; PAT ₹18,651.2m
A8: S3 | B8: Quarterly archives FY16–FY20 | C8: ₹m / $m / % / # | D8: https://www.persistent.com/investors/quarterly-results/ | E8: Quarterly P&L and operating history | F8: Loaded | G8: Official ZIP archives
A9: S4 | B9: Quarterly factsheets FY21–FY26 | C9: ₹m / $m / % / # | D9: https://www.persistent.com/investors/quarterly-results/ | E9: Quarterly P&L, mix, clients, people and bookings | F9: Loaded | G9: Quarterly current-period column retained
A10: S5 | B10: Q1 FY27 presentation and FS | C10: ₹m / $m / % / # | D10: https://www.persistent.com/wp-content/uploads/2026/08/analyst-presentation-and-factsheet-q1fy27.pdf | E10: Q1 FY27 actuals, TCV/ACV and operating KPIs | F10: Loaded | G10: Revenue $452.4m; TCV $1,146.2m; ACV $536.8m
A11: S6 | B11: Nagarro transaction | C11: EUR / scenario | D11: https://www.persistent.com/investors/investors-communication/investor-events/ | E11: Default-off M&A scenario | F11: Loaded | G11: Pending transaction is not consolidated in base case
A12: S7 | B12: Market prices | C12: ₹ / share | D12: https://finance.yahoo.com/quote/PERSISTENT.NS/history/ | E12: Daily series downloaded; month-end history displayed with exact FY-end closes | F12: Loaded | G12: Third-party price series only; editable forecast reference price
A13: S8 | B13: Historical direct cost / gross profit | C13: ₹m | D13: Official quarterly factsheets | E13: Calculated annual operating lines | F13: Calculated | G13: Sum of four reported quarters; audited annual PBT/PAT remain source of truth
A14: S9 | B14: Historical cash-flow residuals | C14: ₹m | D14: Audited CFS totals | E14: Line-by-line reconciliation | F14: Calculated | G14: Residuals make reported totals transparent; forecast residual is zero
A15: S10 | B15: Historical AI revenue | C15: n/a | D15: n/a | E15: Forecast policy | F15: Not disclosed | G15: AI narrative/activity is not hardcoded as historical revenue

Sheet Assumptions
A1: Forecast Assumptions
A2: Blue text on yellow = editable; all forecast financials and valuation outputs are formula-driven
A5: Driver | B5: FY27E | C5: FY28E | D5: FY29E | E5: FY30E | F5: Logic / interpretation
A6: Revenue retention | B6: 0.97 | C6: 0.972 | D6: 0.974 | E6: 0.975 | F6: Retained prior-year organic revenue; FY27 uses Q1 annualized run-rate instead
A7: ACV growth | B7: 0.12 | C7: 0.1 | D7: 0.09 | E7: 0.08 | F7: Total ACV bookings
A8: New ACV share | B8: 0.55 | C8: 0.56 | D8: 0.57 | E8: 0.58 | F8: Scenario share of ACV representing new scope
A9: New ACV first-year realization | B9: 0.1 | C9: 0.16 | D9: 0.16 | E9: 0.16 | F9: Revenue recognized from new ACV
A10: Strategic mega-deal TCV | B10: 650 | C10: 650 | D10: 650 | E10: 650 | F10: Q1 FY27 disclosed strategic deal; no incremental undisclosed mega-deal added
A11: Strategic deal realization | B11: 0.08 | C11: 0.1 | D11: 0.12 | E11: 0.12 | F11: Annual revenue ramp from disclosed strategic TCV
A12: Client farming / pricing uplift | B12: 0.015 | C12: 0.015 | D12: 0.015 | E12: 0.015 | F12: Cross-sell, wallet-share and pricing on prior revenue
A13: T&M mix | B13: 0.6 | C13: 0.58 | D13: 0.56 | E13: 0.54 | F13: Model assumption; not a reported historical series
A14: AI deflation on T&M | B14: 0.01 | C14: 0.01 | D14: 0.008 | E14: 0.006 | F14: Productivity / rate deflation on T&M pool
A15: Incremental AI uplift | B15: 0.035 | C15: 0.04 | D15: 0.045 | E15: 0.045 | F15: Incremental AI-led demand; not historical disclosed AI revenue
A16: Average INR / USD | B16: 91 | C16: 95 | D16: 96 | E16: 97 | F16: Translation rate
A17: Gross margin | B17: 0.352 | C17: 0.356 | D17: 0.359 | E17: 0.362 | F17: Delivery leverage and mix
... A52: DCF weight | B52: 0.3 | C52: 0.3 | D52: 0.3 | E52: 0.3 | F52: Blended valuation
A53: Reference market price | B53: ='PERSISTENT Prices'!B202 -> 5594.5 | C53: ='PERSISTENT Prices'!B202 -> 5594.5 | D53: ='PERSISTENT Prices'!B202 -> 5594.5 | E53: ='PERSISTENT Prices'!B202 -> 5594.5 | F53: Latest historical close carried into FY27–FY30; editable
A54: Nagarro scenario toggle | B54: 0 | C54: 0 | D54: 0 | E54: 0 | F54: 0 = exclude; 1 = include scenario inputs
A55: Nagarro consolidation months | B55: 0 | C55: 12 | D55: 12 | E55: 12 | F55: User input after closing
A56: Nagarro annual revenue | B56: 0 | C56: 0 | D56: 0 | E56: 0 | F56: User input; no unreported revenue is hardcoded
A57: Nagarro revenue growth | B57: 0 | C57: 0 | D57: 0 | E57: 0 | F57: Scenario growth
A58: Nagarro cash consideration | B58: 0 | C58: 0 | D58: 0 | E58: 0 | F58: Cash acquisition outflow
A59: Nagarro share consideration | B59: 0 | C59: 0 | D59: 0 | E59: 0 | F59: Non-cash equity consideration
A60: Nagarro debt funding | B60: 0 | C60: 0 | D60: 0 | E60: 0 | F60: Acquisition financing
A61: Nagarro net assets acquired | B61: 0 | C61: 0 | D61: 0 | E61: 0 | F61: Scenario purchase-price allocation input

Sheet Raw Financials
A1: Raw Reported Financials — Source Layer
A2: Hardcoded official reported inputs only; calculations and classifications live downstream
A4: Annual reported P&L
A5: Metric | B5: Units | C5: FY16A | D5: FY17A | E5: FY18A | F5: FY19A | G5: FY20A | H5: FY21A | I5: FY22A | J5: FY23A | K5: FY24A | L5: FY25A | M5: FY26A
A6: Revenue | B6: ₹m | C6: 23123.31 | D6: 28784.39 | E6: 30337.03 | F6: 33659.41 | G6: 35658.08 | H6: 41878.88 | I6: 57107.46 | J6: 83505.92 | K6: 98215.87 | L6: 119387.17 | M6: 147484.49
A7: Other income | B7: ₹m | C7: 784.49 | D7: 958.45 | E7: 1191.01 | F7: 876.55 | G7: 1323.77 | H7: 1077.72 | I7: 1439.55 | J7: 706.17 | K7: 1280.2 | L7: 1381.54 | M7: 1804.26
A8: Total income | B8: ₹m | C8: 23907.8 | D8: 29742.84 | E8: 31528.04 | F8: 34535.96 | G8: 36981.85 | H8: 42956.6 | I8: 58547.01 | J8: 84212.09 | K8: 99496.07 | L8: 120768.71 | M8: 149288.75
A9: Employee benefits | B9: ₹m | C9: 13828.26 | D9: 17648.97 | E9: 18316.46 | F9: 19249.53 | G9: 21556.4 | H9: 25157.99 | I9: 34593.1 | J9: 49695.65 | K9: 59609.7 | L9: 68737.17 | M9: 79495.42
A10: Subcontracting / professionals | B10: ₹m | C10: 1586.63 | D10: 2177.66 | E10: 3180.63 | F10: 3490.45 | G10: 3918.94 | H10: 5563.68 | I10: 7974.18 | J10: 10426.01 | K10: 11492.7 | L10: 17491.65 | M10: 21986.14
A11: Finance costs | B11: ₹m | C11: 0.92 | D11: 0.91 | E11: 0.79 | F11: 3.05 | G11: 63.32 | H11: 57.94 | I11: 118.35 | J11: 473.4 | K11: 467.27 | L11: 671.29 | M11: 726.82
A12: D&A | B12: ₹m | C12: 965.16 | D12: 1490.17 | E12: 1584.87 | F12: 1572.51 | G12: 1659.62 | H12: 1755.5 | I12: 1660.12 | J12: 2718.95 | K12: 3093.73 | L12: 3069.1 | M12: 4029.5
A13: Other expenses | B13: ₹m | C13: 3570.56 | D13: 4304.29 | E13: 4152.68 | F13: 5357.03 | G13: 5260.15 | H13: 4327.06 | I13: 4958.47 | J13: 8193.01 | K13: 10356.61 | L13: 12576.42 | M13: 18048.5
A14: PBT pre-exceptional | B14: ₹m | C14: 3956.27 | D14: 4120.84 | E14: 4292.61 | F14: 4863.39 | G14: 4523.42 | H14: 6094.43 | I14: 9242.79 | J14: 12705.07 | K14: 14476.06 | L14: 18223.08 | M14: 25002.37
A15: Exceptional items | B15: ₹m | C15: 0 | D15: -114.11 | E15: 0 | F15: 0 | G15: 0 | H15: 0 | I15: 0 | J15: -296.55 | K15: 0 | L15: 0 | M15: -890.25
A16: PBT | B16: ₹m | C16: 3956.27 | D16: 4006.73 | E16: 4292.61 | F16: 4863.39 | G16: 4523.42 | H16: 6094.43 | I16: 9242.79 | J16: 12408.52 | K16: 14476.06 | L16: 18223.08 | M16: 24112.12
A17: Tax | B17: ₹m | C17: 982.66 | D17: 992.08 | E17: 1061.73 | F17: 1346.6 | G17: 1120.53 | H17: 1587.66 | I17: 2338.93 | J17: 3197.59 | K17: 3541.15 | L17: 4221.47 | M17: 5460.92
... A20: Diluted EPS | B20: ₹ / share | C20: 37.17 | D20: 37.68 | E20: 40.39 | F20: 43.99 | G20: 44.38 | H20: 58.97 | I20: 90.34 | J20: 120.52 | K20: 71.07 | L20: 90.24 | M20: 118.87
A24: Quarterly reported P&L
A25: Metric | B25: Units | C25: Q1 FY16A | D25: Q2 FY16A | E25: Q3 FY16A | F25: Q4 FY16A | G25: Q1 FY17A | H25: Q2 FY17A | I25: Q3 FY17A | J25: Q4 FY17A | K25: Q1 FY18A | L25: Q2 FY18A | M25: Q3 FY18A | N25: Q4 FY18A | O25: Q1 FY19A | P25: Q2 FY19A | Q25: Q3 FY19A | R25: Q4 FY19A | S25: Q1 FY20A | T25: Q2 FY20A | U25: Q3 FY20A | V25: Q4 FY20A | W25: Q1 FY21A | X25: Q2 FY21A | Y25: Q3 FY21A | Z25: Q4 FY21A | AA25: Q1 FY22A | AB25: Q2 FY22A | AC25: Q3 FY22A | AD25: Q4 FY22A | AE25: Q1 FY23A | AF25: Q2 FY23A | AG25: Q3 FY23A | AH25: Q4 FY23A | AI25: Q1 FY24A | AJ25: Q2 FY24A | AK25: Q3 FY24A | AL25: Q4 FY24A | AM25: Q1 FY25A | AN25: Q2 FY25A | AO25: Q3 FY25A | AP25: Q4 FY25A | AQ25: Q1 FY26A | AR25: Q2 FY26A | AS25: Q3 FY26A | AT25: Q4 FY26A | AU25: Q1 FY27A
A26: Revenue | B26: $m | C26: 78.61 | D26: 82.96 | E26: 89.65 | F26: 100.43 | G26: 104.76 | H26: 105.18 | I26: 110.03 | J26: 109.03 | K26: 112.97 | L26: 118.1 | M26: 122.53 | N26: 116.95 | O26: 123.6 | P26: 118.23 | Q26: 120.84 | R26: 118.3 | S26: 119.62 | T26: 125.51 | U26: 129.43 | V26: 127.05 | W26: 131.02 | X26: 136.09 | Y26: 146.15 | Z26: 152.82 | AA26: 144.93129 | AB26: 182.32 | AC26: 172.68 | AD26: 217.32 | AE26: 241.52 | AF26: 255.56 | AG26: 242.65 | AH26: 274.55 | AI26: 282.9 | AJ26: 291.71 | AK26: 300.55 | AL26: 310.89 | AM26: 328.2 | AN26: 345.5 | AO26: 360.2 | AP26: 375.2 | AQ26: 389.7 | AR26: 406.2 | AS26: 422.5 | AT26: 436 | AU26: 452.4
A27: Average FX | B27: ₹ / $ | C27: 63.66 | D27: 65.42 | E27: 66.04 | F27: 67.42 | G27: 66.99 | H27: 66.93 | I27: 67.76 | J27: 66.69 | K27: 64.44 | L27: 64.46 | M27: 64.63 | N27: 64.35 | O27: 67.5 | P27: 70.67 | Q27: 71.52 | R27: 70.32 | S27: 69.56 | T27: 70.48 | U27: 71.29 | V27: 72.91 | W27: 75.69 | X27: 74.05 | Y27: 73.58 | Z27: 72.85 | AA27: 73.7372 | AB27: 74.11 | AC27: 74.92 | AE27: 77.76 | AF27: 80.16 | AG27: 82.06 | AH27: 82.12 | AI27: 82.05 | AJ27: 82.67 | AK27: 83.12 | AL27: 83.33 | AM27: 83.4 | AN27: 83.9 | AO27: 85 | AP27: 86.4 | AQ27: 85.5 | AR27: 88.2 | AS27: 89.4 | AT27: 93 | AU27: 95.1
A28: Revenue | B28: ₹m | C28: 5004.16 | D28: 5427.31 | E28: 5920.74 | F28: 6771.1 | G28: 7017.77 | H28: 7040.19 | I28: 7455.35 | J28: 7271.08 | K28: 7280.15 | L28: 7612.52 | M28: 7918.9 | N28: 7525.46 | O28: 8342.81 | P28: 8355.57 | Q28: 8642.49 | R28: 8318.54 | S28: 8321.14 | T28: 8846 | U28: 9227.29 | V28: 9263.65 | W28: 9913.85 | X28: 10077.47 | Y28: 10753.98 | Z28: 11133.58 | AA28: 12299.261 | AB28: 13512.49 | AC28: 14917.17 | AD28: 16378.54 | AE28: 18781.11 | AF28: 20486.41 | AG28: 21693.68 | AH28: 22544.72 | AI28: 23211.75 | AJ28: 24116.7 | AK28: 24982.16 | AL28: 25905.26 | AM28: 27371.7 | AN28: 28971.5 | AO28: 30622.8 | AP28: 32421.1 | AQ28: 33335.9 | AR28: 35807.2 | AS28: 37782.1 | AT28: 40559.4 | AU28: 43032.3
A29: Cost of revenue | B29: ₹m | C29: 3015.2 | D29: 3313.74 | E29: 3622.39 | F29: 4353.47 | G29: 4584.52 | H29: 4538.51 | I29: 4751.02 | J29: 4643.97 | K29: 4783.17 | L29: 4994.06 | M29: 5008.9 | N29: 4917.99 | O29: 5372.82 | P29: 5409.62 | Q29: 5341.15 | R29: 5254.56 | S29: 5434.02 | T29: 5773.25 | U29: 6157.43 | V29: 6129.63 | W29: 6646.37 | X29: 6576.62 | Y29: 7064.21 | Z29: 7363.04 | AA29: 8173.087 | AB29: 8982.03 | AC29: 9880.34 | AD29: 10859.49 | AE29: 12433.14 | AF29: 13628.38 | AG29: 14360.05 | AH29: 14893.75 | AI29: 15278.46 | AJ29: 16127.2 | AK29: 16539.12 | AM29: 18328.7 | AN29: 19294 | AO29: 20000.4 | AP29: 21117 | AQ29: 21576.2 | AR29: 22923.8 | AS29: 25017.8 | AT29: 26246.9 | AU29: 27915.4
A30: Gross profit | B30: ₹m | C30: 1988.96 | D30: 2113.57 | E30: 2298.35 | F30: 2417.63 | G30: 2433.25 | H30: 2501.68 | I30: 2704.33 | J30: 2627.11 | K30: 2496.98 | L30: 2618.46 | M30: 2910 | N30: 2607.47 | O30: 2969.99 | P30: 2945.95 | Q30: 3301.34 | R30: 3063.98 | S30: 2887.12 | T30: 3072.75 | U30: 3069.86 | V30: 3134.02 | W30: 3267.48 | X30: 3500.85 | Y30: 3689.77 | Z30: 3770.54 | AA30: 4126.183 | AB30: 4530.46 | AC30: 5036.83 | AD30: 5519.05 | AE30: 6347.97 | AF30: 6858.03 | AG30: 7333.63 | AH30: 7650.97 | AI30: 7933.29 | AJ30: 7989.5 | AK30: 8443.04 | AL30: 8618.95 | AM30: 9043 | AN30: 9677.5 | AO30: 10622.5 | AP30: 11304.1 | AQ30: 11759.7 | AR30: 12883.4 | AS30: 12764.3 | AT30: 14312.4 | AU30: 15116.9
A31: Gross margin | B31: % | C31: 0.39746131 | D31: 0.38943233 | E31: 0.38818627 | F31: 0.35705129 | G31: 0.34672695 | H31: 0.35534268 | I31: 0.36273683 | J31: 0.36130946 | K31: 0.34298469 | L31: 0.34396757 | M31: 0.36747528 | N31: 0.34648646 | O31: 0.35599396 | P31: 0.35257319 | Q31: 0.38198945 | R31: 0.36833146 | S31: 0.34696207 | T31: 0.34736039 | U31: 0.33269356 | V31: 0.33831373 | W31: 0.3295874 | X31: 0.34739374 | Y31: 0.34310739 | Z31: 0.33866375 | AA31: 0.33548219 | AB31: 0.33527943 | AC31: 0.33765319 | AD31: 0.33696837 | AE31: 0.33799759 | AF31: 0.33475997 | AG31: 0.33805376 | AH31: 0.3393686 | AI31: 0.34177906 | AJ31: 0.33128496 | AK31: 0.33796277 | AL31: 0.33271042 | AM31: 0.33037773 | AN31: 0.33403517 | AO31: 0.34688206 | AP31: 0.34866491 | AQ31: 0.35276384 | AR31: 0.35979915 | AS31: 0.33783988 | AT31: 0.35287504 | AU31: 0.35129194
A32: SG&A | B32: ₹m | C32: 1019.88 | D32: 1096.06 | E32: 1187.9 | F32: 1343.61 | G32: 1375.74 | H32: 1393.89 | I32: 1517.78 | J32: 1439.61 | K32: 1453.4 | L32: 1460.64 | M32: 1534.83 | N32: 1496.84 | O32: 1569.53 | P32: 1509.72 | Q32: 1598.17 | R32: 1798.48 | S32: 1685.19 | T32: 1856.3 | U32: 1835.55 | V32: 1857.17 | W32: 1803.12 | X32: 1843.13 | Y32: 1864.99 | Z32: 1887.25 | AA32: 2110.981 | AB32: 2286.52 | AC32: 2526 | AD32: 2707.31 | AE32: 3015.05 | AF32: 3178.39 | AG32: 3318.08 | AH32: 3487.83 | AI32: 3703.85 | AJ32: 3937.88 | AK32: 4024.7 | AM32: 4490.9 | AN32: 4870.3 | AO32: 5244.1 | AP32: 5460.2 | AQ32: 5643.7 | AR32: 6045.5 | AS32: 6331 | AT32: 6635.4 | AU32: 7095.3
A33: EBITDA | B33: ₹m | C33: 969.08 | D33: 1017.51 | E33: 1110.45 | F33: 1074.02 | G33: 1057.51 | H33: 1107.79 | I33: 1186.55 | J33: 1187.5 | K33: 1043.58 | L33: 1157.82 | M33: 1375.17 | N33: 1110.63 | O33: 1400.46 | P33: 1436.23 | Q33: 1703.17 | R33: 1265.5 | S33: 1201.93 | T33: 1216.45 | U33: 1234.31 | V33: 1276.85 | W33: 1464.36 | X33: 1657.72 | Y33: 1824.78 | Z33: 1883.29 | AA33: 2015.201 | AB33: 2243.94 | AC33: 2510.83 | AD33: 2811.74 | AE33: 3332.92 | AF33: 3679.64 | AG33: 4015.55 | AH33: 4163.14 | AI33: 4229.44 | AJ33: 4051.62 | AK33: 4418.34 | AL33: 4543.62 | AM33: 4552.1 | AN33: 4807.3 | AO33: 5378.4 | AP33: 5843.9 | AQ33: 6115.9 | AR33: 6837.9 | AS33: 6433.3 | AT33: 7677 | AU33: 8021.6
A34: Depreciation | B34: ₹m | C34: 132.76 | D34: 141.3 | E34: 150.14 | F34: 144.33 | G34: 147.83 | H34: 139.26 | I34: 143.19 | J34: 142.09 | K34: 132.76 | L34: 130.01 | M34: 124.37 | N34: 133.77 | O34: 122.86 | P34: 119.72 | Q34: 115.83 | R34: 115.98 | S34: 110.2 | T34: 115.91 | U34: 116.24 | V34: 111.14 | W34: 109.8 | X34: 115.08 | Y34: 117.22 | Z34: 124.68 | AB34: 168.12 | AD34: 231.18 | AE34: 222.08 | AF34: 243.95 | AH34: 293.22 | AI34: 287.56 | AJ34: 297.09 | AK34: 303.21 | AL34: 299.65 | AM34: 211.5 | AN34: 226.9 | AO34: 242.4 | AP34: 239.9 | AQ34: 252.8 | AR34: 254.2 | AS34: 246.8 | AT34: 257.9 | AU34: 244.2
A35: Amortization | B35: ₹m | C35: 93.96 | D35: 94.75 | E35: 96.33 | F35: 111.59 | G35: 194.98 | H35: 227.45 | I35: 243.34 | J35: 252.03 | K35: 259.15 | L35: 249.43 | M35: 268.26 | N35: 287.12 | O35: 277.95 | P35: 278.86 | Q35: 280.49 | R35: 260.82 | S35: 275.97 | T35: 308.99 | U35: 312.06 | V35: 309.11 | W35: 325.81 | X35: 324.71 | Y35: 343.83 | Z35: 294.37 | AB35: 202.71 | AD35: 280.17 | AE35: 423.04 | AF35: 449.12 | AH35: 404.03 | AI35: 475.72 | AJ35: 446.88 | AK35: 484.1 | AL35: 499.52 | AM35: 500.5 | AN35: 518.1 | AO35: 578.8 | AP35: 551.2 | AQ35: 685.1 | AR35: 746.3 | AS35: 759.1 | AT35: 827.5 | AU35: 908.6
A36: D&A | B36: ₹m | C36: 226.72 | D36: 236.05 | E36: 246.47 | F36: 255.92 | G36: 342.81 | H36: 366.71 | I36: 386.53 | J36: 394.12 | K36: 391.91 | L36: 379.44 | M36: 392.63 | N36: 420.89 | O36: 400.81 | P36: 398.58 | Q36: 396.32 | R36: 376.8 | S36: 386.17 | T36: 424.9 | U36: 428.3 | V36: 420.25 | W36: 435.61 | X36: 439.79 | Y36: 461.05 | Z36: 419.05 | AB36: 370.83 | AD36: 511.35 | AE36: 645.12 | AF36: 693.07 | AH36: 697.25 | AI36: 763.28 | AJ36: 743.97 | AK36: 787.31 | AL36: 799.17 | AM36: 712 | AN36: 745 | AO36: 821.2 | AP36: 791.1 | AQ36: 937.9 | AR36: 1000.5 | AS36: 1005.9 | AT36: 1085.4 | AU36: 1152.8
A37: EBIT | B37: ₹m | C37: 742.36 | D37: 781.46 | E37: 863.98 | F37: 818.1 | G37: 714.7 | H37: 741.08 | I37: 800.02 | J37: 793.38 | K37: 651.67 | L37: 778.38 | M37: 982.54 | N37: 689.74 | O37: 999.65 | P37: 1037.65 | Q37: 1306.85 | R37: 888.7 | S37: 815.76 | T37: 791.55 | U37: 806.01 | V37: 856.6 | W37: 1028.75 | X37: 1217.93 | Y37: 1363.73 | Z37: 1464.24 | AA37: 1665.111 | AB37: 1873.11 | AC37: 2082.98 | AD37: 2300.39 | AE37: 2687.8 | AF37: 2986.57 | AG37: 3332.04 | AH37: 3465.89 | AI37: 3466.16 | AJ37: 3307.65 | AK37: 3631.03 | AL37: 3744.45 | AM37: 3840.2 | AN37: 4062.3 | AO37: 4557.3 | AP37: 5052.9 | AQ37: 5178.1 | AR37: 5837.4 | AS37: 5427.5 | AT37: 6591.6 | AU37: 6868.8
A38: Other income | B38: ₹m | C38: 128.36 | D38: 111.46 | E38: 118.51 | F38: 245.53 | G38: 172.44 | H38: 202.54 | I38: 143.33 | J38: 170.74 | K38: 183.28 | L38: 133.49 | M38: 142.99 | N38: 144.21 | O38: 165.97 | P38: 195.47 | Q38: 229.25 | R38: 282.94 | S38: 202.02 | T38: 226.16 | U38: 231.64 | V38: 229.33 | W38: 279.32 | X38: 207.77 | Y38: 288.11 | Z38: 210.77 | AA38: 256.3821 | AB38: 292.88 | AC38: 251.25 | AD38: 251.28 | AE38: 89.15 | AF38: 60.79 | AG38: 87.02 | AH38: 129.05 | AI38: 154.58 | AJ38: 166.28 | AK38: 181.08 | AL38: 226.02 | AM38: 172.5 | AN38: 176.9 | AO38: 118.4 | AP38: 153.5 | AQ38: 187.3 | AR38: 58.9 | AS38: 300.6 | AT38: 136.3 | AU38: 414.9
A39: FX gain / loss | B39: ₹m | C39: 69.38 | D39: 70.91 | E39: 41.95 | F39: -35.73 | G39: 80.86 | H39: 40.82 | I39: 174.44 | J39: -27.62 | K39: 184.45 | L39: 202.69 | M39: 49.63 | N39: 149.54 | O39: 20.63 | P39: 35.67 | Q39: -240.89 | R39: -58.5 | S39: 79.83 | T39: 137.92 | U39: 102.1 | V39: 44.5 | W39: -87.63 | X39: -50.59 | Y39: -1.74 | Z39: 173.77 | AA39: 109.03173 | AB39: 10.33 | AC39: 29.89 | AD39: 120.16 | AE39: 41.8 | AF39: -91.32 | AG39: 105.37 | AH39: -189.09 | AI39: -64.09 | AJ39: 83.7 | AK39: 80.9 | AL39: -15.54 | AM39: -7.3 | AN39: 106 | AO39: 144.7 | AP39: -154.3 | AQ39: 188.7 | AR39: 272 | AS39: -78.2 | AT39: 11.9 | AU39: -1052.7
A40: PBT | B40: ₹m | C40: 940.1 | D40: 963.83 | E40: 1024.44 | F40: 1027.9 | G40: 968 | H40: 984.44 | I40: 1117.79 | J40: 936.5 | K40: 1019.4 | L40: 1114.56 | M40: 1175.16 | N40: 983.49 | O40: 1186.25 | P40: 1268.79 | Q40: 1295.21 | R40: 1113.14 | S40: 1097.61 | T40: 1155.63 | U40: 1139.75 | V40: 1130.43 | W40: 1220.44 | X40: 1375.11 | Y40: 1650.1 | Z40: 1848.78 | AA40: 2030.521 | AB40: 2176.32 | AC40: 2364.12 | AD40: 2671.83 | AE40: 2818.75 | AF40: 2956.04 | AG40: 3227.88 | AH40: 3405.85 | AI40: 3070.49 | AJ40: 3557.63 | AK40: 3893.01 | AL40: 3954.93 | AM40: 4005.4 | AN40: 4345.2 | AO40: 4820.4 | AP40: 5052.1 | AQ40: 5554.1 | AR40: 6168.3 | AS40: 5649.9 | AT40: 6739.8 | AU40: 6231
A41: Tax | B41: ₹m | C41: 267.94 | D41: 245.34 | E41: 249.55 | F41: 219.83 | G41: 235.14 | H41: 249.51 | I41: 298.88 | J41: 208.55 | K41: 268.51 | L41: 288.33 | M41: 258.46 | N41: 246.43 | O41: 312.77 | P41: 387.38 | Q41: 378.04 | R41: 268.41 | S41: 272.91 | T41: 294.91 | U41: 260.49 | V41: 292.22 | W41: 320.36 | X41: 355.25 | Y41: 440.86 | Z41: 471.19 | AA41: 518.04471 | AB41: 558.79 | AC41: 600.17 | AD41: 661.93 | AE41: 702.63 | AF41: 755.9 | AG41: 848.34 | AH41: 890.72 | AI41: 782.81 | AJ41: 924.95 | AK41: 1031.67 | AL41: 801.71 | AM41: 941.3 | AN41: 1095.2 | AO41: 1090.5 | AP41: 1094.5 | AQ41: 1304.7 | AR41: 1453.6 | AS41: 1255.4 | AT41: 1447.2 | AU41: 1400.6
A42: PAT | B42: ₹m | C42: 672.16 | D42: 718.49 | E42: 774.89 | F42: 808.07 | G42: 732.86 | H42: 734.93 | I42: 818.91 | J42: 727.95 | K42: 750.89 | L42: 826.23 | M42: 916.7 | N42: 737.06 | O42: 873.48 | P42: 881.41 | Q42: 917.17 | R42: 844.73 | S42: 824.7 | T42: 860.72 | U42: 879.26 | V42: 838.21 | W42: 900.08 | X42: 1019.86 | Y42: 1209.24 | Z42: 1377.59 | AA42: 1512.481 | AB42: 1617.53 | AC42: 1763.95 | AD42: 2009.9 | AE42: 2116.12 | AF42: 2200.14 | AG42: 2379.54 | AH42: 2515.13 | AI42: 2287.68 | AJ42: 2632.68 | AK42: 2861.34 | AL42: 3153.22 | AM42: 3064.2 | AN42: 3250 | AO42: 3729.9 | AP42: 3957.6 | AQ42: 4249.4 | AR42: 4714.7 | AS42: 4394.5 | AT42: 5292.6 | AU42: 4830.4
A43: EPS | B43: ₹ / share | C43: 8.45 | AF43: 29.61 | AG43: 31.9 | AH43: 33.65 | AI43: 30.5 | AJ43: 35 | AK43: 37.83 | AL43: 41.46 | AM43: 20.1 | AN43: 21.2 | AO43: 24.3 | AP43: 25.6 | AQ43: 27.4 | AR43: 30.3 | AS43: 28.2 | AT43: 33.8 | AU43: 30.9
A48: Annual reported balance sheet
A49: Metric | B49: Units | C49: FY16A | D49: FY17A | E49: FY18A | F49: FY19A | G49: FY20A | H49: FY21A | I49: FY22A | J49: FY23A | K49: FY24A | L49: FY25A | M49: FY26A
A50: PPE | B50: ppe | C50: 3007.45 | D50: 2768.36 | E50: 2581.3 | F50: 2331.24 | G50: 2224.6 | H50: 2401.4 | I50: 2917.67 | J50: 4859.95 | K50: 4420.03 | L50: 4350.88 | M50: 3968.88
...

Sheet Raw Operating
A1: Raw Reported Operating Metrics
A2: Annual reported KPIs; blanks mean not disclosed under a comparable definition
A5: Metric | B5: Units | C5: FY16A | D5: FY17A | E5: FY18A | F5: FY19A | G5: FY20A | H5: FY21A | I5: FY22A | J5: FY23A | K5: FY24A | L5: FY25A | M5: FY26A | N5: FY27E | O5: FY28E | P5: FY29E | Q5: FY30E
A7: Revenue | B7: $m | C7: 352 | D7: 429 | E7: 471 | F7: 481 | G7: 502 | H7: 566 | I7: 766 | J7: 1036 | K7: 1186 | L7: 1409.1 | M7: 1654.4
A8: Headcount | B8: # | C8: 9264 | D8: 9460 | E8: 8976 | F8: 9962 | G8: 10632 | H8: 13680 | I8: 18599 | J8: 22889 | K8: 23850 | L8: 24594 | M8: 27502
A9: Technical employees | B9: # | L9: 23072 | M9: 25849
A10: Attrition | B10: % | C10: 0.164 | D10: 0.157 | E10: 0.147 | F10: 0.167 | G10: 0.143 | H10: 0.117 | I10: 0.266 | J10: 0.198 | K10: 0.115 | L10: 0.129 | M10: 0.13
A11: Utilization | B11: % | L11: 0.856 | M11: 0.883
A12: TCV bookings | B12: $m | I12: 1222.6 | J12: 1623.6 | K12: 1828.7 | L12: 2103.4 | M12: 2405.3
A13: ACV bookings | B13: $m | I13: 943.1 | J13: 1170.9 | K13: 1296.7 | L13: 1464.1 | M13: 1780.1
A14: North America mix | B14: % | C14: 0.855 | D14: 0.864 | E14: 0.835 | F14: 0.817 | G14: 0.81 | H14: 0.808 | I14: 0.788 | J14: 0.78 | K14: 0.796 | L14: 0.808 | M14: 0.806
A15: Europe mix | B15: % | C15: 0.065 | D15: 0.055 | E15: 0.075 | F15: 0.088 | G15: 0.095 | H15: 0.092 | I15: 0.087 | J15: 0.09 | K15: 0.09 | L15: 0.081 | M15: 0.087
A16: India mix | B16: % | L16: 0.094 | M16: 0.088
A17: ROW / residual mix | B17: % | C17: 0.08 | D17: 0.081 | E17: 0.09 | F17: 0.095 | G17: 0.095 | H17: 0.1 | I17: 0.125 | J17: 0.13 | K17: 0.114 | L17: 0.017 | M17: 0.019
A18: BFSI mix | B18: % | H18: 0.308 | I18: 0.316 | J18: 0.329 | K18: 0.319 | L18: 0.316 | M18: 0.346
A19: Healthcare & Life Sciences mix | B19: % | H19: 0.193 | I19: 0.208 | J19: 0.197 | K19: 0.21 | L19: 0.273 | M19: 0.256
A20: Software, Hi-Tech & Emerging mix | B20: % | H20: 0.499 | I20: 0.476 | J20: 0.474 | K20: 0.471 | L20: 0.411 | M20: 0.398
A21: Top 10 concentration | B21: % | C21: 0.455 | D21: 0.531 | E21: 0.535 | F21: 0.518 | G21: 0.517 | H21: 0.477 | I21: 0.446 | J21: 0.367 | K21: 0.39 | L21: 0.409 | M21: 0.416
A22: Clients $75m+ | B22: # | L22: 4 | M22: 4
A23: Clients $20–50m | B23: # | L23: 6 | M23: 8
A24: Clients $10–20m | B24: # | L24: 11 | M24: 17
A25: Clients $5–10m | B25: # | L25: 34 | M25: 33
A26: Clients $1–5m | B26: # | L26: 136 | M26: 139
A27: Clients $1m+ | B27: # | L27: 191 | M27: 201

Sheet Quarterly P&L
A1: Quarterly Profit & Loss
A4: Metric | B4: Q1 FY16A | C4: Q2 FY16A | D4: Q3 FY16A | E4: Q4 FY16A | F4: Q1 FY17A | G4: Q2 FY17A | H4: Q3 FY17A | I4: Q4 FY17A | J4: Q1 FY18A | K4: Q2 FY18A | L4: Q3 FY18A | M4: Q4 FY18A | N4: Q1 FY19A | O4: Q2 FY19A | P4: Q3 FY19A | Q4: Q4 FY19A | R4: Q1 FY20A | S4: Q2 FY20A | T4: Q3 FY20A | U4: Q4 FY20A | V4: Q1 FY21A | W4: Q2 FY21A | X4: Q3 FY21A | Y4: Q4 FY21A | Z4: Q1 FY22A | AA4: Q2 FY22A | AB4: Q3 FY22A | AC4: Q4 FY22A | AD4: Q1 FY23A | AE4: Q2 FY23A | AF4: Q3 FY23A | AG4: Q4 FY23A | AH4: Q1 FY24A | AI4: Q2 FY24A | AJ4: Q3 FY24A | AK4: Q4 FY24A | AL4: Q1 FY25A | AM4: Q2 FY25A | AN4: Q3 FY25A | AO4: Q4 FY25A | AP4: Q1 FY26A | AQ4: Q2 FY26A | AR4: Q3 FY26A | AS4: Q4 FY26A | AT4: Q1 FY27A
A5: Revenue | B5: 78.61 | C5: 82.96 | D5: 89.65 | E5: 100.43 | F5: 104.76 | G5: 105.18 | H5: 110.03 | I5: 109.03 | J5: 112.97 | K5: 118.1 | L5: 122.53 | M5: 116.95 | N5: 123.6 | O5: 118.23 | P5: 120.84 | Q5: 118.3 | R5: 119.62 | S5: 125.51 | T5: 129.43 | U5: 127.05 | V5: 131.02 | W5: 136.09 | X5: 146.15 | Y5: 152.82 | Z5: 144.93129 | AA5: 182.32 | AB5: 172.68 | AC5: 217.32 | AD5: 241.52 | AE5: 255.56 | AF5: 242.65 | AG5: 274.55 | AH5: 282.9 | AI5: 291.71 | AJ5: 300.55 | AK5: 310.89 | AL5: 328.2 | AM5: 345.5 | AN5: 360.2 | AO5: 375.2 | AP5: 389.7 | AQ5: 406.2 | AR5: 422.5 | AS5: 436 | AT5: 452.4
A6: Average FX | B6: 63.66 | C6: 65.42 | D6: 66.04 | E6: 67.42 | F6: 66.99 | G6: 66.93 | H6: 67.76 | I6: 66.69 | J6: 64.44 | K6: 64.46 | L6: 64.63 | M6: 64.35 | N6: 67.5 | O6: 70.67 | P6: 71.52 | Q6: 70.32 | R6: 69.56 | S6: 70.48 | T6: 71.29 | U6: 72.91 | V6: 75.69 | W6: 74.05 | X6: 73.58 | Y6: 72.85 | Z6: 73.7372 | AA6: 74.11 | AB6: 74.92 | AD6: 77.76 | AE6: 80.16 | AF6: 82.06 | AG6: 82.12 | AH6: 82.05 | AI6: 82.67 | AJ6: 83.12 | AK6: 83.33 | AL6: 83.4 | AM6: 83.9 | AN6: 85 | AO6: 86.4 | AP6: 85.5 | AQ6: 88.2 | AR6: 89.4 | AS6: 93 | AT6: 95.1
A7: Revenue | B7: 5004.16 | C7: 5427.31 | D7: 5920.74 | E7: 6771.1 | F7: 7017.77 | G7: 7040.19 | H7: 7455.35 | I7: 7271.08 | J7: 7280.15 | K7: 7612.52 | L7: 7918.9 | M7: 7525.46 | N7: 8342.81 | O7: 8355.57 | P7: 8642.49 | Q7: 8318.54 | R7: 8321.14 | S7: 8846 | T7: 9227.29 | U7: 9263.65 | V7: 9913.85 | W7: 10077.47 | X7: 10753.98 | Y7: 11133.58 | Z7: 12299.261 | AA7: 13512.49 | AB7: 14917.17 | AC7: 16378.54 | AD7: 18781.11 | AE7: 20486.41 | AF7: 21693.68 | AG7: 22544.72 | AH7: 23211.75 | AI7: 24116.7 | AJ7: 24982.16 | AK7: 25905.26 | AL7: 27371.7 | AM7: 28971.5 | AN7: 30622.8 | AO7: 32421.1 | AP7: 33335.9 | AQ7: 35807.2 | AR7: 37782.1 | AS7: 40559.4 | AT7: 43032.3
A8: QoQ growth | C8: 0.084559646 | D8: 0.090916126 | E8: 0.14362394 | F8: 0.036429827 | G8: 0.003194747 | H8: 0.058969999 | I8: -0.024716479 | J8: 0.0012474075 | K8: 0.045654279 | L8: 0.040246856 | M8: -0.049683668 | N8: 0.1086113 | O8: 0.0015294607 | P8: 0.03433877 | Q8: -0.03748341 | R8: 0.00031255485 | S8: 0.063075492 | T8: 0.043103097 | U8: 0.0039404852 | V8: 0.070188317 | W8: 0.016504184 | X8: 0.067130937 | Y8: 0.035298559 | Z8: 0.10469958 | AA8: 0.098642422 | AB8: 0.10395419 | AC8: 0.097965633 | AD8: 0.14669012 | AE8: 0.09079868 | AF8: 0.058930286 | AG8: 0.039229859 | AH8: 0.029586972 | AI8: 0.03898672 | AJ8: 0.035886336 | AK8: 0.036950368 | AL8: 0.056607809 | AM8: 0.058447228 | AN8: 0.056997394 | AO8: 0.058724219 | AP8: 0.028216193 | AQ8: 0.074133292 | AR8: 0.055153712 | AS8: 0.073508354 | AT8: 0.060969837
A9: YoY growth | F9: 0.40238721 | G9: 0.29717853 | H9: 0.25919226 | I9: 0.073840292 | J9: 0.037387945 | K9: 0.081294681 | L9: 0.062176826 | M9: 0.034985174 | N9: 0.14596677 | O9: 0.097608939 | P9: 0.091375065 | Q9: 0.10538625 | R9: -0.0025974462 | S9: 0.058694978 | T9: 0.067665684 | U9: 0.11361489 | V9: 0.19140526 | W9: 0.13921207 | X9: 0.16545378 | Y9: 0.20185672 | Z9: 0.240614 | AA9: 0.34086135 | AB9: 0.38713016 | AC9: 0.47109375 | AD9: 0.52701124 | AE9: 0.51610917 | AF9: 0.45427584 | AG9: 0.37647922 | AH9: 0.23590938 | AI9: 0.17720479 | AJ9: 0.15158701 | AK9: 0.14906107 | AL9: 0.17921742 | AM9: 0.20130449 | AN9: 0.22578672 | AO9: 0.25152575 | AP9: 0.21789659 | AQ9: 0.23594567 | AR9: 0.23378986 | AS9: 0.25101863 | AT9: 0.2908696
A10: Cost of revenue | B10: 3015.2 | C10: 3313.74 | D10: 3622.39 | E10: 4353.47 | F10: 4584.52 | G10: 4538.51 | H10: 4751.02 | I10: 4643.97 | J10: 4783.17 | K10: 4994.06 | L10: 5008.9 | M10: 4917.99 | N10: 5372.82 | O10: 5409.62 | P10: 5341.15 | Q10: 5254.56 | R10: 5434.02 | S10: 5773.25 | T10: 6157.43 | U10: 6129.63 | V10: 6646.37 | W10: 6576.62 | X10: 7064.21 | Y10: 7363.04 | Z10: 8173.087 | AA10: 8982.03 | AB10: 9880.34 | AC10: 10859.49 | AD10: 12433.14 | AE10: 13628.38 | AF10: 14360.05 | AG10: 14893.75 | AH10: 15278.46 | AI10: 16127.2 | AJ10: 16539.12 | AL10: 18328.7 | AM10: 19294 | AN10: 20000.4 | AO10: 21117 | AP10: 21576.2 | AQ10: 22923.8 | AR10: 25017.8 | AS10: 26246.9 | AT10: 27915.4
A11: Gross profit | B11: 1988.96 | C11: 2113.57 | D11: 2298.35 | E11: 2417.63 | F11: 2433.25 | G11: 2501.68 | H11: 2704.33 | I11: 2627.11 | J11: 2496.98 | K11: 2618.46 | L11: 2910 | M11: 2607.47 | N11: 2969.99 | O11: 2945.95 | P11: 3301.34 | Q11: 3063.98 | R11: 2887.12 | S11: 3072.75 | T11: 3069.86 | U11: 3134.02 | V11: 3267.48 | W11: 3500.85 | X11: 3689.77 | Y11: 3770.54 | Z11: 4126.183 | AA11: 4530.46 | AB11: 5036.83 | AC11: 5519.05 | AD11: 6347.97 | AE11: 6858.03 | AF11: 7333.63 | AG11: 7650.97 | AH11: 7933.29 | AI11: 7989.5 | AJ11: 8443.04 | AK11: 8618.95 | AL11: 9043 | AM11: 9677.5 | AN11: 10622.5 | AO11: 11304.1 | AP11: 11759.7 | AQ11: 12883.4 | AR11: 12764.3 | AS11: 14312.4 | AT11: 15116.9
A12: Gross margin | B12: 0.39746131 | C12: 0.38943233 | D12: 0.38818627 | E12: 0.35705129 | F12: 0.34672695 | G12: 0.35534268 | H12: 0.36273683 | I12: 0.36130946 | J12: 0.34298469 | K12: 0.34396757 | L12: 0.36747528 | M12: 0.34648646 | N12: 0.35599396 | O12: 0.35257319 | P12: 0.38198945 | Q12: 0.36833146 | R12: 0.34696207 | S12: 0.34736039 | T12: 0.33269356 | U12: 0.33831373 | V12: 0.3295874 | W12: 0.34739374 | X12: 0.34310739 | Y12: 0.33866375 | Z12: 0.33548219 | AA12: 0.33527943 | AB12: 0.33765319 | AC12: 0.33696837 | AD12: 0.33799759 | AE12: 0.33475997 | AF12: 0.33805376 | AG12: 0.3393686 | AH12: 0.34177906 | AI12: 0.33128496 | AJ12: 0.33796277 | AK12: 0.33271042 | AL12: 0.33037773 | AM12: 0.33403517 | AN12: 0.34688206 | AO12: 0.34866491 | AP12: 0.35276384 | AQ12: 0.35979915 | AR12: 0.33783988 | AS12: 0.35287504 | AT12: 0.35129194
A13: SG&A | B13: 1019.88 | C13: 1096.06 | D13: 1187.9 | E13: 1343.61 | F13: 1375.74 | G13: 1393.89 | H13: 1517.78 | I13: 1439.61 | J13: 1453.4 | K13: 1460.64 | L13: 1534.83 | M13: 1496.84 | N13: 1569.53 | O13: 1509.72 | P13: 1598.17 | Q13: 1798.48 | R13: 1685.19 | S13: 1856.3 | T13: 1835.55 | U13: 1857.17 | V13: 1803.12 | W13: 1843.13 | X13: 1864.99 | Y13: 1887.25 | Z13: 2110.981 | AA13: 2286.52 | AB13: 2526 | AC13: 2707.31 | AD13: 3015.05 | AE13: 3178.39 | AF13: 3318.08 | AG13: 3487.83 | AH13: 3703.85 | AI13: 3937.88 | AJ13: 4024.7 | AL13: 4490.9 | AM13: 4870.3 | AN13: 5244.1 | AO13: 5460.2 | AP13: 5643.7 | AQ13: 6045.5 | AR13: 6331 | AS13: 6635.4 | AT13: 7095.3
A14: EBITDA | B14: 969.08 | C14: 1017.51 | D14: 1110.45 | E14: 1074.02 | F14: 1057.51 | G14: 1107.79 | H14: 1186.55 | I14: 1187.5 | J14: 1043.58 | K14: 1157.82 | L14: 1375.17 | M14: 1110.63 | N14: 1400.46 | O14: 1436.23 | P14: 1703.17 | Q14: 1265.5 | R14: 1201.93 | S14: 1216.45 | T14: 1234.31 | U14: 1276.85 | V14: 1464.36 | W14: 1657.72 | X14: 1824.78 | Y14: 1883.29 | Z14: 2015.201 | AA14: 2243.94 | AB14: 2510.83 | AC14: 2811.74 | AD14: 3332.92 | AE14: 3679.64 | AF14: 4015.55 | AG14: 4163.14 | AH14: 4229.44 | AI14: 4051.62 | AJ14: 4418.34 | AK14: 4543.62 | AL14: 4552.1 | AM14: 4807.3 | AN14: 5378.4 | AO14: 5843.9 | AP14: 6115.9 | AQ14: 6837.9 | AR14: 6433.3 | AS14: 7677 | AT14: 8021.6
