Workbook

Sheet Summary
A1: TCS — Financial Summary
A4: Profit & Loss Statement | B4: FY16A | C4: FY17A | D4: FY18A | E4: FY19A | F4: FY20A | G4: FY21A | H4: FY22A | I4: FY23A | J4: FY24A | K4: FY25A | L4: FY26A | M4: FY27E | N4: FY28E | O4: FY29E | P4: FY30E | R4: Key Ratios | S4: FY16A | T4: FY17A | U4: FY18A | V4: FY19A | W4: FY20A | X4: FY21A | Y4: FY22A | Z4: FY23A | AA4: FY24A | AB4: FY25A | AC4: FY26A | AD4: FY27E | AE4: FY28E | AF4: FY29E | AG4: FY30E
A5: Revenue | B5: 16544.9 | C5: 17576 | D5: 19089 | E5: 20913 | F5: 22031 | G5: 22174 | H5: 25707 | I5: 27927 | J5: 29080 | K5: 30179 | L5: 30017 | M5: 30925.818 | N5: 32162.851 | O5: 33770.993 | P5: 35459.543 | R5: Revenue growth | S5: =B6 -> 0 | T5: =C6 -> 0.06232132 | U5: =D6 -> 0.086083295 | V5: =E6 -> 0.095552412 | W5: =F6 -> 0.053459571 | X5: =G6 -> 0.0064908538 | Y5: =H6 -> 0.15933075 | Z5: =I6 -> 0.086357801 | ... AG5: =P6 -> 0.05
A6: Growth | B6: 0 | C6: =C5/B5-1 -> 0.06232132 | D6: =D5/C5-1 -> 0.086083295 | E6: =E5/D5-1 -> 0.095552412 | F6: =F5/E5-1 -> 0.053459571 | G6: =G5/F5-1 -> 0.0064908538 | H6: =H5/G5-1 -> 0.15933075 | I6: =I5/H5-1 -> 0.086357801 | J6: =J5/I5-1 -> 0.04128621 | ... P6: =P5/O5-1 -> 0.05 | R6: Gross margin | S6: =B8 -> 0.43947077 | T6: =C8 -> 0.43303368 | U6: =D8 -> 0.42092304 | V6: =E8 -> 0.41854349 | W6: =F8 -> 0.41166266 | X6: =G8 -> 0.40840624 | Y6: =H8 -> 0.40226397 | Z6: =I8 -> 0.39542378 | ... AG6: =P8 -> 0.40206303
A7: Gross profit | B7: 7271 | C7: 7611 | D7: 8035 | E7: 8753 | F7: 9069.34 | G7: 9056 | H7: 10341 | I7: 11043 | J7: 11745 | K7: 11741 | L7: 12027 | M7: 12396.516 | N7: 12910.519 | O7: 13567.079 | P7: 14256.971 | R7: EBITDA margin | S7: =B10 -> 0.28238914 | T7: =C10 -> 0.27389622 | U7: =D10 -> 0.26413118 | V7: =E10 -> 0.26973653 | W7: =F10 -> 0.26825609 | X7: =G10 -> 0.2762695 | Y7: =H10 -> 0.27669506 | Z7: =I10 -> 0.26272066 | ... AG7: =P10 -> 0.27240638
A8: Gross margin | B8: 0.43947077 | C8: 0.43303368 | D8: 0.42092304 | E8: 0.41854349 | F8: 0.41166266 | G8: 0.40840624 | H8: 0.40226397 | I8: 0.39542378 | J8: 0.40388583 | K8: 0.38904536 | L8: 0.40067295 | M8: 0.40084683 | N8: 0.40141089 | O8: 0.40173763 | P8: 0.40206303 | R8: EBIT margin | S8: =B12 -> 0.26501218 | T8: =C12 -> 0.25705508 | U8: =D12 -> 0.24778668 | V8: =E12 -> 0.25567829 | W8: =F12 -> 0.24574463 | X8: =G12 -> 0.25146568 | Y8: =H12 -> 0.25269382 | Z8: =I12 -> 0.2404125 | ... AG8: =P12 -> 0.25206303
A9: EBITDA | B9: 4672.1 | C9: 4814 | D9: 5042 | E9: 5641 | F9: 5909.95 | G9: 6126 | H9: 7113 | I9: 7337 | J9: 7645 | K9: 7967 | L9: 7629 | M9: 8280.7264 | N9: 8740.9613 | O9: 9188.7435 | P9: 9659.4056 | R9: PBT margin | S9: =B14 -> 0.29307521 | T9: =C14 -> 0.29255803 | U9: =D14 -> 0.27696579 | V9: =E14 -> 0.28384259 | W9: =F14 -> 0.26930235 | X9: =G14 -> 0.26670876 | Y9: =H14 -> 0.26957638 | Z9: =I14 -> 0.25230064 | ... AG9: =P14 -> 0.26074588
A10: EBITDA margin | B10: =B9/B5 -> 0.28238914 | C10: =C9/C5 -> 0.27389622 | D10: =D9/D5 -> 0.26413118 | E10: =E9/E5 -> 0.26973653 | F10: =F9/F5 -> 0.26825609 | G10: =G9/G5 -> 0.2762695 | H10: =H9/H5 -> 0.27669506 | I10: =I9/I5 -> 0.26272066 | ... P10: =P9/P5 -> 0.27240638 | R10: Net margin | S10: =B17 -> 0.22287231 | T10: =C17 -> 0.22286072 | U10: =D17 -> 0.20980669 | V10: =E17 -> 0.21489026 | W10: =F17 -> 0.20611865 | X10: =G17 -> 0.19770903 | Y10: =H17 -> 0.19990664 | Z10: =I17 -> 0.18688008 | ... AG10: =P17 -> 0.19561938
A11: EBIT | B11: 4384.6 | C11: 4518 | D11: 4730 | E11: 5347 | F11: 5414 | G11: 5576 | H11: 6496 | I11: 6714 | J11: 7043 | K11: 7348 | L11: 7003 | M11: 7647.5676 | N11: 8086.091 | O11: 8501.4297 | P11: 8938.0397 | R11: CFO / net income | S11: =IFERROR(B28/B16,0) -> 0.86402343 | T11: =IFERROR(C28/C16,0) -> 1.0270615 | U11: =IFERROR(D28/D16,0) -> 1.0911361 | V11: =IFERROR(E28/E16,0) -> 1.0062305 | W11: =IFERROR(F28/F16,0) -> 1.0944726 | X11: =IFERROR(G28/G16,0) -> 1.2673358 | Y11: =IFERROR(H28/H16,0) -> 1.1000195 | Z11: =IFERROR(I28/I16,0) -> 1.0557578 | ... AG11: =IFERROR(P28/P16,0) -> 1.1137686
A12: EBIT margin | B12: 0.26501218 | C12: 0.25705508 | D12: 0.24778668 | E12: 0.25567829 | F12: 0.24574463 | G12: 0.25146568 | H12: 0.25269382 | I12: 0.2404125 | J12: 0.24219395 | K12: 0.24348057 | L12: 0.23330113 | M12: 0.24728748 | N12: 0.25141089 | O12: 0.25173763 | P12: 0.25206303 | R12: FCF margin | S12: =IFERROR((B28+B29)/B5,0) -> 0.17443442 | T12: =IFERROR((C28+C29)/C5,0) -> 0.21199363 | U12: =IFERROR((D28+D29)/D5,0) -> 0.21378805 | V12: =IFERROR((E28+E29)/E5,0) -> 0.20097547 | W12: =IFERROR((F28+F29)/F5,0) -> 0.20502928 | X12: =IFERROR((G28+G29)/G5,0) -> 0.23117164 | Y12: =IFERROR((H28+H29)/H5,0) -> 0.20434123 | Z12: =IFERROR((I28+I29)/I5,0) -> 0.18354997 | ... AG12: =IFERROR((P28+P29)/P5,0) -> 0.2006019
A13: PBT | B13: =B12/B5 -> 1.6017756e-05 | C13: =C12/C5 -> 1.4625346e-05 | D13: =D12/D5 -> 1.2980601e-05 | E13: =E12/E5 -> 1.2225806e-05 | F13: =F12/F5 -> 1.1154493e-05 | G13: =G12/G5 -> 1.1340565e-05 | H13: =H12/H5 -> 9.8297669e-06 | I13: =I12/I5 -> 8.6086047e-06 | ... P13: =P12/P5 -> 7.108468e-06 | R13: Net cash / revenue | S13: =IFERROR(B62/B5,0) -> 0.057419507 | T13: =IFERROR(C62/C5,0) -> 0.031577151 | U13: =IFERROR(D62/D5,0) -> 0.039342029 | V13: =IFERROR(E62/E5,0) -> 0.049968919 | W13: =IFERROR(F62/F5,0) -> 0.052017612 | X13: =IFERROR(G62/G5,0) -> 0.042121403 | Y13: =IFERROR(H62/H5,0) -> 0.064184852 | Z13: =IFERROR(I62/I5,0) -> 0.031009417 | ... AG13: =IFERROR(P62/P5,0) -> 0.14069643
A14: PBT margin | B14: 0.29307521 | C14: 0.29255803 | D14: 0.27696579 | E14: 0.28384259 | F14: 0.26930235 | G14: 0.26670876 | H14: 0.26957638 | I14: 0.25230064 | J14: 0.25735901 | K14: 0.25587329 | L14: 0.24662691 | M14: 0.26391737 | N14: 0.26134603 | O14: 0.26087921 | P14: 0.26074588 | S14: =B10 -> 0.28238914 | T14: =C10 -> 0.27389622 | U14: =D10 -> 0.26413118 | V14: =E10 -> 0.26973653 | W14: =F10 -> 0.26825609 | X14: =G10 -> 0.2762695 | Y14: =H10 -> 0.27669506 | Z14: =I10 -> 0.26272066 | ... AG14: =P10 -> 0.27240638
A15: Income tax | B15: 1142.4 | C15: 1215 | D15: 1273 | E15: 1428 | F15: 1377 | G15: 1513 | H15: 1775 | I15: 1808 | J15: 1919 | K15: 1954 | L15: 1842 | M15: 2007.8177 | N15: 2067.7858 | O15: 2167.2969 | P15: 2274.4987 | S15: =B12 -> 0.26501218 | T15: =C12 -> 0.25705508 | U15: =D12 -> 0.24778668 | V15: =E12 -> 0.25567829 | W15: =F12 -> 0.24574463 | X15: =G12 -> 0.25146568 | Y15: =H12 -> 0.25269382 | Z15: =I12 -> 0.2404125 | ... AG15: =P12 -> 0.25206303
A16: Net profit | B16: 3687.4 | C16: 3917 | D16: 4005 | E16: 4494 | F16: 4541 | G16: 4384 | H16: 5139 | I16: 5219 | J16: 5542 | K16: 5739 | L16: 5534 | M16: 6123.2727 | N16: 6306.1582 | O16: 6609.639 | P16: 6936.5739 | S16: =B14 -> 0.29307521 | T16: =C14 -> 0.29255803 | U16: =D14 -> 0.27696579 | V16: =E14 -> 0.28384259 | W16: =F14 -> 0.26930235 | X16: =G14 -> 0.26670876 | Y16: =H14 -> 0.26957638 | Z16: =I14 -> 0.25230064 | ... AG16: =P14 -> 0.26074588
A17: Net margin | B17: 0.22287231 | C17: 0.22286072 | D17: 0.20980669 | E17: 0.21489026 | F17: 0.20611865 | G17: 0.19770903 | H17: 0.19990664 | I17: 0.18688008 | J17: 0.19057772 | K17: 0.19016535 | L17: 0.18436219 | M17: 0.19799873 | N17: 0.19606963 | O17: 0.19571941 | P17: 0.19561938 | S17: =B17 -> 0.22287231 | T17: =C17 -> 0.22286072 | U17: =D17 -> 0.20980669 | V17: =E17 -> 0.21489026 | W17: =F17 -> 0.20611865 | X17: =G17 -> 0.19770903 | Y17: =H17 -> 0.19990664 | Z17: =I17 -> 0.18688008 | ... AG17: =P17 -> 0.19561938
A18: EPS | B18: 1.88 | C18: 1.99 | D18: 2.08 | E18: 1.19 | F18: 1.21 | G18: 1.21 | H18: 1.39 | I18: 1.43 | J18: 1.54 | K18: 1.59 | L18: 1.64 | M18: 1.6924001 | N18: 1.7429475 | O18: 1.8268259 | P18: 1.9171869
S20: =B63 -> 0 | T20: =C63 -> 0 | U20: =D63 -> 0 | V20: =E63 -> 0 | W20: =F63 -> 0 | X20: =G63 -> 0 | Y20: =H63 -> 0 | Z20: =I63 -> 0 | ... AG20: =P63 -> 0
S22: =B42 -> 0.12910323 | T22: =C42 -> 0.071916249 | U22: =D42 -> 0.2260988 | V22: =E42 -> 0.20212308 | W22: =F42 -> 0.25405111 | X22: =G42 -> 0.18494633 | Y22: =H42 -> 0.19920644 | Z22: =I42 -> 0.18150893 | ... AG22: =P42 -> 0.2006019
A24: Cash Flow Statement | B24: FY16A | C24: FY17A | D24: FY18A | E24: FY19A | F24: FY20A | G24: FY21A | H24: FY22A | I24: FY23A | J24: FY24A | K24: FY25A | L24: FY26A | M24: FY27E | N24: FY28E | O24: FY29E | P24: FY30E
A25: Profit incl. NCI | B25: 3707 | C25: 3927 | D25: 4014 | E25: 4508 | F25: 4556 | G25: 4401 | H25: 5155 | I25: 5238 | J25: 5565 | K25: 5768 | L25: 5561 | M25: 6154.0429 | N25: 6337.8474 | O25: 6642.8532 | P25: 6971.4311
A26: D&A | B26: 288 | C26: 296 | D26: 312 | E26: 294 | F26: 495 | G26: 549 | H26: 617 | I26: 622 | J26: 602 | K26: 619 | L26: 626 | M26: 633.15877 | N26: 654.87026 | O26: 687.31384 | P26: 721.3659
A27: Other non-cash / reclassification | B27: 1088 | C27: 1241 | D27: 1226 | E27: 1474 | F27: 1371 | G27: 1686 | H27: 1773 | I27: 1800 | J27: 1924 | K27: 1964 | L27: 1880 | M27: 0 | N27: 0 | O27: 0 | P27: 0
A28: CFO | B28: 3186 | C28: 4023 | D28: 4370 | E28: 4522 | F28: 4970 | G28: 5556 | H28: 5653 | I28: 5510 | J28: 5662 | K28: 6078 | L28: 6143 | M28: 7614.6273 | N28: 6625.9366 | O28: 7319.7101 | P28: 7725.7382
A29: Capex | B29: -300 | C29: -297 | D29: -289 | E29: -319 | F29: -453 | G29: -430 | H29: -400 | I29: -384 | J29: -324 | K29: -465 | L29: -480 | M29: -807.99004 | N29: -506.31144 | O29: -700.85037 | P29: -612.48663
A30: CFI | B30: -1050 | C30: -2759 | D30: -54 | E30: -295 | F30: 627 | G30: -1455 | H30: -532 | I30: -441 | J30: 323 | K30: -699 | L30: -1954 | M30: -807.99004 | N30: -506.31144 | O30: -700.85037 | P30: -612.48663
A31: CFF | B31: -1499 | C31: -1635 | D31: -4169 | E31: -3891 | F31: -5476 | G31: -4350 | H31: -4375 | I31: -5849 | J31: -5767 | K31: -5453 | L31: -4611 | M31: -5389.6823 | N31: -5433.0161 | O31: -5584.8856 | P31: -5939.7587
A32: Net change before FX | B32: 637 | C32: -371 | D32: 147 | E32: 336 | F32: 121 | G32: -249 | H32: 746 | I32: -780 | J32: 218 | K32: -74 | L32: -422 | M32: 1416.955 | N32: 686.60914 | O32: 1033.9741 | P32: 1173.4929
A33: FX effect | B33: 15 | C33: -24 | D33: 49 | E33: -42 | F33: -20 | G33: 37 | H33: -30 | I33: -4 | J33: -3 | K33: -31 | L33: 124 | M33: 0 | N33: 0 | O33: 0 | P33: 0
A34: Opening cash | B34: 298 | C34: 950 | D34: 555 | E34: 751 | F34: 1045 | G34: 1146 | H34: 934 | I34: 1650 | J34: 866 | K34: 1081 | L34: 976 | M34: 678 | N34: 2094.955 | O34: 2781.5641 | P34: 3815.5382
A35: Closing cash | B35: 950 | C35: 555 | D35: 751 | E35: 1045 | F35: 1146 | G35: 934 | H35: 1650 | I35: 866 | J35: 1081 | K35: 976 | L35: 678 | M35: 2094.955 | N35: 2781.5641 | O35: 3815.5382 | P35: 4989.0312
S38: =IF(S37>0,S37*B21,0) -> 0 | T38: =IF(T37>0,T37*C21,0) -> 0 | U38: =IF(U37>0,U37*D21,0) -> 0 | V38: =IF(V37>0,V37*E21,0) -> 0 | W38: =IF(W37>0,W37*F21,0) -> 0 | X38: =IF(X37>0,X37*G21,0) -> 0 | Y38: =IF(Y37>0,Y37*H21,0) -> 0 | Z38: =IF(Z37>0,Z37*I21,0) -> 0 | ... AG38: =IF(AG37>0,AG37*P21,0) -> 0
S39: =IF(S37>0,S38+B55-B46,0) -> 0 | T39: =IF(T37>0,T38+C55-C46,0) -> 0 | U39: =IF(U37>0,U38+D55-D46,0) -> 0 | V39: =IF(V37>0,V38+E55-E46,0) -> 0 | W39: =IF(W37>0,W38+F55-F46,0) -> 0 | X39: =IF(X37>0,X38+G55-G46,0) -> 0 | Y39: =IF(Y37>0,Y38+H55-H46,0) -> 0 | Z39: =IF(Z37>0,Z38+I55-I46,0) -> 0 | ... AG39: =IF(AG37>0,AG38+P55-P46,0) -> 0
S40: =IF(S37>0,IFERROR(S37/B19,0),0) -> 0 | T40: =IF(T37>0,IFERROR(T37/C19,0),0) -> 0 | U40: =IF(U37>0,IFERROR(U37/D19,0),0) -> 0 | V40: =IF(V37>0,IFERROR(V37/E19,0),0) -> 0 | W40: =IF(W37>0,IFERROR(W37/F19,0),0) -> 0 | X40: =IF(X37>0,IFERROR(X37/G19,0),0) -> 0 | Y40: =IF(Y37>0,IFERROR(Y37/H19,0),0) -> 0 | Z40: =IF(Z37>0,IFERROR(Z37/I19,0),0) -> 0 | ... AG40: =IF(AG37>0,IFERROR(AG37/P19,0),0) -> 0
B41: =B28+B30 -> 2136 | C41: =C28+C30 -> 1264 | D41: =D28+D30 -> 4316 | E41: =E28+E30 -> 4227 | F41: =F28+F30 -> 5597 | G41: =G28+G30 -> 4101 | H41: =H28+H30 -> 5121 | I41: =I28+I30 -> 5069 | ... P41: =P28+P30 -> 7113.2516 | S41: =IF(S37>0,IFERROR(S39/B9,0),0) -> 0 | T41: =IF(T37>0,IFERROR(T39/C9,0),0) -> 0 | U41: =IF(U37>0,IFERROR(U39/D9,0),0) -> 0 | V41: =IF(V37>0,IFERROR(V39/E9,0),0) -> 0 | W41: =IF(W37>0,IFERROR(W39/F9,0),0) -> 0 | X41: =IF(X37>0,IFERROR(X39/G9,0),0) -> 0 | Y41: =IF(Y37>0,IFERROR(Y39/H9,0),0) -> 0 | Z41: =IF(Z37>0,IFERROR(Z39/I9,0),0) -> 0 | ... AG41: =IF(AG37>0,IFERROR(AG39/P9,0),0) -> 0
B42: =IFERROR(B41/B5,0) -> 0.12910323 | C42: =IFERROR(C41/C5,0) -> 0.071916249 | D42: =IFERROR(D41/D5,0) -> 0.2260988 | E42: =IFERROR(E41/E5,0) -> 0.20212308 | F42: =IFERROR(F41/F5,0) -> 0.25405111 | G42: =IFERROR(G41/G5,0) -> 0.18494633 | H42: =IFERROR(H41/H5,0) -> 0.19920644 | I42: =IFERROR(I41/I5,0) -> 0.18150893 | ... P42: =IFERROR(P41/P5,0) -> 0.2006019 | S42: =IF(S37>0,IFERROR(S38/B60,0),0) -> 0 | T42: =IF(T37>0,IFERROR(T38/C60,0),0) -> 0 | U42: =IF(U37>0,IFERROR(U38/D60,0),0) -> 0 | V42: =IF(V37>0,IFERROR(V38/E60,0),0) -> 0 | W42: =IF(W37>0,IFERROR(W38/F60,0),0) -> 0 | X42: =IF(X37>0,IFERROR(X38/G60,0),0) -> 0 | Y42: =IF(Y37>0,IFERROR(Y38/H60,0),0) -> 0 | Z42: =IF(Z37>0,IFERROR(Z38/I60,0),0) -> 0 | ... AG42: =IF(AG37>0,IFERROR(AG38/P60,0),0) -> 0
S44: =IF(S37>0,IFERROR(S43/S37,0),0) -> 0 | T44: =IF(T37>0,IFERROR(T43/T37,0),0) -> 0 | U44: =IF(U37>0,IFERROR(U43/U37,0),0) -> 0 | V44: =IF(V37>0,IFERROR(V43/V37,0),0) -> 0 | W44: =IF(W37>0,IFERROR(W43/W37,0),0) -> 0 | X44: =IF(X37>0,IFERROR(X43/X37,0),0) -> 0 | Y44: =IF(Y37>0,IFERROR(Y43/Y37,0),0) -> 0 | Z44: =IF(Z37>0,IFERROR(Z43/Z37,0),0) -> 0 | ... AG44: =IF(AG37>0,IFERROR(AG43/AG37,0),0) -> 0
A45: Balance Sheet | B45: FY16A | C45: FY17A | D45: FY18A | E45: FY19A | F45: FY20A | G45: FY21A | H45: FY22A | I45: FY23A | J45: FY24A | K45: FY25A | L45: FY26A | M45: FY27E | N45: FY28E | O45: FY29E | P45: FY30E | R45: Revenue Build — Billable-employee Revenue + AI Revenue | S45: FY16A | T45: FY17A | U45: FY18A | V45: FY19A | W45: FY20A | X45: FY21A | Y45: FY22A | Z45: FY23A | AA45: FY24A | AB45: FY25A | AC45: FY26A | AD45: FY27E | AE45: FY28E | AF45: FY29E | AG45: FY30E
A46: Cash & equivalents | B46: 950 | C46: 555 | D46: 751 | E46: 1045 | F46: 1146 | G46: 934 | H46: 1650 | I46: 866 | J46: 1081 | K46: 976 | L46: 678 | M46: 2094.955 | N46: 2781.5641 | O46: 3815.5382 | P46: 4989.0312 | R46: Billable-employee revenue | S46: ='Revenue Drivers'!B20 -> 16544.9 | T46: ='Revenue Drivers'!C20 -> 17576 | U46: ='Revenue Drivers'!D20 -> 19089 | V46: ='Revenue Drivers'!E20 -> 20913 | W46: ='Revenue Drivers'!F20 -> 22031 | X46: ='Revenue Drivers'!G20 -> 22174 | Y46: ='Revenue Drivers'!H20 -> 25707 | Z46: ='Revenue Drivers'!I20 -> 27927 | ... AG46: ='Revenue Drivers'!P20 -> 31351.746
A47: Trade receivables | B47: 3634 | C47: 3488 | D47: 3835 | E47: 3955 | F47: 4047 | G47: 4098 | H47: 4501 | I47: 4992 | J47: 5328 | K47: 5869 | L47: 6092 | M47: 6267.6527 | N47: 6518.3588 | O47: 6844.2768 | P47: 7186.4906 | R47: AI revenue | S47: ='Revenue Drivers'!B21 -> 0 | T47: ='Revenue Drivers'!C21 -> 0 | U47: ='Revenue Drivers'!D21 -> 0 | V47: ='Revenue Drivers'!E21 -> 0 | W47: ='Revenue Drivers'!F21 -> 0 | X47: ='Revenue Drivers'!G21 -> 0 | Y47: ='Revenue Drivers'!H21 -> 0 | Z47: ='Revenue Drivers'!I21 -> 0 | ... AG47: ='Revenue Drivers'!P21 -> 4107.7968
A48: Other current assets | B48: 331 | C48: 354 | D48: 402 | E48: 877 | F48: 1090 | G48: 1532 | H48: 1344 | I48: 1185 | J48: 1475 | K48: 1730 | L48: 1747 | M48: 1051.1168 | N48: 1093.1615 | O48: 1147.8196 | P48: 1205.2105 | R48: Total modelled revenue | S48: =SUM(S46:S47) -> 16544.9 | T48: =SUM(T46:T47) -> 17576 | U48: =SUM(U46:U47) -> 19089 | V48: =SUM(V46:V47) -> 20913 | W48: =SUM(W46:W47) -> 22031 | X48: =SUM(X46:X47) -> 22174 | Y48: =SUM(Y46:Y47) -> 25707 | Z48: =SUM(Z46:Z47) -> 27927 | ... AG48: =SUM(AG46:AG47) -> 35459.543
...

Sheet Assumptions
A1: TCS — Assumptions | R1: FY27 Quarterly Assumptions
A4: Annual Assumptions | B4: FY16A | C4: FY17A | D4: FY18A | E4: FY19A | F4: FY20A | G4: FY21A | H4: FY22A | I4: FY23A | J4: FY24A | K4: FY25A | L4: FY26A | M4: FY27E | N4: FY28E | O4: FY29E | P4: FY30E | R4: Driver | S4: Q1 FY27A | T4: Q2 FY27E | U4: Q3 FY27E | V4: Q4 FY27E
A5: Revenue growth | B5: 0 | C5: =IFERROR(Annual_Statements!C9/Annual_Statements!B9-1,0) -> 0.06232132 | D5: =IFERROR(Annual_Statements!D9/Annual_Statements!C9-1,0) -> 0.086083295 | E5: =IFERROR(Annual_Statements!E9/Annual_Statements!D9-1,0) -> 0.095552412 | F5: =IFERROR(Annual_Statements!F9/Annual_Statements!E9-1,0) -> 0.053459571 | G5: =IFERROR(Annual_Statements!G9/Annual_Statements!F9-1,0) -> 0.0064908538 | H5: =IFERROR(Annual_Statements!H9/Annual_Statements!G9-1,0) -> 0.15933075 | I5: =IFERROR(Annual_Statements!I9/Annual_Statements!H9-1,0) -> 0.086357801 | J5: =IFERROR(Annual_Statements!J9/Annual_Statements!I9-1,0) -> 0.04128621 | ... P5: =IFERROR(Annual_Statements!P9/Annual_Statements!O9-1,0) -> 0.05 | R5: Sequential revenue growth | S5: 0.004 | T5: 0.008 | U5: 0.01 | V5: 0.012
A6: Cost of revenue / revenue | B6: =IFERROR(Annual_Statements!B18/Annual_Statements!B9,0) -> 0.56052923 | C6: =IFERROR(Annual_Statements!C18/Annual_Statements!C9,0) -> 0.56696632 | D6: =IFERROR(Annual_Statements!D18/Annual_Statements!D9,0) -> 0.57907696 | E6: =IFERROR(Annual_Statements!E18/Annual_Statements!E9,0) -> 0.58145651 | F6: =IFERROR(Annual_Statements!F18/Annual_Statements!F9,0) -> 0.58833734 | G6: =IFERROR(Annual_Statements!G18/Annual_Statements!G9,0) -> 0.59159376 | H6: =IFERROR(Annual_Statements!H18/Annual_Statements!H9,0) -> 0.59773603 | I6: =IFERROR(Annual_Statements!I18/Annual_Statements!I9,0) -> 0.60457622 | ... N6: =IFERROR(Annual_Statements!N18/Annual_Statements!N9,0) -> 0.59858911 | O6: 0.59826237 | P6: 0.59793697 | R6: Operating margin | S6: 0.239 | T6: 0.245 | U6: 0.25 | V6: 0.255
A7: SG&A / revenue | B7: =IFERROR(Annual_Statements!B29/Annual_Statements!B9,0) -> 0.17445859 | C7: =IFERROR(Annual_Statements!C29/Annual_Statements!C9,0) -> 0.17597861 | D7: =IFERROR(Annual_Statements!D29/Annual_Statements!D9,0) -> 0.17313636 | E7: =IFERROR(Annual_Statements!E29/Annual_Statements!E9,0) -> 0.1628652 | F7: =IFERROR(Annual_Statements!F29/Annual_Statements!F9,0) -> 0.16591802 | G7: =IFERROR(Annual_Statements!G29/Annual_Statements!G9,0) -> 0.15694056 | H7: =IFERROR(Annual_Statements!H29/Annual_Statements!H9,0) -> 0.14957016 | I7: =IFERROR(Annual_Statements!I29/Annual_Statements!I9,0) -> 0.15501128 | ... P7: =IFERROR(Annual_Statements!P29/Annual_Statements!P9,0) -> 0.15 | R7: Tax rate | S7: 0.252 | T7: 0.25 | U7: 0.25 | V7: 0.25
A8: Other income / revenue | B8: =IFERROR(Annual_Statements!B32/Annual_Statements!B9,0) -> 0.028063028 | C8: =IFERROR(Annual_Statements!C32/Annual_Statements!C9,0) -> 0.035502959 | D8: =IFERROR(Annual_Statements!D32/Annual_Statements!D9,0) -> 0.029179108 | E8: =IFERROR(Annual_Statements!E32/Annual_Statements!E9,0) -> 0.0281643 | F8: =IFERROR(Annual_Statements!F32/Annual_Statements!F9,0) -> 0.023557714 | G8: =IFERROR(Annual_Statements!G32/Annual_Statements!G9,0) -> 0.015243077 | H8: =IFERROR(Annual_Statements!H32/Annual_Statements!H9,0) -> 0.016882561 | I8: =IFERROR(Annual_Statements!I32/Annual_Statements!I9,0) -> 0.011888137 | ... P8: =IFERROR(Annual_Statements!P32/Annual_Statements!P9,0) -> 0.0086828577 | R8: HyperVault revenue | S8: 0 | T8: 0 | U8: 0 | V8: 0
A9: Tax rate | B9: =IFERROR(Annual_Statements!B34/Annual_Statements!B33,0) -> 0.23559983 | C9: =IFERROR(Annual_Statements!C34/Annual_Statements!C33,0) -> 0.23628938 | D9: =IFERROR(Annual_Statements!D34/Annual_Statements!D33,0) -> 0.24077927 | E9: =IFERROR(Annual_Statements!E34/Annual_Statements!E33,0) -> 0.24056604 | F9: =IFERROR(Annual_Statements!F34/Annual_Statements!F33,0) -> 0.23209169 | G9: =IFERROR(Annual_Statements!G34/Annual_Statements!G33,0) -> 0.25583362 | H9: =IFERROR(Annual_Statements!H34/Annual_Statements!H33,0) -> 0.25613276 | I9: =IFERROR(Annual_Statements!I34/Annual_Statements!I33,0) -> 0.25659949 | ... P9: =IFERROR(Annual_Statements!P34/Annual_Statements!P33,0) -> 0.246
A10: NCI / profit incl. NCI | B10: =IFERROR(Annual_Statements!B37/Annual_Statements!B36,0) -> 0.0051262681 | C10: =IFERROR(Annual_Statements!C37/Annual_Statements!C36,0) -> 0.0025464731 | D10: =IFERROR(Annual_Statements!D37/Annual_Statements!D36,0) -> 0.0022421525 | E10: =IFERROR(Annual_Statements!E37/Annual_Statements!E36,0) -> 0.0031055901 | F10: =IFERROR(Annual_Statements!F37/Annual_Statements!F36,0) -> 0.0032923617 | G10: =IFERROR(Annual_Statements!G37/Annual_Statements!G36,0) -> 0.0038627585 | H10: =IFERROR(Annual_Statements!H37/Annual_Statements!H36,0) -> 0.0031037827 | I10: =IFERROR(Annual_Statements!I37/Annual_Statements!I36,0) -> 0.0036273387 | ... P10: =IFERROR(Annual_Statements!P37/Annual_Statements!P36,0) -> 0.005
A11: D&A / revenue | B11: =IFERROR(Annual_Statements!B41/Annual_Statements!B9,0) -> 0.017376956 | C11: =IFERROR(Annual_Statements!C41/Annual_Statements!C9,0) -> 0.016841147 | D11: =IFERROR(Annual_Statements!D41/Annual_Statements!D9,0) -> 0.016344492 | E11: =IFERROR(Annual_Statements!E41/Annual_Statements!E9,0) -> 0.014058241 | F11: =IFERROR(Annual_Statements!F41/Annual_Statements!F9,0) -> 0.022511461 | G11: =IFERROR(Annual_Statements!G41/Annual_Statements!G9,0) -> 0.024803824 | H11: =IFERROR(Annual_Statements!H41/Annual_Statements!H9,0) -> 0.024001245 | I11: =IFERROR(Annual_Statements!I41/Annual_Statements!I9,0) -> 0.022308161 | ... P11: =IFERROR(Annual_Statements!P41/Annual_Statements!P9,0) -> 0.02034335
A12: Capex / revenue | B12: =IFERROR(-Annual_Statements!B119/Annual_Statements!B9,0) -> 0.018132476 | C12: =IFERROR(-Annual_Statements!C119/Annual_Statements!C9,0) -> 0.016898043 | D12: =IFERROR(-Annual_Statements!D119/Annual_Statements!D9,0) -> 0.015139609 | E12: =IFERROR(-Annual_Statements!E119/Annual_Statements!E9,0) -> 0.01525367 | F12: =IFERROR(-Annual_Statements!F119/Annual_Statements!F9,0) -> 0.020561935 | G12: =IFERROR(-Annual_Statements!G119/Annual_Statements!G9,0) -> 0.019392081 | H12: =IFERROR(-Annual_Statements!H119/Annual_Statements!H9,0) -> 0.015559964 | I12: =IFERROR(-Annual_Statements!I119/Annual_Statements!I9,0) -> 0.013750134 | ... P12: =IFERROR(-Annual_Statements!P119/Annual_Statements!P9,0) -> 0.017272829
A13: Dividend payout | B13: 0 | C13: 0 | D13: 0 | E13: 0 | F13: 0 | G13: 0 | H13: 0 | I13: 0 | J13: 0 | K13: 0 | L13: 0 | M13: 0.72 | N13: 0.72 | O13: 0.72 | P13: 0.72
A14: HyperVault capacity commissioned (MW) | B14: 0 | C14: 0 | D14: 0 | E14: 0 | F14: 0 | G14: 0 | H14: 0 | I14: 0 | J14: 0 | K14: 0 | L14: 0 | M14: 100 | N14: 150 | O14: 250 | P14: 250
A15: HyperVault funding deployment | B15: 0 | C15: 0 | D15: 0 | E15: 0 | F15: 0 | G15: 0 | H15: 0 | I15: 0 | J15: 0 | K15: 0 | L15: 0 | M15: 0.1 | N15: 0.2 | O15: 0.3 | P15: 0.25
A16: HyperVault utilization | B16: 0 | C16: 0 | D16: 0 | E16: 0 | F16: 0 | G16: 0 | H16: 0 | I16: 0 | J16: 0 | K16: 0 | L16: 0 | M16: 0 | N16: 0 | O16: 0 | P16: 0
A17: HyperVault revenue / MW (₹ cr) | B17: 0 | C17: 0 | D17: 0 | E17: 0 | F17: 0 | G17: 0 | H17: 0 | I17: 0 | J17: 0 | K17: 0 | L17: 0 | M17: 0 | N17: 0 | O17: 0 | P17: 0
A18: HyperVault EBITDA margin | B18: 0 | C18: 0 | D18: 0 | E18: 0 | F18: 0 | G18: 0 | H18: 0 | I18: 0 | J18: 0 | K18: 0 | L18: 0 | M18: 0 | N18: 0 | O18: 0 | P18: 0
A20: HyperVault economics not disclosed by TCS are explicitly set to zero; these are editable scenario inputs, not missing data.
A22: AI run-rate growth — Q2 FY27E | M22: 0 | N22: 0.08 | O22: 0.08 | P22: 0.08
A23: AI run-rate growth — Q3 FY27E | M23: 0 | N23: 0.07 | O23: 0.07 | P23: 0.07
A24: AI run-rate growth — Q4 FY27E | M24: 0 | N24: 0.06 | O24: 0.06 | P24: 0.06

Sheet Revenue Drivers
A1: Annual Revenue Drivers — Core TCS + HyperVault | R1: Quarterly Revenue Bridge — Billable-employee Revenue + AI Revenue
A4: Metric | B4: FY16A | C4: FY17A | D4: FY18A | E4: FY19A | F4: FY20A | G4: FY21A | H4: FY22A | I4: FY23A | J4: FY24A | K4: FY25A | L4: FY26A | M4: FY27E | N4: FY28E | O4: FY29E | P4: FY30E | R4: Q1 FY26A | S4: Q2 FY26A* | T4: Q3 FY26A | U4: Q4 FY26A | V4: Q1 FY27A | W4: Q2 FY27E | X4: Q3 FY27E | Y4: Q4 FY27E
A5: Revenue | B5: 16544.9 | C5: 17576 | D5: 19089 | E5: 20913 | F5: 22031 | G5: 22174 | H5: 25707 | I5: 27927 | J5: 29080 | K5: 30179 | L5: 30017 | M5: 30925.818 | N5: 32162.851 | O5: 33770.993 | P5: 35459.543 | Q5: Total revenue | R5: 7421 | S5: 7466 | T5: 7509 | U5: 7621 | V5: 7624 | W5: 7685 | X5: 7762 | Y5: 7855
A6: Growth | B6: 0 | C6: =IFERROR(C5/B5-1,0) -> 0.06232132 | D6: =IFERROR(D5/C5-1,0) -> 0.086083295 | E6: =IFERROR(E5/D5-1,0) -> 0.095552412 | F6: =IFERROR(F5/E5-1,0) -> 0.053459571 | G6: =IFERROR(G5/F5-1,0) -> 0.0064908538 | H6: =IFERROR(H5/G5-1,0) -> 0.15933075 | I6: =IFERROR(I5/H5-1,0) -> 0.086357801 | J6: =IFERROR(J5/I5-1,0) -> 0.04128621 | ... P6: =IFERROR(P5/O5-1,0) -> 0.05 | Q6: Annualized AI run-rate | R6: 1308.207 | S6: 1534.5269 | T6: 1800 | U6: 2300 | V6: 2600 | W6: 2808 | X6: 3004.56 | Y6: 3184.8336
A7: Total headcount | B7: 353843 | C7: 387223 | D7: 394998 | E7: 424285 | F7: 448464 | G7: 488649 | H7: 592195 | I7: 614795 | J7: 601546 | K7: 607979 | L7: 584519 | M7: 593798 | N7: 593798 | O7: 593798 | P7: 593798 | Q7: Quarterly AI revenue proxy | R7: 327.05176 | S7: 383.63171 | T7: 450 | U7: 575 | V7: 650 | W7: 702 | X7: 751.14 | Y7: 796.2084
A8: Headcount growth | B8: 0 | C8: =IFERROR(C7/B7-1,0) -> 0.094335623 | D8: =IFERROR(D7/C7-1,0) -> 0.020078869 | E8: =IFERROR(E7/D7-1,0) -> 0.074144679 | F8: =IFERROR(F7/E7-1,0) -> 0.056987638 | G8: =IFERROR(G7/F7-1,0) -> 0.089605855 | H8: =IFERROR(H7/G7-1,0) -> 0.21190261 | I8: =IFERROR(I7/H7-1,0) -> 0.038163105 | J8: =IFERROR(J7/I7-1,0) -> -0.021550273 | ... P8: =IFERROR(P7/O7-1,0) -> 0 | Q8: Billable-employee revenue | R8: 7093.9482 | S8: 7082.3683 | T8: 7059 | U8: 7046 | V8: 6974 | W8: 6983 | X8: 7010.86 | Y8: 7058.7916
A9: Net additions | B9: 9152 | C9: 8726 | D9: 4118 | E9: 6356 | F9: 1789 | G9: 19388 | H9: 35209 | I9: 821 | J9: -1759 | K9: 625 | L9: 2356 | M9: 9279 | N9: 9279 | O9: 9279 | P9: 9279 | Q9: AI revenue / total | R9: =R7/R5 -> 0.044071117 | S9: =S7/S5 -> 0.051383835 | T9: =T7/T5 -> 0.059928086 | U9: =U7/U5 -> 0.075449416 | V9: =V7/V5 -> 0.085257083 | W9: =W7/W5 -> 0.091346779 | X9: =X7/X5 -> 0.096771451 | Y9: =Y7/Y5 -> 0.10136326
A10: Attrition — voluntary IT services | B10: =IFERROR(B9/B7,0) -> 0.025864578 | C10: =IFERROR(C9/C7,0) -> 0.022534818 | D10: =IFERROR(D9/D7,0) -> 0.010425369 | E10: =IFERROR(E9/E7,0) -> 0.014980497 | F10: =IFERROR(F9/F7,0) -> 0.0039891719 | G10: =IFERROR(G9/G7,0) -> 0.039676741 | H10: =IFERROR(H9/H7,0) -> 0.059455078 | I10: =IFERROR(I9/I7,0) -> 0.0013354045 | ... P10: =IFERROR(P9/P7,0) -> 0.015626526 | Q10: AI run-rate QoQ growth | R10: 0 | S10: =S6/R6-1 -> 0.173 | T10: =T6/S6-1 -> 0.173 | U10: =U6/T6-1 -> 0.27777778 | V10: =V6/U6-1 -> 0.13043478 | W10: =W6/V6-1 -> 0.08 | X10: =X6/W6-1 -> 0.07 | Y10: =Y6/X6-1 -> 0.06
A11: Women associates | B11: =IFERROR(B5/B9,0) -> 1.8077906 | C11: =IFERROR(C5/C9,0) -> 2.0142104 | D11: =IFERROR(D5/D9,0) -> 4.6355027 | E11: =IFERROR(E5/E9,0) -> 3.2902769 | F11: =IFERROR(F5/F9,0) -> 12.314701 | G11: =IFERROR(G5/G9,0) -> 1.1436971 | H11: =IFERROR(H5/H9,0) -> 0.73012582 | I11: =IFERROR(I5/I9,0) -> 34.015834 | ... L11: =IFERROR(L5/L9,0) -> 12.740662 | M11: 0.35 | N11: =IFERROR(N5/N9,0) -> 3.4661979 | O11: =IFERROR(O5/O9,0) -> 3.6395078 | P11: =IFERROR(P5/P9,0) -> 3.8214832 | Q11: Revenue bridge check | R11: =R8+R7-R5 -> 0 | S11: =S8+S7-S5 -> 0 | T11: =T8+T7-T5 -> 0 | U11: =U8+U7-U5 -> 0 | V11: =V8+V7-V5 -> 0 | W11: =W8+W7-W5 -> 0 | X11: =X8+X7-X5 -> 0 | Y11: =Y8+Y7-Y5 -> 0
A12: Nationalities | B12: 129 | C12: 130 | D12: 131 | E12: 147 | F12: 144 | G12: 154 | H12: 153 | I12: 150 | J12: 152 | K12: 152 | L12: 149 | M12: 148 | N12: 148 | O12: 148 | P12: 148
A13: USD 1m+ clients | B13: 829 | C13: 897 | D13: 963 | E13: 1008 | F13: 1072 | G13: 1096 | H13: 1182 | I13: 1241 | J13: 1294 | K13: 1332 | L13: 1397 | M13: 1401 | N13: 1401 | O13: 1401 | P13: 1401 | Q13: * Q2 FY26 AI run-rate implied from TCS-disclosed Q3 run-rate and 17.3% sequential CC growth; Q1 FY26 is model-backcast at the same rate. Q3 FY26, Q4 FY26 and Q1 FY27 are company-reported.
A14: USD 5m+ clients | B14: 429 | C14: 459 | D14: 495 | E14: 532 | F14: 565 | G14: 569 | H14: 638 | I14: 665 | J14: 693 | K14: 723 | L14: 738 | M14: 746 | N14: 746 | O14: 746 | P14: 746
A15: USD 10m+ clients | B15: 298 | C15: 310 | D15: 350 | E15: 371 | F15: 391 | G15: 387 | H15: 439 | I15: 461 | J15: 487 | K15: 493 | L15: 499 | M15: 504 | N15: 504 | O15: 504 | P15: 504
A16: USD 20m+ clients | B16: 173 | C16: 190 | D16: 207 | E16: 215 | F16: 240 | G16: 228 | H16: 268 | I16: 291 | J16: 301 | K16: 298 | L16: 311 | M16: 307 | N16: 307 | O16: 307 | P16: 307
A17: USD 50m+ clients | B17: 73 | C17: 84 | D17: 97 | E17: 99 | F17: 105 | G17: 101 | H17: 120 | I17: 133 | J17: 139 | K17: 130 | L17: 139 | M17: 139 | N17: 139 | O17: 139 | P17: 139
A18: USD 100m+ clients | B18: =B5 -> 16544.9 | C18: =C5 -> 17576 | D18: =D5 -> 19089 | E18: =E5 -> 20913 | F18: =F5 -> 22031 | G18: =G5 -> 22174 | H18: =H5 -> 25707 | I18: =I5 -> 27927 | ... L18: =L5 -> 30017 | M18: 66 | N18: 66 | O18: 66 | P18: 66
A19: Revenue / employee (US$ '000) | B19: =IFERROR(B20/B7*1000,0) -> 46.757743 | C19: =IFERROR(C20/C7*1000,0) -> 45.389866 | D19: =IFERROR(D20/D7*1000,0) -> 48.326827 | E19: =IFERROR(E20/E7*1000,0) -> 49.289982 | F19: =IFERROR(F20/F7*1000,0) -> 49.125459 | G19: =IFERROR(G20/G7*1000,0) -> 45.378175 | H19: =IFERROR(H20/H7*1000,0) -> 43.409688 | I19: =IFERROR(I20/I7*1000,0) -> 45.424898 | ... P19: =IFERROR(P20/P7*1000,0) -> 52.798672
A20: Billable-employee revenue | B20: =B5-B21 -> 16544.9 | C20: =C5-C21 -> 17576 | D20: =D5-D21 -> 19089 | E20: =E5-E21 -> 20913 | F20: =F5-F21 -> 22031 | G20: =G5-G21 -> 22174 | H20: =H5-H21 -> 25707 | I20: =I5-I21 -> 27927 | ... P20: =P5-P21 -> 31351.746
A21: AI revenue — quarterly run-rate roll-up | B21: 0 | C21: 0 | D21: 0 | E21: 0 | F21: 0 | G21: 0 | H21: 0 | I21: 0 | J21: 0 | K21: 0 | L21: 1735.6835 | M21: 2899.3484 | N21: 3334.2507 | O21: 3734.3607 | P21: 4107.7968
A22: Total modelled revenue | B22: =SUM(B20:B21) -> 16544.9 | C22: =SUM(C20:C21) -> 17576 | D22: =SUM(D20:D21) -> 19089 | E22: =SUM(E20:E21) -> 20913 | F22: =SUM(F20:F21) -> 22031 | G22: =SUM(G20:G21) -> 22174 | H22: =SUM(H20:H21) -> 25707 | I22: =SUM(I20:I21) -> 27927 | ... P22: =SUM(P20:P21) -> 35459.543
A23: Revenue bridge check | B23: =B22-B5 -> 0 | C23: =C22-C5 -> 0 | D23: =D22-D5 -> 0 | E23: =E22-E5 -> 0 | F23: =F22-F5 -> 0 | G23: =G22-G5 -> 0 | H23: =H22-H5 -> 0 | I23: =I22-I5 -> 0 | ... P23: =P22-P5 -> 0
A24: Annualized AI revenue run-rate — year-end | B24: 0 | C24: 0 | D24: 0 | E24: 0 | F24: 0 | G24: 0 | H24: 0 | I24: 0 | J24: 0 | K24: 0 | L24: 2300 | M24: 3184.8336 | N24: 3662.5586 | O24: 4102.0657 | P24: 4512.2722
A25: HyperVault commissioned capacity (MW) | B25: 0 | C25: 0 | D25: 0 | E25: 0 | F25: 0 | G25: 0 | H25: 0 | I25: 0 | J25: 0 | K25: 0 | L25: 0 | M25: 100 | N25: 250 | O25: 500 | P25: 750
A26: HyperVault revenue (US$ m) | B26: 0 | C26: 0 | D26: 0 | E26: 0 | F26: 0 | G26: 0 | H26: 0 | I26: 0 | J26: 0 | K26: 0 | L26: 0 | M26: 0 | N26: 0 | O26: 0 | P26: 0

Sheet Sources
A1: Sources & Model Conventions
A4: Item | B4: Period | C4: Source | D4: URL / reference | E4: Treatment | F4: Notes
A5: Historical financials | B5: FY16–FY26 | C5: TCS filings / data sheet | D5: https://www.tcs.com/investor-relations | E5: Reported actuals | F5: Audited IFRS USD
A6: Q1 FY27 | B6: Q1 FY27 | C6: TCS consolidated IFRS filing | D6: https://www.tcs.com/who-we-are/newsroom/press-release/tcs-financial-results-q1-fy-2027 | E6: Primary filing | F6: Latest reported quarter
A7: Operating metrics | B7: FY16–Q1 FY27 | C7: TCS data sheet | D7: https://www.tcs.com/investor-relations | E7: All disclosed metrics retained | F7: Distributed across Revenue Drivers, Segment Revenue and Client Data
A8: HyperVault | B8: FY27E onward | C8: TCS disclosures | D8: https://www.tcs.com/what-we-do/services/ai-led-data-centres | E8: Scenario assumptions | F8: Undisclosed economics default to zero
A9: Forecasts | B9: FY27E–FY30E | C9: Model assumptions | D9: Assumptions tab | E9: Formula-driven | F9: No hardcoded statement outputs
A10: Currency | B10: All periods | C10: Model convention | E10: USD million | F10: Unless stated otherwise
A11: Annual policy | B11: FY16–FY26 | C11: Audited reported basis | E11: Reported including exceptional items | F11: No ex-adjustment in annual history
A12: Market data | B12: FY16–FY26 | C12: Yahoo Finance NSE TCS | D12: https://finance.yahoo.com/quote/TCS.NS/history/ | E12: Fiscal year-end | F12: Price inputs
A13: AI annualized revenue | B13: Q3 FY26 | C13: TCS Q3 FY26 results | D13: https://www.tcs.com/who-we-are/newsroom/press-release/tcs-financial-results-q3-fy-2026 | E13: US$1.8bn reported | F13: Q3 growth of 17.3% CC used only to imply Q2 and backcast Q1
A14: AI annualized revenue | B14: Q4 FY26 | C14: TCS Q4 FY26 results | D14: https://www.tcs.com/who-we-are/newsroom/press-release/tcs-financial-results-q4-fy-2026 | E14: US$2.3bn reported | F14: Quarterly AI revenue proxy equals annualized run-rate / 4
A15: AI annualized revenue | B15: Q1 FY27 | C15: TCS Q1 FY27 results | D15: https://www.tcs.com/who-we-are/newsroom/press-release/tcs-financial-results-q1-fy-2027 | E15: US$2.6bn reported | F15: Up 13.6% QoQ; forecast growth is model assumption

Sheet Quarterly P&L
A1: Quarterly Profit & Loss Statement
A4: Metric | B4: 1Q16 | C4: 2Q16 | D4: 3Q16 | E4: 4Q16 | F4: 1Q17 | G4: 2Q17 | H4: 3Q17 | I4: 4Q17 | J4: 1Q18 | K4: 2Q18 | L4: 3Q18 | M4: 4Q18 | N4: 1Q19 | O4: 2Q19 | P4: 3Q19 | Q4: 4Q19 | R4: 1Q20 | S4: 2Q20 | T4: 3Q20 | U4: 4Q20 | V4: 1Q21 | W4: 2Q21 | X4: 3Q21 | Y4: 4Q21 | Z4: 1Q22 | AA4: 2Q22 | AB4: 3Q22 | AC4: 4Q22 | AD4: 1Q23 | AE4: 2Q23 | AF4: 3Q23 | AG4: 4Q23 | AH4: 1Q24 | AI4: 2Q24 | AJ4: 3Q24 | AK4: 4Q24 | AL4: 1Q25 | AM4: 2Q25 | AN4: 3Q25 | AO4: 4Q25 | AP4: 1Q26 | AQ4: 2Q26 | AR4: 3Q26 | AS4: 4Q26 | AT4: 1Q27
A5: Revenue | B5: 4036.4 | C5: 4156.4 | D5: 4145.4 | E5: 4206.7 | F5: 4362 | G5: 4374 | H5: 4387 | I5: 4452 | J5: 4591 | K5: 4739 | L5: 4787 | M5: 4972 | N5: 5051 | O5: 5215 | P5: 5250 | Q5: 5397 | R5: 5485 | S5: 5517 | T5: 5586 | U5: 5444 | V5: 5059 | W5: 5424 | X5: 5702 | Y5: 5989 | Z5: 6154 | AA5: 6333 | AB5: 6524 | AC5: 6696 | AD5: 6780 | AE5: 6877 | AF5: 7075 | AG5: 7195 | AH5: 7226 | AI5: 7210 | AJ5: 7281 | AK5: 7363 | AL5: 7505 | AM5: 7670 | AN5: 7539 | AO5: 7465 | AP5: 7421 | AQ5: 7466 | AR5: 7509 | AS5: 7621 | AT5: 7624
A6: IT & consultancy revenue | B6: 3925.2 | C6: 4070 | D6: 4145.5 | E6: 4206.7 | F6: =IFERROR(F5/B5-1,0) -> 0.08066594 | G6: =IFERROR(G5/C5-1,0) -> 0.052352998 | H6: =IFERROR(H5/D5-1,0) -> 0.058281469 | I6: =IFERROR(I5/E5-1,0) -> 0.058311741 | J6: =IFERROR(J5/F5-1,0) -> 0.052498854 | K6: =IFERROR(K5/G5-1,0) -> 0.083447645 | L6: =IFERROR(L5/H5-1,0) -> 0.091178482 | M6: =IFERROR(M5/I5-1,0) -> 0.11680144 | ... BI6: =IFERROR(BI5/BE5-1,0) -> 0
A7: Equipment & licence revenue | B7: 111.2 | C7: 86.4
A8: Cost of revenue | B8: 2275.1 | C8: 2318 | D8: 2305.6 | E8: 2375.1 | F8: 2501 | G8: 2470 | H8: 2490 | I8: 2504 | J8: 2683 | K8: 2733 | L8: 2767 | M8: 2871 | N8: 2961 | O8: 3000 | P8: 3056 | Q8: 3144 | R8: 3264.73 | S8: 3263.93 | T8: 3275 | U8: 3158 | V8: 3065 | W8: 3205 | X8: 3329 | Y8: 3519 | Z8: 3670 | AA8: 3773 | AB8: 3915 | AC8: 4008 | AD8: 4175 | AE8: 4161 | AF8: 4241 | AG8: 4307 | AH8: 4370 | AI8: 4320 | AJ8: 4311 | AK8: 4334 | AL8: 4514 | AM8: 4741 | AN8: 4613 | AO8: 4570 | AP8: 4517 | AQ8: 4512 | AR8: 4444 | AS8: 4517 | AT8: 22 | AU8: =AU5-AU7 -> 0 | AV8: =AV5-AV7 -> 0 | AW8: =AW5-AW7 -> 0 | AX8: =AX5-AX7 -> 0 | AY8: =AY5-AY7 -> 0 | AZ8: =AZ5-AZ7 -> 0 | BA8: =BA5-BA7 -> 0 | BB8: =BB5-BB7 -> 0 | ... BI8: =BI5-BI7 -> 0
A9: Gross profit | B9: =IFERROR(B8/B5,0) -> 0.56364582 | C9: =IFERROR(C8/C5,0) -> 0.55769416 | D9: =IFERROR(D8/D5,0) -> 0.55618276 | E9: =IFERROR(E8/E5,0) -> 0.56459933 | F9: =IFERROR(F8/F5,0) -> 0.57336084 | G9: =IFERROR(G8/G5,0) -> 0.5647005 | H9: =IFERROR(H8/H5,0) -> 0.56758605 | I9: =IFERROR(I8/I5,0) -> 0.56244385 | ... BI9: =IFERROR(BI8/BI5,0) -> 0
A10: Employee cost — SG&A | B10: 507 | C10: 493.8 | D10: 533.4 | E10: 516.8 | F10: 558 | G10: 579 | H10: 566 | I10: 594 | J10: 626 | K10: 631 | L10: 604 | M10: 627 | N10: 618 | O10: 615 | P10: 640 | Q10: 653 | R10: 691 | S10: 715 | T10: 706 | U10: 737 | V10: 624 | W10: 648 | X10: 714 | Y10: 696 | Z10: 744 | AA10: 778 | AB10: 801 | AC10: 816 | AD10: 854 | AE10: 867 | AF10: 884 | AG10: 910 | AH10: 955 | AI10: 937 | AJ10: 934 | AK10: 903 | AL10: 915 | AM10: 882 | AN10: 892 | AO10: 877 | AP10: 880 | AQ10: 875 | AR10: 940 | AS10: 920
A11: Consultants — SG&A | B11: =IFERROR(B10/B5,0) -> 0.12560698 | C11: =IFERROR(C10/C5,0) -> 0.11880473 | D11: =IFERROR(D10/D5,0) -> 0.12867275 | E11: =IFERROR(E10/E5,0) -> 0.12285164 | F11: =IFERROR(F10/F5,0) -> 0.12792297 | G11: =IFERROR(G10/G5,0) -> 0.13237311 | H11: =IFERROR(H10/H5,0) -> 0.12901755 | I11: =IFERROR(I10/I5,0) -> 0.13342318 | ... BI11: =IFERROR(BI10/BI5,0) -> 0
A12: Doubtful debts | B12: 6.2 | C12: 5.5 | D12: 3.7 | E12: 5.2 | F12: 7 | G12: 2 | H12: 5 | I12: 4 | J12: 5 | K12: 7 | L12: 10 | M12: 10 | N12: 7 | O12: 7 | P12: 5 | Q12: 8 | R12: 7 | S12: 5.35 | T12: 2 | U12: 5 | V12: 7 | W12: 10 | X12: 4 | Y12: 6 | Z12: 6 | AA12: 5 | AB12: 6 | AC12: 2 | AD12: 2 | AE12: 5 | AF12: 5 | AG12: 5 | AH12: 2 | AI12: 4 | AJ12: 3 | AK12: 5 | AL12: 5 | AM12: 2 | AN12: 5 | AO12: 3 | AP12: 3 | AQ12: 4 | AR12: 4 | AS12: 9
A13: D&A — SG&A | B13: =IFERROR(B12/B5,0) -> 0.0015360222 | C13: =IFERROR(C12/C5,0) -> 0.0013232605 | D13: =IFERROR(D12/D5,0) -> 0.0008925556 | E13: =IFERROR(E12/E5,0) -> 0.0012361233 | F13: =IFERROR(F12/F5,0) -> 0.0016047685 | G13: =IFERROR(G12/G5,0) -> 0.00045724737 | H13: =IFERROR(H12/H5,0) -> 0.001139731 | I13: =IFERROR(I12/I5,0) -> 0.0008984726 | ... BI13: =IFERROR(BI12/BI5,0) -> 0
A14: Facility — SG&A | B14: 46.1 | C14: 46.4 | D14: 47.4 | E14: 49 | F14: 51 | G14: 51 | H14: 51 | I14: 54 | J14: 52 | K14: 49 | L14: 50 | M14: 49 | N14: 46 | O14: 45 | P14: 45 | Q14: 47 | R14: 33 | S14: 32.83 | T14: 31 | U14: 30 | V14: 27 | W14: 23 | X14: 21 | Y14: 27 | Z14: 25 | AA14: 24 | AB14: 28 | AC14: 28 | AD14: 28 | AE14: 30 | AF14: 32 | AG14: 34 | AH14: 35 | AI14: 34 | AJ14: 37 | AK14: 36 | AL14: 37 | AM14: 39 | AN14: 39 | AO14: 38 | AP14: 38 | AQ14: 38 | AR14: 38 | AS14: 41 | AV14: =AV8-AV10-AV12 -> 0 | AW14: =AW8-AW10-AW12 -> 0 | AX14: =AX8-AX10-AX12 -> 0 | AY14: =AY8-AY10-AY12 -> 0 | AZ14: =AZ8-AZ10-AZ12 -> 0 | BA14: =BA8-BA10-BA12 -> 0 | BB14: =BB8-BB10-BB12 -> 0 | BC14: =BC8-BC10-BC12 -> 0 | ... BI14: =BI8-BI10-BI12 -> 0
A15: Travel — SG&A | B15: =IFERROR(B14/B5,0) -> 0.011421068 | C15: =IFERROR(C14/C5,0) -> 0.011163507 | D15: =IFERROR(D14/D5,0) -> 0.011434361 | E15: =IFERROR(E14/E5,0) -> 0.011648085 | F15: =IFERROR(F14/F5,0) -> 0.011691884 | G15: =IFERROR(G14/G5,0) -> 0.011659808 | H15: =IFERROR(H14/H5,0) -> 0.011625256 | I15: =IFERROR(I14/I5,0) -> 0.01212938 | ... BI15: =IFERROR(BI14/BI5,0) -> 0
A16: Communication — SG&A | B16: 11.2 | C16: 11.8 | D16: 11.2 | E16: 10 | F16: 12 | G16: 11 | H16: 11 | I16: 10 | J16: 12 | K16: 12 | L16: 11 | M16: 8 | N16: 12 | O16: 13 | P16: 12 | Q16: 12 | R16: 12 | S16: 12.46 | T16: 12 | U16: 14 | V16: 17 | W16: 16 | X16: 13 | Y16: 16 | Z16: 17 | AA16: 14 | AB16: 18 | AC16: 19 | AD16: 18 | AE16: 21 | AF16: 28 | AG16: 26 | AH16: 26 | AI16: 21 | AJ16: 25 | AK16: 23 | AL16: 21 | AM16: 24 | AN16: 22 | AO16: 22 | AP16: 22 | AQ16: 21 | AR16: 25 | AS16: 29
A17: Other SG&A | B17: 50.9 | C17: 73.2 | D17: 63.2 | E17: 61.5 | F17: 56 | G17: 54 | H17: 55 | I17: 59 | J17: 55 | K17: 48 | L17: 66 | M17: 73 | N17: 70 | O17: 70 | P17: 72 | Q17: 98 | R17: 65 | S17: 81.5 | T17: 78 | U17: 62 | V17: 71 | W17: 38 | X17: 45 | Y17: 55 | Z17: 60 | AA17: 52 | AB17: 62 | AC17: 78 | AD17: 59 | AE17: 60 | AF17: 63 | AG17: 57 | AH17: 67 | AI17: 62 | AJ17: 62 | AK17: 64 | AL17: 84 | AM17: 56 | AN17: 49 | AO17: 64 | AP17: 64 | AQ17: 59 | AR17: 83 | AS17: 93 | AT17: 1468 | AU17: =AU14+AU16 -> 0 | AV17: =AV14+AV16 -> 0 | AW17: =AW14+AW16 -> 0 | AX17: =AX14+AX16 -> 0 | AY17: =AY14+AY16 -> 0 | AZ17: =AZ14+AZ16 -> 0 | BA17: =BA14+BA16 -> 0 | BB17: =BB14+BB16 -> 0 | ... BI17: =BI14+BI16 -> 0
A18: Operating expenses | B18: =IFERROR(B17/B5,0) -> 0.012610247 | C18: =IFERROR(C17/C5,0) -> 0.017611394 | D18: =IFERROR(D17/D5,0) -> 0.015245815 | E18: =IFERROR(E17/E5,0) -> 0.014619536 | F18: =IFERROR(F17/F5,0) -> 0.012838148 | G18: =IFERROR(G17/G5,0) -> 0.012345679 | H18: =IFERROR(H17/H5,0) -> 0.012537041 | I18: =IFERROR(I17/I5,0) -> 0.013252471 | ... BI18: =IFERROR(BI17/BI5,0) -> 0
A19: Operating income | B19: 1061.2 | C19: 1125.1 | D19: 1102.3 | E19: 1096 | F19: 1093 | G19: 1138 | H19: 1141 | I19: 1146 | J19: 1073 | K19: 1188 | L19: 1205 | M19: 1263 | N19: 1264 | O19: 1383 | P19: 1345 | Q19: 1354 | R19: 1324.7 | S19: 1325.67 | T19: 1398 | U19: 1366 | V19: 1194 | W19: 1422 | X19: 1517 | Y19: 1608 | Z19: 1570 | AA19: 1622 | AB19: 1633 | AC19: 1671 | AD19: 1566 | AE19: 1651 | AF19: 1736 | AG19: 1761 | AH19: 1674 | AI19: 1749 | AJ19: 1821 | AK19: 1914 | AL19: 1851 | AM19: 1846 | AN19: 1844 | AO19: 1807 | AP19: 1815 | AQ19: 1879 | AR19: 1889 | AS19: 1927
A20: Operating margin | B20: =B19/B5 -> 0.26290754 | C20: =C19/C5 -> 0.27069098 | D20: =D19/D5 -> 0.2659092 | E20: =E19/E5 -> 0.26053676 | F20: =F19/F5 -> 0.25057313 | G20: =G19/G5 -> 0.26017375 | H20: =H19/H5 -> 0.26008662 | I20: =I19/I5 -> 0.2574124 | ... AT20: =AT19/AT5 -> 0 | AV20: =AV14+AV19 -> 0 | AW20: =AW14+AW19 -> 0 | AX20: =AX14+AX19 -> 0 | AY20: =AY14+AY19 -> 0 | AZ20: =AZ14+AZ19 -> 0 | BA20: =BA14+BA19 -> 0 | BB20: =BB14+BB19 -> 0 | BC20: =BC14+BC19 -> 0 | ... BI20: =BI14+BI19 -> 0
A21: Other income | B21: =IFERROR(B20/B5,0) -> 6.5134164e-05 | C21: =IFERROR(C20/C5,0) -> 6.5126307e-05 | D21: =IFERROR(D20/D5,0) -> 6.4145607e-05 | E21: =IFERROR(E20/E5,0) -> 6.1933763e-05 | F21: =IFERROR(F20/F5,0) -> 5.7444551e-05 | G21: =IFERROR(G20/G5,0) -> 5.9481882e-05 | H21: =IFERROR(H20/H5,0) -> 5.9285758e-05 | I21: =IFERROR(I20/I5,0) -> 5.7819497e-05 | ... BI21: =IFERROR(BI20/BI5,0) -> 0
A22: PBT | B22: 1182.5 | C22: 1228.4 | D22: 1208.2 | E22: 1229.8 | F22: 1236 | G22: 1295 | H22: 1316 | I22: 1294 | J22: 1218 | K22: 1315 | L22: 1339 | M22: 1415 | N22: 1442 | O22: 1468 | P22: 1506 | Q22: 1519 | R22: 1527.7 | S22: 1491.67 | T22: 1481 | U22: 1432 | V22: 1254 | W22: 1523 | X22: 1585 | Y22: 1717 | Z22: 1648 | AA22: 1753 | AB22: 1760 | AC22: 1769 | AD22: 1642 | AE22: 1753 | AF22: 1780 | AG22: 1871 | AH22: 1824 | AI22: 1851 | AJ22: 1907 | AK22: 2027 | AL22: 1945 | AM22: 1914 | AN22: 1963 | AO22: 1900 | AP22: 1987 | AQ22: 1952 | AR22: 1992 | AS22: 1979
A23: Income tax | B23: =IFERROR(B22/B20,0) -> 4497.7789 | C23: =IFERROR(C22/C20,0) -> 4538.016 | D23: =IFERROR(D22/D20,0) -> 4543.6562 | E23: =IFERROR(E22/E20,0) -> 4720.2552 | F23: =IFERROR(F22/F20,0) -> 4932.6917 | G23: =IFERROR(G22/G20,0) -> 4977.4429 | H23: =IFERROR(H22/H20,0) -> 5059.8528 | I23: =IFERROR(I22/I20,0) -> 5026.9529 | ... BI23: =IFERROR(BI22/BI20,0) -> 0
A24: Profit incl. NCI | B24: 907.8 | C24: 932.2 | D24: 927.9 | E24: 938.5 | F24: 940 | G24: 986 | H24: 1006 | I24: 994 | J24: 924 | K24: 1003 | L24: 1014 | M24: 1073 | N24: 1085 | O24: 1123 | P24: 1142 | Q24: 1157 | R24: 1170.7 | S24: 1141.67 | T24: 1141 | U24: 1102 | V24: 930 | W24: 1145 | X24: 1183 | Y24: 1272 | Z24: 1224 | AA24: 1305 | AB24: 1308 | AC24: 1318 | AD24: 1223 | AE24: 1302 | AF24: 1323 | AG24: 1390 | AH24: 1353 | AI24: 1374 | AJ24: 1415 | AK24: 1504 | AL24: 1450 | AM24: 1427 | AN24: 1466 | AO24: 1425 | AP24: 1500 | AQ24: 1470 | AR24: 1510 | AS24: 1486 | AV24: =AV20-AV22 -> 0 | AW24: =AW20-AW22 -> 0 | AX24: =AX20-AX22 -> 0 | AY24: =AY20-AY22 -> 0 | AZ24: =AZ20-AZ22 -> 0 | BA24: =BA20-BA22 -> 0 | BB24: =BB20-BB22 -> 0 | BC24: =BC20-BC22 -> 0 | ... BI24: =BI20-BI22 -> 0
A25: NCI | B25: -10 | C25: -5.8 | D25: -2.4 | E25: -0.8 | F25: 0 | G25: -2 | H25: -6 | I25: -2 | J25: -1 | K25: -3 | L25: -2 | M25: -3 | N25: -3 | O25: -4 | P25: -2 | Q25: -3 | R25: -3 | S25: -3 | T25: -3 | U25: -6 | V25: -5 | W25: -4 | X25: -3 | Y25: -5 | Z25: -3 | AA25: -4 | AB25: -5 | AC25: -4 | AD25: -5 | AE25: -4 | AF25: -5 | AG25: -5 | AH25: -6 | AI25: -4 | AJ25: -5 | AK25: -8 | AL25: -8 | AM25: -6 | AN25: -8 | AO25: -7 | AP25: -7 | AQ25: -6 | AR25: -7 | AS25: -7
A26: Net profit attributable | B26: 897.7 | C26: 926.5 | D26: 925.5 | E26: 937.7 | F26: 940 | G26: 984 | H26: 1000 | I26: 992 | J26: 923 | K26: 1000 | L26: 1012 | M26: 1070 | N26: 1082 | O26: 1119 | P26: 1140 | Q26: 1154 | R26: 1167.7 | S26: 1138.67 | T26: 1138 | U26: 1096 | V26: 925 | W26: 1141 | X26: 1180 | Y26: 1267 | Z26: 1221 | AA26: 1301 | AB26: 1303 | AC26: 1314 | AD26: 1218 | AE26: 1298 | AF26: 1318 | AG26: 1385 | AH26: 1347 | AI26: 1370 | AJ26: 1410 | AK26: 1496 | AL26: 1442 | AM26: 1421 | AN26: 1458 | AO26: 1418 | AP26: 1493 | AQ26: 1464 | AR26: 1503 | AS26: 1479 | AV26: =AV24-AV25 -> 0 | AW26: =AW24-AW25 -> 0 | AX26: =AX24-AX25 -> 0 | AY26: =AY24-AY25 -> 0 | AZ26: =AZ24-AZ25 -> 0 | BA26: =BA24-BA25 -> 0 | BB26: =BB24-BB25 -> 0 | BC26: =BC24-BC25 -> 0 | ... BI26: =BI24-BI25 -> 0
A27: EPS | B27: =IFERROR(B26/B5,0) -> 0.22240115 | C27: =IFERROR(C26/C5,0) -> 0.22290925 | D27: =IFERROR(D26/D5,0) -> 0.22325952 | E27: =IFERROR(E26/E5,0) -> 0.22290632 | F27: =IFERROR(F26/F5,0) -> 0.21549748 | G27: =IFERROR(G26/G5,0) -> 0.22496571 | H27: =IFERROR(H26/H5,0) -> 0.2279462 | I27: =IFERROR(I26/I5,0) -> 0.2228212 | ... BI27: =IFERROR(BI26/BI5,0) -> 0

Sheet Annual_Statements
A1: Annual Profit & Loss Statement
A4: Metric | B4: FY16A | C4: FY17A | D4: FY18A | E4: FY19A | F4: FY20A | G4: FY21A | H4: FY22A | I4: FY23A | J4: FY24A | K4: FY25A | L4: FY26A | M4: FY27E | N4: FY28E | O4: FY29E | P4: FY30E
A5: Annual P&L
A6: Detailed consolidated IFRS income statement | USD million
A7: IT & consultancy services revenue | B7: 16544.9 | C7: 17576 | D7: 19089 | E7: 20913 | F7: 22031 | G7: 22174 | H7: 25707 | I7: 27927 | J7: 29080 | K7: 30179 | L7: 30017 | M7: 30925.818 | N7: 32162.851 | O7: 33770.993 | P7: 35459.543
A8: Equipment & software licence revenue | B8: 0 | C8: 0 | D8: 0 | E8: 0 | F8: 0 | G8: 0 | H8: 0 | I8: 0 | J8: 0 | K8: 0 | L8: 0 | M8: 0 | N8: 0 | O8: 0 | P8: 0
A9: Revenue | B9: 16544.9 | C9: 17576 | D9: 19089 | E9: 20913 | F9: 22031 | G9: 22174 | H9: 25707 | I9: 27927 | J9: 29080 | K9: 30179 | L9: 30017 | M9: 30925.818 | N9: 32162.851 | O9: 33770.993 | P9: 35459.543
A10: Employee cost — cost of revenue | B10: 6379.1 | C10: 6884 | D10: 7807 | E10: 8647 | F10: 9216 | G10: 9714 | H10: 11280 | I10: 12284 | J10: 13188 | K10: 13668 | L10: 13817 | M10: 14231.204 | N10: 14786.519 | O10: 15517.37 | P10: 16284.377
A11: External consultants — cost of revenue | B11: 1190.4 | C11: 1243 | D11: 1307 | E11: 1525 | F11: 1755 | G11: 1709 | H11: 2251 | I11: 2559 | J11: 1810 | K11: 1305 | L11: 1566 | M11: 1612.9453 | N11: 1675.8839 | O11: 1758.7176 | P11: 1845.6491
A12: Equipment & software licences — cost of revenue | B12: 391.3 | C12: 418 | D12: 419 | E12: 325 | F12: 267 | G12: 198 | H12: 155 | I12: 231 | J12: 446 | K12: 1376 | L12: 491 | M12: 505.71913 | N12: 525.45275 | O12: 551.42424 | P12: 578.68053
A13: Depreciation — cost of revenue | B13: 205.7 | C13: 217 | D13: 244 | E13: 236 | F13: 377 | G13: 417 | H13: 478 | I13: 474 | J13: 461 | K13: 483 | L13: 489 | M13: 503.65918 | N13: 523.31242 | O13: 549.17811 | P13: 576.32338
A14: Travel — cost of revenue | B14: 243.4 | C14: 268 | D14: 291 | E14: 333 | F14: 321.55 | G14: 119 | H14: 174 | I14: 225 | J14: 249 | K14: 276 | L14: 261 | M14: 268.82422 | N14: 279.31399 | O14: 293.1196 | P14: 307.60818
A15: Communication — cost of revenue | B15: 124.6 | C15: 115 | D15: 123 | E15: 140 | F15: 172.83 | G15: 194 | H15: 206 | I15: 186 | J15: 178 | K15: 190 | L15: 210 | M15: 216.29535 | N15: 224.73539 | O15: 235.84336 | P15: 247.50084
A16: Facility expense — cost of revenue | B16: 329.9 | C16: 343 | D16: 410 | E16: 426 | F16: 253.28 | G16: 189 | H16: 182 | I16: 205 | J16: 233 | K16: 255 | L16: 261 | M16: 268.82422 | N16: 279.31399 | O16: 293.1196 | P16: 307.60818
A17: Other expenses — cost of revenue | B17: 409.5 | C17: 477 | D17: 453 | E17: 528 | F17: 599 | G17: 578 | H17: 640 | I17: 720 | J17: 770 | K17: 885 | L17: 895 | M17: 921.83019 | N17: 957.80084 | O17: 1005.1419 | P17: 1054.825
A18: Cost of revenue | B18: 9273.9 | C18: 9965 | D18: 11054 | E18: 12160 | F18: 12961.66 | G18: 13118 | H18: 15366 | I18: 16884 | J18: 17335 | K18: 18438 | L18: 17990 | M18: 18529.302 | N18: 19252.332 | O18: 20203.915 | P18: 21202.572
... A39: Net margin attributable to TCS | B39: 0.22287231 | C39: 0.22286072 | D39: 0.20980669 | E39: 0.21489026 | F39: 0.20611865 | G39: 0.19770903 | H39: 0.19990664 | I39: 0.18688008 | J39: 0.19057772 | K39: 0.19016535 | L39: 0.18436219 | M39: 0.19799873 | N39: 0.19606963 | O39: 0.19571941 | P39: 0.19561938
A40: EPS (US$) | B40: =SUM(B37:B39) -> 3706.6229 | C40: =SUM(C37:C39) -> 3927.2229 | D40: =SUM(D37:D39) -> 4014.2098 | E40: =SUM(E37:E39) -> 4508.2149 | F40: =SUM(F37:F39) -> 4556.2061 | G40: =SUM(G37:G39) -> 4401.1977 | H40: =SUM(H37:H39) -> 5155.1999 | I40: =SUM(I37:I39) -> 5238.1869 | ... P40: =SUM(P37:P39) -> 6971.6267
A41: Total D&A | B41: 287.5 | C41: 296 | D41: 312 | E41: 294 | F41: 495.95 | G41: 550 | H41: 617 | I41: 623 | J41: 602 | K41: 619 | L41: 626 | M41: 633.15877 | N41: 654.87026 | O41: 687.31384 | P41: 721.3659
A44: Annual Balance Sheet
B45: =SUM(B40:B44) -> 3994.1229 | C45: =SUM(C40:C44) -> 4223.2229 | D45: =SUM(D40:D44) -> 4326.2098 | E45: =SUM(E40:E44) -> 4802.2149 | F45: =SUM(F40:F44) -> 5052.1561 | G45: =SUM(G40:G44) -> 4951.1977 | H45: =SUM(H40:H44) -> 5772.1999 | I45: =SUM(I40:I44) -> 5861.1869 | ... P45: =SUM(P40:P44) -> 7692.9926
A47: Metric | B47: FY16A | C47: FY17A | D47: FY18A | E47: FY19A | F47: FY20A | G47: FY21A | H47: FY22A | I47: FY23A | J47: FY24A | K47: FY25A | L47: FY26A | M47: FY27E | N47: FY28E | O47: FY29E | P47: FY30E
A48: Annual Balance Sheet
A49: Detailed consolidated IFRS balance sheet | USD million
A50: Cash & cash equivalents | B50: 950 | C50: 555 | D50: 751 | E50: 1045 | F50: 1146 | G50: 934 | H50: 1650 | I50: 866 | J50: 1081 | K50: 976 | L50: 678 | M50: 2094.955 | N50: 2781.5641 | O50: 3815.5382 | P50: 4989.0312
A51: Bank deposits — current | B51: 8 | C51: 66 | D51: 316 | E51: 785 | F51: 107 | G51: 308 | H51: 728 | I51: 392 | J51: 456 | K51: 727 | L51: 622 | M51: 667.86615 | N51: 613.68077 | O51: 454.26108 | P51: 373.26603
A52: Trade receivables — current | B52: =SUM(B46:B51) -> 958 | C52: =SUM(C46:C51) -> 621 | D52: =SUM(D46:D51) -> 1067 | E52: =SUM(E46:E51) -> 1830 | F52: =SUM(F46:F51) -> 1253 | G52: =SUM(G46:G51) -> 1242 | H52: =SUM(H46:H51) -> 2378 | I52: =SUM(I46:I51) -> 1258 | ... P52: =SUM(P46:P51) -> 5362.2972
A53: Investments — current | B53: 3393 | C53: 6421 | D53: 5490 | E53: 4208 | F53: 3465 | G53: 3973 | H53: 3998 | I53: 4487 | J53: 3776 | K53: 3592 | L53: 3570 | M53: 3833.2511 | N53: 3522.2514 | O53: 2607.2541 | P53: 2142.379
A54: Other current financial assets | B54: 619 | C54: 695 | D54: 661 | E54: 1446 | F54: 1347 | G54: 1781 | H54: 1065 | I54: 405 | J54: 320 | K54: 428 | L54: 433 | M54: 260.52294 | N54: 270.94386 | O54: 284.49105 | P54: 298.7156
A55: Unbilled receivables — current | B55: =SUM(B53:B54) -> 4012 | C55: =SUM(C53:C54) -> 7116 | D55: =SUM(D53:D54) -> 6151 | E55: =SUM(E53:E54) -> 5654 | F55: =SUM(F53:F54) -> 4812 | G55: =SUM(G53:G54) -> 5754 | H55: =SUM(H53:H54) -> 5063 | I55: =SUM(I53:I54) -> 4892 | ... P55: =SUM(P53:P54) -> 2441.0946
A56: Current income tax assets | B56: 5 | C56: 4 | D56: 6 | E56: 268 | F56: 1 | G56: 3 | H56: 1 | I56: 1 | J56: 18 | K56: 30 | L56: 133 | M56: 80.022058 | N56: 83.22294 | O56: 87.384087 | P56: 91.753292
A57: Other current assets | B57: =B55+B56 -> 4017 | C57: =C55+C56 -> 7120 | D57: =D55+D56 -> 6157 | E57: =E55+E56 -> 5922 | F57: =F55+F56 -> 4813 | G57: =G55+G56 -> 5757 | H57: =H55+H56 -> 5064 | I57: =I55+I56 -> 4893 | ... P57: =P55+P56 -> 2532.8479
A58: Total current assets | B58: =B52+B57 -> 4975 | C58: =C52+C57 -> 7741 | D58: =D52+D57 -> 7224 | E58: =E52+E57 -> 7752 | F58: =F52+F57 -> 6066 | G58: =G52+G57 -> 6999 | H58: =H52+H57 -> 7442 | I58: =I52+I57 -> 6151 | ... P58: =P52+P57 -> 7895.145
A59: Bank deposits — non-current | B59: =ROUND(B45-B58,1) -> -980.9 | C59: =ROUND(C45-C58,1) -> -3517.8 | D59: =ROUND(D45-D58,1) -> -2897.8 | E59: =ROUND(E45-E58,1) -> -2949.8 | F59: =ROUND(F45-F58,1) -> -1013.8 | G59: =ROUND(G45-G58,1) -> -2047.8 | H59: =ROUND(H45-H58,1) -> -1669.8 | I59: =ROUND(I45-I58,1) -> -289.8 | ... P59: =ROUND(P45-P58,1) -> -202.2
A60: Investments — non-current | B60: 52 | C60: 53 | D60: 46 | E60: 35 | F60: 29 | G60: 29 | H60: 29 | I60: 32 | J60: 34 | K60: 32 | L60: 23 | M60: 24.696015 | N60: 22.692376 | O60: 16.797435 | P60: 13.802441
A61: Trade receivables — non-current | B61: 0 | C61: 10 | D61: 14 | E61: 14 | F61: 10 | G61: 8 | H61: 19 | I61: 18 | J61: 15 | K61: 11 | L61: 10 | M61: 10.288333 | N61: 10.699867 | O61: 11.23486 | P61: 11.796603
A62: Unbilled receivables — non-current | B62: 0 | C62: 22 | D62: 35 | E62: 57 | F62: 43 | G62: 37 | H62: 7 | I62: 24 | J62: 2 | K62: 4 | L62: 12 | M62: 22.032494 | N62: 22.913793 | O62: 24.059483 | P62: 25.262457
A63: Other non-current financial assets | B63: 510 | C63: 129 | D63: 410 | E63: 115 | F63: 115 | G63: 120 | H63: 176 | I63: 120 | J63: 123 | K63: 123 | L63: 252 | M63: 0 | N63: 0 | O63: 60.235917 | P63: 1.1738839
A64: Non-current income tax assets | B64: 674 | C64: 739 | D64: 635 | E64: 581 | F64: 326 | G64: 251 | H64: 262 | I64: 314 | J64: 192 | K64: 184 | L64: 152 | M64: 0 | N64: 0 | O64: 36.332775 | P64: 0.70805694
A65: Deferred tax assets | B65: 435 | C65: 433 | D65: 527 | E65: 381 | F65: 372 | G65: 532 | H65: 486 | I65: 399 | J65: 405 | K65: 415 | L65: 468 | M65: 0 | N65: 0 | O65: 111.8667 | P65: 2.18007
...

Sheet Segment Revenue
A1: Segment Revenue — Active Geography and Industry Classifications
A4: Metric | B4: FY16A | C4: FY17A | D4: FY18A | E4: FY19A | F4: FY20A | G4: FY21A | H4: FY22A | I4: FY23A | J4: FY24A | K4: FY25A | L4: FY26A | M4: FY27E | N4: FY28E | O4: FY29E | P4: FY30E
A5: Geography mix
A6: Americas | B6: 0.56 | C6: 0.554 | D6: 0.522 | E6: 0.527 | F6: 0.521 | G6: 0.502 | H6: 0.533 | I6: 0.542 | J6: 0.52 | K6: 0.5 | L6: 0.504 | M6: 0.503 | N6: 0.503 | O6: 0.503 | P6: 0.503
A7: North America | B7: 0.54 | C7: 0.533 | D7: 0.502 | E7: 0.507 | F7: 0.503 | G7: 0.486 | H7: 0.516 | I7: 0.524 | J7: 0.5 | K7: 0.482 | L7: 0.485 | M7: 0.483 | N7: 0.483 | O7: 0.483 | P7: 0.483
A8: Latin America | B8: =B$5*B7 -> 0 | C8: =C$5*C7 -> 0 | D8: =D$5*D7 -> 0 | E8: =E$5*E7 -> 0 | F8: =F$5*F7 -> 0 | G8: =G$5*G7 -> 0 | H8: =H$5*H7 -> 0 | I8: =I$5*I7 -> 0 | ... P8: =P$5*P7 -> 0
A9: Europe | B9: 0.261 | C9: 0.255 | D9: 0.294 | E9: 0.3 | F9: 0.312 | G9: 0.328 | H9: 0.311 | I9: 0.308 | J9: 0.314 | K9: 0.311 | L9: 0.328 | M9: 0.326 | N9: 0.326 | O9: 0.326 | P9: 0.326
A10: United Kingdom | B10: =B$5*B9 -> 0 | C10: =C$5*C9 -> 0 | D10: =D$5*D9 -> 0 | E10: =E$5*E9 -> 0 | F10: =F$5*F9 -> 0 | G10: =G$5*G9 -> 0 | H10: =H$5*H9 -> 0 | I10: =I$5*I9 -> 0 | ... P10: =P$5*P9 -> 0
A11: Continental Europe | B11: 0.112 | C11: 0.118 | D11: 0.142 | E11: 0.141 | F11: 0.152 | G11: 0.168 | H11: 0.155 | I11: 0.151 | J11: 0.146 | K11: 0.143 | L11: 0.156 | M11: 0.154 | N11: 0.154 | O11: 0.154 | P11: 0.154
A12: India | B12: =B$5*B11 -> 0 | C12: =C$5*C11 -> 0 | D12: =D$5*D11 -> 0 | E12: =E$5*E11 -> 0 | F12: =F$5*F11 -> 0 | G12: =G$5*G11 -> 0 | H12: =H$5*H11 -> 0 | I12: =I$5*I11 -> 0 | ... P12: =P$5*P11 -> 0
A13: Asia Pacific | B13: 0.096 | C13: 0.097 | D13: 0.097 | E13: 0.095 | F13: 0.093 | G13: 0.094 | H13: 0.085 | I13: 0.08 | J13: 0.078 | K13: 0.081 | L13: 0.083 | M13: 0.084 | N13: 0.084 | O13: 0.084 | P13: 0.084
A14: Middle East & Africa | B14: =B$5*B13 -> 0 | C14: =C$5*C13 -> 0 | D14: =D$5*D13 -> 0 | E14: =E$5*E13 -> 0 | F14: =F$5*F13 -> 0 | G14: =G$5*G13 -> 0 | H14: =H$5*H13 -> 0 | I14: =I$5*I13 -> 0 | ... P14: =P$5*P13 -> 0
A15: Geography total | B15: =IF(COUNT(B7,B9,B11,B13)=4,SUM(B7,B9,B11,B13)-100%,0) -> 0.009 | C15: =IF(COUNT(C7,C9,C11,C13)=4,SUM(C7,C9,C11,C13)-100%,0) -> 0.003 | D15: =IF(COUNT(D7,D9,D11,D13)=4,SUM(D7,D9,D11,D13)-100%,0) -> 0.035 | E15: =IF(COUNT(E7,E9,E11,E13)=4,SUM(E7,E9,E11,E13)-100%,0) -> 0.043 | F15: =IF(COUNT(F7,F9,F11,F13)=4,SUM(F7,F9,F11,F13)-100%,0) -> 0.06 | G15: =IF(COUNT(G7,G9,G11,G13)=4,SUM(G7,G9,G11,G13)-100%,0) -> 0.076 | H15: =IF(COUNT(H7,H9,H11,H13)=4,SUM(H7,H9,H11,H13)-100%,0) -> 0.067 | I15: =IF(COUNT(I7,I9,I11,I13)=4,SUM(I7,I9,I11,I13)-100%,0) -> 0.063 | ... P15: =IF(COUNT(P7,P9,P11,P13)=4,SUM(P7,P9,P11,P13)-100%,0) -> 0.047
A16: Industry mix
A17: BFSI | B17: 0.409 | C17: 0.329 | D17: 0.311 | E17: 0.309 | F17: 0.3 | G17: 0.322 | H17: 0.317 | I17: 0.329 | J17: 0.313 | K17: 0.312 | L17: 0.316 | M17: 0.321 | N17: 0.321 | O17: 0.321 | P17: 0.321
A18: Consumer Business | B18: 0.141 | C18: 0.123 | D18: 0.166 | E18: 0.151 | F18: 0.154 | G18: 0.145 | H18: 0.153 | I18: 0.16 | J18: 0.157 | K18: 0.153 | L18: 0.157 | M18: 0.15 | N18: 0.15 | O18: 0.15 | P18: 0.15
A19: Life Sciences & Healthcare | B19: 0.073 | C19: 0.069 | D19: 0.072 | E19: 0.077 | F19: 0.088 | G19: 0.097 | H19: 0.101 | I19: 0.109 | J19: 0.109 | K19: 0.101 | L19: 0.104 | M19: 0.103 | N19: 0.103 | O19: 0.103 | P19: 0.103
A20: Technology & Services | B20: 0.056 | C20: 0.078 | D20: 0.078 | E20: 0.086 | F20: 0.087 | G20: 0.084 | H20: 0.087 | I20: 0.089 | J20: 0.082 | K20: 0.081 | L20: 0.084 | M20: 0.085 | N20: 0.085 | O20: 0.085 | P20: 0.085
A21: Manufacturing | B21: 0.104 | C21: 0.073 | D21: 0.074 | E21: 0.096 | F21: 0.101 | G21: 0.096 | H21: 0.1 | I21: 0.082 | J21: 0.088 | K21: 0.084 | L21: 0.088 | M21: 0.087 | N21: 0.087 | O21: 0.087 | P21: 0.087
A22: Communication & Media | B22: 0.108 | C22: 0.072 | D22: 0.071 | E22: 0.068 | F22: 0.07 | G22: 0.065 | H22: 0.069 | I22: 0.071 | J22: 0.066 | K22: 0.058 | L22: 0.058 | M22: 0.058 | N22: 0.058 | O22: 0.058 | P22: 0.058
A23: Energy, Resources & Utilities | B23: 0.041 | C23: 0.037 | D23: 0.048 | I23: 0.054 | J23: 0.056 | K23: 0.057 | L23: 0.063 | M23: 0.063 | N23: 0.063 | O23: 0.063 | P23: 0.063
A24: Regional Markets & Others | B24: 0.031 | C24: 0.185 | D24: 0.18 | E24: 0.213 | F24: 0.2 | G24: 0.191 | H24: 0.173 | I24: 0.106 | J24: 0.129 | K24: 0.154 | L24: 0.13 | M24: 0.133 | N24: 0.133 | O24: 0.133 | P24: 0.133
A25: Industry total | B25: 1 | C25: 1 | D25: 1 | E25: 1 | F25: 1 | G25: 1 | H25: 1 | I25: 1 | J25: 1 | K25: 1 | L25: 1 | M25: 1 | N25: 1 | O25: 1 | P25: 1
A26: Constant-currency growth — geography
A27: North America CC growth | B27: 0.117 | C27: 0.043 | D27: 0.049 | E27: 0.099 | F27: 0.002 | G27: 0.059 | H27: 0.187 | I27: 0.096 | J27: -0.023 | K27: -0.019 | L27: 0.025 | M27: 0.02 | N27: 0.02 | O27: 0.02 | P27: 0.02
A28: Latin America CC growth | B28: 0.175 | C28: 0.048 | D28: 0.05 | E28: 0.162 | F28: 0.039 | G28: 0.015 | H28: 0.206 | I28: 0.151 | J28: 0.098 | K28: 0.043 | L28: -0.029 | M28: -0.021 | N28: -0.021 | O28: -0.021 | P28: -0.021
A29: United Kingdom CC growth | B29: 0.064 | C29: 0.097 | D29: 0.107 | E29: 0.213 | F29: 0.054 | G29: 0.01 | H29: 0.13 | I29: 0.17 | J29: 0.062 | K29: 0.012 | L29: -0.012 | M29: -0.006 | N29: -0.006 | O29: -0.006 | P29: -0.006
A30: Continental Europe CC growth | B30: 0.103 | C30: 0.151 | D30: 0.191 | E30: 0.175 | F30: 0.119 | G30: 0.117 | H30: 0.101 | I30: 0.084 | J30: -0.02 | K30: 0.014 | L30: 0.01 | M30: 0.043 | N30: 0.043 | O30: 0.043 | P30: 0.043
A31: India CC growth | B31: 0.056 | C31: 0.209 | D31: -0.023 | E31: 0.113 | F31: -0.019 | G31: 0.112 | H31: 0.07 | I31: 0.134 | J31: 0.379 | K31: 0.33 | L31: -0.23 | M31: 0.229 | N31: 0.229 | O31: 0.229 | P31: 0.229
A32: Asia Pacific CC growth | B32: 0.086 | C32: 0.047 | D32: 0.086 | E32: 0.115 | F32: 0.035 | G32: 0.015 | H32: 0.055 | I32: 0.075 | J32: 0.052 | K32: 0.064 | L32: 0.004 | M32: 0.025 | N32: 0.025 | O32: 0.025 | P32: 0.025
A33: Middle East & Africa CC growth | B33: 0.252 | C33: 0.114 | D33: 0.022 | E33: -0.04 | F33: 0.013 | G33: 0.106 | H33: 0.073 | I33: 0.113 | J33: 0.107 | K33: 0.132 | L33: 0.078 | M33: 0.076 | N33: 0.076 | O33: 0.076 | P33: 0.076
A34: Total CC growth | B34: 0.104 | C34: 0.075 | D34: 0.072 | E34: 0.127 | F34: 0.03 | G34: 0.059 | H34: 0.143 | I34: 0.107 | J34: 0.022 | K34: 0.025 | L34: -0.006 | M34: 0.032 | N34: 0.032 | O34: 0.032 | P34: 0.032
A35: Constant-currency growth — industry
A36: BFSI CC growth | J36: -0.032 | K36: 0.025 | L36: 0.004 | M36: 0.024 | N36: 0.024 | O36: 0.024 | P36: 0.024
