Workbook

Sheet Cover
A1: Tata Consultancy Services — Fresh Integrated Financial Model | B1: Tata Consultancy Services — Fresh Integrated Financial Model | C1: Tata Consultancy Services — Fresh Integrated Financial Model | D1: Tata Consultancy Services — Fresh Integrated Financial Model | E1: Tata Consultancy Services — Fresh Integrated Financial Model | F1: Tata Consultancy Services — Fresh Integrated Financial Model | G1: Tata Consultancy Services — Fresh Integrated Financial Model | H1: Tata Consultancy Services — Fresh Integrated Financial Model | I1: Tata Consultancy Services — Fresh Integrated Financial Model | J1: Tata Consultancy Services — Fresh Integrated Financial Model | K1: Tata Consultancy Services — Fresh Integrated Financial Model | L1: Tata Consultancy Services — Fresh Integrated Financial Model | M1: Tata Consultancy Services — Fresh Integrated Financial Model | N1: Tata Consultancy Services — Fresh Integrated Financial Model | O1: Tata Consultancy Services — Fresh Integrated Financial Model | P1: Tata Consultancy Services — Fresh Integrated Financial Model
A2: Tata Consultancy Services — Fresh Integrated Financial Model | B2: Tata Consultancy Services — Fresh Integrated Financial Model | C2: Tata Consultancy Services — Fresh Integrated Financial Model | D2: Tata Consultancy Services — Fresh Integrated Financial Model | E2: Tata Consultancy Services — Fresh Integrated Financial Model | F2: Tata Consultancy Services — Fresh Integrated Financial Model | G2: Tata Consultancy Services — Fresh Integrated Financial Model | H2: Tata Consultancy Services — Fresh Integrated Financial Model | I2: Tata Consultancy Services — Fresh Integrated Financial Model | J2: Tata Consultancy Services — Fresh Integrated Financial Model | K2: Tata Consultancy Services — Fresh Integrated Financial Model | L2: Tata Consultancy Services — Fresh Integrated Financial Model | M2: Tata Consultancy Services — Fresh Integrated Financial Model | N2: Tata Consultancy Services — Fresh Integrated Financial Model | O2: Tata Consultancy Services — Fresh Integrated Financial Model | P2: Tata Consultancy Services — Fresh Integrated Financial Model
A3: FY16A–FY26A historicals | FY27E–FY30E forecasts | INR million unless stated otherwise | B3: FY16A–FY26A historicals | FY27E–FY30E forecasts | INR million unless stated otherwise | C3: FY16A–FY26A historicals | FY27E–FY30E forecasts | INR million unless stated otherwise | D3: FY16A–FY26A historicals | FY27E–FY30E forecasts | INR million unless stated otherwise | E3: FY16A–FY26A historicals | FY27E–FY30E forecasts | INR million unless stated otherwise | F3: FY16A–FY26A historicals | FY27E–FY30E forecasts | INR million unless stated otherwise | G3: FY16A–FY26A historicals | FY27E–FY30E forecasts | INR million unless stated otherwise | H3: FY16A–FY26A historicals | FY27E–FY30E forecasts | INR million unless stated otherwise | I3: FY16A–FY26A historicals | FY27E–FY30E forecasts | INR million unless stated otherwise | J3: FY16A–FY26A historicals | FY27E–FY30E forecasts | INR million unless stated otherwise | K3: FY16A–FY26A historicals | FY27E–FY30E forecasts | INR million unless stated otherwise | L3: FY16A–FY26A historicals | FY27E–FY30E forecasts | INR million unless stated otherwise | M3: FY16A–FY26A historicals | FY27E–FY30E forecasts | INR million unless stated otherwise | N3: FY16A–FY26A historicals | FY27E–FY30E forecasts | INR million unless stated otherwise | O3: FY16A–FY26A historicals | FY27E–FY30E forecasts | INR million unless stated otherwise | P3: FY16A–FY26A historicals | FY27E–FY30E forecasts | INR million unless stated otherwise
A5: Built from scratch. No formulas, assumptions or outputs have been imported from the discarded TCS model.
A7: Model architecture | B7: Model architecture | C7: Model architecture | D7: Model architecture | E7: Model architecture | F7: Model architecture | G7: Model architecture | H7: Model architecture | I7: Model architecture | J7: Model architecture | K7: Model architecture | L7: Model architecture | M7: Model architecture | N7: Model architecture | O7: Model architecture | P7: Model architecture
A9: Tab | B9: Purpose
A10: Summary | B10: Executive financial, operating and valuation dashboard
A11: Sources | B11: Official reports and source notes
A12: Assumptions | B12: Editable forecast drivers and scenario assumptions
A13: Raw Financials | B13: Reported source layer; reported figures override ex-adjusted cells
A14: Quarterly P&L | B14: Quarterly profit and loss only; FY16–FY30
A15: Annual P&L | B15: Annual income statement, margins, EPS and dividends
A16: Annual Balance Sheet | B16: Detailed current/non-current assets and liabilities
A17: Annual Cash Flow | B17: Line-by-line cash flow with reported controls and cash anchoring
A18: Segment Revenue | B18: Geography and industry mix, absolutes and growth
A19: Currency Revenue | B19: USD/GBP/EUR/Other mix, absolute revenue and growth
A20: Client Data | B20: Client revenue bands and related operating metrics
... A24: Checks | B24: Accounting, cash, currency and formula integrity checks
A27: Formatting legend | B27: Formatting legend | C27: Formatting legend | D27: Formatting legend | E27: Formatting legend | F27: Formatting legend | G27: Formatting legend | H27: Formatting legend | I27: Formatting legend | J27: Formatting legend | K27: Formatting legend | L27: Formatting legend | M27: Formatting legend | N27: Formatting legend | O27: Formatting legend | P27: Formatting legend
A29: Blue font / yellow fill | B29: Editable assumption or input
A30: Green font | B30: Formula linking another tab
A31: Black font | B31: Formula calculated on the same tab
A32: Light green shading | B32: Forecast period
A33: Blue font in Raw Financials | B33: Reported source data

Sheet Summary
A1: TCS Financial Model Summary | B1: TCS Financial Model Summary | C1: TCS Financial Model Summary | D1: TCS Financial Model Summary | E1: TCS Financial Model Summary | F1: TCS Financial Model Summary | G1: TCS Financial Model Summary | H1: TCS Financial Model Summary | I1: TCS Financial Model Summary | J1: TCS Financial Model Summary | K1: TCS Financial Model Summary | L1: TCS Financial Model Summary | M1: TCS Financial Model Summary | N1: TCS Financial Model Summary
A2: TCS Financial Model Summary | B2: TCS Financial Model Summary | C2: TCS Financial Model Summary | D2: TCS Financial Model Summary | E2: TCS Financial Model Summary | F2: TCS Financial Model Summary | G2: TCS Financial Model Summary | H2: TCS Financial Model Summary | I2: TCS Financial Model Summary | J2: TCS Financial Model Summary | K2: TCS Financial Model Summary | L2: TCS Financial Model Summary | M2: TCS Financial Model Summary | N2: TCS Financial Model Summary
A3: Reported historicals, operating drivers, currency analysis, valuation and checks. | B3: Reported historicals, operating drivers, currency analysis, valuation and checks. | C3: Reported historicals, operating drivers, currency analysis, valuation and checks. | D3: Reported historicals, operating drivers, currency analysis, valuation and checks. | E3: Reported historicals, operating drivers, currency analysis, valuation and checks. | F3: Reported historicals, operating drivers, currency analysis, valuation and checks. | G3: Reported historicals, operating drivers, currency analysis, valuation and checks. | H3: Reported historicals, operating drivers, currency analysis, valuation and checks. | I3: Reported historicals, operating drivers, currency analysis, valuation and checks. | J3: Reported historicals, operating drivers, currency analysis, valuation and checks. | K3: Reported historicals, operating drivers, currency analysis, valuation and checks. | L3: Reported historicals, operating drivers, currency analysis, valuation and checks. | M3: Reported historicals, operating drivers, currency analysis, valuation and checks. | N3: Reported historicals, operating drivers, currency analysis, valuation and checks.
A5: Financial overview | B5: Financial overview | C5: Financial overview | D5: Financial overview | E5: Financial overview | F5: Financial overview | G5: Financial overview | H5: Financial overview | I5: Financial overview | J5: Financial overview | K5: Financial overview | L5: Financial overview | M5: Financial overview | N5: Financial overview
B6: FY22 | C6: FY23 | D6: FY24 | E6: FY25 | F6: FY26 | G6: FY27E | H6: FY28E | I6: FY29E | J6: FY30E
A7: Revenue | B7: ='Annual P&L'!$H$6 -> 1917540 | C7: ='Annual P&L'!$I$6 -> 2254580 | D7: ='Annual P&L'!$J$6 -> 2408930 | E7: ='Annual P&L'!$K$6 -> 2553240 | F7: ='Annual P&L'!$L$6 -> 2670210 | G7: ='Annual P&L'!$M$6 -> 2755881.9 | H7: ='Annual P&L'!$N$6 -> 2901779.8 | I7: ='Annual P&L'!$O$6 -> 3046126 | J7: ='Annual P&L'!$P$6 -> 3195140.9
A8: Revenue growth | B8: ='Annual P&L'!$H$7 -> 0.16797115 | C8: ='Annual P&L'!$I$7 -> 0.17576687 | D8: ='Annual P&L'!$J$7 -> 0.068460645 | E8: ='Annual P&L'!$K$7 -> 0.059906265 | F8: ='Annual P&L'!$L$7 -> 0.04581238 | G8: ='Annual P&L'!$M$7 -> 0.032084342 | H8: ='Annual P&L'!$N$7 -> 0.052940551 | I8: ='Annual P&L'!$O$7 -> 0.049744003 | J8: ='Annual P&L'!$P$7 -> 0.048919495
A9: Operating income | B9: ='Annual P&L'!$H$13 -> 484530 | C9: ='Annual P&L'!$I$13 -> 542370 | D9: ='Annual P&L'!$J$13 -> 583530 | E9: ='Annual P&L'!$K$13 -> 621650 | F9: ='Annual P&L'!$L$13 -> 623120 | G9: ='Annual P&L'!$M$13 -> 666923.43 | H9: ='Annual P&L'!$N$13 -> 710936.06 | I9: ='Annual P&L'!$O$13 -> 755439.24 | J9: ='Annual P&L'!$P$13 -> 798785.23
A10: Operating margin | B10: ='Annual P&L'!$H$14 -> 0.25268313 | C10: ='Annual P&L'!$I$14 -> 0.24056365 | D10: ='Annual P&L'!$J$14 -> 0.24223618 | E10: ='Annual P&L'!$K$14 -> 0.24347496 | F10: ='Annual P&L'!$L$14 -> 0.23335992 | G10: ='Annual P&L'!$M$14 -> 0.242 | H10: ='Annual P&L'!$N$14 -> 0.245 | I10: ='Annual P&L'!$O$14 -> 0.248 | J10: ='Annual P&L'!$P$14 -> 0.25
A11: Net income attributable | B11: ='Annual P&L'!$H$22 -> 383270 | C11: ='Annual P&L'!$I$22 -> 421470 | D11: ='Annual P&L'!$J$22 -> 459080 | E11: ='Annual P&L'!$K$22 -> 485530 | F11: ='Annual P&L'!$L$22 -> 492100 | G11: ='Annual P&L'!$M$22 -> 529993.58 | H11: ='Annual P&L'!$N$22 -> 564591.4 | I11: ='Annual P&L'!$O$22 -> 599541.41 | J11: ='Annual P&L'!$P$22 -> 633671.21
A12: Net margin | B12: ='Annual P&L'!$H$23 -> 0.19987588 | C12: ='Annual P&L'!$I$23 -> 0.18693947 | D12: ='Annual P&L'!$J$23 -> 0.19057424 | E12: ='Annual P&L'!$K$23 -> 0.1901623 | F12: ='Annual P&L'!$L$23 -> 0.18429262 | G12: ='Annual P&L'!$M$23 -> 0.1923136 | H12: ='Annual P&L'!$N$23 -> 0.19456727 | I12: ='Annual P&L'!$O$23 -> 0.19682095 | J12: ='Annual P&L'!$P$23 -> 0.1983234
A13: EPS — basic | B13: ='Annual P&L'!$H$24 -> 103.62 | C13: ='Annual P&L'!$I$24 -> 115.19 | D13: ='Annual P&L'!$J$24 -> 125.88 | E13: ='Annual P&L'!$K$24 -> 134.19 | F13: ='Annual P&L'!$L$24 -> 136.01 | G13: ='Annual P&L'!$M$24 -> 146.48445 | H13: ='Annual P&L'!$N$24 -> 156.04692 | I13: ='Annual P&L'!$O$24 -> 165.70672 | J13: ='Annual P&L'!$P$24 -> 175.13982
A14: DPS | B14: ='Annual P&L'!$H$27 -> 43 | C14: ='Annual P&L'!$I$27 -> 115 | D14: ='Annual P&L'!$J$27 -> 73 | E14: ='Annual P&L'!$K$27 -> 126 | F14: ='Annual P&L'!$L$27 -> 110 | G14: ='Annual P&L'!$M$27 -> 117.18756 | H14: ='Annual P&L'!$N$27 -> 124.83753 | I14: ='Annual P&L'!$O$27 -> 132.56537 | J14: ='Annual P&L'!$P$27 -> 140.11186
A15: CFO | B15: ='Annual P&L'!$H$111 -> 399490 | C15: ='Annual P&L'!$I$111 -> 419650 | D15: ='Annual P&L'!$J$111 -> 443380 | E15: ='Annual P&L'!$K$111 -> 489080 | F15: ='Annual P&L'!$L$111 -> 520940 | G15: ='Annual P&L'!$M$111 -> 596746.33 | H15: ='Annual P&L'!$N$111 -> 628674.18 | I15: ='Annual P&L'!$O$111 -> 671708.65 | J15: ='Annual P&L'!$P$111 -> 703967.19
A16: Free cash flow | B16: ='Annual P&L'!$H$141 -> 369540 | C16: ='Annual P&L'!$I$141 -> 388650 | D16: ='Annual P&L'!$J$141 -> 416640 | E16: ='Annual P&L'!$K$141 -> 449710 | F16: ='Annual P&L'!$L$141 -> 479480 | G16: ='Annual P&L'!$M$141 -> 552652.22 | H16: ='Annual P&L'!$N$141 -> 580794.82 | I16: ='Annual P&L'!$O$141 -> 619924.51 | J16: ='Annual P&L'!$P$141 -> 649649.8
A17: Closing cash | B17: ='Annual P&L'!$H$138 -> 124880 | C17: ='Annual P&L'!$I$138 -> 71230 | D17: ='Annual P&L'!$J$138 -> 90160 | E17: ='Annual P&L'!$K$138 -> 83420 | F17: ='Annual P&L'!$L$138 -> 64170 | G17: ='Annual P&L'!$M$138 -> 174267.74 | H17: ='Annual P&L'!$N$138 -> 284557.44 | I17: ='Annual P&L'!$O$138 -> 405688.2 | J17: ='Annual P&L'!$P$138 -> 528994.54
A20: Operating and demand indicators | B20: Operating and demand indicators | C20: Operating and demand indicators | D20: Operating and demand indicators | E20: Operating and demand indicators | F20: Operating and demand indicators | G20: Operating and demand indicators | H20: Operating and demand indicators | I20: Operating and demand indicators | J20: Operating and demand indicators | K20: Operating and demand indicators | L20: Operating and demand indicators | M20: Operating and demand indicators | N20: Operating and demand indicators
A21: Headcount | B21: ='Revenue Drivers'!$H$10 -> 592195 | C21: ='Revenue Drivers'!$I$10 -> 614795 | D21: ='Revenue Drivers'!$J$10 -> 601546 | E21: ='Revenue Drivers'!$K$10 -> 607979 | F21: ='Revenue Drivers'!$L$10 -> 584519 | G21: ='Revenue Drivers'!$M$10 -> 593286.78 | H21: ='Revenue Drivers'!$N$10 -> 605152.52 | I21: ='Revenue Drivers'!$O$10 -> 620281.33 | J21: ='Revenue Drivers'!$P$10 -> 635788.37
A22: Attrition | B22: ='Raw Financials'!$H$135 -> 0.174 | C22: ='Raw Financials'!$I$135 -> 0.201 | D22: ='Raw Financials'!$J$135 -> 0.125 | E22: ='Raw Financials'!$K$135 -> 0.133 | F22: ='Raw Financials'!$L$135 -> 0.137 | G22: ="" | H22: ="" | I22: ="" | J22: =""
A23: TCV (USD bn) | B23: ='Revenue Drivers'!$H$25 -> 34.6 | C23: ='Revenue Drivers'!$I$25 -> 34.1 | D23: ='Revenue Drivers'!$J$25 -> 42.7 | E23: ='Revenue Drivers'!$K$25 -> 39.4 | F23: ='Revenue Drivers'!$L$25 -> 40.7 | G23: ='Revenue Drivers'!$M$25 -> 0 | H23: ='Revenue Drivers'!$N$25 -> 0 | I23: ='Revenue Drivers'!$O$25 -> 0 | J23: ='Revenue Drivers'!$P$25 -> 0
A24: AI exit run-rate (USD bn) | B24: ='Revenue Drivers'!$H$19 -> 0 | C24: ='Revenue Drivers'!$I$19 -> 0 | D24: ='Revenue Drivers'!$J$19 -> 0 | E24: ='Revenue Drivers'!$K$19 -> 0 | F24: ='Revenue Drivers'!$L$19 -> 2.3 | G24: ='Revenue Drivers'!$M$19 -> 3.3 | H24: ='Revenue Drivers'!$N$19 -> 4.1 | I24: ='Revenue Drivers'!$O$19 -> 4.9 | J24: ='Revenue Drivers'!$P$19 -> 5.7
A25: AI revenue uplift (INR m) | B25: ='Revenue Drivers'!$H$22 -> 0 | C25: ='Revenue Drivers'!$I$22 -> 0 | D25: ='Revenue Drivers'!$J$22 -> 0 | E25: ='Revenue Drivers'!$K$22 -> 0 | F25: ='Revenue Drivers'!$L$22 -> 0 | G25: ='Revenue Drivers'!$M$22 -> 47000 | H25: ='Revenue Drivers'!$N$22 -> 133000 | I25: ='Revenue Drivers'!$O$22 -> 211200 | J25: ='Revenue Drivers'!$P$22 -> 291000
G28: =G30/F30-1 -> 0.03717843
A29: Valuation snapshot | B29: Valuation snapshot | C29: Valuation snapshot | D29: Valuation snapshot | E29: Valuation snapshot | F29: Valuation snapshot | G29: Valuation snapshot | H29: Valuation snapshot | I29: Valuation snapshot | J29: Valuation snapshot | K29: Valuation snapshot | L29: Valuation snapshot | M29: Valuation snapshot | N29: Valuation snapshot
A30: Share price | B30: =Valuation!$H$6 -> 3739.95 | C30: =Valuation!$I$6 -> 3205.8999 | D30: =Valuation!$J$6 -> 3876.3 | E30: =Valuation!$K$6 -> 3606.1499 | F30: =Valuation!$L$6 -> 2358.8999 | G30: =Valuation!$M$6 -> 2446.6001 | H30: =Valuation!$N$6 -> 2446.6001 | I30: =Valuation!$O$6 -> 2446.6001 | J30: =Valuation!$P$6 -> 2446.6001
A31: P/E | B31: =Valuation!$H$22 -> 36.092935 | C31: =Valuation!$I$22 -> 27.831408 | D31: =Valuation!$J$22 -> 30.793613 | E31: =Valuation!$K$22 -> 26.873462 | F31: =Valuation!$L$22 -> 17.343577 | G31: =Valuation!$M$22 -> 16.702114 | H31: =Valuation!$N$22 -> 15.678619 | I31: =Valuation!$O$22 -> 14.76464 | J31: =Valuation!$P$22 -> 13.96941
A32: EV / EBITDA | B32: =Valuation!$H$23 -> 25.2832 | C32: =Valuation!$I$23 -> 19.100561 | D32: =Valuation!$J$23 -> 21.706509 | E32: =Valuation!$K$23 -> 18.794763 | F32: =Valuation!$L$23 -> 12.182736 | G32: =Valuation!$M$23 -> 11.680838 | H32: =Valuation!$N$23 -> 10.801262 | I32: =Valuation!$O$23 -> 10.00411 | J32: =Valuation!$P$23 -> 9.3030466
A33: P/B | B33: =Valuation!$H$24 -> 15.158447 | C33: =Valuation!$I$24 -> 12.675923 | D33: =Valuation!$J$24 -> 15.263996 | E33: =Valuation!$K$24 -> 13.467276 | F33: =Valuation!$L$24 -> 7.8030887 | G33: =Valuation!$M$24 -> 7.2274822 | H33: =Valuation!$N$24 -> 6.454778 | I33: =Valuation!$O$24 -> 5.8086679 | J33: =Valuation!$P$24 -> 5.2534689
A34: Dividend yield | B34: =Valuation!$H$25 -> 0.01149748 | C34: =Valuation!$I$25 -> 0.035871363 | D34: =Valuation!$J$25 -> 0.018832391 | E34: =Valuation!$K$25 -> 0.034940311 | F34: =Valuation!$L$25 -> 0.046631907 | G34: =Valuation!$M$25 -> 0.047898127 | H34: =Valuation!$N$25 -> 0.051024903 | I34: =Valuation!$O$25 -> 0.054183508 | J34: =Valuation!$P$25 -> 0.057267986
A35: Average implied value | B35: =Valuation!$H$33 -> 0 | C35: =Valuation!$I$33 -> 0 | D35: =Valuation!$J$33 -> 0 | E35: =Valuation!$K$33 -> 0 | F35: =Valuation!$L$33 -> 0 | G35: =Valuation!$M$33 -> 3303.2545 | H35: =Valuation!$N$33 -> 3464.5241 | I35: =Valuation!$O$33 -> 3612.0175 | J35: =Valuation!$P$33 -> 3741.8277
A38: Model integrity | B38: Model integrity | C38: Model integrity | D38: Model integrity | E38: Model integrity | F38: Model integrity | G38: Model integrity | H38: Model integrity | I38: Model integrity | J38: Model integrity | K38: Model integrity | L38: Model integrity | M38: Model integrity | N38: Model integrity
A39: Overall model check | B39: =Checks!$B$8 -> PASS
A42: Period | B42: Revenue | C42: Operating income | D42: Net income
A43: FY22 | B43: ='Annual P&L'!$H$6 -> 1917540 | C43: ='Annual P&L'!$H$13 -> 484530 | D43: ='Annual P&L'!$H$22 -> 383270
A44: FY23 | B44: ='Annual P&L'!$I$6 -> 2254580 | C44: ='Annual P&L'!$I$13 -> 542370 | D44: ='Annual P&L'!$I$22 -> 421470
A45: FY24 | B45: ='Annual P&L'!$J$6 -> 2408930 | C45: ='Annual P&L'!$J$13 -> 583530 | D45: ='Annual P&L'!$J$22 -> 459080
A46: FY25 | B46: ='Annual P&L'!$K$6 -> 2553240 | C46: ='Annual P&L'!$K$13 -> 621650 | D46: ='Annual P&L'!$K$22 -> 485530
A47: FY26 | B47: ='Annual P&L'!$L$6 -> 2670210 | C47: ='Annual P&L'!$L$13 -> 623120 | D47: ='Annual P&L'!$L$22 -> 492100
A48: FY27E | B48: ='Annual P&L'!$M$6 -> 2755881.9 | C48: ='Annual P&L'!$M$13 -> 666923.43 | D48: ='Annual P&L'!$M$22 -> 529993.58
A49: FY28E | B49: ='Annual P&L'!$N$6 -> 2901779.8 | C49: ='Annual P&L'!$N$13 -> 710936.06 | D49: ='Annual P&L'!$N$22 -> 564591.4
...

Sheet Sources
A1: Sources and Model Notes | B1: Sources and Model Notes | C1: Sources and Model Notes | D1: Sources and Model Notes | E1: Sources and Model Notes | F1: Sources and Model Notes | G1: Sources and Model Notes | H1: Sources and Model Notes | I1: Sources and Model Notes | J1: Sources and Model Notes | K1: Sources and Model Notes | L1: Sources and Model Notes
A2: Sources and Model Notes | B2: Sources and Model Notes | C2: Sources and Model Notes | D2: Sources and Model Notes | E2: Sources and Model Notes | F2: Sources and Model Notes | G2: Sources and Model Notes | H2: Sources and Model Notes | I2: Sources and Model Notes | J2: Sources and Model Notes | K2: Sources and Model Notes | L2: Sources and Model Notes
A3: Primary-source hierarchy, accounting basis and forecast treatment | B3: Primary-source hierarchy, accounting basis and forecast treatment | C3: Primary-source hierarchy, accounting basis and forecast treatment | D3: Primary-source hierarchy, accounting basis and forecast treatment | E3: Primary-source hierarchy, accounting basis and forecast treatment | F3: Primary-source hierarchy, accounting basis and forecast treatment | G3: Primary-source hierarchy, accounting basis and forecast treatment | H3: Primary-source hierarchy, accounting basis and forecast treatment | I3: Primary-source hierarchy, accounting basis and forecast treatment | J3: Primary-source hierarchy, accounting basis and forecast treatment | K3: Primary-source hierarchy, accounting basis and forecast treatment | L3: Primary-source hierarchy, accounting basis and forecast treatment
A5: Primary sources | B5: Primary sources | C5: Primary sources | D5: Primary sources | E5: Primary sources | F5: Primary sources | G5: Primary sources | H5: Primary sources | I5: Primary sources | J5: Primary sources | K5: Primary sources | L5: Primary sources
A6: # | B6: Source | C6: URL | D6: Use
A7: 1 | B7: TCS Financial Statements | C7: https://www.tcs.com/investor-relations/financial-statements | D7: Official TCS source
A8: 2 | B8: TCS FY26 Annual Report | C8: https://www.tcs.com/content/dam/tcs/investor-relations/financial-statements/2025-26/ar/annual-report-2025-2026.pdf | D8: Official TCS source
A9: 3 | B9: TCS FY25 Annual Report | C9: https://www.tcs.com/content/dam/tcs/investor-relations/financial-statements/2024-25/ar/annual-report-2024-2025.pdf | D9: Official TCS source
A10: 4 | B10: TCS FY24 Annual Report | C10: https://www.tcs.com/content/dam/tcs/investor-relations/financial-statements/2023-24/ar/annual-report-2023-2024.pdf | D10: Official TCS source
A11: 5 | B11: TCS FY22 Annual Report | C11: https://www.tcs.com/content/dam/tcs/investor-relations/financial-statements/2021-22/ar/annual-report-2021-2022.pdf | D11: Official TCS source
A12: 6 | B12: TCS FY20 Annual Report | C12: https://www.tcs.com/content/dam/tcs/investor-relations/financial-statements/2019-20/ar/annual-report-2019-2020.pdf | D12: Official TCS source
A13: 7 | B13: TCS FY18 Annual Report | C13: https://www.tcs.com/content/dam/tcs/investor-relations/financial-statements/2017-18/ar/annual-report-2017-2018.pdf | D13: Official TCS source
A14: 8 | B14: TCS FY16 Annual Report | C14: https://www.tcs.com/content/dam/tcs/pdf/discover-tcs/investor-relations/key-events/TCS_Annual_Report_2015-2016.pdf | D14: Official TCS source
A15: 9 | B15: TCS Q1 FY27 Results | C15: https://www.tcs.com/who-we-are/newsroom/press-release/tcs-financial-results-q1-fy-2027 | D15: Official TCS source
A18: Model policies | B18: Model policies | C18: Model policies | D18: Model policies | E18: Model policies | F18: Model policies | G18: Model policies | H18: Model policies | I18: Model policies | J18: Model policies | K18: Model policies | L18: Model policies
A19: Topic | B19: Policy
A20: Reported vs adjusted | B20: Historical P&L uses reported figures. Where the official data sheet stores an ex-adjusted cell and the reported figure in the comment, the reported comment value is used.
A21: Cash flow basis | B21: Historical CFO/CFI/CFF controls are taken from consolidated annual cash-flow statements. Detailed working-capital lines are calculated from the balance sheet; a clearly labelled residual captures translation/reclassification differences.
A22: Cash anchoring | B22: Historical closing cash is linked to reported balance-sheet cash. Forecast balance-sheet cash links to the cash-flow roll-forward.
A23: Segment classifications | B23: Industry classifications changed over time. The model does not manufacture a restated series; separate disclosed classification blocks are retained.
A24: AI revenue | B24: TCS discloses annualised AI run-rate, not reported AI revenue. Forecast AI uplift is time-weighted from opening/closing run-rate and shown separately from core billable revenue.
A25: T&M mix | B25: Recent T&M mix is not disclosed. FY26 base and forecast T&M mix are explicit editable assumptions, not historical facts.
A26: Market price | B26: TCS Prices contains the TCS.NS source series. Valuation price assumptions are formula-linked and separately visible.

Sheet Assumptions
A1: Forecast Assumptions | B1: Forecast Assumptions | C1: Forecast Assumptions | D1: Forecast Assumptions | E1: Forecast Assumptions | F1: Forecast Assumptions | G1: Forecast Assumptions | H1: Forecast Assumptions | I1: Forecast Assumptions | J1: Forecast Assumptions | K1: Forecast Assumptions | L1: Forecast Assumptions | M1: Forecast Assumptions | N1: Forecast Assumptions | O1: Forecast Assumptions | P1: Forecast Assumptions
A2: Forecast Assumptions | B2: Forecast Assumptions | C2: Forecast Assumptions | D2: Forecast Assumptions | E2: Forecast Assumptions | F2: Forecast Assumptions | G2: Forecast Assumptions | H2: Forecast Assumptions | I2: Forecast Assumptions | J2: Forecast Assumptions | K2: Forecast Assumptions | L2: Forecast Assumptions | M2: Forecast Assumptions | N2: Forecast Assumptions | O2: Forecast Assumptions | P2: Forecast Assumptions
A3: Blue-font/yellow-fill cells are editable. Historical metrics are formula-linked and are not forecast inputs. | B3: Blue-font/yellow-fill cells are editable. Historical metrics are formula-linked and are not forecast inputs. | C3: Blue-font/yellow-fill cells are editable. Historical metrics are formula-linked and are not forecast inputs. | D3: Blue-font/yellow-fill cells are editable. Historical metrics are formula-linked and are not forecast inputs. | E3: Blue-font/yellow-fill cells are editable. Historical metrics are formula-linked and are not forecast inputs. | F3: Blue-font/yellow-fill cells are editable. Historical metrics are formula-linked and are not forecast inputs. | G3: Blue-font/yellow-fill cells are editable. Historical metrics are formula-linked and are not forecast inputs. | H3: Blue-font/yellow-fill cells are editable. Historical metrics are formula-linked and are not forecast inputs. | I3: Blue-font/yellow-fill cells are editable. Historical metrics are formula-linked and are not forecast inputs. | J3: Blue-font/yellow-fill cells are editable. Historical metrics are formula-linked and are not forecast inputs. | K3: Blue-font/yellow-fill cells are editable. Historical metrics are formula-linked and are not forecast inputs. | L3: Blue-font/yellow-fill cells are editable. Historical metrics are formula-linked and are not forecast inputs. | M3: Blue-font/yellow-fill cells are editable. Historical metrics are formula-linked and are not forecast inputs. | N3: Blue-font/yellow-fill cells are editable. Historical metrics are formula-linked and are not forecast inputs. | O3: Blue-font/yellow-fill cells are editable. Historical metrics are formula-linked and are not forecast inputs. | P3: Blue-font/yellow-fill cells are editable. Historical metrics are formula-linked and are not forecast inputs.
B5: FY16 | C5: FY17 | D5: FY18 | E5: FY19 | F5: FY20 | G5: FY21 | H5: FY22 | I5: FY23 | J5: FY24 | K5: FY25 | L5: FY26 | M5: FY27E | N5: FY28E | O5: FY29E | P5: FY30E
A7: Revenue and operating drivers | B7: Revenue and operating drivers | C7: Revenue and operating drivers | D7: Revenue and operating drivers | E7: Revenue and operating drivers | F7: Revenue and operating drivers | G7: Revenue and operating drivers | H7: Revenue and operating drivers | I7: Revenue and operating drivers | J7: Revenue and operating drivers | K7: Revenue and operating drivers | L7: Revenue and operating drivers | M7: Revenue and operating drivers | N7: Revenue and operating drivers | O7: Revenue and operating drivers | P7: Revenue and operating drivers
A8: Revenue growth | B8: ="" | C8: =IFERROR(C7/B7-1,"") | D8: =IFERROR(D7/C7-1,"") | E8: =IFERROR(E7/D7-1,"") | F8: =IFERROR(F7/E7-1,"") | G8: =IFERROR(G7/F7-1,"") | H8: =IFERROR(H7/G7-1,"") | I8: =IFERROR(I7/H7-1,"") | J8: =IFERROR(J7/I7-1,"") | ... L8: =IFERROR(L7/K7-1,"") | M8: ='Annual P&L'!$M$7 -> 0.032084342 | N8: ='Annual P&L'!$N$7 -> 0.052940551 | O8: ='Annual P&L'!$O$7 -> 0.049744003 | P8: ='Annual P&L'!$P$7 -> 0.048919495
A9: Headcount growth | B9: ="" | C9: =IFERROR('Raw Financials'!$C$133/'Raw Financials'!$B$133-1,"") -> 0.094335623 | D9: =IFERROR('Raw Financials'!$D$133/'Raw Financials'!$C$133-1,"") -> 0.020078869 | E9: =IFERROR('Raw Financials'!$E$133/'Raw Financials'!$D$133-1,"") -> 0.074144679 | F9: =IFERROR('Raw Financials'!$F$133/'Raw Financials'!$E$133-1,"") -> 0.056987638 | G9: =IFERROR('Raw Financials'!$G$133/'Raw Financials'!$F$133-1,"") -> 0.089605855 | H9: =IFERROR('Raw Financials'!$H$133/'Raw Financials'!$G$133-1,"") -> 0.21190261 | I9: =IFERROR('Raw Financials'!$I$133/'Raw Financials'!$H$133-1,"") -> 0.038163105 | J9: =IFERROR('Raw Financials'!$J$133/'Raw Financials'!$I$133-1,"") -> -0.021550273 | K9: =IFERROR('Raw Financials'!$K$133/'Raw Financials'!$J$133-1,"") -> 0.010694112 | L9: =IFERROR('Raw Financials'!$L$133/'Raw Financials'!$K$133-1,"") -> -0.038586859 | M9: 0.015 | N9: 0.02 | O9: 0.025 | P9: 0.025
A10: Billable employee share (model assumption) | L10: 0.82 | M10: 0.82 | N10: 0.815 | O10: 0.81 | P10: 0.805
A11: T&M mix (model assumption) | L11: 0.55 | M11: 0.53 | N11: 0.51 | O11: 0.49 | P11: 0.47
A12: Pricing / productivity uplift | M12: 0.015 | N12: 0.018 | O12: 0.02 | P12: 0.02
A13: AI deflation on T&M work | M13: 0.015 | N13: 0.02 | O13: 0.025 | P13: 0.03
A14: AI annualised exit run-rate (USD bn) | B14: ='Raw Financials'!$B$139 -> 0 | C14: ='Raw Financials'!$C$139 -> 0 | D14: ='Raw Financials'!$D$139 -> 0 | E14: ='Raw Financials'!$E$139 -> 0 | F14: ='Raw Financials'!$F$139 -> 0 | G14: ='Raw Financials'!$G$139 -> 0 | H14: ='Raw Financials'!$H$139 -> 0 | I14: ='Raw Financials'!$I$139 -> 0 | J14: ='Raw Financials'!$J$139 -> 0 | K14: ='Raw Financials'!$K$139 -> 0 | L14: ='Raw Financials'!$L$139 -> 2.3 | M14: 3.3 | N14: 4.1 | O14: 4.9 | P14: 5.7
A15: Average USD/INR | B15: ='Raw Financials'!$B$151 -> 65.676638 | C15: ='Raw Financials'!$C$151 -> 67.130765 | D15: ='Raw Financials'!$D$151 -> 64.49 | E15: ='Raw Financials'!$E$151 -> 70.07 | F15: ='Raw Financials'!$F$151 -> 71.23 | G15: ='Raw Financials'!$G$151 -> 74.06 | H15: ='Raw Financials'!$H$151 -> 74.61 | I15: ='Raw Financials'!$I$151 -> 80.74 | J15: ='Raw Financials'!$J$151 -> 82.83 | K15: ='Raw Financials'!$K$151 -> 84.59 | L15: ='Raw Financials'!$L$151 -> 88.94 | M15: 94 | N15: 95 | O15: 96 | P15: 97
A16: Average GBP/INR | B16: ='Raw Financials'!$B$152 -> 98.658158 | C16: ='Raw Financials'!$C$152 -> 87.346492 | D16: ='Raw Financials'!$D$152 -> 86.05 | E16: ='Raw Financials'!$E$152 -> 91.6 | F16: ='Raw Financials'!$F$152 -> 90.15 | G16: ='Raw Financials'!$G$152 -> 97.32 | H16: ='Raw Financials'!$H$152 -> 101.5 | I16: ='Raw Financials'!$I$152 -> 96.98 | J16: ='Raw Financials'!$J$152 -> 104.07 | K16: ='Raw Financials'!$K$152 -> 108.26 | L16: ='Raw Financials'!$L$152 -> 119.42 | M16: 126 | N16: 128 | O16: 130 | P16: 132
A17: Average EUR/INR | B17: ='Raw Financials'!$B$153 -> 72.540871 | C17: ='Raw Financials'!$C$153 -> 73.265561 | D17: ='Raw Financials'!$D$153 -> 76.16 | E17: ='Raw Financials'!$E$153 -> 80.82 | F17: ='Raw Financials'!$F$153 -> 78.94 | G17: ='Raw Financials'!$G$153 -> 86.69 | H17: ='Raw Financials'!$H$153 -> 86.36 | I17: ='Raw Financials'!$I$153 -> 84.01 | J17: ='Raw Financials'!$J$153 -> 89.8 | K17: ='Raw Financials'!$K$153 -> 90.81 | L17: ='Raw Financials'!$L$153 -> 103.26 | M17: 110 | N17: 112 | O17: 114 | P17: 116
A18: Client-band growth | M18: 0.03 | N18: 0.03 | O18: 0.025 | P18: 0.025
A21: P&L assumptions | B21: P&L assumptions | C21: P&L assumptions | D21: P&L assumptions | E21: P&L assumptions | F21: P&L assumptions | G21: P&L assumptions | H21: P&L assumptions | I21: P&L assumptions | J21: P&L assumptions | K21: P&L assumptions | L21: P&L assumptions | M21: P&L assumptions | N21: P&L assumptions | O21: P&L assumptions | P21: P&L assumptions
A22: Operating margin | B22: ='Annual P&L'!B$14 -> 0.26498936 | C22: ='Annual P&L'!C$14 -> 0.25705712 | D22: ='Annual P&L'!D$14 -> 0.24777424 | E22: ='Annual P&L'!E$14 -> 0.25569598 | F22: ='Annual P&L'!F$14 -> 0.24581233 | G22: ='Annual P&L'!G$14 -> 0.25875123 | H22: ='Annual P&L'!H$14 -> 0.25268313 | I22: ='Annual P&L'!I$14 -> 0.24056365 | ... L22: ='Annual P&L'!L$14 -> 0.23335992 | M22: 0.242 | N22: 0.245 | O22: 0.248 | P22: 0.25
A23: Cost of revenue / revenue | B23: =IFERROR('Annual P&L'!B$8/'Annual P&L'!B$6,"") -> 0.56053193 | C23: =IFERROR('Annual P&L'!C$8/'Annual P&L'!C$6,"") -> 0.56700236 | D23: =IFERROR('Annual P&L'!D$8/'Annual P&L'!D$6,"") -> 0.5790876 | E23: =IFERROR('Annual P&L'!E$8/'Annual P&L'!E$6,"") -> 0.58143012 | F23: =IFERROR('Annual P&L'!F$8/'Annual P&L'!F$6,"") -> 0.5882293 | G23: =IFERROR('Annual P&L'!G$8/'Annual P&L'!G$6,"") -> 0.59166631 | H23: =IFERROR('Annual P&L'!H$8/'Annual P&L'!H$6,"") -> 0.59775024 | I23: =IFERROR('Annual P&L'!I$8/'Annual P&L'!I$6,"") -> 0.60440526 | ... L23: =IFERROR('Annual P&L'!L$8/'Annual P&L'!L$6,"") -> 0.73074028 | M23: 0.725 | N23: 0.723 | O23: 0.721 | P23: 0.72
A24: Other income / revenue | B24: ='Annual P&L'!B15/'Annual P&L'!B6 -> 0.028074334 | C24: ='Annual P&L'!C15/'Annual P&L'!C6 -> 0.035510232 | D24: ='Annual P&L'!D15/'Annual P&L'!D6 -> 0.029162334 | E24: ='Annual P&L'!E15/'Annual P&L'!E6 -> 0.028082178 | F24: ='Annual P&L'!F15/'Annual P&L'!F6 -> 0.023370649 | G24: ='Annual P&L'!G15/'Annual P&L'!G6 -> 0.015209195 | H24: ='Annual P&L'!H15/'Annual P&L'!H6 -> 0.016865359 | I24: ='Annual P&L'!I15/'Annual P&L'!I6 -> 0.01184256 | ... L24: ='Annual P&L'!L15/'Annual P&L'!L6 -> 0.011890451 | M24: 0.014 | N24: 0.014 | O24: 0.014 | P24: 0.014
A25: Effective tax rate | B25: ='Annual P&L'!B19 -> 0.23563375 | C25: ='Annual P&L'!C19 -> 0.23631675 | D25: ='Annual P&L'!D19 -> 0.24087763 | E25: ='Annual P&L'!E19 -> 0.24062267 | F25: ='Annual P&L'!F19 -> 0.23198731 | G25: ='Annual P&L'!G19 -> 0.25474677 | H25: ='Annual P&L'!H19 -> 0.25611856 | I25: ='Annual P&L'!I19 -> 0.25662924 | ... L25: ='Annual P&L'!L19 -> 0.24482722 | M25: 0.245 | N25: 0.245 | O25: 0.245 | P25: 0.245
A26: NCI / net profit incl. NCI | B26: ='Annual P&L'!B21/'Annual P&L'!B20 -> -0.0050432212 | C26: ='Annual P&L'!C21/'Annual P&L'!C20 -> -0.0025799598 | D26: ='Annual P&L'!D21/'Annual P&L'!D20 -> -0.0020865533 | E26: ='Annual P&L'!E21/'Annual P&L'!E20 -> -0.0028515303 | F26: ='Annual P&L'!F21/'Annual P&L'!F20 -> -0.0032976855 | G26: ='Annual P&L'!G21/'Annual P&L'!G20 -> -0.0039379475 | H26: ='Annual P&L'!H21/'Annual P&L'!H20 -> -0.0031730344 | I26: ='Annual P&L'!I21/'Annual P&L'!I20 -> -0.0036876817 | ... L26: ='Annual P&L'!L21/'Annual P&L'!L20 -> -0.0049338779 | M26: 0.005 | N26: 0.005 | O26: 0.005 | P26: 0.005
A27: D&A / revenue | B27: ='Raw Financials'!B14/'Raw Financials'!B7 -> 0.017376952 | C27: ='Raw Financials'!C14/'Raw Financials'!C7 -> 0.016843836 | D27: ='Raw Financials'!D14/'Raw Financials'!D7 -> 0.016360151 | E27: ='Raw Financials'!E14/'Raw Financials'!E7 -> 0.014030847 | F27: ='Raw Financials'!F14/'Raw Financials'!F7 -> 0.022491383 | G27: ='Raw Financials'!G14/'Raw Financials'!G7 -> 0.024759863 | H27: ='Raw Financials'!H14/'Raw Financials'!H7 -> 0.024009929 | I27: ='Raw Financials'!I14/'Raw Financials'!I7 -> 0.022279094 | ... L27: ='Raw Financials'!L14/'Raw Financials'!L7 -> 0.017830058 | M27: 0.018 | N27: 0.018 | O27: 0.018 | P27: 0.018
A28: Dividend payout ratio | B28: =-'Annual P&L'!B129/'Annual P&L'!B99 -> 0.39134517 | C28: =-'Annual P&L'!C129/'Annual P&L'!C99 -> 0.41533558 | D28: =-'Annual P&L'!D129/'Annual P&L'!D99 -> 0.41445131 | E28: =-'Annual P&L'!E129/'Annual P&L'!E99 -> 0.36195425 | F28: =-'Annual P&L'!F129/'Annual P&L'!F99 -> 1.1598607 | G28: =-'Annual P&L'!G129/'Annual P&L'!G99 -> 0.32368735 | H28: =-'Annual P&L'!H129/'Annual P&L'!H99 -> 0.34635491 | I28: =-'Annual P&L'!I129/'Annual P&L'!I99 -> 0.97740113 | ... L28: =-'Annual P&L'!L129/'Annual P&L'!L99 -> 0.79744813 | M28: 0.8 | N28: 0.8 | O28: 0.8 | P28: 0.8
A31: Balance-sheet assumptions | B31: Balance-sheet assumptions | C31: Balance-sheet assumptions | D31: Balance-sheet assumptions | E31: Balance-sheet assumptions | F31: Balance-sheet assumptions | G31: Balance-sheet assumptions | H31: Balance-sheet assumptions | I31: Balance-sheet assumptions | J31: Balance-sheet assumptions | K31: Balance-sheet assumptions | L31: Balance-sheet assumptions | M31: Balance-sheet assumptions | N31: Balance-sheet assumptions | O31: Balance-sheet assumptions | P31: Balance-sheet assumptions
A32: Trade receivables / revenue | B32: =IFERROR('Raw Financials'!$B$76/'Annual P&L'!$B$6,"") -> 0.22157239 | C32: =IFERROR('Raw Financials'!$C$76/'Annual P&L'!$C$6,"") -> 0.19172473 | D32: =IFERROR('Raw Financials'!$D$76/'Annual P&L'!$D$6,"") -> 0.2026173 | E32: =IFERROR('Raw Financials'!$E$76/'Annual P&L'!$E$6,"") -> 0.18670927 | F32: =IFERROR('Raw Financials'!$F$76/'Annual P&L'!$F$6,"") -> 0.19453453 | G32: =IFERROR('Raw Financials'!$G$76/'Annual P&L'!$G$6,"") -> 0.1832108 | H32: =IFERROR('Raw Financials'!$H$76/'Annual P&L'!$H$6,"") -> 0.17769642 | I32: =IFERROR('Raw Financials'!$I$76/'Annual P&L'!$I$6,"") -> 0.18206939 | J32: =IFERROR('Raw Financials'!$J$76/'Annual P&L'!$J$6,"") -> 0.18445534 | K32: =IFERROR('Raw Financials'!$K$76/'Annual P&L'!$K$6,"") -> 0.19638577 | L32: =IFERROR('Raw Financials'!$L$76/'Annual P&L'!$L$6,"") -> 0.21582572 | M32: 0.215 | N32: 0.213 | O32: 0.211 | P32: 0.21
A33: Unbilled receivables / revenue | B33: =IFERROR('Raw Financials'!$B$79/'Annual P&L'!$B$6,"") -> 0.036743113 | C33: =IFERROR('Raw Financials'!$C$79/'Annual P&L'!$C$6,"") -> 0.044148314 | D33: =IFERROR('Raw Financials'!$D$79/'Annual P&L'!$D$6,"") -> 0.054311801 | E33: =IFERROR('Raw Financials'!$E$79/'Annual P&L'!$E$6,"") -> 0.035210258 | F33: =IFERROR('Raw Financials'!$F$79/'Annual P&L'!$F$6,"") -> 0.036521418 | G33: =IFERROR('Raw Financials'!$G$79/'Annual P&L'!$G$6,"") -> 0.040096969 | H33: =IFERROR('Raw Financials'!$H$79/'Annual P&L'!$H$6,"") -> 0.040343357 | I33: =IFERROR('Raw Financials'!$I$79/'Annual P&L'!$I$6,"") -> 0.039497379 | J33: =IFERROR('Raw Financials'!$J$79/'Annual P&L'!$J$6,"") -> 0.037954611 | K33: =IFERROR('Raw Financials'!$K$79/'Annual P&L'!$K$6,"") -> 0.034873337 | L33: =IFERROR('Raw Financials'!$L$79/'Annual P&L'!$L$6,"") -> 0.03776482 | M33: 0.038 | N33: 0.038 | O33: 0.037 | P33: 0.037
A34: Bank deposits / revenue | B34: =IFERROR(('Raw Financials'!$B$75+'Raw Financials'!$B$83)/'Annual P&L'!$B$6,"") -> 0.0043075594 | C34: =IFERROR(('Raw Financials'!$C$75+'Raw Financials'!$C$83)/'Annual P&L'!$C$6,"") -> 0.0036451181 | D34: =IFERROR(('Raw Financials'!$D$75+'Raw Financials'!$D$83)/'Annual P&L'!$D$6,"") -> 0.016701326 | E34: =IFERROR(('Raw Financials'!$E$75+'Raw Financials'!$E$83)/'Annual P&L'!$E$6,"") -> 0.037060555 | F34: =IFERROR(('Raw Financials'!$F$75+'Raw Financials'!$F$83)/'Annual P&L'!$F$6,"") -> 0.0073463354 | G34: =IFERROR(('Raw Financials'!$G$75+'Raw Financials'!$G$83)/'Annual P&L'!$G$6,"") -> 0.018157233 | H34: =IFERROR(('Raw Financials'!$H$75+'Raw Financials'!$H$83)/'Annual P&L'!$H$6,"") -> 0.035143987 | I34: =IFERROR(('Raw Financials'!$I$75+'Raw Financials'!$I$83)/'Annual P&L'!$I$6,"") -> 0.020216626 | J34: =IFERROR(('Raw Financials'!$J$75+'Raw Financials'!$J$83)/'Annual P&L'!$J$6,"") -> 0.025102431 | K34: =IFERROR(('Raw Financials'!$K$75+'Raw Financials'!$K$83)/'Annual P&L'!$K$6,"") -> 0.031035077 | L34: =IFERROR(('Raw Financials'!$L$75+'Raw Financials'!$L$83)/'Annual P&L'!$L$6,"") -> 0.027024092 | M34: 0.027 | N34: 0.027 | O34: 0.027 | P34: 0.027
A35: Current investments / revenue | B35: =IFERROR('Raw Financials'!$B$77/'Annual P&L'!$B$6,"") -> 0.20690091 | C35: =IFERROR('Raw Financials'!$C$77/'Annual P&L'!$C$6,"") -> 0.35294915 | D35: =IFERROR('Raw Financials'!$D$77/'Annual P&L'!$D$6,"") -> 0.29005556 | E35: =IFERROR('Raw Financials'!$E$77/'Annual P&L'!$E$6,"") -> 0.19862354 | F35: =IFERROR('Raw Financials'!$F$77/'Annual P&L'!$F$6,"") -> 0.16655092 | G35: =IFERROR('Raw Financials'!$G$77/'Annual P&L'!$G$6,"") -> 0.17761319 | H35: =IFERROR('Raw Financials'!$H$77/'Annual P&L'!$H$6,"") -> 0.15781679 | I35: =IFERROR('Raw Financials'!$I$77/'Annual P&L'!$I$6,"") -> 0.16365354 | J35: =IFERROR('Raw Financials'!$J$77/'Annual P&L'!$J$6,"") -> 0.13068458 | K35: =IFERROR('Raw Financials'!$K$77/'Annual P&L'!$K$6,"") -> 0.1201963 | L35: =IFERROR('Raw Financials'!$L$77/'Annual P&L'!$L$6,"") -> 0.12646945 | M35: 0.126 | N35: 0.125 | O35: 0.124 | P35: 0.123
A36: Other current assets / revenue | B36: =IFERROR(('Raw Financials'!$B$78+'Raw Financials'!$B$80+'Raw Financials'!$B$81)/'Annual P&L'!$B$6,"") -> 0.058179664 | C36: =IFERROR(('Raw Financials'!$C$78+'Raw Financials'!$C$80+'Raw Financials'!$C$81)/'Annual P&L'!$C$6,"") -> 0.057881084 | D36: =IFERROR(('Raw Financials'!$D$78+'Raw Financials'!$D$80+'Raw Financials'!$D$81)/'Annual P&L'!$D$6,"") -> 0.056448206 | E36: =IFERROR(('Raw Financials'!$E$78+'Raw Financials'!$E$80+'Raw Financials'!$E$81)/'Annual P&L'!$E$6,"") -> 0.12211275 | F36: =IFERROR(('Raw Financials'!$F$78+'Raw Financials'!$F$80+'Raw Financials'!$F$81)/'Annual P&L'!$F$6,"") -> 0.11712085 | G36: =IFERROR(('Raw Financials'!$G$78+'Raw Financials'!$G$80+'Raw Financials'!$G$81)/'Annual P&L'!$G$6,"") -> 0.14824245 | H36: =IFERROR(('Raw Financials'!$H$78+'Raw Financials'!$H$80+'Raw Financials'!$H$81)/'Annual P&L'!$H$6,"") -> 0.09513752 | I36: =IFERROR(('Raw Financials'!$I$78+'Raw Financials'!$I$80+'Raw Financials'!$I$81)/'Annual P&L'!$I$6,"") -> 0.057979757 | J36: =IFERROR(('Raw Financials'!$J$78+'Raw Financials'!$J$80+'Raw Financials'!$J$81)/'Annual P&L'!$J$6,"") -> 0.062729095 | K36: =IFERROR(('Raw Financials'!$K$78+'Raw Financials'!$K$80+'Raw Financials'!$K$81)/'Annual P&L'!$K$6,"") -> 0.07331469 | L36: =IFERROR(('Raw Financials'!$L$78+'Raw Financials'!$L$80+'Raw Financials'!$L$81)/'Annual P&L'!$L$6,"") -> 0.082098412 | M36: 0.082 | N36: 0.08 | O36: 0.078 | P36: 0.076
A37: PPE / revenue | B37: =IFERROR('Raw Financials'!$B$87/'Annual P&L'!$B$6,"") -> 0.10851736 | C37: =IFERROR('Raw Financials'!$C$87/'Annual P&L'!$C$6,"") -> 0.099528678 | D37: =IFERROR('Raw Financials'!$D$87/'Annual P&L'!$D$6,"") -> 0.09422927 | E37: =IFERROR('Raw Financials'!$E$87/'Annual P&L'!$E$6,"") -> 0.079542273 | F37: =IFERROR('Raw Financials'!$F$87/'Annual P&L'!$F$6,"") -> 0.076062925 | G37: =IFERROR('Raw Financials'!$G$87/'Annual P&L'!$G$6,"") -> 0.073914129 | H37: =IFERROR('Raw Financials'!$H$87/'Annual P&L'!$H$6,"") -> 0.062997382 | I37: =IFERROR('Raw Financials'!$I$87/'Annual P&L'!$I$6,"") -> 0.051428647 | J37: =IFERROR('Raw Financials'!$J$87/'Annual P&L'!$J$6,"") -> 0.046593301 | K37: =IFERROR('Raw Financials'!$K$87/'Annual P&L'!$K$6,"") -> 0.050649371 | L37: =IFERROR('Raw Financials'!$L$87/'Annual P&L'!$L$6,"") -> 0.053104437 | M37: 0.053 | N37: 0.053 | O37: 0.053 | P37: 0.053
A38: ROU assets / revenue | B38: =IFERROR('Raw Financials'!$B$88/'Annual P&L'!$B$6,"") -> 0 | C38: =IFERROR('Raw Financials'!$C$88/'Annual P&L'!$C$6,"") -> 0 | D38: =IFERROR('Raw Financials'!$D$88/'Annual P&L'!$D$6,"") -> 0 | E38: =IFERROR('Raw Financials'!$E$88/'Annual P&L'!$E$6,"") -> 0 | F38: =IFERROR('Raw Financials'!$F$88/'Annual P&L'!$F$6,"") -> 0.050933743 | G38: =IFERROR('Raw Financials'!$G$88/'Annual P&L'!$G$6,"") -> 0.046492505 | H38: =IFERROR('Raw Financials'!$H$88/'Annual P&L'!$H$6,"") -> 0.039821855 | I38: =IFERROR('Raw Financials'!$I$88/'Annual P&L'!$I$6,"") -> 0.033531744 | J38: =IFERROR('Raw Financials'!$J$88/'Annual P&L'!$J$6,"") -> 0.032736526 | K38: =IFERROR('Raw Financials'!$K$88/'Annual P&L'!$K$6,"") -> 0.036326393 | L38: =IFERROR('Raw Financials'!$L$88/'Annual P&L'!$L$6,"") -> 0.041296377 | M38: 0.041 | N38: 0.04 | O38: 0.039 | P38: 0.038
A39: Trade payables / revenue | B39: =IFERROR('Raw Financials'!$B$97/'Annual P&L'!$B$6,"") -> 0.069408772 | C39: =IFERROR('Raw Financials'!$C$97/'Annual P&L'!$C$6,"") -> 0.041579777 | D39: =IFERROR('Raw Financials'!$D$97/'Annual P&L'!$D$6,"") -> 0.041379646 | E39: =IFERROR('Raw Financials'!$E$97/'Annual P&L'!$E$6,"") -> 0.042959655 | F39: =IFERROR('Raw Financials'!$F$97/'Annual P&L'!$F$6,"") -> 0.042943886 | G39: =IFERROR('Raw Financials'!$G$97/'Annual P&L'!$G$6,"") -> 0.047875159 | H39: =IFERROR('Raw Financials'!$H$97/'Annual P&L'!$H$6,"") -> 0.041954796 | I39: =IFERROR('Raw Financials'!$I$97/'Annual P&L'!$I$6,"") -> 0.046638398 | J39: =IFERROR('Raw Financials'!$J$97/'Annual P&L'!$J$6,"") -> 0.041433333 | K39: =IFERROR('Raw Financials'!$K$97/'Annual P&L'!$K$6,"") -> 0.054475882 | L39: =IFERROR('Raw Financials'!$L$97/'Annual P&L'!$L$6,"") -> 0.055456312 | M39: 0.055 | N39: 0.055 | O39: 0.055 | P39: 0.055
A40: Other operating current liabilities / revenue | B40: =IFERROR(('Raw Financials'!$B$101+'Raw Financials'!$B$102+'Raw Financials'!$B$103+'Raw Financials'!$B$104+'Raw Financials'!$B$106)/'Annual P&L'!$B$6,"") -> 0.064990762 | C40: =IFERROR(('Raw Financials'!$C$101+'Raw Financials'!$C$102+'Raw Financials'!$C$103+'Raw Financials'!$C$104+'Raw Financials'!$C$106)/'Annual P&L'!$C$6,"") -> 0.067621179 | D40: =IFERROR(('Raw Financials'!$D$101+'Raw Financials'!$D$102+'Raw Financials'!$D$103+'Raw Financials'!$D$104+'Raw Financials'!$D$106)/'Annual P&L'!$D$6,"") -> 0.090330127 | E40: =IFERROR(('Raw Financials'!$E$101+'Raw Financials'!$E$102+'Raw Financials'!$E$103+'Raw Financials'!$E$104+'Raw Financials'!$E$106)/'Annual P&L'!$E$6,"") -> 0.089490178 | F40: =IFERROR(('Raw Financials'!$F$101+'Raw Financials'!$F$102+'Raw Financials'!$F$103+'Raw Financials'!$F$104+'Raw Financials'!$F$106)/'Annual P&L'!$F$6,"") -> 0.097738756 | G40: =IFERROR(('Raw Financials'!$G$101+'Raw Financials'!$G$102+'Raw Financials'!$G$103+'Raw Financials'!$G$104+'Raw Financials'!$G$106)/'Annual P&L'!$G$6,"") -> 0.11426692 | H40: =IFERROR(('Raw Financials'!$H$101+'Raw Financials'!$H$102+'Raw Financials'!$H$103+'Raw Financials'!$H$104+'Raw Financials'!$H$106)/'Annual P&L'!$H$6,"") -> 0.1300364 | I40: =IFERROR(('Raw Financials'!$I$101+'Raw Financials'!$I$102+'Raw Financials'!$I$103+'Raw Financials'!$I$104+'Raw Financials'!$I$106)/'Annual P&L'!$I$6,"") -> 0.098523894 | J40: =IFERROR(('Raw Financials'!$J$101+'Raw Financials'!$J$102+'Raw Financials'!$J$103+'Raw Financials'!$J$104+'Raw Financials'!$J$106)/'Annual P&L'!$J$6,"") -> 0.096246051 | K40: =IFERROR(('Raw Financials'!$K$101+'Raw Financials'!$K$102+'Raw Financials'!$K$103+'Raw Financials'!$K$104+'Raw Financials'!$K$106)/'Annual P&L'!$K$6,"") -> 0.097221569 | L40: =IFERROR(('Raw Financials'!$L$101+'Raw Financials'!$L$102+'Raw Financials'!$L$103+'Raw Financials'!$L$104+'Raw Financials'!$L$106)/'Annual P&L'!$L$6,"") -> 0.11057183 | M40: 0.112 | N40: 0.111 | O40: 0.11 | P40: 0.109
A41: Current tax liabilities / revenue | B41: =IFERROR('Raw Financials'!$B$105/'Annual P&L'!$B$6,"") -> 0.0074093703 | C41: =IFERROR('Raw Financials'!$C$105/'Annual P&L'!$C$6,"") -> 0.011969551 | D41: =IFERROR('Raw Financials'!$D$105/'Annual P&L'!$D$6,"") -> 0.011543086 | E41: =IFERROR('Raw Financials'!$E$105/'Annual P&L'!$E$6,"") -> 0.018209377 | F41: =IFERROR('Raw Financials'!$F$105/'Annual P&L'!$F$6,"") -> 0.023650995 | G41: =IFERROR('Raw Financials'!$G$105/'Annual P&L'!$G$6,"") -> 0.038026033 | H41: =IFERROR('Raw Financials'!$H$105/'Annual P&L'!$H$6,"") -> 0.041308134 | I41: =IFERROR('Raw Financials'!$I$105/'Annual P&L'!$I$6,"") -> 0.041448962 | J41: =IFERROR('Raw Financials'!$J$105/'Annual P&L'!$J$6,"") -> 0.047460906 | K41: =IFERROR('Raw Financials'!$K$105/'Annual P&L'!$K$6,"") -> 0.04979947 | L41: =IFERROR('Raw Financials'!$L$105/'Annual P&L'!$L$6,"") -> 0.055242846 | M41: 0.055 | N41: 0.055 | O41: 0.055 | P41: 0.055
A42: Current lease liabilities / revenue | B42: =IFERROR('Raw Financials'!$B$100/'Annual P&L'!$B$6,"") -> 0 | C42: =IFERROR('Raw Financials'!$C$100/'Annual P&L'!$C$6,"") -> 0 | D42: =IFERROR('Raw Financials'!$D$100/'Annual P&L'!$D$6,"") -> 0 | E42: =IFERROR('Raw Financials'!$E$100/'Annual P&L'!$E$6,"") -> 0 | F42: =IFERROR('Raw Financials'!$F$100/'Annual P&L'!$F$6,"") -> 0.0080790575 | G42: =IFERROR('Raw Financials'!$G$100/'Annual P&L'!$G$6,"") -> 0.0078695554 | H42: =IFERROR('Raw Financials'!$H$100/'Annual P&L'!$H$6,"") -> 0.0075617719 | I42: =IFERROR('Raw Financials'!$I$100/'Annual P&L'!$I$6,"") -> 0.0065865926 | J42: =IFERROR('Raw Financials'!$J$100/'Annual P&L'!$J$6,"") -> 0.0062475871 | K42: =IFERROR('Raw Financials'!$K$100/'Annual P&L'!$K$6,"") -> 0.0060863844 | L42: =IFERROR('Raw Financials'!$L$100/'Annual P&L'!$L$6,"") -> 0.0068533936 | M42: 0.007 | N42: 0.007 | O42: 0.007 | P42: 0.007
A43: Non-current lease liabilities / revenue | B43: =IFERROR('Raw Financials'!$B$110/'Annual P&L'!$B$6,"") -> 0 | C43: =IFERROR('Raw Financials'!$C$110/'Annual P&L'!$C$6,"") -> 0 | D43: =IFERROR('Raw Financials'!$D$110/'Annual P&L'!$D$6,"") -> 0 | E43: =IFERROR('Raw Financials'!$E$110/'Annual P&L'!$E$6,"") -> 0 | F43: =IFERROR('Raw Financials'!$F$110/'Annual P&L'!$F$6,"") -> 0.044001555 | G43: =IFERROR('Raw Financials'!$G$110/'Annual P&L'!$G$6,"") -> 0.03960969 | H43: =IFERROR('Raw Financials'!$H$110/'Annual P&L'!$H$6,"") -> 0.033209216 | I43: =IFERROR('Raw Financials'!$I$110/'Annual P&L'!$I$6,"") -> 0.027512885 | J43: =IFERROR('Raw Financials'!$J$110/'Annual P&L'!$J$6,"") -> 0.027049354 | K43: =IFERROR('Raw Financials'!$K$110/'Annual P&L'!$K$6,"") -> 0.03069825 | L43: =IFERROR('Raw Financials'!$L$110/'Annual P&L'!$L$6,"") -> 0.03540171 | M43: 0.035 | N43: 0.034 | O43: 0.033 | P43: 0.032
A46: Cash-flow assumptions | B46: Cash-flow assumptions | C46: Cash-flow assumptions | D46: Cash-flow assumptions | E46: Cash-flow assumptions | F46: Cash-flow assumptions | G46: Cash-flow assumptions | H46: Cash-flow assumptions | I46: Cash-flow assumptions | J46: Cash-flow assumptions | K46: Cash-flow assumptions | L46: Cash-flow assumptions | M46: Cash-flow assumptions | N46: Cash-flow assumptions | O46: Cash-flow assumptions | P46: Cash-flow assumptions
A47: PPE capex / revenue | B47: =IFERROR(-'Raw Financials'!$B$189/'Annual P&L'!$B$6,"") -> 0 | C47: =IFERROR(-'Raw Financials'!$C$189/'Annual P&L'!$C$6,"") -> 0.01686079 | D47: =IFERROR(-'Raw Financials'!$D$189/'Annual P&L'!$D$6,"") -> 0.015125422 | E47: =IFERROR(-'Raw Financials'!$E$189/'Annual P&L'!$E$6,"") -> 0.014017192 | F47: =IFERROR(-'Raw Financials'!$F$189/'Annual P&L'!$F$6,"") -> 0.016170858 | G47: =IFERROR(-'Raw Financials'!$G$189/'Annual P&L'!$G$6,"") -> 0.016561394 | H47: =IFERROR(-'Raw Financials'!$H$189/'Annual P&L'!$H$6,"") -> 0.012948882 | I47: =IFERROR(-'Raw Financials'!$I$189/'Annual P&L'!$I$6,"") -> 0.011230473 | J47: =IFERROR(-'Raw Financials'!$J$189/'Annual P&L'!$J$6,"") -> 0.0091409879 | K47: =IFERROR(-'Raw Financials'!$K$189/'Annual P&L'!$K$6,"") -> 0.0114247 | L47: =IFERROR(-'Raw Financials'!$L$189/'Annual P&L'!$L$6,"") -> 0.013744237 | M47: 0.014 | N47: 0.0145 | O47: 0.015 | P47: 0.015
A48: ROU capex / revenue | B48: =IFERROR(-'Raw Financials'!$B$190/'Annual P&L'!$B$6,"") -> 0 | C48: =IFERROR(-'Raw Financials'!$C$190/'Annual P&L'!$C$6,"") -> 0 | D48: =IFERROR(-'Raw Financials'!$D$190/'Annual P&L'!$D$6,"") -> 0 | E48: =IFERROR(-'Raw Financials'!$E$190/'Annual P&L'!$E$6,"") -> 0 | F48: =IFERROR(-'Raw Financials'!$F$190/'Annual P&L'!$F$6,"") -> 0.0033068067 | G48: =IFERROR(-'Raw Financials'!$G$190/'Annual P&L'!$G$6,"") -> 0.0006151897 | H48: =IFERROR(-'Raw Financials'!$H$190/'Annual P&L'!$H$6,"") -> 7.8225226e-05 | I48: =IFERROR(-'Raw Financials'!$I$190/'Annual P&L'!$I$6,"") -> 0.00094474359 | J48: =IFERROR(-'Raw Financials'!$J$190/'Annual P&L'!$J$6,"") -> 0.00012453662 | K48: =IFERROR(-'Raw Financials'!$K$190/'Annual P&L'!$K$6,"") -> 0.00029766101 | L48: =IFERROR(-'Raw Financials'!$L$190/'Annual P&L'!$L$6,"") -> 0.00040820759 | M48: 0.0005 | N48: 0.0005 | O48: 0.0005 | P48: 0.0005
...

Sheet Raw Financials
A1: Raw Reported Financials — Source Layer | B1: Raw Reported Financials — Source Layer | C1: Raw Reported Financials — Source Layer | D1: Raw Reported Financials — Source Layer | E1: Raw Reported Financials — Source Layer | F1: Raw Reported Financials — Source Layer | G1: Raw Reported Financials — Source Layer | H1: Raw Reported Financials — Source Layer | I1: Raw Reported Financials — Source Layer | J1: Raw Reported Financials — Source Layer | K1: Raw Reported Financials — Source Layer | L1: Raw Reported Financials — Source Layer | M1: Raw Reported Financials — Source Layer | N1: Raw Reported Financials — Source Layer | O1: Raw Reported Financials — Source Layer | P1: Raw Reported Financials — Source Layer | Q1: Raw Reported Financials — Source Layer | R1: Raw Reported Financials — Source Layer | S1: Raw Reported Financials — Source Layer | T1: Raw Reported Financials — Source Layer | U1: Raw Reported Financials — Source Layer | V1: Raw Reported Financials — Source Layer | W1: Raw Reported Financials — Source Layer | X1: Raw Reported Financials — Source Layer | Y1: Raw Reported Financials — Source Layer | Z1: Raw Reported Financials — Source Layer | AA1: Raw Reported Financials — Source Layer | AB1: Raw Reported Financials — Source Layer | AC1: Raw Reported Financials — Source Layer | AD1: Raw Reported Financials — Source Layer | AE1: Raw Reported Financials — Source Layer | AF1: Raw Reported Financials — Source Layer | AG1: Raw Reported Financials — Source Layer | AH1: Raw Reported Financials — Source Layer | AI1: Raw Reported Financials — Source Layer | AJ1: Raw Reported Financials — Source Layer | AK1: Raw Reported Financials — Source Layer | AL1: Raw Reported Financials — Source Layer | AM1: Raw Reported Financials — Source Layer | AN1: Raw Reported Financials — Source Layer | AO1: Raw Reported Financials — Source Layer | AP1: Raw Reported Financials — Source Layer | AQ1: Raw Reported Financials — Source Layer | AR1: Raw Reported Financials — Source Layer | AS1: Raw Reported Financials — Source Layer | AT1: Raw Reported Financials — Source Layer
A2: Raw Reported Financials — Source Layer | B2: Raw Reported Financials — Source Layer | C2: Raw Reported Financials — Source Layer | D2: Raw Reported Financials — Source Layer | E2: Raw Reported Financials — Source Layer | F2: Raw Reported Financials — Source Layer | G2: Raw Reported Financials — Source Layer | H2: Raw Reported Financials — Source Layer | I2: Raw Reported Financials — Source Layer | J2: Raw Reported Financials — Source Layer | K2: Raw Reported Financials — Source Layer | L2: Raw Reported Financials — Source Layer | M2: Raw Reported Financials — Source Layer | N2: Raw Reported Financials — Source Layer | O2: Raw Reported Financials — Source Layer | P2: Raw Reported Financials — Source Layer | Q2: Raw Reported Financials — Source Layer | R2: Raw Reported Financials — Source Layer | S2: Raw Reported Financials — Source Layer | T2: Raw Reported Financials — Source Layer | U2: Raw Reported Financials — Source Layer | V2: Raw Reported Financials — Source Layer | W2: Raw Reported Financials — Source Layer | X2: Raw Reported Financials — Source Layer | Y2: Raw Reported Financials — Source Layer | Z2: Raw Reported Financials — Source Layer | AA2: Raw Reported Financials — Source Layer | AB2: Raw Reported Financials — Source Layer | AC2: Raw Reported Financials — Source Layer | AD2: Raw Reported Financials — Source Layer | AE2: Raw Reported Financials — Source Layer | AF2: Raw Reported Financials — Source Layer | AG2: Raw Reported Financials — Source Layer | AH2: Raw Reported Financials — Source Layer | AI2: Raw Reported Financials — Source Layer | AJ2: Raw Reported Financials — Source Layer | AK2: Raw Reported Financials — Source Layer | AL2: Raw Reported Financials — Source Layer | AM2: Raw Reported Financials — Source Layer | AN2: Raw Reported Financials — Source Layer | AO2: Raw Reported Financials — Source Layer | AP2: Raw Reported Financials — Source Layer | AQ2: Raw Reported Financials — Source Layer | AR2: Raw Reported Financials — Source Layer | AS2: Raw Reported Financials — Source Layer | AT2: Raw Reported Financials — Source Layer
