Workbook

Sheet Cover
A1: Tech Mahindra Integrated Financial Model
A2: Fresh official-source build | Quarterly P&L FY16–FY26 | Annual three statements FY16–FY30E | INR crore unless stated
A4: Operating model, cash-anchored three statements, client mining, TCV, AI revenue bridge and valuation
A6: Model scope | B6: Quarterly P&L only; annual P&L, balance sheet and detailed cash flow
A7: Historical period | B7: FY16–FY26
A8: Forecast period | B8: Quarterly P&L FY16–Q1 FY27; annual P&L, balance sheet and detailed cash flow FY16–FY30E
A9: Primary source | B9: Tech Mahindra Q4 FY26 official data sheet, with cached reported values from the company workbook
A10: Cash policy | B10: Historical CFS ending cash is reconciled explicitly to reported balance-sheet cash; forecast cash is formula-linked across statements
A11: Forecast revenue | B11: Retained base + billable-capacity expansion − T&M AI deflation + deal realization + client mining + AI uplift
A12: AI disclosure policy | B12: No historical AI revenue is hardcoded because Tech Mahindra did not carve it out in the source data sheet; forecast uplift is an editable assumption
A13: Industry classifications | B13: Legacy, FY22–FY23 recast and current FY24+ classifications remain separate; classifications are not blended
A14: Client policy | B14: Discontinued / unavailable fields remain blank; revenue per client is calculated only on a clearly labelled proxy basis
A15: Formatting | B15: Forecast balance sheet rebuilt with explicit asset, working-capital, debt, lease, equity and cash roll-forwards; no circular references
A16: Model status | B16: =Checks!B6 -> OK

Sheet Summary
A1: Tech Mahindra Summary
A2: Annual investment summary through FY26A; Q1 FY27A detail is on the update tab; forecast balance sheet and cash flow use one-way, no-plug schedules
A5: Metric | B5: Units | C5: FY16A | D5: FY17A | E5: FY18A | F5: FY19A | G5: FY20A | H5: FY21A | I5: FY22A | J5: FY23A | K5: FY24A | L5: FY25A | M5: FY26A | N5: FY27E | O5: FY28E | P5: FY29E | Q5: FY30E
A7: Revenue | B7: ₹ cr | C7: ='Annual P&L'!C7 -> 26494.232 | D7: ='Annual P&L'!D7 -> 29140.841 | E7: ='Annual P&L'!E7 -> 30772.881 | F7: ='Annual P&L'!F7 -> 34742.132 | G7: ='Annual P&L'!G7 -> 36867.679 | H7: ='Annual P&L'!H7 -> 37855.081 | I7: ='Annual P&L'!I7 -> 44645.964 | J7: ='Annual P&L'!J7 -> 53290.167 | ... Q7: ='Annual P&L'!Q7 -> 66753.18
A8: Revenue growth | B8: % | C8: ='Annual P&L'!C8 -> 0 | D8: ='Annual P&L'!D8 -> 0.099893788 | E8: ='Annual P&L'!E8 -> 0.056005236 | F8: ='Annual P&L'!F8 -> 0.12898534 | G8: ='Annual P&L'!G8 -> 0.061180684 | H8: ='Annual P&L'!H8 -> 0.026782321 | I8: ='Annual P&L'!I8 -> 0.17939159 | J8: ='Annual P&L'!J8 -> 0.19361667 | ... Q8: ='Annual P&L'!Q8 -> 0.053920233
A9: USD revenue | B9: $m | C9: ='Geography & Currency'!C40 -> 4037.4553 | D9: ='Geography & Currency'!D40 -> 4351.0924 | E9: ='Geography & Currency'!E40 -> 4770.7659 | F9: ='Geography & Currency'!F40 -> 4970.5229 | G9: ='Geography & Currency'!G40 -> 5181.87 | H9: ='Geography & Currency'!H40 -> 5111.06 | I9: ='Geography & Currency'!I40 -> 5997.79 | J9: ='Geography & Currency'!J40 -> 6606.52 | ... Q9: ='Geography & Currency'!Q40 -> 6811.549
A10: USD revenue growth | B10: % | C10: ='Geography & Currency'!C41 -> 0 | D10: ='Geography & Currency'!D41 -> 0.077681863 | E10: ='Geography & Currency'!E41 -> 0.096452438 | F10: ='Geography & Currency'!F41 -> 0.041871071 | G10: ='Geography & Currency'!G41 -> 0.042520083 | H10: ='Geography & Currency'!H41 -> -0.013664951 | I10: ='Geography & Currency'!I41 -> 0.17349239 | J10: ='Geography & Currency'!J41 -> 0.10149238 | ... Q10: ='Geography & Currency'!Q41 -> 0.043165944
A11: EBITDA | B11: ₹ cr | C11: ='Annual P&L'!C15 -> 4270.6903 | D11: ='Annual P&L'!D15 -> 4184.4348 | E11: ='Annual P&L'!E15 -> 4709.5592 | F11: ='Annual P&L'!F15 -> 6336.9176 | G11: ='Annual P&L'!G15 -> 5726.039 | H11: ='Annual P&L'!H15 -> 6847.047 | I11: ='Annual P&L'!I15 -> 8019.984 | J11: ='Annual P&L'!J15 -> 8028.776 | ... Q11: ='Annual P&L'!Q15 -> 12416.092
A12: EBITDA margin | B12: % | C12: ='Annual P&L'!C16 -> 0.16119321 | D12: ='Annual P&L'!D16 -> 0.14359348 | E12: ='Annual P&L'!E16 -> 0.15304252 | F12: ='Annual P&L'!F16 -> 0.18239864 | G12: ='Annual P&L'!G16 -> 0.15531325 | H12: ='Annual P&L'!H16 -> 0.18087524 | I12: ='Annual P&L'!I16 -> 0.17963514 | J12: ='Annual P&L'!J16 -> 0.15066149 | ... Q12: ='Annual P&L'!Q16 -> 0.186
A13: EBIT | B13: ₹ cr | C13: ='Annual P&L'!C20 -> 3511.7673 | D13: ='Annual P&L'!D20 -> 3206.3796 | E13: ='Annual P&L'!E20 -> 3624.5722 | F13: ='Annual P&L'!F20 -> 5207.7176 | G13: ='Annual P&L'!G20 -> 4280.27 | H13: ='Annual P&L'!H20 -> 5389.337 | I13: ='Annual P&L'!I20 -> 6499.591 | J13: ='Annual P&L'!J20 -> 6072.076 | ... Q13: ='Annual P&L'!Q20 -> 10413.496
A14: EBIT margin | B14: % | C14: ='Annual P&L'!C21 -> 0.13254837 | D14: ='Annual P&L'!D21 -> 0.11003044 | E14: ='Annual P&L'!E21 -> 0.11778462 | F14: ='Annual P&L'!F21 -> 0.14989632 | G14: ='Annual P&L'!G21 -> 0.11609817 | H14: ='Annual P&L'!H21 -> 0.1423676 | I14: ='Annual P&L'!I21 -> 0.14558071 | J14: ='Annual P&L'!J21 -> 0.11394365 | ... Q14: ='Annual P&L'!Q21 -> 0.156
A15: Net income | B15: ₹ cr | C15: ='Annual P&L'!C35 -> 2992.886 | D15: ='Annual P&L'!D35 -> 2812.9331 | E15: ='Annual P&L'!E35 -> 3799.755 | F15: ='Annual P&L'!F35 -> 4297.6165 | G15: ='Annual P&L'!G35 -> 4032.942 | H15: ='Annual P&L'!H35 -> 4428.059 | I15: ='Annual P&L'!I35 -> 5566.113 | J15: ='Annual P&L'!J35 -> 4831.276 | ... Q15: ='Annual P&L'!Q35 -> 8008.9397
A16: Net margin | B16: % | C16: ='Annual P&L'!C36 -> 0.11296368 | D16: ='Annual P&L'!D36 -> 0.09652889 | E16: ='Annual P&L'!E36 -> 0.12347739 | F16: ='Annual P&L'!F36 -> 0.12370043 | G16: ='Annual P&L'!G36 -> 0.10938964 | H16: ='Annual P&L'!H36 -> 0.11697397 | I16: ='Annual P&L'!I36 -> 0.12467225 | J16: ='Annual P&L'!J36 -> 0.090659802 | ... Q16: ='Annual P&L'!Q36 -> 0.1199784
A17: Diluted EPS | B17: ₹ / share | C17: ='Annual P&L'!C40 -> 33.71415 | D17: ='Annual P&L'!D40 -> 31.644762 | E17: ='Annual P&L'!E40 -> 42.664589 | F17: ='Annual P&L'!F40 -> 47.720502 | G17: ='Annual P&L'!G40 -> 45.85 | H17: ='Annual P&L'!H40 -> 50.19 | I17: ='Annual P&L'!I40 -> 62.81 | J17: ='Annual P&L'!J40 -> 54.56 | ... Q17: ='Annual P&L'!Q40 -> 90.211242
A18: CFO | B18: ₹ cr | C18: ='Annual Cash Flow'!C38 -> 3213.1963 | D18: ='Annual Cash Flow'!D38 -> 4071.356 | E18: ='Annual Cash Flow'!E38 -> 3553.6 | F18: ='Annual Cash Flow'!F38 -> 4432.0486 | G18: ='Annual Cash Flow'!G38 -> 4358.058 | H18: ='Annual Cash Flow'!H38 -> 8093.841 | I18: ='Annual Cash Flow'!I38 -> 5285.2743 | J18: ='Annual Cash Flow'!J38 -> 5571.964 | ... Q18: ='Annual Cash Flow'!Q38 -> 9597.0303
A19: FCF | B19: ₹ cr | C19: ='Annual Cash Flow'!C88 -> 2286.6963 | D19: ='Annual Cash Flow'!D88 -> 3303.1643 | E19: ='Annual Cash Flow'!E88 -> 2536.9712 | F19: ='Annual Cash Flow'!F88 -> 3627.4486 | G19: ='Annual Cash Flow'!G88 -> 3513.458 | H19: ='Annual Cash Flow'!H88 -> 7427.841 | I19: ='Annual Cash Flow'!I88 -> 4326.8743 | J19: ='Annual Cash Flow'!J88 -> 4556.794 | ... Q19: ='Annual Cash Flow'!Q88 -> 8729.2389
A20: FCF / net income | B20: % | C20: ='Annual Cash Flow'!C89 -> 0.76404389 | D20: ='Annual Cash Flow'!D89 -> 1.1742776 | E20: ='Annual Cash Flow'!E89 -> 0.66766705 | F20: ='Annual Cash Flow'!F89 -> 0.84406057 | G20: ='Annual Cash Flow'!G89 -> 0.87118982 | H20: ='Annual Cash Flow'!H89 -> 1.6774485 | I20: ='Annual Cash Flow'!I89 -> 0.77736013 | J20: ='Annual Cash Flow'!J89 -> 0.94318644 | ... Q20: ='Annual Cash Flow'!Q89 -> 1.0899369
A21: Cash + investments | B21: ₹ cr | C21: ='Annual Balance Sheet'!C62 -> 6507.1237 | D21: ='Annual Balance Sheet'!D62 -> 5614.1408 | E21: ='Annual Balance Sheet'!E62 -> 7735.0749 | F21: ='Annual Balance Sheet'!F62 -> 9664.4913 | G21: ='Annual Balance Sheet'!G62 -> 8976.8873 | H21: ='Annual Balance Sheet'!H62 -> 13044.901 | I21: ='Annual Balance Sheet'!I62 -> 8661.3736 | J21: ='Annual Balance Sheet'!J62 -> 7469.912 | ... Q21: ='Annual Balance Sheet'!Q62 -> 15595.34
A22: Net cash / (debt) | B22: ₹ cr | C22: ='Annual Balance Sheet'!C63 -> 5504.9222 | D22: ='Annual Balance Sheet'!D63 -> 4394.7052 | E22: ='Annual Balance Sheet'!E63 -> 6009.1218 | F22: ='Annual Balance Sheet'!F63 -> 8259.7913 | G22: ='Annual Balance Sheet'!G63 -> 5348.8873 | H22: ='Annual Balance Sheet'!H63 -> 10175.101 | I22: ='Annual Balance Sheet'!I63 -> 6042.9375 | J22: ='Annual Balance Sheet'!J63 -> 4729.712 | ... Q22: ='Annual Balance Sheet'!Q63 -> 13089.304
A23: Total headcount | B23: # | C23: ='Revenue Drivers'!C6 -> 105432 | D23: ='Revenue Drivers'!D6 -> 117693 | E23: ='Revenue Drivers'!E6 -> 112807 | F23: ='Revenue Drivers'!F6 -> 121082 | G23: ='Revenue Drivers'!G6 -> 125236 | H23: ='Revenue Drivers'!H6 -> 121054 | I23: ='Revenue Drivers'!I6 -> 151173 | J23: ='Revenue Drivers'!J6 -> 152400 | ... Q23: ='Revenue Drivers'!Q6 -> 154362.43
A24: Implied billable IT FTE | B24: # | C24: ='Revenue Drivers'!C11 -> 55886.747 | D24: ='Revenue Drivers'!D11 -> 63339.329 | E24: ='Revenue Drivers'!E11 -> 60718.443 | F24: ='Revenue Drivers'!F11 -> 58468.186 | G24: ='Revenue Drivers'!G11 -> 59472.448 | H24: ='Revenue Drivers'!H11 -> 59805.198 | I24: ='Revenue Drivers'!I11 -> 71324.73 | J24: ='Revenue Drivers'!J11 -> 72461.746 | ... Q24: ='Revenue Drivers'!Q11 -> 70767.457
A25: LTM attrition | B25: % | C25: ='Revenue Drivers'!C35 -> 0.21073297 | D25: ='Revenue Drivers'!D35 -> 0.16516347 | E25: ='Revenue Drivers'!E35 -> 0.18084726 | F25: ='Revenue Drivers'!F35 -> 0.208 | G25: ='Revenue Drivers'!G35 -> 0.191 | H25: ='Revenue Drivers'!H35 -> 0.133 | I25: ='Revenue Drivers'!I35 -> 0.235 | J25: ='Revenue Drivers'!J35 -> 0.148 | ... Q25: ='Revenue Drivers'!Q35 -> 0.105
A26: TCV | B26: $m | C26: ='Revenue Drivers'!C22 -> 0 | D26: ='Revenue Drivers'!D22 -> 0 | E26: ='Revenue Drivers'!E22 -> 0 | F26: ='Revenue Drivers'!F22 -> 1666.9 | G26: ='Revenue Drivers'!G22 -> 3712 | H26: ='Revenue Drivers'!H22 -> 2209.69 | I26: ='Revenue Drivers'!I22 -> 3280 | J26: ='Revenue Drivers'!J22 -> 2905 | ... Q26: ='Revenue Drivers'!Q22 -> 4834.1102
A27: Revenue / $1m+ client proxy | B27: $m | C27: ='Client Data'!C18 -> 12.6566 | D27: ='Client Data'!D18 -> 12.291221 | E27: ='Client Data'!E18 -> 12.170321 | F27: ='Client Data'!F18 -> 11.695348 | G27: ='Client Data'!G18 -> 11.618543 | H27: ='Client Data'!H18 -> 11.332727 | I27: ='Client Data'!I18 -> 11.446164 | J27: ='Client Data'!J18 -> 11.351409 | ... Q27: ='Client Data'!Q18 -> 11.314865
A28: AI uplift | B28: ₹ cr | C28: ='Revenue Drivers'!C29 -> 0 | D28: ='Revenue Drivers'!D29 -> 0 | E28: ='Revenue Drivers'!E29 -> 0 | F28: ='Revenue Drivers'!F29 -> 0 | G28: ='Revenue Drivers'!G29 -> 0 | H28: ='Revenue Drivers'!H29 -> 0 | I28: ='Revenue Drivers'!I29 -> 0 | J28: ='Revenue Drivers'!J29 -> 0 | ... Q28: ='Revenue Drivers'!Q29 -> 1266.7596
A29: AI deflation drag | B29: ₹ cr | C29: ='Revenue Drivers'!C21 -> 0 | D29: ='Revenue Drivers'!D21 -> 0 | E29: ='Revenue Drivers'!E21 -> 0 | F29: ='Revenue Drivers'!F21 -> 0 | G29: ='Revenue Drivers'!G21 -> 0 | H29: ='Revenue Drivers'!H21 -> 0 | I29: ='Revenue Drivers'!I21 -> 0 | J29: ='Revenue Drivers'!J21 -> 0 | ... Q29: ='Revenue Drivers'!Q21 -> -555.70935
A30: Share price / implied target | B30: ₹ / share | C30: =Valuation!C7 -> 474.95001 | D30: =Valuation!D7 -> 459.14999 | E30: =Valuation!E7 -> 638.70001 | F30: =Valuation!F7 -> 771.70001 | G30: =Valuation!G7 -> 565.5 | H30: =Valuation!H7 -> 991.45001 | I30: =Valuation!I7 -> 1499.45 | J30: =Valuation!J7 -> 1101.85 | ... Q30: =Valuation!Q7 -> 2165.0698
A31: P/E | B31: x | C31: =Valuation!C14 -> 14.087557 | D31: =Valuation!D14 -> 14.50951 | E31: =Valuation!E14 -> 14.97026 | F31: =Valuation!F14 -> 16.171247 | G31: =Valuation!G14 -> 12.333697 | H31: =Valuation!H14 -> 19.753935 | I31: =Valuation!I14 -> 23.87279 | J31: =Valuation!J14 -> 20.195197 | ... Q31: =Valuation!Q14 -> 24
A32: EV / EBITDA | B32: x | C32: =Valuation!C15 -> 8.5835142 | D32: =Valuation!D15 -> 8.703583 | E32: =Valuation!E15 -> 10.802327 | F32: =Valuation!F15 -> 9.6636928 | G32: =Valuation!G15 -> 7.7526885 | H32: =Valuation!H15 -> 11.289026 | I32: =Valuation!I15 -> 15.814958 | J32: =Valuation!J15 -> 11.563265 | ... Q32: =Valuation!Q15 -> 14.426863
A33: Dividend yield | B33: % | C33: =Valuation!C18 -> 0.014811757 | D33: =Valuation!D18 -> 0.030361056 | E33: =Valuation!E18 -> 0.016591552 | F33: =Valuation!F18 -> 0.021449595 | G33: =Valuation!G18 -> 0.0500934 | H33: =Valuation!H18 -> 0.020113445 | I33: =Valuation!I18 -> 0.029958222 | J33: =Valuation!J18 -> 0.043695453 | ... Q33: =Valuation!Q18 -> 0.033333333

Sheet Sources
A1: Sources & Data Conventions
A2: Official source register, including the Q1 FY27 Tech Mahindra data sheet used for the latest-quarter update
A5: ID | B5: Data / Period | C5: Units | D5: Primary source | E5: Use in model | F5: Status | G5: Notes
A6: S1 | B6: FY16–FY26 data sheet | C6: ₹ mn / $m / % / # | D6: https://insights.techmahindra.com/investors/tml-q4-fy-26-datasheet.xlsx | E6: Quarterly P&L, annual BS/CFS and operating metrics | F6: Loaded | G6: Official company file; cached values used for external-link cells
A7: S2 | B7: Quarterly earnings archive | C7: mixed | D7: https://www.techmahindra.com/investors/quarterly-earnings/ | E7: Cross-checks and disclosure definitions | F7: Referenced | G7: Company investor archive
A8: S3 | B8: FY26 Q4 earnings presentation | C8: mixed | D8: https://insights.techmahindra.com/investors/tml-q4-fy-26-earnings-presentation.pdf | E8: FY26 strategy and operating context | F8: Loaded | G8: No historical AI revenue hardcoded unless explicitly disclosed
A9: S4 | B9: Annual reports archive | C9: ₹ mn | D9: https://www.techmahindra.com/investors/annual-reports-filings/?report-section=tech-mahindra | E9: Accounting policy and annual cross-checks | F9: Referenced | G9: Official annual reports
A10: S5 | B10: TECHM.NS daily prices | C10: ₹ / share | D10: https://query1.finance.yahoo.com/v8/finance/chart/TECHM.NS | E10: Historical price tab and FY-end prices | F10: Loaded | G10: Market price source only; valuation formulas are model calculations
A11: S6 | B11: Industry classifications | C11: % | D11: Official FY26 data sheet — Operating Metrics | E11: Industry revenue tabs | F11: Loaded | G11: Legacy, FY22–23 recast and FY24+ current classifications kept separate
A12: S7 | B12: Cash-flow dividends | C12: ₹ mn | D12: Official FY26 data sheet — Cash Flow rows 77 and 81 | E12: Dividend paid and payout calculations | F12: Loaded | G12: Both reported dividend rows retained separately; total dividend is their sum
A13: S8 | B13: Unavailable disclosures | C13: n/a | D13: n/a | E13: Blanks retained | F13: Policy | G13: No unreported historical T&M mix or historical AI revenue is invented
A14: S9 | B14: Q1 FY27 data sheet | C14: ₹ mn / $m / % / # | D14: https://insights.techmahindra.com/investors/tml-q1-fy-27-datasheet.xlsx | E14: Q1 FY27 P&L, operating metrics, liquidity and cash-flow snapshot | F14: Loaded | G14: Official company data sheet; Q1 values converted from ₹ million to ₹ crore where applicable

Sheet Assumptions
A1: Forecast Assumptions
A2: Blue text on yellow = editable input; balance-sheet forecasts use explicit drivers and cash is calculated from the cash-flow statement
A5: Driver | B5: Units | C5: FY27E | D5: FY28E | E5: FY29E | F5: FY30E | G5: Rationale / anchor
A6: Total headcount growth | B6: % | C6: 0 | D6: 0.01 | E6: 0.015 | F6: 0.02
A7: Software professional share | B7: % | C7: 0.515 | D7: 0.52 | E7: 0.525 | F7: 0.53
A8: Utilization / billable rate | B8: % | C8: 0.86 | D8: 0.862 | E8: 0.865 | F8: 0.865
A9: Revenue per billable FTE pricing / productivity | B9: % | C9: 0.02 | D9: 0.025 | E9: 0.03 | F9: 0.03
A10: Billable capacity revenue realization | B10: % | C10: 0.5 | D10: 0.5 | E10: 0.5 | F10: 0.5
A11: Core revenue retention | B11: % | C11: 0.96 | D11: 0.96 | E11: 0.96 | F11: 0.96
A12: T&M mix | B12: % | C12: 0.35 | D12: 0.33 | E12: 0.31 | F12: 0.3
A13: AI deflation on T&M revenue | B13: % | C13: 0.015 | D13: 0.02 | E13: 0.025 | F13: 0.03
A14: TCV growth | B14: % | C14: 0.05 | D14: 0.06 | E14: 0.07 | F14: 0.07
A15: TCV current-year revenue realization | B15: % | C15: 0.08 | D15: 0.08 | E15: 0.08 | F15: 0.08
A16: AI revenue uplift / prior-year revenue | B16: % | C16: 0.008 | D16: 0.012 | E16: 0.016 | F16: 0.02
A17: Client-mining uplift / prior-year revenue | B17: % | C17: 0.005 | D17: 0.006 | E17: 0.007 | F17: 0.008
... A33: Current operating liabilities / revenue | B33: % | C33: 0.23 | D33: 0.228 | E33: 0.226 | F33: 0.225
A34: Other non-current liabilities / revenue | B34: % | C34: 0.001 | D34: 0.001 | E34: 0.001 | F34: 0.001 | G34: Reset from 5%+ of revenue; FY26 reported other non-current liabilities were immaterial.
A35: Capex / revenue | B35: % | C35: 0.013 | D35: 0.013 | E35: 0.013 | F35: 0.013
A36: ROU additions / revenue | B36: % | C36: 0.012 | D36: 0.012 | E36: 0.012 | F36: 0.012 | G36: ROU additions calibrated to keep ROU assets and lease liabilities broadly stable relative to revenue.
A37: Lease principal / opening lease liability | B37: % | C37: 0.3 | D37: 0.3 | E37: 0.3 | F37: 0.3 | G37: Lease principal as a percentage of opening total lease liabilities.
A38: Acquisitions / business payments | B38: ₹ cr | C38: 0 | D38: 0 | E38: 0 | F38: 0
A39: Net borrowing change | B39: ₹ cr | C39: 0 | D39: 0 | E39: 0 | F39: 0
A40: Current debt share | B40: % | C40: 0.15 | D40: 0.15 | E40: 0.15 | F40: 0.15
A41: Dividend payout | B41: % | C41: 0.8 | D41: 0.8 | E41: 0.8 | F41: 0.8
A42: Other comprehensive income / reserves | B42: ₹ cr | C42: 0 | D42: 0 | E42: 0 | F42: 0
A43: Diluted share count change | B43: % | C43: 0 | D43: 0 | E43: 0 | F43: 0
A44: Target P/E | B44: x | C44: 22.5 | D44: 23 | E44: 23.5 | F44: 24
A45: LTM attrition | B45: % | C45: 0.12 | D45: 0.115 | E45: 0.11 | F45: 0.105
A46: Current lease liability share | B46: % | C46: 0.25 | D46: 0.25 | E46: 0.25 | F46: 0.25
A47: Current tax liabilities / revenue | B47: % | C47: 0.035 | D47: 0.034 | E47: 0.033 | F47: 0.032
A48: Trade payables / revenue | B48: % | C48: 0.088 | D48: 0.087 | E48: 0.086 | F48: 0.085
A49: Current provisions / revenue | B49: % | C49: 0.022 | D49: 0.021 | E49: 0.02 | F49: 0.02
... A52: Share-based compensation / revenue | B52: % | C52: 0.002 | D52: 0.002 | E52: 0.002 | F52: 0.002
A54: Balance-sheet and cash-flow forecast drivers
A55: D&A allocation — PPE | B55: % | C55: 0.35 | D55: 0.35 | E55: 0.35 | F55: 0.35 | G55: Explicit allocation; forecast D&A allocations sum to 100%.
A56: D&A allocation — ROU assets | B56: % | C56: 0.35 | D56: 0.35 | E56: 0.35 | F56: 0.35 | G56: Explicit allocation; used in the ROU asset roll-forward.
A57: D&A allocation — intangibles | B57: % | C57: 0.3 | D57: 0.3 | E57: 0.3 | F57: 0.3 | G57: Explicit allocation; used in the intangible asset roll-forward.
A58: Intangible additions / revenue | B58: % | C58: 0.003 | D58: 0.003 | E58: 0.003 | F58: 0.003 | G58: Included within total capex; prevents unsupported hardcoded intangible balances.
A59: Closing CWIP / tangible capex | B59: % | C59: 0.04 | D59: 0.04 | E59: 0.04 | F59: 0.04 | G59: Anchored to FY26 CWIP as a share of annual capex.
A60: Inventories / revenue | B60: % | C60: 0.0018 | D60: 0.0018 | E60: 0.0018 | F60: 0.0018 | G60: Anchored to the FY26 reported ratio.
...

Sheet Raw Financials
A1: Raw Reported Financials — Source Layer
A2: Official Tech Mahindra reported inputs only; quarterly P&L updated through Q1 FY27A; annual statements remain FY16–FY30E
A4: Annual reported P&L (INR crore unless stated)
A5: Metric | B5: Units | C5: FY16A | D5: FY17A | E5: FY18A | F5: FY19A | G5: FY20A | H5: FY21A | I5: FY22A | J5: FY23A | K5: FY24A | L5: FY25A | M5: FY26A
A6: Revenue | B6: ₹ cr | C6: 26494.232 | D6: 29140.841 | E6: 30772.881 | F6: 34742.132 | G6: 36867.679 | H6: 37855.081 | I6: 44645.964 | J6: 53290.167 | K6: 51995.541 | L6: 52988.3 | M6: 56815.4
A7: Cost of services | B7: ₹ cr | C7: 18329.038 | D7: 20566.059 | E7: 21530.042 | F7: 23358.982 | G7: 25974.337 | H7: 25855.48 | I7: 30972.015 | J7: 38119.703 | K7: 39114.67 | L7: 38084.794 | M7: 39868.82
A8: Gross profit | B8: ₹ cr | C8: 8165.1946 | D8: 8574.7821 | E8: 9242.8906 | F8: 11383.149 | G8: 10893.442 | H8: 11999.6 | I8: 13673.949 | J8: 15170.464 | K8: 12880.882 | L8: 14903.506 | M8: 16946.579
A9: SG&A | B9: ₹ cr | C9: 3894.5043 | D9: 4390.3473 | E9: 4533.2804 | F9: 5046.2316 | G9: 5167.303 | H9: 5152.554 | I9: 5653.965 | J9: 7141.688 | K9: 7916.272 | L9: 7912.4214 | M9: 7912.4797
A10: EBITDA | B10: ₹ cr | C10: 4270.6903 | D10: 4184.4348 | E10: 4709.6102 | F10: 6336.9176 | G10: 5726.139 | H10: 6847.047 | I10: 8019.984 | J10: 8028.776 | K10: 4964.54 | L10: 6991.1424 | M10: 9034.0995
A11: D&A | B11: ₹ cr | C11: 758.923 | D11: 978.0552 | E11: 1085.038 | F11: 1129.2 | G11: 1445.769 | H11: 1457.71 | I11: 1520.392 | J11: 1956.7 | K11: 1817.098 | L11: 1852.8996 | M11: 1881.6
A12: EBIT | B12: ₹ cr | C12: 3511.7673 | D12: 3206.3796 | E12: 3624.5722 | F12: 5207.7176 | G12: 4280.27 | H12: 5389.337 | I12: 6499.591 | J12: 6072.076 | K12: 3147.511 | L12: 5138.2428 | M12: 7152.4995
A13: Impairment | B13: ₹ cr | G13: 217.5 | H13: 50.7 | I13: 0 | J13: 237 | K13: 458.22 | L13: 27.300702 | M13: 5.3290705e-16
A14: Other income total | B14: ₹ cr | C14: 439.37796 | D14: 777.5589 | E14: 1416.45 | F14: 534.15286 | G14: 1192.39 | H14: 787.116 | I14: 1112.316 | J14: 965 | K14: 916.898 | L14: 855.39962 | M14: 31.9
A15: FX gain / (loss) | B15: ₹ cr | C15: 98.59186 | D15: 387.58728 | E15: 774.95874 | F15: 12.109998 | G15: 302.2 | H15: 97.5 | I15: 564.214 | J15: 299 | K15: -42.099 | L15: -237.60038 | M15: -479.9
A16: Interest, dividend & miscellaneous income | B16: ₹ cr | C16: 340.7861 | D16: 389.97161 | E16: 641.4893 | F16: 522.09286 | G16: 890.19 | H16: 689.616 | I16: 548.102 | J16: 666 | K16: 958.998 | L16: 1093 | M16: 511.8
A17: Interest expense | B17: ₹ cr | C17: 97.037558 | D17: 128.59243 | E17: 162.35364 | F17: 133.161 | G17: 191.878 | H17: 174 | I17: 162.6 | J17: 325.6 | K17: 392.199 | L17: 321.7 | M17: 337.4
A18: Share of associate | B18: ₹ cr | C18: 2.6293348 | D18: -2.3315044 | E18: 0.0699921 | F18: -65.549 | G18: -5.54 | H18: 1.2 | I18: 2.8 | J18: -29 | K18: 10.5 | L18: 8.6 | M18: -1.5
A19: PBT before exceptional | B19: ₹ cr | C19: 3856.737 | D19: 3853.0146 | E19: 4878.7506 | F19: 5543.1605 | G19: 5057.842 | H19: 5952.853 | I19: 7452.107 | J19: 6445.477 | K19: 3224.39 | L19: 5653.2418 | M19: 6845.4995
A20: Exceptional item | B20: ₹ cr | C20: 0 | D20: 0 | E20: 0 | F20: 0 | G20: 0 | I20: 0 | J20: 0 | M20: 272.4
A21: PBT | B21: ₹ cr | G21: 5057.842 | H21: 5952.853 | I21: 7452.107 | J21: 6445.477 | K21: 3224.39 | L21: 5653.2418 | M21: 6573.0995
A22: Tax | B22: ₹ cr | C22: 830.11881 | D22: 1002.1243 | E22: 1092.5615 | F22: 1254.394 | G22: 1160.4 | H22: 1599.894 | I22: 1821.994 | J22: 1588.5 | K22: 827.596 | L22: 1400.2 | M22: 1767.5995
A23: PAT before NCI | B23: ₹ cr | C23: 3026.6182 | D23: 2850.8903 | E23: 3786.1891 | F23: 4288.7665 | G23: 3897.442 | H23: 4352.959 | I23: 5630.113 | J23: 4856.977 | K23: 2396.793 | L23: 4253.0418 | M23: 4805.5
A24: NCI / minority interest | B24: ₹ cr | C24: -33.732182 | D24: -37.957189 | E24: 13.579915 | F24: 8.8 | G24: 135.6 | H24: 75 | I24: -64 | J24: 25.7 | K24: 38.999 | L24: 1.5 | M24: -5.3996265
A25: Net income attributable | B25: ₹ cr | C25: 2992.886 | D25: 2812.9331 | E25: 3799.769 | F25: 4297.5665 | G25: 4033.042 | H25: 4427.959 | I25: 5566.113 | J25: 4831.277 | K25: 2357.793 | L25: 4251.5418 | M25: 4810.8996
A26: Reported basic EPS | B26: ₹ / share | C26: 34.508496 | D26: 32.135676 | E26: 43.020352 | F26: 48.474931 | G26: 46.21 | H26: 50.64 | I26: 63.32 | J26: 54.79 | K26: 26.66 | L26: 48.004796 | M26: 54.279265
A27: Reported diluted EPS | B27: ₹ / share | C27: 33.71415 | D27: 31.644762 | E27: 42.664589 | F27: 47.720502 | G27: 45.85 | H27: 50.19 | I27: 62.81 | J27: 54.56 | K27: 26.57 | L27: 47.906128 | M27: 54.189099
A28: USD revenue | B28: $m | C28: 4037.4553 | D28: 4351.0924 | E28: 4770.7659 | F28: 4970.5229 | G28: 5181.87 | H28: 5111.06 | I28: 5997.79 | J28: 6606.52 | K28: 6277.11 | L28: 6263.9885 | M28: 6384.8643
A32: Quarterly reported P&L (INR crore unless stated)
A33: Metric | B33: Units | C33: Q1 FY16A | D33: Q2 FY16A | E33: Q3 FY16A | F33: Q4 FY16A | G33: Q1 FY17A | H33: Q2 FY17A | I33: Q3 FY17A | J33: Q4 FY17A | K33: Q1 FY18A | L33: Q2 FY18A | M33: Q3 FY18A | N33: Q4 FY18A | O33: Q1 FY19A | P33: Q2 FY19A | Q33: Q3 FY19A | R33: Q4 FY19A | S33: Q1 FY20A | T33: Q2 FY20A | U33: Q3 FY20A | V33: Q4 FY20A | W33: Q1 FY21A | X33: Q2 FY21A | Y33: Q3 FY21A | Z33: Q4 FY21A | AA33: Q1 FY22A | AB33: Q2 FY22A | AC33: Q3 FY22A | AD33: Q4 FY22A | AE33: Q1 FY23A | AF33: Q2 FY23A | AG33: Q3 FY23A | AH33: Q4 FY23A | AI33: Q1 FY24A | AJ33: Q2 FY24A | AK33: Q3 FY24A | AL33: Q4 FY24A | AM33: Q1 FY25A | AN33: Q2 FY25A | AO33: Q3 FY25A | AP33: Q4 FY25A | AQ33: Q1 FY26A | AR33: Q2 FY26A | AS33: Q3 FY26A | AT33: Q4 FY26A | AU33: Q1 FY27A
A34: Revenue | B34: ₹ cr | C34: 6293.8237 | D34: 6615.535 | E34: 6701.1416 | F34: 6883.832 | G34: 6920.9344 | H34: 7167.4101 | I34: 7557.5027 | J34: 7494.9943 | K34: 7336.1015 | L34: 7606.3316 | M34: 7775.9562 | N34: 8054.4918 | O34: 8276.2768 | P34: 8629.8487 | Q34: 8943.7135 | R34: 8892.2925 | S34: 8653.029 | T34: 9069.8861 | U34: 9654.5972 | V34: 9490.1669 | W34: 9106.3485 | X34: 9371.7577 | Y34: 9647.0624 | Z34: 9729.912 | AA34: 10197.569 | AB34: 10881.329 | AC34: 11450.79 | AD34: 12116.276 | AE34: 12707.948 | AF34: 13129.468 | AG34: 13734.561 | AH34: 13718.191 | AI34: 13158.977 | AJ34: 12863.917 | AK34: 13101.337 | AL34: 12871.321 | AM34: 13005.474 | AN34: 13313.222 | AO34: 13285.603 | AP34: 13384.001 | AQ34: 13351.2 | AR34: 13994.9 | AS34: 14393.2 | AT34: 15076.1 | AU34: 15711.9
A35: Cost of services | B35: ₹ cr | C35: 4444.0768 | D35: 4499.8859 | E35: 4606.9072 | F35: 4778.1677 | G35: 4880.6965 | H35: 4971.6661 | I35: 5235.2369 | J35: 5478.4599 | K35: 5281.8369 | L35: 5378.9078 | M35: 5380.7436 | N35: 5488.6133 | O35: 5733.9752 | P35: 5692.3055 | Q35: 5984.5337 | R35: 5948.168 | S35: 6164.1896 | T35: 6389.31 | U35: 6731.1711 | V35: 6689.5661 | W35: 6510.4657 | X35: 6424.5493 | Y35: 6470.7935 | Z35: 6449.6548 | AA35: 6968.2267 | AB35: 7434.6173 | AC35: 8008.8287 | AD35: 8560.3421 | AE35: 9116.1914 | AF35: 9461.3919 | AG35: 9793.742 | AH35: 9748.3781 | AI35: 9780.528 | AJ35: 9975.187 | AK35: 9964.831 | AL35: 9394.124 | AM35: 9553.175 | AN35: 9595.681 | AO35: 9455.913 | AP35: 9480.0253 | AQ35: 9523.6221 | AR35: 9915.8871 | AS35: 10027.556 | AT35: 10401.756 | AU35: 10925.9
A36: Gross profit | B36: ₹ cr | C36: 1849.7469 | D36: 2115.6491 | E36: 2094.2343 | F36: 2105.6642 | G36: 2040.2379 | H36: 2195.744 | I36: 2322.2657 | J36: 2016.5345 | K36: 2054.2646 | L36: 2227.4409 | M36: 2395.2527 | N36: 2565.8784 | O36: 2542.3016 | P36: 2937.5432 | Q36: 2959.1799 | R36: 2944.1245 | S36: 2488.8394 | T36: 2680.5761 | U36: 2923.4261 | V36: 2800.6008 | W36: 2595.8329 | X36: 2947.2514 | Y36: 3176.2688 | Z36: 3280.1573 | AA36: 3229.4422 | AB36: 3446.7121 | AC36: 3441.9608 | AD36: 3556.034 | AE36: 3591.6564 | AF36: 3668.0763 | AG36: 3940.8505 | AH36: 3969.8129 | AI36: 3378.549 | AJ36: 2888.73 | AK36: 3136.489 | AL36: 3477.198 | AM36: 3452.298 | AN36: 3717.541 | AO36: 3829.69 | AP36: 3903.976 | AQ36: 3827.5779 | AR36: 4079.0125 | AS36: 4365.6444 | AT36: 4674.3445 | AU36: 4786
A37: SG&A | B37: ₹ cr | C37: 944.75481 | D37: 1028.8609 | E37: 966.2309 | F37: 954.75776 | G37: 1011.1581 | H37: 1125.6222 | I37: 1135.7654 | J37: 1117.8017 | K37: 1119.6513 | L37: 1121.7821 | M37: 1137.7603 | N37: 1153.9866 | O37: 1185.3942 | P37: 1318.8096 | Q37: 1236.551 | R37: 1305.3767 | S37: 1174.7104 | T37: 1179.7077 | U37: 1360.1441 | V37: 1452.7411 | W37: 1295.341 | X37: 1244.2749 | Y37: 1280.9445 | Z37: 1332.0932 | AA37: 1352.9733 | AB37: 1451.4975 | AC37: 1381.9415 | AD37: 1467.5532 | AE37: 1711.6086 | AF37: 1683.9573 | AG37: 1796.8511 | AH37: 1949.2738 | AI37: 2040.469 | AJ37: 1816.414 | AK37: 1990.042 | AL37: 2069.397 | AM37: 1887.825 | AN37: 1967.304 | AO37: 2020.71 | AP37: 2036.5803 | AQ37: 1892.3779 | AR37: 1911.0129 | AS37: 2000.0444 | AT37: 2109.0445 | AU37: 2043.5
A38: EBITDA | B38: ₹ cr | C38: 904.99209 | D38: 1086.7882 | E38: 1128.0034 | F38: 1150.9065 | G38: 1029.0799 | H38: 1070.1218 | I38: 1186.5003 | J38: 898.73282 | K38: 934.61328 | L38: 1105.6487 | M38: 1257.5003 | N38: 1411.8889 | O38: 1356.9074 | P38: 1618.7336 | Q38: 1722.6288 | R38: 1638.7478 | S38: 1314.129 | T38: 1500.8684 | U38: 1563.282 | V38: 1347.8598 | W38: 1300.5418 | X38: 1702.9765 | Y38: 1895.4243 | Z38: 1948.0641 | AA38: 1876.3688 | AB38: 1995.2146 | AC38: 2060.0194 | AD38: 2088.3809 | AE38: 1880.1477 | AF38: 1984.1191 | AG38: 2143.9704 | AH38: 2020.5391 | AI38: 1337.98 | AJ38: 1072.316 | AK38: 1146.464 | AL38: 1407.8 | AM38: 1564.474 | AN38: 1750.237 | AO38: 1808.98 | AP38: 1867.3957 | AQ38: 1935.2 | AR38: 2167.9996 | AS38: 2365.6 | AT38: 2565.3 | AU38: 2742.5
A39: D&A | B39: ₹ cr | C39: 172.4159 | D39: 196.53226 | E39: 172.65135 | F39: 217.3235 | G39: 201.87768 | H39: 244.74799 | I39: 247.9649 | J39: 283.46462 | K39: 246.84448 | L39: 265.35834 | M39: 274.1945 | N39: 298.64069 | O39: 280.77248 | P39: 294.42932 | Q39: 283.58468 | R39: 270.41352 | S39: 321.3 | T39: 341.45864 | U39: 384.81181 | V39: 398.19855 | W39: 383.2 | X39: 371.67778 | Y39: 358.36199 | Z39: 344.36983 | AA39: 331.1 | AB39: 342.95005 | AC39: 362.10011 | AD39: 484.24203 | AE39: 476.7 | AF39: 491.7 | AG39: 498.10014 | AH39: 490.2 | AI39: 446.6 | AJ39: 465.7 | AK39: 443.4 | AL39: 461.4 | AM39: 462.2 | AN39: 469.8 | AO39: 458.8 | AP39: 462.1 | AQ39: 458.1 | AR39: 468.7 | AS39: 473.7 | AT39: 481.1 | AU39: 478.6
A40: EBIT | B40: ₹ cr | C40: 732.57618 | D40: 890.25595 | E40: 955.35209 | F40: 933.58299 | G40: 827.20218 | H40: 825.37382 | I40: 938.53544 | J40: 615.2682 | K40: 687.75079 | L40: 840.24039 | M40: 983.30584 | N40: 1113.2512 | O40: 1076.1349 | P40: 1324.3043 | Q40: 1439.0441 | R40: 1368.3343 | S40: 992.82896 | T40: 1159.4098 | U40: 1178.4702 | V40: 949.56122 | W40: 917.34183 | X40: 1331.2988 | Y40: 1536.9624 | Z40: 1603.6942 | AA40: 1545.2688 | AB40: 1652.1645 | AC40: 1697.9193 | AD40: 1604.2388 | AE40: 1403.4477 | AF40: 1492.4191 | AG40: 1645.8702 | AH40: 1530.3391 | AI40: 891.38 | AJ40: 606.616 | AK40: 703.064 | AL40: 946.4 | AM40: 1102.274 | AN40: 1280.437 | AO40: 1350.18 | AP40: 1405.2957 | AQ40: 1477.1 | AR40: 1699.2996 | AS40: 1891.9 | AT40: 2084.2 | AU40: 2263.9
A41: Impairment | B41: ₹ cr | V41: 217.5 | W41: 0 | X41: 0 | Y41: 0 | Z41: 50.7 | AA41: 0 | AB41: 0 | AC41: 0 | AD41: 0 | AE41: 0 | AF41: 24.4 | AG41: 0 | AH41: 212.6 | AI41: 0 | AJ41: 149.5 | AK41: 0.000243524 | AL41: 308.7 | AM41: 0 | AN41: 0 | AO41: 0 | AP41: 27.300367 | AQ41: 0 | AR41: 0 | AS41: 0 | AT41: 0 | AU41: 0
A42: Other income total | B42: ₹ cr | C42: 124.44579 | D42: 97.760828 | E42: 61.857079 | F42: 155.31426 | G42: 245.79645 | H42: 138.71927 | I42: 155.19625 | J42: 237.84692 | K42: 410.90054 | L42: 322.15663 | M42: 232.13896 | N42: 451.2539 | O42: 111.39728 | P42: 175.05295 | Q42: 80.55981 | R42: 167.14282 | S42: 341.3 | T42: 216.33868 | U42: 349.592 | V42: 285.15932 | W42: 416.1 | X42: 117.5 | Y42: 220.916 | Z42: 32.6 | AA42: 287.3 | AB42: 282.116 | AC42: 223.1 | AD42: 319.8 | AE42: 122.1 | AF42: 290.20049 | AG42: 247.2 | AH42: 305.5 | AI42: 191.7 | AJ42: 264.2 | AK42: 87.5 | AL42: 373.5 | AM42: 144.7 | AN42: 521.5 | AO42: 16.5 | AP42: 172.7 | AQ42: 218.3 | AR42: 40 | AS42: -21.7 | AT42: -204.7 | AU42: -106.4
A43: FX gain / (loss) | B43: ₹ cr | C43: 79.854662 | D43: -20.448292 | E43: -13.136941 | F43: 52.342432 | G43: 47.890939 | H43: 87.622259 | I43: 90.419583 | J43: 161.6545 | K43: 272.64986 | L43: 226.95068 | M43: 101.14944 | N43: 174.25076 | O43: 14.655578 | P43: 50.051803 | Q43: -77.891057 | R43: 25.193673 | S43: 101.8 | T43: 49.597158 | U43: 143.5 | V43: 7.3028417 | W43: 85.7 | X43: -35.6 | Y43: 110.2 | Z43: -62.8 | AA43: 107.7 | AB43: 121.3 | AC43: 124.41389 | AD43: 210.8 | AE43: 53.6 | AF43: 126.7 | AG43: 125.1 | AH43: -6.4 | AI43: 44.5 | AJ43: -3 | AK43: -43.5 | AL43: -40.1 | AM43: -6.5 | AN43: -101.3 | AO43: -91.4 | AP43: -38.4 | AQ43: 29.7 | AR43: -109.5 | AS43: -115.8 | AT43: -284.3 | AU43: -214
A44: Interest, dividend & miscellaneous income | B44: ₹ cr | C44: 44.591127 | D44: 118.20912 | E44: 74.99402 | F44: 102.97183 | G44: 197.90552 | H44: 51.097014 | I44: 64.776663 | J44: 76.192422 | K44: 138.25068 | L44: 95.205952 | M44: 131.00952 | N44: 276.97314 | O44: 96.741704 | P44: 124.95115 | Q44: 158.45087 | R44: 141.94914 | S44: 239.5 | T44: 166.74152 | U44: 206.092 | V44: 277.85648 | W44: 330.4 | X44: 153.1 | Y44: 110.716 | Z44: 95.4 | AA44: 179.6 | AB44: 160.816 | AC44: 98.686114 | AD44: 109 | AE44: 68.5 | AF44: 163.50049 | AG44: 122.1 | AH44: 311.9 | AI44: 147.2 | AJ44: 267.2 | AK44: 131 | AL44: 413.6 | AM44: 151.2 | AN44: 622.8 | AO44: 107.9 | AP44: 211.1 | AQ44: 188.6 | AR44: 149.5 | AS44: 94.1 | AT44: 79.6 | AU44: 107.6
...

Sheet Raw Operating
A1: Raw Reported Operating Metrics
A2: Reported annual / Q4 snapshot inputs from the official Tech Mahindra data sheet
A5: Metric | B5: Units | C5: FY16A | D5: FY17A | E5: FY18A | F5: FY19A | G5: FY20A | H5: FY21A | I5: FY22A | J5: FY23A | K5: FY24A | L5: FY25A | M5: FY26A | N5: FY27E | O5: FY28E | P5: FY29E | Q5: FY30E
A6: USD revenue | B6: $m | C6: 4037.4553 | D6: 4351.0924 | E6: 4770.7659 | F6: 4970.5229 | G6: 5181.87 | H6: 5111.06 | I6: 5997.79 | J6: 6606.52 | K6: 6277.11 | L6: 6263.9885 | M6: 6384.8643
A7: Total headcount | B7: # | C7: 105432 | D7: 117693 | E7: 112807 | F7: 121082 | G7: 125236 | H7: 121054 | I7: 151173 | J7: 152400 | K7: 145455 | L7: 148731 | M7: 147623
A8: Software professionals | B8: # | C8: 72125 | D8: 82403 | E8: 72437 | F8: 71477 | G8: 71515 | H8: 68427 | I8: 85830 | J8: 83789 | K8: 80925 | L8: 80609 | M8: 75377
A9: BPS professionals | B9: # | C9: 27254 | D9: 28414 | E9: 34190 | F9: 43081 | G9: 46816 | H9: 46125 | I9: 57315 | J9: 60102 | K9: 55492 | L9: 59636 | M9: 64330
A10: Sales & support | B10: # | C10: 6053 | D10: 6876 | E10: 6180 | F10: 6524 | G10: 6905 | H10: 6502 | I10: 8028 | J10: 8509 | K10: 9038 | L10: 8486 | M10: 7916
A11: LTM attrition | B11: % | C11: 0.21073297 | D11: 0.16516347 | E11: 0.18084726 | F11: 0.208 | G11: 0.191 | H11: 0.133 | I11: 0.235 | J11: 0.148 | K11: 0.1 | L11: 0.118 | M11: 0.121
A12: IT utilization | B12: % | C12: 0.77485958 | D12: 0.76865319 | E12: 0.83822415 | F12: 0.818 | G12: 0.83160803 | H12: 0.874 | I12: 0.831 | J12: 0.86481216 | K12: 0.8642 | L12: 0.8635 | M12: 0.8612
A13: IT utilization excl. trainees | B13: % | C13: 0.80159829 | D13: 0.80615885 | E13: 0.83973144 | F13: 0.819 | G13: 0.83514897 | H13: 0.874 | I13: 0.842 | J13: 0.86481216 | K13: 0.8641 | L13: 0.8627
A14: Active clients | B14: # | C14: 807 | D14: 843 | E14: 913 | F14: 938 | G14: 973 | H14: 1007 | I14: 1224 | J14: 1297 | K14: 1172 | L14: 1162
A15: Repeat business | B15: % | C15: 0.96275 | D15: 0.93545351 | E15: 0.88397966 | F15: 0.88740007 | G15: 0.86129042 | H15: 0.92220154 | I15: 0.87396636 | J15: 0.91757184 | K15: 0.94038
A16: $1m+ clients | B16: # | C16: 319 | D16: 354 | E16: 392 | F16: 425 | G16: 446 | H16: 451 | I16: 524 | J16: 582 | K16: 553 | L16: 540 | M16: 512
A17: $5m+ clients | B17: # | C17: 112 | D17: 134 | E17: 156 | F17: 156 | G17: 160 | H17: 169 | I17: 174 | J17: 186 | K17: 190 | L17: 195 | M17: 194
A18: $10m+ clients | B18: # | C18: 63 | D18: 71 | E18: 85 | F18: 83 | G18: 85 | H18: 85 | I18: 97 | J18: 112 | K18: 114 | L18: 106 | M18: 112
A19: $20m+ clients | B19: # | C19: 40 | D19: 36 | E19: 44 | F19: 50 | G19: 49 | H19: 50 | I19: 54 | J19: 65 | K19: 63 | L19: 59 | M19: 66
A20: $50m+ clients | B20: # | C20: 14 | D20: 14 | E20: 16 | F20: 20 | G20: 22 | H20: 21 | I20: 23 | J20: 24 | K20: 23 | L20: 25 | M20: 29
A21: Top 5 client concentration | B21: % | C21: 0.30164275 | D21: 0.2790042 | E21: 0.24243633 | F21: 0.22658313 | G21: 0.216888 | H21: 0.2183 | I21: 0.2232 | J21: 0.1846 | K21: 0.1648 | L21: 0.15229953 | M21: 0.15314066
A22: Top 10 client concentration | B22: % | C22: 0.41506312 | D22: 0.38937827 | E22: 0.34286238 | F22: 0.32201796 | G22: 0.3106 | H22: 0.3076 | I22: 0.313 | J22: 0.2789 | K22: 0.2661 | L22: 0.24663735 | M22: 0.24531347
A23: Top 20 client concentration | B23: % | C23: 0.54195308 | D23: 0.5090488 | E23: 0.46295797 | F23: 0.45218498 | G23: 0.432 | H23: 0.4298 | I23: 0.427 | J23: 0.4025 | K23: 0.39056 | L23: 0.38302176 | M23: 0.37931353
A24: TCV | B24: $m | F24: 1666.9 | G24: 3712 | H24: 2209.69 | I24: 3280 | J24: 2905 | K24: 1880.185 | L24: 2680 | M24: 3793.62
A25: DSO incl. unbilled | B25: days | D25: 95 | E25: 102 | F25: 102 | G25: 112 | H25: 92 | I25: 97 | J25: 95.555616 | K25: 92 | L25: 88.03578 | M25: 88.606669
A26: Average INR / USD | B26: ₹ / $ | C26: 65.621115 | D26: 66.973621 | E26: 64.503021 | F26: 69.896331 | G26: 71.147441 | H26: 74.06503 | I26: 74.437358 | J26: 80.662992 | K26: 82.833567 | L26: 84.591951 | M26: 88.984506
A27: Closing INR / USD | B27: ₹ / $ | C27: 66.26 | D27: 64.845 | E27: 65.17 | F27: 69.155 | G27: 75.62 | H27: 73.11 | I27: 75.7925 | J27: 82.17 | K27: 83.41 | L27: 85.475 | M27: 94.835
A28: Free cash flow | B28: $m | C28: 329.32269 | D28: 396.80794 | E28: 428.06914 | F28: 534.50917 | G28: 522.6 | H28: 965.42 | I28: 594.72 | J28: 497.35 | K28: 676.34 | L28: 612.96004 | M28: 616.24421
A29: FCF / PAT | B29: % | C29: 0.72376517 | D29: 0.94601013 | E29: 0.727892 | F29: 0.86966234 | G29: 0.922 | H29: 1.61495 | I29: 0.7967 | J29: 0.8364 | K29: 2.3791 | L29: 1.220272 | M29: 1.1466334
A30: Onsite revenue mix | B30: % | C30: 0.62148793 | D30: 0.63763805 | E30: 0.65070223 | F30: 0.65443059 | G30: 0.6527 | H30: 0.6316 | I30: 0.6163
A31: Offshore revenue mix | B31: % | C31: 0.37851207 | D31: 0.36236195 | E31: 0.34929777 | F31: 0.34556941 | G31: 0.347 | H31: 0.3683 | I31: 0.3836
A32: Onsite IT headcount mix | B32: % | I32: 0.27594087 | J32: 0.2729645 | K32: 0.2619 | L32: 0.23275621 | M32: 0.21875244
A33: Offshore IT headcount mix | B33: % | I33: 0.72405913 | J33: 0.7270355 | K33: 0.7381 | L33: 0.76724379 | M33: 0.78124756
A34: USD revenue mix | B34: % | C34: 0.51051503 | D34: 0.48348981 | E34: 0.48115697 | F34: 0.48217646 | G34: 0.49764 | H34: 0.5121 | I34: 0.5139 | J34: 0.5163 | K34: 0.5325 | L34: 0.52345602 | M34: 0.51447327
A35: GBP revenue mix | B35: % | C35: 0.12022138 | D35: 0.11441514 | E35: 0.11881195 | F35: 0.11551673 | G35: 0.115 | H35: 0.1125 | I35: 0.1085 | J35: 0.101 | K35: 0.0938 | L35: 0.094952509 | M35: 0.093809012
A36: EUR revenue mix | B36: % | C36: 0.1152505 | D36: 0.11689895 | E36: 0.11433922 | F36: 0.10990382 | G36: 0.0941 | H36: 0.0914 | I36: 0.1051 | J36: 0.1134 | K36: 0.1124 | L36: 0.11779954 | M36: 0.1358299
A37: AUD revenue mix | B37: % | C37: 0.046949801 | D37: 0.04584849 | E37: 0.048163994 | F37: 0.049111112 | G37: 0.0463 | H37: 0.0459 | I37: 0.0432 | J37: 0.0387 | K37: 0.0375 | L37: 0.047702174 | M37: 0.05449323
A38: Other currency revenue mix | B38: % | C38: 0.20706329 | D38: 0.23934762 | E38: 0.2375767 | F38: 0.24810053 | G38: 0.247 | H38: 0.2381 | I38: 0.2294 | J38: 0.2306 | K38: 0.2238 | L38: 0.21595326 | M38: 0.20139459
A39: Americas mix | B39: % | C39: 0.47788163 | D39: 0.4721035 | E39: 0.46580473 | F39: 0.47247123 | G39: 0.4805 | H39: 0.474 | I39: 0.4791 | J39: 0.4993 | K39: 0.5183 | L39: 0.50699748 | M39: 0.49811039
A40: Europe mix | B40: % | C40: 0.29038554 | D40: 0.29253597 | E40: 0.29830439 | F40: 0.29272929 | G40: 0.269 | H40: 0.2597 | I40: 0.2624 | J40: 0.2492 | K40: 0.2403 | L40: 0.24110791 | M40: 0.25757022
A41: Rest of world mix | B41: % | C41: 0.23173283 | D41: 0.23536053 | E41: 0.23589089 | F41: 0.23479947 | G41: 0.2501 | H41: 0.2657 | I41: 0.258 | J41: 0.2514 | K41: 0.2414 | L41: 0.2519946 | M41: 0.24430862
A42: Legacy: Communications | B42: % | C42: 0.51958341 | D42: 0.47774846 | E42: 0.43273304 | F42: 0.4122149 | G42: 0.41609801 | H42: 0.39664372
...

Sheet Quarterly P&L
A1: Quarterly Profit & Loss
A2: Reported quarterly P&L through Q1 FY27A; growth, margins and profit subtotals are formula-driven
A5: Metric | B5: Units | C5: Q1 FY16A | D5: Q2 FY16A | E5: Q3 FY16A | F5: Q4 FY16A | G5: Q1 FY17A | H5: Q2 FY17A | I5: Q3 FY17A | J5: Q4 FY17A | K5: Q1 FY18A | L5: Q2 FY18A | M5: Q3 FY18A | N5: Q4 FY18A | O5: Q1 FY19A | P5: Q2 FY19A | Q5: Q3 FY19A | R5: Q4 FY19A | S5: Q1 FY20A | T5: Q2 FY20A | U5: Q3 FY20A | V5: Q4 FY20A | W5: Q1 FY21A | X5: Q2 FY21A | Y5: Q3 FY21A | Z5: Q4 FY21A | AA5: Q1 FY22A | AB5: Q2 FY22A | AC5: Q3 FY22A | AD5: Q4 FY22A | AE5: Q1 FY23A | AF5: Q2 FY23A | AG5: Q3 FY23A | AH5: Q4 FY23A | AI5: Q1 FY24A | AJ5: Q2 FY24A | AK5: Q3 FY24A | AL5: Q4 FY24A | AM5: Q1 FY25A | AN5: Q2 FY25A | AO5: Q3 FY25A | AP5: Q4 FY25A | AQ5: Q1 FY26A | AR5: Q2 FY26A | AS5: Q3 FY26A | AT5: Q4 FY26A | AU5: Q1 FY27A
A6: Revenue | B6: ₹ cr | C6: ='Raw Financials'!C34 -> 6293.8237 | D6: ='Raw Financials'!D34 -> 6615.535 | E6: ='Raw Financials'!E34 -> 6701.1416 | F6: ='Raw Financials'!F34 -> 6883.832 | G6: ='Raw Financials'!G34 -> 6920.9344 | H6: ='Raw Financials'!H34 -> 7167.4101 | I6: ='Raw Financials'!I34 -> 7557.5027 | J6: ='Raw Financials'!J34 -> 7494.9943 | ... AU6: ='Raw Financials'!AU34 -> 15711.9
A7: QoQ growth | B7: % | D7: =IFERROR(D6/C6-1,"") -> 0.051115405 | E7: =IFERROR(E6/D6-1,"") -> 0.012940235 | F7: =IFERROR(F6/E6-1,"") -> 0.027262577 | G7: =IFERROR(G6/F6-1,"") -> 0.0053897909 | H7: =IFERROR(H6/G6-1,"") -> 0.035613068 | I7: =IFERROR(I6/H6-1,"") -> 0.054425875 | J7: =IFERROR(J6/I6-1,"") -> -0.0082710289 | K7: =IFERROR(K6/J6-1,"") -> -0.021199856 | ... AU7: =IFERROR(AU6/AT6-1,"") -> 0.04217271
A8: YoY growth | B8: % | G8: =IFERROR(G6/C6-1,"") -> 0.099639068 | H8: =IFERROR(H6/D6-1,"") -> 0.083421082 | I8: =IFERROR(I6/E6-1,"") -> 0.12779331 | J8: =IFERROR(J6/F6-1,"") -> 0.08878229 | K8: =IFERROR(K6/G6-1,"") -> 0.059987152 | L8: =IFERROR(L6/H6-1,"") -> 0.061238516 | M8: =IFERROR(M6/I6-1,"") -> 0.028905524 | N8: =IFERROR(N6/J6-1,"") -> 0.074649479 | ... AU8: =IFERROR(AU6/AQ6-1,"") -> 0.17681557
A9: Cost of services | B9: ₹ cr | C9: ='Raw Financials'!C35 -> 4444.0768 | D9: ='Raw Financials'!D35 -> 4499.8859 | E9: ='Raw Financials'!E35 -> 4606.9072 | F9: ='Raw Financials'!F35 -> 4778.1677 | G9: ='Raw Financials'!G35 -> 4880.6965 | H9: ='Raw Financials'!H35 -> 4971.6661 | I9: ='Raw Financials'!I35 -> 5235.2369 | J9: ='Raw Financials'!J35 -> 5478.4599 | ... AU9: ='Raw Financials'!AU35 -> 10925.9
A10: Gross profit | B10: ₹ cr | C10: =C6-C9 -> 1849.7469 | D10: =D6-D9 -> 2115.6491 | E10: =E6-E9 -> 2094.2343 | F10: =F6-F9 -> 2105.6642 | G10: =G6-G9 -> 2040.2379 | H10: =H6-H9 -> 2195.744 | I10: =I6-I9 -> 2322.2657 | J10: =J6-J9 -> 2016.5345 | ... AU10: =AU6-AU9 -> 4786
A11: Gross margin | B11: % | C11: =IFERROR(C10/C6,"") -> 0.29389875 | D11: =IFERROR(D10/D6,"") -> 0.31980015 | E11: =IFERROR(E10/E6,"") -> 0.31251904 | F11: =IFERROR(F10/F6,"") -> 0.30588548 | G11: =IFERROR(G10/G6,"") -> 0.29479227 | H11: =IFERROR(H10/H6,"") -> 0.30635111 | I11: =IFERROR(I10/I6,"") -> 0.30727951 | J11: =IFERROR(J10/J6,"") -> 0.26905083 | ... AU11: =IFERROR(AU10/AU6,"") -> 0.30460988
A12: SG&A | B12: ₹ cr | C12: ='Raw Financials'!C37 -> 944.75481 | D12: ='Raw Financials'!D37 -> 1028.8609 | E12: ='Raw Financials'!E37 -> 966.2309 | F12: ='Raw Financials'!F37 -> 954.75776 | G12: ='Raw Financials'!G37 -> 1011.1581 | H12: ='Raw Financials'!H37 -> 1125.6222 | I12: ='Raw Financials'!I37 -> 1135.7654 | J12: ='Raw Financials'!J37 -> 1117.8017 | ... AU12: ='Raw Financials'!AU37 -> 2043.5
A13: EBITDA | B13: ₹ cr | C13: =C10-C12 -> 904.99209 | D13: =D10-D12 -> 1086.7882 | E13: =E10-E12 -> 1128.0034 | F13: =F10-F12 -> 1150.9065 | G13: =G10-G12 -> 1029.0799 | H13: =H10-H12 -> 1070.1218 | I13: =I10-I12 -> 1186.5003 | J13: =J10-J12 -> 898.73282 | ... AU13: =AU10-AU12 -> 2742.5
A14: EBITDA margin | B14: % | C14: =IFERROR(C13/C6,"") -> 0.14379051 | D14: =IFERROR(D13/D6,"") -> 0.1642782 | E14: =IFERROR(E13/E6,"") -> 0.16833004 | F14: =IFERROR(F13/F6,"") -> 0.1671898 | G14: =IFERROR(G13/G6,"") -> 0.14869088 | H14: =IFERROR(H13/H6,"") -> 0.14930383 | I14: =IFERROR(I13/I6,"") -> 0.15699635 | J14: =IFERROR(J13/J6,"") -> 0.11991107 | ... AU14: =IFERROR(AU13/AU6,"") -> 0.17454923
A15: D&A | B15: ₹ cr | C15: ='Raw Financials'!C39 -> 172.4159 | D15: ='Raw Financials'!D39 -> 196.53226 | E15: ='Raw Financials'!E39 -> 172.65135 | F15: ='Raw Financials'!F39 -> 217.3235 | G15: ='Raw Financials'!G39 -> 201.87768 | H15: ='Raw Financials'!H39 -> 244.74799 | I15: ='Raw Financials'!I39 -> 247.9649 | J15: ='Raw Financials'!J39 -> 283.46462 | ... AU15: ='Raw Financials'!AU39 -> 478.6
A16: EBIT | B16: ₹ cr | C16: =C13-C15 -> 732.57618 | D16: =D13-D15 -> 890.25595 | E16: =E13-E15 -> 955.35209 | F16: =F13-F15 -> 933.58299 | G16: =G13-G15 -> 827.20218 | H16: =H13-H15 -> 825.37382 | I16: =I13-I15 -> 938.53544 | J16: =J13-J15 -> 615.2682 | ... AU16: =AU13-AU15 -> 2263.9
A17: EBIT margin | B17: % | C17: =IFERROR(C16/C6,"") -> 0.11639605 | D17: =IFERROR(D16/D6,"") -> 0.13457051 | E17: =IFERROR(E16/E6,"") -> 0.14256557 | F17: =IFERROR(F16/F6,"") -> 0.13561967 | G17: =IFERROR(G16/G6,"") -> 0.11952175 | H17: =IFERROR(H16/H6,"") -> 0.11515649 | I17: =IFERROR(I16/I6,"") -> 0.12418592 | J17: =IFERROR(J16/J6,"") -> 0.082090549 | ... AU17: =IFERROR(AU16/AU6,"") -> 0.14408824
A18: Impairment | B18: ₹ cr | C18: ='Raw Financials'!C41 -> 0 | D18: ='Raw Financials'!D41 -> 0 | E18: ='Raw Financials'!E41 -> 0 | F18: ='Raw Financials'!F41 -> 0 | G18: ='Raw Financials'!G41 -> 0 | H18: ='Raw Financials'!H41 -> 0 | I18: ='Raw Financials'!I41 -> 0 | J18: ='Raw Financials'!J41 -> 0 | ... AU18: ='Raw Financials'!AU41 -> 0
A19: FX gain / (loss) | B19: ₹ cr | C19: ='Raw Financials'!C43 -> 79.854662 | D19: ='Raw Financials'!D43 -> -20.448292 | E19: ='Raw Financials'!E43 -> -13.136941 | F19: ='Raw Financials'!F43 -> 52.342432 | G19: ='Raw Financials'!G43 -> 47.890939 | H19: ='Raw Financials'!H43 -> 87.622259 | I19: ='Raw Financials'!I43 -> 90.419583 | J19: ='Raw Financials'!J43 -> 161.6545 | ... AU19: ='Raw Financials'!AU43 -> -214
A20: Interest, dividend & miscellaneous income | B20: ₹ cr | C20: ='Raw Financials'!C44 -> 44.591127 | D20: ='Raw Financials'!D44 -> 118.20912 | E20: ='Raw Financials'!E44 -> 74.99402 | F20: ='Raw Financials'!F44 -> 102.97183 | G20: ='Raw Financials'!G44 -> 197.90552 | H20: ='Raw Financials'!H44 -> 51.097014 | I20: ='Raw Financials'!I44 -> 64.776663 | J20: ='Raw Financials'!J44 -> 76.192422 | ... AU20: ='Raw Financials'!AU44 -> 107.6
A21: Interest expense | B21: ₹ cr | C21: ='Raw Financials'!C45 -> 21.463855 | D21: ='Raw Financials'!D45 -> 17.492207 | E21: ='Raw Financials'!E45 -> 24.612005 | F21: ='Raw Financials'!F45 -> 33.449491 | G21: ='Raw Financials'!G45 -> 27.405197 | H21: ='Raw Financials'!H45 -> 34.510163 | I21: ='Raw Financials'!I45 -> 34.887159 | J21: ='Raw Financials'!J45 -> 31.789909 | ... AU21: ='Raw Financials'!AU45 -> 111.3
A22: Share of associate | B22: ₹ cr | C22: ='Raw Financials'!C46 -> 1.0734657 | D22: ='Raw Financials'!D46 -> 0.32416479 | E22: ='Raw Financials'!E46 -> -0.12559858 | F22: ='Raw Financials'!F46 -> 1.2753029 | G22: ='Raw Financials'!G46 -> -2.2679132 | H22: ='Raw Financials'!H46 -> -0.2174587 | I22: ='Raw Financials'!I46 -> 0.1520472 | J22: ='Raw Financials'!J46 -> 0.0018203 | ... AU22: ='Raw Financials'!AU46 -> -4.3
A23: PBT before exceptional | B23: ₹ cr | C23: =SUM(C16,-C18,C19:C20,-C21,C22) -> 836.63158 | D23: =SUM(D16,-D18,D19:D20,-D21,D22) -> 970.84873 | E23: =SUM(E16,-E18,E19:E20,-E21,E22) -> 992.47157 | F23: =SUM(F16,-F18,F19:F20,-F21,F22) -> 1056.7231 | G23: =SUM(G16,-G18,G19:G20,-G21,G22) -> 1043.3255 | H23: =SUM(H16,-H18,H19:H20,-H21,H22) -> 929.36547 | I23: =SUM(I16,-I18,I19:I20,-I21,I22) -> 1058.9966 | J23: =SUM(J16,-J18,J19:J20,-J21,J22) -> 821.32703 | ... AU23: =SUM(AU16,-AU18,AU19:AU20,-AU21,AU22) -> 2041.9
A24: Exceptional item | B24: ₹ cr | C24: ='Raw Financials'!C48 -> 0 | D24: ='Raw Financials'!D48 -> 0 | E24: ='Raw Financials'!E48 -> 0 | F24: ='Raw Financials'!F48 -> 0 | G24: ='Raw Financials'!G48 -> 0 | H24: ='Raw Financials'!H48 -> 0 | I24: ='Raw Financials'!I48 -> 0 | J24: ='Raw Financials'!J48 -> 0 | ... AU24: ='Raw Financials'!AU48 -> 0
A25: PBT | B25: ₹ cr | C25: =C23-C24 -> 836.63158 | D25: =D23-D24 -> 970.84873 | E25: =E23-E24 -> 992.47157 | F25: =F23-F24 -> 1056.7231 | G25: =G23-G24 -> 1043.3255 | H25: =H23-H24 -> 929.36547 | I25: =I23-I24 -> 1058.9966 | J25: =J23-J24 -> 821.32703 | ... AU25: =AU23-AU24 -> 2041.9
A26: Tax | B26: ₹ cr | C26: ='Raw Financials'!C50 -> 214.19506 | D26: ='Raw Financials'!D50 -> 202.31151 | E26: ='Raw Financials'!E50 -> 233.00483 | F26: ='Raw Financials'!F50 -> 180.62042 | G26: ='Raw Financials'!G50 -> 246.79286 | H26: ='Raw Financials'!H50 -> 309.5984 | I26: ='Raw Financials'!I50 -> 214.09446 | J26: ='Raw Financials'!J50 -> 231.63861 | ... AU26: ='Raw Financials'!AU50 -> 555.6
A27: PAT before NCI | B27: ₹ cr | C27: =C25-C26 -> 622.43652 | D27: =D25-D26 -> 768.53722 | E27: =E25-E26 -> 759.46674 | F27: =F25-F26 -> 876.10265 | G27: =G25-G26 -> 796.53266 | H27: =H25-H26 -> 619.76707 | I27: =I25-I26 -> 844.90211 | J27: =J25-J26 -> 589.68843 | ... AU27: =AU25-AU26 -> 1486.3
A28: NCI / minority interest | B28: ₹ cr | C28: ='Raw Financials'!C52 -> 0.061248338 | D28: ='Raw Financials'!D52 -> -4.1718607 | E28: ='Raw Financials'!E52 -> -8.2590116 | F28: ='Raw Financials'!F52 -> -21.348558 | G28: ='Raw Financials'!G52 -> -47.246114 | H28: ='Raw Financials'!H52 -> 0.89062441 | I28: ='Raw Financials'!I52 -> 10.132511 | J28: ='Raw Financials'!J52 -> -1.7342102 | ... AU28: ='Raw Financials'!AU52 -> 21.2
A29: Net income attributable | B29: ₹ cr | C29: =C27+C28 -> 622.49777 | D29: =D27+D28 -> 764.36536 | E29: =E27+E28 -> 751.20773 | F29: =F27+F28 -> 854.75409 | G29: =G27+G28 -> 749.28655 | H29: =H27+H28 -> 620.65769 | I29: =I27+I28 -> 855.03462 | J29: =J27+J28 -> 587.95422 | ... AD29: =AD27+AD28 -> 1505.6408 | AE29: =AE27-AE28 -> 1131.6477 | AF29: =AF27-AF28 -> 1285.4196 | AG29: =AG27-AG28 -> 1296.5672 | AH29: =AH27-AH28 -> 1117.6391 | AI29: =AI27-AI28 -> 692.481 | AJ29: =AJ27-AJ28 -> 493.916 | AK29: =AK27-AK28 -> 510.46376 | AL29: =AL27-AL28 -> 661 | ... AU29: =AU27-AU28 -> 1465.1
A30: Net margin | B30: % | C30: =IFERROR(C29/C6,"") -> 0.098906135 | D30: =IFERROR(D29/D6,"") -> 0.11554097 | E30: =IFERROR(E29/E6,"") -> 0.11210146 | F30: =IFERROR(F29/F6,"") -> 0.12416835 | G30: =IFERROR(G29/G6,"") -> 0.10826378 | H30: =IFERROR(H29/H6,"") -> 0.086594416 | I30: =IFERROR(I29/I6,"") -> 0.11313719 | J30: =IFERROR(J29/J6,"") -> 0.078446252 | ... AU30: =IFERROR(AU29/AU6,"") -> 0.093247793
A31: USD revenue | B31: $m | C31: ='Raw Financials'!C56 -> 989.12301 | D31: ='Raw Financials'!D56 -> 1011.0334 | E31: ='Raw Financials'!E56 -> 1014.7137 | F31: ='Raw Financials'!F56 -> 1022.5853 | G31: ='Raw Financials'!G56 -> 1031.4658 | H31: ='Raw Financials'!H56 -> 1072.3792 | I31: ='Raw Financials'!I56 -> 1116.0923 | J31: ='Raw Financials'!J56 -> 1131.1552 | ... AU31: ='Raw Financials'!AU56 -> 1660.4
A32: USD revenue QoQ growth | B32: % | D32: =IFERROR(D31/C31-1,"") -> 0.022151295 | E32: =IFERROR(E31/D31-1,"") -> 0.0036401436 | F32: =IFERROR(F31/E31-1,"") -> 0.0077574891 | G32: =IFERROR(G31/F31-1,"") -> 0.0086843223 | H32: =IFERROR(H31/G31-1,"") -> 0.039665331 | I32: =IFERROR(I31/H31-1,"") -> 0.040762725 | J32: =IFERROR(J31/I31-1,"") -> 0.013496075 | K32: =IFERROR(K31/J31-1,"") -> 0.0061790026 | ... AU32: =IFERROR(AU31/AT31-1,"") -> 0.021991521
A33: Implied INR / USD | B33: ₹ / $ | C33: =IFERROR(C6*10/C31,"") -> 63.630343 | D33: =IFERROR(D6*10/D31,"") -> 65.433399 | E33: =IFERROR(E6*10/E31,"") -> 66.039729 | F33: =IFERROR(F6*10/F31,"") -> 67.317924 | G33: =IFERROR(G6*10/G31,"") -> 67.098052 | H33: =IFERROR(H6*10/H31,"") -> 66.836527 | I33: =IFERROR(I6*10/I31,"") -> 67.713958 | J33: =IFERROR(J6*10/J31,"") -> 66.259649 | ... AU33: =IFERROR(AU6*10/AU31,"") -> 94.627198

Sheet Annual P&L
A1: Annual Profit & Loss
A2: Actuals link to reported source data; FY27E–FY30E are formula-driven from the operating bridge and assumptions
A5: Metric | B5: Units | C5: FY16A | D5: FY17A | E5: FY18A | F5: FY19A | G5: FY20A | H5: FY21A | I5: FY22A | J5: FY23A | K5: FY24A | L5: FY25A | M5: FY26A | N5: FY27E | O5: FY28E | P5: FY29E | Q5: FY30E
A7: Revenue | B7: ₹ cr | C7: ='Raw Financials'!C6 -> 26494.232 | D7: ='Raw Financials'!D6 -> 29140.841 | E7: ='Raw Financials'!E6 -> 30772.881 | F7: ='Raw Financials'!F6 -> 34742.132 | G7: ='Raw Financials'!G6 -> 36867.679 | H7: ='Raw Financials'!H6 -> 37855.081 | I7: ='Raw Financials'!I6 -> 44645.964 | J7: ='Raw Financials'!J6 -> 53290.167 | ... M7: ='Raw Financials'!M6 -> 56815.4 | N7: ='Revenue Drivers'!N30 -> 58225.878 | O7: ='Revenue Drivers'!O30 -> 60460.105 | P7: ='Revenue Drivers'!P30 -> 63337.982 | Q7: ='Revenue Drivers'!Q30 -> 66753.18
A8: YoY growth | B8: % | D8: =IFERROR(D7/C7-1,"") -> 0.099893788 | E8: =IFERROR(E7/D7-1,"") -> 0.056005236 | F8: =IFERROR(F7/E7-1,"") -> 0.12898534 | G8: =IFERROR(G7/F7-1,"") -> 0.061180684 | H8: =IFERROR(H7/G7-1,"") -> 0.026782321 | I8: =IFERROR(I7/H7-1,"") -> 0.17939159 | J8: =IFERROR(J7/I7-1,"") -> 0.19361667 | K8: =IFERROR(K7/J7-1,"") -> -0.0242939 | ... Q8: =IFERROR(Q7/P7-1,"") -> 0.053920233
A9: Cost of services | B9: ₹ cr | C9: ='Raw Financials'!C7 -> 18329.038 | D9: ='Raw Financials'!D7 -> 20566.059 | E9: ='Raw Financials'!E7 -> 21530.042 | F9: ='Raw Financials'!F7 -> 23358.982 | G9: ='Raw Financials'!G7 -> 25974.337 | H9: ='Raw Financials'!H7 -> 25855.48 | I9: ='Raw Financials'!I7 -> 30972.015 | J9: ='Raw Financials'!J7 -> 38119.703 | ... M9: ='Raw Financials'!M7 -> 39868.82 | N9: =N7*(1-Assumptions!C19) -> 40466.985 | O9: =O7*(1-Assumptions!D19) -> 41717.473 | P9: =P7*(1-Assumptions!E19) -> 43386.517 | Q9: =Q7*(1-Assumptions!F19) -> 45392.163
A10: Gross profit | B10: ₹ cr | C10: =C7-C9 -> 8165.1946 | D10: =D7-D9 -> 8574.7821 | E10: =E7-E9 -> 9242.8396 | F10: =F7-F9 -> 11383.149 | G10: =G7-G9 -> 10893.342 | H10: =H7-H9 -> 11999.601 | I10: =I7-I9 -> 13673.949 | J10: =J7-J9 -> 15170.464 | ... Q10: =Q7-Q9 -> 21361.018
A11: Gross margin | B11: % | C11: =IFERROR(C10/C7,"") -> 0.30818763 | D11: =IFERROR(D10/D7,"") -> 0.29425307 | E11: =IFERROR(E10/E7,"") -> 0.30035665 | F11: =IFERROR(F10/F7,"") -> 0.32764683 | G11: =IFERROR(G10/G7,"") -> 0.29547133 | H11: =IFERROR(H10/H7,"") -> 0.31698786 | I11: =IFERROR(I10/I7,"") -> 0.30627514 | J11: =IFERROR(J10/J7,"") -> 0.28467661 | ... M11: =IFERROR(M10/M7,"") -> 0.2982744 | N11: =N10/N7 -> 0.305 | O11: =O10/O7 -> 0.31 | P11: =P10/P7 -> 0.315 | Q11: =Q10/Q7 -> 0.32
A12: Reported gross profit control | B12: ₹ cr | C12: ='Raw Financials'!C8 -> 8165.1946 | D12: ='Raw Financials'!D8 -> 8574.7821 | E12: ='Raw Financials'!E8 -> 9242.8906 | F12: ='Raw Financials'!F8 -> 11383.149 | G12: ='Raw Financials'!G8 -> 10893.442 | H12: ='Raw Financials'!H8 -> 11999.6 | I12: ='Raw Financials'!I8 -> 13673.949 | J12: ='Raw Financials'!J8 -> 15170.464 | ... M12: ='Raw Financials'!M8 -> 16946.579 | N12: =N10 -> 17758.893 | O12: =O10 -> 18742.633 | P12: =P10 -> 19951.464 | Q12: =Q10 -> 21361.018
A13: Gross profit check | B13: ₹ cr | C13: =C10-C12 -> 0 | D13: =D10-D12 -> 0 | E13: =E10-E12 -> -0.051 | F13: =F10-F12 -> 0 | G13: =G10-G12 -> -0.1 | H13: =H10-H12 -> 0.001 | I13: =I10-I12 -> 0 | J13: =J10-J12 -> 0 | ... M13: =M10-M12 -> 0 | N13: =0 -> 0 | O13: =0 -> 0 | P13: =0 -> 0 | Q13: =0 -> 0
A14: SG&A | B14: ₹ cr | C14: ='Raw Financials'!C9 -> 3894.5043 | D14: ='Raw Financials'!D9 -> 4390.3473 | E14: ='Raw Financials'!E9 -> 4533.2804 | F14: ='Raw Financials'!F9 -> 5046.2316 | G14: ='Raw Financials'!G9 -> 5167.303 | H14: ='Raw Financials'!H9 -> 5152.554 | I14: ='Raw Financials'!I9 -> 5653.965 | J14: ='Raw Financials'!J9 -> 7141.688 | ... M14: ='Raw Financials'!M9 -> 7912.4797 | N14: =N7*Assumptions!C20 -> 8035.1712 | O14: =O7*Assumptions!D20 -> 8283.0344 | P14: =P7*Assumptions!E20 -> 8550.6275 | Q14: =Q7*Assumptions!F20 -> 8944.9262
A15: EBITDA | B15: ₹ cr | C15: =C10-C14 -> 4270.6903 | D15: =D10-D14 -> 4184.4348 | E15: =E10-E14 -> 4709.5592 | F15: =F10-F14 -> 6336.9176 | G15: =G10-G14 -> 5726.039 | H15: =H10-H14 -> 6847.047 | I15: =I10-I14 -> 8019.984 | J15: =J10-J14 -> 8028.776 | ... Q15: =Q10-Q14 -> 12416.092
A16: EBITDA margin | B16: % | C16: =IFERROR(C15/C7,"") -> 0.16119321 | D16: =IFERROR(D15/D7,"") -> 0.14359348 | E16: =IFERROR(E15/E7,"") -> 0.15304252 | F16: =IFERROR(F15/F7,"") -> 0.18239864 | G16: =IFERROR(G15/G7,"") -> 0.15531325 | H16: =IFERROR(H15/H7,"") -> 0.18087524 | I16: =IFERROR(I15/I7,"") -> 0.17963514 | J16: =IFERROR(J15/J7,"") -> 0.15066149 | ... M16: =IFERROR(M15/M7,"") -> 0.15900794 | N16: =N15/N7 -> 0.167 | O16: =O15/O7 -> 0.173 | P16: =P15/P7 -> 0.18 | Q16: =Q15/Q7 -> 0.186
A17: Reported EBITDA control | B17: ₹ cr | C17: ='Raw Financials'!C10 -> 4270.6903 | D17: ='Raw Financials'!D10 -> 4184.4348 | E17: ='Raw Financials'!E10 -> 4709.6102 | F17: ='Raw Financials'!F10 -> 6336.9176 | G17: ='Raw Financials'!G10 -> 5726.139 | H17: ='Raw Financials'!H10 -> 6847.047 | I17: ='Raw Financials'!I10 -> 8019.984 | J17: ='Raw Financials'!J10 -> 8028.776 | ... M17: ='Raw Financials'!M10 -> 9034.0995 | N17: =N15 -> 9723.7216 | O17: =O15 -> 10459.598 | P17: =P15 -> 11400.837 | Q17: =Q15 -> 12416.092
A18: EBITDA check | B18: ₹ cr | C18: =C15-C17 -> 0 | D18: =D15-D17 -> 0 | E18: =E15-E17 -> -0.051 | F18: =F15-F17 -> 0 | G18: =G15-G17 -> -0.1 | H18: =H15-H17 -> 0 | I18: =I15-I17 -> 0 | J18: =J15-J17 -> 0 | ... M18: =M15-M17 -> 0 | N18: =0 -> 0 | O18: =0 -> 0 | P18: =0 -> 0 | Q18: =0 -> 0
A19: D&A | B19: ₹ cr | C19: ='Raw Financials'!C11 -> 758.923 | D19: ='Raw Financials'!D11 -> 978.0552 | E19: ='Raw Financials'!E11 -> 1085.038 | F19: ='Raw Financials'!F11 -> 1129.2 | G19: ='Raw Financials'!G11 -> 1445.769 | H19: ='Raw Financials'!H11 -> 1457.71 | I19: ='Raw Financials'!I11 -> 1520.392 | J19: ='Raw Financials'!J11 -> 1956.7 | ... M19: ='Raw Financials'!M11 -> 1881.6 | N19: =N7*Assumptions!C21 -> 1921.454 | O19: =O7*Assumptions!D21 -> 1934.7234 | P19: =P7*Assumptions!E21 -> 1963.4774 | Q19: =Q7*Assumptions!F21 -> 2002.5954
A20: EBIT | B20: ₹ cr | C20: ='Raw Financials'!C12 -> 3511.7673 | D20: ='Raw Financials'!D12 -> 3206.3796 | E20: ='Raw Financials'!E12 -> 3624.5722 | F20: ='Raw Financials'!F12 -> 5207.7176 | G20: ='Raw Financials'!G12 -> 4280.27 | H20: ='Raw Financials'!H12 -> 5389.337 | I20: ='Raw Financials'!I12 -> 6499.591 | J20: ='Raw Financials'!J12 -> 6072.076 | ... M20: ='Raw Financials'!M12 -> 7152.4995 | N20: =N15-N19 -> 7802.2677 | O20: =O15-O19 -> 8524.8748 | P20: =P15-P19 -> 9437.3593 | Q20: =Q15-Q19 -> 10413.496
A21: EBIT margin | B21: % | C21: =IFERROR(C20/C7,"") -> 0.13254837 | D21: =IFERROR(D20/D7,"") -> 0.11003044 | E21: =IFERROR(E20/E7,"") -> 0.11778462 | F21: =IFERROR(F20/F7,"") -> 0.14989632 | G21: =IFERROR(G20/G7,"") -> 0.11609817 | H21: =IFERROR(H20/H7,"") -> 0.1423676 | I21: =IFERROR(I20/I7,"") -> 0.14558071 | J21: =IFERROR(J20/J7,"") -> 0.11394365 | ... M21: =IFERROR(M20/M7,"") -> 0.12589016 | N21: =N20/N7 -> 0.134 | O21: =O20/O7 -> 0.141 | P21: =P20/P7 -> 0.149 | Q21: =Q20/Q7 -> 0.156
A22: Impairment | B22: ₹ cr | C22: ='Raw Financials'!C13 -> 0 | D22: ='Raw Financials'!D13 -> 0 | E22: ='Raw Financials'!E13 -> 0 | F22: ='Raw Financials'!F13 -> 0 | G22: ='Raw Financials'!G13 -> 217.5 | H22: ='Raw Financials'!H13 -> 50.7 | I22: ='Raw Financials'!I13 -> 0 | J22: ='Raw Financials'!J13 -> 237 | ... M22: ='Raw Financials'!M13 -> 5.3290705e-16 | N22: =Assumptions!C22 -> 0 | O22: =Assumptions!D22 -> 0 | P22: =Assumptions!E22 -> 0 | Q22: =Assumptions!F22 -> 0
A23: FX gain / (loss) | B23: ₹ cr | C23: ='Raw Financials'!C15 -> 98.59186 | D23: ='Raw Financials'!D15 -> 387.58728 | E23: ='Raw Financials'!E15 -> 774.95874 | F23: ='Raw Financials'!F15 -> 12.109998 | G23: ='Raw Financials'!G15 -> 302.2 | H23: ='Raw Financials'!H15 -> 97.5 | I23: ='Raw Financials'!I15 -> 564.214 | J23: ='Raw Financials'!J15 -> 299 | ... M23: ='Raw Financials'!M15 -> -479.9 | N23: =0 -> 0 | O23: =0 -> 0 | P23: =0 -> 0 | Q23: =0 -> 0
