Workbook

Sheet Cover
A1: Wipro Integrated Financial Model
A2: Fresh official-source build | Quarterly P&L FY16–Q1FY27 | Annual three statements FY16–FY30E | INR crore unless stated
A4: Cash-anchored three statements, client mining, bookings, AI revenue bridge and valuation
A6: Model scope | B6: Quarterly P&L only; annual P&L, detailed balance sheet and cash flow
A7: Historical period | B7: FY16–FY26 plus Q1 FY27 actual
A8: Forecast period | B8: FY27E–FY30E
A9: Source policy | B9: Official Wipro annual reports, quarterly IFRS statements and company data sheets; SEC company facts used for standardized history
A10: Cash policy | B10: Historical closing cash is anchored to the reported balance sheet; forecast cash is the output of CFO + CFI + CFF
A11: Forecast revenue | B11: Retained core + billable capacity + bookings realization − T&M AI deflation + explicit AI uplift + acquisitions
A12: AI disclosure policy | B12: No historical AI revenue is invented; forecast AI uplift is an editable scenario assumption
A13: Circularity policy | B13: One-way flow: assumptions / drivers → P&L → non-cash BS schedules → cash flow → cash → balance sheet
A14: Formatting | B14: Aptos Narrow 10; hardcoded actuals medium blue; formulas black; forecast columns pale green
A15: Model status | B15: =Checks!B6 -> OK

Sheet Summary
A1: Wipro Financial Summary
A2: Integrated performance, operating drivers, cash generation and valuation
A5: Metric | B5: Units | C5: FY16A | D5: FY17A | E5: FY18A | F5: FY19A | G5: FY20A | H5: FY21A | I5: FY22A | J5: FY23A | K5: FY24A | L5: FY25A | M5: FY26A | N5: FY27E | O5: FY28E | P5: FY29E | Q5: FY30E
A7: Revenue | B7: ₹ cr | C7: ='Annual P&L'!C7 -> 51244 | D7: ='Annual P&L'!D7 -> 55040.2 | E7: ='Annual P&L'!E7 -> 54487.1 | F7: ='Annual P&L'!F7 -> 58584.5 | G7: ='Annual P&L'!G7 -> 61023.2 | H7: ='Annual P&L'!H7 -> 61943 | I7: ='Annual P&L'!I7 -> 79093.4 | J7: ='Annual P&L'!J7 -> 90487.6 | ... Q7: ='Annual P&L'!Q7 -> 118382.92
A8: Revenue growth | B8: % | C8: ='Annual P&L'!C8 -> 0 | D8: ='Annual P&L'!D8 -> 0.074080868 | E8: ='Annual P&L'!E8 -> -0.010049019 | F8: ='Annual P&L'!F8 -> 0.075199451 | G8: ='Annual P&L'!G8 -> 0.041627052 | H8: ='Annual P&L'!H8 -> 0.015072956 | I8: ='Annual P&L'!I8 -> 0.2768739 | J8: ='Annual P&L'!J8 -> 0.14406006 | ... Q8: ='Annual P&L'!Q8 -> 0.085114922
A9: Gross margin | B9: % | C9: ='Annual P&L'!C11 -> 0.30387167 | D9: ='Annual P&L'!D11 -> 0.28862177 | E9: ='Annual P&L'!E11 -> 0.29235544 | F9: ='Annual P&L'!F11 -> 0.29497905 | G9: ='Annual P&L'!G11 -> 0.28537835 | H9: ='Annual P&L'!H11 -> 0.31678317 | I9: ='Annual P&L'!I11 -> 0.29719547 | J9: ='Annual P&L'!J11 -> 0.28670227 | ... Q9: ='Annual P&L'!Q11 -> 0.3
A10: EBITDA | B10: ₹ cr | C10: ='Annual P&L'!C15 -> 11182.5 | D10: ='Annual P&L'!D15 -> 11698.6 | E10: ='Annual P&L'!E15 -> 10541.8 | F10: ='Annual P&L'!F15 -> 11938.4 | G10: ='Annual P&L'!G15 -> 12659.2 | H10: ='Annual P&L'!H15 -> 15070.9 | I10: ='Annual P&L'!I15 -> 17119.7 | J10: ='Annual P&L'!J15 -> 17300.8 | ... Q10: ='Annual P&L'!Q15 -> 24386.881
A11: EBITDA margin | B11: % | C11: ='Annual P&L'!C16 -> 0.21822067 | D11: ='Annual P&L'!D16 -> 0.21254647 | E11: ='Annual P&L'!E16 -> 0.19347332 | F11: ='Annual P&L'!F16 -> 0.20378086 | G11: ='Annual P&L'!G16 -> 0.20744897 | H11: ='Annual P&L'!H16 -> 0.24330271 | I11: ='Annual P&L'!I16 -> 0.21644916 | J11: ='Annual P&L'!J16 -> 0.19119526 | ... Q11: ='Annual P&L'!Q16 -> 0.206
A12: EBIT | B12: ₹ cr | C12: ='Annual P&L'!C18 -> 9686 | D12: ='Annual P&L'!D18 -> 9387.9 | E12: ='Annual P&L'!E18 -> 8429.4 | F12: ='Annual P&L'!F18 -> 9991 | G12: ='Annual P&L'!G18 -> 10573 | H12: ='Annual P&L'!H18 -> 12305.3 | I12: ='Annual P&L'!I18 -> 14028.6 | J12: ='Annual P&L'!J18 -> 13960.6 | ... Q12: ='Annual P&L'!Q18 -> 21072.159
A13: EBIT margin | B13: % | C13: ='Annual P&L'!C19 -> 0.18901725 | D13: ='Annual P&L'!D19 -> 0.17056442 | E13: ='Annual P&L'!E19 -> 0.15470451 | F13: ='Annual P&L'!F19 -> 0.17053999 | G13: ='Annual P&L'!G19 -> 0.17326197 | H13: ='Annual P&L'!H19 -> 0.19865522 | I13: ='Annual P&L'!I19 -> 0.17736752 | J13: ='Annual P&L'!J19 -> 0.15428191 | ... Q13: ='Annual P&L'!Q19 -> 0.178
A14: Net income | B14: ₹ cr | C14: ='Annual P&L'!C29 -> 8907.5 | D14: ='Annual P&L'!D29 -> 8489.5 | E14: ='Annual P&L'!E29 -> 8008.1 | F14: ='Annual P&L'!F29 -> 9003.1 | G14: ='Annual P&L'!G29 -> 9721.8 | H14: ='Annual P&L'!H29 -> 10794.6 | I14: ='Annual P&L'!I29 -> 12219.1 | J14: ='Annual P&L'!J29 -> 11350 | ... Q14: ='Annual P&L'!Q29 -> 17320.917
A15: Net margin | B15: % | C15: ='Annual P&L'!C30 -> 0.17382523 | D15: ='Annual P&L'!D30 -> 0.15424181 | E15: ='Annual P&L'!E30 -> 0.1469724 | F15: ='Annual P&L'!F30 -> 0.15367717 | G15: ='Annual P&L'!G30 -> 0.15931318 | H15: ='Annual P&L'!H30 -> 0.17426666 | I15: ='Annual P&L'!I30 -> 0.1544895 | J15: ='Annual P&L'!J30 -> 0.12543155 | ... Q15: ='Annual P&L'!Q30 -> 0.14631264
A16: Diluted EPS | B16: ₹ / share | C16: ='Annual P&L'!C34 -> 18.092246 | D16: ='Annual P&L'!D34 -> 13.070563 | E16: ='Annual P&L'!E34 -> 12.622148 | F16: ='Annual P&L'!F34 -> 14.949593 | G16: ='Annual P&L'!G34 -> 16.624648 | H16: ='Annual P&L'!H34 -> 19.066147 | I16: ='Annual P&L'!I34 -> 22.289154 | J16: ='Annual P&L'!J34 -> 10.338876 | ... Q16: ='Annual P&L'!Q34 -> 17.909365
A17: CFO | B17: ₹ cr | C17: ='Annual Cash Flow'!C29 -> 7887.3 | D17: ='Annual Cash Flow'!D29 -> 9277.3 | E17: ='Annual Cash Flow'!E29 -> 8423.3 | F17: ='Annual Cash Flow'!F29 -> 11631.6 | G17: ='Annual Cash Flow'!G29 -> 10064.3 | H17: ='Annual Cash Flow'!H29 -> 14755 | I17: ='Annual Cash Flow'!I29 -> 11079.7 | J17: ='Annual Cash Flow'!J29 -> 13060.1 | ... Q17: ='Annual Cash Flow'!Q29 -> 19814.582
A18: Free cash flow | B18: ₹ cr | C18: ='Annual Cash Flow'!C59 -> 6492.2 | D18: ='Annual Cash Flow'!D59 -> 7192 | E18: ='Annual Cash Flow'!E59 -> 6236.3 | F18: ='Annual Cash Flow'!F59 -> 9353.5 | G18: ='Annual Cash Flow'!G59 -> 7714.6 | H18: ='Annual Cash Flow'!H59 -> 12797.3 | I18: ='Annual Cash Flow'!I59 -> 9064.4 | J18: ='Annual Cash Flow'!J59 -> 11576.7 | ... Q18: ='Annual Cash Flow'!Q59 -> 17683.69
A19: Closing cash | B19: ₹ cr | C19: ='Annual Balance Sheet'!C22 -> 9904.9 | D19: ='Annual Balance Sheet'!D22 -> 5271 | E19: ='Annual Balance Sheet'!E22 -> 4492.5 | F19: ='Annual Balance Sheet'!F22 -> 15852.9 | G19: ='Annual Balance Sheet'!G22 -> 14449.9 | H19: ='Annual Balance Sheet'!H22 -> 16979.3 | I19: ='Annual Balance Sheet'!I22 -> 10383.6 | J19: ='Annual Balance Sheet'!J22 -> 9188 | ... Q19: ='Annual Balance Sheet'!Q22 -> 19893.038
A20: Net cash + investments / debt & lease | B20: ₹ cr | C20: ='Annual Balance Sheet'!C62 -> 11167.9 | D20: ='Annual Balance Sheet'!D62 -> 20232.8 | E20: ='Annual Balance Sheet'!E62 -> 15576 | F20: ='Annual Balance Sheet'!F62 -> 27977.8 | G20: ='Annual Balance Sheet'!G62 -> 23689.4 | H20: ='Annual Balance Sheet'!H62 -> 24098.6 | I20: ='Annual Balance Sheet'!I62 -> 16956.2 | J20: ='Annual Balance Sheet'!J62 -> 22644.6 | ... Q20: ='Annual Balance Sheet'!Q62 -> 46219.439
A21: Headcount | B21: # | C21: ='Revenue Drivers'!C7 -> 172912 | D21: ='Revenue Drivers'!D7 -> 181482 | E21: ='Revenue Drivers'!E7 -> 163827 | F21: ='Revenue Drivers'!F7 -> 171425 | G21: ='Revenue Drivers'!G7 -> 182886 | H21: ='Revenue Drivers'!H7 -> 197712 | I21: ='Revenue Drivers'!I7 -> 243128 | J21: ='Revenue Drivers'!J7 -> 256921 | ... Q21: ='Revenue Drivers'!Q7 -> 268573.23
A22: Billable FTE | B22: # | C22: ='Revenue Drivers'!C12 -> 127657.83 | D22: ='Revenue Drivers'!D12 -> 137454.17 | E22: ='Revenue Drivers'!E12 -> 122835.07 | F22: ='Revenue Drivers'!F12 -> 133191.12 | G22: ='Revenue Drivers'!G12 -> 138245.89 | H22: ='Revenue Drivers'!H12 -> 156633.5 | I22: ='Revenue Drivers'!I12 -> 195679.32 | J22: ='Revenue Drivers'!J12 -> 194827.22 | ... Q22: ='Revenue Drivers'!Q12 -> 216148.81
A23: Total bookings | B23: $m | C23: ='Client Data'!C21 -> 0 | D23: ='Client Data'!D21 -> 0 | E23: ='Client Data'!E21 -> 0 | F23: ='Client Data'!F21 -> 0 | G23: ='Client Data'!G21 -> 0 | H23: ='Client Data'!H21 -> 0 | I23: ='Client Data'!I21 -> 0 | J23: ='Client Data'!J21 -> 0 | ... Q23: ='Client Data'!Q21 -> 21760.89
A24: Large-deal TCV | B24: $m | C24: ='Client Data'!C23 -> 0 | D24: ='Client Data'!D23 -> 0 | E24: ='Client Data'!E23 -> 0 | F24: ='Client Data'!F23 -> 0 | G24: ='Client Data'!G23 -> 0 | H24: ='Client Data'!H23 -> 0 | I24: ='Client Data'!I23 -> 0 | J24: ='Client Data'!J23 -> 0 | ... Q24: ='Client Data'!Q23 -> 10357.226
A25: Revenue per active client | B25: $m | C25: ='Client Data'!C17 -> 6.0067866 | D25: ='Client Data'!D17 -> 5.8235072 | E25: ='Client Data'!E17 -> 6.4584936 | F25: ='Client Data'!F17 -> 7.2827803 | G25: ='Client Data'!G17 -> 7.6873371 | H25: ='Client Data'!H17 -> 7.2647321 | I25: ='Client Data'!I17 -> 7.5645727 | J25: ='Client Data'!J17 -> 7.7444136 | ... Q25: ='Client Data'!Q17 -> 7.7439241
A26: AI revenue uplift | B26: ₹ cr | C26: ='Revenue Drivers'!C28 -> 0 | D26: ='Revenue Drivers'!D28 -> 0 | E26: ='Revenue Drivers'!E28 -> 0 | F26: ='Revenue Drivers'!F28 -> 0 | G26: ='Revenue Drivers'!G28 -> 0 | H26: ='Revenue Drivers'!H28 -> 0 | I26: ='Revenue Drivers'!I28 -> 0 | J26: ='Revenue Drivers'!J28 -> 0 | ... Q26: ='Revenue Drivers'!Q28 -> 1636.4569
A27: Reference share price | B27: ₹ / share | C27: =Valuation!C7 -> 105.7969 | D27: =Valuation!D7 -> 96.693771 | E27: =Valuation!E7 -> 105.43127 | F27: =Valuation!F7 -> 127.375 | G27: =Valuation!G7 -> 98.349998 | H27: =Valuation!H7 -> 207.075 | I27: =Valuation!I7 -> 295.95001 | J27: =Valuation!J7 -> 182.625 | ... Q27: =Valuation!Q7 -> 180.28999
A28: P/E | B28: x | C28: =Valuation!C15 -> 5.8476375 | D28: =Valuation!D15 -> 7.3978275 | E28: =Valuation!E15 -> 8.3528788 | F28: =Valuation!F15 -> 8.5202988 | G28: =Valuation!G15 -> 5.9159148 | H28: =Valuation!H15 -> 10.860873 | I28: =Valuation!I15 -> 13.277759 | J28: =Valuation!J15 -> 17.663912 | ... Q28: =Valuation!Q15 -> 10.0668
A29: EV / EBITDA | B29: x | C29: =Valuation!C17 -> 3.6934561 | D29: =Valuation!D17 -> 3.6232652 | E29: =Valuation!E17 -> 4.8566422 | F29: =Valuation!F17 -> 4.0659688 | G29: =Valuation!G17 -> 2.6606682 | H29: =Valuation!H17 -> 6.1631072 | I29: =Valuation!I17 -> 8.4599009 | J29: =Valuation!J17 -> 10.255009 | ... Q29: =Valuation!Q17 -> 5.3496848
A30: Implied target price | B30: ₹ / share | C30: =Valuation!C23 -> 0 | D30: =Valuation!D23 -> 0 | E30: =Valuation!E23 -> 0 | F30: =Valuation!F23 -> 0 | G30: =Valuation!G23 -> 0 | H30: =Valuation!H23 -> 0 | I30: =Valuation!I23 -> 0 | J30: =Valuation!J23 -> 0 | ... Q30: =Valuation!Q23 -> 367.14198
A31: Upside / (downside) | B31: % | C31: =Valuation!C24 -> 0 | D31: =Valuation!D24 -> 0 | E31: =Valuation!E24 -> 0 | F31: =Valuation!F24 -> 0 | G31: =Valuation!G24 -> 0 | H31: =Valuation!H24 -> 0 | I31: =Valuation!I24 -> 0 | J31: =Valuation!J24 -> 0 | ... Q31: =Valuation!Q24 -> 1.0363969

Sheet Sources
A1: Sources & Data Conventions
A2: Primary-source register; unavailable disclosures stay blank and derived values are explicitly identified
A5: ID | B5: Data / Period | C5: Units | D5: Primary source | E5: Use | F5: Status | G5: Notes
A6: S1 | B6: Annual reports FY16–FY26 | C6: ₹ mn | D6: https://www.wipro.com/investors/annual-reports/ | E6: Audited P&L, balance sheet and cash flow | F6: Loaded | G6: FY26 annual report manually controlled because SEC filing uses extension tags
A7: S2 | B7: Quarterly IFRS financials FY16–Q1FY27 | C7: ₹ mn | D7: https://www.wipro.com/investors/quarterly-results/ | E7: Quarterly consolidated P&L | F7: Loaded | G7: Q4 is annual less Q1–Q3 where needed, ensuring audited annual roll-up
A8: S3 | B8: Quarterly data sheets FY16–Q1FY27 | C8: $m / % / # | D8: https://www.wipro.com/investors/quarterly-results/ | E8: USD revenue, margin, vertical/geography/currency mix, clients, headcount, utilization and bookings | F8: Loaded | G8: Definitions and classifications change over time and are kept separate
A9: S4 | B9: SEC company facts | C9: INR / shares | D9: https://data.sec.gov/api/xbrl/companyfacts/CIK0001123799.json | E9: Standardized FY16–FY25 IFRS history and shares | F9: Loaded | G9: Latest-filed comparative selected for each fiscal period
A10: S5 | B10: WIPRO.NS daily prices | C10: ₹ / share | D10: https://query1.finance.yahoo.com/v8/finance/chart/WIPRO.NS | E10: Market-data tab and historical FY-end valuation | F10: Loaded | G10: No external valuation opinion is imported
A11: S6 | B11: Q1 FY27 Wipro results | C11: ₹ mn / $m | D11: https://www.wipro.com/investors/quarterly-results/ | E11: Q1 FY27 actual P&L and operating metrics | F11: Loaded | G11: Revenue ₹244,786m; IT services revenue $2,614.5m; bookings $3,370m
A12: S7 | B12: Historical AI revenue | C12: n/a | D12: n/a | E12: Forecast policy | F12: Not disclosed | G12: No historical AI revenue is hardcoded; model uses a scenario-driven incremental uplift
A13: S8 | B13: Derived interim D&A | C13: ₹ cr | D13: Audited annual D&A less reported quarters | E13: Quarterly EBITDA bridge | F13: Derived | G13: Only used where the interim D&A table was image-only; allocation is revenue-weighted and annual total is exact
A14: S9 | B14: Cash-flow residual lines | C14: ₹ cr | D14: Audited CFS totals | E14: Historical detailed CFS bridge | F14: Calculated | G14: Other CFO / CFI / CFF is a formula residual, never an invented hardcode

Sheet Assumptions
A1: Forecast Assumptions
A2: Blue text on yellow = editable; every forecast output is formula-linked
A5: Driver | B5: Units | C5: FY27E | D5: FY28E | E5: FY29E | F5: FY30E | G5: Logic / interpretation
A6: Total headcount growth | B6: % | C6: 0.015 | D6: 0.025 | E6: 0.03 | F6: 0.035 | G6: Closing headcount growth
A7: Service employee share | B7: % | C7: 0.935 | D7: 0.936 | E7: 0.937 | F7: 0.938 | G7: Headcount less sales / support
A8: Utilization / billable rate | B8: % | C8: 0.845 | D8: 0.85 | E8: 0.855 | F8: 0.858 | G8: Billable FTE conversion
A9: Pricing / productivity uplift | B9: % | C9: 0.02 | D9: 0.025 | E9: 0.03 | F9: 0.03 | G9: Revenue per billable FTE improvement
A10: Capacity uplift realization | B10: % | C10: 0.65 | D10: 0.7 | E10: 0.75 | F10: 0.75 | G10: Recognized share of billable capacity / productivity uplift
A11: Core revenue retention | B11: % | C11: 0.97 | D11: 0.972 | E11: 0.974 | F11: 0.975 | G11: Prior-year revenue retained before incremental drivers
A12: FPP mix | B12: % | C12: 0.55 | D12: 0.56 | E12: 0.57 | F12: 0.58 | G12: Fixed-price / managed-services mix
A13: AI deflation on T&M revenue | B13: % | C13: 0.01 | D13: 0.013 | E13: 0.016 | F13: 0.018 | G13: Explicit T&M productivity / pricing drag
A14: Total bookings growth | B14: % | C14: 0.06 | D14: 0.07 | E14: 0.08 | F14: 0.08 | G14: Bookings scenario
A15: Bookings current-year realization | B15: % | C15: 0.02 | D15: 0.022 | E15: 0.024 | F15: 0.025 | G15: Incremental recognized revenue from bookings
A16: AI uplift / prior-year revenue | B16: % | C16: 0.006 | D16: 0.01 | E16: 0.013 | F16: 0.015 | G16: Incremental AI-led recognized revenue; not historical disclosure
A17: Acquisition revenue / prior-year revenue | B17: % | C17: 0.004 | D17: 0.003 | E17: 0.002 | F17: 0.002 | G17: Separate acquisition contribution
... A57: FX effect on cash | B57: ₹ cr | C57: 0 | D57: 0 | E57: 0 | F57: 0 | G57: Forecast cash translation adjustment

Sheet Raw Financials
A1: Raw Reported Financials — Source Layer
A2: Hardcoded official reported inputs only; calculations live downstream
A4: Annual reported P&L
A5: Metric | B5: Units | C5: FY16A | D5: FY17A | E5: FY18A | F5: FY19A | G5: FY20A | H5: FY21A | I5: FY22A | J5: FY23A | K5: FY24A | L5: FY25A | M5: FY26A
A6: Revenue | B6: ₹ cr | C6: 51244 | D6: 55040.2 | E6: 54487.1 | F6: 58584.5 | G6: 61023.2 | H6: 61943 | I6: 79093.4 | J6: 90487.6 | K6: 89760.3 | L6: 89088.4 | M6: 92624
A7: Cost of revenue | B7: ₹ cr | C7: 35672.4 | D7: 39154.4 | E7: 38557.5 | F7: 41303.3 | G7: 43608.5 | H7: 42320.5 | I7: 55587.2 | J7: 64544.6 | K7: 63149.7 | L7: 61780.2 | M7: 65619.2
A8: Gross profit | B8: ₹ cr | C8: 15571.6 | D8: 15885.8 | E8: 15929.6 | F8: 17281.2 | G8: 17414.7 | H8: 19622.5 | I8: 23506.2 | J8: 25943 | K8: 26610.6 | L8: 27308.2 | M8: 27004.8
A9: Selling & marketing | B9: ₹ cr | C9: 3409.7 | D9: 4081.7 | E9: 4234.9 | F9: 4451 | G9: 4290.7 | H9: 4140 | I9: 5493.5 | J9: 6515.7 | K9: 6997.2 | L9: 6437.8 | M9: 5921.6
A10: General & administrative | B10: ₹ cr | C10: 2862.6 | D10: 3202.1 | E10: 3414.1 | F10: 3595.1 | G10: 2982.3 | H10: 3468.6 | I10: 4638.2 | J10: 5913.9 | K10: 6037.5 | L10: 5746.5 | M10: 6143.4
A11: Other operating income / FX | B11: ₹ cr
A12: EBITDA | B12: ₹ cr | C12: 11182.5 | D12: 11698.6 | E12: 10541.8 | F12: 11938.4 | G12: 12659.2 | H12: 15070.9 | I12: 17119.7 | J12: 17300.8 | K12: 17017 | L12: 18085 | M12: 18035.8
A13: D&A | B13: ₹ cr | C13: 1496.5 | D13: 2310.7 | E13: 2112.4 | F13: 1947.4 | G13: 2086.2 | H13: 2765.6 | I13: 3091.1 | J13: 3340.2 | K13: 3407.1 | L13: 2957.9 | M13: 2910.7
A14: EBIT | B14: ₹ cr | C14: 9686 | D14: 9387.9 | E14: 8429.4 | F14: 9991 | G14: 10573 | H14: 12305.3 | I14: 14028.6 | J14: 13960.6 | K14: 13609.9 | L14: 15127.1 | M14: 15125.1
A15: Finance expense | B15: ₹ cr | C15: 537.8 | D15: 594.2 | E15: 583 | F15: 737.5 | G15: 732.8 | H15: 508.8 | I15: 532.5 | J15: 1007.7 | K15: 1255.2 | L15: 1477 | M15: 1457.7
A16: Finance & other income | B16: ₹ cr | C16: 2345.1 | D16: 2241.9 | E16: 2399.9 | F16: 2292.3 | G16: 2408.1 | H16: 2091.2 | I16: 1625.7 | J16: 1818.5 | K16: 2389.6 | L16: 3820.2 | M16: 3649.1
A17: Share of associate / JV | B17: ₹ cr | C17: 0 | D17: 0 | E17: 1.1 | F17: -4.3 | G17: 2.9 | H17: 13 | I17: 5.7 | J17: -5.7 | K17: -23.3 | L17: 25.4 | M17: 25.7
A18: PBT | B18: ₹ cr | C18: 11493.3 | D18: 11035.6 | E18: 10247.4 | F18: 11541.5 | G18: 12251.2 | H18: 13900.7 | I18: 15127.5 | J18: 14765.7 | K18: 14721 | L18: 17495.7 | M18: 17342.2
A19: Tax | B19: ₹ cr | C19: 2536.6 | D19: 2521.3 | E19: 2239 | F19: 2524.2 | G19: 2479.9 | H19: 3034.5 | I19: 2894.6 | J19: 3399.2 | K19: 3608.9 | L19: 4277.7 | M19: 4076.7
A20: Profit incl. NCI | B20: ₹ cr | C20: 8956.7 | D20: 8514.3 | E20: 8008.4 | F20: 9017.3 | G20: 9771.3 | H20: 10866.2 | I20: 12232.9 | J20: 11366.5 | K20: 11112.1 | L20: 13218 | M20: 13265.5
A21: NCI | B21: ₹ cr | C21: 49.2 | D21: 24.8 | E21: 0.3 | F21: 14.2 | G21: 49.5 | H21: 71.6 | I21: 13.8 | J21: 16.5 | K21: 66.9 | L21: 82.6 | M21: 68.1
A22: Net income attributable | B22: ₹ cr | C22: 8907.5 | D22: 8489.5 | E22: 8008.1 | F22: 9003.1 | G22: 9721.8 | H22: 10794.6 | I22: 12219.1 | J22: 11350 | K22: 11045.2 | L22: 13135.4 | M22: 13197.4
A23: Basic EPS | B23: ₹ / share | C23: 18.13 | D23: 13.11 | E23: 12.64 | F23: 14.99 | G23: 16.67 | H23: 19.11 | I23: 22.35 | J23: 10.36 | K23: 10.44 | L23: 12.56 | M23: 12.6
... A26: Diluted weighted shares | B26: m | C26: 4923.3798 | D26: 6495.1295 | E26: 6344.4826 | F26: 6022.3044 | G26: 5847.8232 | H26: 5661.6578 | I26: 5482.0834 | J26: 10977.982 | K26: 10611.425 | L26: 10488.939 | M26: 10503.423
A30: Quarterly reported P&L — Q4 derived as annual less Q1–Q3 where required
A31: Metric | B31: Units | C31: Q1 FY16A | D31: Q2 FY16A | E31: Q3 FY16A | F31: Q4 FY16A | G31: Q1 FY17A | H31: Q2 FY17A | I31: Q3 FY17A | J31: Q4 FY17A | K31: Q1 FY18A | L31: Q2 FY18A | M31: Q3 FY18A | N31: Q4 FY18A | O31: Q1 FY19A | P31: Q2 FY19A | Q31: Q3 FY19A | R31: Q4 FY19A | S31: Q1 FY20A | T31: Q2 FY20A | U31: Q3 FY20A | V31: Q4 FY20A | W31: Q1 FY21A | X31: Q2 FY21A | Y31: Q3 FY21A | Z31: Q4 FY21A | AA31: Q1 FY22A | AB31: Q2 FY22A | AC31: Q3 FY22A | AD31: Q4 FY22A | AE31: Q1 FY23A | AF31: Q2 FY23A | AG31: Q3 FY23A | AH31: Q4 FY23A | AI31: Q1 FY24A | AJ31: Q2 FY24A | AK31: Q3 FY24A | AL31: Q4 FY24A | AM31: Q1 FY25A | AN31: Q2 FY25A | AO31: Q3 FY25A | AP31: Q4 FY25A | AQ31: Q1 FY26A | AR31: Q2 FY26A | AS31: Q3 FY26A | AT31: Q4 FY26A | AU31: Q1 FY27A
A32: Revenue | B32: ₹ cr | C32: 12237.6 | D32: 12513.5 | E32: 12860.5 | F32: 13632.4 | G32: 13599.2 | H32: 13765.7 | I32: 13687.8 | J32: 13987.5 | K32: 13626.1 | L32: 13423.4 | M32: 13669 | N32: 13768.6 | O32: 13977.7 | P32: 14541 | Q32: 15059.5 | R32: 15006.3 | S32: 14716.1 | T32: 15125.6 | U32: 15470.5 | V32: 15711 | W32: 14913.1 | X32: 15114.5 | Y32: 15670 | Z32: 16245.4 | AA32: 18252.4 | AB32: 19667.4 | AC32: 20313.6 | AD32: 20860 | AE32: 21528.6 | AF32: 22539.7 | AG32: 23229 | AH32: 23190.3 | AI32: 22831 | AJ32: 22515.9 | AK32: 22205.1 | AL32: 22208.3 | AM32: 21963.8 | AN32: 22301.6 | AO32: 22318.8 | AP32: 22504.2 | AQ32: 22134.6 | AR32: 22697.3 | AS32: 23555.8 | AT32: 24236.3 | AU32: 24478.6
A33: Cost of revenue | B33: ₹ cr | C33: 8478.7 | D33: 8582.4 | E33: 9027 | F33: 9584.3 | G33: 9638.9 | H33: 9780.8 | I33: 9657.6 | J33: 10077.1 | K33: 9711.1 | L33: 9469.4 | M33: 9597.6 | N33: 9779.4 | O33: 10035 | P33: 10177 | Q33: 10397.1 | R33: 10694.2 | S33: 10427.3 | T33: 10800.6 | U33: 10967.3 | V33: 11413.3 | W33: 10370 | X33: 10538.7 | Y33: 10431.3 | Z33: 10980.5 | AA33: 12756.7 | AB33: 13756.2 | AC33: 14277.8 | AD33: 14796.5 | AE33: 15560 | AF33: 16383.5 | AG33: 16327.3 | AH33: 16273.8 | AI33: 16126.1 | AJ33: 15919.1 | AK33: 15382.6 | AL33: 15721.9 | AM33: 15330.6 | AN33: 15504.9 | AO33: 15392.2 | AP33: 15552.5 | AQ33: 15724.7 | AR33: 15983.2 | AS33: 16719.9 | AT33: 17191.4 | AU33: 17490
A34: Gross profit | B34: ₹ cr | C34: 3758.9 | D34: 3931.1 | E34: 3833.5 | F34: 4048.1 | G34: 3960.3 | H34: 3984.9 | I34: 4030.2 | J34: 3910.4 | K34: 3915 | L34: 3954 | M34: 4071.4 | N34: 3989.2 | O34: 3942.7 | P34: 4364 | Q34: 4662.4 | R34: 4312.1 | S34: 4288.8 | T34: 4325 | U34: 4503.2 | V34: 4297.7 | W34: 4543.1 | X34: 4575.8 | Y34: 5238.7 | Z34: 5264.9 | AA34: 5495.7 | AB34: 5911.2 | AC34: 6035.8 | AD34: 6063.5 | AE34: 5968.6 | AF34: 6156.2 | AG34: 6901.7 | AH34: 6916.5 | AI34: 6704.9 | AJ34: 6596.8 | AK34: 6822.5 | AL34: 6486.4 | AM34: 6633.2 | AN34: 6796.7 | AO34: 6926.6 | AP34: 6951.7 | AQ34: 6409.9 | AR34: 6714.1 | AS34: 6835.9 | AT34: 7044.9 | AU34: 6988.6
A35: Selling & marketing | B35: ₹ cr | C35: 804.4 | D35: 870.8 | E35: 836.2 | F35: 898.3 | G35: 1014.1 | H35: 961.4 | I35: 922.6 | J35: 1183.6 | K35: 1014.6 | L35: 986.7 | M35: 1107.3 | N35: 1126.3 | O35: 1081.3 | P35: 1081.4 | Q35: 1188.9 | R35: 1099.4 | S35: 1095.3 | T35: 1062.9 | U35: 1103 | V35: 1029.5 | W35: 978.9 | X35: 960.6 | Y35: 1132.6 | Z35: 1067.9 | AA35: 1301.7 | AB35: 1385.2 | AC35: 1398.8 | AD35: 1407.8 | AE35: 1535.9 | AF35: 1514 | AG35: 1775.2 | AH35: 1690.6 | AI35: 1658.4 | AJ35: 1876.7 | AK35: 1917.8 | AL35: 1544.3 | AM35: 1584.4 | AN35: 1738.8 | AO35: 1608.1 | AP35: 1506.5 | AQ35: 1528.5 | AR35: 1492 | AS35: 1500.8 | AT35: 1400.3 | AU35: 1649.6
A36: General & administrative | B36: ₹ cr | C36: 685.3 | D36: 684.7 | E36: 701 | F36: 791.6 | G36: 759.9 | H36: 854.5 | I36: 861 | J36: 726.7 | K36: 726.4 | L36: 708.5 | M36: 999.1 | N36: 980.1 | O36: 860.8 | P36: 1369.6 | Q36: 697.8 | R36: 666.9 | S36: 811.9 | T36: 652.7 | U36: 749.6 | V36: 768.1 | W36: 1000.6 | X36: 817.7 | Y36: 781.4 | Z36: 868.9 | AA36: 1053 | AB36: 1128.8 | AC36: 1203.6 | AD36: 1252.8 | AE36: 1347.1 | AF36: 1497.6 | AG36: 1502 | AH36: 1567.2 | AI36: 1588.7 | AJ36: 1412.4 | AK36: 1644.4 | AL36: 1392 | AM36: 1421.3 | AN36: 1303.4 | AO36: 1462.9 | AP36: 1558.9 | AQ36: 1327.2 | AR36: 1495 | AS36: 1840.4 | AT36: 1480.8 | AU36: 1496.3
A37: Other operating income / FX | B37: ₹ cr | C37: 133 | D37: 53.3 | E37: 91.1 | F37: 109.3 | G37: 98.4 | H37: 128.1 | I37: 76.7 | J37: 482.7 | K37: 35.3 | L37: 45.3 | M37: 12.5 | N37: 55.7 | O37: 330 | P37: 148.6 | Q37: 91.1 | R37: 186.2 | S37: 155.7 | T37: 64.1 | U37: 72.7 | V37: 138.8 | W37: 130.2 | X37: 16 | Y37: 56.6 | Z37: 88.6 | AA37: 331 | AB37: 94.8 | AC37: 120.1 | AD37: 108.2 | AE37: 103.4 | AF37: 105.7 | AG37: 139.1 | AH37: 99 | AI37: -6.2 | AJ37: 26.8 | AK37: 26.2 | AL37: -12.8 | AM37: -20.6 | AN37: -39.6 | AO37: 41 | AP37: 22.4 | AQ37: 18.2 | AR37: 55.8 | AS37: 78.8 | AT37: 32.5 | AU37: 77.9
A38: EBITDA | B38: ₹ cr | C38: 2738.9 | D38: 2781.9 | E38: 2763.8 | F38: 2897.9 | G38: 2751.2 | H38: 2782 | I38: 2864.5 | J38: 3300.9 | K38: 2703.6 | L38: 2824.1 | M38: 2505.4 | N38: 2508.7 | O38: 2788.3368 | P38: 2498.6 | Q38: 3359.9632 | R38: 3291.5 | S38: 3032.8 | T38: 3154.9 | U38: 3252.8 | V38: 3218.7 | W38: 3359.6326 | X38: 3488.3246 | Y38: 4080.9263 | Z38: 4142.0165 | AA38: 4185.3338 | AB38: 4260.6343 | AC38: 4347.3889 | AD38: 4326.3431 | AE38: 3983.6926 | AF38: 4082.3157 | AG38: 4621.0601 | AH38: 4613.7315 | AI38: 4318.2136 | AJ38: 4189.1531 | AK38: 4129.3559 | AL38: 4380.2773 | AM38: 4336.1389 | AN38: 4455.3545 | AO38: 4637.6255 | AP38: 4655.8812 | AQ38: 4267.9776 | AR38: 4496.1604 | AS38: 4313.7387 | AT38: 4957.9233
A39: D&A | B39: ₹ cr | C39: 336.7 | D39: 353 | E39: 376.4 | F39: 430.4 | G39: 466.5 | H39: 484.9 | I39: 541.2 | J39: 818.1 | K39: 494.3 | L39: 520 | M39: 527.9 | N39: 570.2 | O39: 457.7368 | P39: 437 | Q39: 493.1632 | R39: 559.5 | S39: 495.5 | T39: 481.4 | U39: 529.5 | V39: 579.8 | W39: 665.83261 | X39: 674.82462 | Y39: 699.6263 | Z39: 725.31647 | AA39: 713.33378 | AB39: 768.6343 | AC39: 793.88886 | AD39: 815.24307 | AE39: 794.69264 | AF39: 832.01572 | AG39: 857.46009 | AH39: 856.03155 | AI39: 866.61364 | AJ39: 854.65315 | AK39: 842.85588 | AL39: 842.97734 | AM39: 729.23887 | AN39: 740.45445 | AO39: 741.02553 | AP39: 747.18115 | AQ39: 695.57761 | AR39: 713.2604 | AS39: 740.23868 | AT39: 761.62332
A40: EBIT | B40: ₹ cr | C40: 2402.2 | D40: 2428.9 | E40: 2387.4 | F40: 2467.5 | G40: 2284.7 | H40: 2297.1 | I40: 2323.3 | J40: 2482.8 | K40: 2209.3 | L40: 2304.1 | M40: 1977.5 | N40: 1938.5 | O40: 2330.6 | P40: 2061.6 | Q40: 2866.8 | R40: 2732 | S40: 2537.3 | T40: 2673.5 | U40: 2723.3 | V40: 2638.9 | W40: 2693.8 | X40: 2813.5 | Y40: 3381.3 | Z40: 3416.7 | AA40: 3472 | AB40: 3492 | AC40: 3553.5 | AD40: 3511.1 | AE40: 3189 | AF40: 3250.3 | AG40: 3763.6 | AH40: 3757.7 | AI40: 3451.6 | AJ40: 3334.5 | AK40: 3286.5 | AL40: 3537.3 | AM40: 3606.9 | AN40: 3714.9 | AO40: 3896.6 | AP40: 3908.7 | AQ40: 3572.4 | AR40: 3782.9 | AS40: 3573.5 | AT40: 4196.3 | AU40: 3920.6
A41: Finance expense | B41: ₹ cr | C41: 128.6 | D41: 158.9 | E41: 142.3 | F41: 108 | G41: 133.6 | H41: 142.8 | I41: 136.6 | J41: 181.2 | K41: 147.4 | L41: 138.6 | M41: 120.5 | N41: 176.5 | O41: 164.9 | P41: 156.9 | Q41: 162.7 | R41: 253 | S41: 158.4 | T41: 224.7 | U41: 184.4 | V41: 165.3 | W41: 129.9 | X41: 126.7 | Y41: 140 | Z41: 112.2 | AA41: 74.6 | AB41: 145.9 | AC41: 140.3 | AD41: 171.7 | AE41: 204.5 | AF41: 227 | AG41: 290.2 | AH41: 286 | AI41: 308.6 | AJ41: 303.3 | AK41: 312.5 | AL41: 330.8 | AM41: 328.8 | AN41: 356.9 | AO41: 414.6 | AP41: 376.7 | AQ41: 360.8 | AR41: 361.2 | AS41: 365.6 | AT41: 370.1 | AU41: 472.8
A42: Finance & other income | B42: ₹ cr | C42: 524.2 | D42: 619.4 | E42: 622.7 | F42: 578.8 | G42: 520 | H42: 510.5 | I42: 571.9 | J42: 639.5 | K42: 620 | L42: 666.1 | M42: 613.4 | N42: 500.4 | O42: 519.7 | P42: 513.6 | Q42: 536.2 | R42: 722.8 | S42: 694.7 | T42: 685.7 | U42: 537 | V42: 490.7 | W42: 528.1 | X42: 520.9 | Y42: 597.5 | Z42: 444.7 | AA42: 461.9 | AB42: 411.4 | AC42: 357.8 | AD42: 394.6 | AE42: 369 | AF42: 404 | AG42: 499.2 | AH42: 546.3 | AI42: 654.2 | AJ42: 481 | AK42: 578.5 | AL42: 675.9 | AM42: 748 | AN42: 919.5 | AO42: 970.8 | AP42: 1181.9 | AQ42: 1041.7 | AR42: 845.5 | AS42: 923.2 | AT42: 838.7 | AU42: 887.2
A43: Share of associate / JV | B43: ₹ cr | C43: 0 | D43: 0 | E43: 0 | F43: 0 | G43: 0 | H43: 0 | I43: 0 | J43: 0 | K43: -0.1 | L43: 0.5 | M43: 1 | N43: -0.3 | O43: -5.3 | P43: 2 | Q43: 0.7 | R43: -1.7 | S43: -1.6 | T43: -0.2 | U43: 3.4 | V43: 1.3 | W43: 3.1 | X43: -0.6 | Y43: 10.1 | Z43: 0.4 | AA43: 0.7 | AB43: -1 | AC43: 7.6 | AD43: -1.6 | AE43: -1.5 | AF43: -7.2 | AG43: 2.6 | AH43: 0.4 | AI43: 0.3 | AJ43: -3 | AK43: -0.4 | AL43: -20.2 | AM43: -4.5 | AN43: 0.3 | AO43: 0.5 | AP43: 29.1 | AQ43: 5 | AR43: 15.2 | AS43: 2.8 | AT43: 2.7 | AU43: -0.5
A44: PBT | B44: ₹ cr | C44: 2797.8 | D44: 2889.4 | E44: 2867.8 | F44: 2938.3 | G44: 2671.1 | H44: 2664.8 | I44: 2758.6 | J44: 2941.1 | K44: 2681.8 | L44: 2832.1 | M44: 2471.4 | N44: 2262.1 | O44: 2680.1 | P44: 2420.3 | Q44: 3241 | R44: 3200.1 | S44: 3072 | T44: 3134.3 | U44: 3079.3 | V44: 2965.6 | W44: 3095.1 | X44: 3207.1 | Y44: 3848.9 | Z44: 3749.6 | AA44: 3860 | AB44: 3756.5 | AC44: 3778.6 | AD44: 3732.4 | AE44: 3352 | AF44: 3420.1 | AG44: 3975.2 | AH44: 4018.4 | AI44: 3797.5 | AJ44: 3509.2 | AK44: 3552.1 | AL44: 3862.2 | AM44: 4021.6 | AN44: 4277.8 | AO44: 4453.3 | AP44: 4743 | AQ44: 4258.3 | AR44: 4282.4 | AS44: 4133.9 | AT44: 4667.6 | AU44: 4334.5
A45: Tax | B45: ₹ cr | C45: 594.5 | D45: 648.6 | E45: 624.8 | F45: 668.7 | G45: 612.2 | H45: 590.9 | I45: 644 | J45: 674.2 | K45: 599.4 | L45: 642.6 | M45: 535.5 | N45: 461.5 | O45: 586.5 | P45: 534.7 | Q45: 696.6 | R45: 706.4 | S45: 669.9 | T45: 573.1 | U45: 616.4 | V45: 620.5 | W45: 683.8 | X45: 722.8 | Y45: 852.4 | Z45: 775.5 | AA45: 622.5 | AB45: 825.9 | AC45: 806.3 | AD45: 639.9 | AE45: 793.1 | AF45: 771 | AG45: 910.2 | AH45: 924.9 | AI45: 911.5 | AJ45: 841.9 | AK45: 851.5 | AL45: 1004 | AM45: 985 | AN45: 1051.2 | AO45: 1086.6 | AP45: 1154.9 | AQ45: 921.8 | AR45: 1020 | AS45: 988.9 | AT45: 1146 | AU45: 978.2
A46: Profit incl. NCI | B46: ₹ cr | C46: 2203.3 | D46: 2240.8 | E46: 2243 | F46: 2269.6 | G46: 2058.9 | H46: 2073.9 | I46: 2114.6 | J46: 2266.9 | K46: 2082.4 | L46: 4119 | M46: 1935.9 | N46: -128.9 | O46: 2093.6 | P46: 1885.6 | Q46: 2544.4 | R46: 2493.7 | S46: 2402.1 | T46: 2561.2 | U46: 2462.9 | V46: 2345.1 | W46: 2411.3 | X46: 2484.3 | Y46: 2996.5 | Z46: 2974.1 | AA46: 3237.5 | AB46: 2930.6 | AC46: 2972.3 | AD46: 3092.5 | AE46: 2558.9 | AF46: 2649.1 | AG46: 3065 | AH46: 3093.5 | AI46: 2886 | AJ46: 2667.3 | AK46: 2700.6 | AL46: 2858.2 | AM46: 3036.6 | AN46: 3226.6 | AO46: 3366.7 | AP46: 3588.1 | AQ46: 3336.5 | AR46: 3262.4 | AS46: 3145 | AT46: 3521.6 | AU46: 3356.3
...

Sheet Raw Operating
A1: Raw Reported Operating Metrics
A2: Quarter-end operating metrics from official Wipro data sheets; classifications remain separate
A5: Metric | B5: Units | C5: FY16A | D5: FY17A | E5: FY18A | F5: FY19A | G5: FY20A | H5: FY21A | I5: FY22A | J5: FY23A | K5: FY24A | L5: FY25A | M5: FY26A | N5: FY27E | O5: FY28E | P5: FY29E | Q5: FY30E
A7: IT services revenue | B7: $m | C7: 7346.3 | D7: 7704.5 | E7: 8060.2 | F7: 8120.3 | G7: 8256.2 | H7: 8136.5 | I7: 10355.9 | J7: 11159.7 | K7: 10805.3 | L7: 10511.5 | M7: 10478.1
A8: Closing headcount | B8: # | C8: 172912 | D8: 181482 | E8: 163827 | F8: 171425 | G8: 182886 | H8: 197712 | I8: 243128 | J8: 256921 | K8: 234054 | L8: 233346 | M8: 242156
A9: Sales & support staff | B9: # | C9: 13140 | D9: 14466 | E9: 14936 | F9: 14360 | G9: 14908 | H9: 15368 | I9: 17691 | J9: 16986 | K9: 15601 | L9: 15230 | M9: 14574
A10: Net utilization excl. trainees | B10: % | C10: 0.799 | D10: 0.823 | E10: 0.825 | F10: 0.848 | G10: 0.823 | H10: 0.859 | I10: 0.868 | J10: 0.812 | K10: 0.848 | L10: 0.856 | M10: 0.845
A11: Voluntary attrition TTM | B11: % | C11: 0.161 | D11: 0.163 | E11: 0.166 | F11: 0.176 | G11: 0.147 | H11: 0.121 | I11: 0.238 | J11: 0.192 | K11: 0.142 | L11: 0.15 | M11: 0.138
A12: FPP mix | B12: % | C12: 0.552 | D12: 0.571 | E12: 0.581 | F12: 0.594 | G12: 0.624 | H12: 0.62 | I12: 0.628 | J12: 0.594 | K12: 0.592 | L12: 0.566 | M12: 0.543
A13: Active clients | B13: # | C13: 1223 | D13: 1323 | E13: 1248 | F13: 1115 | G13: 1074 | H13: 1120 | I13: 1369 | J13: 1441 | K13: 1371 | L13: 1282 | M13: 1233
A14: $100m+ clients | B14: # | C14: 9 | D14: 9 | E14: 8 | F14: 10 | G14: 15 | H14: 11 | I14: 19 | J14: 19 | K14: 22 | L14: 17 | M14: 16
A15: $50m+ clients | B15: # | C15: 33 | D15: 34 | E15: 39 | F15: 41 | G15: 40 | H15: 40 | I15: 50 | J15: 53 | K15: 45 | L15: 44 | M15: 45
A16: $20m+ clients | B16: # | C16: 89 | D16: 91 | E16: 95 | F16: 96 | G16: 96 | H16: 93 | I16: 117 | J16: 117 | K16: 116 | L16: 111 | M16: 106
A17: $10m+ clients | B17: # | C17: 160 | D17: 163 | E17: 171 | F17: 172 | G17: 166 | H17: 167 | I17: 194 | J17: 208 | K17: 205 | L17: 181 | M17: 183
A18: $5m+ clients | B18: # | C18: 248 | D18: 268 | E18: 277 | F18: 262 | G18: 260 | H18: 257 | I18: 297 | J18: 311 | K18: 301 | L18: 289 | M18: 289
... A22: Top 10 | B22: % | C22: 0.1 | D22: 0.1 | E22: 0.1 | F22: 0.1 | G22: 0.1 | H22: 0.1 | I22: 0.1 | J22: 0.1 | K22: 0.1 | L22: 0.1 | M22: 0.1
A23: Total bookings | B23: $m | K23: 14907 | L23: 14315 | M23: 16449
A24: Large-deal TCV | B24: $m | L24: 5368 | M24: 7829
A25: USD mix | B25: % | C25: 0.6 | D25: 0.61 | E25: 0.58 | F25: 0.61 | G25: 0.63 | H25: 0.61 | I25: 0.59 | J25: 0.61 | K25: 0.6 | L25: 0.62 | M25: 0.61
A26: GBP mix | B26: % | C26: 0.12 | D26: 0.1 | E26: 0.1 | F26: 0.1 | G26: 0.1 | H26: 0.1 | I26: 0.11 | J26: 0.1 | K26: 0.11 | L26: 0.1 | M26: 0.11
A27: EUR mix | B27: % | C27: 0.08 | D27: 0.09 | E27: 0.09 | F27: 0.09 | G27: 0.08 | H27: 0.08 | I27: 0.1 | J27: 0.1 | K27: 0.1 | L27: 0.1 | M27: 0.09
A28: INR mix | B28: % | C28: 0.07 | D28: 0.07 | E28: 0.08 | F28: 0.05 | G28: 0.04 | H28: 0.05 | I28: 0.05 | J28: 0.04 | K28: 0.05 | L28: 0.04 | M28: 0.05
A29: AUD mix | B29: % | C29: 0.04 | D29: 0.04 | E29: 0.05 | F29: 0.05 | G29: 0.05 | H29: 0.05 | I29: 0.05 | J29: 0.05 | K29: 0.04 | L29: 0.04 | M29: 0.04
A30: CAD mix | B30: % | C30: 0.02 | D30: 0.02 | E30: 0.02 | F30: 0.03 | G30: 0.03 | H30: 0.03 | I30: 0.03 | J30: 0.03 | K30: 0.03 | L30: 0.03 | M30: 0.03
A31: Other currency mix | B31: % | C31: 0.07 | D31: 0.07 | E31: 0.08 | F31: 0.07 | G31: 0.07 | H31: 0.08 | I31: 0.07 | J31: 0.07 | K31: 0.07 | L31: 0.07 | M31: 0.07
A34: Legacy vertical and geography mix
A35: BFSI / finance solutions | B35: % | C35: 0.263 | D35: 0.257 | E35: 0.281 | F35: 0.309 | G35: 0.31 | H35: 0.307 | I35: 0.347 | J35: 0.349 | K35: 0.334 | L35: 0.343 | M35: 0.341
A36: Communications / media | B36: % | C36: 0.133 | D36: 0.073 | E36: 0.064 | F36: 0.057 | G36: 0.057 | H36: 0.052 | I36: 0.05 | J36: 0.047 | K36: 0.042 | L36: 0.152 | M36: 0.02
A37: Manufacturing / energy & resources | B37: % | C37: 0.186 | M37: 0.17
A38: Health | B38: % | C38: 0.12 | D38: 0.156 | F38: 0.132 | G38: 0.132 | H38: 0.13 | I38: 0.115 | J38: 0.122 | K38: 0.141 | L38: 0.144 | M38: 0.142
A39: Consumer / retail | B39: % | C39: 0.152 | D39: 0.158 | E39: 0.158 | F39: 0.157 | G39: 0.163 | H39: 0.17 | I39: 0.179 | J39: 0.188 | K39: 0.187 | L39: 0.189 | M39: 0.184
A40: Energy legacy | B40: % | C40: 0.146 | D40: 0.131
A41: Technology & communications | B41: % | L41: 0.153 | M41: 0.16
A42: Americas | B42: % | C42: 0.527 | D42: 0.547 | E42: 0.534 | F42: 0.568 | G42: 0.591 | H42: 0.294 | I42: 0.279 | J42: 0.291 | K42: 0.3 | L42: 0.317 | M42: 0.332
A43: Europe | B43: % | C43: 0.253 | D43: 0.244 | E43: 0.256 | F43: 0.255 | G43: 0.24 | H43: 0.273 | I43: 0.299 | J43: 0.286 | K43: 0.284 | L43: 0.271 | M43: 0.265
A44: India & Middle East | B44: % | C44: 0.108 | D44: 0.101 | E44: 0.099
A45: APAC / other emerging | B45: % | C45: 0.112 | D45: 0.108 | E45: 0.111
A46: Americas 1 | B46: % | H46: 0.294 | I46: 0.279 | J46: 0.291 | K46: 0.3 | L46: 0.317 | M46: 0.332
A47: Americas 2 | B47: % | H47: 0.297 | I47: 0.306 | J47: 0.31 | K47: 0.301 | L47: 0.306 | M47: 0.292
A48: APMEA | B48: % | H48: 0.136 | I48: 0.116 | J48: 0.113 | K48: 0.115 | L48: 0.106 | M48: 0.111

Sheet Quarterly P&L
A1: Quarterly Profit & Loss
A2: FY16–FY26 actual plus Q1 FY27 actual; all lines link to the raw source layer
A5: Metric | B5: Units | C5: Q1 FY16A | D5: Q2 FY16A | E5: Q3 FY16A | F5: Q4 FY16A | G5: Q1 FY17A | H5: Q2 FY17A | I5: Q3 FY17A | J5: Q4 FY17A | K5: Q1 FY18A | L5: Q2 FY18A | M5: Q3 FY18A | N5: Q4 FY18A | O5: Q1 FY19A | P5: Q2 FY19A | Q5: Q3 FY19A | R5: Q4 FY19A | S5: Q1 FY20A | T5: Q2 FY20A | U5: Q3 FY20A | V5: Q4 FY20A | W5: Q1 FY21A | X5: Q2 FY21A | Y5: Q3 FY21A | Z5: Q4 FY21A | AA5: Q1 FY22A | AB5: Q2 FY22A | AC5: Q3 FY22A | AD5: Q4 FY22A | AE5: Q1 FY23A | AF5: Q2 FY23A | AG5: Q3 FY23A | AH5: Q4 FY23A | AI5: Q1 FY24A | AJ5: Q2 FY24A | AK5: Q3 FY24A | AL5: Q4 FY24A | AM5: Q1 FY25A | AN5: Q2 FY25A | AO5: Q3 FY25A | AP5: Q4 FY25A | AQ5: Q1 FY26A | AR5: Q2 FY26A | AS5: Q3 FY26A | AT5: Q4 FY26A | AU5: Q1 FY27A
A6: Revenue | B6: ₹ cr | C6: ='Raw Financials'!C32 -> 12237.6 | D6: ='Raw Financials'!D32 -> 12513.5 | E6: ='Raw Financials'!E32 -> 12860.5 | F6: ='Raw Financials'!F32 -> 13632.4 | G6: ='Raw Financials'!G32 -> 13599.2 | H6: ='Raw Financials'!H32 -> 13765.7 | I6: ='Raw Financials'!I32 -> 13687.8 | J6: ='Raw Financials'!J32 -> 13987.5 | ... AU6: ='Raw Financials'!AU32 -> 24478.6
A7: QoQ growth | B7: % | D7: =IFERROR(D6/C6-1,"") -> 0.02254527 | E7: =IFERROR(E6/D6-1,"") -> 0.027730052 | F7: =IFERROR(F6/E6-1,"") -> 0.060020995 | G7: =IFERROR(G6/F6-1,"") -> -0.0024353745 | H7: =IFERROR(H6/G6-1,"") -> 0.012243367 | I7: =IFERROR(I6/H6-1,"") -> -0.005658993 | J7: =IFERROR(J6/I6-1,"") -> 0.021895411 | K7: =IFERROR(K6/J6-1,"") -> -0.025837355 | ... AU7: =IFERROR(AU6/AT6-1,"") -> 0.0099974006
A8: YoY growth | B8: % | G8: =IFERROR(G6/C6-1,"") -> 0.11126365 | H8: =IFERROR(H6/D6-1,"") -> 0.10006793 | I8: =IFERROR(I6/E6-1,"") -> 0.064328759 | J8: =IFERROR(J6/F6-1,"") -> 0.026048238 | K8: =IFERROR(K6/G6-1,"") -> 0.0019780575 | L8: =IFERROR(L6/H6-1,"") -> -0.024866153 | M8: =IFERROR(M6/I6-1,"") -> -0.0013734859 | N8: =IFERROR(N6/J6-1,"") -> -0.015649687 | ... AU8: =IFERROR(AU6/AQ6-1,"") -> 0.10589755
A9: Cost of revenue | B9: ₹ cr | C9: ='Raw Financials'!C33 -> 8478.7 | D9: ='Raw Financials'!D33 -> 8582.4 | E9: ='Raw Financials'!E33 -> 9027 | F9: ='Raw Financials'!F33 -> 9584.3 | G9: ='Raw Financials'!G33 -> 9638.9 | H9: ='Raw Financials'!H33 -> 9780.8 | I9: ='Raw Financials'!I33 -> 9657.6 | J9: ='Raw Financials'!J33 -> 10077.1 | ... AU9: ='Raw Financials'!AU33 -> 17490
A10: Gross profit | B10: ₹ cr | C10: ='Raw Financials'!C34 -> 3758.9 | D10: ='Raw Financials'!D34 -> 3931.1 | E10: ='Raw Financials'!E34 -> 3833.5 | F10: ='Raw Financials'!F34 -> 4048.1 | G10: ='Raw Financials'!G34 -> 3960.3 | H10: ='Raw Financials'!H34 -> 3984.9 | I10: ='Raw Financials'!I34 -> 4030.2 | J10: ='Raw Financials'!J34 -> 3910.4 | ... AU10: ='Raw Financials'!AU34 -> 6988.6
A11: Gross margin | B11: % | C11: =IFERROR(C10/C6,"") -> 0.3071599 | D11: =IFERROR(D10/D6,"") -> 0.31414872 | E11: =IFERROR(E10/E6,"") -> 0.29808328 | F11: =IFERROR(F10/F6,"") -> 0.29694698 | G11: =IFERROR(G10/G6,"") -> 0.29121566 | H11: =IFERROR(H10/H6,"") -> 0.28948038 | I11: =IFERROR(I10/I6,"") -> 0.29443738 | J11: =IFERROR(J10/J6,"") -> 0.2795639 | ... AU11: =IFERROR(AU10/AU6,"") -> 0.28549835
A12: Selling & marketing | B12: ₹ cr | C12: ='Raw Financials'!C35 -> 804.4 | D12: ='Raw Financials'!D35 -> 870.8 | E12: ='Raw Financials'!E35 -> 836.2 | F12: ='Raw Financials'!F35 -> 898.3 | G12: ='Raw Financials'!G35 -> 1014.1 | H12: ='Raw Financials'!H35 -> 961.4 | I12: ='Raw Financials'!I35 -> 922.6 | J12: ='Raw Financials'!J35 -> 1183.6 | ... AU12: ='Raw Financials'!AU35 -> 1649.6
A13: General & administrative | B13: ₹ cr | C13: ='Raw Financials'!C36 -> 685.3 | D13: ='Raw Financials'!D36 -> 684.7 | E13: ='Raw Financials'!E36 -> 701 | F13: ='Raw Financials'!F36 -> 791.6 | G13: ='Raw Financials'!G36 -> 759.9 | H13: ='Raw Financials'!H36 -> 854.5 | I13: ='Raw Financials'!I36 -> 861 | J13: ='Raw Financials'!J36 -> 726.7 | ... AU13: ='Raw Financials'!AU36 -> 1496.3
A14: Other operating income / FX | B14: ₹ cr | C14: ='Raw Financials'!C37 -> 133 | D14: ='Raw Financials'!D37 -> 53.3 | E14: ='Raw Financials'!E37 -> 91.1 | F14: ='Raw Financials'!F37 -> 109.3 | G14: ='Raw Financials'!G37 -> 98.4 | H14: ='Raw Financials'!H37 -> 128.1 | I14: ='Raw Financials'!I37 -> 76.7 | J14: ='Raw Financials'!J37 -> 482.7 | ... AU14: ='Raw Financials'!AU37 -> 77.9
A15: EBITDA | B15: ₹ cr | C15: ='Raw Financials'!C38 -> 2738.9 | D15: ='Raw Financials'!D38 -> 2781.9 | E15: ='Raw Financials'!E38 -> 2763.8 | F15: ='Raw Financials'!F38 -> 2897.9 | G15: ='Raw Financials'!G38 -> 2751.2 | H15: ='Raw Financials'!H38 -> 2782 | I15: ='Raw Financials'!I38 -> 2864.5 | J15: ='Raw Financials'!J38 -> 3300.9 | ... AU15: ='Raw Financials'!AU38 -> 0
A16: EBITDA margin | B16: % | C16: =IFERROR(C15/C6,"") -> 0.22381022 | D16: =IFERROR(D15/D6,"") -> 0.2223119 | E16: =IFERROR(E15/E6,"") -> 0.21490611 | F16: =IFERROR(F15/F6,"") -> 0.21257445 | G16: =IFERROR(G15/G6,"") -> 0.20230602 | H16: =IFERROR(H15/H6,"") -> 0.20209652 | I16: =IFERROR(I15/I6,"") -> 0.20927395 | J16: =IFERROR(J15/J6,"") -> 0.23598928 | ... AU16: =IFERROR(AU15/AU6,"") -> 0
A17: D&A | B17: ₹ cr | C17: ='Raw Financials'!C39 -> 336.7 | D17: ='Raw Financials'!D39 -> 353 | E17: ='Raw Financials'!E39 -> 376.4 | F17: ='Raw Financials'!F39 -> 430.4 | G17: ='Raw Financials'!G39 -> 466.5 | H17: ='Raw Financials'!H39 -> 484.9 | I17: ='Raw Financials'!I39 -> 541.2 | J17: ='Raw Financials'!J39 -> 818.1 | ... AU17: ='Raw Financials'!AU39 -> 0
A18: EBIT | B18: ₹ cr | C18: ='Raw Financials'!C40 -> 2402.2 | D18: ='Raw Financials'!D40 -> 2428.9 | E18: ='Raw Financials'!E40 -> 2387.4 | F18: ='Raw Financials'!F40 -> 2467.5 | G18: ='Raw Financials'!G40 -> 2284.7 | H18: ='Raw Financials'!H40 -> 2297.1 | I18: ='Raw Financials'!I40 -> 2323.3 | J18: ='Raw Financials'!J40 -> 2482.8 | ... AU18: ='Raw Financials'!AU40 -> 3920.6
A19: EBIT margin | B19: % | C19: =IFERROR(C18/C6,"") -> 0.19629666 | D19: =IFERROR(D18/D6,"") -> 0.19410237 | E19: =IFERROR(E18/E6,"") -> 0.18563819 | F19: =IFERROR(F18/F6,"") -> 0.18100261 | G19: =IFERROR(G18/G6,"") -> 0.16800253 | H19: =IFERROR(H18/H6,"") -> 0.16687128 | I19: =IFERROR(I18/I6,"") -> 0.16973509 | J19: =IFERROR(J18/J6,"") -> 0.17750134 | ... AU19: =IFERROR(AU18/AU6,"") -> 0.16016439
A20: Finance expense | B20: ₹ cr | C20: ='Raw Financials'!C41 -> 128.6 | D20: ='Raw Financials'!D41 -> 158.9 | E20: ='Raw Financials'!E41 -> 142.3 | F20: ='Raw Financials'!F41 -> 108 | G20: ='Raw Financials'!G41 -> 133.6 | H20: ='Raw Financials'!H41 -> 142.8 | I20: ='Raw Financials'!I41 -> 136.6 | J20: ='Raw Financials'!J41 -> 181.2 | ... AU20: ='Raw Financials'!AU41 -> 472.8
A21: Finance & other income | B21: ₹ cr | C21: ='Raw Financials'!C42 -> 524.2 | D21: ='Raw Financials'!D42 -> 619.4 | E21: ='Raw Financials'!E42 -> 622.7 | F21: ='Raw Financials'!F42 -> 578.8 | G21: ='Raw Financials'!G42 -> 520 | H21: ='Raw Financials'!H42 -> 510.5 | I21: ='Raw Financials'!I42 -> 571.9 | J21: ='Raw Financials'!J42 -> 639.5 | ... AU21: ='Raw Financials'!AU42 -> 887.2
A22: Share of associate / JV | B22: ₹ cr | C22: ='Raw Financials'!C43 -> 0 | D22: ='Raw Financials'!D43 -> 0 | E22: ='Raw Financials'!E43 -> 0 | F22: ='Raw Financials'!F43 -> 0 | G22: ='Raw Financials'!G43 -> 0 | H22: ='Raw Financials'!H43 -> 0 | I22: ='Raw Financials'!I43 -> 0 | J22: ='Raw Financials'!J43 -> 0 | ... AU22: ='Raw Financials'!AU43 -> -0.5
A23: PBT | B23: ₹ cr | C23: ='Raw Financials'!C44 -> 2797.8 | D23: ='Raw Financials'!D44 -> 2889.4 | E23: ='Raw Financials'!E44 -> 2867.8 | F23: ='Raw Financials'!F44 -> 2938.3 | G23: ='Raw Financials'!G44 -> 2671.1 | H23: ='Raw Financials'!H44 -> 2664.8 | I23: ='Raw Financials'!I44 -> 2758.6 | J23: ='Raw Financials'!J44 -> 2941.1 | ... AU23: ='Raw Financials'!AU44 -> 4334.5
A24: PBT margin | B24: % | C24: =IFERROR(C23/C6,"") -> 0.22862326 | D24: =IFERROR(D23/D6,"") -> 0.23090263 | E24: =IFERROR(E23/E6,"") -> 0.22299289 | F24: =IFERROR(F23/F6,"") -> 0.21553798 | G24: =IFERROR(G23/G6,"") -> 0.19641597 | H24: =IFERROR(H23/H6,"") -> 0.1935826 | I24: =IFERROR(I23/I6,"") -> 0.20153714 | J24: =IFERROR(J23/J6,"") -> 0.21026631 | ... AU24: =IFERROR(AU23/AU6,"") -> 0.17707304
A25: Tax | B25: ₹ cr | C25: ='Raw Financials'!C45 -> 594.5 | D25: ='Raw Financials'!D45 -> 648.6 | E25: ='Raw Financials'!E45 -> 624.8 | F25: ='Raw Financials'!F45 -> 668.7 | G25: ='Raw Financials'!G45 -> 612.2 | H25: ='Raw Financials'!H45 -> 590.9 | I25: ='Raw Financials'!I45 -> 644 | J25: ='Raw Financials'!J45 -> 674.2 | ... AU25: ='Raw Financials'!AU45 -> 978.2
A26: Effective tax rate | B26: % | C26: =IFERROR(C25/C23,"") -> 0.21248838 | D26: =IFERROR(D25/D23,"") -> 0.22447567 | E26: =IFERROR(E25/E23,"") -> 0.21786735 | F26: =IFERROR(F25/F23,"") -> 0.22758057 | G26: =IFERROR(G25/G23,"") -> 0.22919397 | H26: =IFERROR(H25/H23,"") -> 0.22174272 | I26: =IFERROR(I25/I23,"") -> 0.23345175 | J26: =IFERROR(J25/J23,"") -> 0.22923396 | ... AU26: =IFERROR(AU25/AU23,"") -> 0.2256777
A27: Profit incl. NCI | B27: ₹ cr | C27: ='Raw Financials'!C46 -> 2203.3 | D27: ='Raw Financials'!D46 -> 2240.8 | E27: ='Raw Financials'!E46 -> 2243 | F27: ='Raw Financials'!F46 -> 2269.6 | G27: ='Raw Financials'!G46 -> 2058.9 | H27: ='Raw Financials'!H46 -> 2073.9 | I27: ='Raw Financials'!I46 -> 2114.6 | J27: ='Raw Financials'!J46 -> 2266.9 | ... AU27: ='Raw Financials'!AU46 -> 3356.3
A28: NCI | B28: ₹ cr | C28: ='Raw Financials'!C47 -> 15.6 | D28: ='Raw Financials'!D47 -> 5.4 | E28: ='Raw Financials'!E47 -> 8.9 | F28: ='Raw Financials'!F47 -> 19.3 | G28: ='Raw Financials'!G47 -> 7.1 | H28: ='Raw Financials'!H47 -> 6.7 | I28: ='Raw Financials'!I47 -> 5.2 | J28: ='Raw Financials'!J47 -> 5.8 | ... AU28: ='Raw Financials'!AU47 -> 4.3
A29: Net income attributable | B29: ₹ cr | C29: ='Raw Financials'!C48 -> 2187.7 | D29: ='Raw Financials'!D48 -> 2235.4 | E29: ='Raw Financials'!E48 -> 2234.1 | F29: ='Raw Financials'!F48 -> 2250.3 | G29: ='Raw Financials'!G48 -> 2051.8 | H29: ='Raw Financials'!H48 -> 2067.2 | I29: ='Raw Financials'!I48 -> 2109.4 | J29: ='Raw Financials'!J48 -> 2261.1 | ... AU29: ='Raw Financials'!AU48 -> 3352
A30: Net margin | B30: % | C30: =IFERROR(C29/C6,"") -> 0.17876871 | D30: =IFERROR(D29/D6,"") -> 0.17863907 | E30: =IFERROR(E29/E6,"") -> 0.17371797 | F30: =IFERROR(F29/F6,"") -> 0.16506998 | G30: =IFERROR(G29/G6,"") -> 0.15087652 | H30: =IFERROR(H29/H6,"") -> 0.15017035 | I30: =IFERROR(I29/I6,"") -> 0.15410804 | J30: =IFERROR(J29/J6,"") -> 0.16165147 | ... AU30: =IFERROR(AU29/AU6,"") -> 0.13693594

Sheet Annual P&L
A1: Annual Profit & Loss
A2: Historical values link to official reported data; FY27E–FY30E are calculated
A5: Metric | B5: Units | C5: FY16A | D5: FY17A | E5: FY18A | F5: FY19A | G5: FY20A | H5: FY21A | I5: FY22A | J5: FY23A | K5: FY24A | L5: FY25A | M5: FY26A | N5: FY27E | O5: FY28E | P5: FY29E | Q5: FY30E
A7: Revenue | B7: ₹ cr | C7: ='Raw Financials'!C6 -> 51244 | D7: ='Raw Financials'!D6 -> 55040.2 | E7: ='Raw Financials'!E6 -> 54487.1 | F7: ='Raw Financials'!F6 -> 58584.5 | G7: ='Raw Financials'!G6 -> 61023.2 | H7: ='Raw Financials'!H6 -> 61943 | I7: ='Raw Financials'!I6 -> 79093.4 | J7: ='Raw Financials'!J6 -> 90487.6 | ... M7: ='Raw Financials'!M6 -> 92624 | N7: ='Revenue Drivers'!N31 -> 95426.741 | O7: ='Revenue Drivers'!O31 -> 101167.44 | P7: ='Revenue Drivers'!P31 -> 109097.12 | Q7: ='Revenue Drivers'!Q31 -> 118382.92
A8: YoY growth | B8: % | D8: =IFERROR(D7/C7-1,"") -> 0.074080868 | E8: =IFERROR(E7/D7-1,"") -> -0.010049019 | F8: =IFERROR(F7/E7-1,"") -> 0.075199451 | G8: =IFERROR(G7/F7-1,"") -> 0.041627052 | H8: =IFERROR(H7/G7-1,"") -> 0.015072956 | I8: =IFERROR(I7/H7-1,"") -> 0.2768739 | J8: =IFERROR(J7/I7-1,"") -> 0.14406006 | K8: =IFERROR(K7/J7-1,"") -> -0.0080375654 | ... Q8: =IFERROR(Q7/P7-1,"") -> 0.085114922
A9: Cost of revenue | B9: ₹ cr | C9: ='Raw Financials'!C7 -> 35672.4 | D9: ='Raw Financials'!D7 -> 39154.4 | E9: ='Raw Financials'!E7 -> 38557.5 | F9: ='Raw Financials'!F7 -> 41303.3 | G9: ='Raw Financials'!G7 -> 43608.5 | H9: ='Raw Financials'!H7 -> 42320.5 | I9: ='Raw Financials'!I7 -> 55587.2 | J9: ='Raw Financials'!J7 -> 64544.6 | ... M9: ='Raw Financials'!M7 -> 65619.2 | N9: =N7-N10 -> 67562.133 | O9: =O7-O10 -> 71323.043 | P9: =P7-P10 -> 76586.181 | Q9: =Q7-Q10 -> 82868.042
A10: Gross profit | B10: ₹ cr | C10: ='Raw Financials'!C8 -> 15571.6 | D10: ='Raw Financials'!D8 -> 15885.8 | E10: ='Raw Financials'!E8 -> 15929.6 | F10: ='Raw Financials'!F8 -> 17281.2 | G10: ='Raw Financials'!G8 -> 17414.7 | H10: ='Raw Financials'!H8 -> 19622.5 | I10: ='Raw Financials'!I8 -> 23506.2 | J10: ='Raw Financials'!J8 -> 25943 | ... M10: ='Raw Financials'!M8 -> 27004.8 | N10: =N7*Assumptions!C19 -> 27864.608 | O10: =O7*Assumptions!D19 -> 29844.394 | P10: =P7*Assumptions!E19 -> 32510.943 | Q10: =Q7*Assumptions!F19 -> 35514.875
A11: Gross margin | B11: % | C11: =IFERROR(C10/C7,"") -> 0.30387167 | D11: =IFERROR(D10/D7,"") -> 0.28862177 | E11: =IFERROR(E10/E7,"") -> 0.29235544 | F11: =IFERROR(F10/F7,"") -> 0.29497905 | G11: =IFERROR(G10/G7,"") -> 0.28537835 | H11: =IFERROR(H10/H7,"") -> 0.31678317 | I11: =IFERROR(I10/I7,"") -> 0.29719547 | J11: =IFERROR(J10/J7,"") -> 0.28670227 | ... Q11: =IFERROR(Q10/Q7,"") -> 0.3
A12: Selling & marketing | B12: ₹ cr | C12: ='Raw Financials'!C9 -> 3409.7 | D12: ='Raw Financials'!D9 -> 4081.7 | E12: ='Raw Financials'!E9 -> 4234.9 | F12: ='Raw Financials'!F9 -> 4451 | G12: ='Raw Financials'!G9 -> 4290.7 | H12: ='Raw Financials'!H9 -> 4140 | I12: ='Raw Financials'!I9 -> 5493.5 | J12: ='Raw Financials'!J9 -> 6515.7 | ... M12: ='Raw Financials'!M9 -> 5921.6 | N12: =N7*Assumptions!C20 -> 6107.3114 | O12: =O7*Assumptions!D20 -> 6373.5485 | P12: =P7*Assumptions!E20 -> 6764.0217 | Q12: =Q7*Assumptions!F20 -> 7221.3579
A13: General & administrative | B13: ₹ cr | C13: ='Raw Financials'!C10 -> 2862.6 | D13: ='Raw Financials'!D10 -> 3202.1 | E13: ='Raw Financials'!E10 -> 3414.1 | F13: ='Raw Financials'!F10 -> 3595.1 | G13: ='Raw Financials'!G10 -> 2982.3 | H13: ='Raw Financials'!H10 -> 3468.6 | I13: ='Raw Financials'!I10 -> 4638.2 | J13: ='Raw Financials'!J10 -> 5913.9 | ... M13: ='Raw Financials'!M10 -> 6143.4 | N13: =N7*Assumptions!C21 -> 6298.1649 | O13: =O7*Assumptions!D21 -> 6575.8834 | P13: =P7*Assumptions!E21 -> 6982.2159 | Q13: =Q7*Assumptions!F21 -> 7458.1238
A14: Other operating income / FX | B14: ₹ cr | C14: ='Raw Financials'!C11 -> 0 | D14: ='Raw Financials'!D11 -> 0 | E14: ='Raw Financials'!E11 -> 0 | F14: ='Raw Financials'!F11 -> 0 | G14: ='Raw Financials'!G11 -> 0 | H14: ='Raw Financials'!H11 -> 0 | I14: ='Raw Financials'!I11 -> 0 | J14: ='Raw Financials'!J11 -> 0 | ... M14: ='Raw Financials'!M11 -> 0 | N14: =N7*Assumptions!C22 -> 190.85348 | O14: =O7*Assumptions!D22 -> 202.33487 | P14: =P7*Assumptions!E22 -> 218.19425 | Q14: =Q7*Assumptions!F22 -> 236.76583
A15: EBITDA | B15: ₹ cr | C15: ='Raw Financials'!C12 -> 11182.5 | D15: ='Raw Financials'!D12 -> 11698.6 | E15: ='Raw Financials'!E12 -> 10541.8 | F15: ='Raw Financials'!F12 -> 11938.4 | G15: ='Raw Financials'!G12 -> 12659.2 | H15: ='Raw Financials'!H12 -> 15070.9 | I15: ='Raw Financials'!I12 -> 17119.7 | J15: ='Raw Financials'!J12 -> 17300.8 | ... M15: ='Raw Financials'!M12 -> 18035.8 | N15: =N18+N17 -> 18608.215 | O15: =O18+O17 -> 20132.32 | P15: =P18+P17 -> 22146.716 | Q15: =Q18+Q17 -> 24386.881
A16: EBITDA margin | B16: % | C16: =IFERROR(C15/C7,"") -> 0.21822067 | D16: =IFERROR(D15/D7,"") -> 0.21254647 | E16: =IFERROR(E15/E7,"") -> 0.19347332 | F16: =IFERROR(F15/F7,"") -> 0.20378086 | G16: =IFERROR(G15/G7,"") -> 0.20744897 | H16: =IFERROR(H15/H7,"") -> 0.24330271 | I16: =IFERROR(I15/I7,"") -> 0.21644916 | J16: =IFERROR(J15/J7,"") -> 0.19119526 | ... Q16: =IFERROR(Q15/Q7,"") -> 0.206
A17: D&A | B17: ₹ cr | C17: ='Raw Financials'!C13 -> 1496.5 | D17: ='Raw Financials'!D13 -> 2310.7 | E17: ='Raw Financials'!E13 -> 2112.4 | F17: ='Raw Financials'!F13 -> 1947.4 | G17: ='Raw Financials'!G13 -> 2086.2 | H17: ='Raw Financials'!H13 -> 2765.6 | I17: ='Raw Financials'!I13 -> 3091.1 | J17: ='Raw Financials'!J13 -> 3340.2 | ... M17: ='Raw Financials'!M13 -> 2910.7 | N17: =N7*Assumptions!C23 -> 2958.229 | O17: =O7*Assumptions!D23 -> 3035.0231 | P17: =P7*Assumptions!E23 -> 3163.8166 | Q17: =Q7*Assumptions!F23 -> 3314.7217
A18: EBIT | B18: ₹ cr | C18: ='Raw Financials'!C14 -> 9686 | D18: ='Raw Financials'!D14 -> 9387.9 | E18: ='Raw Financials'!E14 -> 8429.4 | F18: ='Raw Financials'!F14 -> 9991 | G18: ='Raw Financials'!G14 -> 10573 | H18: ='Raw Financials'!H14 -> 12305.3 | I18: ='Raw Financials'!I14 -> 14028.6 | J18: ='Raw Financials'!J14 -> 13960.6 | ... M18: ='Raw Financials'!M14 -> 15125.1 | N18: =N10-N12-N13+N14 -> 15649.986 | O18: =O10-O12-O13+O14 -> 17097.297 | P18: =P10-P12-P13+P14 -> 18982.9 | Q18: =Q10-Q12-Q13+Q14 -> 21072.159
A19: EBIT margin | B19: % | C19: =IFERROR(C18/C7,"") -> 0.18901725 | D19: =IFERROR(D18/D7,"") -> 0.17056442 | E19: =IFERROR(E18/E7,"") -> 0.15470451 | F19: =IFERROR(F18/F7,"") -> 0.17053999 | G19: =IFERROR(G18/G7,"") -> 0.17326197 | H19: =IFERROR(H18/H7,"") -> 0.19865522 | I19: =IFERROR(I18/I7,"") -> 0.17736752 | J19: =IFERROR(J18/J7,"") -> 0.15428191 | ... Q19: =IFERROR(Q18/Q7,"") -> 0.178
A20: Finance expense | B20: ₹ cr | C20: ='Raw Financials'!C15 -> 537.8 | D20: ='Raw Financials'!D15 -> 594.2 | E20: ='Raw Financials'!E15 -> 583 | F20: ='Raw Financials'!F15 -> 737.5 | G20: ='Raw Financials'!G15 -> 732.8 | H20: ='Raw Financials'!H15 -> 508.8 | I20: ='Raw Financials'!I15 -> 532.5 | J20: ='Raw Financials'!J15 -> 1007.7 | ... M20: ='Raw Financials'!M15 -> 1457.7 | N20: =SUM('Annual Balance Sheet'!M60,'Annual Balance Sheet'!M61)*Assumptions!C25 -> 1420.37 | O20: =SUM('Annual Balance Sheet'!N60,'Annual Balance Sheet'!N61)*Assumptions!D25 -> 1439.2155 | P20: =SUM('Annual Balance Sheet'!O60,'Annual Balance Sheet'!O61)*Assumptions!E25 -> 1458.1717 | Q20: =SUM('Annual Balance Sheet'!P60,'Annual Balance Sheet'!P61)*Assumptions!F25 -> 1479.0499
A21: Finance & other income | B21: ₹ cr | C21: ='Raw Financials'!C16 -> 2345.1 | D21: ='Raw Financials'!D16 -> 2241.9 | E21: ='Raw Financials'!E16 -> 2399.9 | F21: ='Raw Financials'!F16 -> 2292.3 | G21: ='Raw Financials'!G16 -> 2408.1 | H21: ='Raw Financials'!H16 -> 2091.2 | I21: ='Raw Financials'!I16 -> 1625.7 | J21: ='Raw Financials'!J16 -> 1818.5 | ... M21: ='Raw Financials'!M16 -> 3649.1 | N21: =SUM('Annual Balance Sheet'!M21:M22,'Annual Balance Sheet'!M11)*Assumptions!C24 -> 3427.728 | O21: =SUM('Annual Balance Sheet'!N21:N22,'Annual Balance Sheet'!N11)*Assumptions!D24 -> 2943.9668 | P21: =SUM('Annual Balance Sheet'!O21:O22,'Annual Balance Sheet'!O11)*Assumptions!E24 -> 3063.5425 | Q21: =SUM('Annual Balance Sheet'!P21:P22,'Annual Balance Sheet'!P11)*Assumptions!F24 -> 3197.571
A22: Share of associate / JV | B22: ₹ cr | C22: ='Raw Financials'!C17 -> 0 | D22: ='Raw Financials'!D17 -> 0 | E22: ='Raw Financials'!E17 -> 1.1 | F22: ='Raw Financials'!F17 -> -4.3 | G22: ='Raw Financials'!G17 -> 2.9 | H22: ='Raw Financials'!H17 -> 13 | I22: ='Raw Financials'!I17 -> 5.7 | J22: ='Raw Financials'!J17 -> -5.7 | ... M22: ='Raw Financials'!M17 -> 25.7 | N22: =0 -> 0 | O22: =0 -> 0 | P22: =0 -> 0 | Q22: =0 -> 0
A23: PBT | B23: ₹ cr | C23: ='Raw Financials'!C18 -> 11493.3 | D23: ='Raw Financials'!D18 -> 11035.6 | E23: ='Raw Financials'!E18 -> 10247.4 | F23: ='Raw Financials'!F18 -> 11541.5 | G23: ='Raw Financials'!G18 -> 12251.2 | H23: ='Raw Financials'!H18 -> 13900.7 | I23: ='Raw Financials'!I18 -> 15127.5 | J23: ='Raw Financials'!J18 -> 14765.7 | ... M23: ='Raw Financials'!M18 -> 17342.2 | N23: =N18-N20+N21+N22 -> 17657.344 | O23: =O18-O20+O21+O22 -> 18602.048 | P23: =P18-P20+P21+P22 -> 20588.27 | Q23: =Q18-Q20+Q21+Q22 -> 22790.68
A24: PBT margin | B24: % | C24: =IFERROR(C23/C7,"") -> 0.22428577 | D24: =IFERROR(D23/D7,"") -> 0.20050072 | E24: =IFERROR(E23/E7,"") -> 0.1880702 | F24: =IFERROR(F23/F7,"") -> 0.19700603 | G24: =IFERROR(G23/G7,"") -> 0.20076299 | H24: =IFERROR(H23/H7,"") -> 0.22441115 | I24: =IFERROR(I23/I7,"") -> 0.19126122 | J24: =IFERROR(J23/J7,"") -> 0.16317926 | ... Q24: =IFERROR(Q23/Q7,"") -> 0.19251663
A25: Tax | B25: ₹ cr | C25: ='Raw Financials'!C19 -> 2536.6 | D25: ='Raw Financials'!D19 -> 2521.3 | E25: ='Raw Financials'!E19 -> 2239 | F25: ='Raw Financials'!F19 -> 2524.2 | G25: ='Raw Financials'!G19 -> 2479.9 | H25: ='Raw Financials'!H19 -> 3034.5 | I25: ='Raw Financials'!I19 -> 2894.6 | J25: ='Raw Financials'!J19 -> 3399.2 | ... M25: ='Raw Financials'!M19 -> 4076.7 | N25: =N23*Assumptions!C26 -> 4237.7625 | O25: =O23*Assumptions!D26 -> 4464.4915 | P25: =P23*Assumptions!E26 -> 4941.1849 | Q25: =Q23*Assumptions!F26 -> 5469.7633
A26: Effective tax rate | B26: % | C26: =IFERROR(C25/C23,"") -> 0.2207025 | D26: =IFERROR(D25/D23,"") -> 0.22846968 | E26: =IFERROR(E25/E23,"") -> 0.21849445 | F26: =IFERROR(F25/F23,"") -> 0.21870641 | G26: =IFERROR(G25/G23,"") -> 0.20242099 | H26: =IFERROR(H25/H23,"") -> 0.21829836 | I26: =IFERROR(I25/I23,"") -> 0.19134688 | J26: =IFERROR(J25/J23,"") -> 0.2302092 | ... Q26: =IFERROR(Q25/Q23,"") -> 0.24
A27: Profit incl. NCI | B27: ₹ cr | C27: ='Raw Financials'!C20 -> 8956.7 | D27: ='Raw Financials'!D20 -> 8514.3 | E27: ='Raw Financials'!E20 -> 8008.4 | F27: ='Raw Financials'!F20 -> 9017.3 | G27: ='Raw Financials'!G20 -> 9771.3 | H27: ='Raw Financials'!H20 -> 10866.2 | I27: ='Raw Financials'!I20 -> 12232.9 | J27: ='Raw Financials'!J20 -> 11366.5 | ... M27: ='Raw Financials'!M20 -> 13265.5 | N27: =N23-N25 -> 13419.581 | O27: =O23-O25 -> 14137.557 | P27: =P23-P25 -> 15647.085 | Q27: =Q23-Q25 -> 17320.917
A28: NCI | B28: ₹ cr | C28: ='Raw Financials'!C21 -> 49.2 | D28: ='Raw Financials'!D21 -> 24.8 | E28: ='Raw Financials'!E21 -> 0.3 | F28: ='Raw Financials'!F21 -> 14.2 | G28: ='Raw Financials'!G21 -> 49.5 | H28: ='Raw Financials'!H21 -> 71.6 | I28: ='Raw Financials'!I21 -> 13.8 | J28: ='Raw Financials'!J21 -> 16.5 | ... M28: ='Raw Financials'!M21 -> 68.1 | N28: =0 -> 0 | O28: =0 -> 0 | P28: =0 -> 0 | Q28: =0 -> 0
A29: Net income attributable | B29: ₹ cr | C29: ='Raw Financials'!C22 -> 8907.5 | D29: ='Raw Financials'!D22 -> 8489.5 | E29: ='Raw Financials'!E22 -> 8008.1 | F29: ='Raw Financials'!F22 -> 9003.1 | G29: ='Raw Financials'!G22 -> 9721.8 | H29: ='Raw Financials'!H22 -> 10794.6 | I29: ='Raw Financials'!I22 -> 12219.1 | J29: ='Raw Financials'!J22 -> 11350 | ... M29: ='Raw Financials'!M22 -> 13197.4 | N29: =N27-N28 -> 13419.581 | O29: =O27-O28 -> 14137.557 | P29: =P27-P28 -> 15647.085 | Q29: =Q27-Q28 -> 17320.917
A30: Net margin | B30: % | C30: =IFERROR(C29/C7,"") -> 0.17382523 | D30: =IFERROR(D29/D7,"") -> 0.15424181 | E30: =IFERROR(E29/E7,"") -> 0.1469724 | F30: =IFERROR(F29/F7,"") -> 0.15367717 | G30: =IFERROR(G29/G7,"") -> 0.15931318 | H30: =IFERROR(H29/H7,"") -> 0.17426666 | I30: =IFERROR(I29/I7,"") -> 0.1544895 | J30: =IFERROR(J29/J7,"") -> 0.12543155 | ... Q30: =IFERROR(Q29/Q7,"") -> 0.14631264
A31: Basic weighted shares | B31: m | C31: ='Raw Financials'!C25 -> 4913.1188 | D31: ='Raw Financials'!D25 -> 6476.108 | E31: ='Raw Financials'!E25 -> 6333.3912 | F31: ='Raw Financials'!F25 -> 6007.3768 | G31: ='Raw Financials'!G25 -> 5833.384 | H31: ='Raw Financials'!H25 -> 5649.2659 | I31: ='Raw Financials'!I25 -> 5466.7058 | J31: ='Raw Financials'!J25 -> 10954.933 | ... M31: ='Raw Financials'!M25 -> 10476.248 | N31: =MAX(0,M31-Assumptions!C47*10/Assumptions!C51) -> 9644.2549 | O31: =MAX(0,N31-Assumptions!D47*10/Assumptions!D51) -> 9644.2549 | P31: =MAX(0,O31-Assumptions!E47*10/Assumptions!E51) -> 9644.2549 | Q31: =MAX(0,P31-Assumptions!F47*10/Assumptions!F51) -> 9644.2549
A32: Diluted weighted shares | B32: m | C32: ='Raw Financials'!C26 -> 4923.3798 | D32: ='Raw Financials'!D26 -> 6495.1295 | E32: ='Raw Financials'!E26 -> 6344.4826 | F32: ='Raw Financials'!F26 -> 6022.3044 | G32: ='Raw Financials'!G26 -> 5847.8232 | H32: ='Raw Financials'!H26 -> 5661.6578 | I32: ='Raw Financials'!I26 -> 5482.0834 | J32: ='Raw Financials'!J26 -> 10977.982 | ... M32: ='Raw Financials'!M26 -> 10503.423 | N32: =MAX(0,M32-Assumptions!C47*10/Assumptions!C51) -> 9671.43 | O32: =MAX(0,N32-Assumptions!D47*10/Assumptions!D51) -> 9671.43 | P32: =MAX(0,O32-Assumptions!E47*10/Assumptions!E51) -> 9671.43 | Q32: =MAX(0,P32-Assumptions!F47*10/Assumptions!F51) -> 9671.43
A33: Basic EPS | B33: ₹ / share | C33: =IFERROR(C29*10/C31,"") -> 18.130032 | D33: =IFERROR(D29*10/D31,"") -> 13.108954 | E33: =IFERROR(E29*10/E31,"") -> 12.644253 | F33: =IFERROR(F29*10/F31,"") -> 14.986741 | G33: =IFERROR(G29*10/G31,"") -> 16.665798 | H33: =IFERROR(H29*10/H31,"") -> 19.107969 | I33: =IFERROR(I29*10/I31,"") -> 22.351852 | J33: =IFERROR(J29*10/J31,"") -> 10.360629 | ... Q33: =IFERROR(Q29*10/Q31,"") -> 17.959829
A34: Diluted EPS | B34: ₹ / share | C34: =IFERROR(C29*10/C32,"") -> 18.092246 | D34: =IFERROR(D29*10/D32,"") -> 13.070563 | E34: =IFERROR(E29*10/E32,"") -> 12.622148 | F34: =IFERROR(F29*10/F32,"") -> 14.949593 | G34: =IFERROR(G29*10/G32,"") -> 16.624648 | H34: =IFERROR(H29*10/H32,"") -> 19.066147 | I34: =IFERROR(I29*10/I32,"") -> 22.289154 | J34: =IFERROR(J29*10/J32,"") -> 10.338876 | ... Q34: =IFERROR(Q29*10/Q32,"") -> 17.909365
